Workbook

Sheet FY26A Segment P&L (Verified)
A1: PB FINTECH — FY26A SEGMENT P&L (VERIFIED)
A2: Source: Management Presentation / Verified Image
A4: Segment | B4: GWP (₹ Cr) | C4: Take Rate | D4: Revenue (₹ Cr) | E4: Direct Cost (₹ Cr) | F4: Contri Margin | G4: Contri Profit (₹ Cr) | H4: Indirect Cost (₹ Cr) | I4: EBITDA Margin | J4: EBITDA (₹ Cr)
A5: Term - New | B5: 2688 | C5: 0.4 | D5: 1075 | E5: 430 | F5: 0.6 | G5: 645 | H5: 484 | I5: 0.15 | J5: 161
A6: Term - Renewal | B6: 2688 | C6: 0.03 | D6: 67 | E6: 7 | F6: 0.9 | G6: 60 | H6: 13 | I6: 0.7 | J6: 47
A7: Health - New | B7: 2688 | C7: 0.4 | D7: 1075 | E7: 1129 | F7: -0.05 | G7: -54 | H7: 54 | I7: -0.1 | J7: -108
A8: Health - Renewal | B8: 2688 | C8: 0.2 | D8: 538 | E8: 108 | F8: 0.8 | G8: 430 | H8: 54 | I8: 0.7 | J8: 376
A9: ULIP - New | B9: 3010 | C9: 0.12 | D9: 361 | E9: 217 | F9: 0.4 | G9: 144 | H9: 116 | I9: 0.08 | J9: 29
A10: ULIP - Renewal | B10: 4515 | C10: 0.01 | D10: 45 | E10: 5 | F10: 0.9 | G10: 41 | H10: 9 | I10: 0.7 | J10: 32
A11: Motor - New | B11: 1613 | C11: 0.2 | D11: 323 | E11: 194 | F11: 0.4 | G11: 129 | H11: 103 | I11: 0.08 | J11: 26
A12: Motor - Renewal | B12: 1613 | C12: 0.16 | D12: 258 | E12: 52 | F12: 0.8 | G12: 206 | H12: 26 | I12: 0.7 | J12: 181
A13: PoSP / Others | B13: 9500 | C13: 0.25 | D13: 2375 | E13: 2256 | F13: 0.05 | G13: 119 | H13: 214 | I13: -0.04 | J13: -95
A14: PaisaBazaar | B14: 30000 | C14: 0.021 | D14: 630 | E14: 410 | F14: 0.35 | G14: 221 | H14: 221 | I14: 0 | J14: 0
A15: CONSOLIDATED | B15: 31003 | C15: 0.197 | D15: 6747 | E15: 4805 | F15: 0.288 | G15: 1942 | H15: 1293 | I15: 0.096 | J15: 649
A17: Below EBITDA:
A18: ESOPs | D18: 649
A19: Other Income | D19: 215
A20: Dep / Amortization | D20: 372
A21: PBT | D21: 175
A22: Tax Factor | D22: 631 | G22: 0.95x
A23: PAT | D23: 600

Sheet Health - Unit Economics
A1: HEALTH INSURANCE — Customer LTV Model (Fully Linked)
A2: Source: PB Fintech FY26A Segment P&L | IRDAI Proposed Commission Caps (Sep 2026)
A4: Assumption | B4: Pre-Reg | C4: Post-Reg | D4: Note
A5: Annual Premium — Year 1 (₹) | B5: 25000 | C5: 25000 | D5: Avg retail health policy
A6: Annual Premium Growth | B6: 0.08 | C6: 0.08 | D6: Age + inflation + SI increase
A7: FY Take Rate (Commission) | B7: 0.4 | C7: 0.15 | D7: Actual PB: 40% | Proposed IDE cap: 15%
A8: Renewal Take Rate | B8: 0.2 | C8: 0.05 | D8: Actual PB: 20% | Proposed IDE cap: 5%
A9: Acquisition Cost — Direct (₹) | B9: 10500 | C9: 10500 | D9: FIXED: call center, marketing, verification
A10: Acquisition Cost — Indirect (₹) | B10: 500 | C10: 500 | D10: FIXED: allocated overhead per customer
A11: Renewal Direct Cost (% of Rev) | B11: 0.2 | C11: 0.2 | D11: From FY26A P&L: ₹108Cr / ₹538Cr
A12: Renewal Indirect Cost (% of Rev) | B12: 0.1 | C12: 0.1 | D12: From FY26A P&L: ₹54Cr / ₹538Cr
A13: Customer Retention Rate | B13: 0.9 | C13: 0.85 | D13: Lower commission → less servicing → lower retention
A14: Direct Cost as % of FY Revenue (Derived) | B14: =B9/($B$5*B7) -> 1.05 | C14: =C9/($C$5*C7) -> 2.8 | D14: Pre: ~105% | Post: ~280% — same ₹ cost, less revenue
A16: PRE-REGULATION — Year-by-Year Economics (Per Customer)
A17: Metric | B17: Year 1 | C17: Year 2 | D17: Year 3 | E17: Year 4 | F17: Year 5 | G17: Year 6 | H17: Year 7 | I17: Year 8 | J17: Year 9 | K17: Year 10 | L17: Year 11 | M17: Year 12 | N17: Year 13 | O17: Year 14 | P17: Year 15
A18: Annual Premium (₹) | B18: =$B$5 -> 25000 | C18: =B18*(1+$B$6) -> 27000 | D18: =C18*(1+$B$6) -> 29160 | E18: =D18*(1+$B$6) -> 31492.8 | F18: =E18*(1+$B$6) -> 34012.224 | G18: =F18*(1+$B$6) -> 36733.202 | H18: =G18*(1+$B$6) -> 39671.858 | I18: =H18*(1+$B$6) -> 42845.607 | J18: =I18*(1+$B$6) -> 46273.255 | ... P18: =O18*(1+$B$6) -> 73429.841
A19: Revenue (₹) | B19: =B18*$B$7 -> 10000 | C19: =C18*$B$8 -> 5400 | D19: =D18*$B$8 -> 5832 | E19: =E18*$B$8 -> 6298.56 | F19: =F18*$B$8 -> 6802.4448 | G19: =G18*$B$8 -> 7346.6404 | H19: =H18*$B$8 -> 7934.3716 | I19: =I18*$B$8 -> 8569.1213 | J19: =J18*$B$8 -> 9254.6511 | ... P19: =P18*$B$8 -> 14685.968
A20: Direct Cost (₹) | B20: =$B$9 -> 10500 | C20: =C19*$B$11 -> 1080 | D20: =D19*$B$11 -> 1166.4 | E20: =E19*$B$11 -> 1259.712 | F20: =F19*$B$11 -> 1360.489 | G20: =G19*$B$11 -> 1469.3281 | H20: =H19*$B$11 -> 1586.8743 | I20: =I19*$B$11 -> 1713.8243 | J20: =J19*$B$11 -> 1850.9302 | ... P20: =P19*$B$11 -> 2937.1936
A21: Contribution Profit (₹) | B21: =B19-B20 -> -500 | C21: =C19-C20 -> 4320 | D21: =D19-D20 -> 4665.6 | E21: =E19-E20 -> 5038.848 | F21: =F19-F20 -> 5441.9558 | G21: =G19-G20 -> 5877.3123 | H21: =H19-H20 -> 6347.4973 | I21: =I19-I20 -> 6855.2971 | ... P21: =P19-P20 -> 11748.774
A22: Indirect Cost (₹) | B22: =$B$10 -> 500 | C22: =C19*$B$12 -> 540 | D22: =D19*$B$12 -> 583.2 | E22: =E19*$B$12 -> 629.856 | F22: =F19*$B$12 -> 680.24448 | G22: =G19*$B$12 -> 734.66404 | H22: =H19*$B$12 -> 793.43716 | I22: =I19*$B$12 -> 856.91213 | J22: =J19*$B$12 -> 925.46511 | ... P22: =P19*$B$12 -> 1468.5968
A23: EBITDA (₹) | B23: =B21-B22 -> -1000 | C23: =C21-C22 -> 3780 | D23: =D21-D22 -> 4082.4 | E23: =E21-E22 -> 4408.992 | F23: =F21-F22 -> 4761.7114 | G23: =G21-G22 -> 5142.6483 | H23: =H21-H22 -> 5554.0601 | I23: =I21-I22 -> 5998.3849 | ... P23: =P21-P22 -> 10280.178
A24: Surviving Customers (of 100) | B24: =100 -> 100 | C24: =100*$B$13^1 -> 90 | D24: =100*$B$13^2 -> 81 | E24: =100*$B$13^3 -> 72.9 | F24: =100*$B$13^4 -> 65.61 | G24: =100*$B$13^5 -> 59.049 | H24: =100*$B$13^6 -> 53.1441 | I24: =100*$B$13^7 -> 47.82969 | J24: =100*$B$13^8 -> 43.046721 | K24: =100*$B$13^9 -> 38.742049 | L24: =100*$B$13^10 -> 34.867844 | M24: =100*$B$13^11 -> 31.38106 | N24: =100*$B$13^12 -> 28.242954 | O24: =100*$B$13^13 -> 25.418658 | P24: =100*$B$13^14 -> 22.876792
A25: Weighted EBITDA (₹) | B25: =B23*B24/100 -> -1000 | C25: =C23*C24/100 -> 3402 | D25: =D23*D24/100 -> 3306.744 | E25: =E23*E24/100 -> 3214.1552 | F25: =F23*F24/100 -> 3124.1588 | G25: =G23*G24/100 -> 3036.6824 | H25: =H23*H24/100 -> 2951.6553 | I25: =I23*I24/100 -> 2869.0089 | ... P25: =P23*P24/100 -> 2351.7749
A26: Cumulative Profit (₹) | B26: =SUM($B$25:B25) -> -1000 | C26: =SUM($B$25:C25) -> 2402 | D26: =SUM($B$25:D25) -> 5708.744 | E26: =SUM($B$25:E25) -> 8922.8992 | F26: =SUM($B$25:F25) -> 12047.058 | G26: =SUM($B$25:G25) -> 15083.74 | H26: =SUM($B$25:H25) -> 18035.396 | I26: =SUM($B$25:I25) -> 20904.405 | ... P26: =SUM($B$25:P25) -> 38859.814
A28: POST-REGULATION — Year-by-Year Economics (Per Customer)
A29: Metric | B29: Year 1 | C29: Year 2 | D29: Year 3 | E29: Year 4 | F29: Year 5 | G29: Year 6 | H29: Year 7 | I29: Year 8 | J29: Year 9 | K29: Year 10 | L29: Year 11 | M29: Year 12 | N29: Year 13 | O29: Year 14 | P29: Year 15
A30: Annual Premium (₹) | B30: =$C$5 -> 25000 | C30: =B30*(1+$C$6) -> 27000 | D30: =C30*(1+$C$6) -> 29160 | E30: =D30*(1+$C$6) -> 31492.8 | F30: =E30*(1+$C$6) -> 34012.224 | G30: =F30*(1+$C$6) -> 36733.202 | H30: =G30*(1+$C$6) -> 39671.858 | I30: =H30*(1+$C$6) -> 42845.607 | J30: =I30*(1+$C$6) -> 46273.255 | ... P30: =O30*(1+$C$6) -> 73429.841
A31: Revenue (₹) | B31: =B30*$C$7 -> 3750 | C31: =C30*$C$8 -> 1350 | D31: =D30*$C$8 -> 1458 | E31: =E30*$C$8 -> 1574.64 | F31: =F30*$C$8 -> 1700.6112 | G31: =G30*$C$8 -> 1836.6601 | H31: =H30*$C$8 -> 1983.5929 | I31: =I30*$C$8 -> 2142.2803 | J31: =J30*$C$8 -> 2313.6628 | ... P31: =P30*$C$8 -> 3671.492
A32: Direct Cost (₹) | B32: =$C$9 -> 10500 | C32: =C31*$C$11 -> 270 | D32: =D31*$C$11 -> 291.6 | E32: =E31*$C$11 -> 314.928 | F32: =F31*$C$11 -> 340.12224 | G32: =G31*$C$11 -> 367.33202 | H32: =H31*$C$11 -> 396.71858 | I32: =I31*$C$11 -> 428.45607 | J32: =J31*$C$11 -> 462.73255 | ... P32: =P31*$C$11 -> 734.29841
A33: Contribution Profit (₹) | B33: =B31-B32 -> -6750 | C33: =C31-C32 -> 1080 | D33: =D31-D32 -> 1166.4 | E33: =E31-E32 -> 1259.712 | F33: =F31-F32 -> 1360.489 | G33: =G31-G32 -> 1469.3281 | H33: =H31-H32 -> 1586.8743 | I33: =I31-I32 -> 1713.8243 | ... P33: =P31-P32 -> 2937.1936
A34: Indirect Cost (₹) | B34: =$C$10 -> 500 | C34: =C31*$C$12 -> 135 | D34: =D31*$C$12 -> 145.8 | E34: =E31*$C$12 -> 157.464 | F34: =F31*$C$12 -> 170.06112 | G34: =G31*$C$12 -> 183.66601 | H34: =H31*$C$12 -> 198.35929 | I34: =I31*$C$12 -> 214.22803 | J34: =J31*$C$12 -> 231.36628 | ... P34: =P31*$C$12 -> 367.1492
A35: EBITDA (₹) | B35: =B33-B34 -> -7250 | C35: =C33-C34 -> 945 | D35: =D33-D34 -> 1020.6 | E35: =E33-E34 -> 1102.248 | F35: =F33-F34 -> 1190.4278 | G35: =G33-G34 -> 1285.6621 | H35: =H33-H34 -> 1388.515 | I35: =I33-I34 -> 1499.5962 | ... P35: =P33-P34 -> 2570.0444
A36: Surviving Customers (of 100) | B36: =100 -> 100 | C36: =100*$C$13^1 -> 85 | D36: =100*$C$13^2 -> 72.25 | E36: =100*$C$13^3 -> 61.4125 | F36: =100*$C$13^4 -> 52.200625 | G36: =100*$C$13^5 -> 44.370531 | H36: =100*$C$13^6 -> 37.714952 | I36: =100*$C$13^7 -> 32.057709 | J36: =100*$C$13^8 -> 27.249053 | K36: =100*$C$13^9 -> 23.161695 | L36: =100*$C$13^10 -> 19.68744 | M36: =100*$C$13^11 -> 16.734324 | N36: =100*$C$13^12 -> 14.224176 | O36: =100*$C$13^13 -> 12.090549 | P36: =100*$C$13^14 -> 10.276967
A37: Weighted EBITDA (₹) | B37: =B35*B36/100 -> -7250 | C37: =C35*C36/100 -> 803.25 | D37: =D35*D36/100 -> 737.3835 | E37: =E35*E36/100 -> 676.91805 | F37: =F35*F36/100 -> 621.41077 | G37: =G35*G36/100 -> 570.45509 | H37: =H35*H36/100 -> 523.67777 | I37: =I35*I36/100 -> 480.73619 | ... P37: =P35*P36/100 -> 264.12262
A38: Cumulative Profit (₹) | B38: =SUM($B$37:B37) -> -7250 | C38: =SUM($B$37:C37) -> -6446.75 | D38: =SUM($B$37:D37) -> -5709.3665 | E38: =SUM($B$37:E37) -> -5032.4484 | F38: =SUM($B$37:F37) -> -4411.0377 | G38: =SUM($B$37:G37) -> -3840.5826 | H38: =SUM($B$37:H37) -> -3316.9048 | I38: =SUM($B$37:I37) -> -2836.1686 | ... P38: =SUM($B$37:P37) -> -411.15319
A40: IMPACT SUMMARY
A41: Metric | B41: Pre-Reg | C41: Post-Reg | D41: Change
A42: FY Take Rate | B42: =$B$7 -> 0.4 | C42: =$C$7 -> 0.15 | D42: =C42-B42 -> -0.25
A43: Renewal Take Rate | B43: =$B$8 -> 0.2 | C43: =$C$8 -> 0.05 | D43: =C43-B43 -> -0.15
A44: Y1 Revenue (₹) | B44: =B19 -> 10000 | C44: =B31 -> 3750 | D44: =C44-B44 -> -6250
...

Sheet Term - Unit Economics
A1: TERM INSURANCE — Distributor Unit Economics (Per Customer)
A2: Aligned to PB Fintech FY26A Verified Segment P&L
A4: KEY ASSUMPTIONS
A5: Assumption | B5: Pre-Reg (Actual) | C5: Post-Reg (Proposed) | D5: Note
A6: Annual Premium | B6: 15000 | C6: 15000 | D6: INR — avg term plan, 30yo, ₹1Cr cover
A7: Premium Growth | B7: 0 | C7: 0 | D7: Term premium is FIXED at purchase
A8: FY Take Rate (Commission) | B8: 0.4 | C8: 0.25 | D8: Actual PB: 40% | Proposed IDE cap: 25%
A9: Renewal Take Rate | B9: 0.03 | C9: 0.075 | D9: Actual PB: 3% | Proposed IDE cap: 7.5% (INCREASE)
A10: FY Contribution Margin | B10: 0.6 | C10: Derived | D10: From verified P&L
A11: Renewal Contribution Margin | B11: 0.9 | C11: Derived | D11: From verified P&L
A12: FY EBITDA Margin | B12: 0.15 | C12: Derived | D12: From verified P&L
A13: Renewal EBITDA Margin | B13: 0.7 | C13: Derived | D13: From verified P&L
A14: CAC (Fully Loaded per Customer) | B14: 8000 | C14: 8000 | D14: Lower than health — simpler comparison
A15: Direct Cost as % of Revenue (New) | B15: 0.4 | C15: Derived | D15: Actual: ₹430 / ₹1,075 = 40%
A16: Direct Cost as % of Revenue (Renewal) | B16: 0.1 | C16: Derived | D16: Actual: ₹7 / ₹67 ≈ 10%
A17: Indirect Cost as % of Revenue (New) | B17: 0.45 | C17: Derived | D17: Actual: ₹484 / ₹1,075 = 45%
A18: Indirect Cost as % of Revenue (Renewal) | B18: 0.19 | C18: Derived | D18: Actual: ₹13 / ₹67 ≈ 19%
A19: Customer Retention Rate | B19: 0.95 | C19: 0.95 | D19: High — switching = re-underwriting at older age
A20: Projection Period (Years) | B20: 15 | C20: 15
A23: YEAR-BY-YEAR ECONOMICS — PRE-REGULATION (ACTUAL PB RATES)
A24: Metric | B24: Year 1 | C24: Year 2 | D24: Year 3 | E24: Year 5 | F24: Year 7 | G24: Year 10 | H24: Year 15
A25: Annual Premium (₹) | B25: =$B$6 -> 15000 | C25: =$B$6 -> 15000 | D25: =$B$6 -> 15000 | E25: =$B$6 -> 15000 | F25: =$B$6 -> 15000 | G25: =$B$6 -> 15000 | H25: =$B$6 -> 15000
A26: Revenue — Take Rate × Premium (₹) | B26: =B25*$B$8 -> 6000 | C26: =C25*$B$9 -> 450 | D26: =D25*$B$9 -> 450 | E26: =E25*$B$9 -> 450 | F26: =F25*$B$9 -> 450 | G26: =G25*$B$9 -> 450 | H26: =H25*$B$9 -> 450
A27: Direct Cost (₹) | B27: =B26*$B$15 -> 2400 | C27: =C26*$B$16 -> 45 | D27: =D26*$B$16 -> 45 | E27: =E26*$B$16 -> 45 | F27: =F26*$B$16 -> 45 | G27: =G26*$B$16 -> 45 | H27: =H26*$B$16 -> 45
A28: Contribution Margin (%) | B28: =IF(B26=0,0,(B26-B27)/B26) -> 0.6 | C28: =IF(C26=0,0,(C26-C27)/C26) -> 0.9 | D28: =IF(D26=0,0,(D26-D27)/D26) -> 0.9 | E28: =IF(E26=0,0,(E26-E27)/E26) -> 0.9 | F28: =IF(F26=0,0,(F26-F27)/F26) -> 0.9 | G28: =IF(G26=0,0,(G26-G27)/G26) -> 0.9 | H28: =IF(H26=0,0,(H26-H27)/H26) -> 0.9
A29: Contribution Profit (₹) | B29: =B26-B27 -> 3600 | C29: =C26-C27 -> 405 | D29: =D26-D27 -> 405 | E29: =E26-E27 -> 405 | F29: =F26-F27 -> 405 | G29: =G26-G27 -> 405 | H29: =H26-H27 -> 405
A30: Indirect Cost (₹) | B30: =B26*$B$17 -> 2700 | C30: =C26*$B$18 -> 85.5 | D30: =D26*$B$18 -> 85.5 | E30: =E26*$B$18 -> 85.5 | F30: =F26*$B$18 -> 85.5 | G30: =G26*$B$18 -> 85.5 | H30: =H26*$B$18 -> 85.5
A31: EBITDA (₹) | B31: =B29-B30 -> 900 | C31: =C29-C30 -> 319.5 | D31: =D29-D30 -> 319.5 | E31: =E29-E30 -> 319.5 | F31: =F29-F30 -> 319.5 | G31: =G29-G30 -> 319.5 | H31: =H29-H30 -> 319.5
A32: EBITDA Margin (%) | B32: =IF(B26=0,0,B31/B26) -> 0.15 | C32: =IF(C26=0,0,C31/C26) -> 0.71 | D32: =IF(D26=0,0,D31/D26) -> 0.71 | E32: =IF(E26=0,0,E31/E26) -> 0.71 | F32: =IF(F26=0,0,F31/F26) -> 0.71 | G32: =IF(G26=0,0,G31/G26) -> 0.71 | H32: =IF(H26=0,0,H31/H26) -> 0.71
A33: Cumulative Revenue (₹) | B33: =B26 -> 6000 | C33: =B33+C26*1 -> 6450 | D33: =C33+D26*1 -> 6900 | E33: =D33+E26*2 -> 7800 | F33: =E33+F26*2 -> 8700 | G33: =F33+G26*3 -> 10050 | H33: =G33+H26*5 -> 12300
A34: Cumulative Cost (₹) | B34: =B27+B30 -> 5100 | C34: =B34+(C27+C30)*1 -> 5230.5 | D34: =C34+(D27+D30)*1 -> 5361 | E34: =D34+(E27+E30)*2 -> 5622 | F34: =E34+(F27+F30)*2 -> 5883 | G34: =F34+(G27+G30)*3 -> 6274.5 | H34: =G34+(H27+H30)*5 -> 6927
A35: Cumulative Profit (₹) | B35: =B33-B34 -> 900 | C35: =C33-C34 -> 1219.5 | D35: =D33-D34 -> 1539 | E35: =E33-E34 -> 2178 | F35: =F33-F34 -> 2817 | G35: =G33-G34 -> 3775.5 | H35: =H33-H34 -> 5373
A36: Surviving Customers (of 100) | B36: 100 | C36: =100*$B$19^1 -> 95 | D36: =100*$B$19^2 -> 90.25 | E36: =100*$B$19^4 -> 81.450625 | F36: =100*$B$19^6 -> 73.509189 | G36: =100*$B$19^9 -> 63.024941 | H36: =100*$B$19^14 -> 48.767498
A39: YEAR-BY-YEAR ECONOMICS — POST-REGULATION (PROPOSED CAPS)
A40: Metric | B40: Year 1 | C40: Year 2 | D40: Year 3 | E40: Year 5 | F40: Year 7 | G40: Year 10 | H40: Year 15
A41: Annual Premium (₹) | B41: =$C$6 -> 15000 | C41: =$C$6 -> 15000 | D41: =$C$6 -> 15000 | E41: =$C$6 -> 15000 | F41: =$C$6 -> 15000 | G41: =$C$6 -> 15000 | H41: =$C$6 -> 15000
A42: Revenue — Take Rate × Premium (₹) | B42: =B41*$C$8 -> 3750 | C42: =C41*$C$9 -> 1125 | D42: =D41*$C$9 -> 1125 | E42: =E41*$C$9 -> 1125 | F42: =F41*$C$9 -> 1125 | G42: =G41*$C$9 -> 1125 | H42: =H41*$C$9 -> 1125
A43: Direct Cost (₹) | B43: =B41*$B$8*$B$15 -> 2400 | C43: =C42*$B$16 -> 112.5 | D43: =D42*$B$16 -> 112.5 | E43: =E42*$B$16 -> 112.5 | F43: =F42*$B$16 -> 112.5 | G43: =G42*$B$16 -> 112.5 | H43: =H42*$B$16 -> 112.5
A44: Contribution Margin (%) | B44: =IF(B42=0,0,(B42-B43)/B42) -> 0.36 | C44: =IF(C42=0,0,(C42-C43)/C42) -> 0.9 | D44: =IF(D42=0,0,(D42-D43)/D42) -> 0.9 | E44: =IF(E42=0,0,(E42-E43)/E42) -> 0.9 | F44: =IF(F42=0,0,(F42-F43)/F42) -> 0.9 | G44: =IF(G42=0,0,(G42-G43)/G42) -> 0.9 | H44: =IF(H42=0,0,(H42-H43)/H42) -> 0.9
A45: Contribution Profit (₹) | B45: =B42-B43 -> 1350 | C45: =C42-C43 -> 1012.5 | D45: =D42-D43 -> 1012.5 | E45: =E42-E43 -> 1012.5 | F45: =F42-F43 -> 1012.5 | G45: =G42-G43 -> 1012.5 | H45: =H42-H43 -> 1012.5
...

Sheet Health vs Term Comparison
A1: HEALTH vs TERM — Distributor Economics Comparison
A2: Based on PB Fintech FY26A Verified Segment P&L
A4: Metric | B4: Health Pre-Reg | C4: Health Post-Reg | D4: Term Pre-Reg | E4: Term Post-Reg
A5: FY Take Rate | B5: ='Health - Unit Economics'!B8 -> 0.2 | C5: ='Health - Unit Economics'!C8 -> 0.05 | D5: ='Term - Unit Economics'!B8 -> 0.4 | E5: ='Term - Unit Economics'!C8 -> 0.25
A6: Renewal Take Rate | B6: ='Health - Unit Economics'!B9 -> 10500 | C6: ='Health - Unit Economics'!C9 -> 10500 | D6: ='Term - Unit Economics'!B9 -> 0.03 | E6: ='Term - Unit Economics'!C9 -> 0.075
A7: FY Contribution Margin | B7: ='Health - Unit Economics'!B10 -> 500 | C7: ='Health - Unit Economics'!C10 -> 500 | D7: ='Term - Unit Economics'!B10 -> 0.6 | E7: ='Term - Unit Economics'!C10 -> Derived
A8: Renewal Contribution Margin | B8: ='Health - Unit Economics'!B11 -> 0.2 | C8: ='Health - Unit Economics'!C11 -> 0.2 | D8: ='Term - Unit Economics'!B11 -> 0.9 | E8: ='Term - Unit Economics'!C11 -> Derived
A9: FY EBITDA Margin | B9: ='Health - Unit Economics'!B12 -> 0.1 | C9: ='Health - Unit Economics'!C12 -> 0.1 | D9: ='Term - Unit Economics'!B12 -> 0.15 | E9: ='Term - Unit Economics'!C12 -> Derived
A10: Renewal EBITDA Margin | B10: ='Health - Unit Economics'!B13 -> 0.9 | C10: ='Health - Unit Economics'!C13 -> 0.85 | D10: ='Term - Unit Economics'!B13 -> 0.7 | E10: ='Term - Unit Economics'!C13 -> Derived
A11: Direct Cost % (New) | B11: ='Health - Unit Economics'!B15 -> 0 | D11: ='Term - Unit Economics'!B15 -> 0.4
A12: Direct Cost % (Renewal) | B12: ='Health - Unit Economics'!B16 -> 0 | D12: ='Term - Unit Economics'!B16 -> 0.1
A13: Retention Rate | B13: ='Health - Unit Economics'!B19 -> 10000 | C13: ='Health - Unit Economics'!C19 -> 5400 | D13: ='Term - Unit Economics'!B19 -> 0.95 | E13: ='Term - Unit Economics'!C19 -> 0.95
A16: KEY INSIGHTS
A17: Health Pre-Reg: -5% contri margin on new (loss leader), +80% on renewal (profit engine). Subsidy model works.
A18: Health Post-Reg: FY revenue drops 63%, renewal drops 75%. Loss leader becomes permanent loss. Subsidy breaks.
A19: Term Pre-Reg: +60% contri margin on new (profitable from day 1), +90% on renewal. Front-loaded value capture.
A20: Term Post-Reg: FY revenue drops 37%, but renewal INCREASES (3% → 7.5%). Timing shift, not destruction.
A21: The asymmetry: Health = VALUE DESTRUCTION (both FY AND renewal gutted). Term = TIMING SHIFT (less FY, more trail).
A22: EBITDA margins tell the same story: Health-new -10% → catastrophic post-caps. Term-new 15% → compressed but survivable.
A23: PoSP business (5% contri margin, -4% EBITDA margin) becomes unviable. Eliminated in FY28 per Bernstein model.
