Workbook

Sheet Quality Check
A1: Exchange | B1: Sheet | C1: Data From | D1: Data To | E1: Data Rows | F1: Turnover Total (INR Bn)
A2: NSE | B2: Year NSE Equity Cash | C2: ='Year NSE Equity Cash'!A2 -> 1994-1995 | D2: =LOOKUP(2,1/('Year NSE Equity Cash'!$A$2:$A$100000<>""),'Year NSE Equity Cash'!$A$2:$A$100000) -> 2025-2026 | E2: =COUNTA('Year NSE Equity Cash'!$A:$A)-1 -> 32 | F2: =SUM('Year NSE Equity Cash'!$I:$I) -> 1899269
A3: NSE | B3: Monthly NSE Equity Cash | C3: ='Monthly NSE Equity Cash'!A2 -> 36251 | D3: =LOOKUP(2,1/('Monthly NSE Equity Cash'!$A$2:$A$100000<>""),'Monthly NSE Equity Cash'!$A$2:$A$100000) -> 46235 | E3: =COUNTA('Monthly NSE Equity Cash'!$A:$A)-1 -> 329 | F3: =SUM('Monthly NSE Equity Cash'!$K:$K) -> 2022184.5
A4: NSE | B4: Daily NSE Equity Cash | C4: ='Daily NSE Equity Cash'!A2 -> 43922 | D4: =LOOKUP(2,1/('Daily NSE Equity Cash'!$A$2:$A$100000<>""),'Daily NSE Equity Cash'!$A$2:$A$100000) -> 46272 | E4: =COUNTA('Daily NSE Equity Cash'!$A:$A)-1 -> 1592 | F4: =SUM('Daily NSE Equity Cash'!$H:$H) -> 1332162
A5: BSE | B5: Year BSE Equity Cash | C5: ='Year BSE Equity Cash'!A2 -> 1997-1998 | D5: =LOOKUP(2,1/('Year BSE Equity Cash'!$A$2:$A$100000<>""),'Year BSE Equity Cash'!$A$2:$A$100000) -> 2026-2027 | E5: =COUNTA('Year BSE Equity Cash'!$A:$A)-1 -> 30 | F5: =SUM('Year BSE Equity Cash'!$F:$F) -> 275345.7
A6: BSE | B6: Monthly BSE Equity Cash | C6: ='Monthly BSE Equity Cash'!A2 -> 35735 | D6: =LOOKUP(2,1/('Monthly BSE Equity Cash'!$A$2:$A$100000<>""),'Monthly BSE Equity Cash'!$A$2:$A$100000) -> 46266 | E6: =COUNTA('Monthly BSE Equity Cash'!$A:$A)-1 -> 347 | F6: =SUM('Monthly BSE Equity Cash'!$G:$G) -> 275345.7
A7: BSE | B7: Daily BSE Equity Cash | C7: ='Daily BSE Equity Cash'!A2 -> 43922 | D7: =LOOKUP(2,1/('Daily BSE Equity Cash'!$A$2:$A$100000<>""),'Daily BSE Equity Cash'!$A$2:$A$100000) -> 46272 | E7: =COUNTA('Daily BSE Equity Cash'!$A:$A)-1 -> 1597 | F7: =SUM('Daily BSE Equity Cash'!$H:$H) -> 100482.39
A9: NSE & BSE daily end dates aligned? | C9: =IF($D$4=$D$7,"YES","NO") -> YES
A11: Turnover Reconciliation | B11: Aggregate (INR Bn) | C11: Component Sum (INR Bn) | D11: Difference | E11: Status | F11: Remarks
A12: NSE: Monthly vs Daily (Apr-2020 → last completed month) | B12: =SUMIFS('Monthly NSE Equity Cash'!$K:$K,'Monthly NSE Equity Cash'!$A:$A,">="&DATE(2020,4,1)) -> 1330029.4 | C12: =SUMIFS('Daily NSE Equity Cash'!$H:$H,'Daily NSE Equity Cash'!$A:$A,"<="&EOMONTH($D$3,0)) -> 1326463.5 | D12: =B12-C12 -> 3565.8974 | E12: =IF(ABS(D12)<=0.25,"OK","CHECK") -> CHECK | F12: NSE source gaps: daily rows missing 22-Nov-2021 & 07/08/09/11/14-Aug-2023
A13: NSE: Yearly vs Monthly (FY1999-2000 → last completed FY) | B13: =SUMIFS('Year NSE Equity Cash'!$I:$I,'Year NSE Equity Cash'!$A:$A,">=1999-2000") -> 1887786.4 | C13: =SUMIFS('Monthly NSE Equity Cash'!$K:$K,'Monthly NSE Equity Cash'!$A:$A,"<="&DATE(VALUE(RIGHT($D$2,4)),3,31)) -> 1887786.6 | D13: =B13-C13 -> -0.21 | E13: =IF(ABS(D13)<=0.25,"OK","CHECK") -> OK | F13: ~0.2 INR Bn rounding at NSE (FY2020-21)
A14: BSE: Monthly vs Daily (Apr-2020 → last month) | B14: =SUMIFS('Monthly BSE Equity Cash'!$G:$G,'Monthly BSE Equity Cash'!$A:$A,">="&DATE(2020,4,1),'Monthly BSE Equity Cash'!$A:$A,"<="&DATE(YEAR($D$7),MONTH($D$7),1)) -> 100482.44 | C14: =SUMIFS('Daily BSE Equity Cash'!$H:$H,'Daily BSE Equity Cash'!$A:$A,"<="&EOMONTH($D$6,0)) -> 100482.39 | D14: =B14-C14 -> 0.0555 | E14: =IF(ABS(D14)<=0.25,"OK","CHECK") -> OK
A15: BSE: Yearly vs Monthly (full history) | B15: =SUM('Year BSE Equity Cash'!$F:$F) -> 275345.7 | C15: =SUM('Monthly BSE Equity Cash'!$G:$G) -> 275345.7 | D15: =B15-C15 -> 0 | E15: =IF(ABS(D15)<=0.25,"OK","CHECK") -> OK
A17: Notes
A18: Units: shares & trades in Crores; all monetary values in INR Bn (1 Bn = 100 Crores); same units for both exchanges.
A19: Each Market Share sheet carries a period-to-date Comparison block below the data - Year & Day: current-FY YTD vs prior FY; Qrtr: running quarter vs same quarter a year earlier; Mth: running month vs same month a year earlier - always over the FIRST EQUAL NUMBER of NSE trading days of the prior period (matched window shown in the block; live formulas on the daily sheets).
A20: NSE publishes Monthly figures only for completed months; the NSE Year sheet excludes the in-progress fiscal year.
A21: Known NSE source gaps (same on nseindia.com): daily rows missing for 22-Nov-2021 and 07/08/09/11/14-Aug-2023; Aug-2023 monthly total is ~1 trading day low; Dec-2021 monthly & FY2020-21 yearly differ by ~0.2 INR Bn (NSE rounding).
A22: History starts: NSE yearly FY1994-95, monthly Apr-1999; BSE yearly FY1997-98, monthly Nov-1997; daily sheets per chosen range.
A23: Market Share sheets: NSE turnover for periods not yet published by NSE at yearly/monthly level (current FY / current month / current quarter) is summed from the Daily NSE Equity Cash sheet; once NSE publishes the official aggregate, that figure takes over automatically.

Sheet Year Eq Cash Turnover Mkt Share
A1: Fiscal Year | B1: NSE Turnover (INR Bn) | C1: BSE Turnover (INR Bn) | D1: Total Turnover (INR Bn) | E1: NSE YoY Growth | F1: BSE YoY Growth | G1: Total Turnover YoY Growth | H1: NSE Market Share | I1: BSE Market Share
A2: 1994-1995 | B2: =IF(MAX(SUMIFS('Year NSE Equity Cash'!$I:$I,'Year NSE Equity Cash'!$A:$A,$A2),SUMIFS('Daily NSE Equity Cash'!$H:$H,'Daily NSE Equity Cash'!$A:$A,">="&DATE(VALUE(LEFT($A2,4)),4,1),'Daily NSE Equity Cash'!$A:$A,"<="&DATE(VALUE(RIGHT($A2,4)),3,31)))=0,"",MAX(SUMIFS('Year NSE Equity Cash'!$I:$I,'Year NSE Equity Cash'!$A:$A,$A2),SUMIFS('Daily NSE Equity Cash'!$H:$H,'Daily NSE Equity Cash'!$A:$A,">="&DATE(VALUE(LEFT($A2,4)),4,1),'Daily NSE Equity Cash'!$A:$A,"<="&DATE(VALUE(RIGHT($A2,4)),3,31)))) -> 18.05 | C2: =IF(SUMIFS('Year BSE Equity Cash'!$F:$F,'Year BSE Equity Cash'!$A:$A,$A2)=0,"",SUMIFS('Year BSE Equity Cash'!$F:$F,'Year BSE Equity Cash'!$A:$A,$A2)) | D2: =IF(OR(B2="",C2=""),"",B2+C2) | H2: =IF(D2="","",B2/D2) | I2: =IF(D2="","",C2/D2)
A3: 1995-1996 | B3: =IF(MAX(SUMIFS('Year NSE Equity Cash'!$I:$I,'Year NSE Equity Cash'!$A:$A,$A3),SUMIFS('Daily NSE Equity Cash'!$H:$H,'Daily NSE Equity Cash'!$A:$A,">="&DATE(VALUE(LEFT($A3,4)),4,1),'Daily NSE Equity Cash'!$A:$A,"<="&DATE(VALUE(RIGHT($A3,4)),3,31)))=0,"",MAX(SUMIFS('Year NSE Equity Cash'!$I:$I,'Year NSE Equity Cash'!$A:$A,$A3),SUMIFS('Daily NSE Equity Cash'!$H:$H,'Daily NSE Equity Cash'!$A:$A,">="&DATE(VALUE(LEFT($A3,4)),4,1),'Daily NSE Equity Cash'!$A:$A,"<="&DATE(VALUE(RIGHT($A3,4)),3,31)))) -> 672.87 | C3: =IF(SUMIFS('Year BSE Equity Cash'!$F:$F,'Year BSE Equity Cash'!$A:$A,$A3)=0,"",SUMIFS('Year BSE Equity Cash'!$F:$F,'Year BSE Equity Cash'!$A:$A,$A3)) | D3: =IF(OR(B3="",C3=""),"",B3+C3) | E3: =IF(OR(B3="",B2=""),"",B3/B2-1) -> 36.278116 | F3: =IF(OR(C3="",C2=""),"",C3/C2-1) | G3: =IF(OR(D3="",D2=""),"",D3/D2-1) | H3: =IF(D3="","",B3/D3) | I3: =IF(D3="","",C3/D3)
A4: 1996-1997 | B4: =IF(MAX(SUMIFS('Year NSE Equity Cash'!$I:$I,'Year NSE Equity Cash'!$A:$A,$A4),SUMIFS('Daily NSE Equity Cash'!$H:$H,'Daily NSE Equity Cash'!$A:$A,">="&DATE(VALUE(LEFT($A4,4)),4,1),'Daily NSE Equity Cash'!$A:$A,"<="&DATE(VALUE(RIGHT($A4,4)),3,31)))=0,"",MAX(SUMIFS('Year NSE Equity Cash'!$I:$I,'Year NSE Equity Cash'!$A:$A,$A4),SUMIFS('Daily NSE Equity Cash'!$H:$H,'Daily NSE Equity Cash'!$A:$A,">="&DATE(VALUE(LEFT($A4,4)),4,1),'Daily NSE Equity Cash'!$A:$A,"<="&DATE(VALUE(RIGHT($A4,4)),3,31)))) -> 2945.03 | C4: =IF(SUMIFS('Year BSE Equity Cash'!$F:$F,'Year BSE Equity Cash'!$A:$A,$A4)=0,"",SUMIFS('Year BSE Equity Cash'!$F:$F,'Year BSE Equity Cash'!$A:$A,$A4)) | D4: =IF(OR(B4="",C4=""),"",B4+C4) | E4: =IF(OR(B4="",B3=""),"",B4/B3-1) -> 3.3768187 | F4: =IF(OR(C4="",C3=""),"",C4/C3-1) | G4: =IF(OR(D4="",D3=""),"",D4/D3-1) | H4: =IF(D4="","",B4/D4) | I4: =IF(D4="","",C4/D4)
A5: 1997-1998 | B5: =IF(MAX(SUMIFS('Year NSE Equity Cash'!$I:$I,'Year NSE Equity Cash'!$A:$A,$A5),SUMIFS('Daily NSE Equity Cash'!$H:$H,'Daily NSE Equity Cash'!$A:$A,">="&DATE(VALUE(LEFT($A5,4)),4,1),'Daily NSE Equity Cash'!$A:$A,"<="&DATE(VALUE(RIGHT($A5,4)),3,31)))=0,"",MAX(SUMIFS('Year NSE Equity Cash'!$I:$I,'Year NSE Equity Cash'!$A:$A,$A5),SUMIFS('Daily NSE Equity Cash'!$H:$H,'Daily NSE Equity Cash'!$A:$A,">="&DATE(VALUE(LEFT($A5,4)),4,1),'Daily NSE Equity Cash'!$A:$A,"<="&DATE(VALUE(RIGHT($A5,4)),3,31)))) -> 3701.93 | C5: =IF(SUMIFS('Year BSE Equity Cash'!$F:$F,'Year BSE Equity Cash'!$A:$A,$A5)=0,"",SUMIFS('Year BSE Equity Cash'!$F:$F,'Year BSE Equity Cash'!$A:$A,$A5)) -> 868.9916 | D5: =IF(OR(B5="",C5=""),"",B5+C5) -> 4570.9216 | E5: =IF(OR(B5="",B4=""),"",B5/B4-1) -> 0.25700927 | F5: =IF(OR(C5="",C4=""),"",C5/C4-1) | G5: =IF(OR(D5="",D4=""),"",D5/D4-1) | H5: =IF(D5="","",B5/D5) -> 0.809887 | I5: =IF(D5="","",C5/D5) -> 0.190113
A6: 1998-1999 | B6: =IF(MAX(SUMIFS('Year NSE Equity Cash'!$I:$I,'Year NSE Equity Cash'!$A:$A,$A6),SUMIFS('Daily NSE Equity Cash'!$H:$H,'Daily NSE Equity Cash'!$A:$A,">="&DATE(VALUE(LEFT($A6,4)),4,1),'Daily NSE Equity Cash'!$A:$A,"<="&DATE(VALUE(RIGHT($A6,4)),3,31)))=0,"",MAX(SUMIFS('Year NSE Equity Cash'!$I:$I,'Year NSE Equity Cash'!$A:$A,$A6),SUMIFS('Daily NSE Equity Cash'!$H:$H,'Daily NSE Equity Cash'!$A:$A,">="&DATE(VALUE(LEFT($A6,4)),4,1),'Daily NSE Equity Cash'!$A:$A,"<="&DATE(VALUE(RIGHT($A6,4)),3,31)))) -> 4144.74 | C6: =IF(SUMIFS('Year BSE Equity Cash'!$F:$F,'Year BSE Equity Cash'!$A:$A,$A6)=0,"",SUMIFS('Year BSE Equity Cash'!$F:$F,'Year BSE Equity Cash'!$A:$A,$A6)) -> 2846.3687 | D6: =IF(OR(B6="",C6=""),"",B6+C6) -> 6991.1087 | E6: =IF(OR(B6="",B5=""),"",B6/B5-1) -> 0.11961598 | F6: =IF(OR(C6="",C5=""),"",C6/C5-1) -> 2.2754847 | G6: =IF(OR(D6="",D5=""),"",D6/D5-1) -> 0.52947465 | H6: =IF(D6="","",B6/D6) -> 0.59285876 | I6: =IF(D6="","",C6/D6) -> 0.40714124
A7: 1999-2000 | B7: =IF(MAX(SUMIFS('Year NSE Equity Cash'!$I:$I,'Year NSE Equity Cash'!$A:$A,$A7),SUMIFS('Daily NSE Equity Cash'!$H:$H,'Daily NSE Equity Cash'!$A:$A,">="&DATE(VALUE(LEFT($A7,4)),4,1),'Daily NSE Equity Cash'!$A:$A,"<="&DATE(VALUE(RIGHT($A7,4)),3,31)))=0,"",MAX(SUMIFS('Year NSE Equity Cash'!$I:$I,'Year NSE Equity Cash'!$A:$A,$A7),SUMIFS('Daily NSE Equity Cash'!$H:$H,'Daily NSE Equity Cash'!$A:$A,">="&DATE(VALUE(LEFT($A7,4)),4,1),'Daily NSE Equity Cash'!$A:$A,"<="&DATE(VALUE(RIGHT($A7,4)),3,31)))) -> 8390.52 | C7: =IF(SUMIFS('Year BSE Equity Cash'!$F:$F,'Year BSE Equity Cash'!$A:$A,$A7)=0,"",SUMIFS('Year BSE Equity Cash'!$F:$F,'Year BSE Equity Cash'!$A:$A,$A7)) -> 6864.2855 | D7: =IF(OR(B7="",C7=""),"",B7+C7) -> 15254.806 | E7: =IF(OR(B7="",B6=""),"",B7/B6-1) -> 1.0243779 | F7: =IF(OR(C7="",C6=""),"",C7/C6-1) -> 1.4115939 | G7: =IF(OR(D7="",D6=""),"",D7/D6-1) -> 1.1820295 | H7: =IF(D7="","",B7/D7) -> 0.55002471 | I7: =IF(D7="","",C7/D7) -> 0.44997529
A8: 2000-2001 | B8: =IF(MAX(SUMIFS('Year NSE Equity Cash'!$I:$I,'Year NSE Equity Cash'!$A:$A,$A8),SUMIFS('Daily NSE Equity Cash'!$H:$H,'Daily NSE Equity Cash'!$A:$A,">="&DATE(VALUE(LEFT($A8,4)),4,1),'Daily NSE Equity Cash'!$A:$A,"<="&DATE(VALUE(RIGHT($A8,4)),3,31)))=0,"",MAX(SUMIFS('Year NSE Equity Cash'!$I:$I,'Year NSE Equity Cash'!$A:$A,$A8),SUMIFS('Daily NSE Equity Cash'!$H:$H,'Daily NSE Equity Cash'!$A:$A,">="&DATE(VALUE(LEFT($A8,4)),4,1),'Daily NSE Equity Cash'!$A:$A,"<="&DATE(VALUE(RIGHT($A8,4)),3,31)))) -> 13395.1 | C8: =IF(SUMIFS('Year BSE Equity Cash'!$F:$F,'Year BSE Equity Cash'!$A:$A,$A8)=0,"",SUMIFS('Year BSE Equity Cash'!$F:$F,'Year BSE Equity Cash'!$A:$A,$A8)) -> 10000.326 | D8: =IF(OR(B8="",C8=""),"",B8+C8) -> 23395.426 | E8: =IF(OR(B8="",B7=""),"",B8/B7-1) -> 0.59645648 | F8: =IF(OR(C8="",C7=""),"",C8/C7-1) -> 0.45686338 | G8: =IF(OR(D8="",D7=""),"",D8/D7-1) -> 0.53364303 | H8: =IF(D8="","",B8/D8) -> 0.57255208 | I8: =IF(D8="","",C8/D8) -> 0.42744792
A9: 2001-2002 | B9: =IF(MAX(SUMIFS('Year NSE Equity Cash'!$I:$I,'Year NSE Equity Cash'!$A:$A,$A9),SUMIFS('Daily NSE Equity Cash'!$H:$H,'Daily NSE Equity Cash'!$A:$A,">="&DATE(VALUE(LEFT($A9,4)),4,1),'Daily NSE Equity Cash'!$A:$A,"<="&DATE(VALUE(RIGHT($A9,4)),3,31)))=0,"",MAX(SUMIFS('Year NSE Equity Cash'!$I:$I,'Year NSE Equity Cash'!$A:$A,$A9),SUMIFS('Daily NSE Equity Cash'!$H:$H,'Daily NSE Equity Cash'!$A:$A,">="&DATE(VALUE(LEFT($A9,4)),4,1),'Daily NSE Equity Cash'!$A:$A,"<="&DATE(VALUE(RIGHT($A9,4)),3,31)))) -> 5131.67 | C9: =IF(SUMIFS('Year BSE Equity Cash'!$F:$F,'Year BSE Equity Cash'!$A:$A,$A9)=0,"",SUMIFS('Year BSE Equity Cash'!$F:$F,'Year BSE Equity Cash'!$A:$A,$A9)) -> 3072.9777 | D9: =IF(OR(B9="",C9=""),"",B9+C9) -> 8204.6477 | E9: =IF(OR(B9="",B8=""),"",B9/B8-1) -> -0.61689946 | F9: =IF(OR(C9="",C8=""),"",C9/C8-1) -> -0.69271225 | G9: =IF(OR(D9="",D8=""),"",D9/D8-1) -> -0.64930548 | H9: =IF(D9="","",B9/D9) -> 0.62545891 | I9: =IF(D9="","",C9/D9) -> 0.37454109
A10: 2002-2003 | B10: =IF(MAX(SUMIFS('Year NSE Equity Cash'!$I:$I,'Year NSE Equity Cash'!$A:$A,$A10),SUMIFS('Daily NSE Equity Cash'!$H:$H,'Daily NSE Equity Cash'!$A:$A,">="&DATE(VALUE(LEFT($A10,4)),4,1),'Daily NSE Equity Cash'!$A:$A,"<="&DATE(VALUE(RIGHT($A10,4)),3,31)))=0,"",MAX(SUMIFS('Year NSE Equity Cash'!$I:$I,'Year NSE Equity Cash'!$A:$A,$A10),SUMIFS('Daily NSE Equity Cash'!$H:$H,'Daily NSE Equity Cash'!$A:$A,">="&DATE(VALUE(LEFT($A10,4)),4,1),'Daily NSE Equity Cash'!$A:$A,"<="&DATE(VALUE(RIGHT($A10,4)),3,31)))) -> 6179.89 | C10: =IF(SUMIFS('Year BSE Equity Cash'!$F:$F,'Year BSE Equity Cash'!$A:$A,$A10)=0,"",SUMIFS('Year BSE Equity Cash'!$F:$F,'Year BSE Equity Cash'!$A:$A,$A10)) -> 3140.7313 | D10: =IF(OR(B10="",C10=""),"",B10+C10) -> 9320.6213 | E10: =IF(OR(B10="",B9=""),"",B10/B9-1) -> 0.20426489 | F10: =IF(OR(C10="",C9=""),"",C10/C9-1) -> 0.022048191 | G10: =IF(OR(D10="",D9=""),"",D10/D9-1) -> 0.13601725 | H10: =IF(D10="","",B10/D10) -> 0.66303413 | I10: =IF(D10="","",C10/D10) -> 0.33696587
A11: 2003-2004 | B11: =IF(MAX(SUMIFS('Year NSE Equity Cash'!$I:$I,'Year NSE Equity Cash'!$A:$A,$A11),SUMIFS('Daily NSE Equity Cash'!$H:$H,'Daily NSE Equity Cash'!$A:$A,">="&DATE(VALUE(LEFT($A11,4)),4,1),'Daily NSE Equity Cash'!$A:$A,"<="&DATE(VALUE(RIGHT($A11,4)),3,31)))=0,"",MAX(SUMIFS('Year NSE Equity Cash'!$I:$I,'Year NSE Equity Cash'!$A:$A,$A11),SUMIFS('Daily NSE Equity Cash'!$H:$H,'Daily NSE Equity Cash'!$A:$A,">="&DATE(VALUE(LEFT($A11,4)),4,1),'Daily NSE Equity Cash'!$A:$A,"<="&DATE(VALUE(RIGHT($A11,4)),3,31)))) -> 10995.35 | C11: =IF(SUMIFS('Year BSE Equity Cash'!$F:$F,'Year BSE Equity Cash'!$A:$A,$A11)=0,"",SUMIFS('Year BSE Equity Cash'!$F:$F,'Year BSE Equity Cash'!$A:$A,$A11)) -> 5026.1838 | D11: =IF(OR(B11="",C11=""),"",B11+C11) -> 16021.534 | E11: =IF(OR(B11="",B10=""),"",B11/B10-1) -> 0.77921452 | F11: =IF(OR(C11="",C10=""),"",C11/C10-1) -> 0.60032277 | G11: =IF(OR(D11="",D10=""),"",D11/D10-1) -> 0.7189341 | H11: =IF(D11="","",B11/D11) -> 0.68628573 | I11: =IF(D11="","",C11/D11) -> 0.31371427
A12: 2004-2005 | B12: =IF(MAX(SUMIFS('Year NSE Equity Cash'!$I:$I,'Year NSE Equity Cash'!$A:$A,$A12),SUMIFS('Daily NSE Equity Cash'!$H:$H,'Daily NSE Equity Cash'!$A:$A,">="&DATE(VALUE(LEFT($A12,4)),4,1),'Daily NSE Equity Cash'!$A:$A,"<="&DATE(VALUE(RIGHT($A12,4)),3,31)))=0,"",MAX(SUMIFS('Year NSE Equity Cash'!$I:$I,'Year NSE Equity Cash'!$A:$A,$A12),SUMIFS('Daily NSE Equity Cash'!$H:$H,'Daily NSE Equity Cash'!$A:$A,">="&DATE(VALUE(LEFT($A12,4)),4,1),'Daily NSE Equity Cash'!$A:$A,"<="&DATE(VALUE(RIGHT($A12,4)),3,31)))) -> 11400.71 | C12: =IF(SUMIFS('Year BSE Equity Cash'!$F:$F,'Year BSE Equity Cash'!$A:$A,$A12)=0,"",SUMIFS('Year BSE Equity Cash'!$F:$F,'Year BSE Equity Cash'!$A:$A,$A12)) -> 5187.1565 | D12: =IF(OR(B12="",C12=""),"",B12+C12) -> 16587.867 | E12: =IF(OR(B12="",B11=""),"",B12/B11-1) -> 0.036866494 | F12: =IF(OR(C12="",C11=""),"",C12/C11-1) -> 0.032026823 | G12: =IF(OR(D12="",D11=""),"",D12/D11-1) -> 0.03534822 | H12: =IF(D12="","",B12/D12) -> 0.68729212 | I12: =IF(D12="","",C12/D12) -> 0.31270788
A13: 2005-2006 | B13: =IF(MAX(SUMIFS('Year NSE Equity Cash'!$I:$I,'Year NSE Equity Cash'!$A:$A,$A13),SUMIFS('Daily NSE Equity Cash'!$H:$H,'Daily NSE Equity Cash'!$A:$A,">="&DATE(VALUE(LEFT($A13,4)),4,1),'Daily NSE Equity Cash'!$A:$A,"<="&DATE(VALUE(RIGHT($A13,4)),3,31)))=0,"",MAX(SUMIFS('Year NSE Equity Cash'!$I:$I,'Year NSE Equity Cash'!$A:$A,$A13),SUMIFS('Daily NSE Equity Cash'!$H:$H,'Daily NSE Equity Cash'!$A:$A,">="&DATE(VALUE(LEFT($A13,4)),4,1),'Daily NSE Equity Cash'!$A:$A,"<="&DATE(VALUE(RIGHT($A13,4)),3,31)))) -> 15695.58 | C13: =IF(SUMIFS('Year BSE Equity Cash'!$F:$F,'Year BSE Equity Cash'!$A:$A,$A13)=0,"",SUMIFS('Year BSE Equity Cash'!$F:$F,'Year BSE Equity Cash'!$A:$A,$A13)) -> 8160.847 | D13: =IF(OR(B13="",C13=""),"",B13+C13) -> 23856.427 | E13: =IF(OR(B13="",B12=""),"",B13/B12-1) -> 0.37671952 | F13: =IF(OR(C13="",C12=""),"",C13/C12-1) -> 0.5732795 | G13: =IF(OR(D13="",D12=""),"",D13/D12-1) -> 0.43818537 | H13: =IF(D13="","",B13/D13) -> 0.6579183 | I13: =IF(D13="","",C13/D13) -> 0.3420817
A14: 2006-2007 | B14: =IF(MAX(SUMIFS('Year NSE Equity Cash'!$I:$I,'Year NSE Equity Cash'!$A:$A,$A14),SUMIFS('Daily NSE Equity Cash'!$H:$H,'Daily NSE Equity Cash'!$A:$A,">="&DATE(VALUE(LEFT($A14,4)),4,1),'Daily NSE Equity Cash'!$A:$A,"<="&DATE(VALUE(RIGHT($A14,4)),3,31)))=0,"",MAX(SUMIFS('Year NSE Equity Cash'!$I:$I,'Year NSE Equity Cash'!$A:$A,$A14),SUMIFS('Daily NSE Equity Cash'!$H:$H,'Daily NSE Equity Cash'!$A:$A,">="&DATE(VALUE(LEFT($A14,4)),4,1),'Daily NSE Equity Cash'!$A:$A,"<="&DATE(VALUE(RIGHT($A14,4)),3,31)))) -> 19452.85 | C14: =IF(SUMIFS('Year BSE Equity Cash'!$F:$F,'Year BSE Equity Cash'!$A:$A,$A14)=0,"",SUMIFS('Year BSE Equity Cash'!$F:$F,'Year BSE Equity Cash'!$A:$A,$A14)) -> 9561.8911 | D14: =IF(OR(B14="",C14=""),"",B14+C14) -> 29014.741 | E14: =IF(OR(B14="",B13=""),"",B14/B13-1) -> 0.23938395 | F14: =IF(OR(C14="",C13=""),"",C14/C13-1) -> 0.17167876 | G14: =IF(OR(D14="",D13=""),"",D14/D13-1) -> 0.21622325 | H14: =IF(D14="","",B14/D14) -> 0.67044713 | I14: =IF(D14="","",C14/D14) -> 0.32955287
... A34: 2026-2027 | B34: =IF(MAX(SUMIFS('Year NSE Equity Cash'!$I:$I,'Year NSE Equity Cash'!$A:$A,$A34),SUMIFS('Daily NSE Equity Cash'!$H:$H,'Daily NSE Equity Cash'!$A:$A,">="&DATE(VALUE(LEFT($A34,4)),4,1),'Daily NSE Equity Cash'!$A:$A,"<="&DATE(VALUE(RIGHT($A34,4)),3,31)))=0,"",MAX(SUMIFS('Year NSE Equity Cash'!$I:$I,'Year NSE Equity Cash'!$A:$A,$A34),SUMIFS('Daily NSE Equity Cash'!$H:$H,'Daily NSE Equity Cash'!$A:$A,">="&DATE(VALUE(LEFT($A34,4)),4,1),'Daily NSE Equity Cash'!$A:$A,"<="&DATE(VALUE(RIGHT($A34,4)),3,31)))) -> 140096.37 | C34: =IF(SUMIFS('Year BSE Equity Cash'!$F:$F,'Year BSE Equity Cash'!$A:$A,$A34)=0,"",SUMIFS('Year BSE Equity Cash'!$F:$F,'Year BSE Equity Cash'!$A:$A,$A34)) -> 11094.718 | D34: =IF(OR(B34="",C34=""),"",B34+C34) -> 151191.09 | E34: =IF(OR(B34="",B33=""),"",B34/B33-1) -> -0.4624624 | F34: =IF(OR(C34="",C33=""),"",C34/C33-1) -> -0.43499433 | G34: =IF(OR(D34="",D33=""),"",D34/D33-1) -> -0.46053786 | H34: =IF(D34="","",B34/D34) -> 0.92661791 | I34: =IF(D34="","",C34/D34) -> 0.073382093
A36: YTD Comparison - FY2026-2027 YTD vs FY2025-2026 YTD (same number of trading days)
A37: Trading days elapsed in FY2026-2027 (per NSE daily) | B37: =COUNTIF('Daily NSE Equity Cash'!$A:$A,">="&DATE(2026,4,1)) -> 109
A38: Matched FY2025-2026 window | B38: =DATE(2025,4,1) -> 45748 | C38: =INDEX('Daily NSE Equity Cash'!$A:$A,COUNTIF('Daily NSE Equity Cash'!$A:$A,"<"&DATE(2025,4,1))+1+$B37) -> 45908
B39: NSE Turnover (INR Bn) | C39: BSE Turnover (INR Bn) | D39: Total Turnover (INR Bn) | H39: NSE Market Share | I39: BSE Market Share
A40: FY2025-2026 YTD (first N trading days) | B40: =SUMIFS('Daily NSE Equity Cash'!$H:$H,'Daily NSE Equity Cash'!$A:$A,">="&$B$38,'Daily NSE Equity Cash'!$A:$A,"<="&$C$38) -> 111256.13 | C40: =SUMIFS('Daily BSE Equity Cash'!$H:$H,'Daily BSE Equity Cash'!$A:$A,">="&$B$38,'Daily BSE Equity Cash'!$A:$A,"<="&$C$38) -> 8217.5111 | D40: =B40+C40 -> 119473.64 | H40: =IF(D40=0,"",B40/D40) -> 0.93121905 | I40: =IF(D40=0,"",C40/D40) -> 0.068780953
A41: FY2026-2027 YTD | B41: =SUMIFS('Daily NSE Equity Cash'!$H:$H,'Daily NSE Equity Cash'!$A:$A,">="&DATE(2026,4,1)) -> 140096.37 | C41: =SUMIFS('Daily BSE Equity Cash'!$H:$H,'Daily BSE Equity Cash'!$A:$A,">="&DATE(2026,4,1)) -> 11094.717 | D41: =B41+C41 -> 151191.08 | H41: =IF(D41=0,"",B41/D41) -> 0.92661791 | I41: =IF(D41=0,"",C41/D41) -> 0.073382088
A42: YTD Growth (FY2026-2027 vs FY2025-2026) | B42: =IF(OR(B40=0,B40=""),"",B41/B40-1) -> 0.25922376 | C42: =IF(OR(C40=0,C40=""),"",C41/C40-1) -> 0.35013111 | D42: =IF(OR(D40=0,D40=""),"",D41/D40-1) -> 0.26547646

Sheet Qrtr Eq Cash Turnover Mkt Share
A1: Qrtr - Year | B1: NSE Turnover (INR Bn) | C1: BSE Turnover (INR Bn) | D1: Total Turnover (INR Bn) | E1: NSE YoY Growth | F1: BSE YoY Growth | G1: Total Turnover YoY Growth | H1: NSE QoQ Growth | I1: BSE QoQ Growth | J1: Total Turnover QoQ Growth | K1: NSE Market Share | L1: BSE Market Share
A2: Q3FY98 | B2: =IF(MAX(SUMIFS('Monthly NSE Equity Cash'!$K:$K,'Monthly NSE Equity Cash'!$C:$C,$A2),SUMIFS('Daily NSE Equity Cash'!$H:$H,'Daily NSE Equity Cash'!$D:$D,$A2))=0,"",MAX(SUMIFS('Monthly NSE Equity Cash'!$K:$K,'Monthly NSE Equity Cash'!$C:$C,$A2),SUMIFS('Daily NSE Equity Cash'!$H:$H,'Daily NSE Equity Cash'!$D:$D,$A2))) | C2: =IF(SUMIFS('Monthly BSE Equity Cash'!$G:$G,'Monthly BSE Equity Cash'!$C:$C,$A2)=0,"",SUMIFS('Monthly BSE Equity Cash'!$G:$G,'Monthly BSE Equity Cash'!$C:$C,$A2)) -> 299.6254 | D2: =IF(OR(B2="",C2=""),"",B2+C2) | K2: =IF(D2="","",B2/D2) | L2: =IF(D2="","",C2/D2)
A3: Q4FY98 | B3: =IF(MAX(SUMIFS('Monthly NSE Equity Cash'!$K:$K,'Monthly NSE Equity Cash'!$C:$C,$A3),SUMIFS('Daily NSE Equity Cash'!$H:$H,'Daily NSE Equity Cash'!$D:$D,$A3))=0,"",MAX(SUMIFS('Monthly NSE Equity Cash'!$K:$K,'Monthly NSE Equity Cash'!$C:$C,$A3),SUMIFS('Daily NSE Equity Cash'!$H:$H,'Daily NSE Equity Cash'!$D:$D,$A3))) | C3: =IF(SUMIFS('Monthly BSE Equity Cash'!$G:$G,'Monthly BSE Equity Cash'!$C:$C,$A3)=0,"",SUMIFS('Monthly BSE Equity Cash'!$G:$G,'Monthly BSE Equity Cash'!$C:$C,$A3)) -> 569.3662 | D3: =IF(OR(B3="",C3=""),"",B3+C3) | H3: =IF(OR(B3="",B2=""),"",B3/B2-1) | I3: =IF(OR(C3="",C2=""),"",C3/C2-1) -> 0.90026012 | J3: =IF(OR(D3="",D2=""),"",D3/D2-1) | K3: =IF(D3="","",B3/D3) | L3: =IF(D3="","",C3/D3)
A4: Q1FY99 | B4: =IF(MAX(SUMIFS('Monthly NSE Equity Cash'!$K:$K,'Monthly NSE Equity Cash'!$C:$C,$A4),SUMIFS('Daily NSE Equity Cash'!$H:$H,'Daily NSE Equity Cash'!$D:$D,$A4))=0,"",MAX(SUMIFS('Monthly NSE Equity Cash'!$K:$K,'Monthly NSE Equity Cash'!$C:$C,$A4),SUMIFS('Daily NSE Equity Cash'!$H:$H,'Daily NSE Equity Cash'!$D:$D,$A4))) | C4: =IF(SUMIFS('Monthly BSE Equity Cash'!$G:$G,'Monthly BSE Equity Cash'!$C:$C,$A4)=0,"",SUMIFS('Monthly BSE Equity Cash'!$G:$G,'Monthly BSE Equity Cash'!$C:$C,$A4)) -> 452.6481 | D4: =IF(OR(B4="",C4=""),"",B4+C4) | H4: =IF(OR(B4="",B3=""),"",B4/B3-1) | I4: =IF(OR(C4="",C3=""),"",C4/C3-1) -> -0.20499654 | J4: =IF(OR(D4="",D3=""),"",D4/D3-1) | K4: =IF(D4="","",B4/D4) | L4: =IF(D4="","",C4/D4)
A5: Q2FY99 | B5: =IF(MAX(SUMIFS('Monthly NSE Equity Cash'!$K:$K,'Monthly NSE Equity Cash'!$C:$C,$A5),SUMIFS('Daily NSE Equity Cash'!$H:$H,'Daily NSE Equity Cash'!$D:$D,$A5))=0,"",MAX(SUMIFS('Monthly NSE Equity Cash'!$K:$K,'Monthly NSE Equity Cash'!$C:$C,$A5),SUMIFS('Daily NSE Equity Cash'!$H:$H,'Daily NSE Equity Cash'!$D:$D,$A5))) | C5: =IF(SUMIFS('Monthly BSE Equity Cash'!$G:$G,'Monthly BSE Equity Cash'!$C:$C,$A5)=0,"",SUMIFS('Monthly BSE Equity Cash'!$G:$G,'Monthly BSE Equity Cash'!$C:$C,$A5)) -> 670.9652 | D5: =IF(OR(B5="",C5=""),"",B5+C5) | H5: =IF(OR(B5="",B4=""),"",B5/B4-1) | I5: =IF(OR(C5="",C4=""),"",C5/C4-1) -> 0.48231087 | J5: =IF(OR(D5="",D4=""),"",D5/D4-1) | K5: =IF(D5="","",B5/D5) | L5: =IF(D5="","",C5/D5)
A6: Q3FY99 | B6: =IF(MAX(SUMIFS('Monthly NSE Equity Cash'!$K:$K,'Monthly NSE Equity Cash'!$C:$C,$A6),SUMIFS('Daily NSE Equity Cash'!$H:$H,'Daily NSE Equity Cash'!$D:$D,$A6))=0,"",MAX(SUMIFS('Monthly NSE Equity Cash'!$K:$K,'Monthly NSE Equity Cash'!$C:$C,$A6),SUMIFS('Daily NSE Equity Cash'!$H:$H,'Daily NSE Equity Cash'!$D:$D,$A6))) | C6: =IF(SUMIFS('Monthly BSE Equity Cash'!$G:$G,'Monthly BSE Equity Cash'!$C:$C,$A6)=0,"",SUMIFS('Monthly BSE Equity Cash'!$G:$G,'Monthly BSE Equity Cash'!$C:$C,$A6)) -> 692.7328 | D6: =IF(OR(B6="",C6=""),"",B6+C6) | E6: =IF(OR(B6="",B2=""),"",B6/B2-1) | F6: =IF(OR(C6="",C2=""),"",C6/C2-1) -> 1.3119962 | G6: =IF(OR(D6="",D2=""),"",D6/D2-1) | H6: =IF(OR(B6="",B5=""),"",B6/B5-1) | I6: =IF(OR(C6="",C5=""),"",C6/C5-1) -> 0.032442219 | J6: =IF(OR(D6="",D5=""),"",D6/D5-1) | K6: =IF(D6="","",B6/D6) | L6: =IF(D6="","",C6/D6)
A7: Q4FY99 | B7: =IF(MAX(SUMIFS('Monthly NSE Equity Cash'!$K:$K,'Monthly NSE Equity Cash'!$C:$C,$A7),SUMIFS('Daily NSE Equity Cash'!$H:$H,'Daily NSE Equity Cash'!$D:$D,$A7))=0,"",MAX(SUMIFS('Monthly NSE Equity Cash'!$K:$K,'Monthly NSE Equity Cash'!$C:$C,$A7),SUMIFS('Daily NSE Equity Cash'!$H:$H,'Daily NSE Equity Cash'!$D:$D,$A7))) | C7: =IF(SUMIFS('Monthly BSE Equity Cash'!$G:$G,'Monthly BSE Equity Cash'!$C:$C,$A7)=0,"",SUMIFS('Monthly BSE Equity Cash'!$G:$G,'Monthly BSE Equity Cash'!$C:$C,$A7)) -> 1030.0226 | D7: =IF(OR(B7="",C7=""),"",B7+C7) | E7: =IF(OR(B7="",B3=""),"",B7/B3-1) | F7: =IF(OR(C7="",C3=""),"",C7/C3-1) -> 0.80906875 | G7: =IF(OR(D7="",D3=""),"",D7/D3-1) | H7: =IF(OR(B7="",B6=""),"",B7/B6-1) | I7: =IF(OR(C7="",C6=""),"",C7/C6-1) -> 0.4868974 | J7: =IF(OR(D7="",D6=""),"",D7/D6-1) | K7: =IF(D7="","",B7/D7) | L7: =IF(D7="","",C7/D7)
A8: Q1FY00 | B8: =IF(MAX(SUMIFS('Monthly NSE Equity Cash'!$K:$K,'Monthly NSE Equity Cash'!$C:$C,$A8),SUMIFS('Daily NSE Equity Cash'!$H:$H,'Daily NSE Equity Cash'!$D:$D,$A8))=0,"",MAX(SUMIFS('Monthly NSE Equity Cash'!$K:$K,'Monthly NSE Equity Cash'!$C:$C,$A8),SUMIFS('Daily NSE Equity Cash'!$H:$H,'Daily NSE Equity Cash'!$D:$D,$A8))) -> 1266.69 | C8: =IF(SUMIFS('Monthly BSE Equity Cash'!$G:$G,'Monthly BSE Equity Cash'!$C:$C,$A8)=0,"",SUMIFS('Monthly BSE Equity Cash'!$G:$G,'Monthly BSE Equity Cash'!$C:$C,$A8)) -> 964.776 | D8: =IF(OR(B8="",C8=""),"",B8+C8) -> 2231.466 | E8: =IF(OR(B8="",B4=""),"",B8/B4-1) | F8: =IF(OR(C8="",C4=""),"",C8/C4-1) -> 1.1314041 | G8: =IF(OR(D8="",D4=""),"",D8/D4-1) | H8: =IF(OR(B8="",B7=""),"",B8/B7-1) | I8: =IF(OR(C8="",C7=""),"",C8/C7-1) -> -0.063344824 | J8: =IF(OR(D8="",D7=""),"",D8/D7-1) | K8: =IF(D8="","",B8/D8) -> 0.56764925 | L8: =IF(D8="","",C8/D8) -> 0.43235075
A9: Q2FY00 | B9: =IF(MAX(SUMIFS('Monthly NSE Equity Cash'!$K:$K,'Monthly NSE Equity Cash'!$C:$C,$A9),SUMIFS('Daily NSE Equity Cash'!$H:$H,'Daily NSE Equity Cash'!$D:$D,$A9))=0,"",MAX(SUMIFS('Monthly NSE Equity Cash'!$K:$K,'Monthly NSE Equity Cash'!$C:$C,$A9),SUMIFS('Daily NSE Equity Cash'!$H:$H,'Daily NSE Equity Cash'!$D:$D,$A9))) -> 1650.32 | C9: =IF(SUMIFS('Monthly BSE Equity Cash'!$G:$G,'Monthly BSE Equity Cash'!$C:$C,$A9)=0,"",SUMIFS('Monthly BSE Equity Cash'!$G:$G,'Monthly BSE Equity Cash'!$C:$C,$A9)) -> 1432.1419 | D9: =IF(OR(B9="",C9=""),"",B9+C9) -> 3082.4619 | E9: =IF(OR(B9="",B5=""),"",B9/B5-1) | F9: =IF(OR(C9="",C5=""),"",C9/C5-1) -> 1.1344503 | G9: =IF(OR(D9="",D5=""),"",D9/D5-1) | H9: =IF(OR(B9="",B8=""),"",B9/B8-1) -> 0.30286021 | I9: =IF(OR(C9="",C8=""),"",C9/C8-1) -> 0.48442944 | J9: =IF(OR(D9="",D8=""),"",D9/D8-1) -> 0.3813618 | K9: =IF(D9="","",B9/D9) -> 0.53539023 | L9: =IF(D9="","",C9/D9) -> 0.46460977
A10: Q3FY00 | B10: =IF(MAX(SUMIFS('Monthly NSE Equity Cash'!$K:$K,'Monthly NSE Equity Cash'!$C:$C,$A10),SUMIFS('Daily NSE Equity Cash'!$H:$H,'Daily NSE Equity Cash'!$D:$D,$A10))=0,"",MAX(SUMIFS('Monthly NSE Equity Cash'!$K:$K,'Monthly NSE Equity Cash'!$C:$C,$A10),SUMIFS('Daily NSE Equity Cash'!$H:$H,'Daily NSE Equity Cash'!$D:$D,$A10))) -> 2371.32 | C10: =IF(SUMIFS('Monthly BSE Equity Cash'!$G:$G,'Monthly BSE Equity Cash'!$C:$C,$A10)=0,"",SUMIFS('Monthly BSE Equity Cash'!$G:$G,'Monthly BSE Equity Cash'!$C:$C,$A10)) -> 1852.6767 | D10: =IF(OR(B10="",C10=""),"",B10+C10) -> 4223.9967 | E10: =IF(OR(B10="",B6=""),"",B10/B6-1) | F10: =IF(OR(C10="",C6=""),"",C10/C6-1) -> 1.6744463 | G10: =IF(OR(D10="",D6=""),"",D10/D6-1) | H10: =IF(OR(B10="",B9=""),"",B10/B9-1) -> 0.43688497 | I10: =IF(OR(C10="",C9=""),"",C10/C9-1) -> 0.29364046 | J10: =IF(OR(D10="",D9=""),"",D10/D9-1) -> 0.37033217 | K10: =IF(D10="","",B10/D10) -> 0.56139248 | L10: =IF(D10="","",C10/D10) -> 0.43860752
A11: Q4FY00 | B11: =IF(MAX(SUMIFS('Monthly NSE Equity Cash'!$K:$K,'Monthly NSE Equity Cash'!$C:$C,$A11),SUMIFS('Daily NSE Equity Cash'!$H:$H,'Daily NSE Equity Cash'!$D:$D,$A11))=0,"",MAX(SUMIFS('Monthly NSE Equity Cash'!$K:$K,'Monthly NSE Equity Cash'!$C:$C,$A11),SUMIFS('Daily NSE Equity Cash'!$H:$H,'Daily NSE Equity Cash'!$D:$D,$A11))) -> 3102.17 | C11: =IF(SUMIFS('Monthly BSE Equity Cash'!$G:$G,'Monthly BSE Equity Cash'!$C:$C,$A11)=0,"",SUMIFS('Monthly BSE Equity Cash'!$G:$G,'Monthly BSE Equity Cash'!$C:$C,$A11)) -> 2614.6909 | D11: =IF(OR(B11="",C11=""),"",B11+C11) -> 5716.8609 | E11: =IF(OR(B11="",B7=""),"",B11/B7-1) | F11: =IF(OR(C11="",C7=""),"",C11/C7-1) -> 1.5384792 | G11: =IF(OR(D11="",D7=""),"",D11/D7-1) | H11: =IF(OR(B11="",B10=""),"",B11/B10-1) -> 0.30820387 | I11: =IF(OR(C11="",C10=""),"",C11/C10-1) -> 0.41130447 | J11: =IF(OR(D11="",D10=""),"",D11/D10-1) -> 0.35342457 | K11: =IF(D11="","",B11/D11) -> 0.54263521 | L11: =IF(D11="","",C11/D11) -> 0.45736479
A12: Q1FY01 | B12: =IF(MAX(SUMIFS('Monthly NSE Equity Cash'!$K:$K,'Monthly NSE Equity Cash'!$C:$C,$A12),SUMIFS('Daily NSE Equity Cash'!$H:$H,'Daily NSE Equity Cash'!$D:$D,$A12))=0,"",MAX(SUMIFS('Monthly NSE Equity Cash'!$K:$K,'Monthly NSE Equity Cash'!$C:$C,$A12),SUMIFS('Daily NSE Equity Cash'!$H:$H,'Daily NSE Equity Cash'!$D:$D,$A12))) -> 2556.39 | C12: =IF(SUMIFS('Monthly BSE Equity Cash'!$G:$G,'Monthly BSE Equity Cash'!$C:$C,$A12)=0,"",SUMIFS('Monthly BSE Equity Cash'!$G:$G,'Monthly BSE Equity Cash'!$C:$C,$A12)) -> 1887.704 | D12: =IF(OR(B12="",C12=""),"",B12+C12) -> 4444.094 | E12: =IF(OR(B12="",B8=""),"",B12/B8-1) -> 1.0181655 | F12: =IF(OR(C12="",C8=""),"",C12/C8-1) -> 0.95662413 | G12: =IF(OR(D12="",D8=""),"",D12/D8-1) -> 0.99155802 | H12: =IF(OR(B12="",B11=""),"",B12/B11-1) -> -0.17593491 | I12: =IF(OR(C12="",C11=""),"",C12/C11-1) -> -0.27803933 | J12: =IF(OR(D12="",D11=""),"",D12/D11-1) -> -0.22263388 | K12: =IF(D12="","",B12/D12) -> 0.57523311 | L12: =IF(D12="","",C12/D12) -> 0.42476689
A13: Q2FY01 | B13: =IF(MAX(SUMIFS('Monthly NSE Equity Cash'!$K:$K,'Monthly NSE Equity Cash'!$C:$C,$A13),SUMIFS('Daily NSE Equity Cash'!$H:$H,'Daily NSE Equity Cash'!$D:$D,$A13))=0,"",MAX(SUMIFS('Monthly NSE Equity Cash'!$K:$K,'Monthly NSE Equity Cash'!$C:$C,$A13),SUMIFS('Daily NSE Equity Cash'!$H:$H,'Daily NSE Equity Cash'!$D:$D,$A13))) -> 3778.83 | C13: =IF(SUMIFS('Monthly BSE Equity Cash'!$G:$G,'Monthly BSE Equity Cash'!$C:$C,$A13)=0,"",SUMIFS('Monthly BSE Equity Cash'!$G:$G,'Monthly BSE Equity Cash'!$C:$C,$A13)) -> 2873.4186 | D13: =IF(OR(B13="",C13=""),"",B13+C13) -> 6652.2486 | E13: =IF(OR(B13="",B9=""),"",B13/B9-1) -> 1.2897559 | F13: =IF(OR(C13="",C9=""),"",C13/C9-1) -> 1.0063784 | G13: =IF(OR(D13="",D9=""),"",D13/D9-1) -> 1.158096 | H13: =IF(OR(B13="",B12=""),"",B13/B12-1) -> 0.47818995 | I13: =IF(OR(C13="",C12=""),"",C13/C12-1) -> 0.52217646 | J13: =IF(OR(D13="",D12=""),"",D13/D12-1) -> 0.49687396 | K13: =IF(D13="","",B13/D13) -> 0.56805303 | L13: =IF(D13="","",C13/D13) -> 0.43194697
A14: Q3FY01 | B14: =IF(MAX(SUMIFS('Monthly NSE Equity Cash'!$K:$K,'Monthly NSE Equity Cash'!$C:$C,$A14),SUMIFS('Daily NSE Equity Cash'!$H:$H,'Daily NSE Equity Cash'!$D:$D,$A14))=0,"",MAX(SUMIFS('Monthly NSE Equity Cash'!$K:$K,'Monthly NSE Equity Cash'!$C:$C,$A14),SUMIFS('Daily NSE Equity Cash'!$H:$H,'Daily NSE Equity Cash'!$D:$D,$A14))) -> 3610 | C14: =IF(SUMIFS('Monthly BSE Equity Cash'!$G:$G,'Monthly BSE Equity Cash'!$C:$C,$A14)=0,"",SUMIFS('Monthly BSE Equity Cash'!$G:$G,'Monthly BSE Equity Cash'!$C:$C,$A14)) -> 2624.7436 | D14: =IF(OR(B14="",C14=""),"",B14+C14) -> 6234.7436 | E14: =IF(OR(B14="",B10=""),"",B14/B10-1) -> 0.52235885 | F14: =IF(OR(C14="",C10=""),"",C14/C10-1) -> 0.41673051 | G14: =IF(OR(D14="",D10=""),"",D14/D10-1) -> 0.47602947 | H14: =IF(OR(B14="",B13=""),"",B14/B13-1) -> -0.04467785 | I14: =IF(OR(C14="",C13=""),"",C14/C13-1) -> -0.086543255 | J14: =IF(OR(D14="",D13=""),"",D14/D13-1) -> -0.062761485 | K14: =IF(D14="","",B14/D14) -> 0.57901339 | L14: =IF(D14="","",C14/D14) -> 0.42098661
A15: Q4FY01 | B15: =IF(MAX(SUMIFS('Monthly NSE Equity Cash'!$K:$K,'Monthly NSE Equity Cash'!$C:$C,$A15),SUMIFS('Daily NSE Equity Cash'!$H:$H,'Daily NSE Equity Cash'!$D:$D,$A15))=0,"",MAX(SUMIFS('Monthly NSE Equity Cash'!$K:$K,'Monthly NSE Equity Cash'!$C:$C,$A15),SUMIFS('Daily NSE Equity Cash'!$H:$H,'Daily NSE Equity Cash'!$D:$D,$A15))) -> 3449.88 | C15: =IF(SUMIFS('Monthly BSE Equity Cash'!$G:$G,'Monthly BSE Equity Cash'!$C:$C,$A15)=0,"",SUMIFS('Monthly BSE Equity Cash'!$G:$G,'Monthly BSE Equity Cash'!$C:$C,$A15)) -> 2614.46 | D15: =IF(OR(B15="",C15=""),"",B15+C15) -> 6064.34 | E15: =IF(OR(B15="",B11=""),"",B15/B11-1) -> 0.11208606 | F15: =IF(OR(C15="",C11=""),"",C15/C11-1) -> -8.8308717e-05 | G15: =IF(OR(D15="",D11=""),"",D15/D11-1) -> 0.060781451 | H15: =IF(OR(B15="",B14=""),"",B15/B14-1) -> -0.044354571 | I15: =IF(OR(C15="",C14=""),"",C15/C14-1) -> -0.0039179446 | J15: =IF(OR(D15="",D14=""),"",D15/D14-1) -> -0.027331292 | K15: =IF(D15="","",B15/D15) -> 0.56887971 | L15: =IF(D15="","",C15/D15) -> 0.43112029
A16: Q1FY02 | B16: =IF(MAX(SUMIFS('Monthly NSE Equity Cash'!$K:$K,'Monthly NSE Equity Cash'!$C:$C,$A16),SUMIFS('Daily NSE Equity Cash'!$H:$H,'Daily NSE Equity Cash'!$D:$D,$A16))=0,"",MAX(SUMIFS('Monthly NSE Equity Cash'!$K:$K,'Monthly NSE Equity Cash'!$C:$C,$A16),SUMIFS('Daily NSE Equity Cash'!$H:$H,'Daily NSE Equity Cash'!$D:$D,$A16))) -> 1267.28 | C16: =IF(SUMIFS('Monthly BSE Equity Cash'!$G:$G,'Monthly BSE Equity Cash'!$C:$C,$A16)=0,"",SUMIFS('Monthly BSE Equity Cash'!$G:$G,'Monthly BSE Equity Cash'!$C:$C,$A16)) -> 811.9537 | D16: =IF(OR(B16="",C16=""),"",B16+C16) -> 2079.2337 | E16: =IF(OR(B16="",B12=""),"",B16/B12-1) -> -0.50426969 | F16: =IF(OR(C16="",C12=""),"",C16/C12-1) -> -0.56987234 | G16: =IF(OR(D16="",D12=""),"",D16/D12-1) -> -0.53213553 | H16: =IF(OR(B16="",B15=""),"",B16/B15-1) -> -0.63265969 | I16: =IF(OR(C16="",C15=""),"",C16/C15-1) -> -0.68943732 | J16: =IF(OR(D16="",D15=""),"",D16/D15-1) -> -0.65713768 | K16: =IF(D16="","",B16/D16) -> 0.60949378 | L16: =IF(D16="","",C16/D16) -> 0.39050622
A17: Q2FY02 | B17: =IF(MAX(SUMIFS('Monthly NSE Equity Cash'!$K:$K,'Monthly NSE Equity Cash'!$C:$C,$A17),SUMIFS('Daily NSE Equity Cash'!$H:$H,'Daily NSE Equity Cash'!$D:$D,$A17))=0,"",MAX(SUMIFS('Monthly NSE Equity Cash'!$K:$K,'Monthly NSE Equity Cash'!$C:$C,$A17),SUMIFS('Daily NSE Equity Cash'!$H:$H,'Daily NSE Equity Cash'!$D:$D,$A17))) -> 919.68 | C17: =IF(SUMIFS('Monthly BSE Equity Cash'!$G:$G,'Monthly BSE Equity Cash'!$C:$C,$A17)=0,"",SUMIFS('Monthly BSE Equity Cash'!$G:$G,'Monthly BSE Equity Cash'!$C:$C,$A17)) -> 562.8124 | D17: =IF(OR(B17="",C17=""),"",B17+C17) -> 1482.4924 | E17: =IF(OR(B17="",B13=""),"",B17/B13-1) -> -0.75662308 | F17: =IF(OR(C17="",C13=""),"",C17/C13-1) -> -0.80413143 | G17: =IF(OR(D17="",D13=""),"",D17/D13-1) -> -0.77714417 | H17: =IF(OR(B17="",B16=""),"",B17/B16-1) -> -0.27428824 | I17: =IF(OR(C17="",C16=""),"",C17/C16-1) -> -0.30684176 | J17: =IF(OR(D17="",D16=""),"",D17/D16-1) -> -0.28700059 | K17: =IF(D17="","",B17/D17) -> 0.62036068 | L17: =IF(D17="","",C17/D17) -> 0.37963932
... A117: Q2FY27 | B117: =IF(MAX(SUMIFS('Monthly NSE Equity Cash'!$K:$K,'Monthly NSE Equity Cash'!$C:$C,$A117),SUMIFS('Daily NSE Equity Cash'!$H:$H,'Daily NSE Equity Cash'!$D:$D,$A117))=0,"",MAX(SUMIFS('Monthly NSE Equity Cash'!$K:$K,'Monthly NSE Equity Cash'!$C:$C,$A117),SUMIFS('Daily NSE Equity Cash'!$H:$H,'Daily NSE Equity Cash'!$D:$D,$A117))) -> 58527.129 | C117: =IF(SUMIFS('Monthly BSE Equity Cash'!$G:$G,'Monthly BSE Equity Cash'!$C:$C,$A117)=0,"",SUMIFS('Monthly BSE Equity Cash'!$G:$G,'Monthly BSE Equity Cash'!$C:$C,$A117)) -> 5121.5337 | D117: =IF(OR(B117="",C117=""),"",B117+C117) -> 63648.663 | E117: =IF(OR(B117="",B113=""),"",B117/B113-1) -> -0.044475623 | F117: =IF(OR(C117="",C113=""),"",C117/C113-1) -> 0.0042769583 | G117: =IF(OR(D117="",D113=""),"",D117/D113-1) -> -0.040728513 | H117: =IF(OR(B117="",B116=""),"",B117/B116-1) -> -0.28248529 | I117: =IF(OR(C117="",C116=""),"",C117/C116-1) -> -0.14257904 | J117: =IF(OR(D117="",D116=""),"",D117/D116-1) -> -0.27293922 | K117: =IF(D117="","",B117/D117) -> 0.91953431 | L117: =IF(D117="","",C117/D117) -> 0.080465692
A119: QTD Comparison - Q2FY27 QTD vs Q2FY26 QTD (same number of trading days)
A120: Trading days elapsed in Q2FY27 (per NSE daily) | B120: =COUNTIF('Daily NSE Equity Cash'!$A:$A,">="&DATE(2026,7,1)) -> 49
A121: Matched Q2FY26 window | B121: =DATE(2025,7,1) -> 45839 | C121: =INDEX('Daily NSE Equity Cash'!$A:$A,COUNTIF('Daily NSE Equity Cash'!$A:$A,"<"&DATE(2025,7,1))+1+$B120) -> 45909
B122: NSE Turnover (INR Bn) | C122: BSE Turnover (INR Bn) | D122: Total Turnover (INR Bn) | K122: NSE Market Share | L122: BSE Market Share
A123: Q2FY26 QTD (first N trading days) | B123: =SUMIFS('Daily NSE Equity Cash'!$H:$H,'Daily NSE Equity Cash'!$A:$A,">="&$B$121,'Daily NSE Equity Cash'!$A:$A,"<="&$C$121) -> 45844.493 | C123: =SUMIFS('Daily BSE Equity Cash'!$H:$H,'Daily BSE Equity Cash'!$A:$A,">="&$B$121,'Daily BSE Equity Cash'!$A:$A,"<="&$C$121) -> 3908.3072 | D123: =B123+C123 -> 49752.801 | K123: =IF(D123=0,"",B123/D123) -> 0.92144548 | L123: =IF(D123=0,"",C123/D123) -> 0.078554517
A124: Q2FY27 QTD | B124: =SUMIFS('Daily NSE Equity Cash'!$H:$H,'Daily NSE Equity Cash'!$A:$A,">="&DATE(2026,7,1)) -> 58527.129 | C124: =SUMIFS('Daily BSE Equity Cash'!$H:$H,'Daily BSE Equity Cash'!$A:$A,">="&DATE(2026,7,1)) -> 5121.533 | D124: =B124+C124 -> 63648.662 | K124: =IF(D124=0,"",B124/D124) -> 0.91953432 | L124: =IF(D124=0,"",C124/D124) -> 0.080465682
A125: QTD Growth (Q2FY27 vs Q2FY26) | B125: =IF(OR(B123=0,B123=""),"",B124/B123-1) -> 0.2766447 | C125: =IF(OR(C123=0,C123=""),"",C124/C123-1) -> 0.31042232 | D125: =IF(OR(D123=0,D123=""),"",D124/D123-1) -> 0.27929808

Sheet Mth Eq Cash Turnover Mkt Share
A1: Month | B1: Fiscal Year | C1: Qrtr - Year | D1: NSE Turnover (INR Bn) | E1: BSE Turnover (INR Bn) | F1: Total Turnover (INR Bn) | G1: NSE YoY Growth | H1: BSE YoY Growth | I1: Total Turnover YoY Growth | J1: NSE MoM Growth | K1: BSE MoM Growth | L1: Total Turnover MoM Growth | M1: NSE Market Share | N1: BSE Market Share
A2: 35735 | B2: 1997-1998 | C2: Q3FY98 | D2: =IF(MAX(SUMIFS('Monthly NSE Equity Cash'!$K:$K,'Monthly NSE Equity Cash'!$A:$A,$A2),SUMIFS('Daily NSE Equity Cash'!$H:$H,'Daily NSE Equity Cash'!$C:$C,$A2))=0,"",MAX(SUMIFS('Monthly NSE Equity Cash'!$K:$K,'Monthly NSE Equity Cash'!$A:$A,$A2),SUMIFS('Daily NSE Equity Cash'!$H:$H,'Daily NSE Equity Cash'!$C:$C,$A2))) | E2: =IF(SUMIFS('Monthly BSE Equity Cash'!$G:$G,'Monthly BSE Equity Cash'!$A:$A,$A2)=0,"",SUMIFS('Monthly BSE Equity Cash'!$G:$G,'Monthly BSE Equity Cash'!$A:$A,$A2)) -> 118.8862 | F2: =IF(OR(D2="",E2=""),"",D2+E2) | M2: =IF(F2="","",D2/F2) | N2: =IF(F2="","",E2/F2)
A3: 35765 | B3: 1997-1998 | C3: Q3FY98 | D3: =IF(MAX(SUMIFS('Monthly NSE Equity Cash'!$K:$K,'Monthly NSE Equity Cash'!$A:$A,$A3),SUMIFS('Daily NSE Equity Cash'!$H:$H,'Daily NSE Equity Cash'!$C:$C,$A3))=0,"",MAX(SUMIFS('Monthly NSE Equity Cash'!$K:$K,'Monthly NSE Equity Cash'!$A:$A,$A3),SUMIFS('Daily NSE Equity Cash'!$H:$H,'Daily NSE Equity Cash'!$C:$C,$A3))) | E3: =IF(SUMIFS('Monthly BSE Equity Cash'!$G:$G,'Monthly BSE Equity Cash'!$A:$A,$A3)=0,"",SUMIFS('Monthly BSE Equity Cash'!$G:$G,'Monthly BSE Equity Cash'!$A:$A,$A3)) -> 180.7392 | F3: =IF(OR(D3="",E3=""),"",D3+E3) | J3: =IF(OR(D3="",D2=""),"",D3/D2-1) | K3: =IF(OR(E3="",E2=""),"",E3/E2-1) -> 0.52027065 | L3: =IF(OR(F3="",F2=""),"",F3/F2-1) | M3: =IF(F3="","",D3/F3) | N3: =IF(F3="","",E3/F3)
A4: 35796 | B4: 1997-1998 | C4: Q4FY98 | D4: =IF(MAX(SUMIFS('Monthly NSE Equity Cash'!$K:$K,'Monthly NSE Equity Cash'!$A:$A,$A4),SUMIFS('Daily NSE Equity Cash'!$H:$H,'Daily NSE Equity Cash'!$C:$C,$A4))=0,"",MAX(SUMIFS('Monthly NSE Equity Cash'!$K:$K,'Monthly NSE Equity Cash'!$A:$A,$A4),SUMIFS('Daily NSE Equity Cash'!$H:$H,'Daily NSE Equity Cash'!$C:$C,$A4))) | E4: =IF(SUMIFS('Monthly BSE Equity Cash'!$G:$G,'Monthly BSE Equity Cash'!$A:$A,$A4)=0,"",SUMIFS('Monthly BSE Equity Cash'!$G:$G,'Monthly BSE Equity Cash'!$A:$A,$A4)) -> 173.5888 | F4: =IF(OR(D4="",E4=""),"",D4+E4) | J4: =IF(OR(D4="",D3=""),"",D4/D3-1) | K4: =IF(OR(E4="",E3=""),"",E4/E3-1) -> -0.039561977 | L4: =IF(OR(F4="",F3=""),"",F4/F3-1) | M4: =IF(F4="","",D4/F4) | N4: =IF(F4="","",E4/F4)
A5: 35827 | B5: 1997-1998 | C5: Q4FY98 | D5: =IF(MAX(SUMIFS('Monthly NSE Equity Cash'!$K:$K,'Monthly NSE Equity Cash'!$A:$A,$A5),SUMIFS('Daily NSE Equity Cash'!$H:$H,'Daily NSE Equity Cash'!$C:$C,$A5))=0,"",MAX(SUMIFS('Monthly NSE Equity Cash'!$K:$K,'Monthly NSE Equity Cash'!$A:$A,$A5),SUMIFS('Daily NSE Equity Cash'!$H:$H,'Daily NSE Equity Cash'!$C:$C,$A5))) | E5: =IF(SUMIFS('Monthly BSE Equity Cash'!$G:$G,'Monthly BSE Equity Cash'!$A:$A,$A5)=0,"",SUMIFS('Monthly BSE Equity Cash'!$G:$G,'Monthly BSE Equity Cash'!$A:$A,$A5)) -> 164.0306 | F5: =IF(OR(D5="",E5=""),"",D5+E5) | J5: =IF(OR(D5="",D4=""),"",D5/D4-1) | K5: =IF(OR(E5="",E4=""),"",E5/E4-1) -> -0.055062308 | L5: =IF(OR(F5="",F4=""),"",F5/F4-1) | M5: =IF(F5="","",D5/F5) | N5: =IF(F5="","",E5/F5)
A6: 35855 | B6: 1997-1998 | C6: Q4FY98 | D6: =IF(MAX(SUMIFS('Monthly NSE Equity Cash'!$K:$K,'Monthly NSE Equity Cash'!$A:$A,$A6),SUMIFS('Daily NSE Equity Cash'!$H:$H,'Daily NSE Equity Cash'!$C:$C,$A6))=0,"",MAX(SUMIFS('Monthly NSE Equity Cash'!$K:$K,'Monthly NSE Equity Cash'!$A:$A,$A6),SUMIFS('Daily NSE Equity Cash'!$H:$H,'Daily NSE Equity Cash'!$C:$C,$A6))) | E6: =IF(SUMIFS('Monthly BSE Equity Cash'!$G:$G,'Monthly BSE Equity Cash'!$A:$A,$A6)=0,"",SUMIFS('Monthly BSE Equity Cash'!$G:$G,'Monthly BSE Equity Cash'!$A:$A,$A6)) -> 231.7468 | F6: =IF(OR(D6="",E6=""),"",D6+E6) | J6: =IF(OR(D6="",D5=""),"",D6/D5-1) | K6: =IF(OR(E6="",E5=""),"",E6/E5-1) -> 0.41282663 | L6: =IF(OR(F6="",F5=""),"",F6/F5-1) | M6: =IF(F6="","",D6/F6) | N6: =IF(F6="","",E6/F6)
A7: 35886 | B7: 1998-1999 | C7: Q1FY99 | D7: =IF(MAX(SUMIFS('Monthly NSE Equity Cash'!$K:$K,'Monthly NSE Equity Cash'!$A:$A,$A7),SUMIFS('Daily NSE Equity Cash'!$H:$H,'Daily NSE Equity Cash'!$C:$C,$A7))=0,"",MAX(SUMIFS('Monthly NSE Equity Cash'!$K:$K,'Monthly NSE Equity Cash'!$A:$A,$A7),SUMIFS('Daily NSE Equity Cash'!$H:$H,'Daily NSE Equity Cash'!$C:$C,$A7))) | E7: =IF(SUMIFS('Monthly BSE Equity Cash'!$G:$G,'Monthly BSE Equity Cash'!$A:$A,$A7)=0,"",SUMIFS('Monthly BSE Equity Cash'!$G:$G,'Monthly BSE Equity Cash'!$A:$A,$A7)) -> 265.5279 | F7: =IF(OR(D7="",E7=""),"",D7+E7) | J7: =IF(OR(D7="",D6=""),"",D7/D6-1) | K7: =IF(OR(E7="",E6=""),"",E7/E6-1) -> 0.14576728 | L7: =IF(OR(F7="",F6=""),"",F7/F6-1) | M7: =IF(F7="","",D7/F7) | N7: =IF(F7="","",E7/F7)
A8: 35916 | B8: 1998-1999 | C8: Q1FY99 | D8: =IF(MAX(SUMIFS('Monthly NSE Equity Cash'!$K:$K,'Monthly NSE Equity Cash'!$A:$A,$A8),SUMIFS('Daily NSE Equity Cash'!$H:$H,'Daily NSE Equity Cash'!$C:$C,$A8))=0,"",MAX(SUMIFS('Monthly NSE Equity Cash'!$K:$K,'Monthly NSE Equity Cash'!$A:$A,$A8),SUMIFS('Daily NSE Equity Cash'!$H:$H,'Daily NSE Equity Cash'!$C:$C,$A8))) | E8: =IF(SUMIFS('Monthly BSE Equity Cash'!$G:$G,'Monthly BSE Equity Cash'!$A:$A,$A8)=0,"",SUMIFS('Monthly BSE Equity Cash'!$G:$G,'Monthly BSE Equity Cash'!$A:$A,$A8)) -> 56.179 | F8: =IF(OR(D8="",E8=""),"",D8+E8) | J8: =IF(OR(D8="",D7=""),"",D8/D7-1) | K8: =IF(OR(E8="",E7=""),"",E8/E7-1) -> -0.78842525 | L8: =IF(OR(F8="",F7=""),"",F8/F7-1) | M8: =IF(F8="","",D8/F8) | N8: =IF(F8="","",E8/F8)
A9: 35947 | B9: 1998-1999 | C9: Q1FY99 | D9: =IF(MAX(SUMIFS('Monthly NSE Equity Cash'!$K:$K,'Monthly NSE Equity Cash'!$A:$A,$A9),SUMIFS('Daily NSE Equity Cash'!$H:$H,'Daily NSE Equity Cash'!$C:$C,$A9))=0,"",MAX(SUMIFS('Monthly NSE Equity Cash'!$K:$K,'Monthly NSE Equity Cash'!$A:$A,$A9),SUMIFS('Daily NSE Equity Cash'!$H:$H,'Daily NSE Equity Cash'!$C:$C,$A9))) | E9: =IF(SUMIFS('Monthly BSE Equity Cash'!$G:$G,'Monthly BSE Equity Cash'!$A:$A,$A9)=0,"",SUMIFS('Monthly BSE Equity Cash'!$G:$G,'Monthly BSE Equity Cash'!$A:$A,$A9)) -> 130.9412 | F9: =IF(OR(D9="",E9=""),"",D9+E9) | J9: =IF(OR(D9="",D8=""),"",D9/D8-1) | K9: =IF(OR(E9="",E8=""),"",E9/E8-1) -> 1.3307855 | L9: =IF(OR(F9="",F8=""),"",F9/F8-1) | M9: =IF(F9="","",D9/F9) | N9: =IF(F9="","",E9/F9)
A10: 35977 | B10: 1998-1999 | C10: Q2FY99 | D10: =IF(MAX(SUMIFS('Monthly NSE Equity Cash'!$K:$K,'Monthly NSE Equity Cash'!$A:$A,$A10),SUMIFS('Daily NSE Equity Cash'!$H:$H,'Daily NSE Equity Cash'!$C:$C,$A10))=0,"",MAX(SUMIFS('Monthly NSE Equity Cash'!$K:$K,'Monthly NSE Equity Cash'!$A:$A,$A10),SUMIFS('Daily NSE Equity Cash'!$H:$H,'Daily NSE Equity Cash'!$C:$C,$A10))) | E10: =IF(SUMIFS('Monthly BSE Equity Cash'!$G:$G,'Monthly BSE Equity Cash'!$A:$A,$A10)=0,"",SUMIFS('Monthly BSE Equity Cash'!$G:$G,'Monthly BSE Equity Cash'!$A:$A,$A10)) -> 212.3811 | F10: =IF(OR(D10="",E10=""),"",D10+E10) | J10: =IF(OR(D10="",D9=""),"",D10/D9-1) | K10: =IF(OR(E10="",E9=""),"",E10/E9-1) -> 0.62195779 | L10: =IF(OR(F10="",F9=""),"",F10/F9-1) | M10: =IF(F10="","",D10/F10) | N10: =IF(F10="","",E10/F10)
A11: 36008 | B11: 1998-1999 | C11: Q2FY99 | D11: =IF(MAX(SUMIFS('Monthly NSE Equity Cash'!$K:$K,'Monthly NSE Equity Cash'!$A:$A,$A11),SUMIFS('Daily NSE Equity Cash'!$H:$H,'Daily NSE Equity Cash'!$C:$C,$A11))=0,"",MAX(SUMIFS('Monthly NSE Equity Cash'!$K:$K,'Monthly NSE Equity Cash'!$A:$A,$A11),SUMIFS('Daily NSE Equity Cash'!$H:$H,'Daily NSE Equity Cash'!$C:$C,$A11))) | E11: =IF(SUMIFS('Monthly BSE Equity Cash'!$G:$G,'Monthly BSE Equity Cash'!$A:$A,$A11)=0,"",SUMIFS('Monthly BSE Equity Cash'!$G:$G,'Monthly BSE Equity Cash'!$A:$A,$A11)) -> 182.117 | F11: =IF(OR(D11="",E11=""),"",D11+E11) | J11: =IF(OR(D11="",D10=""),"",D11/D10-1) | K11: =IF(OR(E11="",E10=""),"",E11/E10-1) -> -0.14249903 | L11: =IF(OR(F11="",F10=""),"",F11/F10-1) | M11: =IF(F11="","",D11/F11) | N11: =IF(F11="","",E11/F11)
A12: 36039 | B12: 1998-1999 | C12: Q2FY99 | D12: =IF(MAX(SUMIFS('Monthly NSE Equity Cash'!$K:$K,'Monthly NSE Equity Cash'!$A:$A,$A12),SUMIFS('Daily NSE Equity Cash'!$H:$H,'Daily NSE Equity Cash'!$C:$C,$A12))=0,"",MAX(SUMIFS('Monthly NSE Equity Cash'!$K:$K,'Monthly NSE Equity Cash'!$A:$A,$A12),SUMIFS('Daily NSE Equity Cash'!$H:$H,'Daily NSE Equity Cash'!$C:$C,$A12))) | E12: =IF(SUMIFS('Monthly BSE Equity Cash'!$G:$G,'Monthly BSE Equity Cash'!$A:$A,$A12)=0,"",SUMIFS('Monthly BSE Equity Cash'!$G:$G,'Monthly BSE Equity Cash'!$A:$A,$A12)) -> 276.4671 | F12: =IF(OR(D12="",E12=""),"",D12+E12) | J12: =IF(OR(D12="",D11=""),"",D12/D11-1) | K12: =IF(OR(E12="",E11=""),"",E12/E11-1) -> 0.5180741 | L12: =IF(OR(F12="",F11=""),"",F12/F11-1) | M12: =IF(F12="","",D12/F12) | N12: =IF(F12="","",E12/F12)
A13: 36069 | B13: 1998-1999 | C13: Q3FY99 | D13: =IF(MAX(SUMIFS('Monthly NSE Equity Cash'!$K:$K,'Monthly NSE Equity Cash'!$A:$A,$A13),SUMIFS('Daily NSE Equity Cash'!$H:$H,'Daily NSE Equity Cash'!$C:$C,$A13))=0,"",MAX(SUMIFS('Monthly NSE Equity Cash'!$K:$K,'Monthly NSE Equity Cash'!$A:$A,$A13),SUMIFS('Daily NSE Equity Cash'!$H:$H,'Daily NSE Equity Cash'!$C:$C,$A13))) | E13: =IF(SUMIFS('Monthly BSE Equity Cash'!$G:$G,'Monthly BSE Equity Cash'!$A:$A,$A13)=0,"",SUMIFS('Monthly BSE Equity Cash'!$G:$G,'Monthly BSE Equity Cash'!$A:$A,$A13)) -> 223.6513 | F13: =IF(OR(D13="",E13=""),"",D13+E13) | J13: =IF(OR(D13="",D12=""),"",D13/D12-1) | K13: =IF(OR(E13="",E12=""),"",E13/E12-1) -> -0.19103828 | L13: =IF(OR(F13="",F12=""),"",F13/F12-1) | M13: =IF(F13="","",D13/F13) | N13: =IF(F13="","",E13/F13)
A14: 36100 | B14: 1998-1999 | C14: Q3FY99 | D14: =IF(MAX(SUMIFS('Monthly NSE Equity Cash'!$K:$K,'Monthly NSE Equity Cash'!$A:$A,$A14),SUMIFS('Daily NSE Equity Cash'!$H:$H,'Daily NSE Equity Cash'!$C:$C,$A14))=0,"",MAX(SUMIFS('Monthly NSE Equity Cash'!$K:$K,'Monthly NSE Equity Cash'!$A:$A,$A14),SUMIFS('Daily NSE Equity Cash'!$H:$H,'Daily NSE Equity Cash'!$C:$C,$A14))) | E14: =IF(SUMIFS('Monthly BSE Equity Cash'!$G:$G,'Monthly BSE Equity Cash'!$A:$A,$A14)=0,"",SUMIFS('Monthly BSE Equity Cash'!$G:$G,'Monthly BSE Equity Cash'!$A:$A,$A14)) -> 202.2055 | F14: =IF(OR(D14="",E14=""),"",D14+E14) | G14: =IF(OR(D14="",D2=""),"",D14/D2-1) | H14: =IF(OR(E14="",E2=""),"",E14/E2-1) -> 0.70083239 | I14: =IF(OR(F14="",F2=""),"",F14/F2-1) | J14: =IF(OR(D14="",D13=""),"",D14/D13-1) | K14: =IF(OR(E14="",E13=""),"",E14/E13-1) -> -0.095889449 | L14: =IF(OR(F14="",F13=""),"",F14/F13-1) | M14: =IF(F14="","",D14/F14) | N14: =IF(F14="","",E14/F14)
A15: 36130 | B15: 1998-1999 | C15: Q3FY99 | D15: =IF(MAX(SUMIFS('Monthly NSE Equity Cash'!$K:$K,'Monthly NSE Equity Cash'!$A:$A,$A15),SUMIFS('Daily NSE Equity Cash'!$H:$H,'Daily NSE Equity Cash'!$C:$C,$A15))=0,"",MAX(SUMIFS('Monthly NSE Equity Cash'!$K:$K,'Monthly NSE Equity Cash'!$A:$A,$A15),SUMIFS('Daily NSE Equity Cash'!$H:$H,'Daily NSE Equity Cash'!$C:$C,$A15))) | E15: =IF(SUMIFS('Monthly BSE Equity Cash'!$G:$G,'Monthly BSE Equity Cash'!$A:$A,$A15)=0,"",SUMIFS('Monthly BSE Equity Cash'!$G:$G,'Monthly BSE Equity Cash'!$A:$A,$A15)) -> 266.876 | F15: =IF(OR(D15="",E15=""),"",D15+E15) | G15: =IF(OR(D15="",D3=""),"",D15/D3-1) | H15: =IF(OR(E15="",E3=""),"",E15/E3-1) -> 0.47658062 | I15: =IF(OR(F15="",F3=""),"",F15/F3-1) | J15: =IF(OR(D15="",D14=""),"",D15/D14-1) | K15: =IF(OR(E15="",E14=""),"",E15/E14-1) -> 0.31982562 | L15: =IF(OR(F15="",F14=""),"",F15/F14-1) | M15: =IF(F15="","",D15/F15) | N15: =IF(F15="","",E15/F15)
A16: 36161 | B16: 1998-1999 | C16: Q4FY99 | D16: =IF(MAX(SUMIFS('Monthly NSE Equity Cash'!$K:$K,'Monthly NSE Equity Cash'!$A:$A,$A16),SUMIFS('Daily NSE Equity Cash'!$H:$H,'Daily NSE Equity Cash'!$C:$C,$A16))=0,"",MAX(SUMIFS('Monthly NSE Equity Cash'!$K:$K,'Monthly NSE Equity Cash'!$A:$A,$A16),SUMIFS('Daily NSE Equity Cash'!$H:$H,'Daily NSE Equity Cash'!$C:$C,$A16))) | E16: =IF(SUMIFS('Monthly BSE Equity Cash'!$G:$G,'Monthly BSE Equity Cash'!$A:$A,$A16)=0,"",SUMIFS('Monthly BSE Equity Cash'!$G:$G,'Monthly BSE Equity Cash'!$A:$A,$A16)) -> 325.1586 | F16: =IF(OR(D16="",E16=""),"",D16+E16) | G16: =IF(OR(D16="",D4=""),"",D16/D4-1) | H16: =IF(OR(E16="",E4=""),"",E16/E4-1) -> 0.87315426 | I16: =IF(OR(F16="",F4=""),"",F16/F4-1) | J16: =IF(OR(D16="",D15=""),"",D16/D15-1) | K16: =IF(OR(E16="",E15=""),"",E16/E15-1) -> 0.21838832 | L16: =IF(OR(F16="",F15=""),"",F16/F15-1) | M16: =IF(F16="","",D16/F16) | N16: =IF(F16="","",E16/F16)
A17: 36192 | B17: 1998-1999 | C17: Q4FY99 | D17: =IF(MAX(SUMIFS('Monthly NSE Equity Cash'!$K:$K,'Monthly NSE Equity Cash'!$A:$A,$A17),SUMIFS('Daily NSE Equity Cash'!$H:$H,'Daily NSE Equity Cash'!$C:$C,$A17))=0,"",MAX(SUMIFS('Monthly NSE Equity Cash'!$K:$K,'Monthly NSE Equity Cash'!$A:$A,$A17),SUMIFS('Daily NSE Equity Cash'!$H:$H,'Daily NSE Equity Cash'!$C:$C,$A17))) | E17: =IF(SUMIFS('Monthly BSE Equity Cash'!$G:$G,'Monthly BSE Equity Cash'!$A:$A,$A17)=0,"",SUMIFS('Monthly BSE Equity Cash'!$G:$G,'Monthly BSE Equity Cash'!$A:$A,$A17)) -> 311.4178 | F17: =IF(OR(D17="",E17=""),"",D17+E17) | G17: =IF(OR(D17="",D5=""),"",D17/D5-1) | H17: =IF(OR(E17="",E5=""),"",E17/E5-1) -> 0.89853479 | I17: =IF(OR(F17="",F5=""),"",F17/F5-1) | J17: =IF(OR(D17="",D16=""),"",D17/D16-1) | K17: =IF(OR(E17="",E16=""),"",E17/E16-1) -> -0.042258762 | L17: =IF(OR(F17="",F16=""),"",F17/F16-1) | M17: =IF(F17="","",D17/F17) | N17: =IF(F17="","",E17/F17)
A18: 36220 | B18: 1998-1999 | C18: Q4FY99 | D18: =IF(MAX(SUMIFS('Monthly NSE Equity Cash'!$K:$K,'Monthly NSE Equity Cash'!$A:$A,$A18),SUMIFS('Daily NSE Equity Cash'!$H:$H,'Daily NSE Equity Cash'!$C:$C,$A18))=0,"",MAX(SUMIFS('Monthly NSE Equity Cash'!$K:$K,'Monthly NSE Equity Cash'!$A:$A,$A18),SUMIFS('Daily NSE Equity Cash'!$H:$H,'Daily NSE Equity Cash'!$C:$C,$A18))) | E18: =IF(SUMIFS('Monthly BSE Equity Cash'!$G:$G,'Monthly BSE Equity Cash'!$A:$A,$A18)=0,"",SUMIFS('Monthly BSE Equity Cash'!$G:$G,'Monthly BSE Equity Cash'!$A:$A,$A18)) -> 393.4462 | F18: =IF(OR(D18="",E18=""),"",D18+E18) | G18: =IF(OR(D18="",D6=""),"",D18/D6-1) | H18: =IF(OR(E18="",E6=""),"",E18/E6-1) -> 0.69774167 | I18: =IF(OR(F18="",F6=""),"",F18/F6-1) | J18: =IF(OR(D18="",D17=""),"",D18/D17-1) | K18: =IF(OR(E18="",E17=""),"",E18/E17-1) -> 0.26340306 | L18: =IF(OR(F18="",F17=""),"",F18/F17-1) | M18: =IF(F18="","",D18/F18) | N18: =IF(F18="","",E18/F18)
A19: 36251 | B19: 1999-2000 | C19: Q1FY00 | D19: =IF(MAX(SUMIFS('Monthly NSE Equity Cash'!$K:$K,'Monthly NSE Equity Cash'!$A:$A,$A19),SUMIFS('Daily NSE Equity Cash'!$H:$H,'Daily NSE Equity Cash'!$C:$C,$A19))=0,"",MAX(SUMIFS('Monthly NSE Equity Cash'!$K:$K,'Monthly NSE Equity Cash'!$A:$A,$A19),SUMIFS('Daily NSE Equity Cash'!$H:$H,'Daily NSE Equity Cash'!$C:$C,$A19))) -> 359.33 | E19: =IF(SUMIFS('Monthly BSE Equity Cash'!$G:$G,'Monthly BSE Equity Cash'!$A:$A,$A19)=0,"",SUMIFS('Monthly BSE Equity Cash'!$G:$G,'Monthly BSE Equity Cash'!$A:$A,$A19)) -> 270.0271 | F19: =IF(OR(D19="",E19=""),"",D19+E19) -> 629.3571 | G19: =IF(OR(D19="",D7=""),"",D19/D7-1) | H19: =IF(OR(E19="",E7=""),"",E19/E7-1) -> 0.016944359 | I19: =IF(OR(F19="",F7=""),"",F19/F7-1) | J19: =IF(OR(D19="",D18=""),"",D19/D18-1) | K19: =IF(OR(E19="",E18=""),"",E19/E18-1) -> -0.31368736 | L19: =IF(OR(F19="",F18=""),"",F19/F18-1) | M19: =IF(F19="","",D19/F19) -> 0.57094772 | N19: =IF(F19="","",E19/F19) -> 0.42905228
A20: 36281 | B20: 1999-2000 | C20: Q1FY00 | D20: =IF(MAX(SUMIFS('Monthly NSE Equity Cash'!$K:$K,'Monthly NSE Equity Cash'!$A:$A,$A20),SUMIFS('Daily NSE Equity Cash'!$H:$H,'Daily NSE Equity Cash'!$C:$C,$A20))=0,"",MAX(SUMIFS('Monthly NSE Equity Cash'!$K:$K,'Monthly NSE Equity Cash'!$A:$A,$A20),SUMIFS('Daily NSE Equity Cash'!$H:$H,'Daily NSE Equity Cash'!$C:$C,$A20))) -> 502.63 | E20: =IF(SUMIFS('Monthly BSE Equity Cash'!$G:$G,'Monthly BSE Equity Cash'!$A:$A,$A20)=0,"",SUMIFS('Monthly BSE Equity Cash'!$G:$G,'Monthly BSE Equity Cash'!$A:$A,$A20)) -> 362.3534 | F20: =IF(OR(D20="",E20=""),"",D20+E20) -> 864.9834 | G20: =IF(OR(D20="",D8=""),"",D20/D8-1) | H20: =IF(OR(E20="",E8=""),"",E20/E8-1) -> 5.4499795 | I20: =IF(OR(F20="",F8=""),"",F20/F8-1) | J20: =IF(OR(D20="",D19=""),"",D20/D19-1) -> 0.39879776 | K20: =IF(OR(E20="",E19=""),"",E20/E19-1) -> 0.34191494 | L20: =IF(OR(F20="",F19=""),"",F20/F19-1) -> 0.37439206 | M20: =IF(F20="","",D20/F20) -> 0.5810863 | N20: =IF(F20="","",E20/F20) -> 0.4189137
A21: 36312 | B21: 1999-2000 | C21: Q1FY00 | D21: =IF(MAX(SUMIFS('Monthly NSE Equity Cash'!$K:$K,'Monthly NSE Equity Cash'!$A:$A,$A21),SUMIFS('Daily NSE Equity Cash'!$H:$H,'Daily NSE Equity Cash'!$C:$C,$A21))=0,"",MAX(SUMIFS('Monthly NSE Equity Cash'!$K:$K,'Monthly NSE Equity Cash'!$A:$A,$A21),SUMIFS('Daily NSE Equity Cash'!$H:$H,'Daily NSE Equity Cash'!$C:$C,$A21))) -> 404.73 | E21: =IF(SUMIFS('Monthly BSE Equity Cash'!$G:$G,'Monthly BSE Equity Cash'!$A:$A,$A21)=0,"",SUMIFS('Monthly BSE Equity Cash'!$G:$G,'Monthly BSE Equity Cash'!$A:$A,$A21)) -> 332.3955 | F21: =IF(OR(D21="",E21=""),"",D21+E21) -> 737.1255 | G21: =IF(OR(D21="",D9=""),"",D21/D9-1) | H21: =IF(OR(E21="",E9=""),"",E21/E9-1) -> 1.5385097 | I21: =IF(OR(F21="",F9=""),"",F21/F9-1) | J21: =IF(OR(D21="",D20=""),"",D21/D20-1) -> -0.19477548 | K21: =IF(OR(E21="",E20=""),"",E21/E20-1) -> -0.082675918 | L21: =IF(OR(F21="",F20=""),"",F21/F20-1) -> -0.14781544 | M21: =IF(F21="","",D21/F21) -> 0.54906525 | N21: =IF(F21="","",E21/F21) -> 0.45093475
A22: 36342 | B22: 1999-2000 | C22: Q2FY00 | D22: =IF(MAX(SUMIFS('Monthly NSE Equity Cash'!$K:$K,'Monthly NSE Equity Cash'!$A:$A,$A22),SUMIFS('Daily NSE Equity Cash'!$H:$H,'Daily NSE Equity Cash'!$C:$C,$A22))=0,"",MAX(SUMIFS('Monthly NSE Equity Cash'!$K:$K,'Monthly NSE Equity Cash'!$A:$A,$A22),SUMIFS('Daily NSE Equity Cash'!$H:$H,'Daily NSE Equity Cash'!$C:$C,$A22))) -> 554.55 | E22: =IF(SUMIFS('Monthly BSE Equity Cash'!$G:$G,'Monthly BSE Equity Cash'!$A:$A,$A22)=0,"",SUMIFS('Monthly BSE Equity Cash'!$G:$G,'Monthly BSE Equity Cash'!$A:$A,$A22)) -> 466.3931 | F22: =IF(OR(D22="",E22=""),"",D22+E22) -> 1020.9431 | G22: =IF(OR(D22="",D10=""),"",D22/D10-1) | H22: =IF(OR(E22="",E10=""),"",E22/E10-1) -> 1.1960198 | I22: =IF(OR(F22="",F10=""),"",F22/F10-1) | J22: =IF(OR(D22="",D21=""),"",D22/D21-1) -> 0.37017271 | K22: =IF(OR(E22="",E21=""),"",E22/E21-1) -> 0.403127 | L22: =IF(OR(F22="",F21=""),"",F22/F21-1) -> 0.38503294 | M22: =IF(F22="","",D22/F22) -> 0.54317425 | N22: =IF(F22="","",E22/F22) -> 0.45682575
A23: 36373 | B23: 1999-2000 | C23: Q2FY00 | D23: =IF(MAX(SUMIFS('Monthly NSE Equity Cash'!$K:$K,'Monthly NSE Equity Cash'!$A:$A,$A23),SUMIFS('Daily NSE Equity Cash'!$H:$H,'Daily NSE Equity Cash'!$C:$C,$A23))=0,"",MAX(SUMIFS('Monthly NSE Equity Cash'!$K:$K,'Monthly NSE Equity Cash'!$A:$A,$A23),SUMIFS('Daily NSE Equity Cash'!$H:$H,'Daily NSE Equity Cash'!$C:$C,$A23))) -> 536.99 | E23: =IF(SUMIFS('Monthly BSE Equity Cash'!$G:$G,'Monthly BSE Equity Cash'!$A:$A,$A23)=0,"",SUMIFS('Monthly BSE Equity Cash'!$G:$G,'Monthly BSE Equity Cash'!$A:$A,$A23)) -> 499.9716 | F23: =IF(OR(D23="",E23=""),"",D23+E23) -> 1036.9616 | G23: =IF(OR(D23="",D11=""),"",D23/D11-1) | H23: =IF(OR(E23="",E11=""),"",E23/E11-1) -> 1.7453318 | I23: =IF(OR(F23="",F11=""),"",F23/F11-1) | J23: =IF(OR(D23="",D22=""),"",D23/D22-1) -> -0.031665314 | K23: =IF(OR(E23="",E22=""),"",E23/E22-1) -> 0.071996134 | L23: =IF(OR(F23="",F22=""),"",F23/F22-1) -> 0.015689905 | M23: =IF(F23="","",D23/F23) -> 0.51784946 | N23: =IF(F23="","",E23/F23) -> 0.48215054
A24: 36404 | B24: 1999-2000 | C24: Q2FY00 | D24: =IF(MAX(SUMIFS('Monthly NSE Equity Cash'!$K:$K,'Monthly NSE Equity Cash'!$A:$A,$A24),SUMIFS('Daily NSE Equity Cash'!$H:$H,'Daily NSE Equity Cash'!$C:$C,$A24))=0,"",MAX(SUMIFS('Monthly NSE Equity Cash'!$K:$K,'Monthly NSE Equity Cash'!$A:$A,$A24),SUMIFS('Daily NSE Equity Cash'!$H:$H,'Daily NSE Equity Cash'!$C:$C,$A24))) -> 558.78 | E24: =IF(SUMIFS('Monthly BSE Equity Cash'!$G:$G,'Monthly BSE Equity Cash'!$A:$A,$A24)=0,"",SUMIFS('Monthly BSE Equity Cash'!$G:$G,'Monthly BSE Equity Cash'!$A:$A,$A24)) -> 465.7772 | F24: =IF(OR(D24="",E24=""),"",D24+E24) -> 1024.5572 | G24: =IF(OR(D24="",D12=""),"",D24/D12-1) | H24: =IF(OR(E24="",E12=""),"",E24/E12-1) -> 0.6847473 | I24: =IF(OR(F24="",F12=""),"",F24/F12-1) | J24: =IF(OR(D24="",D23=""),"",D24/D23-1) -> 0.040578037 | K24: =IF(OR(E24="",E23=""),"",E24/E23-1) -> -0.068392685 | L24: =IF(OR(F24="",F23=""),"",F24/F23-1) -> -0.011962256 | M24: =IF(F24="","",D24/F24) -> 0.54538683 | N24: =IF(F24="","",E24/F24) -> 0.45461317
A25: 36434 | B25: 1999-2000 | C25: Q3FY00 | D25: =IF(MAX(SUMIFS('Monthly NSE Equity Cash'!$K:$K,'Monthly NSE Equity Cash'!$A:$A,$A25),SUMIFS('Daily NSE Equity Cash'!$H:$H,'Daily NSE Equity Cash'!$C:$C,$A25))=0,"",MAX(SUMIFS('Monthly NSE Equity Cash'!$K:$K,'Monthly NSE Equity Cash'!$A:$A,$A25),SUMIFS('Daily NSE Equity Cash'!$H:$H,'Daily NSE Equity Cash'!$C:$C,$A25))) -> 722.16 | E25: =IF(SUMIFS('Monthly BSE Equity Cash'!$G:$G,'Monthly BSE Equity Cash'!$A:$A,$A25)=0,"",SUMIFS('Monthly BSE Equity Cash'!$G:$G,'Monthly BSE Equity Cash'!$A:$A,$A25)) -> 576.9879 | F25: =IF(OR(D25="",E25=""),"",D25+E25) -> 1299.1479 | G25: =IF(OR(D25="",D13=""),"",D25/D13-1) | H25: =IF(OR(E25="",E13=""),"",E25/E13-1) -> 1.5798549 | I25: =IF(OR(F25="",F13=""),"",F25/F13-1) | J25: =IF(OR(D25="",D24=""),"",D25/D24-1) -> 0.29238699 | K25: =IF(OR(E25="",E24=""),"",E25/E24-1) -> 0.23876373 | L25: =IF(OR(F25="",F24=""),"",F25/F24-1) -> 0.26800915 | M25: =IF(F25="","",D25/F25) -> 0.55587205 | N25: =IF(F25="","",E25/F25) -> 0.44412795
