Workbook

Sheet Quality Check
A1: Exchange | B1: Sheet | C1: Data From | D1: Data To | E1: Data Rows | F1: Index Futures Turnover Total (INR Bn) | G1: Index Futures Contracts Total | H1: Stock/Equity Futures Turnover Total (INR Bn) | I1: Stock/Equity Futures Contracts Total | J1: Total Futures Turnover Total (INR Bn) | K1: Total Futures Contracts Total
A2: NSE | B2: Year NSE Equity Futures | C2: ='Year NSE Equity Futures'!A2 | D2: =LOOKUP(2,1/('Year NSE Equity Futures'!$A$2:$A$100000<>""),'Year NSE Equity Futures'!$A$2:$A$100000) | E2: =COUNTA('Year NSE Equity Futures'!$A:$A)-1 | F2: =SUM('Year NSE Equity Futures'!$B:$B) | G2: =SUM('Year NSE Equity Futures'!$C:$C) | H2: =SUM('Year NSE Equity Futures'!$D:$D) | I2: =SUM('Year NSE Equity Futures'!$E:$E) | J2: =SUM('Year NSE Equity Futures'!$F:$F) | K2: =SUM('Year NSE Equity Futures'!$G:$G)
A3: NSE | B3: Monthly NSE Equity Futures | C3: ='Monthly NSE Equity Futures'!A2 | D3: =LOOKUP(2,1/('Monthly NSE Equity Futures'!$A$2:$A$100000<>""),'Monthly NSE Equity Futures'!$A$2:$A$100000) | E3: =COUNTA('Monthly NSE Equity Futures'!$A:$A)-1 | F3: =SUM('Monthly NSE Equity Futures'!$D:$D) | G3: =SUM('Monthly NSE Equity Futures'!$E:$E) | H3: =SUM('Monthly NSE Equity Futures'!$F:$F) | I3: =SUM('Monthly NSE Equity Futures'!$G:$G) | J3: =SUM('Monthly NSE Equity Futures'!$H:$H) | K3: =SUM('Monthly NSE Equity Futures'!$I:$I)
A4: NSE | B4: Daily NSE Equity Futures | C4: ='Daily NSE Equity Futures'!A2 | D4: =LOOKUP(2,1/('Daily NSE Equity Futures'!$A$2:$A$100000<>""),'Daily NSE Equity Futures'!$A$2:$A$100000) | E4: =COUNTA('Daily NSE Equity Futures'!$A:$A)-1 | F4: =SUM('Daily NSE Equity Futures'!$E:$E) | G4: =SUM('Daily NSE Equity Futures'!$F:$F) | H4: =SUM('Daily NSE Equity Futures'!$G:$G) | I4: =SUM('Daily NSE Equity Futures'!$H:$H) | J4: =SUM('Daily NSE Equity Futures'!$I:$I) | K4: =SUM('Daily NSE Equity Futures'!$J:$J)
A5: BSE | B5: Year BSE Equity Futures | C5: ='Year BSE Equity Futures'!A2 | D5: =LOOKUP(2,1/('Year BSE Equity Futures'!$A$2:$A$100000<>""),'Year BSE Equity Futures'!$A$2:$A$100000) | E5: =COUNTA('Year BSE Equity Futures'!$A:$A)-1 | F5: =SUM('Year BSE Equity Futures'!$B:$B) | G5: =SUM('Year BSE Equity Futures'!$C:$C) | H5: =SUM('Year BSE Equity Futures'!$D:$D) | I5: =SUM('Year BSE Equity Futures'!$E:$E) | J5: =SUM('Year BSE Equity Futures'!$F:$F) | K5: =SUM('Year BSE Equity Futures'!$G:$G)
A6: BSE | B6: Monthly BSE Equity Futures | C6: ='Monthly BSE Equity Futures'!A2 | D6: =LOOKUP(2,1/('Monthly BSE Equity Futures'!$A$2:$A$100000<>""),'Monthly BSE Equity Futures'!$A$2:$A$100000) | E6: =COUNTA('Monthly BSE Equity Futures'!$A:$A)-1 | F6: =SUM('Monthly BSE Equity Futures'!$D:$D) | G6: =SUM('Monthly BSE Equity Futures'!$E:$E) | H6: =SUM('Monthly BSE Equity Futures'!$F:$F) | I6: =SUM('Monthly BSE Equity Futures'!$G:$G) | J6: =SUM('Monthly BSE Equity Futures'!$H:$H) | K6: =SUM('Monthly BSE Equity Futures'!$I:$I)
A7: BSE | B7: Daily BSE Equity Futures | C7: ='Daily BSE Equity Futures'!A2 | D7: =LOOKUP(2,1/('Daily BSE Equity Futures'!$A$2:$A$100000<>""),'Daily BSE Equity Futures'!$A$2:$A$100000) | E7: =COUNTA('Daily BSE Equity Futures'!$A:$A)-1 | F7: =SUM('Daily BSE Equity Futures'!$E:$E) | G7: =SUM('Daily BSE Equity Futures'!$F:$F) | H7: =SUM('Daily BSE Equity Futures'!$G:$G) | I7: =SUM('Daily BSE Equity Futures'!$H:$H) | J7: =SUM('Daily BSE Equity Futures'!$I:$I) | K7: =SUM('Daily BSE Equity Futures'!$J:$J)
A9: NSE & BSE daily end dates aligned? | C9: =IF($D$4=$D$7,"YES","NO")
A11: Reconciliation | B11: Aggregate | C11: Component Sum | D11: Difference | E11: Status | F11: Remarks
A12: NSE: Yearly vs Monthly (from first yearly FY) - Index Futures Turnover | B12: =SUM('Year NSE Equity Futures'!$B:$B) | C12: =SUMIFS('Monthly NSE Equity Futures'!$D:$D,'Monthly NSE Equity Futures'!$A:$A,">="&DATE(LEFT('Year NSE Equity Futures'!$A$2,4)+0,4,1)) | D12: =B12-C12 | E12: =IF(ABS(D12)<=0.02,"OK","CHECK") | F12: tolerance 0.02 INR Bn (source rounding)
A13: NSE: Monthly vs Daily (from daily start) - Index Futures Turnover | B13: =SUMIFS('Monthly NSE Equity Futures'!$D:$D,'Monthly NSE Equity Futures'!$A:$A,">="&DATE(YEAR($C$4),MONTH($C$4),1)) | C13: =SUM('Daily NSE Equity Futures'!$E:$E) | D13: =B13-C13 | E13: =IF(ABS(D13)<=0.02,"OK","CHECK") | F13: tolerance 0.02 INR Bn (source rounding)
A14: BSE: Yearly vs Monthly (full history) - Index Futures Turnover | B14: =SUM('Year BSE Equity Futures'!$B:$B) | C14: =SUM('Monthly BSE Equity Futures'!$D:$D) | D14: =B14-C14 | E14: =IF(ABS(D14)<=0.02,"OK","CHECK") | F14: tolerance 0.02 INR Bn (source rounding)
A15: BSE: Monthly vs Daily (from daily start) - Index Futures Turnover | B15: =SUMIFS('Monthly BSE Equity Futures'!$D:$D,'Monthly BSE Equity Futures'!$A:$A,">="&DATE(YEAR($C$7),MONTH($C$7),1)) | C15: =SUM('Daily BSE Equity Futures'!$E:$E) | D15: =B15-C15 | E15: =IF(ABS(D15)<=0.02,"OK","CHECK") | F15: tolerance 0.02 INR Bn (source rounding)
A16: NSE: Yearly vs Monthly (from first yearly FY) - Index Futures Contracts | B16: =SUM('Year NSE Equity Futures'!$C:$C) | C16: =SUMIFS('Monthly NSE Equity Futures'!$E:$E,'Monthly NSE Equity Futures'!$A:$A,">="&DATE(LEFT('Year NSE Equity Futures'!$A$2,4)+0,4,1)) | D16: =B16-C16 | E16: =IF(ABS(D16)<=0,"OK","CHECK") | F16: counts must match exactly
A17: NSE: Monthly vs Daily (from daily start) - Index Futures Contracts | B17: =SUMIFS('Monthly NSE Equity Futures'!$E:$E,'Monthly NSE Equity Futures'!$A:$A,">="&DATE(YEAR($C$4),MONTH($C$4),1)) | C17: =SUM('Daily NSE Equity Futures'!$F:$F) | D17: =B17-C17 | E17: =IF(ABS(D17)<=0,"OK","CHECK") | F17: counts must match exactly
A18: BSE: Yearly vs Monthly (full history) - Index Futures Contracts | B18: =SUM('Year BSE Equity Futures'!$C:$C) | C18: =SUM('Monthly BSE Equity Futures'!$E:$E) | D18: =B18-C18 | E18: =IF(ABS(D18)<=0,"OK","CHECK") | F18: counts must match exactly
A19: BSE: Monthly vs Daily (from daily start) - Index Futures Contracts | B19: =SUMIFS('Monthly BSE Equity Futures'!$E:$E,'Monthly BSE Equity Futures'!$A:$A,">="&DATE(YEAR($C$7),MONTH($C$7),1)) | C19: =SUM('Daily BSE Equity Futures'!$F:$F) | D19: =B19-C19 | E19: =IF(ABS(D19)<=0,"OK","CHECK") | F19: counts must match exactly
A20: NSE: Yearly vs Monthly (from first yearly FY) - Stock/Equity Futures Turnover | B20: =SUM('Year NSE Equity Futures'!$D:$D) | C20: =SUMIFS('Monthly NSE Equity Futures'!$F:$F,'Monthly NSE Equity Futures'!$A:$A,">="&DATE(LEFT('Year NSE Equity Futures'!$A$2,4)+0,4,1)) | D20: =B20-C20 | E20: =IF(ABS(D20)<=0.02,"OK","CHECK") | F20: tolerance 0.02 INR Bn (source rounding)
A21: NSE: Monthly vs Daily (from daily start) - Stock/Equity Futures Turnover | B21: =SUMIFS('Monthly NSE Equity Futures'!$F:$F,'Monthly NSE Equity Futures'!$A:$A,">="&DATE(YEAR($C$4),MONTH($C$4),1)) | C21: =SUM('Daily NSE Equity Futures'!$G:$G) | D21: =B21-C21 | E21: =IF(ABS(D21)<=0.02,"OK","CHECK") | F21: tolerance 0.02 INR Bn (source rounding)
A22: BSE: Yearly vs Monthly (full history) - Stock/Equity Futures Turnover | B22: =SUM('Year BSE Equity Futures'!$D:$D) | C22: =SUM('Monthly BSE Equity Futures'!$F:$F) | D22: =B22-C22 | E22: =IF(ABS(D22)<=0.02,"OK","CHECK") | F22: tolerance 0.02 INR Bn (source rounding)
A23: BSE: Monthly vs Daily (from daily start) - Stock/Equity Futures Turnover | B23: =SUMIFS('Monthly BSE Equity Futures'!$F:$F,'Monthly BSE Equity Futures'!$A:$A,">="&DATE(YEAR($C$7),MONTH($C$7),1)) | C23: =SUM('Daily BSE Equity Futures'!$G:$G) | D23: =B23-C23 | E23: =IF(ABS(D23)<=0.02,"OK","CHECK") | F23: tolerance 0.02 INR Bn (source rounding)
A24: NSE: Yearly vs Monthly (from first yearly FY) - Stock/Equity Futures Contracts | B24: =SUM('Year NSE Equity Futures'!$E:$E) | C24: =SUMIFS('Monthly NSE Equity Futures'!$G:$G,'Monthly NSE Equity Futures'!$A:$A,">="&DATE(LEFT('Year NSE Equity Futures'!$A$2,4)+0,4,1)) | D24: =B24-C24 | E24: =IF(ABS(D24)<=0,"OK","CHECK") | F24: counts must match exactly
A25: NSE: Monthly vs Daily (from daily start) - Stock/Equity Futures Contracts | B25: =SUMIFS('Monthly NSE Equity Futures'!$G:$G,'Monthly NSE Equity Futures'!$A:$A,">="&DATE(YEAR($C$4),MONTH($C$4),1)) | C25: =SUM('Daily NSE Equity Futures'!$H:$H) | D25: =B25-C25 | E25: =IF(ABS(D25)<=0,"OK","CHECK") | F25: counts must match exactly
A26: BSE: Yearly vs Monthly (full history) - Stock/Equity Futures Contracts | B26: =SUM('Year BSE Equity Futures'!$E:$E) | C26: =SUM('Monthly BSE Equity Futures'!$G:$G) | D26: =B26-C26 | E26: =IF(ABS(D26)<=0,"OK","CHECK") | F26: counts must match exactly
A27: BSE: Monthly vs Daily (from daily start) - Stock/Equity Futures Contracts | B27: =SUMIFS('Monthly BSE Equity Futures'!$G:$G,'Monthly BSE Equity Futures'!$A:$A,">="&DATE(YEAR($C$7),MONTH($C$7),1)) | C27: =SUM('Daily BSE Equity Futures'!$H:$H) | D27: =B27-C27 | E27: =IF(ABS(D27)<=0,"OK","CHECK") | F27: counts must match exactly
A28: NSE: Yearly vs Monthly (from first yearly FY) - Total Futures Turnover | B28: =SUM('Year NSE Equity Futures'!$F:$F) | C28: =SUMIFS('Monthly NSE Equity Futures'!$H:$H,'Monthly NSE Equity Futures'!$A:$A,">="&DATE(LEFT('Year NSE Equity Futures'!$A$2,4)+0,4,1)) | D28: =B28-C28 | E28: =IF(ABS(D28)<=0.04,"OK","CHECK") | F28: tolerance 0.04 INR Bn (source rounding)
A29: NSE: Monthly vs Daily (from daily start) - Total Futures Turnover | B29: =SUMIFS('Monthly NSE Equity Futures'!$H:$H,'Monthly NSE Equity Futures'!$A:$A,">="&DATE(YEAR($C$4),MONTH($C$4),1)) | C29: =SUM('Daily NSE Equity Futures'!$I:$I) | D29: =B29-C29 | E29: =IF(ABS(D29)<=0.04,"OK","CHECK") | F29: tolerance 0.04 INR Bn (source rounding)
A30: BSE: Yearly vs Monthly (full history) - Total Futures Turnover | B30: =SUM('Year BSE Equity Futures'!$F:$F) | C30: =SUM('Monthly BSE Equity Futures'!$H:$H) | D30: =B30-C30 | E30: =IF(ABS(D30)<=0.04,"OK","CHECK") | F30: tolerance 0.04 INR Bn (source rounding)
A31: BSE: Monthly vs Daily (from daily start) - Total Futures Turnover | B31: =SUMIFS('Monthly BSE Equity Futures'!$H:$H,'Monthly BSE Equity Futures'!$A:$A,">="&DATE(YEAR($C$7),MONTH($C$7),1)) | C31: =SUM('Daily BSE Equity Futures'!$I:$I) | D31: =B31-C31 | E31: =IF(ABS(D31)<=0.04,"OK","CHECK") | F31: tolerance 0.04 INR Bn (source rounding)
A32: NSE: Yearly vs Monthly (from first yearly FY) - Total Futures Contracts | B32: =SUM('Year NSE Equity Futures'!$G:$G) | C32: =SUMIFS('Monthly NSE Equity Futures'!$I:$I,'Monthly NSE Equity Futures'!$A:$A,">="&DATE(LEFT('Year NSE Equity Futures'!$A$2,4)+0,4,1)) | D32: =B32-C32 | E32: =IF(ABS(D32)<=0,"OK","CHECK") | F32: counts must match exactly
A33: NSE: Monthly vs Daily (from daily start) - Total Futures Contracts | B33: =SUMIFS('Monthly NSE Equity Futures'!$I:$I,'Monthly NSE Equity Futures'!$A:$A,">="&DATE(YEAR($C$4),MONTH($C$4),1)) | C33: =SUM('Daily NSE Equity Futures'!$J:$J) | D33: =B33-C33 | E33: =IF(ABS(D33)<=0,"OK","CHECK") | F33: counts must match exactly
A34: BSE: Yearly vs Monthly (full history) - Total Futures Contracts | B34: =SUM('Year BSE Equity Futures'!$G:$G) | C34: =SUM('Monthly BSE Equity Futures'!$I:$I) | D34: =B34-C34 | E34: =IF(ABS(D34)<=0,"OK","CHECK") | F34: counts must match exactly
A35: BSE: Monthly vs Daily (from daily start) - Total Futures Contracts | B35: =SUMIFS('Monthly BSE Equity Futures'!$I:$I,'Monthly BSE Equity Futures'!$A:$A,">="&DATE(YEAR($C$7),MONTH($C$7),1)) | C35: =SUM('Daily BSE Equity Futures'!$J:$J) | D35: =B35-C35 | E35: =IF(ABS(D35)<=0,"OK","CHECK") | F35: counts must match exactly
A37: Notes
A38: Futures only (Index Futures and Stock/Equity Futures); options are excluded. Total Futures = Index + Stock/Equity per metric. Futures turnover is notional - there is no premium leg. All monetary figures in INR Bn (= published INR Crs / 100); No. of Contracts are raw counts (BSE equity futures trade only a handful of contracts a day).
A39: Market Share sheets: values are live SUMIFS on the data sheets at the Total Futures level; one-sided periods (e.g. BSE-only history before Apr-2009, zero-activity BSE days) show the available exchange but a BLANK total/share - never a fake 100%. Growth columns are on Turnover; YoY on in-progress periods compares partial vs full prior period.
A40: NSE: single source at three granularities (F&O Business Growth report). Yearly starts FY2015-16, Monthly starts Apr-2009, so Yearly-vs-Monthly reconciles from the first yearly FY and the Year Mkt Share sheet fills NSE from the Monthly sheet (MAX of the two) for FY2009-15; both the in-progress month and fiscal year are published. The feed's Volume (volatility) Futures fields are zero/null over the entire history and are excluded. No. of Trading Days is derived (F&O total turnover / published average, options included) - blank where the published average is internally inconsistent.
A41: BSE: Yearly & Monthly from the Key Statistics - Derivatives Turnover page (history FY2003-04 onward); Daily from the independent Derivatives Archives Day-wise Market Summary page (product types IF / EF), so the BSE reconciliation cross-validates the two sources. BSE publishes trading-day counts directly. Days with zero futures trades have no row in the BSE daily source.
A42: Each Mkt Share sheet also carries a period-to-date Comparison block below the data - Year & Day sheets: current-FY YTD vs the prior FY; Qrtr sheet: running quarter QTD vs the same quarter a year earlier; Mth sheet: running month MTD vs the same month a year earlier - always over the FIRST EQUAL NUMBER of NSE trading days of the prior period (matched window shown in the block, sliding forward with each refresh); live formulas on the daily data sheets, growth on NSE/BSE/Total for Turnover and Contracts.
A43: Colour code: BLUE = Turnover (INR Bn), GREEN = No. of Contracts; grey left borders mark the Index / Stock/Equity / Total group boundaries. On Market Share sheets the share columns show the red-to-green scale instead, and the growth block is blue (turnover-based).

Sheet Year Equity Futures Mkt Share
A1: Fiscal Year | B1: NSE Turnover (INR Bn) | C1: BSE Turnover (INR Bn) | D1: Total Turnover (INR Bn) | E1: NSE Turnover Market Share | F1: BSE Turnover Market Share | G1: NSE Turnover YoY Growth | H1: BSE Turnover YoY Growth | I1: Total Turnover YoY Growth | J1: NSE No. of Contracts | K1: BSE No. of Contracts | L1: Total No. of Contracts | M1: NSE Contracts Market Share | N1: BSE Contracts Market Share
A2: 2003-2004 | B2: =IF(MAX(SUMIFS('Year NSE Equity Futures'!$F:$F,'Year NSE Equity Futures'!$A:$A,$A2),SUMIFS('Monthly NSE Equity Futures'!$H:$H,'Monthly NSE Equity Futures'!$B:$B,$A2))=0,"",MAX(SUMIFS('Year NSE Equity Futures'!$F:$F,'Year NSE Equity Futures'!$A:$A,$A2),SUMIFS('Monthly NSE Equity Futures'!$H:$H,'Monthly NSE Equity Futures'!$B:$B,$A2))) | C2: =IF(SUMIFS('Year BSE Equity Futures'!$F:$F,'Year BSE Equity Futures'!$A:$A,$A2)=0,"",SUMIFS('Year BSE Equity Futures'!$F:$F,'Year BSE Equity Futures'!$A:$A,$A2)) | D2: =IF(OR(B2="",C2=""),"",B2+C2) | E2: =IF(D2="","",B2/D2) | F2: =IF(D2="","",C2/D2) | J2: =IF(MAX(SUMIFS('Year NSE Equity Futures'!$G:$G,'Year NSE Equity Futures'!$A:$A,$A2),SUMIFS('Monthly NSE Equity Futures'!$I:$I,'Monthly NSE Equity Futures'!$B:$B,$A2))=0,"",MAX(SUMIFS('Year NSE Equity Futures'!$G:$G,'Year NSE Equity Futures'!$A:$A,$A2),SUMIFS('Monthly NSE Equity Futures'!$I:$I,'Monthly NSE Equity Futures'!$B:$B,$A2))) | K2: =IF(SUMIFS('Year BSE Equity Futures'!$G:$G,'Year BSE Equity Futures'!$A:$A,$A2)=0,"",SUMIFS('Year BSE Equity Futures'!$G:$G,'Year BSE Equity Futures'!$A:$A,$A2)) | L2: =IF(OR(J2="",K2=""),"",J2+K2) | M2: =IF(L2="","",J2/L2) | N2: =IF(L2="","",K2/L2)
A3: 2004-2005 | B3: =IF(MAX(SUMIFS('Year NSE Equity Futures'!$F:$F,'Year NSE Equity Futures'!$A:$A,$A3),SUMIFS('Monthly NSE Equity Futures'!$H:$H,'Monthly NSE Equity Futures'!$B:$B,$A3))=0,"",MAX(SUMIFS('Year NSE Equity Futures'!$F:$F,'Year NSE Equity Futures'!$A:$A,$A3),SUMIFS('Monthly NSE Equity Futures'!$H:$H,'Monthly NSE Equity Futures'!$B:$B,$A3))) | C3: =IF(SUMIFS('Year BSE Equity Futures'!$F:$F,'Year BSE Equity Futures'!$A:$A,$A3)=0,"",SUMIFS('Year BSE Equity Futures'!$F:$F,'Year BSE Equity Futures'!$A:$A,$A3)) | D3: =IF(OR(B3="",C3=""),"",B3+C3) | E3: =IF(D3="","",B3/D3) | F3: =IF(D3="","",C3/D3) | G3: =IF(OR(B3="",B2=""),"",B3/B2-1) | H3: =IF(OR(C3="",C2=""),"",C3/C2-1) | I3: =IF(OR(D3="",D2=""),"",D3/D2-1) | J3: =IF(MAX(SUMIFS('Year NSE Equity Futures'!$G:$G,'Year NSE Equity Futures'!$A:$A,$A3),SUMIFS('Monthly NSE Equity Futures'!$I:$I,'Monthly NSE Equity Futures'!$B:$B,$A3))=0,"",MAX(SUMIFS('Year NSE Equity Futures'!$G:$G,'Year NSE Equity Futures'!$A:$A,$A3),SUMIFS('Monthly NSE Equity Futures'!$I:$I,'Monthly NSE Equity Futures'!$B:$B,$A3))) | K3: =IF(SUMIFS('Year BSE Equity Futures'!$G:$G,'Year BSE Equity Futures'!$A:$A,$A3)=0,"",SUMIFS('Year BSE Equity Futures'!$G:$G,'Year BSE Equity Futures'!$A:$A,$A3)) | L3: =IF(OR(J3="",K3=""),"",J3+K3) | M3: =IF(L3="","",J3/L3) | N3: =IF(L3="","",K3/L3)
A4: 2005-2006 | B4: =IF(MAX(SUMIFS('Year NSE Equity Futures'!$F:$F,'Year NSE Equity Futures'!$A:$A,$A4),SUMIFS('Monthly NSE Equity Futures'!$H:$H,'Monthly NSE Equity Futures'!$B:$B,$A4))=0,"",MAX(SUMIFS('Year NSE Equity Futures'!$F:$F,'Year NSE Equity Futures'!$A:$A,$A4),SUMIFS('Monthly NSE Equity Futures'!$H:$H,'Monthly NSE Equity Futures'!$B:$B,$A4))) | C4: =IF(SUMIFS('Year BSE Equity Futures'!$F:$F,'Year BSE Equity Futures'!$A:$A,$A4)=0,"",SUMIFS('Year BSE Equity Futures'!$F:$F,'Year BSE Equity Futures'!$A:$A,$A4)) | D4: =IF(OR(B4="",C4=""),"",B4+C4) | E4: =IF(D4="","",B4/D4) | F4: =IF(D4="","",C4/D4) | G4: =IF(OR(B4="",B3=""),"",B4/B3-1) | H4: =IF(OR(C4="",C3=""),"",C4/C3-1) | I4: =IF(OR(D4="",D3=""),"",D4/D3-1) | J4: =IF(MAX(SUMIFS('Year NSE Equity Futures'!$G:$G,'Year NSE Equity Futures'!$A:$A,$A4),SUMIFS('Monthly NSE Equity Futures'!$I:$I,'Monthly NSE Equity Futures'!$B:$B,$A4))=0,"",MAX(SUMIFS('Year NSE Equity Futures'!$G:$G,'Year NSE Equity Futures'!$A:$A,$A4),SUMIFS('Monthly NSE Equity Futures'!$I:$I,'Monthly NSE Equity Futures'!$B:$B,$A4))) | K4: =IF(SUMIFS('Year BSE Equity Futures'!$G:$G,'Year BSE Equity Futures'!$A:$A,$A4)=0,"",SUMIFS('Year BSE Equity Futures'!$G:$G,'Year BSE Equity Futures'!$A:$A,$A4)) | L4: =IF(OR(J4="",K4=""),"",J4+K4) | M4: =IF(L4="","",J4/L4) | N4: =IF(L4="","",K4/L4)
A5: 2006-2007 | B5: =IF(MAX(SUMIFS('Year NSE Equity Futures'!$F:$F,'Year NSE Equity Futures'!$A:$A,$A5),SUMIFS('Monthly NSE Equity Futures'!$H:$H,'Monthly NSE Equity Futures'!$B:$B,$A5))=0,"",MAX(SUMIFS('Year NSE Equity Futures'!$F:$F,'Year NSE Equity Futures'!$A:$A,$A5),SUMIFS('Monthly NSE Equity Futures'!$H:$H,'Monthly NSE Equity Futures'!$B:$B,$A5))) | C5: =IF(SUMIFS('Year BSE Equity Futures'!$F:$F,'Year BSE Equity Futures'!$A:$A,$A5)=0,"",SUMIFS('Year BSE Equity Futures'!$F:$F,'Year BSE Equity Futures'!$A:$A,$A5)) | D5: =IF(OR(B5="",C5=""),"",B5+C5) | E5: =IF(D5="","",B5/D5) | F5: =IF(D5="","",C5/D5) | G5: =IF(OR(B5="",B4=""),"",B5/B4-1) | H5: =IF(OR(C5="",C4=""),"",C5/C4-1) | I5: =IF(OR(D5="",D4=""),"",D5/D4-1) | J5: =IF(MAX(SUMIFS('Year NSE Equity Futures'!$G:$G,'Year NSE Equity Futures'!$A:$A,$A5),SUMIFS('Monthly NSE Equity Futures'!$I:$I,'Monthly NSE Equity Futures'!$B:$B,$A5))=0,"",MAX(SUMIFS('Year NSE Equity Futures'!$G:$G,'Year NSE Equity Futures'!$A:$A,$A5),SUMIFS('Monthly NSE Equity Futures'!$I:$I,'Monthly NSE Equity Futures'!$B:$B,$A5))) | K5: =IF(SUMIFS('Year BSE Equity Futures'!$G:$G,'Year BSE Equity Futures'!$A:$A,$A5)=0,"",SUMIFS('Year BSE Equity Futures'!$G:$G,'Year BSE Equity Futures'!$A:$A,$A5)) | L5: =IF(OR(J5="",K5=""),"",J5+K5) | M5: =IF(L5="","",J5/L5) | N5: =IF(L5="","",K5/L5)
A6: 2007-2008 | B6: =IF(MAX(SUMIFS('Year NSE Equity Futures'!$F:$F,'Year NSE Equity Futures'!$A:$A,$A6),SUMIFS('Monthly NSE Equity Futures'!$H:$H,'Monthly NSE Equity Futures'!$B:$B,$A6))=0,"",MAX(SUMIFS('Year NSE Equity Futures'!$F:$F,'Year NSE Equity Futures'!$A:$A,$A6),SUMIFS('Monthly NSE Equity Futures'!$H:$H,'Monthly NSE Equity Futures'!$B:$B,$A6))) | C6: =IF(SUMIFS('Year BSE Equity Futures'!$F:$F,'Year BSE Equity Futures'!$A:$A,$A6)=0,"",SUMIFS('Year BSE Equity Futures'!$F:$F,'Year BSE Equity Futures'!$A:$A,$A6)) | D6: =IF(OR(B6="",C6=""),"",B6+C6) | E6: =IF(D6="","",B6/D6) | F6: =IF(D6="","",C6/D6) | G6: =IF(OR(B6="",B5=""),"",B6/B5-1) | H6: =IF(OR(C6="",C5=""),"",C6/C5-1) | I6: =IF(OR(D6="",D5=""),"",D6/D5-1) | J6: =IF(MAX(SUMIFS('Year NSE Equity Futures'!$G:$G,'Year NSE Equity Futures'!$A:$A,$A6),SUMIFS('Monthly NSE Equity Futures'!$I:$I,'Monthly NSE Equity Futures'!$B:$B,$A6))=0,"",MAX(SUMIFS('Year NSE Equity Futures'!$G:$G,'Year NSE Equity Futures'!$A:$A,$A6),SUMIFS('Monthly NSE Equity Futures'!$I:$I,'Monthly NSE Equity Futures'!$B:$B,$A6))) | K6: =IF(SUMIFS('Year BSE Equity Futures'!$G:$G,'Year BSE Equity Futures'!$A:$A,$A6)=0,"",SUMIFS('Year BSE Equity Futures'!$G:$G,'Year BSE Equity Futures'!$A:$A,$A6)) | L6: =IF(OR(J6="",K6=""),"",J6+K6) | M6: =IF(L6="","",J6/L6) | N6: =IF(L6="","",K6/L6)
A7: 2008-2009 | B7: =IF(MAX(SUMIFS('Year NSE Equity Futures'!$F:$F,'Year NSE Equity Futures'!$A:$A,$A7),SUMIFS('Monthly NSE Equity Futures'!$H:$H,'Monthly NSE Equity Futures'!$B:$B,$A7))=0,"",MAX(SUMIFS('Year NSE Equity Futures'!$F:$F,'Year NSE Equity Futures'!$A:$A,$A7),SUMIFS('Monthly NSE Equity Futures'!$H:$H,'Monthly NSE Equity Futures'!$B:$B,$A7))) | C7: =IF(SUMIFS('Year BSE Equity Futures'!$F:$F,'Year BSE Equity Futures'!$A:$A,$A7)=0,"",SUMIFS('Year BSE Equity Futures'!$F:$F,'Year BSE Equity Futures'!$A:$A,$A7)) | D7: =IF(OR(B7="",C7=""),"",B7+C7) | E7: =IF(D7="","",B7/D7) | F7: =IF(D7="","",C7/D7) | G7: =IF(OR(B7="",B6=""),"",B7/B6-1) | H7: =IF(OR(C7="",C6=""),"",C7/C6-1) | I7: =IF(OR(D7="",D6=""),"",D7/D6-1) | J7: =IF(MAX(SUMIFS('Year NSE Equity Futures'!$G:$G,'Year NSE Equity Futures'!$A:$A,$A7),SUMIFS('Monthly NSE Equity Futures'!$I:$I,'Monthly NSE Equity Futures'!$B:$B,$A7))=0,"",MAX(SUMIFS('Year NSE Equity Futures'!$G:$G,'Year NSE Equity Futures'!$A:$A,$A7),SUMIFS('Monthly NSE Equity Futures'!$I:$I,'Monthly NSE Equity Futures'!$B:$B,$A7))) | K7: =IF(SUMIFS('Year BSE Equity Futures'!$G:$G,'Year BSE Equity Futures'!$A:$A,$A7)=0,"",SUMIFS('Year BSE Equity Futures'!$G:$G,'Year BSE Equity Futures'!$A:$A,$A7)) | L7: =IF(OR(J7="",K7=""),"",J7+K7) | M7: =IF(L7="","",J7/L7) | N7: =IF(L7="","",K7/L7)
A8: 2009-2010 | B8: =IF(MAX(SUMIFS('Year NSE Equity Futures'!$F:$F,'Year NSE Equity Futures'!$A:$A,$A8),SUMIFS('Monthly NSE Equity Futures'!$H:$H,'Monthly NSE Equity Futures'!$B:$B,$A8))=0,"",MAX(SUMIFS('Year NSE Equity Futures'!$F:$F,'Year NSE Equity Futures'!$A:$A,$A8),SUMIFS('Monthly NSE Equity Futures'!$H:$H,'Monthly NSE Equity Futures'!$B:$B,$A8))) | C8: =IF(SUMIFS('Year BSE Equity Futures'!$F:$F,'Year BSE Equity Futures'!$A:$A,$A8)=0,"",SUMIFS('Year BSE Equity Futures'!$F:$F,'Year BSE Equity Futures'!$A:$A,$A8)) | D8: =IF(OR(B8="",C8=""),"",B8+C8) | E8: =IF(D8="","",B8/D8) | F8: =IF(D8="","",C8/D8) | G8: =IF(OR(B8="",B7=""),"",B8/B7-1) | H8: =IF(OR(C8="",C7=""),"",C8/C7-1) | I8: =IF(OR(D8="",D7=""),"",D8/D7-1) | J8: =IF(MAX(SUMIFS('Year NSE Equity Futures'!$G:$G,'Year NSE Equity Futures'!$A:$A,$A8),SUMIFS('Monthly NSE Equity Futures'!$I:$I,'Monthly NSE Equity Futures'!$B:$B,$A8))=0,"",MAX(SUMIFS('Year NSE Equity Futures'!$G:$G,'Year NSE Equity Futures'!$A:$A,$A8),SUMIFS('Monthly NSE Equity Futures'!$I:$I,'Monthly NSE Equity Futures'!$B:$B,$A8))) | K8: =IF(SUMIFS('Year BSE Equity Futures'!$G:$G,'Year BSE Equity Futures'!$A:$A,$A8)=0,"",SUMIFS('Year BSE Equity Futures'!$G:$G,'Year BSE Equity Futures'!$A:$A,$A8)) | L8: =IF(OR(J8="",K8=""),"",J8+K8) | M8: =IF(L8="","",J8/L8) | N8: =IF(L8="","",K8/L8)
A9: 2010-2011 | B9: =IF(MAX(SUMIFS('Year NSE Equity Futures'!$F:$F,'Year NSE Equity Futures'!$A:$A,$A9),SUMIFS('Monthly NSE Equity Futures'!$H:$H,'Monthly NSE Equity Futures'!$B:$B,$A9))=0,"",MAX(SUMIFS('Year NSE Equity Futures'!$F:$F,'Year NSE Equity Futures'!$A:$A,$A9),SUMIFS('Monthly NSE Equity Futures'!$H:$H,'Monthly NSE Equity Futures'!$B:$B,$A9))) | C9: =IF(SUMIFS('Year BSE Equity Futures'!$F:$F,'Year BSE Equity Futures'!$A:$A,$A9)=0,"",SUMIFS('Year BSE Equity Futures'!$F:$F,'Year BSE Equity Futures'!$A:$A,$A9)) | D9: =IF(OR(B9="",C9=""),"",B9+C9) | E9: =IF(D9="","",B9/D9) | F9: =IF(D9="","",C9/D9) | G9: =IF(OR(B9="",B8=""),"",B9/B8-1) | H9: =IF(OR(C9="",C8=""),"",C9/C8-1) | I9: =IF(OR(D9="",D8=""),"",D9/D8-1) | J9: =IF(MAX(SUMIFS('Year NSE Equity Futures'!$G:$G,'Year NSE Equity Futures'!$A:$A,$A9),SUMIFS('Monthly NSE Equity Futures'!$I:$I,'Monthly NSE Equity Futures'!$B:$B,$A9))=0,"",MAX(SUMIFS('Year NSE Equity Futures'!$G:$G,'Year NSE Equity Futures'!$A:$A,$A9),SUMIFS('Monthly NSE Equity Futures'!$I:$I,'Monthly NSE Equity Futures'!$B:$B,$A9))) | K9: =IF(SUMIFS('Year BSE Equity Futures'!$G:$G,'Year BSE Equity Futures'!$A:$A,$A9)=0,"",SUMIFS('Year BSE Equity Futures'!$G:$G,'Year BSE Equity Futures'!$A:$A,$A9)) | L9: =IF(OR(J9="",K9=""),"",J9+K9) | M9: =IF(L9="","",J9/L9) | N9: =IF(L9="","",K9/L9)
A10: 2011-2012 | B10: =IF(MAX(SUMIFS('Year NSE Equity Futures'!$F:$F,'Year NSE Equity Futures'!$A:$A,$A10),SUMIFS('Monthly NSE Equity Futures'!$H:$H,'Monthly NSE Equity Futures'!$B:$B,$A10))=0,"",MAX(SUMIFS('Year NSE Equity Futures'!$F:$F,'Year NSE Equity Futures'!$A:$A,$A10),SUMIFS('Monthly NSE Equity Futures'!$H:$H,'Monthly NSE Equity Futures'!$B:$B,$A10))) | C10: =IF(SUMIFS('Year BSE Equity Futures'!$F:$F,'Year BSE Equity Futures'!$A:$A,$A10)=0,"",SUMIFS('Year BSE Equity Futures'!$F:$F,'Year BSE Equity Futures'!$A:$A,$A10)) | D10: =IF(OR(B10="",C10=""),"",B10+C10) | E10: =IF(D10="","",B10/D10) | F10: =IF(D10="","",C10/D10) | G10: =IF(OR(B10="",B9=""),"",B10/B9-1) | H10: =IF(OR(C10="",C9=""),"",C10/C9-1) | I10: =IF(OR(D10="",D9=""),"",D10/D9-1) | J10: =IF(MAX(SUMIFS('Year NSE Equity Futures'!$G:$G,'Year NSE Equity Futures'!$A:$A,$A10),SUMIFS('Monthly NSE Equity Futures'!$I:$I,'Monthly NSE Equity Futures'!$B:$B,$A10))=0,"",MAX(SUMIFS('Year NSE Equity Futures'!$G:$G,'Year NSE Equity Futures'!$A:$A,$A10),SUMIFS('Monthly NSE Equity Futures'!$I:$I,'Monthly NSE Equity Futures'!$B:$B,$A10))) | K10: =IF(SUMIFS('Year BSE Equity Futures'!$G:$G,'Year BSE Equity Futures'!$A:$A,$A10)=0,"",SUMIFS('Year BSE Equity Futures'!$G:$G,'Year BSE Equity Futures'!$A:$A,$A10)) | L10: =IF(OR(J10="",K10=""),"",J10+K10) | M10: =IF(L10="","",J10/L10) | N10: =IF(L10="","",K10/L10)
A11: 2012-2013 | B11: =IF(MAX(SUMIFS('Year NSE Equity Futures'!$F:$F,'Year NSE Equity Futures'!$A:$A,$A11),SUMIFS('Monthly NSE Equity Futures'!$H:$H,'Monthly NSE Equity Futures'!$B:$B,$A11))=0,"",MAX(SUMIFS('Year NSE Equity Futures'!$F:$F,'Year NSE Equity Futures'!$A:$A,$A11),SUMIFS('Monthly NSE Equity Futures'!$H:$H,'Monthly NSE Equity Futures'!$B:$B,$A11))) | C11: =IF(SUMIFS('Year BSE Equity Futures'!$F:$F,'Year BSE Equity Futures'!$A:$A,$A11)=0,"",SUMIFS('Year BSE Equity Futures'!$F:$F,'Year BSE Equity Futures'!$A:$A,$A11)) | D11: =IF(OR(B11="",C11=""),"",B11+C11) | E11: =IF(D11="","",B11/D11) | F11: =IF(D11="","",C11/D11) | G11: =IF(OR(B11="",B10=""),"",B11/B10-1) | H11: =IF(OR(C11="",C10=""),"",C11/C10-1) | I11: =IF(OR(D11="",D10=""),"",D11/D10-1) | J11: =IF(MAX(SUMIFS('Year NSE Equity Futures'!$G:$G,'Year NSE Equity Futures'!$A:$A,$A11),SUMIFS('Monthly NSE Equity Futures'!$I:$I,'Monthly NSE Equity Futures'!$B:$B,$A11))=0,"",MAX(SUMIFS('Year NSE Equity Futures'!$G:$G,'Year NSE Equity Futures'!$A:$A,$A11),SUMIFS('Monthly NSE Equity Futures'!$I:$I,'Monthly NSE Equity Futures'!$B:$B,$A11))) | K11: =IF(SUMIFS('Year BSE Equity Futures'!$G:$G,'Year BSE Equity Futures'!$A:$A,$A11)=0,"",SUMIFS('Year BSE Equity Futures'!$G:$G,'Year BSE Equity Futures'!$A:$A,$A11)) | L11: =IF(OR(J11="",K11=""),"",J11+K11) | M11: =IF(L11="","",J11/L11) | N11: =IF(L11="","",K11/L11)
A12: 2013-2014 | B12: =IF(MAX(SUMIFS('Year NSE Equity Futures'!$F:$F,'Year NSE Equity Futures'!$A:$A,$A12),SUMIFS('Monthly NSE Equity Futures'!$H:$H,'Monthly NSE Equity Futures'!$B:$B,$A12))=0,"",MAX(SUMIFS('Year NSE Equity Futures'!$F:$F,'Year NSE Equity Futures'!$A:$A,$A12),SUMIFS('Monthly NSE Equity Futures'!$H:$H,'Monthly NSE Equity Futures'!$B:$B,$A12))) | C12: =IF(SUMIFS('Year BSE Equity Futures'!$F:$F,'Year BSE Equity Futures'!$A:$A,$A12)=0,"",SUMIFS('Year BSE Equity Futures'!$F:$F,'Year BSE Equity Futures'!$A:$A,$A12)) | D12: =IF(OR(B12="",C12=""),"",B12+C12) | E12: =IF(D12="","",B12/D12) | F12: =IF(D12="","",C12/D12) | G12: =IF(OR(B12="",B11=""),"",B12/B11-1) | H12: =IF(OR(C12="",C11=""),"",C12/C11-1) | I12: =IF(OR(D12="",D11=""),"",D12/D11-1) | J12: =IF(MAX(SUMIFS('Year NSE Equity Futures'!$G:$G,'Year NSE Equity Futures'!$A:$A,$A12),SUMIFS('Monthly NSE Equity Futures'!$I:$I,'Monthly NSE Equity Futures'!$B:$B,$A12))=0,"",MAX(SUMIFS('Year NSE Equity Futures'!$G:$G,'Year NSE Equity Futures'!$A:$A,$A12),SUMIFS('Monthly NSE Equity Futures'!$I:$I,'Monthly NSE Equity Futures'!$B:$B,$A12))) | K12: =IF(SUMIFS('Year BSE Equity Futures'!$G:$G,'Year BSE Equity Futures'!$A:$A,$A12)=0,"",SUMIFS('Year BSE Equity Futures'!$G:$G,'Year BSE Equity Futures'!$A:$A,$A12)) | L12: =IF(OR(J12="",K12=""),"",J12+K12) | M12: =IF(L12="","",J12/L12) | N12: =IF(L12="","",K12/L12)
A13: 2014-2015 | B13: =IF(MAX(SUMIFS('Year NSE Equity Futures'!$F:$F,'Year NSE Equity Futures'!$A:$A,$A13),SUMIFS('Monthly NSE Equity Futures'!$H:$H,'Monthly NSE Equity Futures'!$B:$B,$A13))=0,"",MAX(SUMIFS('Year NSE Equity Futures'!$F:$F,'Year NSE Equity Futures'!$A:$A,$A13),SUMIFS('Monthly NSE Equity Futures'!$H:$H,'Monthly NSE Equity Futures'!$B:$B,$A13))) | C13: =IF(SUMIFS('Year BSE Equity Futures'!$F:$F,'Year BSE Equity Futures'!$A:$A,$A13)=0,"",SUMIFS('Year BSE Equity Futures'!$F:$F,'Year BSE Equity Futures'!$A:$A,$A13)) | D13: =IF(OR(B13="",C13=""),"",B13+C13) | E13: =IF(D13="","",B13/D13) | F13: =IF(D13="","",C13/D13) | G13: =IF(OR(B13="",B12=""),"",B13/B12-1) | H13: =IF(OR(C13="",C12=""),"",C13/C12-1) | I13: =IF(OR(D13="",D12=""),"",D13/D12-1) | J13: =IF(MAX(SUMIFS('Year NSE Equity Futures'!$G:$G,'Year NSE Equity Futures'!$A:$A,$A13),SUMIFS('Monthly NSE Equity Futures'!$I:$I,'Monthly NSE Equity Futures'!$B:$B,$A13))=0,"",MAX(SUMIFS('Year NSE Equity Futures'!$G:$G,'Year NSE Equity Futures'!$A:$A,$A13),SUMIFS('Monthly NSE Equity Futures'!$I:$I,'Monthly NSE Equity Futures'!$B:$B,$A13))) | K13: =IF(SUMIFS('Year BSE Equity Futures'!$G:$G,'Year BSE Equity Futures'!$A:$A,$A13)=0,"",SUMIFS('Year BSE Equity Futures'!$G:$G,'Year BSE Equity Futures'!$A:$A,$A13)) | L13: =IF(OR(J13="",K13=""),"",J13+K13) | M13: =IF(L13="","",J13/L13) | N13: =IF(L13="","",K13/L13)
A14: 2015-2016 | B14: =IF(MAX(SUMIFS('Year NSE Equity Futures'!$F:$F,'Year NSE Equity Futures'!$A:$A,$A14),SUMIFS('Monthly NSE Equity Futures'!$H:$H,'Monthly NSE Equity Futures'!$B:$B,$A14))=0,"",MAX(SUMIFS('Year NSE Equity Futures'!$F:$F,'Year NSE Equity Futures'!$A:$A,$A14),SUMIFS('Monthly NSE Equity Futures'!$H:$H,'Monthly NSE Equity Futures'!$B:$B,$A14))) | C14: =IF(SUMIFS('Year BSE Equity Futures'!$F:$F,'Year BSE Equity Futures'!$A:$A,$A14)=0,"",SUMIFS('Year BSE Equity Futures'!$F:$F,'Year BSE Equity Futures'!$A:$A,$A14)) | D14: =IF(OR(B14="",C14=""),"",B14+C14) | E14: =IF(D14="","",B14/D14) | F14: =IF(D14="","",C14/D14) | G14: =IF(OR(B14="",B13=""),"",B14/B13-1) | H14: =IF(OR(C14="",C13=""),"",C14/C13-1) | I14: =IF(OR(D14="",D13=""),"",D14/D13-1) | J14: =IF(MAX(SUMIFS('Year NSE Equity Futures'!$G:$G,'Year NSE Equity Futures'!$A:$A,$A14),SUMIFS('Monthly NSE Equity Futures'!$I:$I,'Monthly NSE Equity Futures'!$B:$B,$A14))=0,"",MAX(SUMIFS('Year NSE Equity Futures'!$G:$G,'Year NSE Equity Futures'!$A:$A,$A14),SUMIFS('Monthly NSE Equity Futures'!$I:$I,'Monthly NSE Equity Futures'!$B:$B,$A14))) | K14: =IF(SUMIFS('Year BSE Equity Futures'!$G:$G,'Year BSE Equity Futures'!$A:$A,$A14)=0,"",SUMIFS('Year BSE Equity Futures'!$G:$G,'Year BSE Equity Futures'!$A:$A,$A14)) | L14: =IF(OR(J14="",K14=""),"",J14+K14) | M14: =IF(L14="","",J14/L14) | N14: =IF(L14="","",K14/L14)
... A25: 2026-2027 | B25: =IF(MAX(SUMIFS('Year NSE Equity Futures'!$F:$F,'Year NSE Equity Futures'!$A:$A,$A25),SUMIFS('Monthly NSE Equity Futures'!$H:$H,'Monthly NSE Equity Futures'!$B:$B,$A25))=0,"",MAX(SUMIFS('Year NSE Equity Futures'!$F:$F,'Year NSE Equity Futures'!$A:$A,$A25),SUMIFS('Monthly NSE Equity Futures'!$H:$H,'Monthly NSE Equity Futures'!$B:$B,$A25))) | C25: =IF(SUMIFS('Year BSE Equity Futures'!$F:$F,'Year BSE Equity Futures'!$A:$A,$A25)=0,"",SUMIFS('Year BSE Equity Futures'!$F:$F,'Year BSE Equity Futures'!$A:$A,$A25)) | D25: =IF(OR(B25="",C25=""),"",B25+C25) | E25: =IF(D25="","",B25/D25) | F25: =IF(D25="","",C25/D25) | G25: =IF(OR(B25="",B24=""),"",B25/B24-1) | H25: =IF(OR(C25="",C24=""),"",C25/C24-1) | I25: =IF(OR(D25="",D24=""),"",D25/D24-1) | J25: =IF(MAX(SUMIFS('Year NSE Equity Futures'!$G:$G,'Year NSE Equity Futures'!$A:$A,$A25),SUMIFS('Monthly NSE Equity Futures'!$I:$I,'Monthly NSE Equity Futures'!$B:$B,$A25))=0,"",MAX(SUMIFS('Year NSE Equity Futures'!$G:$G,'Year NSE Equity Futures'!$A:$A,$A25),SUMIFS('Monthly NSE Equity Futures'!$I:$I,'Monthly NSE Equity Futures'!$B:$B,$A25))) | K25: =IF(SUMIFS('Year BSE Equity Futures'!$G:$G,'Year BSE Equity Futures'!$A:$A,$A25)=0,"",SUMIFS('Year BSE Equity Futures'!$G:$G,'Year BSE Equity Futures'!$A:$A,$A25)) | L25: =IF(OR(J25="",K25=""),"",J25+K25) | M25: =IF(L25="","",J25/L25) | N25: =IF(L25="","",K25/L25)
A27: YTD Comparison - FY2026-2027 YTD vs FY2025-2026 YTD (same number of trading days)
A28: Trading days elapsed in FY2026-2027 (per NSE daily) | B28: =COUNTIF('Daily NSE Equity Futures'!$A:$A,">="&DATE(2026,4,1))
A29: Matched FY2025-2026 window | B29: =DATE(2025,4,1) | C29: =INDEX('Daily NSE Equity Futures'!$A:$A,COUNTIF('Daily NSE Equity Futures'!$A:$A,"<"&DATE(2025,4,1))+1+$B28)
B30: NSE Turnover (INR Bn) | C30: BSE Turnover (INR Bn) | D30: Total Turnover (INR Bn) | E30: NSE Turnover Market Share | F30: BSE Turnover Market Share | J30: NSE No. of Contracts | K30: BSE No. of Contracts | L30: Total No. of Contracts | M30: NSE Contracts Market Share | N30: BSE Contracts Market Share
A31: FY2025-2026 YTD (first N trading days) | B31: =SUMIFS('Daily NSE Equity Futures'!$I:$I,'Daily NSE Equity Futures'!$A:$A,">="&$B$29,'Daily NSE Equity Futures'!$A:$A,"<="&$C$29) | C31: =SUMIFS('Daily BSE Equity Futures'!$I:$I,'Daily BSE Equity Futures'!$A:$A,">="&$B$29,'Daily BSE Equity Futures'!$A:$A,"<="&$C$29) | D31: =B31+C31 | E31: =IF(D31=0,"",B31/D31) | F31: =IF(D31=0,"",C31/D31) | J31: =SUMIFS('Daily NSE Equity Futures'!$J:$J,'Daily NSE Equity Futures'!$A:$A,">="&$B$29,'Daily NSE Equity Futures'!$A:$A,"<="&$C$29) | K31: =SUMIFS('Daily BSE Equity Futures'!$J:$J,'Daily BSE Equity Futures'!$A:$A,">="&$B$29,'Daily BSE Equity Futures'!$A:$A,"<="&$C$29) | L31: =J31+K31 | M31: =IF(L31=0,"",J31/L31) | N31: =IF(L31=0,"",K31/L31)
A32: FY2026-2027 YTD | B32: =SUMIFS('Daily NSE Equity Futures'!$I:$I,'Daily NSE Equity Futures'!$A:$A,">="&DATE(2026,4,1)) | C32: =SUMIFS('Daily BSE Equity Futures'!$I:$I,'Daily BSE Equity Futures'!$A:$A,">="&DATE(2026,4,1)) | D32: =B32+C32 | E32: =IF(D32=0,"",B32/D32) | F32: =IF(D32=0,"",C32/D32) | J32: =SUMIFS('Daily NSE Equity Futures'!$J:$J,'Daily NSE Equity Futures'!$A:$A,">="&DATE(2026,4,1)) | K32: =SUMIFS('Daily BSE Equity Futures'!$J:$J,'Daily BSE Equity Futures'!$A:$A,">="&DATE(2026,4,1)) | L32: =J32+K32 | M32: =IF(L32=0,"",J32/L32) | N32: =IF(L32=0,"",K32/L32)
A33: YTD Growth (FY2026-2027 vs FY2025-2026) | B33: =IF(OR(B31=0,B31=""),"",B32/B31-1) | C33: =IF(OR(C31=0,C31=""),"",C32/C31-1) | D33: =IF(OR(D31=0,D31=""),"",D32/D31-1) | J33: =IF(OR(J31=0,J31=""),"",J32/J31-1) | K33: =IF(OR(K31=0,K31=""),"",K32/K31-1) | L33: =IF(OR(L31=0,L31=""),"",L32/L31-1)

Sheet Qrtr Equity Futures Mkt Share
A1: Qrtr - Year | B1: NSE Turnover (INR Bn) | C1: BSE Turnover (INR Bn) | D1: Total Turnover (INR Bn) | E1: NSE Turnover Market Share | F1: BSE Turnover Market Share | G1: NSE Turnover YoY Growth | H1: BSE Turnover YoY Growth | I1: Total Turnover YoY Growth | J1: NSE Turnover QoQ Growth | K1: BSE Turnover QoQ Growth | L1: Total Turnover QoQ Growth | M1: NSE No. of Contracts | N1: BSE No. of Contracts | O1: Total No. of Contracts | P1: NSE Contracts Market Share | Q1: BSE Contracts Market Share
A2: Q4FY04 | B2: =IF(SUMIFS('Monthly NSE Equity Futures'!$H:$H,'Monthly NSE Equity Futures'!$C:$C,$A2)=0,"",SUMIFS('Monthly NSE Equity Futures'!$H:$H,'Monthly NSE Equity Futures'!$C:$C,$A2)) | C2: =IF(SUMIFS('Monthly BSE Equity Futures'!$H:$H,'Monthly BSE Equity Futures'!$C:$C,$A2)=0,"",SUMIFS('Monthly BSE Equity Futures'!$H:$H,'Monthly BSE Equity Futures'!$C:$C,$A2)) | D2: =IF(OR(B2="",C2=""),"",B2+C2) | E2: =IF(D2="","",B2/D2) | F2: =IF(D2="","",C2/D2) | M2: =IF(SUMIFS('Monthly NSE Equity Futures'!$I:$I,'Monthly NSE Equity Futures'!$C:$C,$A2)=0,"",SUMIFS('Monthly NSE Equity Futures'!$I:$I,'Monthly NSE Equity Futures'!$C:$C,$A2)) | N2: =IF(SUMIFS('Monthly BSE Equity Futures'!$I:$I,'Monthly BSE Equity Futures'!$C:$C,$A2)=0,"",SUMIFS('Monthly BSE Equity Futures'!$I:$I,'Monthly BSE Equity Futures'!$C:$C,$A2)) | O2: =IF(OR(M2="",N2=""),"",M2+N2) | P2: =IF(O2="","",M2/O2) | Q2: =IF(O2="","",N2/O2)
A3: Q1FY05 | B3: =IF(SUMIFS('Monthly NSE Equity Futures'!$H:$H,'Monthly NSE Equity Futures'!$C:$C,$A3)=0,"",SUMIFS('Monthly NSE Equity Futures'!$H:$H,'Monthly NSE Equity Futures'!$C:$C,$A3)) | C3: =IF(SUMIFS('Monthly BSE Equity Futures'!$H:$H,'Monthly BSE Equity Futures'!$C:$C,$A3)=0,"",SUMIFS('Monthly BSE Equity Futures'!$H:$H,'Monthly BSE Equity Futures'!$C:$C,$A3)) | D3: =IF(OR(B3="",C3=""),"",B3+C3) | E3: =IF(D3="","",B3/D3) | F3: =IF(D3="","",C3/D3) | J3: =IF(OR(B3="",B2=""),"",B3/B2-1) | K3: =IF(OR(C3="",C2=""),"",C3/C2-1) | L3: =IF(OR(D3="",D2=""),"",D3/D2-1) | M3: =IF(SUMIFS('Monthly NSE Equity Futures'!$I:$I,'Monthly NSE Equity Futures'!$C:$C,$A3)=0,"",SUMIFS('Monthly NSE Equity Futures'!$I:$I,'Monthly NSE Equity Futures'!$C:$C,$A3)) | N3: =IF(SUMIFS('Monthly BSE Equity Futures'!$I:$I,'Monthly BSE Equity Futures'!$C:$C,$A3)=0,"",SUMIFS('Monthly BSE Equity Futures'!$I:$I,'Monthly BSE Equity Futures'!$C:$C,$A3)) | O3: =IF(OR(M3="",N3=""),"",M3+N3) | P3: =IF(O3="","",M3/O3) | Q3: =IF(O3="","",N3/O3)
A4: Q2FY05 | B4: =IF(SUMIFS('Monthly NSE Equity Futures'!$H:$H,'Monthly NSE Equity Futures'!$C:$C,$A4)=0,"",SUMIFS('Monthly NSE Equity Futures'!$H:$H,'Monthly NSE Equity Futures'!$C:$C,$A4)) | C4: =IF(SUMIFS('Monthly BSE Equity Futures'!$H:$H,'Monthly BSE Equity Futures'!$C:$C,$A4)=0,"",SUMIFS('Monthly BSE Equity Futures'!$H:$H,'Monthly BSE Equity Futures'!$C:$C,$A4)) | D4: =IF(OR(B4="",C4=""),"",B4+C4) | E4: =IF(D4="","",B4/D4) | F4: =IF(D4="","",C4/D4) | J4: =IF(OR(B4="",B3=""),"",B4/B3-1) | K4: =IF(OR(C4="",C3=""),"",C4/C3-1) | L4: =IF(OR(D4="",D3=""),"",D4/D3-1) | M4: =IF(SUMIFS('Monthly NSE Equity Futures'!$I:$I,'Monthly NSE Equity Futures'!$C:$C,$A4)=0,"",SUMIFS('Monthly NSE Equity Futures'!$I:$I,'Monthly NSE Equity Futures'!$C:$C,$A4)) | N4: =IF(SUMIFS('Monthly BSE Equity Futures'!$I:$I,'Monthly BSE Equity Futures'!$C:$C,$A4)=0,"",SUMIFS('Monthly BSE Equity Futures'!$I:$I,'Monthly BSE Equity Futures'!$C:$C,$A4)) | O4: =IF(OR(M4="",N4=""),"",M4+N4) | P4: =IF(O4="","",M4/O4) | Q4: =IF(O4="","",N4/O4)
A5: Q3FY05 | B5: =IF(SUMIFS('Monthly NSE Equity Futures'!$H:$H,'Monthly NSE Equity Futures'!$C:$C,$A5)=0,"",SUMIFS('Monthly NSE Equity Futures'!$H:$H,'Monthly NSE Equity Futures'!$C:$C,$A5)) | C5: =IF(SUMIFS('Monthly BSE Equity Futures'!$H:$H,'Monthly BSE Equity Futures'!$C:$C,$A5)=0,"",SUMIFS('Monthly BSE Equity Futures'!$H:$H,'Monthly BSE Equity Futures'!$C:$C,$A5)) | D5: =IF(OR(B5="",C5=""),"",B5+C5) | E5: =IF(D5="","",B5/D5) | F5: =IF(D5="","",C5/D5) | J5: =IF(OR(B5="",B4=""),"",B5/B4-1) | K5: =IF(OR(C5="",C4=""),"",C5/C4-1) | L5: =IF(OR(D5="",D4=""),"",D5/D4-1) | M5: =IF(SUMIFS('Monthly NSE Equity Futures'!$I:$I,'Monthly NSE Equity Futures'!$C:$C,$A5)=0,"",SUMIFS('Monthly NSE Equity Futures'!$I:$I,'Monthly NSE Equity Futures'!$C:$C,$A5)) | N5: =IF(SUMIFS('Monthly BSE Equity Futures'!$I:$I,'Monthly BSE Equity Futures'!$C:$C,$A5)=0,"",SUMIFS('Monthly BSE Equity Futures'!$I:$I,'Monthly BSE Equity Futures'!$C:$C,$A5)) | O5: =IF(OR(M5="",N5=""),"",M5+N5) | P5: =IF(O5="","",M5/O5) | Q5: =IF(O5="","",N5/O5)
A6: Q4FY05 | B6: =IF(SUMIFS('Monthly NSE Equity Futures'!$H:$H,'Monthly NSE Equity Futures'!$C:$C,$A6)=0,"",SUMIFS('Monthly NSE Equity Futures'!$H:$H,'Monthly NSE Equity Futures'!$C:$C,$A6)) | C6: =IF(SUMIFS('Monthly BSE Equity Futures'!$H:$H,'Monthly BSE Equity Futures'!$C:$C,$A6)=0,"",SUMIFS('Monthly BSE Equity Futures'!$H:$H,'Monthly BSE Equity Futures'!$C:$C,$A6)) | D6: =IF(OR(B6="",C6=""),"",B6+C6) | E6: =IF(D6="","",B6/D6) | F6: =IF(D6="","",C6/D6) | G6: =IF(OR(B6="",B2=""),"",B6/B2-1) | H6: =IF(OR(C6="",C2=""),"",C6/C2-1) | I6: =IF(OR(D6="",D2=""),"",D6/D2-1) | J6: =IF(OR(B6="",B5=""),"",B6/B5-1) | K6: =IF(OR(C6="",C5=""),"",C6/C5-1) | L6: =IF(OR(D6="",D5=""),"",D6/D5-1) | M6: =IF(SUMIFS('Monthly NSE Equity Futures'!$I:$I,'Monthly NSE Equity Futures'!$C:$C,$A6)=0,"",SUMIFS('Monthly NSE Equity Futures'!$I:$I,'Monthly NSE Equity Futures'!$C:$C,$A6)) | N6: =IF(SUMIFS('Monthly BSE Equity Futures'!$I:$I,'Monthly BSE Equity Futures'!$C:$C,$A6)=0,"",SUMIFS('Monthly BSE Equity Futures'!$I:$I,'Monthly BSE Equity Futures'!$C:$C,$A6)) | O6: =IF(OR(M6="",N6=""),"",M6+N6) | P6: =IF(O6="","",M6/O6) | Q6: =IF(O6="","",N6/O6)
A7: Q1FY06 | B7: =IF(SUMIFS('Monthly NSE Equity Futures'!$H:$H,'Monthly NSE Equity Futures'!$C:$C,$A7)=0,"",SUMIFS('Monthly NSE Equity Futures'!$H:$H,'Monthly NSE Equity Futures'!$C:$C,$A7)) | C7: =IF(SUMIFS('Monthly BSE Equity Futures'!$H:$H,'Monthly BSE Equity Futures'!$C:$C,$A7)=0,"",SUMIFS('Monthly BSE Equity Futures'!$H:$H,'Monthly BSE Equity Futures'!$C:$C,$A7)) | D7: =IF(OR(B7="",C7=""),"",B7+C7) | E7: =IF(D7="","",B7/D7) | F7: =IF(D7="","",C7/D7) | G7: =IF(OR(B7="",B3=""),"",B7/B3-1) | H7: =IF(OR(C7="",C3=""),"",C7/C3-1) | I7: =IF(OR(D7="",D3=""),"",D7/D3-1) | J7: =IF(OR(B7="",B6=""),"",B7/B6-1) | K7: =IF(OR(C7="",C6=""),"",C7/C6-1) | L7: =IF(OR(D7="",D6=""),"",D7/D6-1) | M7: =IF(SUMIFS('Monthly NSE Equity Futures'!$I:$I,'Monthly NSE Equity Futures'!$C:$C,$A7)=0,"",SUMIFS('Monthly NSE Equity Futures'!$I:$I,'Monthly NSE Equity Futures'!$C:$C,$A7)) | N7: =IF(SUMIFS('Monthly BSE Equity Futures'!$I:$I,'Monthly BSE Equity Futures'!$C:$C,$A7)=0,"",SUMIFS('Monthly BSE Equity Futures'!$I:$I,'Monthly BSE Equity Futures'!$C:$C,$A7)) | O7: =IF(OR(M7="",N7=""),"",M7+N7) | P7: =IF(O7="","",M7/O7) | Q7: =IF(O7="","",N7/O7)
A8: Q2FY06 | B8: =IF(SUMIFS('Monthly NSE Equity Futures'!$H:$H,'Monthly NSE Equity Futures'!$C:$C,$A8)=0,"",SUMIFS('Monthly NSE Equity Futures'!$H:$H,'Monthly NSE Equity Futures'!$C:$C,$A8)) | C8: =IF(SUMIFS('Monthly BSE Equity Futures'!$H:$H,'Monthly BSE Equity Futures'!$C:$C,$A8)=0,"",SUMIFS('Monthly BSE Equity Futures'!$H:$H,'Monthly BSE Equity Futures'!$C:$C,$A8)) | D8: =IF(OR(B8="",C8=""),"",B8+C8) | E8: =IF(D8="","",B8/D8) | F8: =IF(D8="","",C8/D8) | G8: =IF(OR(B8="",B4=""),"",B8/B4-1) | H8: =IF(OR(C8="",C4=""),"",C8/C4-1) | I8: =IF(OR(D8="",D4=""),"",D8/D4-1) | J8: =IF(OR(B8="",B7=""),"",B8/B7-1) | K8: =IF(OR(C8="",C7=""),"",C8/C7-1) | L8: =IF(OR(D8="",D7=""),"",D8/D7-1) | M8: =IF(SUMIFS('Monthly NSE Equity Futures'!$I:$I,'Monthly NSE Equity Futures'!$C:$C,$A8)=0,"",SUMIFS('Monthly NSE Equity Futures'!$I:$I,'Monthly NSE Equity Futures'!$C:$C,$A8)) | N8: =IF(SUMIFS('Monthly BSE Equity Futures'!$I:$I,'Monthly BSE Equity Futures'!$C:$C,$A8)=0,"",SUMIFS('Monthly BSE Equity Futures'!$I:$I,'Monthly BSE Equity Futures'!$C:$C,$A8)) | O8: =IF(OR(M8="",N8=""),"",M8+N8) | P8: =IF(O8="","",M8/O8) | Q8: =IF(O8="","",N8/O8)
A9: Q3FY06 | B9: =IF(SUMIFS('Monthly NSE Equity Futures'!$H:$H,'Monthly NSE Equity Futures'!$C:$C,$A9)=0,"",SUMIFS('Monthly NSE Equity Futures'!$H:$H,'Monthly NSE Equity Futures'!$C:$C,$A9)) | C9: =IF(SUMIFS('Monthly BSE Equity Futures'!$H:$H,'Monthly BSE Equity Futures'!$C:$C,$A9)=0,"",SUMIFS('Monthly BSE Equity Futures'!$H:$H,'Monthly BSE Equity Futures'!$C:$C,$A9)) | D9: =IF(OR(B9="",C9=""),"",B9+C9) | E9: =IF(D9="","",B9/D9) | F9: =IF(D9="","",C9/D9) | G9: =IF(OR(B9="",B5=""),"",B9/B5-1) | H9: =IF(OR(C9="",C5=""),"",C9/C5-1) | I9: =IF(OR(D9="",D5=""),"",D9/D5-1) | J9: =IF(OR(B9="",B8=""),"",B9/B8-1) | K9: =IF(OR(C9="",C8=""),"",C9/C8-1) | L9: =IF(OR(D9="",D8=""),"",D9/D8-1) | M9: =IF(SUMIFS('Monthly NSE Equity Futures'!$I:$I,'Monthly NSE Equity Futures'!$C:$C,$A9)=0,"",SUMIFS('Monthly NSE Equity Futures'!$I:$I,'Monthly NSE Equity Futures'!$C:$C,$A9)) | N9: =IF(SUMIFS('Monthly BSE Equity Futures'!$I:$I,'Monthly BSE Equity Futures'!$C:$C,$A9)=0,"",SUMIFS('Monthly BSE Equity Futures'!$I:$I,'Monthly BSE Equity Futures'!$C:$C,$A9)) | O9: =IF(OR(M9="",N9=""),"",M9+N9) | P9: =IF(O9="","",M9/O9) | Q9: =IF(O9="","",N9/O9)
A10: Q4FY06 | B10: =IF(SUMIFS('Monthly NSE Equity Futures'!$H:$H,'Monthly NSE Equity Futures'!$C:$C,$A10)=0,"",SUMIFS('Monthly NSE Equity Futures'!$H:$H,'Monthly NSE Equity Futures'!$C:$C,$A10)) | C10: =IF(SUMIFS('Monthly BSE Equity Futures'!$H:$H,'Monthly BSE Equity Futures'!$C:$C,$A10)=0,"",SUMIFS('Monthly BSE Equity Futures'!$H:$H,'Monthly BSE Equity Futures'!$C:$C,$A10)) | D10: =IF(OR(B10="",C10=""),"",B10+C10) | E10: =IF(D10="","",B10/D10) | F10: =IF(D10="","",C10/D10) | G10: =IF(OR(B10="",B6=""),"",B10/B6-1) | H10: =IF(OR(C10="",C6=""),"",C10/C6-1) | I10: =IF(OR(D10="",D6=""),"",D10/D6-1) | J10: =IF(OR(B10="",B9=""),"",B10/B9-1) | K10: =IF(OR(C10="",C9=""),"",C10/C9-1) | L10: =IF(OR(D10="",D9=""),"",D10/D9-1) | M10: =IF(SUMIFS('Monthly NSE Equity Futures'!$I:$I,'Monthly NSE Equity Futures'!$C:$C,$A10)=0,"",SUMIFS('Monthly NSE Equity Futures'!$I:$I,'Monthly NSE Equity Futures'!$C:$C,$A10)) | N10: =IF(SUMIFS('Monthly BSE Equity Futures'!$I:$I,'Monthly BSE Equity Futures'!$C:$C,$A10)=0,"",SUMIFS('Monthly BSE Equity Futures'!$I:$I,'Monthly BSE Equity Futures'!$C:$C,$A10)) | O10: =IF(OR(M10="",N10=""),"",M10+N10) | P10: =IF(O10="","",M10/O10) | Q10: =IF(O10="","",N10/O10)
A11: Q1FY07 | B11: =IF(SUMIFS('Monthly NSE Equity Futures'!$H:$H,'Monthly NSE Equity Futures'!$C:$C,$A11)=0,"",SUMIFS('Monthly NSE Equity Futures'!$H:$H,'Monthly NSE Equity Futures'!$C:$C,$A11)) | C11: =IF(SUMIFS('Monthly BSE Equity Futures'!$H:$H,'Monthly BSE Equity Futures'!$C:$C,$A11)=0,"",SUMIFS('Monthly BSE Equity Futures'!$H:$H,'Monthly BSE Equity Futures'!$C:$C,$A11)) | D11: =IF(OR(B11="",C11=""),"",B11+C11) | E11: =IF(D11="","",B11/D11) | F11: =IF(D11="","",C11/D11) | G11: =IF(OR(B11="",B7=""),"",B11/B7-1) | H11: =IF(OR(C11="",C7=""),"",C11/C7-1) | I11: =IF(OR(D11="",D7=""),"",D11/D7-1) | J11: =IF(OR(B11="",B10=""),"",B11/B10-1) | K11: =IF(OR(C11="",C10=""),"",C11/C10-1) | L11: =IF(OR(D11="",D10=""),"",D11/D10-1) | M11: =IF(SUMIFS('Monthly NSE Equity Futures'!$I:$I,'Monthly NSE Equity Futures'!$C:$C,$A11)=0,"",SUMIFS('Monthly NSE Equity Futures'!$I:$I,'Monthly NSE Equity Futures'!$C:$C,$A11)) | N11: =IF(SUMIFS('Monthly BSE Equity Futures'!$I:$I,'Monthly BSE Equity Futures'!$C:$C,$A11)=0,"",SUMIFS('Monthly BSE Equity Futures'!$I:$I,'Monthly BSE Equity Futures'!$C:$C,$A11)) | O11: =IF(OR(M11="",N11=""),"",M11+N11) | P11: =IF(O11="","",M11/O11) | Q11: =IF(O11="","",N11/O11)
A12: Q2FY07 | B12: =IF(SUMIFS('Monthly NSE Equity Futures'!$H:$H,'Monthly NSE Equity Futures'!$C:$C,$A12)=0,"",SUMIFS('Monthly NSE Equity Futures'!$H:$H,'Monthly NSE Equity Futures'!$C:$C,$A12)) | C12: =IF(SUMIFS('Monthly BSE Equity Futures'!$H:$H,'Monthly BSE Equity Futures'!$C:$C,$A12)=0,"",SUMIFS('Monthly BSE Equity Futures'!$H:$H,'Monthly BSE Equity Futures'!$C:$C,$A12)) | D12: =IF(OR(B12="",C12=""),"",B12+C12) | E12: =IF(D12="","",B12/D12) | F12: =IF(D12="","",C12/D12) | G12: =IF(OR(B12="",B8=""),"",B12/B8-1) | H12: =IF(OR(C12="",C8=""),"",C12/C8-1) | I12: =IF(OR(D12="",D8=""),"",D12/D8-1) | J12: =IF(OR(B12="",B11=""),"",B12/B11-1) | K12: =IF(OR(C12="",C11=""),"",C12/C11-1) | L12: =IF(OR(D12="",D11=""),"",D12/D11-1) | M12: =IF(SUMIFS('Monthly NSE Equity Futures'!$I:$I,'Monthly NSE Equity Futures'!$C:$C,$A12)=0,"",SUMIFS('Monthly NSE Equity Futures'!$I:$I,'Monthly NSE Equity Futures'!$C:$C,$A12)) | N12: =IF(SUMIFS('Monthly BSE Equity Futures'!$I:$I,'Monthly BSE Equity Futures'!$C:$C,$A12)=0,"",SUMIFS('Monthly BSE Equity Futures'!$I:$I,'Monthly BSE Equity Futures'!$C:$C,$A12)) | O12: =IF(OR(M12="",N12=""),"",M12+N12) | P12: =IF(O12="","",M12/O12) | Q12: =IF(O12="","",N12/O12)
A13: Q3FY07 | B13: =IF(SUMIFS('Monthly NSE Equity Futures'!$H:$H,'Monthly NSE Equity Futures'!$C:$C,$A13)=0,"",SUMIFS('Monthly NSE Equity Futures'!$H:$H,'Monthly NSE Equity Futures'!$C:$C,$A13)) | C13: =IF(SUMIFS('Monthly BSE Equity Futures'!$H:$H,'Monthly BSE Equity Futures'!$C:$C,$A13)=0,"",SUMIFS('Monthly BSE Equity Futures'!$H:$H,'Monthly BSE Equity Futures'!$C:$C,$A13)) | D13: =IF(OR(B13="",C13=""),"",B13+C13) | E13: =IF(D13="","",B13/D13) | F13: =IF(D13="","",C13/D13) | G13: =IF(OR(B13="",B9=""),"",B13/B9-1) | H13: =IF(OR(C13="",C9=""),"",C13/C9-1) | I13: =IF(OR(D13="",D9=""),"",D13/D9-1) | J13: =IF(OR(B13="",B12=""),"",B13/B12-1) | K13: =IF(OR(C13="",C12=""),"",C13/C12-1) | L13: =IF(OR(D13="",D12=""),"",D13/D12-1) | M13: =IF(SUMIFS('Monthly NSE Equity Futures'!$I:$I,'Monthly NSE Equity Futures'!$C:$C,$A13)=0,"",SUMIFS('Monthly NSE Equity Futures'!$I:$I,'Monthly NSE Equity Futures'!$C:$C,$A13)) | N13: =IF(SUMIFS('Monthly BSE Equity Futures'!$I:$I,'Monthly BSE Equity Futures'!$C:$C,$A13)=0,"",SUMIFS('Monthly BSE Equity Futures'!$I:$I,'Monthly BSE Equity Futures'!$C:$C,$A13)) | O13: =IF(OR(M13="",N13=""),"",M13+N13) | P13: =IF(O13="","",M13/O13) | Q13: =IF(O13="","",N13/O13)
A14: Q4FY07 | B14: =IF(SUMIFS('Monthly NSE Equity Futures'!$H:$H,'Monthly NSE Equity Futures'!$C:$C,$A14)=0,"",SUMIFS('Monthly NSE Equity Futures'!$H:$H,'Monthly NSE Equity Futures'!$C:$C,$A14)) | C14: =IF(SUMIFS('Monthly BSE Equity Futures'!$H:$H,'Monthly BSE Equity Futures'!$C:$C,$A14)=0,"",SUMIFS('Monthly BSE Equity Futures'!$H:$H,'Monthly BSE Equity Futures'!$C:$C,$A14)) | D14: =IF(OR(B14="",C14=""),"",B14+C14) | E14: =IF(D14="","",B14/D14) | F14: =IF(D14="","",C14/D14) | G14: =IF(OR(B14="",B10=""),"",B14/B10-1) | H14: =IF(OR(C14="",C10=""),"",C14/C10-1) | I14: =IF(OR(D14="",D10=""),"",D14/D10-1) | J14: =IF(OR(B14="",B13=""),"",B14/B13-1) | K14: =IF(OR(C14="",C13=""),"",C14/C13-1) | L14: =IF(OR(D14="",D13=""),"",D14/D13-1) | M14: =IF(SUMIFS('Monthly NSE Equity Futures'!$I:$I,'Monthly NSE Equity Futures'!$C:$C,$A14)=0,"",SUMIFS('Monthly NSE Equity Futures'!$I:$I,'Monthly NSE Equity Futures'!$C:$C,$A14)) | N14: =IF(SUMIFS('Monthly BSE Equity Futures'!$I:$I,'Monthly BSE Equity Futures'!$C:$C,$A14)=0,"",SUMIFS('Monthly BSE Equity Futures'!$I:$I,'Monthly BSE Equity Futures'!$C:$C,$A14)) | O14: =IF(OR(M14="",N14=""),"",M14+N14) | P14: =IF(O14="","",M14/O14) | Q14: =IF(O14="","",N14/O14)
A15: Q1FY08 | B15: =IF(SUMIFS('Monthly NSE Equity Futures'!$H:$H,'Monthly NSE Equity Futures'!$C:$C,$A15)=0,"",SUMIFS('Monthly NSE Equity Futures'!$H:$H,'Monthly NSE Equity Futures'!$C:$C,$A15)) | C15: =IF(SUMIFS('Monthly BSE Equity Futures'!$H:$H,'Monthly BSE Equity Futures'!$C:$C,$A15)=0,"",SUMIFS('Monthly BSE Equity Futures'!$H:$H,'Monthly BSE Equity Futures'!$C:$C,$A15)) | D15: =IF(OR(B15="",C15=""),"",B15+C15) | E15: =IF(D15="","",B15/D15) | F15: =IF(D15="","",C15/D15) | G15: =IF(OR(B15="",B11=""),"",B15/B11-1) | H15: =IF(OR(C15="",C11=""),"",C15/C11-1) | I15: =IF(OR(D15="",D11=""),"",D15/D11-1) | J15: =IF(OR(B15="",B14=""),"",B15/B14-1) | K15: =IF(OR(C15="",C14=""),"",C15/C14-1) | L15: =IF(OR(D15="",D14=""),"",D15/D14-1) | M15: =IF(SUMIFS('Monthly NSE Equity Futures'!$I:$I,'Monthly NSE Equity Futures'!$C:$C,$A15)=0,"",SUMIFS('Monthly NSE Equity Futures'!$I:$I,'Monthly NSE Equity Futures'!$C:$C,$A15)) | N15: =IF(SUMIFS('Monthly BSE Equity Futures'!$I:$I,'Monthly BSE Equity Futures'!$C:$C,$A15)=0,"",SUMIFS('Monthly BSE Equity Futures'!$I:$I,'Monthly BSE Equity Futures'!$C:$C,$A15)) | O15: =IF(OR(M15="",N15=""),"",M15+N15) | P15: =IF(O15="","",M15/O15) | Q15: =IF(O15="","",N15/O15)
A16: Q2FY08 | B16: =IF(SUMIFS('Monthly NSE Equity Futures'!$H:$H,'Monthly NSE Equity Futures'!$C:$C,$A16)=0,"",SUMIFS('Monthly NSE Equity Futures'!$H:$H,'Monthly NSE Equity Futures'!$C:$C,$A16)) | C16: =IF(SUMIFS('Monthly BSE Equity Futures'!$H:$H,'Monthly BSE Equity Futures'!$C:$C,$A16)=0,"",SUMIFS('Monthly BSE Equity Futures'!$H:$H,'Monthly BSE Equity Futures'!$C:$C,$A16)) | D16: =IF(OR(B16="",C16=""),"",B16+C16) | E16: =IF(D16="","",B16/D16) | F16: =IF(D16="","",C16/D16) | G16: =IF(OR(B16="",B12=""),"",B16/B12-1) | H16: =IF(OR(C16="",C12=""),"",C16/C12-1) | I16: =IF(OR(D16="",D12=""),"",D16/D12-1) | J16: =IF(OR(B16="",B15=""),"",B16/B15-1) | K16: =IF(OR(C16="",C15=""),"",C16/C15-1) | L16: =IF(OR(D16="",D15=""),"",D16/D15-1) | M16: =IF(SUMIFS('Monthly NSE Equity Futures'!$I:$I,'Monthly NSE Equity Futures'!$C:$C,$A16)=0,"",SUMIFS('Monthly NSE Equity Futures'!$I:$I,'Monthly NSE Equity Futures'!$C:$C,$A16)) | N16: =IF(SUMIFS('Monthly BSE Equity Futures'!$I:$I,'Monthly BSE Equity Futures'!$C:$C,$A16)=0,"",SUMIFS('Monthly BSE Equity Futures'!$I:$I,'Monthly BSE Equity Futures'!$C:$C,$A16)) | O16: =IF(OR(M16="",N16=""),"",M16+N16) | P16: =IF(O16="","",M16/O16) | Q16: =IF(O16="","",N16/O16)
A17: Q3FY08 | B17: =IF(SUMIFS('Monthly NSE Equity Futures'!$H:$H,'Monthly NSE Equity Futures'!$C:$C,$A17)=0,"",SUMIFS('Monthly NSE Equity Futures'!$H:$H,'Monthly NSE Equity Futures'!$C:$C,$A17)) | C17: =IF(SUMIFS('Monthly BSE Equity Futures'!$H:$H,'Monthly BSE Equity Futures'!$C:$C,$A17)=0,"",SUMIFS('Monthly BSE Equity Futures'!$H:$H,'Monthly BSE Equity Futures'!$C:$C,$A17)) | D17: =IF(OR(B17="",C17=""),"",B17+C17) | E17: =IF(D17="","",B17/D17) | F17: =IF(D17="","",C17/D17) | G17: =IF(OR(B17="",B13=""),"",B17/B13-1) | H17: =IF(OR(C17="",C13=""),"",C17/C13-1) | I17: =IF(OR(D17="",D13=""),"",D17/D13-1) | J17: =IF(OR(B17="",B16=""),"",B17/B16-1) | K17: =IF(OR(C17="",C16=""),"",C17/C16-1) | L17: =IF(OR(D17="",D16=""),"",D17/D16-1) | M17: =IF(SUMIFS('Monthly NSE Equity Futures'!$I:$I,'Monthly NSE Equity Futures'!$C:$C,$A17)=0,"",SUMIFS('Monthly NSE Equity Futures'!$I:$I,'Monthly NSE Equity Futures'!$C:$C,$A17)) | N17: =IF(SUMIFS('Monthly BSE Equity Futures'!$I:$I,'Monthly BSE Equity Futures'!$C:$C,$A17)=0,"",SUMIFS('Monthly BSE Equity Futures'!$I:$I,'Monthly BSE Equity Futures'!$C:$C,$A17)) | O17: =IF(OR(M17="",N17=""),"",M17+N17) | P17: =IF(O17="","",M17/O17) | Q17: =IF(O17="","",N17/O17)
... A92: Q2FY27 | B92: =IF(SUMIFS('Monthly NSE Equity Futures'!$H:$H,'Monthly NSE Equity Futures'!$C:$C,$A92)=0,"",SUMIFS('Monthly NSE Equity Futures'!$H:$H,'Monthly NSE Equity Futures'!$C:$C,$A92)) | C92: =IF(SUMIFS('Monthly BSE Equity Futures'!$H:$H,'Monthly BSE Equity Futures'!$C:$C,$A92)=0,"",SUMIFS('Monthly BSE Equity Futures'!$H:$H,'Monthly BSE Equity Futures'!$C:$C,$A92)) | D92: =IF(OR(B92="",C92=""),"",B92+C92) | E92: =IF(D92="","",B92/D92) | F92: =IF(D92="","",C92/D92) | G92: =IF(OR(B92="",B88=""),"",B92/B88-1) | H92: =IF(OR(C92="",C88=""),"",C92/C88-1) | I92: =IF(OR(D92="",D88=""),"",D92/D88-1) | J92: =IF(OR(B92="",B91=""),"",B92/B91-1) | K92: =IF(OR(C92="",C91=""),"",C92/C91-1) | L92: =IF(OR(D92="",D91=""),"",D92/D91-1) | M92: =IF(SUMIFS('Monthly NSE Equity Futures'!$I:$I,'Monthly NSE Equity Futures'!$C:$C,$A92)=0,"",SUMIFS('Monthly NSE Equity Futures'!$I:$I,'Monthly NSE Equity Futures'!$C:$C,$A92)) | N92: =IF(SUMIFS('Monthly BSE Equity Futures'!$I:$I,'Monthly BSE Equity Futures'!$C:$C,$A92)=0,"",SUMIFS('Monthly BSE Equity Futures'!$I:$I,'Monthly BSE Equity Futures'!$C:$C,$A92)) | O92: =IF(OR(M92="",N92=""),"",M92+N92) | P92: =IF(O92="","",M92/O92) | Q92: =IF(O92="","",N92/O92)
A94: QTD Comparison - Q2FY27 QTD vs Q2FY26 QTD (same number of trading days)
A95: Trading days elapsed in Q2FY27 (per NSE daily) | B95: =COUNTIF('Daily NSE Equity Futures'!$A:$A,">="&DATE(2026,7,1))
A96: Matched Q2FY26 window | B96: =DATE(2025,7,1) | C96: =INDEX('Daily NSE Equity Futures'!$A:$A,COUNTIF('Daily NSE Equity Futures'!$A:$A,"<"&DATE(2025,7,1))+1+$B95)
B97: NSE Turnover (INR Bn) | C97: BSE Turnover (INR Bn) | D97: Total Turnover (INR Bn) | E97: NSE Turnover Market Share | F97: BSE Turnover Market Share | M97: NSE No. of Contracts | N97: BSE No. of Contracts | O97: Total No. of Contracts | P97: NSE Contracts Market Share | Q97: BSE Contracts Market Share
A98: Q2FY26 QTD (first N trading days) | B98: =SUMIFS('Daily NSE Equity Futures'!$I:$I,'Daily NSE Equity Futures'!$A:$A,">="&$B$96,'Daily NSE Equity Futures'!$A:$A,"<="&$C$96) | C98: =SUMIFS('Daily BSE Equity Futures'!$I:$I,'Daily BSE Equity Futures'!$A:$A,">="&$B$96,'Daily BSE Equity Futures'!$A:$A,"<="&$C$96) | D98: =B98+C98 | E98: =IF(D98=0,"",B98/D98) | F98: =IF(D98=0,"",C98/D98) | M98: =SUMIFS('Daily NSE Equity Futures'!$J:$J,'Daily NSE Equity Futures'!$A:$A,">="&$B$96,'Daily NSE Equity Futures'!$A:$A,"<="&$C$96) | N98: =SUMIFS('Daily BSE Equity Futures'!$J:$J,'Daily BSE Equity Futures'!$A:$A,">="&$B$96,'Daily BSE Equity Futures'!$A:$A,"<="&$C$96) | O98: =M98+N98 | P98: =IF(O98=0,"",M98/O98) | Q98: =IF(O98=0,"",N98/O98)
A99: Q2FY27 QTD | B99: =SUMIFS('Daily NSE Equity Futures'!$I:$I,'Daily NSE Equity Futures'!$A:$A,">="&DATE(2026,7,1)) | C99: =SUMIFS('Daily BSE Equity Futures'!$I:$I,'Daily BSE Equity Futures'!$A:$A,">="&DATE(2026,7,1)) | D99: =B99+C99 | E99: =IF(D99=0,"",B99/D99) | F99: =IF(D99=0,"",C99/D99) | M99: =SUMIFS('Daily NSE Equity Futures'!$J:$J,'Daily NSE Equity Futures'!$A:$A,">="&DATE(2026,7,1)) | N99: =SUMIFS('Daily BSE Equity Futures'!$J:$J,'Daily BSE Equity Futures'!$A:$A,">="&DATE(2026,7,1)) | O99: =M99+N99 | P99: =IF(O99=0,"",M99/O99) | Q99: =IF(O99=0,"",N99/O99)
A100: QTD Growth (Q2FY27 vs Q2FY26) | B100: =IF(OR(B98=0,B98=""),"",B99/B98-1) | C100: =IF(OR(C98=0,C98=""),"",C99/C98-1) | D100: =IF(OR(D98=0,D98=""),"",D99/D98-1) | M100: =IF(OR(M98=0,M98=""),"",M99/M98-1) | N100: =IF(OR(N98=0,N98=""),"",N99/N98-1) | O100: =IF(OR(O98=0,O98=""),"",O99/O98-1)

Sheet Mth Equity Futures Mkt Share
A1: Month | B1: Fiscal Year | C1: Qrtr - Year | D1: NSE Turnover (INR Bn) | E1: BSE Turnover (INR Bn) | F1: Total Turnover (INR Bn) | G1: NSE Turnover Market Share | H1: BSE Turnover Market Share | I1: NSE Turnover YoY Growth | J1: BSE Turnover YoY Growth | K1: Total Turnover YoY Growth | L1: NSE Turnover MoM Growth | M1: BSE Turnover MoM Growth | N1: Total Turnover MoM Growth | O1: NSE No. of Contracts | P1: BSE No. of Contracts | Q1: Total No. of Contracts | R1: NSE Contracts Market Share | S1: BSE Contracts Market Share
A2: 37987 | B2: 2003-2004 | C2: Q4FY04 | D2: =IF(SUMIFS('Monthly NSE Equity Futures'!$H:$H,'Monthly NSE Equity Futures'!$A:$A,$A2)=0,"",SUMIFS('Monthly NSE Equity Futures'!$H:$H,'Monthly NSE Equity Futures'!$A:$A,$A2)) | E2: =IF(SUMIFS('Monthly BSE Equity Futures'!$H:$H,'Monthly BSE Equity Futures'!$A:$A,$A2)=0,"",SUMIFS('Monthly BSE Equity Futures'!$H:$H,'Monthly BSE Equity Futures'!$A:$A,$A2)) | F2: =IF(OR(D2="",E2=""),"",D2+E2) | G2: =IF(F2="","",D2/F2) | H2: =IF(F2="","",E2/F2) | O2: =IF(SUMIFS('Monthly NSE Equity Futures'!$I:$I,'Monthly NSE Equity Futures'!$A:$A,$A2)=0,"",SUMIFS('Monthly NSE Equity Futures'!$I:$I,'Monthly NSE Equity Futures'!$A:$A,$A2)) | P2: =IF(SUMIFS('Monthly BSE Equity Futures'!$I:$I,'Monthly BSE Equity Futures'!$A:$A,$A2)=0,"",SUMIFS('Monthly BSE Equity Futures'!$I:$I,'Monthly BSE Equity Futures'!$A:$A,$A2)) | Q2: =IF(OR(O2="",P2=""),"",O2+P2) | R2: =IF(Q2="","",O2/Q2) | S2: =IF(Q2="","",P2/Q2)
A3: 38018 | B3: 2003-2004 | C3: Q4FY04 | D3: =IF(SUMIFS('Monthly NSE Equity Futures'!$H:$H,'Monthly NSE Equity Futures'!$A:$A,$A3)=0,"",SUMIFS('Monthly NSE Equity Futures'!$H:$H,'Monthly NSE Equity Futures'!$A:$A,$A3)) | E3: =IF(SUMIFS('Monthly BSE Equity Futures'!$H:$H,'Monthly BSE Equity Futures'!$A:$A,$A3)=0,"",SUMIFS('Monthly BSE Equity Futures'!$H:$H,'Monthly BSE Equity Futures'!$A:$A,$A3)) | F3: =IF(OR(D3="",E3=""),"",D3+E3) | G3: =IF(F3="","",D3/F3) | H3: =IF(F3="","",E3/F3) | L3: =IF(OR(D3="",D2=""),"",D3/D2-1) | M3: =IF(OR(E3="",E2=""),"",E3/E2-1) | N3: =IF(OR(F3="",F2=""),"",F3/F2-1) | O3: =IF(SUMIFS('Monthly NSE Equity Futures'!$I:$I,'Monthly NSE Equity Futures'!$A:$A,$A3)=0,"",SUMIFS('Monthly NSE Equity Futures'!$I:$I,'Monthly NSE Equity Futures'!$A:$A,$A3)) | P3: =IF(SUMIFS('Monthly BSE Equity Futures'!$I:$I,'Monthly BSE Equity Futures'!$A:$A,$A3)=0,"",SUMIFS('Monthly BSE Equity Futures'!$I:$I,'Monthly BSE Equity Futures'!$A:$A,$A3)) | Q3: =IF(OR(O3="",P3=""),"",O3+P3) | R3: =IF(Q3="","",O3/Q3) | S3: =IF(Q3="","",P3/Q3)
