Workbook

Sheet Quality Check
A1: Exchange | B1: Sheet | C1: Data From | D1: Data To | E1: Data Rows | F1: Turnover Total (INR Bn)
A2: NSE | B2: Year NSE Equity Cash | C2: ='Year NSE Equity Cash'!A2 | D2: =LOOKUP(2,1/('Year NSE Equity Cash'!$A$2:$A$100000<>""),'Year NSE Equity Cash'!$A$2:$A$100000) | E2: =COUNTA('Year NSE Equity Cash'!$A:$A)-1 | F2: =SUM('Year NSE Equity Cash'!$I:$I)
A3: NSE | B3: Monthly NSE Equity Cash | C3: ='Monthly NSE Equity Cash'!A2 | D3: =LOOKUP(2,1/('Monthly NSE Equity Cash'!$A$2:$A$100000<>""),'Monthly NSE Equity Cash'!$A$2:$A$100000) | E3: =COUNTA('Monthly NSE Equity Cash'!$A:$A)-1 | F3: =SUM('Monthly NSE Equity Cash'!$K:$K)
A4: NSE | B4: Daily NSE Equity Cash | C4: ='Daily NSE Equity Cash'!A2 | D4: =LOOKUP(2,1/('Daily NSE Equity Cash'!$A$2:$A$100000<>""),'Daily NSE Equity Cash'!$A$2:$A$100000) | E4: =COUNTA('Daily NSE Equity Cash'!$A:$A)-1 | F4: =SUM('Daily NSE Equity Cash'!$H:$H)
A5: BSE | B5: Year BSE Equity Cash | C5: ='Year BSE Equity Cash'!A2 | D5: =LOOKUP(2,1/('Year BSE Equity Cash'!$A$2:$A$100000<>""),'Year BSE Equity Cash'!$A$2:$A$100000) | E5: =COUNTA('Year BSE Equity Cash'!$A:$A)-1 | F5: =SUM('Year BSE Equity Cash'!$F:$F)
A6: BSE | B6: Monthly BSE Equity Cash | C6: ='Monthly BSE Equity Cash'!A2 | D6: =LOOKUP(2,1/('Monthly BSE Equity Cash'!$A$2:$A$100000<>""),'Monthly BSE Equity Cash'!$A$2:$A$100000) | E6: =COUNTA('Monthly BSE Equity Cash'!$A:$A)-1 | F6: =SUM('Monthly BSE Equity Cash'!$G:$G)
A7: BSE | B7: Daily BSE Equity Cash | C7: ='Daily BSE Equity Cash'!A2 | D7: =LOOKUP(2,1/('Daily BSE Equity Cash'!$A$2:$A$100000<>""),'Daily BSE Equity Cash'!$A$2:$A$100000) | E7: =COUNTA('Daily BSE Equity Cash'!$A:$A)-1 | F7: =SUM('Daily BSE Equity Cash'!$H:$H)
A9: NSE & BSE daily end dates aligned? | C9: =IF($D$4=$D$7,"YES","NO")
A11: Turnover Reconciliation | B11: Aggregate (INR Bn) | C11: Component Sum (INR Bn) | D11: Difference | E11: Status | F11: Remarks
A12: NSE: Monthly vs Daily (Apr-2020 → last completed month) | B12: =SUMIFS('Monthly NSE Equity Cash'!$K:$K,'Monthly NSE Equity Cash'!$A:$A,">="&DATE(2020,4,1)) | C12: =SUMIFS('Daily NSE Equity Cash'!$H:$H,'Daily NSE Equity Cash'!$A:$A,"<="&EOMONTH($D$3,0)) | D12: =B12-C12 | E12: =IF(ABS(D12)<=0.25,"OK","CHECK") | F12: NSE source gaps: daily rows missing 22-Nov-2021 & 07/08/09/11/14-Aug-2023
A13: NSE: Yearly vs Monthly (FY1999-2000 → last completed FY) | B13: =SUMIFS('Year NSE Equity Cash'!$I:$I,'Year NSE Equity Cash'!$A:$A,">=1999-2000") | C13: =SUMIFS('Monthly NSE Equity Cash'!$K:$K,'Monthly NSE Equity Cash'!$A:$A,"<="&DATE(VALUE(RIGHT($D$2,4)),3,31)) | D13: =B13-C13 | E13: =IF(ABS(D13)<=0.25,"OK","CHECK") | F13: ~0.2 INR Bn rounding at NSE (FY2020-21)
A14: BSE: Monthly vs Daily (Apr-2020 → last month) | B14: =SUMIFS('Monthly BSE Equity Cash'!$G:$G,'Monthly BSE Equity Cash'!$A:$A,">="&DATE(2020,4,1)) | C14: =SUMIFS('Daily BSE Equity Cash'!$H:$H,'Daily BSE Equity Cash'!$A:$A,"<="&EOMONTH($D$6,0)) | D14: =B14-C14 | E14: =IF(ABS(D14)<=0.25,"OK","CHECK")
A15: BSE: Yearly vs Monthly (full history) | B15: =SUM('Year BSE Equity Cash'!$F:$F) | C15: =SUM('Monthly BSE Equity Cash'!$G:$G) | D15: =B15-C15 | E15: =IF(ABS(D15)<=0.25,"OK","CHECK")
A17: Notes
A18: Units: shares & trades in Crores; all monetary values in INR Bn (1 Bn = 100 Crores); same units for both exchanges.
A19: Each Market Share sheet carries a period-to-date Comparison block below the data - Year & Day: current-FY YTD vs prior FY; Qrtr: running quarter vs same quarter a year earlier; Mth: running month vs same month a year earlier - always over the FIRST EQUAL NUMBER of NSE trading days of the prior period (matched window shown in the block; live formulas on the daily sheets).
A20: NSE publishes Monthly figures only for completed months; the NSE Year sheet excludes the in-progress fiscal year.
A21: Known NSE source gaps (same on nseindia.com): daily rows missing for 22-Nov-2021 and 07/08/09/11/14-Aug-2023; Aug-2023 monthly total is ~1 trading day low; Dec-2021 monthly & FY2020-21 yearly differ by ~0.2 INR Bn (NSE rounding).
A22: History starts: NSE yearly FY1994-95, monthly Apr-1999; BSE yearly FY1997-98, monthly Nov-1997; daily sheets per chosen range.
A23: Market Share sheets: NSE turnover for periods not yet published by NSE at yearly/monthly level (current FY / current month / current quarter) is summed from the Daily NSE Equity Cash sheet; once NSE publishes the official aggregate, that figure takes over automatically.

Sheet Year Eq Cash Turnover Mkt Share
A1: Fiscal Year | B1: NSE Turnover (INR Bn) | C1: BSE Turnover (INR Bn) | D1: Total Turnover (INR Bn) | E1: NSE Market Share | F1: BSE Market Share | G1: NSE YoY Growth | H1: BSE YoY Growth | I1: Total Turnover YoY Growth
A2: 1994-1995 | B2: =IF(MAX(SUMIFS('Year NSE Equity Cash'!$I:$I,'Year NSE Equity Cash'!$A:$A,$A2),SUMIFS('Daily NSE Equity Cash'!$H:$H,'Daily NSE Equity Cash'!$A:$A,">="&DATE(VALUE(LEFT($A2,4)),4,1),'Daily NSE Equity Cash'!$A:$A,"<="&DATE(VALUE(RIGHT($A2,4)),3,31)))=0,"",MAX(SUMIFS('Year NSE Equity Cash'!$I:$I,'Year NSE Equity Cash'!$A:$A,$A2),SUMIFS('Daily NSE Equity Cash'!$H:$H,'Daily NSE Equity Cash'!$A:$A,">="&DATE(VALUE(LEFT($A2,4)),4,1),'Daily NSE Equity Cash'!$A:$A,"<="&DATE(VALUE(RIGHT($A2,4)),3,31)))) | C2: =IF(SUMIFS('Year BSE Equity Cash'!$F:$F,'Year BSE Equity Cash'!$A:$A,$A2)=0,"",SUMIFS('Year BSE Equity Cash'!$F:$F,'Year BSE Equity Cash'!$A:$A,$A2)) | D2: =IF(OR(B2="",C2=""),"",B2+C2) | E2: =IF(D2="","",B2/D2) | F2: =IF(D2="","",C2/D2)
A3: 1995-1996 | B3: =IF(MAX(SUMIFS('Year NSE Equity Cash'!$I:$I,'Year NSE Equity Cash'!$A:$A,$A3),SUMIFS('Daily NSE Equity Cash'!$H:$H,'Daily NSE Equity Cash'!$A:$A,">="&DATE(VALUE(LEFT($A3,4)),4,1),'Daily NSE Equity Cash'!$A:$A,"<="&DATE(VALUE(RIGHT($A3,4)),3,31)))=0,"",MAX(SUMIFS('Year NSE Equity Cash'!$I:$I,'Year NSE Equity Cash'!$A:$A,$A3),SUMIFS('Daily NSE Equity Cash'!$H:$H,'Daily NSE Equity Cash'!$A:$A,">="&DATE(VALUE(LEFT($A3,4)),4,1),'Daily NSE Equity Cash'!$A:$A,"<="&DATE(VALUE(RIGHT($A3,4)),3,31)))) | C3: =IF(SUMIFS('Year BSE Equity Cash'!$F:$F,'Year BSE Equity Cash'!$A:$A,$A3)=0,"",SUMIFS('Year BSE Equity Cash'!$F:$F,'Year BSE Equity Cash'!$A:$A,$A3)) | D3: =IF(OR(B3="",C3=""),"",B3+C3) | E3: =IF(D3="","",B3/D3) | F3: =IF(D3="","",C3/D3) | G3: =IF(OR(B3="",B2=""),"",B3/B2-1) | H3: =IF(OR(C3="",C2=""),"",C3/C2-1) | I3: =IF(OR(D3="",D2=""),"",D3/D2-1)
A4: 1996-1997 | B4: =IF(MAX(SUMIFS('Year NSE Equity Cash'!$I:$I,'Year NSE Equity Cash'!$A:$A,$A4),SUMIFS('Daily NSE Equity Cash'!$H:$H,'Daily NSE Equity Cash'!$A:$A,">="&DATE(VALUE(LEFT($A4,4)),4,1),'Daily NSE Equity Cash'!$A:$A,"<="&DATE(VALUE(RIGHT($A4,4)),3,31)))=0,"",MAX(SUMIFS('Year NSE Equity Cash'!$I:$I,'Year NSE Equity Cash'!$A:$A,$A4),SUMIFS('Daily NSE Equity Cash'!$H:$H,'Daily NSE Equity Cash'!$A:$A,">="&DATE(VALUE(LEFT($A4,4)),4,1),'Daily NSE Equity Cash'!$A:$A,"<="&DATE(VALUE(RIGHT($A4,4)),3,31)))) | C4: =IF(SUMIFS('Year BSE Equity Cash'!$F:$F,'Year BSE Equity Cash'!$A:$A,$A4)=0,"",SUMIFS('Year BSE Equity Cash'!$F:$F,'Year BSE Equity Cash'!$A:$A,$A4)) | D4: =IF(OR(B4="",C4=""),"",B4+C4) | E4: =IF(D4="","",B4/D4) | F4: =IF(D4="","",C4/D4) | G4: =IF(OR(B4="",B3=""),"",B4/B3-1) | H4: =IF(OR(C4="",C3=""),"",C4/C3-1) | I4: =IF(OR(D4="",D3=""),"",D4/D3-1)
A5: 1997-1998 | B5: =IF(MAX(SUMIFS('Year NSE Equity Cash'!$I:$I,'Year NSE Equity Cash'!$A:$A,$A5),SUMIFS('Daily NSE Equity Cash'!$H:$H,'Daily NSE Equity Cash'!$A:$A,">="&DATE(VALUE(LEFT($A5,4)),4,1),'Daily NSE Equity Cash'!$A:$A,"<="&DATE(VALUE(RIGHT($A5,4)),3,31)))=0,"",MAX(SUMIFS('Year NSE Equity Cash'!$I:$I,'Year NSE Equity Cash'!$A:$A,$A5),SUMIFS('Daily NSE Equity Cash'!$H:$H,'Daily NSE Equity Cash'!$A:$A,">="&DATE(VALUE(LEFT($A5,4)),4,1),'Daily NSE Equity Cash'!$A:$A,"<="&DATE(VALUE(RIGHT($A5,4)),3,31)))) | C5: =IF(SUMIFS('Year BSE Equity Cash'!$F:$F,'Year BSE Equity Cash'!$A:$A,$A5)=0,"",SUMIFS('Year BSE Equity Cash'!$F:$F,'Year BSE Equity Cash'!$A:$A,$A5)) | D5: =IF(OR(B5="",C5=""),"",B5+C5) | E5: =IF(D5="","",B5/D5) | F5: =IF(D5="","",C5/D5) | G5: =IF(OR(B5="",B4=""),"",B5/B4-1) | H5: =IF(OR(C5="",C4=""),"",C5/C4-1) | I5: =IF(OR(D5="",D4=""),"",D5/D4-1)
A6: 1998-1999 | B6: =IF(MAX(SUMIFS('Year NSE Equity Cash'!$I:$I,'Year NSE Equity Cash'!$A:$A,$A6),SUMIFS('Daily NSE Equity Cash'!$H:$H,'Daily NSE Equity Cash'!$A:$A,">="&DATE(VALUE(LEFT($A6,4)),4,1),'Daily NSE Equity Cash'!$A:$A,"<="&DATE(VALUE(RIGHT($A6,4)),3,31)))=0,"",MAX(SUMIFS('Year NSE Equity Cash'!$I:$I,'Year NSE Equity Cash'!$A:$A,$A6),SUMIFS('Daily NSE Equity Cash'!$H:$H,'Daily NSE Equity Cash'!$A:$A,">="&DATE(VALUE(LEFT($A6,4)),4,1),'Daily NSE Equity Cash'!$A:$A,"<="&DATE(VALUE(RIGHT($A6,4)),3,31)))) | C6: =IF(SUMIFS('Year BSE Equity Cash'!$F:$F,'Year BSE Equity Cash'!$A:$A,$A6)=0,"",SUMIFS('Year BSE Equity Cash'!$F:$F,'Year BSE Equity Cash'!$A:$A,$A6)) | D6: =IF(OR(B6="",C6=""),"",B6+C6) | E6: =IF(D6="","",B6/D6) | F6: =IF(D6="","",C6/D6) | G6: =IF(OR(B6="",B5=""),"",B6/B5-1) | H6: =IF(OR(C6="",C5=""),"",C6/C5-1) | I6: =IF(OR(D6="",D5=""),"",D6/D5-1)
A7: 1999-2000 | B7: =IF(MAX(SUMIFS('Year NSE Equity Cash'!$I:$I,'Year NSE Equity Cash'!$A:$A,$A7),SUMIFS('Daily NSE Equity Cash'!$H:$H,'Daily NSE Equity Cash'!$A:$A,">="&DATE(VALUE(LEFT($A7,4)),4,1),'Daily NSE Equity Cash'!$A:$A,"<="&DATE(VALUE(RIGHT($A7,4)),3,31)))=0,"",MAX(SUMIFS('Year NSE Equity Cash'!$I:$I,'Year NSE Equity Cash'!$A:$A,$A7),SUMIFS('Daily NSE Equity Cash'!$H:$H,'Daily NSE Equity Cash'!$A:$A,">="&DATE(VALUE(LEFT($A7,4)),4,1),'Daily NSE Equity Cash'!$A:$A,"<="&DATE(VALUE(RIGHT($A7,4)),3,31)))) | C7: =IF(SUMIFS('Year BSE Equity Cash'!$F:$F,'Year BSE Equity Cash'!$A:$A,$A7)=0,"",SUMIFS('Year BSE Equity Cash'!$F:$F,'Year BSE Equity Cash'!$A:$A,$A7)) | D7: =IF(OR(B7="",C7=""),"",B7+C7) | E7: =IF(D7="","",B7/D7) | F7: =IF(D7="","",C7/D7) | G7: =IF(OR(B7="",B6=""),"",B7/B6-1) | H7: =IF(OR(C7="",C6=""),"",C7/C6-1) | I7: =IF(OR(D7="",D6=""),"",D7/D6-1)
A8: 2000-2001 | B8: =IF(MAX(SUMIFS('Year NSE Equity Cash'!$I:$I,'Year NSE Equity Cash'!$A:$A,$A8),SUMIFS('Daily NSE Equity Cash'!$H:$H,'Daily NSE Equity Cash'!$A:$A,">="&DATE(VALUE(LEFT($A8,4)),4,1),'Daily NSE Equity Cash'!$A:$A,"<="&DATE(VALUE(RIGHT($A8,4)),3,31)))=0,"",MAX(SUMIFS('Year NSE Equity Cash'!$I:$I,'Year NSE Equity Cash'!$A:$A,$A8),SUMIFS('Daily NSE Equity Cash'!$H:$H,'Daily NSE Equity Cash'!$A:$A,">="&DATE(VALUE(LEFT($A8,4)),4,1),'Daily NSE Equity Cash'!$A:$A,"<="&DATE(VALUE(RIGHT($A8,4)),3,31)))) | C8: =IF(SUMIFS('Year BSE Equity Cash'!$F:$F,'Year BSE Equity Cash'!$A:$A,$A8)=0,"",SUMIFS('Year BSE Equity Cash'!$F:$F,'Year BSE Equity Cash'!$A:$A,$A8)) | D8: =IF(OR(B8="",C8=""),"",B8+C8) | E8: =IF(D8="","",B8/D8) | F8: =IF(D8="","",C8/D8) | G8: =IF(OR(B8="",B7=""),"",B8/B7-1) | H8: =IF(OR(C8="",C7=""),"",C8/C7-1) | I8: =IF(OR(D8="",D7=""),"",D8/D7-1)
A9: 2001-2002 | B9: =IF(MAX(SUMIFS('Year NSE Equity Cash'!$I:$I,'Year NSE Equity Cash'!$A:$A,$A9),SUMIFS('Daily NSE Equity Cash'!$H:$H,'Daily NSE Equity Cash'!$A:$A,">="&DATE(VALUE(LEFT($A9,4)),4,1),'Daily NSE Equity Cash'!$A:$A,"<="&DATE(VALUE(RIGHT($A9,4)),3,31)))=0,"",MAX(SUMIFS('Year NSE Equity Cash'!$I:$I,'Year NSE Equity Cash'!$A:$A,$A9),SUMIFS('Daily NSE Equity Cash'!$H:$H,'Daily NSE Equity Cash'!$A:$A,">="&DATE(VALUE(LEFT($A9,4)),4,1),'Daily NSE Equity Cash'!$A:$A,"<="&DATE(VALUE(RIGHT($A9,4)),3,31)))) | C9: =IF(SUMIFS('Year BSE Equity Cash'!$F:$F,'Year BSE Equity Cash'!$A:$A,$A9)=0,"",SUMIFS('Year BSE Equity Cash'!$F:$F,'Year BSE Equity Cash'!$A:$A,$A9)) | D9: =IF(OR(B9="",C9=""),"",B9+C9) | E9: =IF(D9="","",B9/D9) | F9: =IF(D9="","",C9/D9) | G9: =IF(OR(B9="",B8=""),"",B9/B8-1) | H9: =IF(OR(C9="",C8=""),"",C9/C8-1) | I9: =IF(OR(D9="",D8=""),"",D9/D8-1)
A10: 2002-2003 | B10: =IF(MAX(SUMIFS('Year NSE Equity Cash'!$I:$I,'Year NSE Equity Cash'!$A:$A,$A10),SUMIFS('Daily NSE Equity Cash'!$H:$H,'Daily NSE Equity Cash'!$A:$A,">="&DATE(VALUE(LEFT($A10,4)),4,1),'Daily NSE Equity Cash'!$A:$A,"<="&DATE(VALUE(RIGHT($A10,4)),3,31)))=0,"",MAX(SUMIFS('Year NSE Equity Cash'!$I:$I,'Year NSE Equity Cash'!$A:$A,$A10),SUMIFS('Daily NSE Equity Cash'!$H:$H,'Daily NSE Equity Cash'!$A:$A,">="&DATE(VALUE(LEFT($A10,4)),4,1),'Daily NSE Equity Cash'!$A:$A,"<="&DATE(VALUE(RIGHT($A10,4)),3,31)))) | C10: =IF(SUMIFS('Year BSE Equity Cash'!$F:$F,'Year BSE Equity Cash'!$A:$A,$A10)=0,"",SUMIFS('Year BSE Equity Cash'!$F:$F,'Year BSE Equity Cash'!$A:$A,$A10)) | D10: =IF(OR(B10="",C10=""),"",B10+C10) | E10: =IF(D10="","",B10/D10) | F10: =IF(D10="","",C10/D10) | G10: =IF(OR(B10="",B9=""),"",B10/B9-1) | H10: =IF(OR(C10="",C9=""),"",C10/C9-1) | I10: =IF(OR(D10="",D9=""),"",D10/D9-1)
A11: 2003-2004 | B11: =IF(MAX(SUMIFS('Year NSE Equity Cash'!$I:$I,'Year NSE Equity Cash'!$A:$A,$A11),SUMIFS('Daily NSE Equity Cash'!$H:$H,'Daily NSE Equity Cash'!$A:$A,">="&DATE(VALUE(LEFT($A11,4)),4,1),'Daily NSE Equity Cash'!$A:$A,"<="&DATE(VALUE(RIGHT($A11,4)),3,31)))=0,"",MAX(SUMIFS('Year NSE Equity Cash'!$I:$I,'Year NSE Equity Cash'!$A:$A,$A11),SUMIFS('Daily NSE Equity Cash'!$H:$H,'Daily NSE Equity Cash'!$A:$A,">="&DATE(VALUE(LEFT($A11,4)),4,1),'Daily NSE Equity Cash'!$A:$A,"<="&DATE(VALUE(RIGHT($A11,4)),3,31)))) | C11: =IF(SUMIFS('Year BSE Equity Cash'!$F:$F,'Year BSE Equity Cash'!$A:$A,$A11)=0,"",SUMIFS('Year BSE Equity Cash'!$F:$F,'Year BSE Equity Cash'!$A:$A,$A11)) | D11: =IF(OR(B11="",C11=""),"",B11+C11) | E11: =IF(D11="","",B11/D11) | F11: =IF(D11="","",C11/D11) | G11: =IF(OR(B11="",B10=""),"",B11/B10-1) | H11: =IF(OR(C11="",C10=""),"",C11/C10-1) | I11: =IF(OR(D11="",D10=""),"",D11/D10-1)
A12: 2004-2005 | B12: =IF(MAX(SUMIFS('Year NSE Equity Cash'!$I:$I,'Year NSE Equity Cash'!$A:$A,$A12),SUMIFS('Daily NSE Equity Cash'!$H:$H,'Daily NSE Equity Cash'!$A:$A,">="&DATE(VALUE(LEFT($A12,4)),4,1),'Daily NSE Equity Cash'!$A:$A,"<="&DATE(VALUE(RIGHT($A12,4)),3,31)))=0,"",MAX(SUMIFS('Year NSE Equity Cash'!$I:$I,'Year NSE Equity Cash'!$A:$A,$A12),SUMIFS('Daily NSE Equity Cash'!$H:$H,'Daily NSE Equity Cash'!$A:$A,">="&DATE(VALUE(LEFT($A12,4)),4,1),'Daily NSE Equity Cash'!$A:$A,"<="&DATE(VALUE(RIGHT($A12,4)),3,31)))) | C12: =IF(SUMIFS('Year BSE Equity Cash'!$F:$F,'Year BSE Equity Cash'!$A:$A,$A12)=0,"",SUMIFS('Year BSE Equity Cash'!$F:$F,'Year BSE Equity Cash'!$A:$A,$A12)) | D12: =IF(OR(B12="",C12=""),"",B12+C12) | E12: =IF(D12="","",B12/D12) | F12: =IF(D12="","",C12/D12) | G12: =IF(OR(B12="",B11=""),"",B12/B11-1) | H12: =IF(OR(C12="",C11=""),"",C12/C11-1) | I12: =IF(OR(D12="",D11=""),"",D12/D11-1)
A13: 2005-2006 | B13: =IF(MAX(SUMIFS('Year NSE Equity Cash'!$I:$I,'Year NSE Equity Cash'!$A:$A,$A13),SUMIFS('Daily NSE Equity Cash'!$H:$H,'Daily NSE Equity Cash'!$A:$A,">="&DATE(VALUE(LEFT($A13,4)),4,1),'Daily NSE Equity Cash'!$A:$A,"<="&DATE(VALUE(RIGHT($A13,4)),3,31)))=0,"",MAX(SUMIFS('Year NSE Equity Cash'!$I:$I,'Year NSE Equity Cash'!$A:$A,$A13),SUMIFS('Daily NSE Equity Cash'!$H:$H,'Daily NSE Equity Cash'!$A:$A,">="&DATE(VALUE(LEFT($A13,4)),4,1),'Daily NSE Equity Cash'!$A:$A,"<="&DATE(VALUE(RIGHT($A13,4)),3,31)))) | C13: =IF(SUMIFS('Year BSE Equity Cash'!$F:$F,'Year BSE Equity Cash'!$A:$A,$A13)=0,"",SUMIFS('Year BSE Equity Cash'!$F:$F,'Year BSE Equity Cash'!$A:$A,$A13)) | D13: =IF(OR(B13="",C13=""),"",B13+C13) | E13: =IF(D13="","",B13/D13) | F13: =IF(D13="","",C13/D13) | G13: =IF(OR(B13="",B12=""),"",B13/B12-1) | H13: =IF(OR(C13="",C12=""),"",C13/C12-1) | I13: =IF(OR(D13="",D12=""),"",D13/D12-1)
A14: 2006-2007 | B14: =IF(MAX(SUMIFS('Year NSE Equity Cash'!$I:$I,'Year NSE Equity Cash'!$A:$A,$A14),SUMIFS('Daily NSE Equity Cash'!$H:$H,'Daily NSE Equity Cash'!$A:$A,">="&DATE(VALUE(LEFT($A14,4)),4,1),'Daily NSE Equity Cash'!$A:$A,"<="&DATE(VALUE(RIGHT($A14,4)),3,31)))=0,"",MAX(SUMIFS('Year NSE Equity Cash'!$I:$I,'Year NSE Equity Cash'!$A:$A,$A14),SUMIFS('Daily NSE Equity Cash'!$H:$H,'Daily NSE Equity Cash'!$A:$A,">="&DATE(VALUE(LEFT($A14,4)),4,1),'Daily NSE Equity Cash'!$A:$A,"<="&DATE(VALUE(RIGHT($A14,4)),3,31)))) | C14: =IF(SUMIFS('Year BSE Equity Cash'!$F:$F,'Year BSE Equity Cash'!$A:$A,$A14)=0,"",SUMIFS('Year BSE Equity Cash'!$F:$F,'Year BSE Equity Cash'!$A:$A,$A14)) | D14: =IF(OR(B14="",C14=""),"",B14+C14) | E14: =IF(D14="","",B14/D14) | F14: =IF(D14="","",C14/D14) | G14: =IF(OR(B14="",B13=""),"",B14/B13-1) | H14: =IF(OR(C14="",C13=""),"",C14/C13-1) | I14: =IF(OR(D14="",D13=""),"",D14/D13-1)
... A34: 2026-2027 | B34: =IF(MAX(SUMIFS('Year NSE Equity Cash'!$I:$I,'Year NSE Equity Cash'!$A:$A,$A34),SUMIFS('Daily NSE Equity Cash'!$H:$H,'Daily NSE Equity Cash'!$A:$A,">="&DATE(VALUE(LEFT($A34,4)),4,1),'Daily NSE Equity Cash'!$A:$A,"<="&DATE(VALUE(RIGHT($A34,4)),3,31)))=0,"",MAX(SUMIFS('Year NSE Equity Cash'!$I:$I,'Year NSE Equity Cash'!$A:$A,$A34),SUMIFS('Daily NSE Equity Cash'!$H:$H,'Daily NSE Equity Cash'!$A:$A,">="&DATE(VALUE(LEFT($A34,4)),4,1),'Daily NSE Equity Cash'!$A:$A,"<="&DATE(VALUE(RIGHT($A34,4)),3,31)))) | C34: =IF(SUMIFS('Year BSE Equity Cash'!$F:$F,'Year BSE Equity Cash'!$A:$A,$A34)=0,"",SUMIFS('Year BSE Equity Cash'!$F:$F,'Year BSE Equity Cash'!$A:$A,$A34)) | D34: =IF(OR(B34="",C34=""),"",B34+C34) | E34: =IF(D34="","",B34/D34) | F34: =IF(D34="","",C34/D34) | G34: =IF(OR(B34="",B33=""),"",B34/B33-1) | H34: =IF(OR(C34="",C33=""),"",C34/C33-1) | I34: =IF(OR(D34="",D33=""),"",D34/D33-1)
A36: YTD Comparison - FY2026-2027 YTD vs FY2025-2026 YTD (same number of trading days)
A37: Trading days elapsed in FY2026-2027 (per NSE daily) | B37: =COUNTIF('Daily NSE Equity Cash'!$A:$A,">="&DATE(2026,4,1))
A38: Matched FY2025-2026 window | B38: =DATE(2025,4,1) | C38: =INDEX('Daily NSE Equity Cash'!$A:$A,COUNTIF('Daily NSE Equity Cash'!$A:$A,"<"&DATE(2025,4,1))+1+$B37)
B39: NSE Turnover (INR Bn) | C39: BSE Turnover (INR Bn) | D39: Total Turnover (INR Bn) | E39: NSE Market Share | F39: BSE Market Share
A40: FY2025-2026 YTD (first N trading days) | B40: =SUMIFS('Daily NSE Equity Cash'!$H:$H,'Daily NSE Equity Cash'!$A:$A,">="&$B$38,'Daily NSE Equity Cash'!$A:$A,"<="&$C$38) | C40: =SUMIFS('Daily BSE Equity Cash'!$H:$H,'Daily BSE Equity Cash'!$A:$A,">="&$B$38,'Daily BSE Equity Cash'!$A:$A,"<="&$C$38) | D40: =B40+C40 | E40: =IF(D40=0,"",B40/D40) | F40: =IF(D40=0,"",C40/D40)
A41: FY2026-2027 YTD | B41: =SUMIFS('Daily NSE Equity Cash'!$H:$H,'Daily NSE Equity Cash'!$A:$A,">="&DATE(2026,4,1)) | C41: =SUMIFS('Daily BSE Equity Cash'!$H:$H,'Daily BSE Equity Cash'!$A:$A,">="&DATE(2026,4,1)) | D41: =B41+C41 | E41: =IF(D41=0,"",B41/D41) | F41: =IF(D41=0,"",C41/D41)
A42: YTD Growth (FY2026-2027 vs FY2025-2026) | B42: =IF(OR(B40=0,B40=""),"",B41/B40-1) | C42: =IF(OR(C40=0,C40=""),"",C41/C40-1) | D42: =IF(OR(D40=0,D40=""),"",D41/D40-1)

Sheet Qrtr Eq Cash Turnover Mkt Share
A1: Qrtr - Year | B1: NSE Turnover (INR Bn) | C1: BSE Turnover (INR Bn) | D1: Total Turnover (INR Bn) | E1: NSE Market Share | F1: BSE Market Share | G1: NSE YoY Growth | H1: BSE YoY Growth | I1: Total Turnover YoY Growth | J1: NSE QoQ Growth | K1: BSE QoQ Growth | L1: Total Turnover QoQ Growth
A2: Q3FY98 | B2: =IF(MAX(SUMIFS('Monthly NSE Equity Cash'!$K:$K,'Monthly NSE Equity Cash'!$C:$C,$A2),SUMIFS('Daily NSE Equity Cash'!$H:$H,'Daily NSE Equity Cash'!$D:$D,$A2))=0,"",MAX(SUMIFS('Monthly NSE Equity Cash'!$K:$K,'Monthly NSE Equity Cash'!$C:$C,$A2),SUMIFS('Daily NSE Equity Cash'!$H:$H,'Daily NSE Equity Cash'!$D:$D,$A2))) | C2: =IF(SUMIFS('Monthly BSE Equity Cash'!$G:$G,'Monthly BSE Equity Cash'!$C:$C,$A2)=0,"",SUMIFS('Monthly BSE Equity Cash'!$G:$G,'Monthly BSE Equity Cash'!$C:$C,$A2)) | D2: =IF(OR(B2="",C2=""),"",B2+C2) | E2: =IF(D2="","",B2/D2) | F2: =IF(D2="","",C2/D2)
A3: Q4FY98 | B3: =IF(MAX(SUMIFS('Monthly NSE Equity Cash'!$K:$K,'Monthly NSE Equity Cash'!$C:$C,$A3),SUMIFS('Daily NSE Equity Cash'!$H:$H,'Daily NSE Equity Cash'!$D:$D,$A3))=0,"",MAX(SUMIFS('Monthly NSE Equity Cash'!$K:$K,'Monthly NSE Equity Cash'!$C:$C,$A3),SUMIFS('Daily NSE Equity Cash'!$H:$H,'Daily NSE Equity Cash'!$D:$D,$A3))) | C3: =IF(SUMIFS('Monthly BSE Equity Cash'!$G:$G,'Monthly BSE Equity Cash'!$C:$C,$A3)=0,"",SUMIFS('Monthly BSE Equity Cash'!$G:$G,'Monthly BSE Equity Cash'!$C:$C,$A3)) | D3: =IF(OR(B3="",C3=""),"",B3+C3) | E3: =IF(D3="","",B3/D3) | F3: =IF(D3="","",C3/D3) | J3: =IF(OR(B3="",B2=""),"",B3/B2-1) | K3: =IF(OR(C3="",C2=""),"",C3/C2-1) | L3: =IF(OR(D3="",D2=""),"",D3/D2-1)
A4: Q1FY99 | B4: =IF(MAX(SUMIFS('Monthly NSE Equity Cash'!$K:$K,'Monthly NSE Equity Cash'!$C:$C,$A4),SUMIFS('Daily NSE Equity Cash'!$H:$H,'Daily NSE Equity Cash'!$D:$D,$A4))=0,"",MAX(SUMIFS('Monthly NSE Equity Cash'!$K:$K,'Monthly NSE Equity Cash'!$C:$C,$A4),SUMIFS('Daily NSE Equity Cash'!$H:$H,'Daily NSE Equity Cash'!$D:$D,$A4))) | C4: =IF(SUMIFS('Monthly BSE Equity Cash'!$G:$G,'Monthly BSE Equity Cash'!$C:$C,$A4)=0,"",SUMIFS('Monthly BSE Equity Cash'!$G:$G,'Monthly BSE Equity Cash'!$C:$C,$A4)) | D4: =IF(OR(B4="",C4=""),"",B4+C4) | E4: =IF(D4="","",B4/D4) | F4: =IF(D4="","",C4/D4) | J4: =IF(OR(B4="",B3=""),"",B4/B3-1) | K4: =IF(OR(C4="",C3=""),"",C4/C3-1) | L4: =IF(OR(D4="",D3=""),"",D4/D3-1)
A5: Q2FY99 | B5: =IF(MAX(SUMIFS('Monthly NSE Equity Cash'!$K:$K,'Monthly NSE Equity Cash'!$C:$C,$A5),SUMIFS('Daily NSE Equity Cash'!$H:$H,'Daily NSE Equity Cash'!$D:$D,$A5))=0,"",MAX(SUMIFS('Monthly NSE Equity Cash'!$K:$K,'Monthly NSE Equity Cash'!$C:$C,$A5),SUMIFS('Daily NSE Equity Cash'!$H:$H,'Daily NSE Equity Cash'!$D:$D,$A5))) | C5: =IF(SUMIFS('Monthly BSE Equity Cash'!$G:$G,'Monthly BSE Equity Cash'!$C:$C,$A5)=0,"",SUMIFS('Monthly BSE Equity Cash'!$G:$G,'Monthly BSE Equity Cash'!$C:$C,$A5)) | D5: =IF(OR(B5="",C5=""),"",B5+C5) | E5: =IF(D5="","",B5/D5) | F5: =IF(D5="","",C5/D5) | J5: =IF(OR(B5="",B4=""),"",B5/B4-1) | K5: =IF(OR(C5="",C4=""),"",C5/C4-1) | L5: =IF(OR(D5="",D4=""),"",D5/D4-1)
A6: Q3FY99 | B6: =IF(MAX(SUMIFS('Monthly NSE Equity Cash'!$K:$K,'Monthly NSE Equity Cash'!$C:$C,$A6),SUMIFS('Daily NSE Equity Cash'!$H:$H,'Daily NSE Equity Cash'!$D:$D,$A6))=0,"",MAX(SUMIFS('Monthly NSE Equity Cash'!$K:$K,'Monthly NSE Equity Cash'!$C:$C,$A6),SUMIFS('Daily NSE Equity Cash'!$H:$H,'Daily NSE Equity Cash'!$D:$D,$A6))) | C6: =IF(SUMIFS('Monthly BSE Equity Cash'!$G:$G,'Monthly BSE Equity Cash'!$C:$C,$A6)=0,"",SUMIFS('Monthly BSE Equity Cash'!$G:$G,'Monthly BSE Equity Cash'!$C:$C,$A6)) | D6: =IF(OR(B6="",C6=""),"",B6+C6) | E6: =IF(D6="","",B6/D6) | F6: =IF(D6="","",C6/D6) | G6: =IF(OR(B6="",B2=""),"",B6/B2-1) | H6: =IF(OR(C6="",C2=""),"",C6/C2-1) | I6: =IF(OR(D6="",D2=""),"",D6/D2-1) | J6: =IF(OR(B6="",B5=""),"",B6/B5-1) | K6: =IF(OR(C6="",C5=""),"",C6/C5-1) | L6: =IF(OR(D6="",D5=""),"",D6/D5-1)
A7: Q4FY99 | B7: =IF(MAX(SUMIFS('Monthly NSE Equity Cash'!$K:$K,'Monthly NSE Equity Cash'!$C:$C,$A7),SUMIFS('Daily NSE Equity Cash'!$H:$H,'Daily NSE Equity Cash'!$D:$D,$A7))=0,"",MAX(SUMIFS('Monthly NSE Equity Cash'!$K:$K,'Monthly NSE Equity Cash'!$C:$C,$A7),SUMIFS('Daily NSE Equity Cash'!$H:$H,'Daily NSE Equity Cash'!$D:$D,$A7))) | C7: =IF(SUMIFS('Monthly BSE Equity Cash'!$G:$G,'Monthly BSE Equity Cash'!$C:$C,$A7)=0,"",SUMIFS('Monthly BSE Equity Cash'!$G:$G,'Monthly BSE Equity Cash'!$C:$C,$A7)) | D7: =IF(OR(B7="",C7=""),"",B7+C7) | E7: =IF(D7="","",B7/D7) | F7: =IF(D7="","",C7/D7) | G7: =IF(OR(B7="",B3=""),"",B7/B3-1) | H7: =IF(OR(C7="",C3=""),"",C7/C3-1) | I7: =IF(OR(D7="",D3=""),"",D7/D3-1) | J7: =IF(OR(B7="",B6=""),"",B7/B6-1) | K7: =IF(OR(C7="",C6=""),"",C7/C6-1) | L7: =IF(OR(D7="",D6=""),"",D7/D6-1)
A8: Q1FY00 | B8: =IF(MAX(SUMIFS('Monthly NSE Equity Cash'!$K:$K,'Monthly NSE Equity Cash'!$C:$C,$A8),SUMIFS('Daily NSE Equity Cash'!$H:$H,'Daily NSE Equity Cash'!$D:$D,$A8))=0,"",MAX(SUMIFS('Monthly NSE Equity Cash'!$K:$K,'Monthly NSE Equity Cash'!$C:$C,$A8),SUMIFS('Daily NSE Equity Cash'!$H:$H,'Daily NSE Equity Cash'!$D:$D,$A8))) | C8: =IF(SUMIFS('Monthly BSE Equity Cash'!$G:$G,'Monthly BSE Equity Cash'!$C:$C,$A8)=0,"",SUMIFS('Monthly BSE Equity Cash'!$G:$G,'Monthly BSE Equity Cash'!$C:$C,$A8)) | D8: =IF(OR(B8="",C8=""),"",B8+C8) | E8: =IF(D8="","",B8/D8) | F8: =IF(D8="","",C8/D8) | G8: =IF(OR(B8="",B4=""),"",B8/B4-1) | H8: =IF(OR(C8="",C4=""),"",C8/C4-1) | I8: =IF(OR(D8="",D4=""),"",D8/D4-1) | J8: =IF(OR(B8="",B7=""),"",B8/B7-1) | K8: =IF(OR(C8="",C7=""),"",C8/C7-1) | L8: =IF(OR(D8="",D7=""),"",D8/D7-1)
A9: Q2FY00 | B9: =IF(MAX(SUMIFS('Monthly NSE Equity Cash'!$K:$K,'Monthly NSE Equity Cash'!$C:$C,$A9),SUMIFS('Daily NSE Equity Cash'!$H:$H,'Daily NSE Equity Cash'!$D:$D,$A9))=0,"",MAX(SUMIFS('Monthly NSE Equity Cash'!$K:$K,'Monthly NSE Equity Cash'!$C:$C,$A9),SUMIFS('Daily NSE Equity Cash'!$H:$H,'Daily NSE Equity Cash'!$D:$D,$A9))) | C9: =IF(SUMIFS('Monthly BSE Equity Cash'!$G:$G,'Monthly BSE Equity Cash'!$C:$C,$A9)=0,"",SUMIFS('Monthly BSE Equity Cash'!$G:$G,'Monthly BSE Equity Cash'!$C:$C,$A9)) | D9: =IF(OR(B9="",C9=""),"",B9+C9) | E9: =IF(D9="","",B9/D9) | F9: =IF(D9="","",C9/D9) | G9: =IF(OR(B9="",B5=""),"",B9/B5-1) | H9: =IF(OR(C9="",C5=""),"",C9/C5-1) | I9: =IF(OR(D9="",D5=""),"",D9/D5-1) | J9: =IF(OR(B9="",B8=""),"",B9/B8-1) | K9: =IF(OR(C9="",C8=""),"",C9/C8-1) | L9: =IF(OR(D9="",D8=""),"",D9/D8-1)
A10: Q3FY00 | B10: =IF(MAX(SUMIFS('Monthly NSE Equity Cash'!$K:$K,'Monthly NSE Equity Cash'!$C:$C,$A10),SUMIFS('Daily NSE Equity Cash'!$H:$H,'Daily NSE Equity Cash'!$D:$D,$A10))=0,"",MAX(SUMIFS('Monthly NSE Equity Cash'!$K:$K,'Monthly NSE Equity Cash'!$C:$C,$A10),SUMIFS('Daily NSE Equity Cash'!$H:$H,'Daily NSE Equity Cash'!$D:$D,$A10))) | C10: =IF(SUMIFS('Monthly BSE Equity Cash'!$G:$G,'Monthly BSE Equity Cash'!$C:$C,$A10)=0,"",SUMIFS('Monthly BSE Equity Cash'!$G:$G,'Monthly BSE Equity Cash'!$C:$C,$A10)) | D10: =IF(OR(B10="",C10=""),"",B10+C10) | E10: =IF(D10="","",B10/D10) | F10: =IF(D10="","",C10/D10) | G10: =IF(OR(B10="",B6=""),"",B10/B6-1) | H10: =IF(OR(C10="",C6=""),"",C10/C6-1) | I10: =IF(OR(D10="",D6=""),"",D10/D6-1) | J10: =IF(OR(B10="",B9=""),"",B10/B9-1) | K10: =IF(OR(C10="",C9=""),"",C10/C9-1) | L10: =IF(OR(D10="",D9=""),"",D10/D9-1)
A11: Q4FY00 | B11: =IF(MAX(SUMIFS('Monthly NSE Equity Cash'!$K:$K,'Monthly NSE Equity Cash'!$C:$C,$A11),SUMIFS('Daily NSE Equity Cash'!$H:$H,'Daily NSE Equity Cash'!$D:$D,$A11))=0,"",MAX(SUMIFS('Monthly NSE Equity Cash'!$K:$K,'Monthly NSE Equity Cash'!$C:$C,$A11),SUMIFS('Daily NSE Equity Cash'!$H:$H,'Daily NSE Equity Cash'!$D:$D,$A11))) | C11: =IF(SUMIFS('Monthly BSE Equity Cash'!$G:$G,'Monthly BSE Equity Cash'!$C:$C,$A11)=0,"",SUMIFS('Monthly BSE Equity Cash'!$G:$G,'Monthly BSE Equity Cash'!$C:$C,$A11)) | D11: =IF(OR(B11="",C11=""),"",B11+C11) | E11: =IF(D11="","",B11/D11) | F11: =IF(D11="","",C11/D11) | G11: =IF(OR(B11="",B7=""),"",B11/B7-1) | H11: =IF(OR(C11="",C7=""),"",C11/C7-1) | I11: =IF(OR(D11="",D7=""),"",D11/D7-1) | J11: =IF(OR(B11="",B10=""),"",B11/B10-1) | K11: =IF(OR(C11="",C10=""),"",C11/C10-1) | L11: =IF(OR(D11="",D10=""),"",D11/D10-1)
A12: Q1FY01 | B12: =IF(MAX(SUMIFS('Monthly NSE Equity Cash'!$K:$K,'Monthly NSE Equity Cash'!$C:$C,$A12),SUMIFS('Daily NSE Equity Cash'!$H:$H,'Daily NSE Equity Cash'!$D:$D,$A12))=0,"",MAX(SUMIFS('Monthly NSE Equity Cash'!$K:$K,'Monthly NSE Equity Cash'!$C:$C,$A12),SUMIFS('Daily NSE Equity Cash'!$H:$H,'Daily NSE Equity Cash'!$D:$D,$A12))) | C12: =IF(SUMIFS('Monthly BSE Equity Cash'!$G:$G,'Monthly BSE Equity Cash'!$C:$C,$A12)=0,"",SUMIFS('Monthly BSE Equity Cash'!$G:$G,'Monthly BSE Equity Cash'!$C:$C,$A12)) | D12: =IF(OR(B12="",C12=""),"",B12+C12) | E12: =IF(D12="","",B12/D12) | F12: =IF(D12="","",C12/D12) | G12: =IF(OR(B12="",B8=""),"",B12/B8-1) | H12: =IF(OR(C12="",C8=""),"",C12/C8-1) | I12: =IF(OR(D12="",D8=""),"",D12/D8-1) | J12: =IF(OR(B12="",B11=""),"",B12/B11-1) | K12: =IF(OR(C12="",C11=""),"",C12/C11-1) | L12: =IF(OR(D12="",D11=""),"",D12/D11-1)
A13: Q2FY01 | B13: =IF(MAX(SUMIFS('Monthly NSE Equity Cash'!$K:$K,'Monthly NSE Equity Cash'!$C:$C,$A13),SUMIFS('Daily NSE Equity Cash'!$H:$H,'Daily NSE Equity Cash'!$D:$D,$A13))=0,"",MAX(SUMIFS('Monthly NSE Equity Cash'!$K:$K,'Monthly NSE Equity Cash'!$C:$C,$A13),SUMIFS('Daily NSE Equity Cash'!$H:$H,'Daily NSE Equity Cash'!$D:$D,$A13))) | C13: =IF(SUMIFS('Monthly BSE Equity Cash'!$G:$G,'Monthly BSE Equity Cash'!$C:$C,$A13)=0,"",SUMIFS('Monthly BSE Equity Cash'!$G:$G,'Monthly BSE Equity Cash'!$C:$C,$A13)) | D13: =IF(OR(B13="",C13=""),"",B13+C13) | E13: =IF(D13="","",B13/D13) | F13: =IF(D13="","",C13/D13) | G13: =IF(OR(B13="",B9=""),"",B13/B9-1) | H13: =IF(OR(C13="",C9=""),"",C13/C9-1) | I13: =IF(OR(D13="",D9=""),"",D13/D9-1) | J13: =IF(OR(B13="",B12=""),"",B13/B12-1) | K13: =IF(OR(C13="",C12=""),"",C13/C12-1) | L13: =IF(OR(D13="",D12=""),"",D13/D12-1)
A14: Q3FY01 | B14: =IF(MAX(SUMIFS('Monthly NSE Equity Cash'!$K:$K,'Monthly NSE Equity Cash'!$C:$C,$A14),SUMIFS('Daily NSE Equity Cash'!$H:$H,'Daily NSE Equity Cash'!$D:$D,$A14))=0,"",MAX(SUMIFS('Monthly NSE Equity Cash'!$K:$K,'Monthly NSE Equity Cash'!$C:$C,$A14),SUMIFS('Daily NSE Equity Cash'!$H:$H,'Daily NSE Equity Cash'!$D:$D,$A14))) | C14: =IF(SUMIFS('Monthly BSE Equity Cash'!$G:$G,'Monthly BSE Equity Cash'!$C:$C,$A14)=0,"",SUMIFS('Monthly BSE Equity Cash'!$G:$G,'Monthly BSE Equity Cash'!$C:$C,$A14)) | D14: =IF(OR(B14="",C14=""),"",B14+C14) | E14: =IF(D14="","",B14/D14) | F14: =IF(D14="","",C14/D14) | G14: =IF(OR(B14="",B10=""),"",B14/B10-1) | H14: =IF(OR(C14="",C10=""),"",C14/C10-1) | I14: =IF(OR(D14="",D10=""),"",D14/D10-1) | J14: =IF(OR(B14="",B13=""),"",B14/B13-1) | K14: =IF(OR(C14="",C13=""),"",C14/C13-1) | L14: =IF(OR(D14="",D13=""),"",D14/D13-1)
A15: Q4FY01 | B15: =IF(MAX(SUMIFS('Monthly NSE Equity Cash'!$K:$K,'Monthly NSE Equity Cash'!$C:$C,$A15),SUMIFS('Daily NSE Equity Cash'!$H:$H,'Daily NSE Equity Cash'!$D:$D,$A15))=0,"",MAX(SUMIFS('Monthly NSE Equity Cash'!$K:$K,'Monthly NSE Equity Cash'!$C:$C,$A15),SUMIFS('Daily NSE Equity Cash'!$H:$H,'Daily NSE Equity Cash'!$D:$D,$A15))) | C15: =IF(SUMIFS('Monthly BSE Equity Cash'!$G:$G,'Monthly BSE Equity Cash'!$C:$C,$A15)=0,"",SUMIFS('Monthly BSE Equity Cash'!$G:$G,'Monthly BSE Equity Cash'!$C:$C,$A15)) | D15: =IF(OR(B15="",C15=""),"",B15+C15) | E15: =IF(D15="","",B15/D15) | F15: =IF(D15="","",C15/D15) | G15: =IF(OR(B15="",B11=""),"",B15/B11-1) | H15: =IF(OR(C15="",C11=""),"",C15/C11-1) | I15: =IF(OR(D15="",D11=""),"",D15/D11-1) | J15: =IF(OR(B15="",B14=""),"",B15/B14-1) | K15: =IF(OR(C15="",C14=""),"",C15/C14-1) | L15: =IF(OR(D15="",D14=""),"",D15/D14-1)
A16: Q1FY02 | B16: =IF(MAX(SUMIFS('Monthly NSE Equity Cash'!$K:$K,'Monthly NSE Equity Cash'!$C:$C,$A16),SUMIFS('Daily NSE Equity Cash'!$H:$H,'Daily NSE Equity Cash'!$D:$D,$A16))=0,"",MAX(SUMIFS('Monthly NSE Equity Cash'!$K:$K,'Monthly NSE Equity Cash'!$C:$C,$A16),SUMIFS('Daily NSE Equity Cash'!$H:$H,'Daily NSE Equity Cash'!$D:$D,$A16))) | C16: =IF(SUMIFS('Monthly BSE Equity Cash'!$G:$G,'Monthly BSE Equity Cash'!$C:$C,$A16)=0,"",SUMIFS('Monthly BSE Equity Cash'!$G:$G,'Monthly BSE Equity Cash'!$C:$C,$A16)) | D16: =IF(OR(B16="",C16=""),"",B16+C16) | E16: =IF(D16="","",B16/D16) | F16: =IF(D16="","",C16/D16) | G16: =IF(OR(B16="",B12=""),"",B16/B12-1) | H16: =IF(OR(C16="",C12=""),"",C16/C12-1) | I16: =IF(OR(D16="",D12=""),"",D16/D12-1) | J16: =IF(OR(B16="",B15=""),"",B16/B15-1) | K16: =IF(OR(C16="",C15=""),"",C16/C15-1) | L16: =IF(OR(D16="",D15=""),"",D16/D15-1)
A17: Q2FY02 | B17: =IF(MAX(SUMIFS('Monthly NSE Equity Cash'!$K:$K,'Monthly NSE Equity Cash'!$C:$C,$A17),SUMIFS('Daily NSE Equity Cash'!$H:$H,'Daily NSE Equity Cash'!$D:$D,$A17))=0,"",MAX(SUMIFS('Monthly NSE Equity Cash'!$K:$K,'Monthly NSE Equity Cash'!$C:$C,$A17),SUMIFS('Daily NSE Equity Cash'!$H:$H,'Daily NSE Equity Cash'!$D:$D,$A17))) | C17: =IF(SUMIFS('Monthly BSE Equity Cash'!$G:$G,'Monthly BSE Equity Cash'!$C:$C,$A17)=0,"",SUMIFS('Monthly BSE Equity Cash'!$G:$G,'Monthly BSE Equity Cash'!$C:$C,$A17)) | D17: =IF(OR(B17="",C17=""),"",B17+C17) | E17: =IF(D17="","",B17/D17) | F17: =IF(D17="","",C17/D17) | G17: =IF(OR(B17="",B13=""),"",B17/B13-1) | H17: =IF(OR(C17="",C13=""),"",C17/C13-1) | I17: =IF(OR(D17="",D13=""),"",D17/D13-1) | J17: =IF(OR(B17="",B16=""),"",B17/B16-1) | K17: =IF(OR(C17="",C16=""),"",C17/C16-1) | L17: =IF(OR(D17="",D16=""),"",D17/D16-1)
... A117: Q2FY27 | B117: =IF(MAX(SUMIFS('Monthly NSE Equity Cash'!$K:$K,'Monthly NSE Equity Cash'!$C:$C,$A117),SUMIFS('Daily NSE Equity Cash'!$H:$H,'Daily NSE Equity Cash'!$D:$D,$A117))=0,"",MAX(SUMIFS('Monthly NSE Equity Cash'!$K:$K,'Monthly NSE Equity Cash'!$C:$C,$A117),SUMIFS('Daily NSE Equity Cash'!$H:$H,'Daily NSE Equity Cash'!$D:$D,$A117))) | C117: =IF(SUMIFS('Monthly BSE Equity Cash'!$G:$G,'Monthly BSE Equity Cash'!$C:$C,$A117)=0,"",SUMIFS('Monthly BSE Equity Cash'!$G:$G,'Monthly BSE Equity Cash'!$C:$C,$A117)) | D117: =IF(OR(B117="",C117=""),"",B117+C117) | E117: =IF(D117="","",B117/D117) | F117: =IF(D117="","",C117/D117) | G117: =IF(OR(B117="",B113=""),"",B117/B113-1) | H117: =IF(OR(C117="",C113=""),"",C117/C113-1) | I117: =IF(OR(D117="",D113=""),"",D117/D113-1) | J117: =IF(OR(B117="",B116=""),"",B117/B116-1) | K117: =IF(OR(C117="",C116=""),"",C117/C116-1) | L117: =IF(OR(D117="",D116=""),"",D117/D116-1)
A119: QTD Comparison - Q2FY27 QTD vs Q2FY26 QTD (same number of trading days)
A120: Trading days elapsed in Q2FY27 (per NSE daily) | B120: =COUNTIF('Daily NSE Equity Cash'!$A:$A,">="&DATE(2026,7,1))
A121: Matched Q2FY26 window | B121: =DATE(2025,7,1) | C121: =INDEX('Daily NSE Equity Cash'!$A:$A,COUNTIF('Daily NSE Equity Cash'!$A:$A,"<"&DATE(2025,7,1))+1+$B120)
B122: NSE Turnover (INR Bn) | C122: BSE Turnover (INR Bn) | D122: Total Turnover (INR Bn) | E122: NSE Market Share | F122: BSE Market Share
A123: Q2FY26 QTD (first N trading days) | B123: =SUMIFS('Daily NSE Equity Cash'!$H:$H,'Daily NSE Equity Cash'!$A:$A,">="&$B$121,'Daily NSE Equity Cash'!$A:$A,"<="&$C$121) | C123: =SUMIFS('Daily BSE Equity Cash'!$H:$H,'Daily BSE Equity Cash'!$A:$A,">="&$B$121,'Daily BSE Equity Cash'!$A:$A,"<="&$C$121) | D123: =B123+C123 | E123: =IF(D123=0,"",B123/D123) | F123: =IF(D123=0,"",C123/D123)
A124: Q2FY27 QTD | B124: =SUMIFS('Daily NSE Equity Cash'!$H:$H,'Daily NSE Equity Cash'!$A:$A,">="&DATE(2026,7,1)) | C124: =SUMIFS('Daily BSE Equity Cash'!$H:$H,'Daily BSE Equity Cash'!$A:$A,">="&DATE(2026,7,1)) | D124: =B124+C124 | E124: =IF(D124=0,"",B124/D124) | F124: =IF(D124=0,"",C124/D124)
A125: QTD Growth (Q2FY27 vs Q2FY26) | B125: =IF(OR(B123=0,B123=""),"",B124/B123-1) | C125: =IF(OR(C123=0,C123=""),"",C124/C123-1) | D125: =IF(OR(D123=0,D123=""),"",D124/D123-1)

Sheet Mth Eq Cash Turnover Mkt Share
A1: Month | B1: Fiscal Year | C1: Qrtr - Year | D1: NSE Turnover (INR Bn) | E1: BSE Turnover (INR Bn) | F1: Total Turnover (INR Bn) | G1: NSE Market Share | H1: BSE Market Share | I1: NSE YoY Growth | J1: BSE YoY Growth | K1: Total Turnover YoY Growth | L1: NSE MoM Growth | M1: BSE MoM Growth | N1: Total Turnover MoM Growth
A2: 35735 | B2: 1997-1998 | C2: Q3FY98 | D2: =IF(MAX(SUMIFS('Monthly NSE Equity Cash'!$K:$K,'Monthly NSE Equity Cash'!$A:$A,$A2),SUMIFS('Daily NSE Equity Cash'!$H:$H,'Daily NSE Equity Cash'!$C:$C,$A2))=0,"",MAX(SUMIFS('Monthly NSE Equity Cash'!$K:$K,'Monthly NSE Equity Cash'!$A:$A,$A2),SUMIFS('Daily NSE Equity Cash'!$H:$H,'Daily NSE Equity Cash'!$C:$C,$A2))) | E2: =IF(SUMIFS('Monthly BSE Equity Cash'!$G:$G,'Monthly BSE Equity Cash'!$A:$A,$A2)=0,"",SUMIFS('Monthly BSE Equity Cash'!$G:$G,'Monthly BSE Equity Cash'!$A:$A,$A2)) | F2: =IF(OR(D2="",E2=""),"",D2+E2) | G2: =IF(F2="","",D2/F2) | H2: =IF(F2="","",E2/F2)
A3: 35765 | B3: 1997-1998 | C3: Q3FY98 | D3: =IF(MAX(SUMIFS('Monthly NSE Equity Cash'!$K:$K,'Monthly NSE Equity Cash'!$A:$A,$A3),SUMIFS('Daily NSE Equity Cash'!$H:$H,'Daily NSE Equity Cash'!$C:$C,$A3))=0,"",MAX(SUMIFS('Monthly NSE Equity Cash'!$K:$K,'Monthly NSE Equity Cash'!$A:$A,$A3),SUMIFS('Daily NSE Equity Cash'!$H:$H,'Daily NSE Equity Cash'!$C:$C,$A3))) | E3: =IF(SUMIFS('Monthly BSE Equity Cash'!$G:$G,'Monthly BSE Equity Cash'!$A:$A,$A3)=0,"",SUMIFS('Monthly BSE Equity Cash'!$G:$G,'Monthly BSE Equity Cash'!$A:$A,$A3)) | F3: =IF(OR(D3="",E3=""),"",D3+E3) | G3: =IF(F3="","",D3/F3) | H3: =IF(F3="","",E3/F3) | L3: =IF(OR(D3="",D2=""),"",D3/D2-1) | M3: =IF(OR(E3="",E2=""),"",E3/E2-1) | N3: =IF(OR(F3="",F2=""),"",F3/F2-1)
A4: 35796 | B4: 1997-1998 | C4: Q4FY98 | D4: =IF(MAX(SUMIFS('Monthly NSE Equity Cash'!$K:$K,'Monthly NSE Equity Cash'!$A:$A,$A4),SUMIFS('Daily NSE Equity Cash'!$H:$H,'Daily NSE Equity Cash'!$C:$C,$A4))=0,"",MAX(SUMIFS('Monthly NSE Equity Cash'!$K:$K,'Monthly NSE Equity Cash'!$A:$A,$A4),SUMIFS('Daily NSE Equity Cash'!$H:$H,'Daily NSE Equity Cash'!$C:$C,$A4))) | E4: =IF(SUMIFS('Monthly BSE Equity Cash'!$G:$G,'Monthly BSE Equity Cash'!$A:$A,$A4)=0,"",SUMIFS('Monthly BSE Equity Cash'!$G:$G,'Monthly BSE Equity Cash'!$A:$A,$A4)) | F4: =IF(OR(D4="",E4=""),"",D4+E4) | G4: =IF(F4="","",D4/F4) | H4: =IF(F4="","",E4/F4) | L4: =IF(OR(D4="",D3=""),"",D4/D3-1) | M4: =IF(OR(E4="",E3=""),"",E4/E3-1) | N4: =IF(OR(F4="",F3=""),"",F4/F3-1)
A5: 35827 | B5: 1997-1998 | C5: Q4FY98 | D5: =IF(MAX(SUMIFS('Monthly NSE Equity Cash'!$K:$K,'Monthly NSE Equity Cash'!$A:$A,$A5),SUMIFS('Daily NSE Equity Cash'!$H:$H,'Daily NSE Equity Cash'!$C:$C,$A5))=0,"",MAX(SUMIFS('Monthly NSE Equity Cash'!$K:$K,'Monthly NSE Equity Cash'!$A:$A,$A5),SUMIFS('Daily NSE Equity Cash'!$H:$H,'Daily NSE Equity Cash'!$C:$C,$A5))) | E5: =IF(SUMIFS('Monthly BSE Equity Cash'!$G:$G,'Monthly BSE Equity Cash'!$A:$A,$A5)=0,"",SUMIFS('Monthly BSE Equity Cash'!$G:$G,'Monthly BSE Equity Cash'!$A:$A,$A5)) | F5: =IF(OR(D5="",E5=""),"",D5+E5) | G5: =IF(F5="","",D5/F5) | H5: =IF(F5="","",E5/F5) | L5: =IF(OR(D5="",D4=""),"",D5/D4-1) | M5: =IF(OR(E5="",E4=""),"",E5/E4-1) | N5: =IF(OR(F5="",F4=""),"",F5/F4-1)
A6: 35855 | B6: 1997-1998 | C6: Q4FY98 | D6: =IF(MAX(SUMIFS('Monthly NSE Equity Cash'!$K:$K,'Monthly NSE Equity Cash'!$A:$A,$A6),SUMIFS('Daily NSE Equity Cash'!$H:$H,'Daily NSE Equity Cash'!$C:$C,$A6))=0,"",MAX(SUMIFS('Monthly NSE Equity Cash'!$K:$K,'Monthly NSE Equity Cash'!$A:$A,$A6),SUMIFS('Daily NSE Equity Cash'!$H:$H,'Daily NSE Equity Cash'!$C:$C,$A6))) | E6: =IF(SUMIFS('Monthly BSE Equity Cash'!$G:$G,'Monthly BSE Equity Cash'!$A:$A,$A6)=0,"",SUMIFS('Monthly BSE Equity Cash'!$G:$G,'Monthly BSE Equity Cash'!$A:$A,$A6)) | F6: =IF(OR(D6="",E6=""),"",D6+E6) | G6: =IF(F6="","",D6/F6) | H6: =IF(F6="","",E6/F6) | L6: =IF(OR(D6="",D5=""),"",D6/D5-1) | M6: =IF(OR(E6="",E5=""),"",E6/E5-1) | N6: =IF(OR(F6="",F5=""),"",F6/F5-1)
A7: 35886 | B7: 1998-1999 | C7: Q1FY99 | D7: =IF(MAX(SUMIFS('Monthly NSE Equity Cash'!$K:$K,'Monthly NSE Equity Cash'!$A:$A,$A7),SUMIFS('Daily NSE Equity Cash'!$H:$H,'Daily NSE Equity Cash'!$C:$C,$A7))=0,"",MAX(SUMIFS('Monthly NSE Equity Cash'!$K:$K,'Monthly NSE Equity Cash'!$A:$A,$A7),SUMIFS('Daily NSE Equity Cash'!$H:$H,'Daily NSE Equity Cash'!$C:$C,$A7))) | E7: =IF(SUMIFS('Monthly BSE Equity Cash'!$G:$G,'Monthly BSE Equity Cash'!$A:$A,$A7)=0,"",SUMIFS('Monthly BSE Equity Cash'!$G:$G,'Monthly BSE Equity Cash'!$A:$A,$A7)) | F7: =IF(OR(D7="",E7=""),"",D7+E7) | G7: =IF(F7="","",D7/F7) | H7: =IF(F7="","",E7/F7) | L7: =IF(OR(D7="",D6=""),"",D7/D6-1) | M7: =IF(OR(E7="",E6=""),"",E7/E6-1) | N7: =IF(OR(F7="",F6=""),"",F7/F6-1)
A8: 35916 | B8: 1998-1999 | C8: Q1FY99 | D8: =IF(MAX(SUMIFS('Monthly NSE Equity Cash'!$K:$K,'Monthly NSE Equity Cash'!$A:$A,$A8),SUMIFS('Daily NSE Equity Cash'!$H:$H,'Daily NSE Equity Cash'!$C:$C,$A8))=0,"",MAX(SUMIFS('Monthly NSE Equity Cash'!$K:$K,'Monthly NSE Equity Cash'!$A:$A,$A8),SUMIFS('Daily NSE Equity Cash'!$H:$H,'Daily NSE Equity Cash'!$C:$C,$A8))) | E8: =IF(SUMIFS('Monthly BSE Equity Cash'!$G:$G,'Monthly BSE Equity Cash'!$A:$A,$A8)=0,"",SUMIFS('Monthly BSE Equity Cash'!$G:$G,'Monthly BSE Equity Cash'!$A:$A,$A8)) | F8: =IF(OR(D8="",E8=""),"",D8+E8) | G8: =IF(F8="","",D8/F8) | H8: =IF(F8="","",E8/F8) | L8: =IF(OR(D8="",D7=""),"",D8/D7-1) | M8: =IF(OR(E8="",E7=""),"",E8/E7-1) | N8: =IF(OR(F8="",F7=""),"",F8/F7-1)
A9: 35947 | B9: 1998-1999 | C9: Q1FY99 | D9: =IF(MAX(SUMIFS('Monthly NSE Equity Cash'!$K:$K,'Monthly NSE Equity Cash'!$A:$A,$A9),SUMIFS('Daily NSE Equity Cash'!$H:$H,'Daily NSE Equity Cash'!$C:$C,$A9))=0,"",MAX(SUMIFS('Monthly NSE Equity Cash'!$K:$K,'Monthly NSE Equity Cash'!$A:$A,$A9),SUMIFS('Daily NSE Equity Cash'!$H:$H,'Daily NSE Equity Cash'!$C:$C,$A9))) | E9: =IF(SUMIFS('Monthly BSE Equity Cash'!$G:$G,'Monthly BSE Equity Cash'!$A:$A,$A9)=0,"",SUMIFS('Monthly BSE Equity Cash'!$G:$G,'Monthly BSE Equity Cash'!$A:$A,$A9)) | F9: =IF(OR(D9="",E9=""),"",D9+E9) | G9: =IF(F9="","",D9/F9) | H9: =IF(F9="","",E9/F9) | L9: =IF(OR(D9="",D8=""),"",D9/D8-1) | M9: =IF(OR(E9="",E8=""),"",E9/E8-1) | N9: =IF(OR(F9="",F8=""),"",F9/F8-1)
A10: 35977 | B10: 1998-1999 | C10: Q2FY99 | D10: =IF(MAX(SUMIFS('Monthly NSE Equity Cash'!$K:$K,'Monthly NSE Equity Cash'!$A:$A,$A10),SUMIFS('Daily NSE Equity Cash'!$H:$H,'Daily NSE Equity Cash'!$C:$C,$A10))=0,"",MAX(SUMIFS('Monthly NSE Equity Cash'!$K:$K,'Monthly NSE Equity Cash'!$A:$A,$A10),SUMIFS('Daily NSE Equity Cash'!$H:$H,'Daily NSE Equity Cash'!$C:$C,$A10))) | E10: =IF(SUMIFS('Monthly BSE Equity Cash'!$G:$G,'Monthly BSE Equity Cash'!$A:$A,$A10)=0,"",SUMIFS('Monthly BSE Equity Cash'!$G:$G,'Monthly BSE Equity Cash'!$A:$A,$A10)) | F10: =IF(OR(D10="",E10=""),"",D10+E10) | G10: =IF(F10="","",D10/F10) | H10: =IF(F10="","",E10/F10) | L10: =IF(OR(D10="",D9=""),"",D10/D9-1) | M10: =IF(OR(E10="",E9=""),"",E10/E9-1) | N10: =IF(OR(F10="",F9=""),"",F10/F9-1)
A11: 36008 | B11: 1998-1999 | C11: Q2FY99 | D11: =IF(MAX(SUMIFS('Monthly NSE Equity Cash'!$K:$K,'Monthly NSE Equity Cash'!$A:$A,$A11),SUMIFS('Daily NSE Equity Cash'!$H:$H,'Daily NSE Equity Cash'!$C:$C,$A11))=0,"",MAX(SUMIFS('Monthly NSE Equity Cash'!$K:$K,'Monthly NSE Equity Cash'!$A:$A,$A11),SUMIFS('Daily NSE Equity Cash'!$H:$H,'Daily NSE Equity Cash'!$C:$C,$A11))) | E11: =IF(SUMIFS('Monthly BSE Equity Cash'!$G:$G,'Monthly BSE Equity Cash'!$A:$A,$A11)=0,"",SUMIFS('Monthly BSE Equity Cash'!$G:$G,'Monthly BSE Equity Cash'!$A:$A,$A11)) | F11: =IF(OR(D11="",E11=""),"",D11+E11) | G11: =IF(F11="","",D11/F11) | H11: =IF(F11="","",E11/F11) | L11: =IF(OR(D11="",D10=""),"",D11/D10-1) | M11: =IF(OR(E11="",E10=""),"",E11/E10-1) | N11: =IF(OR(F11="",F10=""),"",F11/F10-1)
A12: 36039 | B12: 1998-1999 | C12: Q2FY99 | D12: =IF(MAX(SUMIFS('Monthly NSE Equity Cash'!$K:$K,'Monthly NSE Equity Cash'!$A:$A,$A12),SUMIFS('Daily NSE Equity Cash'!$H:$H,'Daily NSE Equity Cash'!$C:$C,$A12))=0,"",MAX(SUMIFS('Monthly NSE Equity Cash'!$K:$K,'Monthly NSE Equity Cash'!$A:$A,$A12),SUMIFS('Daily NSE Equity Cash'!$H:$H,'Daily NSE Equity Cash'!$C:$C,$A12))) | E12: =IF(SUMIFS('Monthly BSE Equity Cash'!$G:$G,'Monthly BSE Equity Cash'!$A:$A,$A12)=0,"",SUMIFS('Monthly BSE Equity Cash'!$G:$G,'Monthly BSE Equity Cash'!$A:$A,$A12)) | F12: =IF(OR(D12="",E12=""),"",D12+E12) | G12: =IF(F12="","",D12/F12) | H12: =IF(F12="","",E12/F12) | L12: =IF(OR(D12="",D11=""),"",D12/D11-1) | M12: =IF(OR(E12="",E11=""),"",E12/E11-1) | N12: =IF(OR(F12="",F11=""),"",F12/F11-1)
A13: 36069 | B13: 1998-1999 | C13: Q3FY99 | D13: =IF(MAX(SUMIFS('Monthly NSE Equity Cash'!$K:$K,'Monthly NSE Equity Cash'!$A:$A,$A13),SUMIFS('Daily NSE Equity Cash'!$H:$H,'Daily NSE Equity Cash'!$C:$C,$A13))=0,"",MAX(SUMIFS('Monthly NSE Equity Cash'!$K:$K,'Monthly NSE Equity Cash'!$A:$A,$A13),SUMIFS('Daily NSE Equity Cash'!$H:$H,'Daily NSE Equity Cash'!$C:$C,$A13))) | E13: =IF(SUMIFS('Monthly BSE Equity Cash'!$G:$G,'Monthly BSE Equity Cash'!$A:$A,$A13)=0,"",SUMIFS('Monthly BSE Equity Cash'!$G:$G,'Monthly BSE Equity Cash'!$A:$A,$A13)) | F13: =IF(OR(D13="",E13=""),"",D13+E13) | G13: =IF(F13="","",D13/F13) | H13: =IF(F13="","",E13/F13) | L13: =IF(OR(D13="",D12=""),"",D13/D12-1) | M13: =IF(OR(E13="",E12=""),"",E13/E12-1) | N13: =IF(OR(F13="",F12=""),"",F13/F12-1)
A14: 36100 | B14: 1998-1999 | C14: Q3FY99 | D14: =IF(MAX(SUMIFS('Monthly NSE Equity Cash'!$K:$K,'Monthly NSE Equity Cash'!$A:$A,$A14),SUMIFS('Daily NSE Equity Cash'!$H:$H,'Daily NSE Equity Cash'!$C:$C,$A14))=0,"",MAX(SUMIFS('Monthly NSE Equity Cash'!$K:$K,'Monthly NSE Equity Cash'!$A:$A,$A14),SUMIFS('Daily NSE Equity Cash'!$H:$H,'Daily NSE Equity Cash'!$C:$C,$A14))) | E14: =IF(SUMIFS('Monthly BSE Equity Cash'!$G:$G,'Monthly BSE Equity Cash'!$A:$A,$A14)=0,"",SUMIFS('Monthly BSE Equity Cash'!$G:$G,'Monthly BSE Equity Cash'!$A:$A,$A14)) | F14: =IF(OR(D14="",E14=""),"",D14+E14) | G14: =IF(F14="","",D14/F14) | H14: =IF(F14="","",E14/F14) | I14: =IF(OR(D14="",D2=""),"",D14/D2-1) | J14: =IF(OR(E14="",E2=""),"",E14/E2-1) | K14: =IF(OR(F14="",F2=""),"",F14/F2-1) | L14: =IF(OR(D14="",D13=""),"",D14/D13-1) | M14: =IF(OR(E14="",E13=""),"",E14/E13-1) | N14: =IF(OR(F14="",F13=""),"",F14/F13-1)
A15: 36130 | B15: 1998-1999 | C15: Q3FY99 | D15: =IF(MAX(SUMIFS('Monthly NSE Equity Cash'!$K:$K,'Monthly NSE Equity Cash'!$A:$A,$A15),SUMIFS('Daily NSE Equity Cash'!$H:$H,'Daily NSE Equity Cash'!$C:$C,$A15))=0,"",MAX(SUMIFS('Monthly NSE Equity Cash'!$K:$K,'Monthly NSE Equity Cash'!$A:$A,$A15),SUMIFS('Daily NSE Equity Cash'!$H:$H,'Daily NSE Equity Cash'!$C:$C,$A15))) | E15: =IF(SUMIFS('Monthly BSE Equity Cash'!$G:$G,'Monthly BSE Equity Cash'!$A:$A,$A15)=0,"",SUMIFS('Monthly BSE Equity Cash'!$G:$G,'Monthly BSE Equity Cash'!$A:$A,$A15)) | F15: =IF(OR(D15="",E15=""),"",D15+E15) | G15: =IF(F15="","",D15/F15) | H15: =IF(F15="","",E15/F15) | I15: =IF(OR(D15="",D3=""),"",D15/D3-1) | J15: =IF(OR(E15="",E3=""),"",E15/E3-1) | K15: =IF(OR(F15="",F3=""),"",F15/F3-1) | L15: =IF(OR(D15="",D14=""),"",D15/D14-1) | M15: =IF(OR(E15="",E14=""),"",E15/E14-1) | N15: =IF(OR(F15="",F14=""),"",F15/F14-1)
A16: 36161 | B16: 1998-1999 | C16: Q4FY99 | D16: =IF(MAX(SUMIFS('Monthly NSE Equity Cash'!$K:$K,'Monthly NSE Equity Cash'!$A:$A,$A16),SUMIFS('Daily NSE Equity Cash'!$H:$H,'Daily NSE Equity Cash'!$C:$C,$A16))=0,"",MAX(SUMIFS('Monthly NSE Equity Cash'!$K:$K,'Monthly NSE Equity Cash'!$A:$A,$A16),SUMIFS('Daily NSE Equity Cash'!$H:$H,'Daily NSE Equity Cash'!$C:$C,$A16))) | E16: =IF(SUMIFS('Monthly BSE Equity Cash'!$G:$G,'Monthly BSE Equity Cash'!$A:$A,$A16)=0,"",SUMIFS('Monthly BSE Equity Cash'!$G:$G,'Monthly BSE Equity Cash'!$A:$A,$A16)) | F16: =IF(OR(D16="",E16=""),"",D16+E16) | G16: =IF(F16="","",D16/F16) | H16: =IF(F16="","",E16/F16) | I16: =IF(OR(D16="",D4=""),"",D16/D4-1) | J16: =IF(OR(E16="",E4=""),"",E16/E4-1) | K16: =IF(OR(F16="",F4=""),"",F16/F4-1) | L16: =IF(OR(D16="",D15=""),"",D16/D15-1) | M16: =IF(OR(E16="",E15=""),"",E16/E15-1) | N16: =IF(OR(F16="",F15=""),"",F16/F15-1)
A17: 36192 | B17: 1998-1999 | C17: Q4FY99 | D17: =IF(MAX(SUMIFS('Monthly NSE Equity Cash'!$K:$K,'Monthly NSE Equity Cash'!$A:$A,$A17),SUMIFS('Daily NSE Equity Cash'!$H:$H,'Daily NSE Equity Cash'!$C:$C,$A17))=0,"",MAX(SUMIFS('Monthly NSE Equity Cash'!$K:$K,'Monthly NSE Equity Cash'!$A:$A,$A17),SUMIFS('Daily NSE Equity Cash'!$H:$H,'Daily NSE Equity Cash'!$C:$C,$A17))) | E17: =IF(SUMIFS('Monthly BSE Equity Cash'!$G:$G,'Monthly BSE Equity Cash'!$A:$A,$A17)=0,"",SUMIFS('Monthly BSE Equity Cash'!$G:$G,'Monthly BSE Equity Cash'!$A:$A,$A17)) | F17: =IF(OR(D17="",E17=""),"",D17+E17) | G17: =IF(F17="","",D17/F17) | H17: =IF(F17="","",E17/F17) | I17: =IF(OR(D17="",D5=""),"",D17/D5-1) | J17: =IF(OR(E17="",E5=""),"",E17/E5-1) | K17: =IF(OR(F17="",F5=""),"",F17/F5-1) | L17: =IF(OR(D17="",D16=""),"",D17/D16-1) | M17: =IF(OR(E17="",E16=""),"",E17/E16-1) | N17: =IF(OR(F17="",F16=""),"",F17/F16-1)
A18: 36220 | B18: 1998-1999 | C18: Q4FY99 | D18: =IF(MAX(SUMIFS('Monthly NSE Equity Cash'!$K:$K,'Monthly NSE Equity Cash'!$A:$A,$A18),SUMIFS('Daily NSE Equity Cash'!$H:$H,'Daily NSE Equity Cash'!$C:$C,$A18))=0,"",MAX(SUMIFS('Monthly NSE Equity Cash'!$K:$K,'Monthly NSE Equity Cash'!$A:$A,$A18),SUMIFS('Daily NSE Equity Cash'!$H:$H,'Daily NSE Equity Cash'!$C:$C,$A18))) | E18: =IF(SUMIFS('Monthly BSE Equity Cash'!$G:$G,'Monthly BSE Equity Cash'!$A:$A,$A18)=0,"",SUMIFS('Monthly BSE Equity Cash'!$G:$G,'Monthly BSE Equity Cash'!$A:$A,$A18)) | F18: =IF(OR(D18="",E18=""),"",D18+E18) | G18: =IF(F18="","",D18/F18) | H18: =IF(F18="","",E18/F18) | I18: =IF(OR(D18="",D6=""),"",D18/D6-1) | J18: =IF(OR(E18="",E6=""),"",E18/E6-1) | K18: =IF(OR(F18="",F6=""),"",F18/F6-1) | L18: =IF(OR(D18="",D17=""),"",D18/D17-1) | M18: =IF(OR(E18="",E17=""),"",E18/E17-1) | N18: =IF(OR(F18="",F17=""),"",F18/F17-1)
A19: 36251 | B19: 1999-2000 | C19: Q1FY00 | D19: =IF(MAX(SUMIFS('Monthly NSE Equity Cash'!$K:$K,'Monthly NSE Equity Cash'!$A:$A,$A19),SUMIFS('Daily NSE Equity Cash'!$H:$H,'Daily NSE Equity Cash'!$C:$C,$A19))=0,"",MAX(SUMIFS('Monthly NSE Equity Cash'!$K:$K,'Monthly NSE Equity Cash'!$A:$A,$A19),SUMIFS('Daily NSE Equity Cash'!$H:$H,'Daily NSE Equity Cash'!$C:$C,$A19))) | E19: =IF(SUMIFS('Monthly BSE Equity Cash'!$G:$G,'Monthly BSE Equity Cash'!$A:$A,$A19)=0,"",SUMIFS('Monthly BSE Equity Cash'!$G:$G,'Monthly BSE Equity Cash'!$A:$A,$A19)) | F19: =IF(OR(D19="",E19=""),"",D19+E19) | G19: =IF(F19="","",D19/F19) | H19: =IF(F19="","",E19/F19) | I19: =IF(OR(D19="",D7=""),"",D19/D7-1) | J19: =IF(OR(E19="",E7=""),"",E19/E7-1) | K19: =IF(OR(F19="",F7=""),"",F19/F7-1) | L19: =IF(OR(D19="",D18=""),"",D19/D18-1) | M19: =IF(OR(E19="",E18=""),"",E19/E18-1) | N19: =IF(OR(F19="",F18=""),"",F19/F18-1)
A20: 36281 | B20: 1999-2000 | C20: Q1FY00 | D20: =IF(MAX(SUMIFS('Monthly NSE Equity Cash'!$K:$K,'Monthly NSE Equity Cash'!$A:$A,$A20),SUMIFS('Daily NSE Equity Cash'!$H:$H,'Daily NSE Equity Cash'!$C:$C,$A20))=0,"",MAX(SUMIFS('Monthly NSE Equity Cash'!$K:$K,'Monthly NSE Equity Cash'!$A:$A,$A20),SUMIFS('Daily NSE Equity Cash'!$H:$H,'Daily NSE Equity Cash'!$C:$C,$A20))) | E20: =IF(SUMIFS('Monthly BSE Equity Cash'!$G:$G,'Monthly BSE Equity Cash'!$A:$A,$A20)=0,"",SUMIFS('Monthly BSE Equity Cash'!$G:$G,'Monthly BSE Equity Cash'!$A:$A,$A20)) | F20: =IF(OR(D20="",E20=""),"",D20+E20) | G20: =IF(F20="","",D20/F20) | H20: =IF(F20="","",E20/F20) | I20: =IF(OR(D20="",D8=""),"",D20/D8-1) | J20: =IF(OR(E20="",E8=""),"",E20/E8-1) | K20: =IF(OR(F20="",F8=""),"",F20/F8-1) | L20: =IF(OR(D20="",D19=""),"",D20/D19-1) | M20: =IF(OR(E20="",E19=""),"",E20/E19-1) | N20: =IF(OR(F20="",F19=""),"",F20/F19-1)
A21: 36312 | B21: 1999-2000 | C21: Q1FY00 | D21: =IF(MAX(SUMIFS('Monthly NSE Equity Cash'!$K:$K,'Monthly NSE Equity Cash'!$A:$A,$A21),SUMIFS('Daily NSE Equity Cash'!$H:$H,'Daily NSE Equity Cash'!$C:$C,$A21))=0,"",MAX(SUMIFS('Monthly NSE Equity Cash'!$K:$K,'Monthly NSE Equity Cash'!$A:$A,$A21),SUMIFS('Daily NSE Equity Cash'!$H:$H,'Daily NSE Equity Cash'!$C:$C,$A21))) | E21: =IF(SUMIFS('Monthly BSE Equity Cash'!$G:$G,'Monthly BSE Equity Cash'!$A:$A,$A21)=0,"",SUMIFS('Monthly BSE Equity Cash'!$G:$G,'Monthly BSE Equity Cash'!$A:$A,$A21)) | F21: =IF(OR(D21="",E21=""),"",D21+E21) | G21: =IF(F21="","",D21/F21) | H21: =IF(F21="","",E21/F21) | I21: =IF(OR(D21="",D9=""),"",D21/D9-1) | J21: =IF(OR(E21="",E9=""),"",E21/E9-1) | K21: =IF(OR(F21="",F9=""),"",F21/F9-1) | L21: =IF(OR(D21="",D20=""),"",D21/D20-1) | M21: =IF(OR(E21="",E20=""),"",E21/E20-1) | N21: =IF(OR(F21="",F20=""),"",F21/F20-1)
A22: 36342 | B22: 1999-2000 | C22: Q2FY00 | D22: =IF(MAX(SUMIFS('Monthly NSE Equity Cash'!$K:$K,'Monthly NSE Equity Cash'!$A:$A,$A22),SUMIFS('Daily NSE Equity Cash'!$H:$H,'Daily NSE Equity Cash'!$C:$C,$A22))=0,"",MAX(SUMIFS('Monthly NSE Equity Cash'!$K:$K,'Monthly NSE Equity Cash'!$A:$A,$A22),SUMIFS('Daily NSE Equity Cash'!$H:$H,'Daily NSE Equity Cash'!$C:$C,$A22))) | E22: =IF(SUMIFS('Monthly BSE Equity Cash'!$G:$G,'Monthly BSE Equity Cash'!$A:$A,$A22)=0,"",SUMIFS('Monthly BSE Equity Cash'!$G:$G,'Monthly BSE Equity Cash'!$A:$A,$A22)) | F22: =IF(OR(D22="",E22=""),"",D22+E22) | G22: =IF(F22="","",D22/F22) | H22: =IF(F22="","",E22/F22) | I22: =IF(OR(D22="",D10=""),"",D22/D10-1) | J22: =IF(OR(E22="",E10=""),"",E22/E10-1) | K22: =IF(OR(F22="",F10=""),"",F22/F10-1) | L22: =IF(OR(D22="",D21=""),"",D22/D21-1) | M22: =IF(OR(E22="",E21=""),"",E22/E21-1) | N22: =IF(OR(F22="",F21=""),"",F22/F21-1)
A23: 36373 | B23: 1999-2000 | C23: Q2FY00 | D23: =IF(MAX(SUMIFS('Monthly NSE Equity Cash'!$K:$K,'Monthly NSE Equity Cash'!$A:$A,$A23),SUMIFS('Daily NSE Equity Cash'!$H:$H,'Daily NSE Equity Cash'!$C:$C,$A23))=0,"",MAX(SUMIFS('Monthly NSE Equity Cash'!$K:$K,'Monthly NSE Equity Cash'!$A:$A,$A23),SUMIFS('Daily NSE Equity Cash'!$H:$H,'Daily NSE Equity Cash'!$C:$C,$A23))) | E23: =IF(SUMIFS('Monthly BSE Equity Cash'!$G:$G,'Monthly BSE Equity Cash'!$A:$A,$A23)=0,"",SUMIFS('Monthly BSE Equity Cash'!$G:$G,'Monthly BSE Equity Cash'!$A:$A,$A23)) | F23: =IF(OR(D23="",E23=""),"",D23+E23) | G23: =IF(F23="","",D23/F23) | H23: =IF(F23="","",E23/F23) | I23: =IF(OR(D23="",D11=""),"",D23/D11-1) | J23: =IF(OR(E23="",E11=""),"",E23/E11-1) | K23: =IF(OR(F23="",F11=""),"",F23/F11-1) | L23: =IF(OR(D23="",D22=""),"",D23/D22-1) | M23: =IF(OR(E23="",E22=""),"",E23/E22-1) | N23: =IF(OR(F23="",F22=""),"",F23/F22-1)
A24: 36404 | B24: 1999-2000 | C24: Q2FY00 | D24: =IF(MAX(SUMIFS('Monthly NSE Equity Cash'!$K:$K,'Monthly NSE Equity Cash'!$A:$A,$A24),SUMIFS('Daily NSE Equity Cash'!$H:$H,'Daily NSE Equity Cash'!$C:$C,$A24))=0,"",MAX(SUMIFS('Monthly NSE Equity Cash'!$K:$K,'Monthly NSE Equity Cash'!$A:$A,$A24),SUMIFS('Daily NSE Equity Cash'!$H:$H,'Daily NSE Equity Cash'!$C:$C,$A24))) | E24: =IF(SUMIFS('Monthly BSE Equity Cash'!$G:$G,'Monthly BSE Equity Cash'!$A:$A,$A24)=0,"",SUMIFS('Monthly BSE Equity Cash'!$G:$G,'Monthly BSE Equity Cash'!$A:$A,$A24)) | F24: =IF(OR(D24="",E24=""),"",D24+E24) | G24: =IF(F24="","",D24/F24) | H24: =IF(F24="","",E24/F24) | I24: =IF(OR(D24="",D12=""),"",D24/D12-1) | J24: =IF(OR(E24="",E12=""),"",E24/E12-1) | K24: =IF(OR(F24="",F12=""),"",F24/F12-1) | L24: =IF(OR(D24="",D23=""),"",D24/D23-1) | M24: =IF(OR(E24="",E23=""),"",E24/E23-1) | N24: =IF(OR(F24="",F23=""),"",F24/F23-1)
A25: 36434 | B25: 1999-2000 | C25: Q3FY00 | D25: =IF(MAX(SUMIFS('Monthly NSE Equity Cash'!$K:$K,'Monthly NSE Equity Cash'!$A:$A,$A25),SUMIFS('Daily NSE Equity Cash'!$H:$H,'Daily NSE Equity Cash'!$C:$C,$A25))=0,"",MAX(SUMIFS('Monthly NSE Equity Cash'!$K:$K,'Monthly NSE Equity Cash'!$A:$A,$A25),SUMIFS('Daily NSE Equity Cash'!$H:$H,'Daily NSE Equity Cash'!$C:$C,$A25))) | E25: =IF(SUMIFS('Monthly BSE Equity Cash'!$G:$G,'Monthly BSE Equity Cash'!$A:$A,$A25)=0,"",SUMIFS('Monthly BSE Equity Cash'!$G:$G,'Monthly BSE Equity Cash'!$A:$A,$A25)) | F25: =IF(OR(D25="",E25=""),"",D25+E25) | G25: =IF(F25="","",D25/F25) | H25: =IF(F25="","",E25/F25) | I25: =IF(OR(D25="",D13=""),"",D25/D13-1) | J25: =IF(OR(E25="",E13=""),"",E25/E13-1) | K25: =IF(OR(F25="",F13=""),"",F25/F13-1) | L25: =IF(OR(D25="",D24=""),"",D25/D24-1) | M25: =IF(OR(E25="",E24=""),"",E25/E24-1) | N25: =IF(OR(F25="",F24=""),"",F25/F24-1)
... A347: 46235 | B347: 2026-2027 | C347: Q2FY27 | D347: =IF(MAX(SUMIFS('Monthly NSE Equity Cash'!$K:$K,'Monthly NSE Equity Cash'!$A:$A,$A347),SUMIFS('Daily NSE Equity Cash'!$H:$H,'Daily NSE Equity Cash'!$C:$C,$A347))=0,"",MAX(SUMIFS('Monthly NSE Equity Cash'!$K:$K,'Monthly NSE Equity Cash'!$A:$A,$A347),SUMIFS('Daily NSE Equity Cash'!$H:$H,'Daily NSE Equity Cash'!$C:$C,$A347))) | E347: =IF(SUMIFS('Monthly BSE Equity Cash'!$G:$G,'Monthly BSE Equity Cash'!$A:$A,$A347)=0,"",SUMIFS('Monthly BSE Equity Cash'!$G:$G,'Monthly BSE Equity Cash'!$A:$A,$A347)) | F347: =IF(OR(D347="",E347=""),"",D347+E347) | G347: =IF(F347="","",D347/F347) | H347: =IF(F347="","",E347/F347) | I347: =IF(OR(D347="",D335=""),"",D347/D335-1) | J347: =IF(OR(E347="",E335=""),"",E347/E335-1) | K347: =IF(OR(F347="",F335=""),"",F347/F335-1) | L347: =IF(OR(D347="",D346=""),"",D347/D346-1) | M347: =IF(OR(E347="",E346=""),"",E347/E346-1) | N347: =IF(OR(F347="",F346=""),"",F347/F346-1)
A349: MTD Comparison - Aug-2026 MTD vs Aug-2025 MTD (same number of trading days)
A350: Trading days elapsed in Aug-2026 (per NSE daily) | B350: =COUNTIF('Daily NSE Equity Cash'!$A:$A,">="&DATE(2026,8,1))
A351: Matched Aug-2025 window | B351: =DATE(2025,8,1) | C351: =INDEX('Daily NSE Equity Cash'!$A:$A,COUNTIF('Daily NSE Equity Cash'!$A:$A,"<"&DATE(2025,8,1))+1+$B350)
D352: NSE Turnover (INR Bn) | E352: BSE Turnover (INR Bn) | F352: Total Turnover (INR Bn) | G352: NSE Market Share | H352: BSE Market Share
A353: Aug-2025 MTD (first N trading days) | D353: =SUMIFS('Daily NSE Equity Cash'!$H:$H,'Daily NSE Equity Cash'!$A:$A,">="&$B$351,'Daily NSE Equity Cash'!$A:$A,"<="&$C$351) | E353: =SUMIFS('Daily BSE Equity Cash'!$H:$H,'Daily BSE Equity Cash'!$A:$A,">="&$B$351,'Daily BSE Equity Cash'!$A:$A,"<="&$C$351) | F353: =D353+E353 | G353: =IF(F353=0,"",D353/F353) | H353: =IF(F353=0,"",E353/F353)
A354: Aug-2026 MTD | D354: =SUMIFS('Daily NSE Equity Cash'!$H:$H,'Daily NSE Equity Cash'!$A:$A,">="&DATE(2026,8,1)) | E354: =SUMIFS('Daily BSE Equity Cash'!$H:$H,'Daily BSE Equity Cash'!$A:$A,">="&DATE(2026,8,1)) | F354: =D354+E354 | G354: =IF(F354=0,"",D354/F354) | H354: =IF(F354=0,"",E354/F354)
A355: MTD Growth (Aug-2026 vs Aug-2025) | D355: =IF(OR(D353=0,D353=""),"",D354/D353-1) | E355: =IF(OR(E353=0,E353=""),"",E354/E353-1) | F355: =IF(OR(F353=0,F353=""),"",F354/F353-1)

Sheet Day Eq Cash Turnover Mkt Share
A1: Trade Date | B1: Trade Day | C1: Trade Month - Year | D1: Qrtr - Year | E1: NSE Turnover (INR Bn) | F1: BSE Turnover (INR Bn) | G1: Total Turnover (INR Bn) | H1: NSE Market Share | I1: BSE Market Share | J1: NSE YoY Growth | K1: BSE YoY Growth | L1: Total Turnover YoY Growth | M1: NSE DoD Growth | N1: BSE DoD Growth | O1: Total Turnover DoD Growth
A2: 43922 | B2: Wednesday | C2: 43922 | D2: Q1FY21 | E2: =IF(SUMIFS('Daily NSE Equity Cash'!$H:$H,'Daily NSE Equity Cash'!$A:$A,$A2)=0,"",SUMIFS('Daily NSE Equity Cash'!$H:$H,'Daily NSE Equity Cash'!$A:$A,$A2)) | F2: =IF(SUMIFS('Daily BSE Equity Cash'!$H:$H,'Daily BSE Equity Cash'!$A:$A,$A2)=0,"",SUMIFS('Daily BSE Equity Cash'!$H:$H,'Daily BSE Equity Cash'!$A:$A,$A2)) | G2: =IF(OR(E2="",F2=""),"",E2+F2) | H2: =IF(G2="","",E2/G2) | I2: =IF(G2="","",F2/G2) | J2: =IFERROR(IF(OR(E2="",INDEX(E:E,MATCH(DATE(YEAR($A2)-1,MONTH($A2),DAY($A2)),$A:$A,0))=""),"",E2/INDEX(E:E,MATCH(DATE(YEAR($A2)-1,MONTH($A2),DAY($A2)),$A:$A,0))-1),"") | K2: =IFERROR(IF(OR(F2="",INDEX(F:F,MATCH(DATE(YEAR($A2)-1,MONTH($A2),DAY($A2)),$A:$A,0))=""),"",F2/INDEX(F:F,MATCH(DATE(YEAR($A2)-1,MONTH($A2),DAY($A2)),$A:$A,0))-1),"") | L2: =IFERROR(IF(OR(G2="",INDEX(G:G,MATCH(DATE(YEAR($A2)-1,MONTH($A2),DAY($A2)),$A:$A,0))=""),"",G2/INDEX(G:G,MATCH(DATE(YEAR($A2)-1,MONTH($A2),DAY($A2)),$A:$A,0))-1),"")
A3: 43924 | B3: Friday | C3: 43922 | D3: Q1FY21 | E3: =IF(SUMIFS('Daily NSE Equity Cash'!$H:$H,'Daily NSE Equity Cash'!$A:$A,$A3)=0,"",SUMIFS('Daily NSE Equity Cash'!$H:$H,'Daily NSE Equity Cash'!$A:$A,$A3)) | F3: =IF(SUMIFS('Daily BSE Equity Cash'!$H:$H,'Daily BSE Equity Cash'!$A:$A,$A3)=0,"",SUMIFS('Daily BSE Equity Cash'!$H:$H,'Daily BSE Equity Cash'!$A:$A,$A3)) | G3: =IF(OR(E3="",F3=""),"",E3+F3) | H3: =IF(G3="","",E3/G3) | I3: =IF(G3="","",F3/G3) | J3: =IFERROR(IF(OR(E3="",INDEX(E:E,MATCH(DATE(YEAR($A3)-1,MONTH($A3),DAY($A3)),$A:$A,0))=""),"",E3/INDEX(E:E,MATCH(DATE(YEAR($A3)-1,MONTH($A3),DAY($A3)),$A:$A,0))-1),"") | K3: =IFERROR(IF(OR(F3="",INDEX(F:F,MATCH(DATE(YEAR($A3)-1,MONTH($A3),DAY($A3)),$A:$A,0))=""),"",F3/INDEX(F:F,MATCH(DATE(YEAR($A3)-1,MONTH($A3),DAY($A3)),$A:$A,0))-1),"") | L3: =IFERROR(IF(OR(G3="",INDEX(G:G,MATCH(DATE(YEAR($A3)-1,MONTH($A3),DAY($A3)),$A:$A,0))=""),"",G3/INDEX(G:G,MATCH(DATE(YEAR($A3)-1,MONTH($A3),DAY($A3)),$A:$A,0))-1),"") | M3: =IF(OR(E3="",E2=""),"",E3/E2-1) | N3: =IF(OR(F3="",F2=""),"",F3/F2-1) | O3: =IF(OR(G3="",G2=""),"",G3/G2-1)
A4: 43928 | B4: Tuesday | C4: 43922 | D4: Q1FY21 | E4: =IF(SUMIFS('Daily NSE Equity Cash'!$H:$H,'Daily NSE Equity Cash'!$A:$A,$A4)=0,"",SUMIFS('Daily NSE Equity Cash'!$H:$H,'Daily NSE Equity Cash'!$A:$A,$A4)) | F4: =IF(SUMIFS('Daily BSE Equity Cash'!$H:$H,'Daily BSE Equity Cash'!$A:$A,$A4)=0,"",SUMIFS('Daily BSE Equity Cash'!$H:$H,'Daily BSE Equity Cash'!$A:$A,$A4)) | G4: =IF(OR(E4="",F4=""),"",E4+F4) | H4: =IF(G4="","",E4/G4) | I4: =IF(G4="","",F4/G4) | J4: =IFERROR(IF(OR(E4="",INDEX(E:E,MATCH(DATE(YEAR($A4)-1,MONTH($A4),DAY($A4)),$A:$A,0))=""),"",E4/INDEX(E:E,MATCH(DATE(YEAR($A4)-1,MONTH($A4),DAY($A4)),$A:$A,0))-1),"") | K4: =IFERROR(IF(OR(F4="",INDEX(F:F,MATCH(DATE(YEAR($A4)-1,MONTH($A4),DAY($A4)),$A:$A,0))=""),"",F4/INDEX(F:F,MATCH(DATE(YEAR($A4)-1,MONTH($A4),DAY($A4)),$A:$A,0))-1),"") | L4: =IFERROR(IF(OR(G4="",INDEX(G:G,MATCH(DATE(YEAR($A4)-1,MONTH($A4),DAY($A4)),$A:$A,0))=""),"",G4/INDEX(G:G,MATCH(DATE(YEAR($A4)-1,MONTH($A4),DAY($A4)),$A:$A,0))-1),"") | M4: =IF(OR(E4="",E3=""),"",E4/E3-1) | N4: =IF(OR(F4="",F3=""),"",F4/F3-1) | O4: =IF(OR(G4="",G3=""),"",G4/G3-1)
