Workbook

Sheet Quality Check
A1: Exchange | B1: Sheet | C1: Data From | D1: Data To | E1: Data Rows | F1: Total Options Premium Total (INR Bn) | G1: Total Options Notional Total (INR Bn) | H1: Total Options Contracts Total
A2: NSE | B2: Year NSE Equity Options | C2: ='Year NSE Equity Options'!A2 | D2: =LOOKUP(2,1/('Year NSE Equity Options'!$A$2:$A$100000<>""),'Year NSE Equity Options'!$A$2:$A$100000) | E2: =COUNTA('Year NSE Equity Options'!$A:$A)-1 | F2: =SUM('Year NSE Equity Options'!$H:$H) | G2: =SUM('Year NSE Equity Options'!$I:$I) | H2: =SUM('Year NSE Equity Options'!$J:$J)
A3: NSE | B3: Monthly NSE Equity Options | C3: ='Monthly NSE Equity Options'!A2 | D3: =LOOKUP(2,1/('Monthly NSE Equity Options'!$A$2:$A$100000<>""),'Monthly NSE Equity Options'!$A$2:$A$100000) | E3: =COUNTA('Monthly NSE Equity Options'!$A:$A)-1 | F3: =SUM('Monthly NSE Equity Options'!$J:$J) | G3: =SUM('Monthly NSE Equity Options'!$K:$K) | H3: =SUM('Monthly NSE Equity Options'!$L:$L)
A4: NSE | B4: Daily NSE Equity Options | C4: ='Daily NSE Equity Options'!A2 | D4: =LOOKUP(2,1/('Daily NSE Equity Options'!$A$2:$A$100000<>""),'Daily NSE Equity Options'!$A$2:$A$100000) | E4: =COUNTA('Daily NSE Equity Options'!$A:$A)-1 | F4: =SUM('Daily NSE Equity Options'!$K:$K) | G4: =SUM('Daily NSE Equity Options'!$L:$L) | H4: =SUM('Daily NSE Equity Options'!$M:$M)
A5: BSE | B5: Year BSE Equity Options | C5: ='Year BSE Equity Options'!A2 | D5: =LOOKUP(2,1/('Year BSE Equity Options'!$A$2:$A$100000<>""),'Year BSE Equity Options'!$A$2:$A$100000) | E5: =COUNTA('Year BSE Equity Options'!$A:$A)-1 | F5: =SUM('Year BSE Equity Options'!$H:$H) | G5: =SUM('Year BSE Equity Options'!$I:$I) | H5: =SUM('Year BSE Equity Options'!$J:$J)
A6: BSE | B6: Monthly BSE Equity Options | C6: ='Monthly BSE Equity Options'!A2 | D6: =LOOKUP(2,1/('Monthly BSE Equity Options'!$A$2:$A$100000<>""),'Monthly BSE Equity Options'!$A$2:$A$100000) | E6: =COUNTA('Monthly BSE Equity Options'!$A:$A)-1 | F6: =SUM('Monthly BSE Equity Options'!$J:$J) | G6: =SUM('Monthly BSE Equity Options'!$K:$K) | H6: =SUM('Monthly BSE Equity Options'!$L:$L)
A7: BSE | B7: Daily BSE Equity Options | C7: ='Daily BSE Equity Options'!A2 | D7: =LOOKUP(2,1/('Daily BSE Equity Options'!$A$2:$A$100000<>""),'Daily BSE Equity Options'!$A$2:$A$100000) | E7: =COUNTA('Daily BSE Equity Options'!$A:$A)-1 | F7: =SUM('Daily BSE Equity Options'!$K:$K) | G7: =SUM('Daily BSE Equity Options'!$L:$L) | H7: =SUM('Daily BSE Equity Options'!$M:$M)
A9: NSE & BSE daily end dates aligned? | C9: =IF($D$4=$D$7,"YES","NO")
A11: Reconciliation | B11: Aggregate | C11: Component Sum | D11: Difference | E11: Status | F11: Remarks
A12: NSE: Yearly vs Monthly (from first yearly FY) - Premium | B12: =SUM('Year NSE Equity Options'!$H:$H) | C12: =SUMIFS('Monthly NSE Equity Options'!$J:$J,'Monthly NSE Equity Options'!$A:$A,">="&DATE(LEFT('Year NSE Equity Options'!$A$2,4)+0,4,1)) | D12: =B12-C12 | E12: =IF(ABS(D12)<=0.04,"OK","CHECK") | F12: tolerance 0.04 INR Bn (source rounding)
A13: NSE: Monthly vs Daily (from daily start) - Premium | B13: =SUMIFS('Monthly NSE Equity Options'!$J:$J,'Monthly NSE Equity Options'!$A:$A,">="&DATE(YEAR($C$4),MONTH($C$4),1)) | C13: =SUM('Daily NSE Equity Options'!$K:$K) | D13: =B13-C13 | E13: =IF(ABS(D13)<=0.04,"OK","CHECK") | F13: tolerance 0.04 INR Bn (source rounding)
A14: BSE: Yearly vs Monthly (full history) - Premium | B14: =SUM('Year BSE Equity Options'!$H:$H) | C14: =SUM('Monthly BSE Equity Options'!$J:$J) | D14: =B14-C14 | E14: =IF(ABS(D14)<=0.04,"OK","CHECK") | F14: tolerance 0.04 INR Bn (source rounding)
A15: BSE: Monthly vs Daily (from daily start) - Premium | B15: =SUMIFS('Monthly BSE Equity Options'!$J:$J,'Monthly BSE Equity Options'!$A:$A,">="&DATE(YEAR($C$7),MONTH($C$7),1)) | C15: =SUM('Daily BSE Equity Options'!$K:$K) | D15: =B15-C15 | E15: =IF(ABS(D15)<=0.04,"OK","CHECK") | F15: tolerance 0.04 INR Bn (source rounding)
A16: NSE: Yearly vs Monthly (from first yearly FY) - Notional | B16: =SUM('Year NSE Equity Options'!$I:$I) | C16: =SUMIFS('Monthly NSE Equity Options'!$K:$K,'Monthly NSE Equity Options'!$A:$A,">="&DATE(LEFT('Year NSE Equity Options'!$A$2,4)+0,4,1)) | D16: =B16-C16 | E16: =IF(ABS(D16)<=0.04,"OK","CHECK") | F16: tolerance 0.04 INR Bn (source rounding)
A17: NSE: Monthly vs Daily (from daily start) - Notional | B17: =SUMIFS('Monthly NSE Equity Options'!$K:$K,'Monthly NSE Equity Options'!$A:$A,">="&DATE(YEAR($C$4),MONTH($C$4),1)) | C17: =SUM('Daily NSE Equity Options'!$L:$L) | D17: =B17-C17 | E17: =IF(ABS(D17)<=0.04,"OK","CHECK") | F17: tolerance 0.04 INR Bn (source rounding)
A18: BSE: Yearly vs Monthly (full history) - Notional | B18: =SUM('Year BSE Equity Options'!$I:$I) | C18: =SUM('Monthly BSE Equity Options'!$K:$K) | D18: =B18-C18 | E18: =IF(ABS(D18)<=0.04,"OK","CHECK") | F18: tolerance 0.04 INR Bn (source rounding)
A19: BSE: Monthly vs Daily (from daily start) - Notional | B19: =SUMIFS('Monthly BSE Equity Options'!$K:$K,'Monthly BSE Equity Options'!$A:$A,">="&DATE(YEAR($C$7),MONTH($C$7),1)) | C19: =SUM('Daily BSE Equity Options'!$L:$L) | D19: =B19-C19 | E19: =IF(ABS(D19)<=0.04,"OK","CHECK") | F19: tolerance 0.04 INR Bn (source rounding)
A20: NSE: Yearly vs Monthly (from first yearly FY) - Contracts | B20: =SUM('Year NSE Equity Options'!$J:$J) | C20: =SUMIFS('Monthly NSE Equity Options'!$L:$L,'Monthly NSE Equity Options'!$A:$A,">="&DATE(LEFT('Year NSE Equity Options'!$A$2,4)+0,4,1)) | D20: =B20-C20 | E20: =IF(ABS(D20)<=0,"OK","CHECK") | F20: counts must match exactly
A21: NSE: Monthly vs Daily (from daily start) - Contracts | B21: =SUMIFS('Monthly NSE Equity Options'!$L:$L,'Monthly NSE Equity Options'!$A:$A,">="&DATE(YEAR($C$4),MONTH($C$4),1)) | C21: =SUM('Daily NSE Equity Options'!$M:$M) | D21: =B21-C21 | E21: =IF(ABS(D21)<=0,"OK","CHECK") | F21: counts must match exactly
A22: BSE: Yearly vs Monthly (full history) - Contracts | B22: =SUM('Year BSE Equity Options'!$J:$J) | C22: =SUM('Monthly BSE Equity Options'!$L:$L) | D22: =B22-C22 | E22: =IF(ABS(D22)<=0,"OK","CHECK") | F22: counts must match exactly
A23: BSE: Monthly vs Daily (from daily start) - Contracts | B23: =SUMIFS('Monthly BSE Equity Options'!$L:$L,'Monthly BSE Equity Options'!$A:$A,">="&DATE(YEAR($C$7),MONTH($C$7),1)) | C23: =SUM('Daily BSE Equity Options'!$M:$M) | D23: =B23-C23 | E23: =IF(ABS(D23)<=0,"OK","CHECK") | F23: counts must match exactly
A25: Notes
A26: Data sheets carry Index Options, Stock/Equity Options and Total Options (= Index + Stock/Equity) groups, each ordered Premium | Notional | Contracts; turnover in INR Bn (= the exchanges' published INR Crores / 100), contracts raw counts. Market Share sheets and the reconciliation above are at the Total Options level only (the standalone NSE/BSE workbooks reconcile the Index/Stock split).
A27: Market Share sheets: values are live SUMIFS on the data sheets; one-sided periods (e.g. BSE-only history before Apr-2009, zero-activity BSE months) show the available exchange but a BLANK total/share - never a fake 100%.
A28: NSE yearly figures start only FY2015-16, so the Year Mkt Share sheet fills NSE from the Monthly NSE sheet (MAX of the two) for FY2009-10 onward; NSE monthly starts Apr-2009, BSE history starts FY2003-04; daily sheets per chosen range.
A29: Growth columns are on Premium Turnover (the standard options turnover measure); YoY on in-progress periods compares partial vs full prior period.
A30: Both exchanges publish in-progress month and fiscal-year figures for options, so no daily fallback is needed at monthly/quarterly level (unlike the Equity Cash workbook).
A31: Each Mkt Share sheet also carries a period-to-date Comparison block below the data - Year & Day sheets: current-FY YTD vs the prior FY; Qrtr sheet: running quarter QTD vs the same quarter a year earlier; Mth sheet: running month MTD vs the same month a year earlier - always over the FIRST EQUAL NUMBER of NSE trading days of the prior period (matched window shown in the block, sliding forward with each refresh); live formulas on the daily data sheets, growth on NSE/BSE/Total for all three metrics.
A32: Colour code across all sheets: GOLD = Premium Turnover, BLUE = Notional Turnover, GREEN = No. of Contracts; grey left borders mark group boundaries. On Market Share sheets the share columns show the red-to-green scale instead, and the growth block is gold (premium-based).

Sheet Year Equity Options Mkt Share
A1: Fiscal Year | B1: NSE Premium Turnover (INR Bn) | C1: BSE Premium Turnover (INR Bn) | D1: Total Premium Turnover (INR Bn) | E1: NSE Premium Market Share | F1: BSE Premium Market Share | G1: NSE Premium YoY Growth | H1: BSE Premium YoY Growth | I1: Total Premium YoY Growth | J1: NSE Notional Turnover (INR Bn) | K1: BSE Notional Turnover (INR Bn) | L1: Total Notional Turnover (INR Bn) | M1: NSE Notional Market Share | N1: BSE Notional Market Share | O1: NSE No. of Contracts | P1: BSE No. of Contracts | Q1: Total No. of Contracts | R1: NSE Contracts Market Share | S1: BSE Contracts Market Share
A2: 2003-2004 | B2: =IF(MAX(SUMIFS('Year NSE Equity Options'!$H:$H,'Year NSE Equity Options'!$A:$A,$A2),SUMIFS('Monthly NSE Equity Options'!$J:$J,'Monthly NSE Equity Options'!$B:$B,$A2))=0,"",MAX(SUMIFS('Year NSE Equity Options'!$H:$H,'Year NSE Equity Options'!$A:$A,$A2),SUMIFS('Monthly NSE Equity Options'!$J:$J,'Monthly NSE Equity Options'!$B:$B,$A2))) | C2: =IF(SUMIFS('Year BSE Equity Options'!$H:$H,'Year BSE Equity Options'!$A:$A,$A2)=0,"",SUMIFS('Year BSE Equity Options'!$H:$H,'Year BSE Equity Options'!$A:$A,$A2)) | D2: =IF(OR(B2="",C2=""),"",B2+C2) | E2: =IF(D2="","",B2/D2) | F2: =IF(D2="","",C2/D2) | J2: =IF(MAX(SUMIFS('Year NSE Equity Options'!$I:$I,'Year NSE Equity Options'!$A:$A,$A2),SUMIFS('Monthly NSE Equity Options'!$K:$K,'Monthly NSE Equity Options'!$B:$B,$A2))=0,"",MAX(SUMIFS('Year NSE Equity Options'!$I:$I,'Year NSE Equity Options'!$A:$A,$A2),SUMIFS('Monthly NSE Equity Options'!$K:$K,'Monthly NSE Equity Options'!$B:$B,$A2))) | K2: =IF(SUMIFS('Year BSE Equity Options'!$I:$I,'Year BSE Equity Options'!$A:$A,$A2)=0,"",SUMIFS('Year BSE Equity Options'!$I:$I,'Year BSE Equity Options'!$A:$A,$A2)) | L2: =IF(OR(J2="",K2=""),"",J2+K2) | M2: =IF(L2="","",J2/L2) | N2: =IF(L2="","",K2/L2) | O2: =IF(MAX(SUMIFS('Year NSE Equity Options'!$J:$J,'Year NSE Equity Options'!$A:$A,$A2),SUMIFS('Monthly NSE Equity Options'!$L:$L,'Monthly NSE Equity Options'!$B:$B,$A2))=0,"",MAX(SUMIFS('Year NSE Equity Options'!$J:$J,'Year NSE Equity Options'!$A:$A,$A2),SUMIFS('Monthly NSE Equity Options'!$L:$L,'Monthly NSE Equity Options'!$B:$B,$A2))) | P2: =IF(SUMIFS('Year BSE Equity Options'!$J:$J,'Year BSE Equity Options'!$A:$A,$A2)=0,"",SUMIFS('Year BSE Equity Options'!$J:$J,'Year BSE Equity Options'!$A:$A,$A2)) | Q2: =IF(OR(O2="",P2=""),"",O2+P2) | R2: =IF(Q2="","",O2/Q2) | S2: =IF(Q2="","",P2/Q2)
A3: 2004-2005 | B3: =IF(MAX(SUMIFS('Year NSE Equity Options'!$H:$H,'Year NSE Equity Options'!$A:$A,$A3),SUMIFS('Monthly NSE Equity Options'!$J:$J,'Monthly NSE Equity Options'!$B:$B,$A3))=0,"",MAX(SUMIFS('Year NSE Equity Options'!$H:$H,'Year NSE Equity Options'!$A:$A,$A3),SUMIFS('Monthly NSE Equity Options'!$J:$J,'Monthly NSE Equity Options'!$B:$B,$A3))) | C3: =IF(SUMIFS('Year BSE Equity Options'!$H:$H,'Year BSE Equity Options'!$A:$A,$A3)=0,"",SUMIFS('Year BSE Equity Options'!$H:$H,'Year BSE Equity Options'!$A:$A,$A3)) | D3: =IF(OR(B3="",C3=""),"",B3+C3) | E3: =IF(D3="","",B3/D3) | F3: =IF(D3="","",C3/D3) | G3: =IF(OR(B3="",B2=""),"",B3/B2-1) | H3: =IF(OR(C3="",C2=""),"",C3/C2-1) | I3: =IF(OR(D3="",D2=""),"",D3/D2-1) | J3: =IF(MAX(SUMIFS('Year NSE Equity Options'!$I:$I,'Year NSE Equity Options'!$A:$A,$A3),SUMIFS('Monthly NSE Equity Options'!$K:$K,'Monthly NSE Equity Options'!$B:$B,$A3))=0,"",MAX(SUMIFS('Year NSE Equity Options'!$I:$I,'Year NSE Equity Options'!$A:$A,$A3),SUMIFS('Monthly NSE Equity Options'!$K:$K,'Monthly NSE Equity Options'!$B:$B,$A3))) | K3: =IF(SUMIFS('Year BSE Equity Options'!$I:$I,'Year BSE Equity Options'!$A:$A,$A3)=0,"",SUMIFS('Year BSE Equity Options'!$I:$I,'Year BSE Equity Options'!$A:$A,$A3)) | L3: =IF(OR(J3="",K3=""),"",J3+K3) | M3: =IF(L3="","",J3/L3) | N3: =IF(L3="","",K3/L3) | O3: =IF(MAX(SUMIFS('Year NSE Equity Options'!$J:$J,'Year NSE Equity Options'!$A:$A,$A3),SUMIFS('Monthly NSE Equity Options'!$L:$L,'Monthly NSE Equity Options'!$B:$B,$A3))=0,"",MAX(SUMIFS('Year NSE Equity Options'!$J:$J,'Year NSE Equity Options'!$A:$A,$A3),SUMIFS('Monthly NSE Equity Options'!$L:$L,'Monthly NSE Equity Options'!$B:$B,$A3))) | P3: =IF(SUMIFS('Year BSE Equity Options'!$J:$J,'Year BSE Equity Options'!$A:$A,$A3)=0,"",SUMIFS('Year BSE Equity Options'!$J:$J,'Year BSE Equity Options'!$A:$A,$A3)) | Q3: =IF(OR(O3="",P3=""),"",O3+P3) | R3: =IF(Q3="","",O3/Q3) | S3: =IF(Q3="","",P3/Q3)
A4: 2005-2006 | B4: =IF(MAX(SUMIFS('Year NSE Equity Options'!$H:$H,'Year NSE Equity Options'!$A:$A,$A4),SUMIFS('Monthly NSE Equity Options'!$J:$J,'Monthly NSE Equity Options'!$B:$B,$A4))=0,"",MAX(SUMIFS('Year NSE Equity Options'!$H:$H,'Year NSE Equity Options'!$A:$A,$A4),SUMIFS('Monthly NSE Equity Options'!$J:$J,'Monthly NSE Equity Options'!$B:$B,$A4))) | C4: =IF(SUMIFS('Year BSE Equity Options'!$H:$H,'Year BSE Equity Options'!$A:$A,$A4)=0,"",SUMIFS('Year BSE Equity Options'!$H:$H,'Year BSE Equity Options'!$A:$A,$A4)) | D4: =IF(OR(B4="",C4=""),"",B4+C4) | E4: =IF(D4="","",B4/D4) | F4: =IF(D4="","",C4/D4) | G4: =IF(OR(B4="",B3=""),"",B4/B3-1) | H4: =IF(OR(C4="",C3=""),"",C4/C3-1) | I4: =IF(OR(D4="",D3=""),"",D4/D3-1) | J4: =IF(MAX(SUMIFS('Year NSE Equity Options'!$I:$I,'Year NSE Equity Options'!$A:$A,$A4),SUMIFS('Monthly NSE Equity Options'!$K:$K,'Monthly NSE Equity Options'!$B:$B,$A4))=0,"",MAX(SUMIFS('Year NSE Equity Options'!$I:$I,'Year NSE Equity Options'!$A:$A,$A4),SUMIFS('Monthly NSE Equity Options'!$K:$K,'Monthly NSE Equity Options'!$B:$B,$A4))) | K4: =IF(SUMIFS('Year BSE Equity Options'!$I:$I,'Year BSE Equity Options'!$A:$A,$A4)=0,"",SUMIFS('Year BSE Equity Options'!$I:$I,'Year BSE Equity Options'!$A:$A,$A4)) | L4: =IF(OR(J4="",K4=""),"",J4+K4) | M4: =IF(L4="","",J4/L4) | N4: =IF(L4="","",K4/L4) | O4: =IF(MAX(SUMIFS('Year NSE Equity Options'!$J:$J,'Year NSE Equity Options'!$A:$A,$A4),SUMIFS('Monthly NSE Equity Options'!$L:$L,'Monthly NSE Equity Options'!$B:$B,$A4))=0,"",MAX(SUMIFS('Year NSE Equity Options'!$J:$J,'Year NSE Equity Options'!$A:$A,$A4),SUMIFS('Monthly NSE Equity Options'!$L:$L,'Monthly NSE Equity Options'!$B:$B,$A4))) | P4: =IF(SUMIFS('Year BSE Equity Options'!$J:$J,'Year BSE Equity Options'!$A:$A,$A4)=0,"",SUMIFS('Year BSE Equity Options'!$J:$J,'Year BSE Equity Options'!$A:$A,$A4)) | Q4: =IF(OR(O4="",P4=""),"",O4+P4) | R4: =IF(Q4="","",O4/Q4) | S4: =IF(Q4="","",P4/Q4)
A5: 2006-2007 | B5: =IF(MAX(SUMIFS('Year NSE Equity Options'!$H:$H,'Year NSE Equity Options'!$A:$A,$A5),SUMIFS('Monthly NSE Equity Options'!$J:$J,'Monthly NSE Equity Options'!$B:$B,$A5))=0,"",MAX(SUMIFS('Year NSE Equity Options'!$H:$H,'Year NSE Equity Options'!$A:$A,$A5),SUMIFS('Monthly NSE Equity Options'!$J:$J,'Monthly NSE Equity Options'!$B:$B,$A5))) | C5: =IF(SUMIFS('Year BSE Equity Options'!$H:$H,'Year BSE Equity Options'!$A:$A,$A5)=0,"",SUMIFS('Year BSE Equity Options'!$H:$H,'Year BSE Equity Options'!$A:$A,$A5)) | D5: =IF(OR(B5="",C5=""),"",B5+C5) | E5: =IF(D5="","",B5/D5) | F5: =IF(D5="","",C5/D5) | G5: =IF(OR(B5="",B4=""),"",B5/B4-1) | H5: =IF(OR(C5="",C4=""),"",C5/C4-1) | I5: =IF(OR(D5="",D4=""),"",D5/D4-1) | J5: =IF(MAX(SUMIFS('Year NSE Equity Options'!$I:$I,'Year NSE Equity Options'!$A:$A,$A5),SUMIFS('Monthly NSE Equity Options'!$K:$K,'Monthly NSE Equity Options'!$B:$B,$A5))=0,"",MAX(SUMIFS('Year NSE Equity Options'!$I:$I,'Year NSE Equity Options'!$A:$A,$A5),SUMIFS('Monthly NSE Equity Options'!$K:$K,'Monthly NSE Equity Options'!$B:$B,$A5))) | K5: =IF(SUMIFS('Year BSE Equity Options'!$I:$I,'Year BSE Equity Options'!$A:$A,$A5)=0,"",SUMIFS('Year BSE Equity Options'!$I:$I,'Year BSE Equity Options'!$A:$A,$A5)) | L5: =IF(OR(J5="",K5=""),"",J5+K5) | M5: =IF(L5="","",J5/L5) | N5: =IF(L5="","",K5/L5) | O5: =IF(MAX(SUMIFS('Year NSE Equity Options'!$J:$J,'Year NSE Equity Options'!$A:$A,$A5),SUMIFS('Monthly NSE Equity Options'!$L:$L,'Monthly NSE Equity Options'!$B:$B,$A5))=0,"",MAX(SUMIFS('Year NSE Equity Options'!$J:$J,'Year NSE Equity Options'!$A:$A,$A5),SUMIFS('Monthly NSE Equity Options'!$L:$L,'Monthly NSE Equity Options'!$B:$B,$A5))) | P5: =IF(SUMIFS('Year BSE Equity Options'!$J:$J,'Year BSE Equity Options'!$A:$A,$A5)=0,"",SUMIFS('Year BSE Equity Options'!$J:$J,'Year BSE Equity Options'!$A:$A,$A5)) | Q5: =IF(OR(O5="",P5=""),"",O5+P5) | R5: =IF(Q5="","",O5/Q5) | S5: =IF(Q5="","",P5/Q5)
A6: 2007-2008 | B6: =IF(MAX(SUMIFS('Year NSE Equity Options'!$H:$H,'Year NSE Equity Options'!$A:$A,$A6),SUMIFS('Monthly NSE Equity Options'!$J:$J,'Monthly NSE Equity Options'!$B:$B,$A6))=0,"",MAX(SUMIFS('Year NSE Equity Options'!$H:$H,'Year NSE Equity Options'!$A:$A,$A6),SUMIFS('Monthly NSE Equity Options'!$J:$J,'Monthly NSE Equity Options'!$B:$B,$A6))) | C6: =IF(SUMIFS('Year BSE Equity Options'!$H:$H,'Year BSE Equity Options'!$A:$A,$A6)=0,"",SUMIFS('Year BSE Equity Options'!$H:$H,'Year BSE Equity Options'!$A:$A,$A6)) | D6: =IF(OR(B6="",C6=""),"",B6+C6) | E6: =IF(D6="","",B6/D6) | F6: =IF(D6="","",C6/D6) | G6: =IF(OR(B6="",B5=""),"",B6/B5-1) | H6: =IF(OR(C6="",C5=""),"",C6/C5-1) | I6: =IF(OR(D6="",D5=""),"",D6/D5-1) | J6: =IF(MAX(SUMIFS('Year NSE Equity Options'!$I:$I,'Year NSE Equity Options'!$A:$A,$A6),SUMIFS('Monthly NSE Equity Options'!$K:$K,'Monthly NSE Equity Options'!$B:$B,$A6))=0,"",MAX(SUMIFS('Year NSE Equity Options'!$I:$I,'Year NSE Equity Options'!$A:$A,$A6),SUMIFS('Monthly NSE Equity Options'!$K:$K,'Monthly NSE Equity Options'!$B:$B,$A6))) | K6: =IF(SUMIFS('Year BSE Equity Options'!$I:$I,'Year BSE Equity Options'!$A:$A,$A6)=0,"",SUMIFS('Year BSE Equity Options'!$I:$I,'Year BSE Equity Options'!$A:$A,$A6)) | L6: =IF(OR(J6="",K6=""),"",J6+K6) | M6: =IF(L6="","",J6/L6) | N6: =IF(L6="","",K6/L6) | O6: =IF(MAX(SUMIFS('Year NSE Equity Options'!$J:$J,'Year NSE Equity Options'!$A:$A,$A6),SUMIFS('Monthly NSE Equity Options'!$L:$L,'Monthly NSE Equity Options'!$B:$B,$A6))=0,"",MAX(SUMIFS('Year NSE Equity Options'!$J:$J,'Year NSE Equity Options'!$A:$A,$A6),SUMIFS('Monthly NSE Equity Options'!$L:$L,'Monthly NSE Equity Options'!$B:$B,$A6))) | P6: =IF(SUMIFS('Year BSE Equity Options'!$J:$J,'Year BSE Equity Options'!$A:$A,$A6)=0,"",SUMIFS('Year BSE Equity Options'!$J:$J,'Year BSE Equity Options'!$A:$A,$A6)) | Q6: =IF(OR(O6="",P6=""),"",O6+P6) | R6: =IF(Q6="","",O6/Q6) | S6: =IF(Q6="","",P6/Q6)
A7: 2008-2009 | B7: =IF(MAX(SUMIFS('Year NSE Equity Options'!$H:$H,'Year NSE Equity Options'!$A:$A,$A7),SUMIFS('Monthly NSE Equity Options'!$J:$J,'Monthly NSE Equity Options'!$B:$B,$A7))=0,"",MAX(SUMIFS('Year NSE Equity Options'!$H:$H,'Year NSE Equity Options'!$A:$A,$A7),SUMIFS('Monthly NSE Equity Options'!$J:$J,'Monthly NSE Equity Options'!$B:$B,$A7))) | C7: =IF(SUMIFS('Year BSE Equity Options'!$H:$H,'Year BSE Equity Options'!$A:$A,$A7)=0,"",SUMIFS('Year BSE Equity Options'!$H:$H,'Year BSE Equity Options'!$A:$A,$A7)) | D7: =IF(OR(B7="",C7=""),"",B7+C7) | E7: =IF(D7="","",B7/D7) | F7: =IF(D7="","",C7/D7) | G7: =IF(OR(B7="",B6=""),"",B7/B6-1) | H7: =IF(OR(C7="",C6=""),"",C7/C6-1) | I7: =IF(OR(D7="",D6=""),"",D7/D6-1) | J7: =IF(MAX(SUMIFS('Year NSE Equity Options'!$I:$I,'Year NSE Equity Options'!$A:$A,$A7),SUMIFS('Monthly NSE Equity Options'!$K:$K,'Monthly NSE Equity Options'!$B:$B,$A7))=0,"",MAX(SUMIFS('Year NSE Equity Options'!$I:$I,'Year NSE Equity Options'!$A:$A,$A7),SUMIFS('Monthly NSE Equity Options'!$K:$K,'Monthly NSE Equity Options'!$B:$B,$A7))) | K7: =IF(SUMIFS('Year BSE Equity Options'!$I:$I,'Year BSE Equity Options'!$A:$A,$A7)=0,"",SUMIFS('Year BSE Equity Options'!$I:$I,'Year BSE Equity Options'!$A:$A,$A7)) | L7: =IF(OR(J7="",K7=""),"",J7+K7) | M7: =IF(L7="","",J7/L7) | N7: =IF(L7="","",K7/L7) | O7: =IF(MAX(SUMIFS('Year NSE Equity Options'!$J:$J,'Year NSE Equity Options'!$A:$A,$A7),SUMIFS('Monthly NSE Equity Options'!$L:$L,'Monthly NSE Equity Options'!$B:$B,$A7))=0,"",MAX(SUMIFS('Year NSE Equity Options'!$J:$J,'Year NSE Equity Options'!$A:$A,$A7),SUMIFS('Monthly NSE Equity Options'!$L:$L,'Monthly NSE Equity Options'!$B:$B,$A7))) | P7: =IF(SUMIFS('Year BSE Equity Options'!$J:$J,'Year BSE Equity Options'!$A:$A,$A7)=0,"",SUMIFS('Year BSE Equity Options'!$J:$J,'Year BSE Equity Options'!$A:$A,$A7)) | Q7: =IF(OR(O7="",P7=""),"",O7+P7) | R7: =IF(Q7="","",O7/Q7) | S7: =IF(Q7="","",P7/Q7)
A8: 2009-2010 | B8: =IF(MAX(SUMIFS('Year NSE Equity Options'!$H:$H,'Year NSE Equity Options'!$A:$A,$A8),SUMIFS('Monthly NSE Equity Options'!$J:$J,'Monthly NSE Equity Options'!$B:$B,$A8))=0,"",MAX(SUMIFS('Year NSE Equity Options'!$H:$H,'Year NSE Equity Options'!$A:$A,$A8),SUMIFS('Monthly NSE Equity Options'!$J:$J,'Monthly NSE Equity Options'!$B:$B,$A8))) | C8: =IF(SUMIFS('Year BSE Equity Options'!$H:$H,'Year BSE Equity Options'!$A:$A,$A8)=0,"",SUMIFS('Year BSE Equity Options'!$H:$H,'Year BSE Equity Options'!$A:$A,$A8)) | D8: =IF(OR(B8="",C8=""),"",B8+C8) | E8: =IF(D8="","",B8/D8) | F8: =IF(D8="","",C8/D8) | G8: =IF(OR(B8="",B7=""),"",B8/B7-1) | H8: =IF(OR(C8="",C7=""),"",C8/C7-1) | I8: =IF(OR(D8="",D7=""),"",D8/D7-1) | J8: =IF(MAX(SUMIFS('Year NSE Equity Options'!$I:$I,'Year NSE Equity Options'!$A:$A,$A8),SUMIFS('Monthly NSE Equity Options'!$K:$K,'Monthly NSE Equity Options'!$B:$B,$A8))=0,"",MAX(SUMIFS('Year NSE Equity Options'!$I:$I,'Year NSE Equity Options'!$A:$A,$A8),SUMIFS('Monthly NSE Equity Options'!$K:$K,'Monthly NSE Equity Options'!$B:$B,$A8))) | K8: =IF(SUMIFS('Year BSE Equity Options'!$I:$I,'Year BSE Equity Options'!$A:$A,$A8)=0,"",SUMIFS('Year BSE Equity Options'!$I:$I,'Year BSE Equity Options'!$A:$A,$A8)) | L8: =IF(OR(J8="",K8=""),"",J8+K8) | M8: =IF(L8="","",J8/L8) | N8: =IF(L8="","",K8/L8) | O8: =IF(MAX(SUMIFS('Year NSE Equity Options'!$J:$J,'Year NSE Equity Options'!$A:$A,$A8),SUMIFS('Monthly NSE Equity Options'!$L:$L,'Monthly NSE Equity Options'!$B:$B,$A8))=0,"",MAX(SUMIFS('Year NSE Equity Options'!$J:$J,'Year NSE Equity Options'!$A:$A,$A8),SUMIFS('Monthly NSE Equity Options'!$L:$L,'Monthly NSE Equity Options'!$B:$B,$A8))) | P8: =IF(SUMIFS('Year BSE Equity Options'!$J:$J,'Year BSE Equity Options'!$A:$A,$A8)=0,"",SUMIFS('Year BSE Equity Options'!$J:$J,'Year BSE Equity Options'!$A:$A,$A8)) | Q8: =IF(OR(O8="",P8=""),"",O8+P8) | R8: =IF(Q8="","",O8/Q8) | S8: =IF(Q8="","",P8/Q8)
A9: 2010-2011 | B9: =IF(MAX(SUMIFS('Year NSE Equity Options'!$H:$H,'Year NSE Equity Options'!$A:$A,$A9),SUMIFS('Monthly NSE Equity Options'!$J:$J,'Monthly NSE Equity Options'!$B:$B,$A9))=0,"",MAX(SUMIFS('Year NSE Equity Options'!$H:$H,'Year NSE Equity Options'!$A:$A,$A9),SUMIFS('Monthly NSE Equity Options'!$J:$J,'Monthly NSE Equity Options'!$B:$B,$A9))) | C9: =IF(SUMIFS('Year BSE Equity Options'!$H:$H,'Year BSE Equity Options'!$A:$A,$A9)=0,"",SUMIFS('Year BSE Equity Options'!$H:$H,'Year BSE Equity Options'!$A:$A,$A9)) | D9: =IF(OR(B9="",C9=""),"",B9+C9) | E9: =IF(D9="","",B9/D9) | F9: =IF(D9="","",C9/D9) | G9: =IF(OR(B9="",B8=""),"",B9/B8-1) | H9: =IF(OR(C9="",C8=""),"",C9/C8-1) | I9: =IF(OR(D9="",D8=""),"",D9/D8-1) | J9: =IF(MAX(SUMIFS('Year NSE Equity Options'!$I:$I,'Year NSE Equity Options'!$A:$A,$A9),SUMIFS('Monthly NSE Equity Options'!$K:$K,'Monthly NSE Equity Options'!$B:$B,$A9))=0,"",MAX(SUMIFS('Year NSE Equity Options'!$I:$I,'Year NSE Equity Options'!$A:$A,$A9),SUMIFS('Monthly NSE Equity Options'!$K:$K,'Monthly NSE Equity Options'!$B:$B,$A9))) | K9: =IF(SUMIFS('Year BSE Equity Options'!$I:$I,'Year BSE Equity Options'!$A:$A,$A9)=0,"",SUMIFS('Year BSE Equity Options'!$I:$I,'Year BSE Equity Options'!$A:$A,$A9)) | L9: =IF(OR(J9="",K9=""),"",J9+K9) | M9: =IF(L9="","",J9/L9) | N9: =IF(L9="","",K9/L9) | O9: =IF(MAX(SUMIFS('Year NSE Equity Options'!$J:$J,'Year NSE Equity Options'!$A:$A,$A9),SUMIFS('Monthly NSE Equity Options'!$L:$L,'Monthly NSE Equity Options'!$B:$B,$A9))=0,"",MAX(SUMIFS('Year NSE Equity Options'!$J:$J,'Year NSE Equity Options'!$A:$A,$A9),SUMIFS('Monthly NSE Equity Options'!$L:$L,'Monthly NSE Equity Options'!$B:$B,$A9))) | P9: =IF(SUMIFS('Year BSE Equity Options'!$J:$J,'Year BSE Equity Options'!$A:$A,$A9)=0,"",SUMIFS('Year BSE Equity Options'!$J:$J,'Year BSE Equity Options'!$A:$A,$A9)) | Q9: =IF(OR(O9="",P9=""),"",O9+P9) | R9: =IF(Q9="","",O9/Q9) | S9: =IF(Q9="","",P9/Q9)
A10: 2011-2012 | B10: =IF(MAX(SUMIFS('Year NSE Equity Options'!$H:$H,'Year NSE Equity Options'!$A:$A,$A10),SUMIFS('Monthly NSE Equity Options'!$J:$J,'Monthly NSE Equity Options'!$B:$B,$A10))=0,"",MAX(SUMIFS('Year NSE Equity Options'!$H:$H,'Year NSE Equity Options'!$A:$A,$A10),SUMIFS('Monthly NSE Equity Options'!$J:$J,'Monthly NSE Equity Options'!$B:$B,$A10))) | C10: =IF(SUMIFS('Year BSE Equity Options'!$H:$H,'Year BSE Equity Options'!$A:$A,$A10)=0,"",SUMIFS('Year BSE Equity Options'!$H:$H,'Year BSE Equity Options'!$A:$A,$A10)) | D10: =IF(OR(B10="",C10=""),"",B10+C10) | E10: =IF(D10="","",B10/D10) | F10: =IF(D10="","",C10/D10) | G10: =IF(OR(B10="",B9=""),"",B10/B9-1) | H10: =IF(OR(C10="",C9=""),"",C10/C9-1) | I10: =IF(OR(D10="",D9=""),"",D10/D9-1) | J10: =IF(MAX(SUMIFS('Year NSE Equity Options'!$I:$I,'Year NSE Equity Options'!$A:$A,$A10),SUMIFS('Monthly NSE Equity Options'!$K:$K,'Monthly NSE Equity Options'!$B:$B,$A10))=0,"",MAX(SUMIFS('Year NSE Equity Options'!$I:$I,'Year NSE Equity Options'!$A:$A,$A10),SUMIFS('Monthly NSE Equity Options'!$K:$K,'Monthly NSE Equity Options'!$B:$B,$A10))) | K10: =IF(SUMIFS('Year BSE Equity Options'!$I:$I,'Year BSE Equity Options'!$A:$A,$A10)=0,"",SUMIFS('Year BSE Equity Options'!$I:$I,'Year BSE Equity Options'!$A:$A,$A10)) | L10: =IF(OR(J10="",K10=""),"",J10+K10) | M10: =IF(L10="","",J10/L10) | N10: =IF(L10="","",K10/L10) | O10: =IF(MAX(SUMIFS('Year NSE Equity Options'!$J:$J,'Year NSE Equity Options'!$A:$A,$A10),SUMIFS('Monthly NSE Equity Options'!$L:$L,'Monthly NSE Equity Options'!$B:$B,$A10))=0,"",MAX(SUMIFS('Year NSE Equity Options'!$J:$J,'Year NSE Equity Options'!$A:$A,$A10),SUMIFS('Monthly NSE Equity Options'!$L:$L,'Monthly NSE Equity Options'!$B:$B,$A10))) | P10: =IF(SUMIFS('Year BSE Equity Options'!$J:$J,'Year BSE Equity Options'!$A:$A,$A10)=0,"",SUMIFS('Year BSE Equity Options'!$J:$J,'Year BSE Equity Options'!$A:$A,$A10)) | Q10: =IF(OR(O10="",P10=""),"",O10+P10) | R10: =IF(Q10="","",O10/Q10) | S10: =IF(Q10="","",P10/Q10)
A11: 2012-2013 | B11: =IF(MAX(SUMIFS('Year NSE Equity Options'!$H:$H,'Year NSE Equity Options'!$A:$A,$A11),SUMIFS('Monthly NSE Equity Options'!$J:$J,'Monthly NSE Equity Options'!$B:$B,$A11))=0,"",MAX(SUMIFS('Year NSE Equity Options'!$H:$H,'Year NSE Equity Options'!$A:$A,$A11),SUMIFS('Monthly NSE Equity Options'!$J:$J,'Monthly NSE Equity Options'!$B:$B,$A11))) | C11: =IF(SUMIFS('Year BSE Equity Options'!$H:$H,'Year BSE Equity Options'!$A:$A,$A11)=0,"",SUMIFS('Year BSE Equity Options'!$H:$H,'Year BSE Equity Options'!$A:$A,$A11)) | D11: =IF(OR(B11="",C11=""),"",B11+C11) | E11: =IF(D11="","",B11/D11) | F11: =IF(D11="","",C11/D11) | G11: =IF(OR(B11="",B10=""),"",B11/B10-1) | H11: =IF(OR(C11="",C10=""),"",C11/C10-1) | I11: =IF(OR(D11="",D10=""),"",D11/D10-1) | J11: =IF(MAX(SUMIFS('Year NSE Equity Options'!$I:$I,'Year NSE Equity Options'!$A:$A,$A11),SUMIFS('Monthly NSE Equity Options'!$K:$K,'Monthly NSE Equity Options'!$B:$B,$A11))=0,"",MAX(SUMIFS('Year NSE Equity Options'!$I:$I,'Year NSE Equity Options'!$A:$A,$A11),SUMIFS('Monthly NSE Equity Options'!$K:$K,'Monthly NSE Equity Options'!$B:$B,$A11))) | K11: =IF(SUMIFS('Year BSE Equity Options'!$I:$I,'Year BSE Equity Options'!$A:$A,$A11)=0,"",SUMIFS('Year BSE Equity Options'!$I:$I,'Year BSE Equity Options'!$A:$A,$A11)) | L11: =IF(OR(J11="",K11=""),"",J11+K11) | M11: =IF(L11="","",J11/L11) | N11: =IF(L11="","",K11/L11) | O11: =IF(MAX(SUMIFS('Year NSE Equity Options'!$J:$J,'Year NSE Equity Options'!$A:$A,$A11),SUMIFS('Monthly NSE Equity Options'!$L:$L,'Monthly NSE Equity Options'!$B:$B,$A11))=0,"",MAX(SUMIFS('Year NSE Equity Options'!$J:$J,'Year NSE Equity Options'!$A:$A,$A11),SUMIFS('Monthly NSE Equity Options'!$L:$L,'Monthly NSE Equity Options'!$B:$B,$A11))) | P11: =IF(SUMIFS('Year BSE Equity Options'!$J:$J,'Year BSE Equity Options'!$A:$A,$A11)=0,"",SUMIFS('Year BSE Equity Options'!$J:$J,'Year BSE Equity Options'!$A:$A,$A11)) | Q11: =IF(OR(O11="",P11=""),"",O11+P11) | R11: =IF(Q11="","",O11/Q11) | S11: =IF(Q11="","",P11/Q11)
A12: 2013-2014 | B12: =IF(MAX(SUMIFS('Year NSE Equity Options'!$H:$H,'Year NSE Equity Options'!$A:$A,$A12),SUMIFS('Monthly NSE Equity Options'!$J:$J,'Monthly NSE Equity Options'!$B:$B,$A12))=0,"",MAX(SUMIFS('Year NSE Equity Options'!$H:$H,'Year NSE Equity Options'!$A:$A,$A12),SUMIFS('Monthly NSE Equity Options'!$J:$J,'Monthly NSE Equity Options'!$B:$B,$A12))) | C12: =IF(SUMIFS('Year BSE Equity Options'!$H:$H,'Year BSE Equity Options'!$A:$A,$A12)=0,"",SUMIFS('Year BSE Equity Options'!$H:$H,'Year BSE Equity Options'!$A:$A,$A12)) | D12: =IF(OR(B12="",C12=""),"",B12+C12) | E12: =IF(D12="","",B12/D12) | F12: =IF(D12="","",C12/D12) | G12: =IF(OR(B12="",B11=""),"",B12/B11-1) | H12: =IF(OR(C12="",C11=""),"",C12/C11-1) | I12: =IF(OR(D12="",D11=""),"",D12/D11-1) | J12: =IF(MAX(SUMIFS('Year NSE Equity Options'!$I:$I,'Year NSE Equity Options'!$A:$A,$A12),SUMIFS('Monthly NSE Equity Options'!$K:$K,'Monthly NSE Equity Options'!$B:$B,$A12))=0,"",MAX(SUMIFS('Year NSE Equity Options'!$I:$I,'Year NSE Equity Options'!$A:$A,$A12),SUMIFS('Monthly NSE Equity Options'!$K:$K,'Monthly NSE Equity Options'!$B:$B,$A12))) | K12: =IF(SUMIFS('Year BSE Equity Options'!$I:$I,'Year BSE Equity Options'!$A:$A,$A12)=0,"",SUMIFS('Year BSE Equity Options'!$I:$I,'Year BSE Equity Options'!$A:$A,$A12)) | L12: =IF(OR(J12="",K12=""),"",J12+K12) | M12: =IF(L12="","",J12/L12) | N12: =IF(L12="","",K12/L12) | O12: =IF(MAX(SUMIFS('Year NSE Equity Options'!$J:$J,'Year NSE Equity Options'!$A:$A,$A12),SUMIFS('Monthly NSE Equity Options'!$L:$L,'Monthly NSE Equity Options'!$B:$B,$A12))=0,"",MAX(SUMIFS('Year NSE Equity Options'!$J:$J,'Year NSE Equity Options'!$A:$A,$A12),SUMIFS('Monthly NSE Equity Options'!$L:$L,'Monthly NSE Equity Options'!$B:$B,$A12))) | P12: =IF(SUMIFS('Year BSE Equity Options'!$J:$J,'Year BSE Equity Options'!$A:$A,$A12)=0,"",SUMIFS('Year BSE Equity Options'!$J:$J,'Year BSE Equity Options'!$A:$A,$A12)) | Q12: =IF(OR(O12="",P12=""),"",O12+P12) | R12: =IF(Q12="","",O12/Q12) | S12: =IF(Q12="","",P12/Q12)
A13: 2014-2015 | B13: =IF(MAX(SUMIFS('Year NSE Equity Options'!$H:$H,'Year NSE Equity Options'!$A:$A,$A13),SUMIFS('Monthly NSE Equity Options'!$J:$J,'Monthly NSE Equity Options'!$B:$B,$A13))=0,"",MAX(SUMIFS('Year NSE Equity Options'!$H:$H,'Year NSE Equity Options'!$A:$A,$A13),SUMIFS('Monthly NSE Equity Options'!$J:$J,'Monthly NSE Equity Options'!$B:$B,$A13))) | C13: =IF(SUMIFS('Year BSE Equity Options'!$H:$H,'Year BSE Equity Options'!$A:$A,$A13)=0,"",SUMIFS('Year BSE Equity Options'!$H:$H,'Year BSE Equity Options'!$A:$A,$A13)) | D13: =IF(OR(B13="",C13=""),"",B13+C13) | E13: =IF(D13="","",B13/D13) | F13: =IF(D13="","",C13/D13) | G13: =IF(OR(B13="",B12=""),"",B13/B12-1) | H13: =IF(OR(C13="",C12=""),"",C13/C12-1) | I13: =IF(OR(D13="",D12=""),"",D13/D12-1) | J13: =IF(MAX(SUMIFS('Year NSE Equity Options'!$I:$I,'Year NSE Equity Options'!$A:$A,$A13),SUMIFS('Monthly NSE Equity Options'!$K:$K,'Monthly NSE Equity Options'!$B:$B,$A13))=0,"",MAX(SUMIFS('Year NSE Equity Options'!$I:$I,'Year NSE Equity Options'!$A:$A,$A13),SUMIFS('Monthly NSE Equity Options'!$K:$K,'Monthly NSE Equity Options'!$B:$B,$A13))) | K13: =IF(SUMIFS('Year BSE Equity Options'!$I:$I,'Year BSE Equity Options'!$A:$A,$A13)=0,"",SUMIFS('Year BSE Equity Options'!$I:$I,'Year BSE Equity Options'!$A:$A,$A13)) | L13: =IF(OR(J13="",K13=""),"",J13+K13) | M13: =IF(L13="","",J13/L13) | N13: =IF(L13="","",K13/L13) | O13: =IF(MAX(SUMIFS('Year NSE Equity Options'!$J:$J,'Year NSE Equity Options'!$A:$A,$A13),SUMIFS('Monthly NSE Equity Options'!$L:$L,'Monthly NSE Equity Options'!$B:$B,$A13))=0,"",MAX(SUMIFS('Year NSE Equity Options'!$J:$J,'Year NSE Equity Options'!$A:$A,$A13),SUMIFS('Monthly NSE Equity Options'!$L:$L,'Monthly NSE Equity Options'!$B:$B,$A13))) | P13: =IF(SUMIFS('Year BSE Equity Options'!$J:$J,'Year BSE Equity Options'!$A:$A,$A13)=0,"",SUMIFS('Year BSE Equity Options'!$J:$J,'Year BSE Equity Options'!$A:$A,$A13)) | Q13: =IF(OR(O13="",P13=""),"",O13+P13) | R13: =IF(Q13="","",O13/Q13) | S13: =IF(Q13="","",P13/Q13)
A14: 2015-2016 | B14: =IF(MAX(SUMIFS('Year NSE Equity Options'!$H:$H,'Year NSE Equity Options'!$A:$A,$A14),SUMIFS('Monthly NSE Equity Options'!$J:$J,'Monthly NSE Equity Options'!$B:$B,$A14))=0,"",MAX(SUMIFS('Year NSE Equity Options'!$H:$H,'Year NSE Equity Options'!$A:$A,$A14),SUMIFS('Monthly NSE Equity Options'!$J:$J,'Monthly NSE Equity Options'!$B:$B,$A14))) | C14: =IF(SUMIFS('Year BSE Equity Options'!$H:$H,'Year BSE Equity Options'!$A:$A,$A14)=0,"",SUMIFS('Year BSE Equity Options'!$H:$H,'Year BSE Equity Options'!$A:$A,$A14)) | D14: =IF(OR(B14="",C14=""),"",B14+C14) | E14: =IF(D14="","",B14/D14) | F14: =IF(D14="","",C14/D14) | G14: =IF(OR(B14="",B13=""),"",B14/B13-1) | H14: =IF(OR(C14="",C13=""),"",C14/C13-1) | I14: =IF(OR(D14="",D13=""),"",D14/D13-1) | J14: =IF(MAX(SUMIFS('Year NSE Equity Options'!$I:$I,'Year NSE Equity Options'!$A:$A,$A14),SUMIFS('Monthly NSE Equity Options'!$K:$K,'Monthly NSE Equity Options'!$B:$B,$A14))=0,"",MAX(SUMIFS('Year NSE Equity Options'!$I:$I,'Year NSE Equity Options'!$A:$A,$A14),SUMIFS('Monthly NSE Equity Options'!$K:$K,'Monthly NSE Equity Options'!$B:$B,$A14))) | K14: =IF(SUMIFS('Year BSE Equity Options'!$I:$I,'Year BSE Equity Options'!$A:$A,$A14)=0,"",SUMIFS('Year BSE Equity Options'!$I:$I,'Year BSE Equity Options'!$A:$A,$A14)) | L14: =IF(OR(J14="",K14=""),"",J14+K14) | M14: =IF(L14="","",J14/L14) | N14: =IF(L14="","",K14/L14) | O14: =IF(MAX(SUMIFS('Year NSE Equity Options'!$J:$J,'Year NSE Equity Options'!$A:$A,$A14),SUMIFS('Monthly NSE Equity Options'!$L:$L,'Monthly NSE Equity Options'!$B:$B,$A14))=0,"",MAX(SUMIFS('Year NSE Equity Options'!$J:$J,'Year NSE Equity Options'!$A:$A,$A14),SUMIFS('Monthly NSE Equity Options'!$L:$L,'Monthly NSE Equity Options'!$B:$B,$A14))) | P14: =IF(SUMIFS('Year BSE Equity Options'!$J:$J,'Year BSE Equity Options'!$A:$A,$A14)=0,"",SUMIFS('Year BSE Equity Options'!$J:$J,'Year BSE Equity Options'!$A:$A,$A14)) | Q14: =IF(OR(O14="",P14=""),"",O14+P14) | R14: =IF(Q14="","",O14/Q14) | S14: =IF(Q14="","",P14/Q14)
... A25: 2026-2027 | B25: =IF(MAX(SUMIFS('Year NSE Equity Options'!$H:$H,'Year NSE Equity Options'!$A:$A,$A25),SUMIFS('Monthly NSE Equity Options'!$J:$J,'Monthly NSE Equity Options'!$B:$B,$A25))=0,"",MAX(SUMIFS('Year NSE Equity Options'!$H:$H,'Year NSE Equity Options'!$A:$A,$A25),SUMIFS('Monthly NSE Equity Options'!$J:$J,'Monthly NSE Equity Options'!$B:$B,$A25))) | C25: =IF(SUMIFS('Year BSE Equity Options'!$H:$H,'Year BSE Equity Options'!$A:$A,$A25)=0,"",SUMIFS('Year BSE Equity Options'!$H:$H,'Year BSE Equity Options'!$A:$A,$A25)) | D25: =IF(OR(B25="",C25=""),"",B25+C25) | E25: =IF(D25="","",B25/D25) | F25: =IF(D25="","",C25/D25) | G25: =IF(OR(B25="",B24=""),"",B25/B24-1) | H25: =IF(OR(C25="",C24=""),"",C25/C24-1) | I25: =IF(OR(D25="",D24=""),"",D25/D24-1) | J25: =IF(MAX(SUMIFS('Year NSE Equity Options'!$I:$I,'Year NSE Equity Options'!$A:$A,$A25),SUMIFS('Monthly NSE Equity Options'!$K:$K,'Monthly NSE Equity Options'!$B:$B,$A25))=0,"",MAX(SUMIFS('Year NSE Equity Options'!$I:$I,'Year NSE Equity Options'!$A:$A,$A25),SUMIFS('Monthly NSE Equity Options'!$K:$K,'Monthly NSE Equity Options'!$B:$B,$A25))) | K25: =IF(SUMIFS('Year BSE Equity Options'!$I:$I,'Year BSE Equity Options'!$A:$A,$A25)=0,"",SUMIFS('Year BSE Equity Options'!$I:$I,'Year BSE Equity Options'!$A:$A,$A25)) | L25: =IF(OR(J25="",K25=""),"",J25+K25) | M25: =IF(L25="","",J25/L25) | N25: =IF(L25="","",K25/L25) | O25: =IF(MAX(SUMIFS('Year NSE Equity Options'!$J:$J,'Year NSE Equity Options'!$A:$A,$A25),SUMIFS('Monthly NSE Equity Options'!$L:$L,'Monthly NSE Equity Options'!$B:$B,$A25))=0,"",MAX(SUMIFS('Year NSE Equity Options'!$J:$J,'Year NSE Equity Options'!$A:$A,$A25),SUMIFS('Monthly NSE Equity Options'!$L:$L,'Monthly NSE Equity Options'!$B:$B,$A25))) | P25: =IF(SUMIFS('Year BSE Equity Options'!$J:$J,'Year BSE Equity Options'!$A:$A,$A25)=0,"",SUMIFS('Year BSE Equity Options'!$J:$J,'Year BSE Equity Options'!$A:$A,$A25)) | Q25: =IF(OR(O25="",P25=""),"",O25+P25) | R25: =IF(Q25="","",O25/Q25) | S25: =IF(Q25="","",P25/Q25)
A27: YTD Comparison - FY2026-2027 YTD vs FY2025-2026 YTD (same number of trading days)
A28: Trading days elapsed in FY2026-2027 (per NSE daily) | B28: =COUNTIF('Daily NSE Equity Options'!$A:$A,">="&DATE(2026,4,1))
A29: Matched FY2025-2026 window | B29: =DATE(2025,4,1) | C29: =INDEX('Daily NSE Equity Options'!$A:$A,COUNTIF('Daily NSE Equity Options'!$A:$A,"<"&DATE(2025,4,1))+1+$B28)
B30: NSE Premium Turnover (INR Bn) | C30: BSE Premium Turnover (INR Bn) | D30: Total Premium Turnover (INR Bn) | E30: NSE Premium Market Share | F30: BSE Premium Market Share | J30: NSE Notional Turnover (INR Bn) | K30: BSE Notional Turnover (INR Bn) | L30: Total Notional Turnover (INR Bn) | M30: NSE Notional Market Share | N30: BSE Notional Market Share | O30: NSE No. of Contracts | P30: BSE No. of Contracts | Q30: Total No. of Contracts | R30: NSE Contracts Market Share | S30: BSE Contracts Market Share
A31: FY2025-2026 YTD (first N trading days) | B31: =SUMIFS('Daily NSE Equity Options'!$K:$K,'Daily NSE Equity Options'!$A:$A,">="&$B$29,'Daily NSE Equity Options'!$A:$A,"<="&$C$29) | C31: =SUMIFS('Daily BSE Equity Options'!$K:$K,'Daily BSE Equity Options'!$A:$A,">="&$B$29,'Daily BSE Equity Options'!$A:$A,"<="&$C$29) | D31: =B31+C31 | E31: =IF(D31=0,"",B31/D31) | F31: =IF(D31=0,"",C31/D31) | J31: =SUMIFS('Daily NSE Equity Options'!$L:$L,'Daily NSE Equity Options'!$A:$A,">="&$B$29,'Daily NSE Equity Options'!$A:$A,"<="&$C$29) | K31: =SUMIFS('Daily BSE Equity Options'!$L:$L,'Daily BSE Equity Options'!$A:$A,">="&$B$29,'Daily BSE Equity Options'!$A:$A,"<="&$C$29) | L31: =J31+K31 | M31: =IF(L31=0,"",J31/L31) | N31: =IF(L31=0,"",K31/L31) | O31: =SUMIFS('Daily NSE Equity Options'!$M:$M,'Daily NSE Equity Options'!$A:$A,">="&$B$29,'Daily NSE Equity Options'!$A:$A,"<="&$C$29) | P31: =SUMIFS('Daily BSE Equity Options'!$M:$M,'Daily BSE Equity Options'!$A:$A,">="&$B$29,'Daily BSE Equity Options'!$A:$A,"<="&$C$29) | Q31: =O31+P31 | R31: =IF(Q31=0,"",O31/Q31) | S31: =IF(Q31=0,"",P31/Q31)
A32: FY2026-2027 YTD | B32: =SUMIFS('Daily NSE Equity Options'!$K:$K,'Daily NSE Equity Options'!$A:$A,">="&DATE(2026,4,1)) | C32: =SUMIFS('Daily BSE Equity Options'!$K:$K,'Daily BSE Equity Options'!$A:$A,">="&DATE(2026,4,1)) | D32: =B32+C32 | E32: =IF(D32=0,"",B32/D32) | F32: =IF(D32=0,"",C32/D32) | J32: =SUMIFS('Daily NSE Equity Options'!$L:$L,'Daily NSE Equity Options'!$A:$A,">="&DATE(2026,4,1)) | K32: =SUMIFS('Daily BSE Equity Options'!$L:$L,'Daily BSE Equity Options'!$A:$A,">="&DATE(2026,4,1)) | L32: =J32+K32 | M32: =IF(L32=0,"",J32/L32) | N32: =IF(L32=0,"",K32/L32) | O32: =SUMIFS('Daily NSE Equity Options'!$M:$M,'Daily NSE Equity Options'!$A:$A,">="&DATE(2026,4,1)) | P32: =SUMIFS('Daily BSE Equity Options'!$M:$M,'Daily BSE Equity Options'!$A:$A,">="&DATE(2026,4,1)) | Q32: =O32+P32 | R32: =IF(Q32=0,"",O32/Q32) | S32: =IF(Q32=0,"",P32/Q32)
A33: YTD Growth (FY2026-2027 vs FY2025-2026) | B33: =IF(OR(B31=0,B31=""),"",B32/B31-1) | C33: =IF(OR(C31=0,C31=""),"",C32/C31-1) | D33: =IF(OR(D31=0,D31=""),"",D32/D31-1) | J33: =IF(OR(J31=0,J31=""),"",J32/J31-1) | K33: =IF(OR(K31=0,K31=""),"",K32/K31-1) | L33: =IF(OR(L31=0,L31=""),"",L32/L31-1) | O33: =IF(OR(O31=0,O31=""),"",O32/O31-1) | P33: =IF(OR(P31=0,P31=""),"",P32/P31-1) | Q33: =IF(OR(Q31=0,Q31=""),"",Q32/Q31-1)

Sheet Qrtr Equity Options Mkt Share
A1: Qrtr - Year | B1: NSE Premium Turnover (INR Bn) | C1: BSE Premium Turnover (INR Bn) | D1: Total Premium Turnover (INR Bn) | E1: NSE Premium Market Share | F1: BSE Premium Market Share | G1: NSE Premium YoY Growth | H1: BSE Premium YoY Growth | I1: Total Premium YoY Growth | J1: NSE Premium QoQ Growth | K1: BSE Premium QoQ Growth | L1: Total Premium QoQ Growth | M1: NSE Notional Turnover (INR Bn) | N1: BSE Notional Turnover (INR Bn) | O1: Total Notional Turnover (INR Bn) | P1: NSE Notional Market Share | Q1: BSE Notional Market Share | R1: NSE No. of Contracts | S1: BSE No. of Contracts | T1: Total No. of Contracts | U1: NSE Contracts Market Share | V1: BSE Contracts Market Share
A2: Q4FY04 | B2: =IF(SUMIFS('Monthly NSE Equity Options'!$J:$J,'Monthly NSE Equity Options'!$C:$C,$A2)=0,"",SUMIFS('Monthly NSE Equity Options'!$J:$J,'Monthly NSE Equity Options'!$C:$C,$A2)) | C2: =IF(SUMIFS('Monthly BSE Equity Options'!$J:$J,'Monthly BSE Equity Options'!$C:$C,$A2)=0,"",SUMIFS('Monthly BSE Equity Options'!$J:$J,'Monthly BSE Equity Options'!$C:$C,$A2)) | D2: =IF(OR(B2="",C2=""),"",B2+C2) | E2: =IF(D2="","",B2/D2) | F2: =IF(D2="","",C2/D2) | M2: =IF(SUMIFS('Monthly NSE Equity Options'!$K:$K,'Monthly NSE Equity Options'!$C:$C,$A2)=0,"",SUMIFS('Monthly NSE Equity Options'!$K:$K,'Monthly NSE Equity Options'!$C:$C,$A2)) | N2: =IF(SUMIFS('Monthly BSE Equity Options'!$K:$K,'Monthly BSE Equity Options'!$C:$C,$A2)=0,"",SUMIFS('Monthly BSE Equity Options'!$K:$K,'Monthly BSE Equity Options'!$C:$C,$A2)) | O2: =IF(OR(M2="",N2=""),"",M2+N2) | P2: =IF(O2="","",M2/O2) | Q2: =IF(O2="","",N2/O2) | R2: =IF(SUMIFS('Monthly NSE Equity Options'!$L:$L,'Monthly NSE Equity Options'!$C:$C,$A2)=0,"",SUMIFS('Monthly NSE Equity Options'!$L:$L,'Monthly NSE Equity Options'!$C:$C,$A2)) | S2: =IF(SUMIFS('Monthly BSE Equity Options'!$L:$L,'Monthly BSE Equity Options'!$C:$C,$A2)=0,"",SUMIFS('Monthly BSE Equity Options'!$L:$L,'Monthly BSE Equity Options'!$C:$C,$A2)) | T2: =IF(OR(R2="",S2=""),"",R2+S2) | U2: =IF(T2="","",R2/T2) | V2: =IF(T2="","",S2/T2)
A3: Q1FY05 | B3: =IF(SUMIFS('Monthly NSE Equity Options'!$J:$J,'Monthly NSE Equity Options'!$C:$C,$A3)=0,"",SUMIFS('Monthly NSE Equity Options'!$J:$J,'Monthly NSE Equity Options'!$C:$C,$A3)) | C3: =IF(SUMIFS('Monthly BSE Equity Options'!$J:$J,'Monthly BSE Equity Options'!$C:$C,$A3)=0,"",SUMIFS('Monthly BSE Equity Options'!$J:$J,'Monthly BSE Equity Options'!$C:$C,$A3)) | D3: =IF(OR(B3="",C3=""),"",B3+C3) | E3: =IF(D3="","",B3/D3) | F3: =IF(D3="","",C3/D3) | J3: =IF(OR(B3="",B2=""),"",B3/B2-1) | K3: =IF(OR(C3="",C2=""),"",C3/C2-1) | L3: =IF(OR(D3="",D2=""),"",D3/D2-1) | M3: =IF(SUMIFS('Monthly NSE Equity Options'!$K:$K,'Monthly NSE Equity Options'!$C:$C,$A3)=0,"",SUMIFS('Monthly NSE Equity Options'!$K:$K,'Monthly NSE Equity Options'!$C:$C,$A3)) | N3: =IF(SUMIFS('Monthly BSE Equity Options'!$K:$K,'Monthly BSE Equity Options'!$C:$C,$A3)=0,"",SUMIFS('Monthly BSE Equity Options'!$K:$K,'Monthly BSE Equity Options'!$C:$C,$A3)) | O3: =IF(OR(M3="",N3=""),"",M3+N3) | P3: =IF(O3="","",M3/O3) | Q3: =IF(O3="","",N3/O3) | R3: =IF(SUMIFS('Monthly NSE Equity Options'!$L:$L,'Monthly NSE Equity Options'!$C:$C,$A3)=0,"",SUMIFS('Monthly NSE Equity Options'!$L:$L,'Monthly NSE Equity Options'!$C:$C,$A3)) | S3: =IF(SUMIFS('Monthly BSE Equity Options'!$L:$L,'Monthly BSE Equity Options'!$C:$C,$A3)=0,"",SUMIFS('Monthly BSE Equity Options'!$L:$L,'Monthly BSE Equity Options'!$C:$C,$A3)) | T3: =IF(OR(R3="",S3=""),"",R3+S3) | U3: =IF(T3="","",R3/T3) | V3: =IF(T3="","",S3/T3)
A4: Q2FY05 | B4: =IF(SUMIFS('Monthly NSE Equity Options'!$J:$J,'Monthly NSE Equity Options'!$C:$C,$A4)=0,"",SUMIFS('Monthly NSE Equity Options'!$J:$J,'Monthly NSE Equity Options'!$C:$C,$A4)) | C4: =IF(SUMIFS('Monthly BSE Equity Options'!$J:$J,'Monthly BSE Equity Options'!$C:$C,$A4)=0,"",SUMIFS('Monthly BSE Equity Options'!$J:$J,'Monthly BSE Equity Options'!$C:$C,$A4)) | D4: =IF(OR(B4="",C4=""),"",B4+C4) | E4: =IF(D4="","",B4/D4) | F4: =IF(D4="","",C4/D4) | J4: =IF(OR(B4="",B3=""),"",B4/B3-1) | K4: =IF(OR(C4="",C3=""),"",C4/C3-1) | L4: =IF(OR(D4="",D3=""),"",D4/D3-1) | M4: =IF(SUMIFS('Monthly NSE Equity Options'!$K:$K,'Monthly NSE Equity Options'!$C:$C,$A4)=0,"",SUMIFS('Monthly NSE Equity Options'!$K:$K,'Monthly NSE Equity Options'!$C:$C,$A4)) | N4: =IF(SUMIFS('Monthly BSE Equity Options'!$K:$K,'Monthly BSE Equity Options'!$C:$C,$A4)=0,"",SUMIFS('Monthly BSE Equity Options'!$K:$K,'Monthly BSE Equity Options'!$C:$C,$A4)) | O4: =IF(OR(M4="",N4=""),"",M4+N4) | P4: =IF(O4="","",M4/O4) | Q4: =IF(O4="","",N4/O4) | R4: =IF(SUMIFS('Monthly NSE Equity Options'!$L:$L,'Monthly NSE Equity Options'!$C:$C,$A4)=0,"",SUMIFS('Monthly NSE Equity Options'!$L:$L,'Monthly NSE Equity Options'!$C:$C,$A4)) | S4: =IF(SUMIFS('Monthly BSE Equity Options'!$L:$L,'Monthly BSE Equity Options'!$C:$C,$A4)=0,"",SUMIFS('Monthly BSE Equity Options'!$L:$L,'Monthly BSE Equity Options'!$C:$C,$A4)) | T4: =IF(OR(R4="",S4=""),"",R4+S4) | U4: =IF(T4="","",R4/T4) | V4: =IF(T4="","",S4/T4)
A5: Q3FY05 | B5: =IF(SUMIFS('Monthly NSE Equity Options'!$J:$J,'Monthly NSE Equity Options'!$C:$C,$A5)=0,"",SUMIFS('Monthly NSE Equity Options'!$J:$J,'Monthly NSE Equity Options'!$C:$C,$A5)) | C5: =IF(SUMIFS('Monthly BSE Equity Options'!$J:$J,'Monthly BSE Equity Options'!$C:$C,$A5)=0,"",SUMIFS('Monthly BSE Equity Options'!$J:$J,'Monthly BSE Equity Options'!$C:$C,$A5)) | D5: =IF(OR(B5="",C5=""),"",B5+C5) | E5: =IF(D5="","",B5/D5) | F5: =IF(D5="","",C5/D5) | J5: =IF(OR(B5="",B4=""),"",B5/B4-1) | K5: =IF(OR(C5="",C4=""),"",C5/C4-1) | L5: =IF(OR(D5="",D4=""),"",D5/D4-1) | M5: =IF(SUMIFS('Monthly NSE Equity Options'!$K:$K,'Monthly NSE Equity Options'!$C:$C,$A5)=0,"",SUMIFS('Monthly NSE Equity Options'!$K:$K,'Monthly NSE Equity Options'!$C:$C,$A5)) | N5: =IF(SUMIFS('Monthly BSE Equity Options'!$K:$K,'Monthly BSE Equity Options'!$C:$C,$A5)=0,"",SUMIFS('Monthly BSE Equity Options'!$K:$K,'Monthly BSE Equity Options'!$C:$C,$A5)) | O5: =IF(OR(M5="",N5=""),"",M5+N5) | P5: =IF(O5="","",M5/O5) | Q5: =IF(O5="","",N5/O5) | R5: =IF(SUMIFS('Monthly NSE Equity Options'!$L:$L,'Monthly NSE Equity Options'!$C:$C,$A5)=0,"",SUMIFS('Monthly NSE Equity Options'!$L:$L,'Monthly NSE Equity Options'!$C:$C,$A5)) | S5: =IF(SUMIFS('Monthly BSE Equity Options'!$L:$L,'Monthly BSE Equity Options'!$C:$C,$A5)=0,"",SUMIFS('Monthly BSE Equity Options'!$L:$L,'Monthly BSE Equity Options'!$C:$C,$A5)) | T5: =IF(OR(R5="",S5=""),"",R5+S5) | U5: =IF(T5="","",R5/T5) | V5: =IF(T5="","",S5/T5)
A6: Q4FY05 | B6: =IF(SUMIFS('Monthly NSE Equity Options'!$J:$J,'Monthly NSE Equity Options'!$C:$C,$A6)=0,"",SUMIFS('Monthly NSE Equity Options'!$J:$J,'Monthly NSE Equity Options'!$C:$C,$A6)) | C6: =IF(SUMIFS('Monthly BSE Equity Options'!$J:$J,'Monthly BSE Equity Options'!$C:$C,$A6)=0,"",SUMIFS('Monthly BSE Equity Options'!$J:$J,'Monthly BSE Equity Options'!$C:$C,$A6)) | D6: =IF(OR(B6="",C6=""),"",B6+C6) | E6: =IF(D6="","",B6/D6) | F6: =IF(D6="","",C6/D6) | G6: =IF(OR(B6="",B2=""),"",B6/B2-1) | H6: =IF(OR(C6="",C2=""),"",C6/C2-1) | I6: =IF(OR(D6="",D2=""),"",D6/D2-1) | J6: =IF(OR(B6="",B5=""),"",B6/B5-1) | K6: =IF(OR(C6="",C5=""),"",C6/C5-1) | L6: =IF(OR(D6="",D5=""),"",D6/D5-1) | M6: =IF(SUMIFS('Monthly NSE Equity Options'!$K:$K,'Monthly NSE Equity Options'!$C:$C,$A6)=0,"",SUMIFS('Monthly NSE Equity Options'!$K:$K,'Monthly NSE Equity Options'!$C:$C,$A6)) | N6: =IF(SUMIFS('Monthly BSE Equity Options'!$K:$K,'Monthly BSE Equity Options'!$C:$C,$A6)=0,"",SUMIFS('Monthly BSE Equity Options'!$K:$K,'Monthly BSE Equity Options'!$C:$C,$A6)) | O6: =IF(OR(M6="",N6=""),"",M6+N6) | P6: =IF(O6="","",M6/O6) | Q6: =IF(O6="","",N6/O6) | R6: =IF(SUMIFS('Monthly NSE Equity Options'!$L:$L,'Monthly NSE Equity Options'!$C:$C,$A6)=0,"",SUMIFS('Monthly NSE Equity Options'!$L:$L,'Monthly NSE Equity Options'!$C:$C,$A6)) | S6: =IF(SUMIFS('Monthly BSE Equity Options'!$L:$L,'Monthly BSE Equity Options'!$C:$C,$A6)=0,"",SUMIFS('Monthly BSE Equity Options'!$L:$L,'Monthly BSE Equity Options'!$C:$C,$A6)) | T6: =IF(OR(R6="",S6=""),"",R6+S6) | U6: =IF(T6="","",R6/T6) | V6: =IF(T6="","",S6/T6)
A7: Q1FY06 | B7: =IF(SUMIFS('Monthly NSE Equity Options'!$J:$J,'Monthly NSE Equity Options'!$C:$C,$A7)=0,"",SUMIFS('Monthly NSE Equity Options'!$J:$J,'Monthly NSE Equity Options'!$C:$C,$A7)) | C7: =IF(SUMIFS('Monthly BSE Equity Options'!$J:$J,'Monthly BSE Equity Options'!$C:$C,$A7)=0,"",SUMIFS('Monthly BSE Equity Options'!$J:$J,'Monthly BSE Equity Options'!$C:$C,$A7)) | D7: =IF(OR(B7="",C7=""),"",B7+C7) | E7: =IF(D7="","",B7/D7) | F7: =IF(D7="","",C7/D7) | G7: =IF(OR(B7="",B3=""),"",B7/B3-1) | H7: =IF(OR(C7="",C3=""),"",C7/C3-1) | I7: =IF(OR(D7="",D3=""),"",D7/D3-1) | J7: =IF(OR(B7="",B6=""),"",B7/B6-1) | K7: =IF(OR(C7="",C6=""),"",C7/C6-1) | L7: =IF(OR(D7="",D6=""),"",D7/D6-1) | M7: =IF(SUMIFS('Monthly NSE Equity Options'!$K:$K,'Monthly NSE Equity Options'!$C:$C,$A7)=0,"",SUMIFS('Monthly NSE Equity Options'!$K:$K,'Monthly NSE Equity Options'!$C:$C,$A7)) | N7: =IF(SUMIFS('Monthly BSE Equity Options'!$K:$K,'Monthly BSE Equity Options'!$C:$C,$A7)=0,"",SUMIFS('Monthly BSE Equity Options'!$K:$K,'Monthly BSE Equity Options'!$C:$C,$A7)) | O7: =IF(OR(M7="",N7=""),"",M7+N7) | P7: =IF(O7="","",M7/O7) | Q7: =IF(O7="","",N7/O7) | R7: =IF(SUMIFS('Monthly NSE Equity Options'!$L:$L,'Monthly NSE Equity Options'!$C:$C,$A7)=0,"",SUMIFS('Monthly NSE Equity Options'!$L:$L,'Monthly NSE Equity Options'!$C:$C,$A7)) | S7: =IF(SUMIFS('Monthly BSE Equity Options'!$L:$L,'Monthly BSE Equity Options'!$C:$C,$A7)=0,"",SUMIFS('Monthly BSE Equity Options'!$L:$L,'Monthly BSE Equity Options'!$C:$C,$A7)) | T7: =IF(OR(R7="",S7=""),"",R7+S7) | U7: =IF(T7="","",R7/T7) | V7: =IF(T7="","",S7/T7)
A8: Q2FY06 | B8: =IF(SUMIFS('Monthly NSE Equity Options'!$J:$J,'Monthly NSE Equity Options'!$C:$C,$A8)=0,"",SUMIFS('Monthly NSE Equity Options'!$J:$J,'Monthly NSE Equity Options'!$C:$C,$A8)) | C8: =IF(SUMIFS('Monthly BSE Equity Options'!$J:$J,'Monthly BSE Equity Options'!$C:$C,$A8)=0,"",SUMIFS('Monthly BSE Equity Options'!$J:$J,'Monthly BSE Equity Options'!$C:$C,$A8)) | D8: =IF(OR(B8="",C8=""),"",B8+C8) | E8: =IF(D8="","",B8/D8) | F8: =IF(D8="","",C8/D8) | G8: =IF(OR(B8="",B4=""),"",B8/B4-1) | H8: =IF(OR(C8="",C4=""),"",C8/C4-1) | I8: =IF(OR(D8="",D4=""),"",D8/D4-1) | J8: =IF(OR(B8="",B7=""),"",B8/B7-1) | K8: =IF(OR(C8="",C7=""),"",C8/C7-1) | L8: =IF(OR(D8="",D7=""),"",D8/D7-1) | M8: =IF(SUMIFS('Monthly NSE Equity Options'!$K:$K,'Monthly NSE Equity Options'!$C:$C,$A8)=0,"",SUMIFS('Monthly NSE Equity Options'!$K:$K,'Monthly NSE Equity Options'!$C:$C,$A8)) | N8: =IF(SUMIFS('Monthly BSE Equity Options'!$K:$K,'Monthly BSE Equity Options'!$C:$C,$A8)=0,"",SUMIFS('Monthly BSE Equity Options'!$K:$K,'Monthly BSE Equity Options'!$C:$C,$A8)) | O8: =IF(OR(M8="",N8=""),"",M8+N8) | P8: =IF(O8="","",M8/O8) | Q8: =IF(O8="","",N8/O8) | R8: =IF(SUMIFS('Monthly NSE Equity Options'!$L:$L,'Monthly NSE Equity Options'!$C:$C,$A8)=0,"",SUMIFS('Monthly NSE Equity Options'!$L:$L,'Monthly NSE Equity Options'!$C:$C,$A8)) | S8: =IF(SUMIFS('Monthly BSE Equity Options'!$L:$L,'Monthly BSE Equity Options'!$C:$C,$A8)=0,"",SUMIFS('Monthly BSE Equity Options'!$L:$L,'Monthly BSE Equity Options'!$C:$C,$A8)) | T8: =IF(OR(R8="",S8=""),"",R8+S8) | U8: =IF(T8="","",R8/T8) | V8: =IF(T8="","",S8/T8)
A9: Q3FY06 | B9: =IF(SUMIFS('Monthly NSE Equity Options'!$J:$J,'Monthly NSE Equity Options'!$C:$C,$A9)=0,"",SUMIFS('Monthly NSE Equity Options'!$J:$J,'Monthly NSE Equity Options'!$C:$C,$A9)) | C9: =IF(SUMIFS('Monthly BSE Equity Options'!$J:$J,'Monthly BSE Equity Options'!$C:$C,$A9)=0,"",SUMIFS('Monthly BSE Equity Options'!$J:$J,'Monthly BSE Equity Options'!$C:$C,$A9)) | D9: =IF(OR(B9="",C9=""),"",B9+C9) | E9: =IF(D9="","",B9/D9) | F9: =IF(D9="","",C9/D9) | G9: =IF(OR(B9="",B5=""),"",B9/B5-1) | H9: =IF(OR(C9="",C5=""),"",C9/C5-1) | I9: =IF(OR(D9="",D5=""),"",D9/D5-1) | J9: =IF(OR(B9="",B8=""),"",B9/B8-1) | K9: =IF(OR(C9="",C8=""),"",C9/C8-1) | L9: =IF(OR(D9="",D8=""),"",D9/D8-1) | M9: =IF(SUMIFS('Monthly NSE Equity Options'!$K:$K,'Monthly NSE Equity Options'!$C:$C,$A9)=0,"",SUMIFS('Monthly NSE Equity Options'!$K:$K,'Monthly NSE Equity Options'!$C:$C,$A9)) | N9: =IF(SUMIFS('Monthly BSE Equity Options'!$K:$K,'Monthly BSE Equity Options'!$C:$C,$A9)=0,"",SUMIFS('Monthly BSE Equity Options'!$K:$K,'Monthly BSE Equity Options'!$C:$C,$A9)) | O9: =IF(OR(M9="",N9=""),"",M9+N9) | P9: =IF(O9="","",M9/O9) | Q9: =IF(O9="","",N9/O9) | R9: =IF(SUMIFS('Monthly NSE Equity Options'!$L:$L,'Monthly NSE Equity Options'!$C:$C,$A9)=0,"",SUMIFS('Monthly NSE Equity Options'!$L:$L,'Monthly NSE Equity Options'!$C:$C,$A9)) | S9: =IF(SUMIFS('Monthly BSE Equity Options'!$L:$L,'Monthly BSE Equity Options'!$C:$C,$A9)=0,"",SUMIFS('Monthly BSE Equity Options'!$L:$L,'Monthly BSE Equity Options'!$C:$C,$A9)) | T9: =IF(OR(R9="",S9=""),"",R9+S9) | U9: =IF(T9="","",R9/T9) | V9: =IF(T9="","",S9/T9)
A10: Q4FY06 | B10: =IF(SUMIFS('Monthly NSE Equity Options'!$J:$J,'Monthly NSE Equity Options'!$C:$C,$A10)=0,"",SUMIFS('Monthly NSE Equity Options'!$J:$J,'Monthly NSE Equity Options'!$C:$C,$A10)) | C10: =IF(SUMIFS('Monthly BSE Equity Options'!$J:$J,'Monthly BSE Equity Options'!$C:$C,$A10)=0,"",SUMIFS('Monthly BSE Equity Options'!$J:$J,'Monthly BSE Equity Options'!$C:$C,$A10)) | D10: =IF(OR(B10="",C10=""),"",B10+C10) | E10: =IF(D10="","",B10/D10) | F10: =IF(D10="","",C10/D10) | G10: =IF(OR(B10="",B6=""),"",B10/B6-1) | H10: =IF(OR(C10="",C6=""),"",C10/C6-1) | I10: =IF(OR(D10="",D6=""),"",D10/D6-1) | J10: =IF(OR(B10="",B9=""),"",B10/B9-1) | K10: =IF(OR(C10="",C9=""),"",C10/C9-1) | L10: =IF(OR(D10="",D9=""),"",D10/D9-1) | M10: =IF(SUMIFS('Monthly NSE Equity Options'!$K:$K,'Monthly NSE Equity Options'!$C:$C,$A10)=0,"",SUMIFS('Monthly NSE Equity Options'!$K:$K,'Monthly NSE Equity Options'!$C:$C,$A10)) | N10: =IF(SUMIFS('Monthly BSE Equity Options'!$K:$K,'Monthly BSE Equity Options'!$C:$C,$A10)=0,"",SUMIFS('Monthly BSE Equity Options'!$K:$K,'Monthly BSE Equity Options'!$C:$C,$A10)) | O10: =IF(OR(M10="",N10=""),"",M10+N10) | P10: =IF(O10="","",M10/O10) | Q10: =IF(O10="","",N10/O10) | R10: =IF(SUMIFS('Monthly NSE Equity Options'!$L:$L,'Monthly NSE Equity Options'!$C:$C,$A10)=0,"",SUMIFS('Monthly NSE Equity Options'!$L:$L,'Monthly NSE Equity Options'!$C:$C,$A10)) | S10: =IF(SUMIFS('Monthly BSE Equity Options'!$L:$L,'Monthly BSE Equity Options'!$C:$C,$A10)=0,"",SUMIFS('Monthly BSE Equity Options'!$L:$L,'Monthly BSE Equity Options'!$C:$C,$A10)) | T10: =IF(OR(R10="",S10=""),"",R10+S10) | U10: =IF(T10="","",R10/T10) | V10: =IF(T10="","",S10/T10)
A11: Q1FY07 | B11: =IF(SUMIFS('Monthly NSE Equity Options'!$J:$J,'Monthly NSE Equity Options'!$C:$C,$A11)=0,"",SUMIFS('Monthly NSE Equity Options'!$J:$J,'Monthly NSE Equity Options'!$C:$C,$A11)) | C11: =IF(SUMIFS('Monthly BSE Equity Options'!$J:$J,'Monthly BSE Equity Options'!$C:$C,$A11)=0,"",SUMIFS('Monthly BSE Equity Options'!$J:$J,'Monthly BSE Equity Options'!$C:$C,$A11)) | D11: =IF(OR(B11="",C11=""),"",B11+C11) | E11: =IF(D11="","",B11/D11) | F11: =IF(D11="","",C11/D11) | G11: =IF(OR(B11="",B7=""),"",B11/B7-1) | H11: =IF(OR(C11="",C7=""),"",C11/C7-1) | I11: =IF(OR(D11="",D7=""),"",D11/D7-1) | J11: =IF(OR(B11="",B10=""),"",B11/B10-1) | K11: =IF(OR(C11="",C10=""),"",C11/C10-1) | L11: =IF(OR(D11="",D10=""),"",D11/D10-1) | M11: =IF(SUMIFS('Monthly NSE Equity Options'!$K:$K,'Monthly NSE Equity Options'!$C:$C,$A11)=0,"",SUMIFS('Monthly NSE Equity Options'!$K:$K,'Monthly NSE Equity Options'!$C:$C,$A11)) | N11: =IF(SUMIFS('Monthly BSE Equity Options'!$K:$K,'Monthly BSE Equity Options'!$C:$C,$A11)=0,"",SUMIFS('Monthly BSE Equity Options'!$K:$K,'Monthly BSE Equity Options'!$C:$C,$A11)) | O11: =IF(OR(M11="",N11=""),"",M11+N11) | P11: =IF(O11="","",M11/O11) | Q11: =IF(O11="","",N11/O11) | R11: =IF(SUMIFS('Monthly NSE Equity Options'!$L:$L,'Monthly NSE Equity Options'!$C:$C,$A11)=0,"",SUMIFS('Monthly NSE Equity Options'!$L:$L,'Monthly NSE Equity Options'!$C:$C,$A11)) | S11: =IF(SUMIFS('Monthly BSE Equity Options'!$L:$L,'Monthly BSE Equity Options'!$C:$C,$A11)=0,"",SUMIFS('Monthly BSE Equity Options'!$L:$L,'Monthly BSE Equity Options'!$C:$C,$A11)) | T11: =IF(OR(R11="",S11=""),"",R11+S11) | U11: =IF(T11="","",R11/T11) | V11: =IF(T11="","",S11/T11)
A12: Q2FY07 | B12: =IF(SUMIFS('Monthly NSE Equity Options'!$J:$J,'Monthly NSE Equity Options'!$C:$C,$A12)=0,"",SUMIFS('Monthly NSE Equity Options'!$J:$J,'Monthly NSE Equity Options'!$C:$C,$A12)) | C12: =IF(SUMIFS('Monthly BSE Equity Options'!$J:$J,'Monthly BSE Equity Options'!$C:$C,$A12)=0,"",SUMIFS('Monthly BSE Equity Options'!$J:$J,'Monthly BSE Equity Options'!$C:$C,$A12)) | D12: =IF(OR(B12="",C12=""),"",B12+C12) | E12: =IF(D12="","",B12/D12) | F12: =IF(D12="","",C12/D12) | G12: =IF(OR(B12="",B8=""),"",B12/B8-1) | H12: =IF(OR(C12="",C8=""),"",C12/C8-1) | I12: =IF(OR(D12="",D8=""),"",D12/D8-1) | J12: =IF(OR(B12="",B11=""),"",B12/B11-1) | K12: =IF(OR(C12="",C11=""),"",C12/C11-1) | L12: =IF(OR(D12="",D11=""),"",D12/D11-1) | M12: =IF(SUMIFS('Monthly NSE Equity Options'!$K:$K,'Monthly NSE Equity Options'!$C:$C,$A12)=0,"",SUMIFS('Monthly NSE Equity Options'!$K:$K,'Monthly NSE Equity Options'!$C:$C,$A12)) | N12: =IF(SUMIFS('Monthly BSE Equity Options'!$K:$K,'Monthly BSE Equity Options'!$C:$C,$A12)=0,"",SUMIFS('Monthly BSE Equity Options'!$K:$K,'Monthly BSE Equity Options'!$C:$C,$A12)) | O12: =IF(OR(M12="",N12=""),"",M12+N12) | P12: =IF(O12="","",M12/O12) | Q12: =IF(O12="","",N12/O12) | R12: =IF(SUMIFS('Monthly NSE Equity Options'!$L:$L,'Monthly NSE Equity Options'!$C:$C,$A12)=0,"",SUMIFS('Monthly NSE Equity Options'!$L:$L,'Monthly NSE Equity Options'!$C:$C,$A12)) | S12: =IF(SUMIFS('Monthly BSE Equity Options'!$L:$L,'Monthly BSE Equity Options'!$C:$C,$A12)=0,"",SUMIFS('Monthly BSE Equity Options'!$L:$L,'Monthly BSE Equity Options'!$C:$C,$A12)) | T12: =IF(OR(R12="",S12=""),"",R12+S12) | U12: =IF(T12="","",R12/T12) | V12: =IF(T12="","",S12/T12)
A13: Q3FY07 | B13: =IF(SUMIFS('Monthly NSE Equity Options'!$J:$J,'Monthly NSE Equity Options'!$C:$C,$A13)=0,"",SUMIFS('Monthly NSE Equity Options'!$J:$J,'Monthly NSE Equity Options'!$C:$C,$A13)) | C13: =IF(SUMIFS('Monthly BSE Equity Options'!$J:$J,'Monthly BSE Equity Options'!$C:$C,$A13)=0,"",SUMIFS('Monthly BSE Equity Options'!$J:$J,'Monthly BSE Equity Options'!$C:$C,$A13)) | D13: =IF(OR(B13="",C13=""),"",B13+C13) | E13: =IF(D13="","",B13/D13) | F13: =IF(D13="","",C13/D13) | G13: =IF(OR(B13="",B9=""),"",B13/B9-1) | H13: =IF(OR(C13="",C9=""),"",C13/C9-1) | I13: =IF(OR(D13="",D9=""),"",D13/D9-1) | J13: =IF(OR(B13="",B12=""),"",B13/B12-1) | K13: =IF(OR(C13="",C12=""),"",C13/C12-1) | L13: =IF(OR(D13="",D12=""),"",D13/D12-1) | M13: =IF(SUMIFS('Monthly NSE Equity Options'!$K:$K,'Monthly NSE Equity Options'!$C:$C,$A13)=0,"",SUMIFS('Monthly NSE Equity Options'!$K:$K,'Monthly NSE Equity Options'!$C:$C,$A13)) | N13: =IF(SUMIFS('Monthly BSE Equity Options'!$K:$K,'Monthly BSE Equity Options'!$C:$C,$A13)=0,"",SUMIFS('Monthly BSE Equity Options'!$K:$K,'Monthly BSE Equity Options'!$C:$C,$A13)) | O13: =IF(OR(M13="",N13=""),"",M13+N13) | P13: =IF(O13="","",M13/O13) | Q13: =IF(O13="","",N13/O13) | R13: =IF(SUMIFS('Monthly NSE Equity Options'!$L:$L,'Monthly NSE Equity Options'!$C:$C,$A13)=0,"",SUMIFS('Monthly NSE Equity Options'!$L:$L,'Monthly NSE Equity Options'!$C:$C,$A13)) | S13: =IF(SUMIFS('Monthly BSE Equity Options'!$L:$L,'Monthly BSE Equity Options'!$C:$C,$A13)=0,"",SUMIFS('Monthly BSE Equity Options'!$L:$L,'Monthly BSE Equity Options'!$C:$C,$A13)) | T13: =IF(OR(R13="",S13=""),"",R13+S13) | U13: =IF(T13="","",R13/T13) | V13: =IF(T13="","",S13/T13)
