Workbook

Sheet Quality Check
A1: Quality Check — Exchanges Monthly Weekly Expiry (MASTER FILE)
A3: Exchange | B3: Sheet | C3: Data From | D3: Data To | E3: Data Rows | F3: Premium Turnover (INR Bn) | I3: Data Sources
A4: NSE | B4: NSE - NIFTY Index Options | C4: ='NSE - NIFTY Index Options'!A2 | D4: =LOOKUP(2,1/('NSE - NIFTY Index Options'!$A$2:$A$100000<>""),'NSE - NIFTY Index Options'!$A$2:$A$100000) | E4: =COUNTA('NSE - NIFTY Index Options'!A:A)-1 | F4: =SUM('NSE - NIFTY Index Options'!M:M) | I4: NSE: F&O contract-wise archives (Security-wise Price Volume data) - https://www.nseindia.com/report-detail/fo_eq_security (API: nseindia.com/api/historicalOR/foCPV, instrumentType=OPTIDX; NIFTY, BANKNIFTY, FINNIFTY, MIDCPNIFTY, NIFTYNXT50)
A5: NSE | B5: NSE - Other Index Options | C5: ='NSE - Other Index Options'!A2 | D5: =LOOKUP(2,1/('NSE - Other Index Options'!$A$2:$A$100000<>""),'NSE - Other Index Options'!$A$2:$A$100000) | E5: =COUNTA('NSE - Other Index Options'!A:A)-1 | F5: =SUM('NSE - Other Index Options'!M:M) | I5: BSE: Derivatives historical archives - https://www.bseindia.com/markets/derivatives/derireports/derihistorical (API: api.bseindia.com/BseIndiaAPI, Product_Type=IO; SENSEX + other index options)
A6: BSE | B6: BSE - SENSEX Index Options | C6: ='BSE - SENSEX Index Options'!A2 | D6: =LOOKUP(2,1/('BSE - SENSEX Index Options'!$A$2:$A$100000<>""),'BSE - SENSEX Index Options'!$A$2:$A$100000) | E6: =COUNTA('BSE - SENSEX Index Options'!A:A)-1 | F6: =SUM('BSE - SENSEX Index Options'!M:M) | I6: Units: raw API turnover in INR lakh, converted to INR Bn (divided by 10,000). Contracts: NSE = traded qty / market lot; BSE = as reported.
A7: BSE | B7: BSE - Other Index Options | C7: ='BSE - Other Index Options'!A2 | D7: =LOOKUP(2,1/('BSE - Other Index Options'!$A$2:$A$100000<>""),'BSE - Other Index Options'!$A$2:$A$100000) | E7: =COUNTA('BSE - Other Index Options'!A:A)-1 | F7: =SUM('BSE - Other Index Options'!M:M) | I7: Validation: BSE daily aggregates reconciled against BSE consolidated product-wise report (0 mismatches, tolerance 0.5%); NSE verified internally (contracts x lot x underlying = notional).
I8: Extraction scripts: nse_options_expiry.py / bse_options_expiry.py in the project's Python Files folder.
A9: NSE data updated through: | B9: =IF(D4=D5,D4,"MISMATCH between NSE sheets")
A10: BSE data updated through: | B10: =IF(D6=D7,D6,"MISMATCH between BSE sheets")
A11: NSE & BSE end dates aligned? | B11: =IF(B9=B10,"YES","NO — update the lagging exchange")
A12: Master file created: | B12: 46210
A13: Last data refresh: | B13: 46243
A14: Monthly Totals (live — populates as data is updated)
A15: Month | B15: NSE - Number of Contracts | C15: NSE - Notional Turnover (INR Bn) | D15: NSE - Premium Turnover (INR Bn) | E15: BSE - Number of Contracts | F15: BSE - Notional Turnover (INR Bn) | G15: BSE - Premium Turnover (INR Bn)
A16: 45901 | B16: =IF(SUMIFS('NSE - NIFTY Index Options'!$K:$K,'NSE - NIFTY Index Options'!$D:$D,$A16)+SUMIFS('NSE - Other Index Options'!$K:$K,'NSE - Other Index Options'!$D:$D,$A16)=0,"",SUMIFS('NSE - NIFTY Index Options'!$K:$K,'NSE - NIFTY Index Options'!$D:$D,$A16)+SUMIFS('NSE - Other Index Options'!$K:$K,'NSE - Other Index Options'!$D:$D,$A16)) | C16: =IF(SUMIFS('NSE - NIFTY Index Options'!$L:$L,'NSE - NIFTY Index Options'!$D:$D,$A16)+SUMIFS('NSE - Other Index Options'!$L:$L,'NSE - Other Index Options'!$D:$D,$A16)=0,"",SUMIFS('NSE - NIFTY Index Options'!$L:$L,'NSE - NIFTY Index Options'!$D:$D,$A16)+SUMIFS('NSE - Other Index Options'!$L:$L,'NSE - Other Index Options'!$D:$D,$A16)) | D16: =IF(SUMIFS('NSE - NIFTY Index Options'!$M:$M,'NSE - NIFTY Index Options'!$D:$D,$A16)+SUMIFS('NSE - Other Index Options'!$M:$M,'NSE - Other Index Options'!$D:$D,$A16)=0,"",SUMIFS('NSE - NIFTY Index Options'!$M:$M,'NSE - NIFTY Index Options'!$D:$D,$A16)+SUMIFS('NSE - Other Index Options'!$M:$M,'NSE - Other Index Options'!$D:$D,$A16)) | E16: =IF(SUMIFS('BSE - SENSEX Index Options'!$K:$K,'BSE - SENSEX Index Options'!$D:$D,$A16)+SUMIFS('BSE - Other Index Options'!$K:$K,'BSE - Other Index Options'!$D:$D,$A16)=0,"",SUMIFS('BSE - SENSEX Index Options'!$K:$K,'BSE - SENSEX Index Options'!$D:$D,$A16)+SUMIFS('BSE - Other Index Options'!$K:$K,'BSE - Other Index Options'!$D:$D,$A16)) | F16: =IF(SUMIFS('BSE - SENSEX Index Options'!$L:$L,'BSE - SENSEX Index Options'!$D:$D,$A16)+SUMIFS('BSE - Other Index Options'!$L:$L,'BSE - Other Index Options'!$D:$D,$A16)=0,"",SUMIFS('BSE - SENSEX Index Options'!$L:$L,'BSE - SENSEX Index Options'!$D:$D,$A16)+SUMIFS('BSE - Other Index Options'!$L:$L,'BSE - Other Index Options'!$D:$D,$A16)) | G16: =IF(SUMIFS('BSE - SENSEX Index Options'!$M:$M,'BSE - SENSEX Index Options'!$D:$D,$A16)+SUMIFS('BSE - Other Index Options'!$M:$M,'BSE - Other Index Options'!$D:$D,$A16)=0,"",SUMIFS('BSE - SENSEX Index Options'!$M:$M,'BSE - SENSEX Index Options'!$D:$D,$A16)+SUMIFS('BSE - Other Index Options'!$M:$M,'BSE - Other Index Options'!$D:$D,$A16))
A17: 45931 | B17: =IF(SUMIFS('NSE - NIFTY Index Options'!$K:$K,'NSE - NIFTY Index Options'!$D:$D,$A17)+SUMIFS('NSE - Other Index Options'!$K:$K,'NSE - Other Index Options'!$D:$D,$A17)=0,"",SUMIFS('NSE - NIFTY Index Options'!$K:$K,'NSE - NIFTY Index Options'!$D:$D,$A17)+SUMIFS('NSE - Other Index Options'!$K:$K,'NSE - Other Index Options'!$D:$D,$A17)) | C17: =IF(SUMIFS('NSE - NIFTY Index Options'!$L:$L,'NSE - NIFTY Index Options'!$D:$D,$A17)+SUMIFS('NSE - Other Index Options'!$L:$L,'NSE - Other Index Options'!$D:$D,$A17)=0,"",SUMIFS('NSE - NIFTY Index Options'!$L:$L,'NSE - NIFTY Index Options'!$D:$D,$A17)+SUMIFS('NSE - Other Index Options'!$L:$L,'NSE - Other Index Options'!$D:$D,$A17)) | D17: =IF(SUMIFS('NSE - NIFTY Index Options'!$M:$M,'NSE - NIFTY Index Options'!$D:$D,$A17)+SUMIFS('NSE - Other Index Options'!$M:$M,'NSE - Other Index Options'!$D:$D,$A17)=0,"",SUMIFS('NSE - NIFTY Index Options'!$M:$M,'NSE - NIFTY Index Options'!$D:$D,$A17)+SUMIFS('NSE - Other Index Options'!$M:$M,'NSE - Other Index Options'!$D:$D,$A17)) | E17: =IF(SUMIFS('BSE - SENSEX Index Options'!$K:$K,'BSE - SENSEX Index Options'!$D:$D,$A17)+SUMIFS('BSE - Other Index Options'!$K:$K,'BSE - Other Index Options'!$D:$D,$A17)=0,"",SUMIFS('BSE - SENSEX Index Options'!$K:$K,'BSE - SENSEX Index Options'!$D:$D,$A17)+SUMIFS('BSE - Other Index Options'!$K:$K,'BSE - Other Index Options'!$D:$D,$A17)) | F17: =IF(SUMIFS('BSE - SENSEX Index Options'!$L:$L,'BSE - SENSEX Index Options'!$D:$D,$A17)+SUMIFS('BSE - Other Index Options'!$L:$L,'BSE - Other Index Options'!$D:$D,$A17)=0,"",SUMIFS('BSE - SENSEX Index Options'!$L:$L,'BSE - SENSEX Index Options'!$D:$D,$A17)+SUMIFS('BSE - Other Index Options'!$L:$L,'BSE - Other Index Options'!$D:$D,$A17)) | G17: =IF(SUMIFS('BSE - SENSEX Index Options'!$M:$M,'BSE - SENSEX Index Options'!$D:$D,$A17)+SUMIFS('BSE - Other Index Options'!$M:$M,'BSE - Other Index Options'!$D:$D,$A17)=0,"",SUMIFS('BSE - SENSEX Index Options'!$M:$M,'BSE - SENSEX Index Options'!$D:$D,$A17)+SUMIFS('BSE - Other Index Options'!$M:$M,'BSE - Other Index Options'!$D:$D,$A17))
A18: 45962 | B18: =IF(SUMIFS('NSE - NIFTY Index Options'!$K:$K,'NSE - NIFTY Index Options'!$D:$D,$A18)+SUMIFS('NSE - Other Index Options'!$K:$K,'NSE - Other Index Options'!$D:$D,$A18)=0,"",SUMIFS('NSE - NIFTY Index Options'!$K:$K,'NSE - NIFTY Index Options'!$D:$D,$A18)+SUMIFS('NSE - Other Index Options'!$K:$K,'NSE - Other Index Options'!$D:$D,$A18)) | C18: =IF(SUMIFS('NSE - NIFTY Index Options'!$L:$L,'NSE - NIFTY Index Options'!$D:$D,$A18)+SUMIFS('NSE - Other Index Options'!$L:$L,'NSE - Other Index Options'!$D:$D,$A18)=0,"",SUMIFS('NSE - NIFTY Index Options'!$L:$L,'NSE - NIFTY Index Options'!$D:$D,$A18)+SUMIFS('NSE - Other Index Options'!$L:$L,'NSE - Other Index Options'!$D:$D,$A18)) | D18: =IF(SUMIFS('NSE - NIFTY Index Options'!$M:$M,'NSE - NIFTY Index Options'!$D:$D,$A18)+SUMIFS('NSE - Other Index Options'!$M:$M,'NSE - Other Index Options'!$D:$D,$A18)=0,"",SUMIFS('NSE - NIFTY Index Options'!$M:$M,'NSE - NIFTY Index Options'!$D:$D,$A18)+SUMIFS('NSE - Other Index Options'!$M:$M,'NSE - Other Index Options'!$D:$D,$A18)) | E18: =IF(SUMIFS('BSE - SENSEX Index Options'!$K:$K,'BSE - SENSEX Index Options'!$D:$D,$A18)+SUMIFS('BSE - Other Index Options'!$K:$K,'BSE - Other Index Options'!$D:$D,$A18)=0,"",SUMIFS('BSE - SENSEX Index Options'!$K:$K,'BSE - SENSEX Index Options'!$D:$D,$A18)+SUMIFS('BSE - Other Index Options'!$K:$K,'BSE - Other Index Options'!$D:$D,$A18)) | F18: =IF(SUMIFS('BSE - SENSEX Index Options'!$L:$L,'BSE - SENSEX Index Options'!$D:$D,$A18)+SUMIFS('BSE - Other Index Options'!$L:$L,'BSE - Other Index Options'!$D:$D,$A18)=0,"",SUMIFS('BSE - SENSEX Index Options'!$L:$L,'BSE - SENSEX Index Options'!$D:$D,$A18)+SUMIFS('BSE - Other Index Options'!$L:$L,'BSE - Other Index Options'!$D:$D,$A18)) | G18: =IF(SUMIFS('BSE - SENSEX Index Options'!$M:$M,'BSE - SENSEX Index Options'!$D:$D,$A18)+SUMIFS('BSE - Other Index Options'!$M:$M,'BSE - Other Index Options'!$D:$D,$A18)=0,"",SUMIFS('BSE - SENSEX Index Options'!$M:$M,'BSE - SENSEX Index Options'!$D:$D,$A18)+SUMIFS('BSE - Other Index Options'!$M:$M,'BSE - Other Index Options'!$D:$D,$A18))
A19: 45992 | B19: =IF(SUMIFS('NSE - NIFTY Index Options'!$K:$K,'NSE - NIFTY Index Options'!$D:$D,$A19)+SUMIFS('NSE - Other Index Options'!$K:$K,'NSE - Other Index Options'!$D:$D,$A19)=0,"",SUMIFS('NSE - NIFTY Index Options'!$K:$K,'NSE - NIFTY Index Options'!$D:$D,$A19)+SUMIFS('NSE - Other Index Options'!$K:$K,'NSE - Other Index Options'!$D:$D,$A19)) | C19: =IF(SUMIFS('NSE - NIFTY Index Options'!$L:$L,'NSE - NIFTY Index Options'!$D:$D,$A19)+SUMIFS('NSE - Other Index Options'!$L:$L,'NSE - Other Index Options'!$D:$D,$A19)=0,"",SUMIFS('NSE - NIFTY Index Options'!$L:$L,'NSE - NIFTY Index Options'!$D:$D,$A19)+SUMIFS('NSE - Other Index Options'!$L:$L,'NSE - Other Index Options'!$D:$D,$A19)) | D19: =IF(SUMIFS('NSE - NIFTY Index Options'!$M:$M,'NSE - NIFTY Index Options'!$D:$D,$A19)+SUMIFS('NSE - Other Index Options'!$M:$M,'NSE - Other Index Options'!$D:$D,$A19)=0,"",SUMIFS('NSE - NIFTY Index Options'!$M:$M,'NSE - NIFTY Index Options'!$D:$D,$A19)+SUMIFS('NSE - Other Index Options'!$M:$M,'NSE - Other Index Options'!$D:$D,$A19)) | E19: =IF(SUMIFS('BSE - SENSEX Index Options'!$K:$K,'BSE - SENSEX Index Options'!$D:$D,$A19)+SUMIFS('BSE - Other Index Options'!$K:$K,'BSE - Other Index Options'!$D:$D,$A19)=0,"",SUMIFS('BSE - SENSEX Index Options'!$K:$K,'BSE - SENSEX Index Options'!$D:$D,$A19)+SUMIFS('BSE - Other Index Options'!$K:$K,'BSE - Other Index Options'!$D:$D,$A19)) | F19: =IF(SUMIFS('BSE - SENSEX Index Options'!$L:$L,'BSE - SENSEX Index Options'!$D:$D,$A19)+SUMIFS('BSE - Other Index Options'!$L:$L,'BSE - Other Index Options'!$D:$D,$A19)=0,"",SUMIFS('BSE - SENSEX Index Options'!$L:$L,'BSE - SENSEX Index Options'!$D:$D,$A19)+SUMIFS('BSE - Other Index Options'!$L:$L,'BSE - Other Index Options'!$D:$D,$A19)) | G19: =IF(SUMIFS('BSE - SENSEX Index Options'!$M:$M,'BSE - SENSEX Index Options'!$D:$D,$A19)+SUMIFS('BSE - Other Index Options'!$M:$M,'BSE - Other Index Options'!$D:$D,$A19)=0,"",SUMIFS('BSE - SENSEX Index Options'!$M:$M,'BSE - SENSEX Index Options'!$D:$D,$A19)+SUMIFS('BSE - Other Index Options'!$M:$M,'BSE - Other Index Options'!$D:$D,$A19))
A20: 46023 | B20: =IF(SUMIFS('NSE - NIFTY Index Options'!$K:$K,'NSE - NIFTY Index Options'!$D:$D,$A20)+SUMIFS('NSE - Other Index Options'!$K:$K,'NSE - Other Index Options'!$D:$D,$A20)=0,"",SUMIFS('NSE - NIFTY Index Options'!$K:$K,'NSE - NIFTY Index Options'!$D:$D,$A20)+SUMIFS('NSE - Other Index Options'!$K:$K,'NSE - Other Index Options'!$D:$D,$A20)) | C20: =IF(SUMIFS('NSE - NIFTY Index Options'!$L:$L,'NSE - NIFTY Index Options'!$D:$D,$A20)+SUMIFS('NSE - Other Index Options'!$L:$L,'NSE - Other Index Options'!$D:$D,$A20)=0,"",SUMIFS('NSE - NIFTY Index Options'!$L:$L,'NSE - NIFTY Index Options'!$D:$D,$A20)+SUMIFS('NSE - Other Index Options'!$L:$L,'NSE - Other Index Options'!$D:$D,$A20)) | D20: =IF(SUMIFS('NSE - NIFTY Index Options'!$M:$M,'NSE - NIFTY Index Options'!$D:$D,$A20)+SUMIFS('NSE - Other Index Options'!$M:$M,'NSE - Other Index Options'!$D:$D,$A20)=0,"",SUMIFS('NSE - NIFTY Index Options'!$M:$M,'NSE - NIFTY Index Options'!$D:$D,$A20)+SUMIFS('NSE - Other Index Options'!$M:$M,'NSE - Other Index Options'!$D:$D,$A20)) | E20: =IF(SUMIFS('BSE - SENSEX Index Options'!$K:$K,'BSE - SENSEX Index Options'!$D:$D,$A20)+SUMIFS('BSE - Other Index Options'!$K:$K,'BSE - Other Index Options'!$D:$D,$A20)=0,"",SUMIFS('BSE - SENSEX Index Options'!$K:$K,'BSE - SENSEX Index Options'!$D:$D,$A20)+SUMIFS('BSE - Other Index Options'!$K:$K,'BSE - Other Index Options'!$D:$D,$A20)) | F20: =IF(SUMIFS('BSE - SENSEX Index Options'!$L:$L,'BSE - SENSEX Index Options'!$D:$D,$A20)+SUMIFS('BSE - Other Index Options'!$L:$L,'BSE - Other Index Options'!$D:$D,$A20)=0,"",SUMIFS('BSE - SENSEX Index Options'!$L:$L,'BSE - SENSEX Index Options'!$D:$D,$A20)+SUMIFS('BSE - Other Index Options'!$L:$L,'BSE - Other Index Options'!$D:$D,$A20)) | G20: =IF(SUMIFS('BSE - SENSEX Index Options'!$M:$M,'BSE - SENSEX Index Options'!$D:$D,$A20)+SUMIFS('BSE - Other Index Options'!$M:$M,'BSE - Other Index Options'!$D:$D,$A20)=0,"",SUMIFS('BSE - SENSEX Index Options'!$M:$M,'BSE - SENSEX Index Options'!$D:$D,$A20)+SUMIFS('BSE - Other Index Options'!$M:$M,'BSE - Other Index Options'!$D:$D,$A20))
A21: 46054 | B21: =IF(SUMIFS('NSE - NIFTY Index Options'!$K:$K,'NSE - NIFTY Index Options'!$D:$D,$A21)+SUMIFS('NSE - Other Index Options'!$K:$K,'NSE - Other Index Options'!$D:$D,$A21)=0,"",SUMIFS('NSE - NIFTY Index Options'!$K:$K,'NSE - NIFTY Index Options'!$D:$D,$A21)+SUMIFS('NSE - Other Index Options'!$K:$K,'NSE - Other Index Options'!$D:$D,$A21)) | C21: =IF(SUMIFS('NSE - NIFTY Index Options'!$L:$L,'NSE - NIFTY Index Options'!$D:$D,$A21)+SUMIFS('NSE - Other Index Options'!$L:$L,'NSE - Other Index Options'!$D:$D,$A21)=0,"",SUMIFS('NSE - NIFTY Index Options'!$L:$L,'NSE - NIFTY Index Options'!$D:$D,$A21)+SUMIFS('NSE - Other Index Options'!$L:$L,'NSE - Other Index Options'!$D:$D,$A21)) | D21: =IF(SUMIFS('NSE - NIFTY Index Options'!$M:$M,'NSE - NIFTY Index Options'!$D:$D,$A21)+SUMIFS('NSE - Other Index Options'!$M:$M,'NSE - Other Index Options'!$D:$D,$A21)=0,"",SUMIFS('NSE - NIFTY Index Options'!$M:$M,'NSE - NIFTY Index Options'!$D:$D,$A21)+SUMIFS('NSE - Other Index Options'!$M:$M,'NSE - Other Index Options'!$D:$D,$A21)) | E21: =IF(SUMIFS('BSE - SENSEX Index Options'!$K:$K,'BSE - SENSEX Index Options'!$D:$D,$A21)+SUMIFS('BSE - Other Index Options'!$K:$K,'BSE - Other Index Options'!$D:$D,$A21)=0,"",SUMIFS('BSE - SENSEX Index Options'!$K:$K,'BSE - SENSEX Index Options'!$D:$D,$A21)+SUMIFS('BSE - Other Index Options'!$K:$K,'BSE - Other Index Options'!$D:$D,$A21)) | F21: =IF(SUMIFS('BSE - SENSEX Index Options'!$L:$L,'BSE - SENSEX Index Options'!$D:$D,$A21)+SUMIFS('BSE - Other Index Options'!$L:$L,'BSE - Other Index Options'!$D:$D,$A21)=0,"",SUMIFS('BSE - SENSEX Index Options'!$L:$L,'BSE - SENSEX Index Options'!$D:$D,$A21)+SUMIFS('BSE - Other Index Options'!$L:$L,'BSE - Other Index Options'!$D:$D,$A21)) | G21: =IF(SUMIFS('BSE - SENSEX Index Options'!$M:$M,'BSE - SENSEX Index Options'!$D:$D,$A21)+SUMIFS('BSE - Other Index Options'!$M:$M,'BSE - Other Index Options'!$D:$D,$A21)=0,"",SUMIFS('BSE - SENSEX Index Options'!$M:$M,'BSE - SENSEX Index Options'!$D:$D,$A21)+SUMIFS('BSE - Other Index Options'!$M:$M,'BSE - Other Index Options'!$D:$D,$A21))
A22: 46082 | B22: =IF(SUMIFS('NSE - NIFTY Index Options'!$K:$K,'NSE - NIFTY Index Options'!$D:$D,$A22)+SUMIFS('NSE - Other Index Options'!$K:$K,'NSE - Other Index Options'!$D:$D,$A22)=0,"",SUMIFS('NSE - NIFTY Index Options'!$K:$K,'NSE - NIFTY Index Options'!$D:$D,$A22)+SUMIFS('NSE - Other Index Options'!$K:$K,'NSE - Other Index Options'!$D:$D,$A22)) | C22: =IF(SUMIFS('NSE - NIFTY Index Options'!$L:$L,'NSE - NIFTY Index Options'!$D:$D,$A22)+SUMIFS('NSE - Other Index Options'!$L:$L,'NSE - Other Index Options'!$D:$D,$A22)=0,"",SUMIFS('NSE - NIFTY Index Options'!$L:$L,'NSE - NIFTY Index Options'!$D:$D,$A22)+SUMIFS('NSE - Other Index Options'!$L:$L,'NSE - Other Index Options'!$D:$D,$A22)) | D22: =IF(SUMIFS('NSE - NIFTY Index Options'!$M:$M,'NSE - NIFTY Index Options'!$D:$D,$A22)+SUMIFS('NSE - Other Index Options'!$M:$M,'NSE - Other Index Options'!$D:$D,$A22)=0,"",SUMIFS('NSE - NIFTY Index Options'!$M:$M,'NSE - NIFTY Index Options'!$D:$D,$A22)+SUMIFS('NSE - Other Index Options'!$M:$M,'NSE - Other Index Options'!$D:$D,$A22)) | E22: =IF(SUMIFS('BSE - SENSEX Index Options'!$K:$K,'BSE - SENSEX Index Options'!$D:$D,$A22)+SUMIFS('BSE - Other Index Options'!$K:$K,'BSE - Other Index Options'!$D:$D,$A22)=0,"",SUMIFS('BSE - SENSEX Index Options'!$K:$K,'BSE - SENSEX Index Options'!$D:$D,$A22)+SUMIFS('BSE - Other Index Options'!$K:$K,'BSE - Other Index Options'!$D:$D,$A22)) | F22: =IF(SUMIFS('BSE - SENSEX Index Options'!$L:$L,'BSE - SENSEX Index Options'!$D:$D,$A22)+SUMIFS('BSE - Other Index Options'!$L:$L,'BSE - Other Index Options'!$D:$D,$A22)=0,"",SUMIFS('BSE - SENSEX Index Options'!$L:$L,'BSE - SENSEX Index Options'!$D:$D,$A22)+SUMIFS('BSE - Other Index Options'!$L:$L,'BSE - Other Index Options'!$D:$D,$A22)) | G22: =IF(SUMIFS('BSE - SENSEX Index Options'!$M:$M,'BSE - SENSEX Index Options'!$D:$D,$A22)+SUMIFS('BSE - Other Index Options'!$M:$M,'BSE - Other Index Options'!$D:$D,$A22)=0,"",SUMIFS('BSE - SENSEX Index Options'!$M:$M,'BSE - SENSEX Index Options'!$D:$D,$A22)+SUMIFS('BSE - Other Index Options'!$M:$M,'BSE - Other Index Options'!$D:$D,$A22))
A23: 46113 | B23: =IF(SUMIFS('NSE - NIFTY Index Options'!$K:$K,'NSE - NIFTY Index Options'!$D:$D,$A23)+SUMIFS('NSE - Other Index Options'!$K:$K,'NSE - Other Index Options'!$D:$D,$A23)=0,"",SUMIFS('NSE - NIFTY Index Options'!$K:$K,'NSE - NIFTY Index Options'!$D:$D,$A23)+SUMIFS('NSE - Other Index Options'!$K:$K,'NSE - Other Index Options'!$D:$D,$A23)) | C23: =IF(SUMIFS('NSE - NIFTY Index Options'!$L:$L,'NSE - NIFTY Index Options'!$D:$D,$A23)+SUMIFS('NSE - Other Index Options'!$L:$L,'NSE - Other Index Options'!$D:$D,$A23)=0,"",SUMIFS('NSE - NIFTY Index Options'!$L:$L,'NSE - NIFTY Index Options'!$D:$D,$A23)+SUMIFS('NSE - Other Index Options'!$L:$L,'NSE - Other Index Options'!$D:$D,$A23)) | D23: =IF(SUMIFS('NSE - NIFTY Index Options'!$M:$M,'NSE - NIFTY Index Options'!$D:$D,$A23)+SUMIFS('NSE - Other Index Options'!$M:$M,'NSE - Other Index Options'!$D:$D,$A23)=0,"",SUMIFS('NSE - NIFTY Index Options'!$M:$M,'NSE - NIFTY Index Options'!$D:$D,$A23)+SUMIFS('NSE - Other Index Options'!$M:$M,'NSE - Other Index Options'!$D:$D,$A23)) | E23: =IF(SUMIFS('BSE - SENSEX Index Options'!$K:$K,'BSE - SENSEX Index Options'!$D:$D,$A23)+SUMIFS('BSE - Other Index Options'!$K:$K,'BSE - Other Index Options'!$D:$D,$A23)=0,"",SUMIFS('BSE - SENSEX Index Options'!$K:$K,'BSE - SENSEX Index Options'!$D:$D,$A23)+SUMIFS('BSE - Other Index Options'!$K:$K,'BSE - Other Index Options'!$D:$D,$A23)) | F23: =IF(SUMIFS('BSE - SENSEX Index Options'!$L:$L,'BSE - SENSEX Index Options'!$D:$D,$A23)+SUMIFS('BSE - Other Index Options'!$L:$L,'BSE - Other Index Options'!$D:$D,$A23)=0,"",SUMIFS('BSE - SENSEX Index Options'!$L:$L,'BSE - SENSEX Index Options'!$D:$D,$A23)+SUMIFS('BSE - Other Index Options'!$L:$L,'BSE - Other Index Options'!$D:$D,$A23)) | G23: =IF(SUMIFS('BSE - SENSEX Index Options'!$M:$M,'BSE - SENSEX Index Options'!$D:$D,$A23)+SUMIFS('BSE - Other Index Options'!$M:$M,'BSE - Other Index Options'!$D:$D,$A23)=0,"",SUMIFS('BSE - SENSEX Index Options'!$M:$M,'BSE - SENSEX Index Options'!$D:$D,$A23)+SUMIFS('BSE - Other Index Options'!$M:$M,'BSE - Other Index Options'!$D:$D,$A23))
A24: 46143 | B24: =IF(SUMIFS('NSE - NIFTY Index Options'!$K:$K,'NSE - NIFTY Index Options'!$D:$D,$A24)+SUMIFS('NSE - Other Index Options'!$K:$K,'NSE - Other Index Options'!$D:$D,$A24)=0,"",SUMIFS('NSE - NIFTY Index Options'!$K:$K,'NSE - NIFTY Index Options'!$D:$D,$A24)+SUMIFS('NSE - Other Index Options'!$K:$K,'NSE - Other Index Options'!$D:$D,$A24)) | C24: =IF(SUMIFS('NSE - NIFTY Index Options'!$L:$L,'NSE - NIFTY Index Options'!$D:$D,$A24)+SUMIFS('NSE - Other Index Options'!$L:$L,'NSE - Other Index Options'!$D:$D,$A24)=0,"",SUMIFS('NSE - NIFTY Index Options'!$L:$L,'NSE - NIFTY Index Options'!$D:$D,$A24)+SUMIFS('NSE - Other Index Options'!$L:$L,'NSE - Other Index Options'!$D:$D,$A24)) | D24: =IF(SUMIFS('NSE - NIFTY Index Options'!$M:$M,'NSE - NIFTY Index Options'!$D:$D,$A24)+SUMIFS('NSE - Other Index Options'!$M:$M,'NSE - Other Index Options'!$D:$D,$A24)=0,"",SUMIFS('NSE - NIFTY Index Options'!$M:$M,'NSE - NIFTY Index Options'!$D:$D,$A24)+SUMIFS('NSE - Other Index Options'!$M:$M,'NSE - Other Index Options'!$D:$D,$A24)) | E24: =IF(SUMIFS('BSE - SENSEX Index Options'!$K:$K,'BSE - SENSEX Index Options'!$D:$D,$A24)+SUMIFS('BSE - Other Index Options'!$K:$K,'BSE - Other Index Options'!$D:$D,$A24)=0,"",SUMIFS('BSE - SENSEX Index Options'!$K:$K,'BSE - SENSEX Index Options'!$D:$D,$A24)+SUMIFS('BSE - Other Index Options'!$K:$K,'BSE - Other Index Options'!$D:$D,$A24)) | F24: =IF(SUMIFS('BSE - SENSEX Index Options'!$L:$L,'BSE - SENSEX Index Options'!$D:$D,$A24)+SUMIFS('BSE - Other Index Options'!$L:$L,'BSE - Other Index Options'!$D:$D,$A24)=0,"",SUMIFS('BSE - SENSEX Index Options'!$L:$L,'BSE - SENSEX Index Options'!$D:$D,$A24)+SUMIFS('BSE - Other Index Options'!$L:$L,'BSE - Other Index Options'!$D:$D,$A24)) | G24: =IF(SUMIFS('BSE - SENSEX Index Options'!$M:$M,'BSE - SENSEX Index Options'!$D:$D,$A24)+SUMIFS('BSE - Other Index Options'!$M:$M,'BSE - Other Index Options'!$D:$D,$A24)=0,"",SUMIFS('BSE - SENSEX Index Options'!$M:$M,'BSE - SENSEX Index Options'!$D:$D,$A24)+SUMIFS('BSE - Other Index Options'!$M:$M,'BSE - Other Index Options'!$D:$D,$A24))
A25: 46174 | B25: =IF(SUMIFS('NSE - NIFTY Index Options'!$K:$K,'NSE - NIFTY Index Options'!$D:$D,$A25)+SUMIFS('NSE - Other Index Options'!$K:$K,'NSE - Other Index Options'!$D:$D,$A25)=0,"",SUMIFS('NSE - NIFTY Index Options'!$K:$K,'NSE - NIFTY Index Options'!$D:$D,$A25)+SUMIFS('NSE - Other Index Options'!$K:$K,'NSE - Other Index Options'!$D:$D,$A25)) | C25: =IF(SUMIFS('NSE - NIFTY Index Options'!$L:$L,'NSE - NIFTY Index Options'!$D:$D,$A25)+SUMIFS('NSE - Other Index Options'!$L:$L,'NSE - Other Index Options'!$D:$D,$A25)=0,"",SUMIFS('NSE - NIFTY Index Options'!$L:$L,'NSE - NIFTY Index Options'!$D:$D,$A25)+SUMIFS('NSE - Other Index Options'!$L:$L,'NSE - Other Index Options'!$D:$D,$A25)) | D25: =IF(SUMIFS('NSE - NIFTY Index Options'!$M:$M,'NSE - NIFTY Index Options'!$D:$D,$A25)+SUMIFS('NSE - Other Index Options'!$M:$M,'NSE - Other Index Options'!$D:$D,$A25)=0,"",SUMIFS('NSE - NIFTY Index Options'!$M:$M,'NSE - NIFTY Index Options'!$D:$D,$A25)+SUMIFS('NSE - Other Index Options'!$M:$M,'NSE - Other Index Options'!$D:$D,$A25)) | E25: =IF(SUMIFS('BSE - SENSEX Index Options'!$K:$K,'BSE - SENSEX Index Options'!$D:$D,$A25)+SUMIFS('BSE - Other Index Options'!$K:$K,'BSE - Other Index Options'!$D:$D,$A25)=0,"",SUMIFS('BSE - SENSEX Index Options'!$K:$K,'BSE - SENSEX Index Options'!$D:$D,$A25)+SUMIFS('BSE - Other Index Options'!$K:$K,'BSE - Other Index Options'!$D:$D,$A25)) | F25: =IF(SUMIFS('BSE - SENSEX Index Options'!$L:$L,'BSE - SENSEX Index Options'!$D:$D,$A25)+SUMIFS('BSE - Other Index Options'!$L:$L,'BSE - Other Index Options'!$D:$D,$A25)=0,"",SUMIFS('BSE - SENSEX Index Options'!$L:$L,'BSE - SENSEX Index Options'!$D:$D,$A25)+SUMIFS('BSE - Other Index Options'!$L:$L,'BSE - Other Index Options'!$D:$D,$A25)) | G25: =IF(SUMIFS('BSE - SENSEX Index Options'!$M:$M,'BSE - SENSEX Index Options'!$D:$D,$A25)+SUMIFS('BSE - Other Index Options'!$M:$M,'BSE - Other Index Options'!$D:$D,$A25)=0,"",SUMIFS('BSE - SENSEX Index Options'!$M:$M,'BSE - SENSEX Index Options'!$D:$D,$A25)+SUMIFS('BSE - Other Index Options'!$M:$M,'BSE - Other Index Options'!$D:$D,$A25))
A26: 46204 | B26: =IF(SUMIFS('NSE - NIFTY Index Options'!$K:$K,'NSE - NIFTY Index Options'!$D:$D,$A26)+SUMIFS('NSE - Other Index Options'!$K:$K,'NSE - Other Index Options'!$D:$D,$A26)=0,"",SUMIFS('NSE - NIFTY Index Options'!$K:$K,'NSE - NIFTY Index Options'!$D:$D,$A26)+SUMIFS('NSE - Other Index Options'!$K:$K,'NSE - Other Index Options'!$D:$D,$A26)) | C26: =IF(SUMIFS('NSE - NIFTY Index Options'!$L:$L,'NSE - NIFTY Index Options'!$D:$D,$A26)+SUMIFS('NSE - Other Index Options'!$L:$L,'NSE - Other Index Options'!$D:$D,$A26)=0,"",SUMIFS('NSE - NIFTY Index Options'!$L:$L,'NSE - NIFTY Index Options'!$D:$D,$A26)+SUMIFS('NSE - Other Index Options'!$L:$L,'NSE - Other Index Options'!$D:$D,$A26)) | D26: =IF(SUMIFS('NSE - NIFTY Index Options'!$M:$M,'NSE - NIFTY Index Options'!$D:$D,$A26)+SUMIFS('NSE - Other Index Options'!$M:$M,'NSE - Other Index Options'!$D:$D,$A26)=0,"",SUMIFS('NSE - NIFTY Index Options'!$M:$M,'NSE - NIFTY Index Options'!$D:$D,$A26)+SUMIFS('NSE - Other Index Options'!$M:$M,'NSE - Other Index Options'!$D:$D,$A26)) | E26: =IF(SUMIFS('BSE - SENSEX Index Options'!$K:$K,'BSE - SENSEX Index Options'!$D:$D,$A26)+SUMIFS('BSE - Other Index Options'!$K:$K,'BSE - Other Index Options'!$D:$D,$A26)=0,"",SUMIFS('BSE - SENSEX Index Options'!$K:$K,'BSE - SENSEX Index Options'!$D:$D,$A26)+SUMIFS('BSE - Other Index Options'!$K:$K,'BSE - Other Index Options'!$D:$D,$A26)) | F26: =IF(SUMIFS('BSE - SENSEX Index Options'!$L:$L,'BSE - SENSEX Index Options'!$D:$D,$A26)+SUMIFS('BSE - Other Index Options'!$L:$L,'BSE - Other Index Options'!$D:$D,$A26)=0,"",SUMIFS('BSE - SENSEX Index Options'!$L:$L,'BSE - SENSEX Index Options'!$D:$D,$A26)+SUMIFS('BSE - Other Index Options'!$L:$L,'BSE - Other Index Options'!$D:$D,$A26)) | G26: =IF(SUMIFS('BSE - SENSEX Index Options'!$M:$M,'BSE - SENSEX Index Options'!$D:$D,$A26)+SUMIFS('BSE - Other Index Options'!$M:$M,'BSE - Other Index Options'!$D:$D,$A26)=0,"",SUMIFS('BSE - SENSEX Index Options'!$M:$M,'BSE - SENSEX Index Options'!$D:$D,$A26)+SUMIFS('BSE - Other Index Options'!$M:$M,'BSE - Other Index Options'!$D:$D,$A26))
A27: 46235 | B27: =IF(SUMIFS('NSE - NIFTY Index Options'!$K:$K,'NSE - NIFTY Index Options'!$D:$D,$A27)+SUMIFS('NSE - Other Index Options'!$K:$K,'NSE - Other Index Options'!$D:$D,$A27)=0,"",SUMIFS('NSE - NIFTY Index Options'!$K:$K,'NSE - NIFTY Index Options'!$D:$D,$A27)+SUMIFS('NSE - Other Index Options'!$K:$K,'NSE - Other Index Options'!$D:$D,$A27)) | C27: =IF(SUMIFS('NSE - NIFTY Index Options'!$L:$L,'NSE - NIFTY Index Options'!$D:$D,$A27)+SUMIFS('NSE - Other Index Options'!$L:$L,'NSE - Other Index Options'!$D:$D,$A27)=0,"",SUMIFS('NSE - NIFTY Index Options'!$L:$L,'NSE - NIFTY Index Options'!$D:$D,$A27)+SUMIFS('NSE - Other Index Options'!$L:$L,'NSE - Other Index Options'!$D:$D,$A27)) | D27: =IF(SUMIFS('NSE - NIFTY Index Options'!$M:$M,'NSE - NIFTY Index Options'!$D:$D,$A27)+SUMIFS('NSE - Other Index Options'!$M:$M,'NSE - Other Index Options'!$D:$D,$A27)=0,"",SUMIFS('NSE - NIFTY Index Options'!$M:$M,'NSE - NIFTY Index Options'!$D:$D,$A27)+SUMIFS('NSE - Other Index Options'!$M:$M,'NSE - Other Index Options'!$D:$D,$A27)) | E27: =IF(SUMIFS('BSE - SENSEX Index Options'!$K:$K,'BSE - SENSEX Index Options'!$D:$D,$A27)+SUMIFS('BSE - Other Index Options'!$K:$K,'BSE - Other Index Options'!$D:$D,$A27)=0,"",SUMIFS('BSE - SENSEX Index Options'!$K:$K,'BSE - SENSEX Index Options'!$D:$D,$A27)+SUMIFS('BSE - Other Index Options'!$K:$K,'BSE - Other Index Options'!$D:$D,$A27)) | F27: =IF(SUMIFS('BSE - SENSEX Index Options'!$L:$L,'BSE - SENSEX Index Options'!$D:$D,$A27)+SUMIFS('BSE - Other Index Options'!$L:$L,'BSE - Other Index Options'!$D:$D,$A27)=0,"",SUMIFS('BSE - SENSEX Index Options'!$L:$L,'BSE - SENSEX Index Options'!$D:$D,$A27)+SUMIFS('BSE - Other Index Options'!$L:$L,'BSE - Other Index Options'!$D:$D,$A27)) | G27: =IF(SUMIFS('BSE - SENSEX Index Options'!$M:$M,'BSE - SENSEX Index Options'!$D:$D,$A27)+SUMIFS('BSE - Other Index Options'!$M:$M,'BSE - Other Index Options'!$D:$D,$A27)=0,"",SUMIFS('BSE - SENSEX Index Options'!$M:$M,'BSE - SENSEX Index Options'!$D:$D,$A27)+SUMIFS('BSE - Other Index Options'!$M:$M,'BSE - Other Index Options'!$D:$D,$A27))
... A43: 46722 | B43: =IF(SUMIFS('NSE - NIFTY Index Options'!$K:$K,'NSE - NIFTY Index Options'!$D:$D,$A43)+SUMIFS('NSE - Other Index Options'!$K:$K,'NSE - Other Index Options'!$D:$D,$A43)=0,"",SUMIFS('NSE - NIFTY Index Options'!$K:$K,'NSE - NIFTY Index Options'!$D:$D,$A43)+SUMIFS('NSE - Other Index Options'!$K:$K,'NSE - Other Index Options'!$D:$D,$A43)) | C43: =IF(SUMIFS('NSE - NIFTY Index Options'!$L:$L,'NSE - NIFTY Index Options'!$D:$D,$A43)+SUMIFS('NSE - Other Index Options'!$L:$L,'NSE - Other Index Options'!$D:$D,$A43)=0,"",SUMIFS('NSE - NIFTY Index Options'!$L:$L,'NSE - NIFTY Index Options'!$D:$D,$A43)+SUMIFS('NSE - Other Index Options'!$L:$L,'NSE - Other Index Options'!$D:$D,$A43)) | D43: =IF(SUMIFS('NSE - NIFTY Index Options'!$M:$M,'NSE - NIFTY Index Options'!$D:$D,$A43)+SUMIFS('NSE - Other Index Options'!$M:$M,'NSE - Other Index Options'!$D:$D,$A43)=0,"",SUMIFS('NSE - NIFTY Index Options'!$M:$M,'NSE - NIFTY Index Options'!$D:$D,$A43)+SUMIFS('NSE - Other Index Options'!$M:$M,'NSE - Other Index Options'!$D:$D,$A43)) | E43: =IF(SUMIFS('BSE - SENSEX Index Options'!$K:$K,'BSE - SENSEX Index Options'!$D:$D,$A43)+SUMIFS('BSE - Other Index Options'!$K:$K,'BSE - Other Index Options'!$D:$D,$A43)=0,"",SUMIFS('BSE - SENSEX Index Options'!$K:$K,'BSE - SENSEX Index Options'!$D:$D,$A43)+SUMIFS('BSE - Other Index Options'!$K:$K,'BSE - Other Index Options'!$D:$D,$A43)) | F43: =IF(SUMIFS('BSE - SENSEX Index Options'!$L:$L,'BSE - SENSEX Index Options'!$D:$D,$A43)+SUMIFS('BSE - Other Index Options'!$L:$L,'BSE - Other Index Options'!$D:$D,$A43)=0,"",SUMIFS('BSE - SENSEX Index Options'!$L:$L,'BSE - SENSEX Index Options'!$D:$D,$A43)+SUMIFS('BSE - Other Index Options'!$L:$L,'BSE - Other Index Options'!$D:$D,$A43)) | G43: =IF(SUMIFS('BSE - SENSEX Index Options'!$M:$M,'BSE - SENSEX Index Options'!$D:$D,$A43)+SUMIFS('BSE - Other Index Options'!$M:$M,'BSE - Other Index Options'!$D:$D,$A43)=0,"",SUMIFS('BSE - SENSEX Index Options'!$M:$M,'BSE - SENSEX Index Options'!$D:$D,$A43)+SUMIFS('BSE - Other Index Options'!$M:$M,'BSE - Other Index Options'!$D:$D,$A43))
A44: Total | B44: =IF(SUM(B16:B43)=0,"",SUM(B16:B43)) | C44: =IF(SUM(C16:C43)=0,"",SUM(C16:C43)) | D44: =IF(SUM(D16:D43)=0,"",SUM(D16:D43)) | E44: =IF(SUM(E16:E43)=0,"",SUM(E16:E43)) | F44: =IF(SUM(F16:F43)=0,"",SUM(F16:F43)) | G44: =IF(SUM(G16:G43)=0,"",SUM(G16:G43))

Sheet Dataset Overview
A1: DATASET OVERVIEW — NSE & BSE Index Options, Expiry-wise Daily Premium Turnover
A2: Orientation page: what this dataset contains, how it is cut, and where to find each view. All figures below are live formulas.
A4: About the data
A5: Granularity: | B5: One row per Trade Date × Expiry Date per sheet; calls and puts combined. Columns: dates, day names, week/month labels, expiry classifications, Contracts, Notional & Premium Turnover.
A6: Coverage: | B6: INDEX OPTIONS ONLY (no stock options, no futures). NSE: NIFTY + other indices (BANKNIFTY, FINNIFTY, MIDCPNIFTY, NIFTYNXT50). BSE: SENSEX + other BSE indices.
A7: Period: | B7: 01-Sep-2025 onwards. NSE updated through: see Quality Check B9; BSE through: Quality Check B10. Includes special Sunday sessions and Muhurat trading.
A8: Units: | B8: Turnover in INR Bn (1 Bn = 100 crore). Raw exchange data arrives in INR lakh and is converted (÷10,000).
A9: Expiry calendar: | B9: NSE expiries fall on Tuesday (Monday when Tuesday is a holiday). BSE expiries fall on Thursday (Wednesday when shifted). NIFTY & SENSEX have weekly + monthly contracts; all other indices are monthly-only.
A10: Expiry Type: | B10: Monthly - <day> if the expiry date is in the last 7 days of its month (the month's final contract), else Weekly - <day>.
A11: Expiry Type 2: | B11: Same as Expiry Type, except a Monthly contract trading within 6 days of its own expiry becomes MDAW - <day> (Monthly acting As Weekly, i.e. the front contract of expiry week). MDAW applies only to NIFTY & SENSEX; other-index sheets keep Expiry Type as-is.
A13: Segment matrix — full period totals (live)
A14: Exchange | B14: Sheet | C14: Expiry Type 2 Cut | D14: Contracts | E14: Notional Turnover (INR Bn) | F14: Premium Turnover (INR Bn) | G14: % of Grand Premium
A15: NSE | B15: NIFTY Index Options | C15: Weekly | D15: =SUMIFS('NSE - NIFTY Index Options'!$K:$K,'NSE - NIFTY Index Options'!$I:$I,"Weekly*") | E15: =SUMIFS('NSE - NIFTY Index Options'!$L:$L,'NSE - NIFTY Index Options'!$I:$I,"Weekly*") | F15: =SUMIFS('NSE - NIFTY Index Options'!$M:$M,'NSE - NIFTY Index Options'!$I:$I,"Weekly*") | G15: =IF($F$32=0,"",F15/$F$32)
A16: NSE | B16: NIFTY Index Options | C16: MDAW | D16: =SUMIFS('NSE - NIFTY Index Options'!$K:$K,'NSE - NIFTY Index Options'!$I:$I,"MDAW*") | E16: =SUMIFS('NSE - NIFTY Index Options'!$L:$L,'NSE - NIFTY Index Options'!$I:$I,"MDAW*") | F16: =SUMIFS('NSE - NIFTY Index Options'!$M:$M,'NSE - NIFTY Index Options'!$I:$I,"MDAW*") | G16: =IF($F$32=0,"",F16/$F$32)
A17: NSE | B17: NIFTY Index Options | C17: Monthly | D17: =SUMIFS('NSE - NIFTY Index Options'!$K:$K,'NSE - NIFTY Index Options'!$I:$I,"Monthly*") | E17: =SUMIFS('NSE - NIFTY Index Options'!$L:$L,'NSE - NIFTY Index Options'!$I:$I,"Monthly*") | F17: =SUMIFS('NSE - NIFTY Index Options'!$M:$M,'NSE - NIFTY Index Options'!$I:$I,"Monthly*") | G17: =IF($F$32=0,"",F17/$F$32)
A18: NSE | B18: NIFTY Index Options — Total | D18: =SUM(D15:D17) | E18: =SUM(E15:E17) | F18: =SUM(F15:F17) | G18: =IF($F$32=0,"",F18/$F$32)
A19: NSE | B19: Other Index Options | C19: Weekly | D19: =SUMIFS('NSE - Other Index Options'!$K:$K,'NSE - Other Index Options'!$I:$I,"Weekly*") | E19: =SUMIFS('NSE - Other Index Options'!$L:$L,'NSE - Other Index Options'!$I:$I,"Weekly*") | F19: =SUMIFS('NSE - Other Index Options'!$M:$M,'NSE - Other Index Options'!$I:$I,"Weekly*") | G19: =IF($F$32=0,"",F19/$F$32)
A20: NSE | B20: Other Index Options | C20: MDAW | D20: =SUMIFS('NSE - Other Index Options'!$K:$K,'NSE - Other Index Options'!$I:$I,"MDAW*") | E20: =SUMIFS('NSE - Other Index Options'!$L:$L,'NSE - Other Index Options'!$I:$I,"MDAW*") | F20: =SUMIFS('NSE - Other Index Options'!$M:$M,'NSE - Other Index Options'!$I:$I,"MDAW*") | G20: =IF($F$32=0,"",F20/$F$32)
A21: NSE | B21: Other Index Options | C21: Monthly | D21: =SUMIFS('NSE - Other Index Options'!$K:$K,'NSE - Other Index Options'!$I:$I,"Monthly*") | E21: =SUMIFS('NSE - Other Index Options'!$L:$L,'NSE - Other Index Options'!$I:$I,"Monthly*") | F21: =SUMIFS('NSE - Other Index Options'!$M:$M,'NSE - Other Index Options'!$I:$I,"Monthly*") | G21: =IF($F$32=0,"",F21/$F$32)
A22: NSE | B22: Other Index Options — Total | D22: =SUM(D19:D21) | E22: =SUM(E19:E21) | F22: =SUM(F19:F21) | G22: =IF($F$32=0,"",F22/$F$32)
A23: BSE | B23: SENSEX Index Options | C23: Weekly | D23: =SUMIFS('BSE - SENSEX Index Options'!$K:$K,'BSE - SENSEX Index Options'!$I:$I,"Weekly*") | E23: =SUMIFS('BSE - SENSEX Index Options'!$L:$L,'BSE - SENSEX Index Options'!$I:$I,"Weekly*") | F23: =SUMIFS('BSE - SENSEX Index Options'!$M:$M,'BSE - SENSEX Index Options'!$I:$I,"Weekly*") | G23: =IF($F$32=0,"",F23/$F$32)
A24: BSE | B24: SENSEX Index Options | C24: MDAW | D24: =SUMIFS('BSE - SENSEX Index Options'!$K:$K,'BSE - SENSEX Index Options'!$I:$I,"MDAW*") | E24: =SUMIFS('BSE - SENSEX Index Options'!$L:$L,'BSE - SENSEX Index Options'!$I:$I,"MDAW*") | F24: =SUMIFS('BSE - SENSEX Index Options'!$M:$M,'BSE - SENSEX Index Options'!$I:$I,"MDAW*") | G24: =IF($F$32=0,"",F24/$F$32)
A25: BSE | B25: SENSEX Index Options | C25: Monthly | D25: =SUMIFS('BSE - SENSEX Index Options'!$K:$K,'BSE - SENSEX Index Options'!$I:$I,"Monthly*") | E25: =SUMIFS('BSE - SENSEX Index Options'!$L:$L,'BSE - SENSEX Index Options'!$I:$I,"Monthly*") | F25: =SUMIFS('BSE - SENSEX Index Options'!$M:$M,'BSE - SENSEX Index Options'!$I:$I,"Monthly*") | G25: =IF($F$32=0,"",F25/$F$32)
A26: BSE | B26: SENSEX Index Options — Total | D26: =SUM(D23:D25) | E26: =SUM(E23:E25) | F26: =SUM(F23:F25) | G26: =IF($F$32=0,"",F26/$F$32)
A27: BSE | B27: Other Index Options | C27: Weekly | D27: =SUMIFS('BSE - Other Index Options'!$K:$K,'BSE - Other Index Options'!$I:$I,"Weekly*") | E27: =SUMIFS('BSE - Other Index Options'!$L:$L,'BSE - Other Index Options'!$I:$I,"Weekly*") | F27: =SUMIFS('BSE - Other Index Options'!$M:$M,'BSE - Other Index Options'!$I:$I,"Weekly*") | G27: =IF($F$32=0,"",F27/$F$32)
A28: BSE | B28: Other Index Options | C28: MDAW | D28: =SUMIFS('BSE - Other Index Options'!$K:$K,'BSE - Other Index Options'!$I:$I,"MDAW*") | E28: =SUMIFS('BSE - Other Index Options'!$L:$L,'BSE - Other Index Options'!$I:$I,"MDAW*") | F28: =SUMIFS('BSE - Other Index Options'!$M:$M,'BSE - Other Index Options'!$I:$I,"MDAW*") | G28: =IF($F$32=0,"",F28/$F$32)
A29: BSE | B29: Other Index Options | C29: Monthly | D29: =SUMIFS('BSE - Other Index Options'!$K:$K,'BSE - Other Index Options'!$I:$I,"Monthly*") | E29: =SUMIFS('BSE - Other Index Options'!$L:$L,'BSE - Other Index Options'!$I:$I,"Monthly*") | F29: =SUMIFS('BSE - Other Index Options'!$M:$M,'BSE - Other Index Options'!$I:$I,"Monthly*") | G29: =IF($F$32=0,"",F29/$F$32)
A30: BSE | B30: Other Index Options — Total | D30: =SUM(D27:D29) | E30: =SUM(E27:E29) | F30: =SUM(F27:F29) | G30: =IF($F$32=0,"",F30/$F$32)
A32: GRAND TOTAL | D32: =D18+D22+D26+D30 | E32: =E18+E22+E26+E30 | F32: =F18+F22+F26+F30 | G32: =IF($F$32=0,"",F32/$F$32)
A35: Sheet guide
A36: Quality Check | B36: Data currency per sheet, NSE/BSE alignment flag, monthly totals, data sources.
A37: Analysis1 | B37: Monthly premium by trade day (6 tables, Mon-Fri + Sunday), NSE vs BSE + market share. All expiry types.
A38: Analysis2 | B38: Same as Analysis1 but weekly-expiry contracts only.
A39: Analysis3 | B39: Week-level premium by trade day: NSE / BSE premium & share matrices. All expiry types.
A40: Analysis4 | B40: Week-level matrices, Weekly + MDAW premium only.
A41: Analysis5 | B41: Week-level matrices, Monthly premium only.
A42: Analysis6 | B42: Overall monthly NSE vs BSE: three tables (All / Weekly+MDAW / Monthly).
A43: Analysis7 | B43: Overall monthly NSE vs BSE: four tables (All / Weekly / MDAW / Monthly) + composition of each cut as % of All (NSE, BSE, combined).
A44: Analysis8 | B44: Combined NSE+BSE week × day premium matrix + day-wise weekly composition + Mon+Tue / Wed+Thu / Fri grouping. All expiry types.
A45: Analysis9 | B45: Same as Analysis8 but Weekly + MDAW only.
...

Sheet Exhibit 1
A1: Exhibit 1 — Quarterly Premium Turnover (INR Bn) by Segment × Expiry Type 2, Q2FY26 to Q2FY27 | J1: Expected trading days Q2FY27: | K1: 65 | M1: Cuts / Scope
A2: Indian fiscal quarters (Apr-Mar FY). Q2FY26 starts Sep-2025 (dataset start); Q2FY27 is partial, live as data updates. Weekly/MDAW rows for Other Index Options are blank — those underlyings are monthly-only. All live formulas on the data sheets. | J2: Trading days elapsed (live): | K2: =SUMPRODUCT(('NSE - NIFTY Index Options'!$E$2:$E$9000="Q2FY27")/COUNTIFS('NSE - NIFTY Index Options'!$A$2:$A$9000,'NSE - NIFTY Index Options'!$A$2:$A$9000&"",'NSE - NIFTY Index Options'!$E$2:$E$9000,'NSE - NIFTY Index Options'!$E$2:$E$9000&"")) | M2: Index Options | N2: Yes
J3: Source: NSE F&O holiday calendar — 66 weekdays minus Ganesh Chaturthi (Mon 14-Sep-2026). | M3: Stock Options | N3: No
A4: Segment | B4: Expiry Type 2 | C4: Q2FY26 | D4: Q3FY26 | E4: Q4FY26 | F4: Q1FY27 | G4: Q2FY27 | H4: Total | I4: Q2FY27 Implied Full Qtr | M4: Index Futures | N4: No
A5: NIFTY Index Options (NSE) | B5: Weekly | C5: =IF(SUMIFS('NSE - NIFTY Index Options'!$M:$M,'NSE - NIFTY Index Options'!$E:$E,C$4,'NSE - NIFTY Index Options'!$I:$I,"Weekly*")=0,"",SUMIFS('NSE - NIFTY Index Options'!$M:$M,'NSE - NIFTY Index Options'!$E:$E,C$4,'NSE - NIFTY Index Options'!$I:$I,"Weekly*")) | D5: =IF(SUMIFS('NSE - NIFTY Index Options'!$M:$M,'NSE - NIFTY Index Options'!$E:$E,D$4,'NSE - NIFTY Index Options'!$I:$I,"Weekly*")=0,"",SUMIFS('NSE - NIFTY Index Options'!$M:$M,'NSE - NIFTY Index Options'!$E:$E,D$4,'NSE - NIFTY Index Options'!$I:$I,"Weekly*")) | E5: =IF(SUMIFS('NSE - NIFTY Index Options'!$M:$M,'NSE - NIFTY Index Options'!$E:$E,E$4,'NSE - NIFTY Index Options'!$I:$I,"Weekly*")=0,"",SUMIFS('NSE - NIFTY Index Options'!$M:$M,'NSE - NIFTY Index Options'!$E:$E,E$4,'NSE - NIFTY Index Options'!$I:$I,"Weekly*")) | F5: =IF(SUMIFS('NSE - NIFTY Index Options'!$M:$M,'NSE - NIFTY Index Options'!$E:$E,F$4,'NSE - NIFTY Index Options'!$I:$I,"Weekly*")=0,"",SUMIFS('NSE - NIFTY Index Options'!$M:$M,'NSE - NIFTY Index Options'!$E:$E,F$4,'NSE - NIFTY Index Options'!$I:$I,"Weekly*")) | G5: =IF(SUMIFS('NSE - NIFTY Index Options'!$M:$M,'NSE - NIFTY Index Options'!$E:$E,G$4,'NSE - NIFTY Index Options'!$I:$I,"Weekly*")=0,"",SUMIFS('NSE - NIFTY Index Options'!$M:$M,'NSE - NIFTY Index Options'!$E:$E,G$4,'NSE - NIFTY Index Options'!$I:$I,"Weekly*")) | H5: =IF(SUM(C5:G5)=0,"",SUM(C5:G5)) | I5: =IF(G5="","",G5*$K$1/$K$2) | M5: NSE | N5: Yes
A6: NIFTY Index Options (NSE) | B6: MDAW | C6: =IF(SUMIFS('NSE - NIFTY Index Options'!$M:$M,'NSE - NIFTY Index Options'!$E:$E,C$4,'NSE - NIFTY Index Options'!$I:$I,"MDAW*")=0,"",SUMIFS('NSE - NIFTY Index Options'!$M:$M,'NSE - NIFTY Index Options'!$E:$E,C$4,'NSE - NIFTY Index Options'!$I:$I,"MDAW*")) | D6: =IF(SUMIFS('NSE - NIFTY Index Options'!$M:$M,'NSE - NIFTY Index Options'!$E:$E,D$4,'NSE - NIFTY Index Options'!$I:$I,"MDAW*")=0,"",SUMIFS('NSE - NIFTY Index Options'!$M:$M,'NSE - NIFTY Index Options'!$E:$E,D$4,'NSE - NIFTY Index Options'!$I:$I,"MDAW*")) | E6: =IF(SUMIFS('NSE - NIFTY Index Options'!$M:$M,'NSE - NIFTY Index Options'!$E:$E,E$4,'NSE - NIFTY Index Options'!$I:$I,"MDAW*")=0,"",SUMIFS('NSE - NIFTY Index Options'!$M:$M,'NSE - NIFTY Index Options'!$E:$E,E$4,'NSE - NIFTY Index Options'!$I:$I,"MDAW*")) | F6: =IF(SUMIFS('NSE - NIFTY Index Options'!$M:$M,'NSE - NIFTY Index Options'!$E:$E,F$4,'NSE - NIFTY Index Options'!$I:$I,"MDAW*")=0,"",SUMIFS('NSE - NIFTY Index Options'!$M:$M,'NSE - NIFTY Index Options'!$E:$E,F$4,'NSE - NIFTY Index Options'!$I:$I,"MDAW*")) | G6: =IF(SUMIFS('NSE - NIFTY Index Options'!$M:$M,'NSE - NIFTY Index Options'!$E:$E,G$4,'NSE - NIFTY Index Options'!$I:$I,"MDAW*")=0,"",SUMIFS('NSE - NIFTY Index Options'!$M:$M,'NSE - NIFTY Index Options'!$E:$E,G$4,'NSE - NIFTY Index Options'!$I:$I,"MDAW*")) | H6: =IF(SUM(C6:G6)=0,"",SUM(C6:G6)) | I6: =IF(G6="","",G6*$K$1/$K$2) | M6: BSE | N6: Yes
A7: NIFTY Index Options (NSE) | B7: Monthly | C7: =IF(SUMIFS('NSE - NIFTY Index Options'!$M:$M,'NSE - NIFTY Index Options'!$E:$E,C$4,'NSE - NIFTY Index Options'!$I:$I,"Monthly*")=0,"",SUMIFS('NSE - NIFTY Index Options'!$M:$M,'NSE - NIFTY Index Options'!$E:$E,C$4,'NSE - NIFTY Index Options'!$I:$I,"Monthly*")) | D7: =IF(SUMIFS('NSE - NIFTY Index Options'!$M:$M,'NSE - NIFTY Index Options'!$E:$E,D$4,'NSE - NIFTY Index Options'!$I:$I,"Monthly*")=0,"",SUMIFS('NSE - NIFTY Index Options'!$M:$M,'NSE - NIFTY Index Options'!$E:$E,D$4,'NSE - NIFTY Index Options'!$I:$I,"Monthly*")) | E7: =IF(SUMIFS('NSE - NIFTY Index Options'!$M:$M,'NSE - NIFTY Index Options'!$E:$E,E$4,'NSE - NIFTY Index Options'!$I:$I,"Monthly*")=0,"",SUMIFS('NSE - NIFTY Index Options'!$M:$M,'NSE - NIFTY Index Options'!$E:$E,E$4,'NSE - NIFTY Index Options'!$I:$I,"Monthly*")) | F7: =IF(SUMIFS('NSE - NIFTY Index Options'!$M:$M,'NSE - NIFTY Index Options'!$E:$E,F$4,'NSE - NIFTY Index Options'!$I:$I,"Monthly*")=0,"",SUMIFS('NSE - NIFTY Index Options'!$M:$M,'NSE - NIFTY Index Options'!$E:$E,F$4,'NSE - NIFTY Index Options'!$I:$I,"Monthly*")) | G7: =IF(SUMIFS('NSE - NIFTY Index Options'!$M:$M,'NSE - NIFTY Index Options'!$E:$E,G$4,'NSE - NIFTY Index Options'!$I:$I,"Monthly*")=0,"",SUMIFS('NSE - NIFTY Index Options'!$M:$M,'NSE - NIFTY Index Options'!$E:$E,G$4,'NSE - NIFTY Index Options'!$I:$I,"Monthly*")) | H7: =IF(SUM(C7:G7)=0,"",SUM(C7:G7)) | I7: =IF(G7="","",G7*$K$1/$K$2) | M7: NIFTY Index | N7: Yes
A8: NIFTY Index Options (NSE) | B8: Total | C8: =IF(SUM(C5:C7)=0,"",SUM(C5:C7)) | D8: =IF(SUM(D5:D7)=0,"",SUM(D5:D7)) | E8: =IF(SUM(E5:E7)=0,"",SUM(E5:E7)) | F8: =IF(SUM(F5:F7)=0,"",SUM(F5:F7)) | G8: =IF(SUM(G5:G7)=0,"",SUM(G5:G7)) | H8: =IF(SUM(H5:H7)=0,"",SUM(H5:H7)) | I8: =IF(G8="","",G8*$K$1/$K$2) | M8: Other NSE Indices | N8: Yes
A9: Other Index Options (NSE) | B9: Weekly | C9: =IF(SUMIFS('NSE - Other Index Options'!$M:$M,'NSE - Other Index Options'!$E:$E,C$4,'NSE - Other Index Options'!$I:$I,"Weekly*")=0,"",SUMIFS('NSE - Other Index Options'!$M:$M,'NSE - Other Index Options'!$E:$E,C$4,'NSE - Other Index Options'!$I:$I,"Weekly*")) | D9: =IF(SUMIFS('NSE - Other Index Options'!$M:$M,'NSE - Other Index Options'!$E:$E,D$4,'NSE - Other Index Options'!$I:$I,"Weekly*")=0,"",SUMIFS('NSE - Other Index Options'!$M:$M,'NSE - Other Index Options'!$E:$E,D$4,'NSE - Other Index Options'!$I:$I,"Weekly*")) | E9: =IF(SUMIFS('NSE - Other Index Options'!$M:$M,'NSE - Other Index Options'!$E:$E,E$4,'NSE - Other Index Options'!$I:$I,"Weekly*")=0,"",SUMIFS('NSE - Other Index Options'!$M:$M,'NSE - Other Index Options'!$E:$E,E$4,'NSE - Other Index Options'!$I:$I,"Weekly*")) | F9: =IF(SUMIFS('NSE - Other Index Options'!$M:$M,'NSE - Other Index Options'!$E:$E,F$4,'NSE - Other Index Options'!$I:$I,"Weekly*")=0,"",SUMIFS('NSE - Other Index Options'!$M:$M,'NSE - Other Index Options'!$E:$E,F$4,'NSE - Other Index Options'!$I:$I,"Weekly*")) | G9: =IF(SUMIFS('NSE - Other Index Options'!$M:$M,'NSE - Other Index Options'!$E:$E,G$4,'NSE - Other Index Options'!$I:$I,"Weekly*")=0,"",SUMIFS('NSE - Other Index Options'!$M:$M,'NSE - Other Index Options'!$E:$E,G$4,'NSE - Other Index Options'!$I:$I,"Weekly*")) | H9: =IF(SUM(C9:G9)=0,"",SUM(C9:G9)) | I9: =IF(G9="","",G9*$K$1/$K$2) | J9: / | M9: SENSEX Index | N9: Yes
A10: Other Index Options (NSE) | B10: MDAW | C10: =IF(SUMIFS('NSE - Other Index Options'!$M:$M,'NSE - Other Index Options'!$E:$E,C$4,'NSE - Other Index Options'!$I:$I,"MDAW*")=0,"",SUMIFS('NSE - Other Index Options'!$M:$M,'NSE - Other Index Options'!$E:$E,C$4,'NSE - Other Index Options'!$I:$I,"MDAW*")) | D10: =IF(SUMIFS('NSE - Other Index Options'!$M:$M,'NSE - Other Index Options'!$E:$E,D$4,'NSE - Other Index Options'!$I:$I,"MDAW*")=0,"",SUMIFS('NSE - Other Index Options'!$M:$M,'NSE - Other Index Options'!$E:$E,D$4,'NSE - Other Index Options'!$I:$I,"MDAW*")) | E10: =IF(SUMIFS('NSE - Other Index Options'!$M:$M,'NSE - Other Index Options'!$E:$E,E$4,'NSE - Other Index Options'!$I:$I,"MDAW*")=0,"",SUMIFS('NSE - Other Index Options'!$M:$M,'NSE - Other Index Options'!$E:$E,E$4,'NSE - Other Index Options'!$I:$I,"MDAW*")) | F10: =IF(SUMIFS('NSE - Other Index Options'!$M:$M,'NSE - Other Index Options'!$E:$E,F$4,'NSE - Other Index Options'!$I:$I,"MDAW*")=0,"",SUMIFS('NSE - Other Index Options'!$M:$M,'NSE - Other Index Options'!$E:$E,F$4,'NSE - Other Index Options'!$I:$I,"MDAW*")) | G10: =IF(SUMIFS('NSE - Other Index Options'!$M:$M,'NSE - Other Index Options'!$E:$E,G$4,'NSE - Other Index Options'!$I:$I,"MDAW*")=0,"",SUMIFS('NSE - Other Index Options'!$M:$M,'NSE - Other Index Options'!$E:$E,G$4,'NSE - Other Index Options'!$I:$I,"MDAW*")) | H10: =IF(SUM(C10:G10)=0,"",SUM(C10:G10)) | I10: =IF(G10="","",G10*$K$1/$K$2) | M10: Other BSE Indices | N10: Yes
A11: Other Index Options (NSE) | B11: Monthly | C11: =IF(SUMIFS('NSE - Other Index Options'!$M:$M,'NSE - Other Index Options'!$E:$E,C$4,'NSE - Other Index Options'!$I:$I,"Monthly*")=0,"",SUMIFS('NSE - Other Index Options'!$M:$M,'NSE - Other Index Options'!$E:$E,C$4,'NSE - Other Index Options'!$I:$I,"Monthly*")) | D11: =IF(SUMIFS('NSE - Other Index Options'!$M:$M,'NSE - Other Index Options'!$E:$E,D$4,'NSE - Other Index Options'!$I:$I,"Monthly*")=0,"",SUMIFS('NSE - Other Index Options'!$M:$M,'NSE - Other Index Options'!$E:$E,D$4,'NSE - Other Index Options'!$I:$I,"Monthly*")) | E11: =IF(SUMIFS('NSE - Other Index Options'!$M:$M,'NSE - Other Index Options'!$E:$E,E$4,'NSE - Other Index Options'!$I:$I,"Monthly*")=0,"",SUMIFS('NSE - Other Index Options'!$M:$M,'NSE - Other Index Options'!$E:$E,E$4,'NSE - Other Index Options'!$I:$I,"Monthly*")) | F11: =IF(SUMIFS('NSE - Other Index Options'!$M:$M,'NSE - Other Index Options'!$E:$E,F$4,'NSE - Other Index Options'!$I:$I,"Monthly*")=0,"",SUMIFS('NSE - Other Index Options'!$M:$M,'NSE - Other Index Options'!$E:$E,F$4,'NSE - Other Index Options'!$I:$I,"Monthly*")) | G11: =IF(SUMIFS('NSE - Other Index Options'!$M:$M,'NSE - Other Index Options'!$E:$E,G$4,'NSE - Other Index Options'!$I:$I,"Monthly*")=0,"",SUMIFS('NSE - Other Index Options'!$M:$M,'NSE - Other Index Options'!$E:$E,G$4,'NSE - Other Index Options'!$I:$I,"Monthly*")) | H11: =IF(SUM(C11:G11)=0,"",SUM(C11:G11)) | I11: =IF(G11="","",G11*$K$1/$K$2) | M11: Expiry Type 2 - Weekly | N11: Yes
A12: Other Index Options (NSE) | B12: Total | C12: =IF(SUM(C9:C11)=0,"",SUM(C9:C11)) | D12: =IF(SUM(D9:D11)=0,"",SUM(D9:D11)) | E12: =IF(SUM(E9:E11)=0,"",SUM(E9:E11)) | F12: =IF(SUM(F9:F11)=0,"",SUM(F9:F11)) | G12: =IF(SUM(G9:G11)=0,"",SUM(G9:G11)) | H12: =IF(SUM(H9:H11)=0,"",SUM(H9:H11)) | I12: =IF(G12="","",G12*$K$1/$K$2) | M12: Expiry Type 2 - MDAW | N12: Yes
A13: SENSEX Index Options (BSE) | B13: Weekly | C13: =IF(SUMIFS('BSE - SENSEX Index Options'!$M:$M,'BSE - SENSEX Index Options'!$E:$E,C$4,'BSE - SENSEX Index Options'!$I:$I,"Weekly*")=0,"",SUMIFS('BSE - SENSEX Index Options'!$M:$M,'BSE - SENSEX Index Options'!$E:$E,C$4,'BSE - SENSEX Index Options'!$I:$I,"Weekly*")) | D13: =IF(SUMIFS('BSE - SENSEX Index Options'!$M:$M,'BSE - SENSEX Index Options'!$E:$E,D$4,'BSE - SENSEX Index Options'!$I:$I,"Weekly*")=0,"",SUMIFS('BSE - SENSEX Index Options'!$M:$M,'BSE - SENSEX Index Options'!$E:$E,D$4,'BSE - SENSEX Index Options'!$I:$I,"Weekly*")) | E13: =IF(SUMIFS('BSE - SENSEX Index Options'!$M:$M,'BSE - SENSEX Index Options'!$E:$E,E$4,'BSE - SENSEX Index Options'!$I:$I,"Weekly*")=0,"",SUMIFS('BSE - SENSEX Index Options'!$M:$M,'BSE - SENSEX Index Options'!$E:$E,E$4,'BSE - SENSEX Index Options'!$I:$I,"Weekly*")) | F13: =IF(SUMIFS('BSE - SENSEX Index Options'!$M:$M,'BSE - SENSEX Index Options'!$E:$E,F$4,'BSE - SENSEX Index Options'!$I:$I,"Weekly*")=0,"",SUMIFS('BSE - SENSEX Index Options'!$M:$M,'BSE - SENSEX Index Options'!$E:$E,F$4,'BSE - SENSEX Index Options'!$I:$I,"Weekly*")) | G13: =IF(SUMIFS('BSE - SENSEX Index Options'!$M:$M,'BSE - SENSEX Index Options'!$E:$E,G$4,'BSE - SENSEX Index Options'!$I:$I,"Weekly*")=0,"",SUMIFS('BSE - SENSEX Index Options'!$M:$M,'BSE - SENSEX Index Options'!$E:$E,G$4,'BSE - SENSEX Index Options'!$I:$I,"Weekly*")) | H13: =IF(SUM(C13:G13)=0,"",SUM(C13:G13)) | I13: =IF(G13="","",G13*$K$1/$K$2) | M13: Expiry Type 2 - Monthly | N13: Yes
A14: SENSEX Index Options (BSE) | B14: MDAW | C14: =IF(SUMIFS('BSE - SENSEX Index Options'!$M:$M,'BSE - SENSEX Index Options'!$E:$E,C$4,'BSE - SENSEX Index Options'!$I:$I,"MDAW*")=0,"",SUMIFS('BSE - SENSEX Index Options'!$M:$M,'BSE - SENSEX Index Options'!$E:$E,C$4,'BSE - SENSEX Index Options'!$I:$I,"MDAW*")) | D14: =IF(SUMIFS('BSE - SENSEX Index Options'!$M:$M,'BSE - SENSEX Index Options'!$E:$E,D$4,'BSE - SENSEX Index Options'!$I:$I,"MDAW*")=0,"",SUMIFS('BSE - SENSEX Index Options'!$M:$M,'BSE - SENSEX Index Options'!$E:$E,D$4,'BSE - SENSEX Index Options'!$I:$I,"MDAW*")) | E14: =IF(SUMIFS('BSE - SENSEX Index Options'!$M:$M,'BSE - SENSEX Index Options'!$E:$E,E$4,'BSE - SENSEX Index Options'!$I:$I,"MDAW*")=0,"",SUMIFS('BSE - SENSEX Index Options'!$M:$M,'BSE - SENSEX Index Options'!$E:$E,E$4,'BSE - SENSEX Index Options'!$I:$I,"MDAW*")) | F14: =IF(SUMIFS('BSE - SENSEX Index Options'!$M:$M,'BSE - SENSEX Index Options'!$E:$E,F$4,'BSE - SENSEX Index Options'!$I:$I,"MDAW*")=0,"",SUMIFS('BSE - SENSEX Index Options'!$M:$M,'BSE - SENSEX Index Options'!$E:$E,F$4,'BSE - SENSEX Index Options'!$I:$I,"MDAW*")) | G14: =IF(SUMIFS('BSE - SENSEX Index Options'!$M:$M,'BSE - SENSEX Index Options'!$E:$E,G$4,'BSE - SENSEX Index Options'!$I:$I,"MDAW*")=0,"",SUMIFS('BSE - SENSEX Index Options'!$M:$M,'BSE - SENSEX Index Options'!$E:$E,G$4,'BSE - SENSEX Index Options'!$I:$I,"MDAW*")) | H14: =IF(SUM(C14:G14)=0,"",SUM(C14:G14)) | I14: =IF(G14="","",G14*$K$1/$K$2)
A15: SENSEX Index Options (BSE) | B15: Monthly | C15: =IF(SUMIFS('BSE - SENSEX Index Options'!$M:$M,'BSE - SENSEX Index Options'!$E:$E,C$4,'BSE - SENSEX Index Options'!$I:$I,"Monthly*")=0,"",SUMIFS('BSE - SENSEX Index Options'!$M:$M,'BSE - SENSEX Index Options'!$E:$E,C$4,'BSE - SENSEX Index Options'!$I:$I,"Monthly*")) | D15: =IF(SUMIFS('BSE - SENSEX Index Options'!$M:$M,'BSE - SENSEX Index Options'!$E:$E,D$4,'BSE - SENSEX Index Options'!$I:$I,"Monthly*")=0,"",SUMIFS('BSE - SENSEX Index Options'!$M:$M,'BSE - SENSEX Index Options'!$E:$E,D$4,'BSE - SENSEX Index Options'!$I:$I,"Monthly*")) | E15: =IF(SUMIFS('BSE - SENSEX Index Options'!$M:$M,'BSE - SENSEX Index Options'!$E:$E,E$4,'BSE - SENSEX Index Options'!$I:$I,"Monthly*")=0,"",SUMIFS('BSE - SENSEX Index Options'!$M:$M,'BSE - SENSEX Index Options'!$E:$E,E$4,'BSE - SENSEX Index Options'!$I:$I,"Monthly*")) | F15: =IF(SUMIFS('BSE - SENSEX Index Options'!$M:$M,'BSE - SENSEX Index Options'!$E:$E,F$4,'BSE - SENSEX Index Options'!$I:$I,"Monthly*")=0,"",SUMIFS('BSE - SENSEX Index Options'!$M:$M,'BSE - SENSEX Index Options'!$E:$E,F$4,'BSE - SENSEX Index Options'!$I:$I,"Monthly*")) | G15: =IF(SUMIFS('BSE - SENSEX Index Options'!$M:$M,'BSE - SENSEX Index Options'!$E:$E,G$4,'BSE - SENSEX Index Options'!$I:$I,"Monthly*")=0,"",SUMIFS('BSE - SENSEX Index Options'!$M:$M,'BSE - SENSEX Index Options'!$E:$E,G$4,'BSE - SENSEX Index Options'!$I:$I,"Monthly*")) | H15: =IF(SUM(C15:G15)=0,"",SUM(C15:G15)) | I15: =IF(G15="","",G15*$K$1/$K$2)
A16: SENSEX Index Options (BSE) | B16: Total | C16: =IF(SUM(C13:C15)=0,"",SUM(C13:C15)) | D16: =IF(SUM(D13:D15)=0,"",SUM(D13:D15)) | E16: =IF(SUM(E13:E15)=0,"",SUM(E13:E15)) | F16: =IF(SUM(F13:F15)=0,"",SUM(F13:F15)) | G16: =IF(SUM(G13:G15)=0,"",SUM(G13:G15)) | H16: =IF(SUM(H13:H15)=0,"",SUM(H13:H15)) | I16: =IF(G16="","",G16*$K$1/$K$2)
A17: Other Index Options (BSE) | B17: Weekly | C17: =IF(SUMIFS('BSE - Other Index Options'!$M:$M,'BSE - Other Index Options'!$E:$E,C$4,'BSE - Other Index Options'!$I:$I,"Weekly*")=0,"",SUMIFS('BSE - Other Index Options'!$M:$M,'BSE - Other Index Options'!$E:$E,C$4,'BSE - Other Index Options'!$I:$I,"Weekly*")) | D17: =IF(SUMIFS('BSE - Other Index Options'!$M:$M,'BSE - Other Index Options'!$E:$E,D$4,'BSE - Other Index Options'!$I:$I,"Weekly*")=0,"",SUMIFS('BSE - Other Index Options'!$M:$M,'BSE - Other Index Options'!$E:$E,D$4,'BSE - Other Index Options'!$I:$I,"Weekly*")) | E17: =IF(SUMIFS('BSE - Other Index Options'!$M:$M,'BSE - Other Index Options'!$E:$E,E$4,'BSE - Other Index Options'!$I:$I,"Weekly*")=0,"",SUMIFS('BSE - Other Index Options'!$M:$M,'BSE - Other Index Options'!$E:$E,E$4,'BSE - Other Index Options'!$I:$I,"Weekly*")) | F17: =IF(SUMIFS('BSE - Other Index Options'!$M:$M,'BSE - Other Index Options'!$E:$E,F$4,'BSE - Other Index Options'!$I:$I,"Weekly*")=0,"",SUMIFS('BSE - Other Index Options'!$M:$M,'BSE - Other Index Options'!$E:$E,F$4,'BSE - Other Index Options'!$I:$I,"Weekly*")) | G17: =IF(SUMIFS('BSE - Other Index Options'!$M:$M,'BSE - Other Index Options'!$E:$E,G$4,'BSE - Other Index Options'!$I:$I,"Weekly*")=0,"",SUMIFS('BSE - Other Index Options'!$M:$M,'BSE - Other Index Options'!$E:$E,G$4,'BSE - Other Index Options'!$I:$I,"Weekly*")) | H17: =IF(SUM(C17:G17)=0,"",SUM(C17:G17)) | I17: =IF(G17="","",G17*$K$1/$K$2)
A18: Other Index Options (BSE) | B18: MDAW | C18: =IF(SUMIFS('BSE - Other Index Options'!$M:$M,'BSE - Other Index Options'!$E:$E,C$4,'BSE - Other Index Options'!$I:$I,"MDAW*")=0,"",SUMIFS('BSE - Other Index Options'!$M:$M,'BSE - Other Index Options'!$E:$E,C$4,'BSE - Other Index Options'!$I:$I,"MDAW*")) | D18: =IF(SUMIFS('BSE - Other Index Options'!$M:$M,'BSE - Other Index Options'!$E:$E,D$4,'BSE - Other Index Options'!$I:$I,"MDAW*")=0,"",SUMIFS('BSE - Other Index Options'!$M:$M,'BSE - Other Index Options'!$E:$E,D$4,'BSE - Other Index Options'!$I:$I,"MDAW*")) | E18: =IF(SUMIFS('BSE - Other Index Options'!$M:$M,'BSE - Other Index Options'!$E:$E,E$4,'BSE - Other Index Options'!$I:$I,"MDAW*")=0,"",SUMIFS('BSE - Other Index Options'!$M:$M,'BSE - Other Index Options'!$E:$E,E$4,'BSE - Other Index Options'!$I:$I,"MDAW*")) | F18: =IF(SUMIFS('BSE - Other Index Options'!$M:$M,'BSE - Other Index Options'!$E:$E,F$4,'BSE - Other Index Options'!$I:$I,"MDAW*")=0,"",SUMIFS('BSE - Other Index Options'!$M:$M,'BSE - Other Index Options'!$E:$E,F$4,'BSE - Other Index Options'!$I:$I,"MDAW*")) | G18: =IF(SUMIFS('BSE - Other Index Options'!$M:$M,'BSE - Other Index Options'!$E:$E,G$4,'BSE - Other Index Options'!$I:$I,"MDAW*")=0,"",SUMIFS('BSE - Other Index Options'!$M:$M,'BSE - Other Index Options'!$E:$E,G$4,'BSE - Other Index Options'!$I:$I,"MDAW*")) | H18: =IF(SUM(C18:G18)=0,"",SUM(C18:G18)) | I18: =IF(G18="","",G18*$K$1/$K$2)
A19: Other Index Options (BSE) | B19: Monthly | C19: =IF(SUMIFS('BSE - Other Index Options'!$M:$M,'BSE - Other Index Options'!$E:$E,C$4,'BSE - Other Index Options'!$I:$I,"Monthly*")=0,"",SUMIFS('BSE - Other Index Options'!$M:$M,'BSE - Other Index Options'!$E:$E,C$4,'BSE - Other Index Options'!$I:$I,"Monthly*")) | D19: =IF(SUMIFS('BSE - Other Index Options'!$M:$M,'BSE - Other Index Options'!$E:$E,D$4,'BSE - Other Index Options'!$I:$I,"Monthly*")=0,"",SUMIFS('BSE - Other Index Options'!$M:$M,'BSE - Other Index Options'!$E:$E,D$4,'BSE - Other Index Options'!$I:$I,"Monthly*")) | E19: =IF(SUMIFS('BSE - Other Index Options'!$M:$M,'BSE - Other Index Options'!$E:$E,E$4,'BSE - Other Index Options'!$I:$I,"Monthly*")=0,"",SUMIFS('BSE - Other Index Options'!$M:$M,'BSE - Other Index Options'!$E:$E,E$4,'BSE - Other Index Options'!$I:$I,"Monthly*")) | F19: =IF(SUMIFS('BSE - Other Index Options'!$M:$M,'BSE - Other Index Options'!$E:$E,F$4,'BSE - Other Index Options'!$I:$I,"Monthly*")=0,"",SUMIFS('BSE - Other Index Options'!$M:$M,'BSE - Other Index Options'!$E:$E,F$4,'BSE - Other Index Options'!$I:$I,"Monthly*")) | G19: =IF(SUMIFS('BSE - Other Index Options'!$M:$M,'BSE - Other Index Options'!$E:$E,G$4,'BSE - Other Index Options'!$I:$I,"Monthly*")=0,"",SUMIFS('BSE - Other Index Options'!$M:$M,'BSE - Other Index Options'!$E:$E,G$4,'BSE - Other Index Options'!$I:$I,"Monthly*")) | H19: =IF(SUM(C19:G19)=0,"",SUM(C19:G19)) | I19: =IF(G19="","",G19*$K$1/$K$2)
A20: Other Index Options (BSE) | B20: Total | C20: =IF(SUM(C17:C19)=0,"",SUM(C17:C19)) | D20: =IF(SUM(D17:D19)=0,"",SUM(D17:D19)) | E20: =IF(SUM(E17:E19)=0,"",SUM(E17:E19)) | F20: =IF(SUM(F17:F19)=0,"",SUM(F17:F19)) | G20: =IF(SUM(G17:G19)=0,"",SUM(G17:G19)) | H20: =IF(SUM(H17:H19)=0,"",SUM(H17:H19)) | I20: =IF(G20="","",G20*$K$1/$K$2)
A22: NSE Total | C22: =IF(SUM(C8)+SUM(C12)=0,"",SUM(C8)+SUM(C12)) | D22: =IF(SUM(D8)+SUM(D12)=0,"",SUM(D8)+SUM(D12)) | E22: =IF(SUM(E8)+SUM(E12)=0,"",SUM(E8)+SUM(E12)) | F22: =IF(SUM(F8)+SUM(F12)=0,"",SUM(F8)+SUM(F12)) | G22: =IF(SUM(G8)+SUM(G12)=0,"",SUM(G8)+SUM(G12)) | H22: =IF(SUM(H8)+SUM(H12)=0,"",SUM(H8)+SUM(H12)) | I22: =IF(G22="","",G22*$K$1/$K$2)
A23: BSE Total | C23: =IF(SUM(C16)+SUM(C20)=0,"",SUM(C16)+SUM(C20)) | D23: =IF(SUM(D16)+SUM(D20)=0,"",SUM(D16)+SUM(D20)) | E23: =IF(SUM(E16)+SUM(E20)=0,"",SUM(E16)+SUM(E20)) | F23: =IF(SUM(F16)+SUM(F20)=0,"",SUM(F16)+SUM(F20)) | G23: =IF(SUM(G16)+SUM(G20)=0,"",SUM(G16)+SUM(G20)) | H23: =IF(SUM(H16)+SUM(H20)=0,"",SUM(H16)+SUM(H20)) | I23: =IF(G23="","",G23*$K$1/$K$2)
A24: GRAND TOTAL | C24: =IF(SUM(C22,C23)=0,"",SUM(C22,C23)) | D24: =IF(SUM(D22,D23)=0,"",SUM(D22,D23)) | E24: =IF(SUM(E22,E23)=0,"",SUM(E22,E23)) | F24: =IF(SUM(F22,F23)=0,"",SUM(F22,F23)) | G24: =IF(SUM(G22,G23)=0,"",SUM(G22,G23)) | H24: =IF(SUM(H22,H23)=0,"",SUM(H22,H23)) | I24: =IF(G24="","",G24*$K$1/$K$2)

Sheet Exhibit 2
A1: Exhibit 2 — Quarterly Premium Turnover by Trade Day, WEEKLY + MDAW (Expiry Type 2), NSE vs BSE (INR Bn) | J1: Expected trading days Q2FY27: | K1: 65 | S1: Cuts / Scope
A2: Same analysis as Analysis4 but at fiscal-quarter level (Q2FY26 = Sep-2025 start; Q2FY27 partial, live). Weekly + MDAW = weekly contracts plus monthly contracts in their final 6 days (front-week trading); Monthly excluded. All index options, both exchanges. MDAW = a monthly contract acting as the front weekly (NIFTY & SENSEX only). | J2: Trading days elapsed (live): | K2: =SUMPRODUCT(('NSE - NIFTY Index Options'!$E$2:$E$9000="Q2FY27")/COUNTIFS('NSE - NIFTY Index Options'!$A$2:$A$9000,'NSE - NIFTY Index Options'!$A$2:$A$9000&"",'NSE - NIFTY Index Options'!$E$2:$E$9000,'NSE - NIFTY Index Options'!$E$2:$E$9000&"")) | S2: Index Options | T2: Yes
S3: Stock Options | T3: No
