Workbook

Sheet Quality Check
A1: Quality Check — Exchanges Monthly Weekly Expiry (MASTER FILE)
A3: Exchange | B3: Sheet | C3: Data From | D3: Data To | E3: Data Rows | F3: Premium Turnover (INR Crs)
A4: NSE | B4: NSE - NIFTY Index Options | C4: ='NSE - NIFTY Index Options'!A2 -> 01-Sep-2025 | D4: =LOOKUP(2,1/('NSE - NIFTY Index Options'!$A$2:$A$100000<>""),'NSE - NIFTY Index Options'!$A$2:$A$100000) -> 08-Jul-2026 | E4: =COUNTA('NSE - NIFTY Index Options'!A:A)-1 -> 3780 | F4: =SUM('NSE - NIFTY Index Options'!L:L) -> 10395049
A5: NSE | B5: NSE - Other Index Options | C5: ='NSE - Other Index Options'!A2 -> 01-Sep-2025 | D5: =LOOKUP(2,1/('NSE - Other Index Options'!$A$2:$A$100000<>""),'NSE - Other Index Options'!$A$2:$A$100000) -> 08-Jul-2026 | E5: =COUNTA('NSE - Other Index Options'!A:A)-1 -> 1260 | F5: =SUM('NSE - Other Index Options'!L:L) -> 1130835
A6: BSE | B6: BSE - SENSEX Index Options | C6: ='BSE - SENSEX Index Options'!A2 -> 01-Sep-2025 | D6: =LOOKUP(2,1/('BSE - SENSEX Index Options'!$A$2:$A$100000<>""),'BSE - SENSEX Index Options'!$A$2:$A$100000) -> 08-Jul-2026 | E6: =COUNTA('BSE - SENSEX Index Options'!A:A)-1 -> 1367 | F6: =SUM('BSE - SENSEX Index Options'!L:L) -> 5219777.2
A7: BSE | B7: BSE - Other Index Options | C7: ='BSE - Other Index Options'!A2 -> 01-Sep-2025 | D7: =LOOKUP(2,1/('BSE - Other Index Options'!$A$2:$A$100000<>""),'BSE - Other Index Options'!$A$2:$A$100000) -> 08-Jul-2026 | E7: =COUNTA('BSE - Other Index Options'!A:A)-1 -> 389 | F7: =SUM('BSE - Other Index Options'!L:L) -> 13306
A9: NSE data updated through: | B9: =IF(D4=D5,D4,"MISMATCH between NSE sheets") -> 08-Jul-2026
A10: BSE data updated through: | B10: =IF(D6=D7,D6,"MISMATCH between BSE sheets") -> 08-Jul-2026
A11: NSE & BSE end dates aligned? | B11: =IF(B9=B10,"YES","NO — update the lagging exchange") -> YES
A12: Master file created: | B12: 46210
A13: Last data refresh: | B13: 46212
A14: Monthly Totals (live — populates as data is updated)
A15: Month | B15: NSE - Number of Contracts | C15: NSE - Notional Turnover (INR Crs) | D15: NSE - Premium Turnover (INR Crs) | E15: BSE - Number of Contracts | F15: BSE - Notional Turnover (INR Crs) | G15: BSE - Premium Turnover (INR Crs)
A16: 45901 | B16: =IF(SUMIFS('NSE - NIFTY Index Options'!$J:$J,'NSE - NIFTY Index Options'!$D:$D,$A16)+SUMIFS('NSE - Other Index Options'!$J:$J,'NSE - Other Index Options'!$D:$D,$A16)=0,"",SUMIFS('NSE - NIFTY Index Options'!$J:$J,'NSE - NIFTY Index Options'!$D:$D,$A16)+SUMIFS('NSE - Other Index Options'!$J:$J,'NSE - Other Index Options'!$D:$D,$A16)) -> 3099992966 | C16: =IF(SUMIFS('NSE - NIFTY Index Options'!$K:$K,'NSE - NIFTY Index Options'!$D:$D,$A16)+SUMIFS('NSE - Other Index Options'!$K:$K,'NSE - Other Index Options'!$D:$D,$A16)=0,"",SUMIFS('NSE - NIFTY Index Options'!$K:$K,'NSE - NIFTY Index Options'!$D:$D,$A16)+SUMIFS('NSE - Other Index Options'!$K:$K,'NSE - Other Index Options'!$D:$D,$A16)) -> 5.8073345e+08 | D16: =IF(SUMIFS('NSE - NIFTY Index Options'!$L:$L,'NSE - NIFTY Index Options'!$D:$D,$A16)+SUMIFS('NSE - Other Index Options'!$L:$L,'NSE - Other Index Options'!$D:$D,$A16)=0,"",SUMIFS('NSE - NIFTY Index Options'!$L:$L,'NSE - NIFTY Index Options'!$D:$D,$A16)+SUMIFS('NSE - Other Index Options'!$L:$L,'NSE - Other Index Options'!$D:$D,$A16)) -> 933317.58 | E16: =IF(SUMIFS('BSE - SENSEX Index Options'!$J:$J,'BSE - SENSEX Index Options'!$D:$D,$A16)+SUMIFS('BSE - Other Index Options'!$J:$J,'BSE - Other Index Options'!$D:$D,$A16)=0,"",SUMIFS('BSE - SENSEX Index Options'!$J:$J,'BSE - SENSEX Index Options'!$D:$D,$A16)+SUMIFS('BSE - Other Index Options'!$J:$J,'BSE - Other Index Options'!$D:$D,$A16)) -> 2235360301 | F16: =IF(SUMIFS('BSE - SENSEX Index Options'!$K:$K,'BSE - SENSEX Index Options'!$D:$D,$A16)+SUMIFS('BSE - Other Index Options'!$K:$K,'BSE - Other Index Options'!$D:$D,$A16)=0,"",SUMIFS('BSE - SENSEX Index Options'!$K:$K,'BSE - SENSEX Index Options'!$D:$D,$A16)+SUMIFS('BSE - Other Index Options'!$K:$K,'BSE - Other Index Options'!$D:$D,$A16)) -> 3.6518155e+08 | G16: =IF(SUMIFS('BSE - SENSEX Index Options'!$L:$L,'BSE - SENSEX Index Options'!$D:$D,$A16)+SUMIFS('BSE - Other Index Options'!$L:$L,'BSE - Other Index Options'!$D:$D,$A16)=0,"",SUMIFS('BSE - SENSEX Index Options'!$L:$L,'BSE - SENSEX Index Options'!$D:$D,$A16)+SUMIFS('BSE - Other Index Options'!$L:$L,'BSE - Other Index Options'!$D:$D,$A16)) -> 346224.72
A17: 45931 | B17: =IF(SUMIFS('NSE - NIFTY Index Options'!$J:$J,'NSE - NIFTY Index Options'!$D:$D,$A17)+SUMIFS('NSE - Other Index Options'!$J:$J,'NSE - Other Index Options'!$D:$D,$A17)=0,"",SUMIFS('NSE - NIFTY Index Options'!$J:$J,'NSE - NIFTY Index Options'!$D:$D,$A17)+SUMIFS('NSE - Other Index Options'!$J:$J,'NSE - Other Index Options'!$D:$D,$A17)) -> 3053547719 | C17: =IF(SUMIFS('NSE - NIFTY Index Options'!$K:$K,'NSE - NIFTY Index Options'!$D:$D,$A17)+SUMIFS('NSE - Other Index Options'!$K:$K,'NSE - Other Index Options'!$D:$D,$A17)=0,"",SUMIFS('NSE - NIFTY Index Options'!$K:$K,'NSE - NIFTY Index Options'!$D:$D,$A17)+SUMIFS('NSE - Other Index Options'!$K:$K,'NSE - Other Index Options'!$D:$D,$A17)) -> 5.859561e+08 | D17: =IF(SUMIFS('NSE - NIFTY Index Options'!$L:$L,'NSE - NIFTY Index Options'!$D:$D,$A17)+SUMIFS('NSE - Other Index Options'!$L:$L,'NSE - Other Index Options'!$D:$D,$A17)=0,"",SUMIFS('NSE - NIFTY Index Options'!$L:$L,'NSE - NIFTY Index Options'!$D:$D,$A17)+SUMIFS('NSE - Other Index Options'!$L:$L,'NSE - Other Index Options'!$D:$D,$A17)) -> 1041799 | E17: =IF(SUMIFS('BSE - SENSEX Index Options'!$J:$J,'BSE - SENSEX Index Options'!$D:$D,$A17)+SUMIFS('BSE - Other Index Options'!$J:$J,'BSE - Other Index Options'!$D:$D,$A17)=0,"",SUMIFS('BSE - SENSEX Index Options'!$J:$J,'BSE - SENSEX Index Options'!$D:$D,$A17)+SUMIFS('BSE - Other Index Options'!$J:$J,'BSE - Other Index Options'!$D:$D,$A17)) -> 2790051623 | F17: =IF(SUMIFS('BSE - SENSEX Index Options'!$K:$K,'BSE - SENSEX Index Options'!$D:$D,$A17)+SUMIFS('BSE - Other Index Options'!$K:$K,'BSE - Other Index Options'!$D:$D,$A17)=0,"",SUMIFS('BSE - SENSEX Index Options'!$K:$K,'BSE - SENSEX Index Options'!$D:$D,$A17)+SUMIFS('BSE - Other Index Options'!$K:$K,'BSE - Other Index Options'!$D:$D,$A17)) -> 4.6412525e+08 | G17: =IF(SUMIFS('BSE - SENSEX Index Options'!$L:$L,'BSE - SENSEX Index Options'!$D:$D,$A17)+SUMIFS('BSE - Other Index Options'!$L:$L,'BSE - Other Index Options'!$D:$D,$A17)=0,"",SUMIFS('BSE - SENSEX Index Options'!$L:$L,'BSE - SENSEX Index Options'!$D:$D,$A17)+SUMIFS('BSE - Other Index Options'!$L:$L,'BSE - Other Index Options'!$D:$D,$A17)) -> 430427.39
A18: 45962 | B18: =IF(SUMIFS('NSE - NIFTY Index Options'!$J:$J,'NSE - NIFTY Index Options'!$D:$D,$A18)+SUMIFS('NSE - Other Index Options'!$J:$J,'NSE - Other Index Options'!$D:$D,$A18)=0,"",SUMIFS('NSE - NIFTY Index Options'!$J:$J,'NSE - NIFTY Index Options'!$D:$D,$A18)+SUMIFS('NSE - Other Index Options'!$J:$J,'NSE - Other Index Options'!$D:$D,$A18)) -> 2587888973 | C18: =IF(SUMIFS('NSE - NIFTY Index Options'!$K:$K,'NSE - NIFTY Index Options'!$D:$D,$A18)+SUMIFS('NSE - Other Index Options'!$K:$K,'NSE - Other Index Options'!$D:$D,$A18)=0,"",SUMIFS('NSE - NIFTY Index Options'!$K:$K,'NSE - NIFTY Index Options'!$D:$D,$A18)+SUMIFS('NSE - Other Index Options'!$K:$K,'NSE - Other Index Options'!$D:$D,$A18)) -> 5.0405879e+08 | D18: =IF(SUMIFS('NSE - NIFTY Index Options'!$L:$L,'NSE - NIFTY Index Options'!$D:$D,$A18)+SUMIFS('NSE - Other Index Options'!$L:$L,'NSE - Other Index Options'!$D:$D,$A18)=0,"",SUMIFS('NSE - NIFTY Index Options'!$L:$L,'NSE - NIFTY Index Options'!$D:$D,$A18)+SUMIFS('NSE - Other Index Options'!$L:$L,'NSE - Other Index Options'!$D:$D,$A18)) -> 913277.33 | E18: =IF(SUMIFS('BSE - SENSEX Index Options'!$J:$J,'BSE - SENSEX Index Options'!$D:$D,$A18)+SUMIFS('BSE - Other Index Options'!$J:$J,'BSE - Other Index Options'!$D:$D,$A18)=0,"",SUMIFS('BSE - SENSEX Index Options'!$J:$J,'BSE - SENSEX Index Options'!$D:$D,$A18)+SUMIFS('BSE - Other Index Options'!$J:$J,'BSE - Other Index Options'!$D:$D,$A18)) -> 2335516230 | F18: =IF(SUMIFS('BSE - SENSEX Index Options'!$K:$K,'BSE - SENSEX Index Options'!$D:$D,$A18)+SUMIFS('BSE - Other Index Options'!$K:$K,'BSE - Other Index Options'!$D:$D,$A18)=0,"",SUMIFS('BSE - SENSEX Index Options'!$K:$K,'BSE - SENSEX Index Options'!$D:$D,$A18)+SUMIFS('BSE - Other Index Options'!$K:$K,'BSE - Other Index Options'!$D:$D,$A18)) -> 3.963897e+08 | G18: =IF(SUMIFS('BSE - SENSEX Index Options'!$L:$L,'BSE - SENSEX Index Options'!$D:$D,$A18)+SUMIFS('BSE - Other Index Options'!$L:$L,'BSE - Other Index Options'!$D:$D,$A18)=0,"",SUMIFS('BSE - SENSEX Index Options'!$L:$L,'BSE - SENSEX Index Options'!$D:$D,$A18)+SUMIFS('BSE - Other Index Options'!$L:$L,'BSE - Other Index Options'!$D:$D,$A18)) -> 363132.11
A19: 45992 | B19: =IF(SUMIFS('NSE - NIFTY Index Options'!$J:$J,'NSE - NIFTY Index Options'!$D:$D,$A19)+SUMIFS('NSE - Other Index Options'!$J:$J,'NSE - Other Index Options'!$D:$D,$A19)=0,"",SUMIFS('NSE - NIFTY Index Options'!$J:$J,'NSE - NIFTY Index Options'!$D:$D,$A19)+SUMIFS('NSE - Other Index Options'!$J:$J,'NSE - Other Index Options'!$D:$D,$A19)) -> 2990707367 | C19: =IF(SUMIFS('NSE - NIFTY Index Options'!$K:$K,'NSE - NIFTY Index Options'!$D:$D,$A19)+SUMIFS('NSE - Other Index Options'!$K:$K,'NSE - Other Index Options'!$D:$D,$A19)=0,"",SUMIFS('NSE - NIFTY Index Options'!$K:$K,'NSE - NIFTY Index Options'!$D:$D,$A19)+SUMIFS('NSE - Other Index Options'!$K:$K,'NSE - Other Index Options'!$D:$D,$A19)) -> 5.8344601e+08 | D19: =IF(SUMIFS('NSE - NIFTY Index Options'!$L:$L,'NSE - NIFTY Index Options'!$D:$D,$A19)+SUMIFS('NSE - Other Index Options'!$L:$L,'NSE - Other Index Options'!$D:$D,$A19)=0,"",SUMIFS('NSE - NIFTY Index Options'!$L:$L,'NSE - NIFTY Index Options'!$D:$D,$A19)+SUMIFS('NSE - Other Index Options'!$L:$L,'NSE - Other Index Options'!$D:$D,$A19)) -> 946922.96 | E19: =IF(SUMIFS('BSE - SENSEX Index Options'!$J:$J,'BSE - SENSEX Index Options'!$D:$D,$A19)+SUMIFS('BSE - Other Index Options'!$J:$J,'BSE - Other Index Options'!$D:$D,$A19)=0,"",SUMIFS('BSE - SENSEX Index Options'!$J:$J,'BSE - SENSEX Index Options'!$D:$D,$A19)+SUMIFS('BSE - Other Index Options'!$J:$J,'BSE - Other Index Options'!$D:$D,$A19)) -> 2594328292 | F19: =IF(SUMIFS('BSE - SENSEX Index Options'!$K:$K,'BSE - SENSEX Index Options'!$D:$D,$A19)+SUMIFS('BSE - Other Index Options'!$K:$K,'BSE - Other Index Options'!$D:$D,$A19)=0,"",SUMIFS('BSE - SENSEX Index Options'!$K:$K,'BSE - SENSEX Index Options'!$D:$D,$A19)+SUMIFS('BSE - Other Index Options'!$K:$K,'BSE - Other Index Options'!$D:$D,$A19)) -> 4.4144495e+08 | G19: =IF(SUMIFS('BSE - SENSEX Index Options'!$L:$L,'BSE - SENSEX Index Options'!$D:$D,$A19)+SUMIFS('BSE - Other Index Options'!$L:$L,'BSE - Other Index Options'!$D:$D,$A19)=0,"",SUMIFS('BSE - SENSEX Index Options'!$L:$L,'BSE - SENSEX Index Options'!$D:$D,$A19)+SUMIFS('BSE - Other Index Options'!$L:$L,'BSE - Other Index Options'!$D:$D,$A19)) -> 412902.5
A20: 46023 | B20: =IF(SUMIFS('NSE - NIFTY Index Options'!$J:$J,'NSE - NIFTY Index Options'!$D:$D,$A20)+SUMIFS('NSE - Other Index Options'!$J:$J,'NSE - Other Index Options'!$D:$D,$A20)=0,"",SUMIFS('NSE - NIFTY Index Options'!$J:$J,'NSE - NIFTY Index Options'!$D:$D,$A20)+SUMIFS('NSE - Other Index Options'!$J:$J,'NSE - Other Index Options'!$D:$D,$A20)) -> 3556776860 | C20: =IF(SUMIFS('NSE - NIFTY Index Options'!$K:$K,'NSE - NIFTY Index Options'!$D:$D,$A20)+SUMIFS('NSE - Other Index Options'!$K:$K,'NSE - Other Index Options'!$D:$D,$A20)=0,"",SUMIFS('NSE - NIFTY Index Options'!$K:$K,'NSE - NIFTY Index Options'!$D:$D,$A20)+SUMIFS('NSE - Other Index Options'!$K:$K,'NSE - Other Index Options'!$D:$D,$A20)) -> 5.9597918e+08 | D20: =IF(SUMIFS('NSE - NIFTY Index Options'!$L:$L,'NSE - NIFTY Index Options'!$D:$D,$A20)+SUMIFS('NSE - Other Index Options'!$L:$L,'NSE - Other Index Options'!$D:$D,$A20)=0,"",SUMIFS('NSE - NIFTY Index Options'!$L:$L,'NSE - NIFTY Index Options'!$D:$D,$A20)+SUMIFS('NSE - Other Index Options'!$L:$L,'NSE - Other Index Options'!$D:$D,$A20)) -> 1153154 | E20: =IF(SUMIFS('BSE - SENSEX Index Options'!$J:$J,'BSE - SENSEX Index Options'!$D:$D,$A20)+SUMIFS('BSE - Other Index Options'!$J:$J,'BSE - Other Index Options'!$D:$D,$A20)=0,"",SUMIFS('BSE - SENSEX Index Options'!$J:$J,'BSE - SENSEX Index Options'!$D:$D,$A20)+SUMIFS('BSE - Other Index Options'!$J:$J,'BSE - Other Index Options'!$D:$D,$A20)) -> 3431358943 | F20: =IF(SUMIFS('BSE - SENSEX Index Options'!$K:$K,'BSE - SENSEX Index Options'!$D:$D,$A20)+SUMIFS('BSE - Other Index Options'!$K:$K,'BSE - Other Index Options'!$D:$D,$A20)=0,"",SUMIFS('BSE - SENSEX Index Options'!$K:$K,'BSE - SENSEX Index Options'!$D:$D,$A20)+SUMIFS('BSE - Other Index Options'!$K:$K,'BSE - Other Index Options'!$D:$D,$A20)) -> 5.7316405e+08 | G20: =IF(SUMIFS('BSE - SENSEX Index Options'!$L:$L,'BSE - SENSEX Index Options'!$D:$D,$A20)+SUMIFS('BSE - Other Index Options'!$L:$L,'BSE - Other Index Options'!$D:$D,$A20)=0,"",SUMIFS('BSE - SENSEX Index Options'!$L:$L,'BSE - SENSEX Index Options'!$D:$D,$A20)+SUMIFS('BSE - Other Index Options'!$L:$L,'BSE - Other Index Options'!$D:$D,$A20)) -> 575377.84
A21: 46054 | B21: =IF(SUMIFS('NSE - NIFTY Index Options'!$J:$J,'NSE - NIFTY Index Options'!$D:$D,$A21)+SUMIFS('NSE - Other Index Options'!$J:$J,'NSE - Other Index Options'!$D:$D,$A21)=0,"",SUMIFS('NSE - NIFTY Index Options'!$J:$J,'NSE - NIFTY Index Options'!$D:$D,$A21)+SUMIFS('NSE - Other Index Options'!$J:$J,'NSE - Other Index Options'!$D:$D,$A21)) -> 3553974028 | C21: =IF(SUMIFS('NSE - NIFTY Index Options'!$K:$K,'NSE - NIFTY Index Options'!$D:$D,$A21)+SUMIFS('NSE - Other Index Options'!$K:$K,'NSE - Other Index Options'!$D:$D,$A21)=0,"",SUMIFS('NSE - NIFTY Index Options'!$K:$K,'NSE - NIFTY Index Options'!$D:$D,$A21)+SUMIFS('NSE - Other Index Options'!$K:$K,'NSE - Other Index Options'!$D:$D,$A21)) -> 5.9499979e+08 | D21: =IF(SUMIFS('NSE - NIFTY Index Options'!$L:$L,'NSE - NIFTY Index Options'!$D:$D,$A21)+SUMIFS('NSE - Other Index Options'!$L:$L,'NSE - Other Index Options'!$D:$D,$A21)=0,"",SUMIFS('NSE - NIFTY Index Options'!$L:$L,'NSE - NIFTY Index Options'!$D:$D,$A21)+SUMIFS('NSE - Other Index Options'!$L:$L,'NSE - Other Index Options'!$D:$D,$A21)) -> 1283969.3 | E21: =IF(SUMIFS('BSE - SENSEX Index Options'!$J:$J,'BSE - SENSEX Index Options'!$D:$D,$A21)+SUMIFS('BSE - Other Index Options'!$J:$J,'BSE - Other Index Options'!$D:$D,$A21)=0,"",SUMIFS('BSE - SENSEX Index Options'!$J:$J,'BSE - SENSEX Index Options'!$D:$D,$A21)+SUMIFS('BSE - Other Index Options'!$J:$J,'BSE - Other Index Options'!$D:$D,$A21)) -> 2818479299 | F21: =IF(SUMIFS('BSE - SENSEX Index Options'!$K:$K,'BSE - SENSEX Index Options'!$D:$D,$A21)+SUMIFS('BSE - Other Index Options'!$K:$K,'BSE - Other Index Options'!$D:$D,$A21)=0,"",SUMIFS('BSE - SENSEX Index Options'!$K:$K,'BSE - SENSEX Index Options'!$D:$D,$A21)+SUMIFS('BSE - Other Index Options'!$K:$K,'BSE - Other Index Options'!$D:$D,$A21)) -> 4.6934097e+08 | G21: =IF(SUMIFS('BSE - SENSEX Index Options'!$L:$L,'BSE - SENSEX Index Options'!$D:$D,$A21)+SUMIFS('BSE - Other Index Options'!$L:$L,'BSE - Other Index Options'!$D:$D,$A21)=0,"",SUMIFS('BSE - SENSEX Index Options'!$L:$L,'BSE - SENSEX Index Options'!$D:$D,$A21)+SUMIFS('BSE - Other Index Options'!$L:$L,'BSE - Other Index Options'!$D:$D,$A21)) -> 532063.59
A22: 46082 | B22: =IF(SUMIFS('NSE - NIFTY Index Options'!$J:$J,'NSE - NIFTY Index Options'!$D:$D,$A22)+SUMIFS('NSE - Other Index Options'!$J:$J,'NSE - Other Index Options'!$D:$D,$A22)=0,"",SUMIFS('NSE - NIFTY Index Options'!$J:$J,'NSE - NIFTY Index Options'!$D:$D,$A22)+SUMIFS('NSE - Other Index Options'!$J:$J,'NSE - Other Index Options'!$D:$D,$A22)) -> 3507526776 | C22: =IF(SUMIFS('NSE - NIFTY Index Options'!$K:$K,'NSE - NIFTY Index Options'!$D:$D,$A22)+SUMIFS('NSE - Other Index Options'!$K:$K,'NSE - Other Index Options'!$D:$D,$A22)=0,"",SUMIFS('NSE - NIFTY Index Options'!$K:$K,'NSE - NIFTY Index Options'!$D:$D,$A22)+SUMIFS('NSE - Other Index Options'!$K:$K,'NSE - Other Index Options'!$D:$D,$A22)) -> 5.41044e+08 | D22: =IF(SUMIFS('NSE - NIFTY Index Options'!$L:$L,'NSE - NIFTY Index Options'!$D:$D,$A22)+SUMIFS('NSE - Other Index Options'!$L:$L,'NSE - Other Index Options'!$D:$D,$A22)=0,"",SUMIFS('NSE - NIFTY Index Options'!$L:$L,'NSE - NIFTY Index Options'!$D:$D,$A22)+SUMIFS('NSE - Other Index Options'!$L:$L,'NSE - Other Index Options'!$D:$D,$A22)) -> 1624667.9 | E22: =IF(SUMIFS('BSE - SENSEX Index Options'!$J:$J,'BSE - SENSEX Index Options'!$D:$D,$A22)+SUMIFS('BSE - Other Index Options'!$J:$J,'BSE - Other Index Options'!$D:$D,$A22)=0,"",SUMIFS('BSE - SENSEX Index Options'!$J:$J,'BSE - SENSEX Index Options'!$D:$D,$A22)+SUMIFS('BSE - Other Index Options'!$J:$J,'BSE - Other Index Options'!$D:$D,$A22)) -> 2780655501 | F22: =IF(SUMIFS('BSE - SENSEX Index Options'!$K:$K,'BSE - SENSEX Index Options'!$D:$D,$A22)+SUMIFS('BSE - Other Index Options'!$K:$K,'BSE - Other Index Options'!$D:$D,$A22)=0,"",SUMIFS('BSE - SENSEX Index Options'!$K:$K,'BSE - SENSEX Index Options'!$D:$D,$A22)+SUMIFS('BSE - Other Index Options'!$K:$K,'BSE - Other Index Options'!$D:$D,$A22)) -> 4.2746291e+08 | G22: =IF(SUMIFS('BSE - SENSEX Index Options'!$L:$L,'BSE - SENSEX Index Options'!$D:$D,$A22)+SUMIFS('BSE - Other Index Options'!$L:$L,'BSE - Other Index Options'!$D:$D,$A22)=0,"",SUMIFS('BSE - SENSEX Index Options'!$L:$L,'BSE - SENSEX Index Options'!$D:$D,$A22)+SUMIFS('BSE - Other Index Options'!$L:$L,'BSE - Other Index Options'!$D:$D,$A22)) -> 627803.99
A23: 46113 | B23: =IF(SUMIFS('NSE - NIFTY Index Options'!$J:$J,'NSE - NIFTY Index Options'!$D:$D,$A23)+SUMIFS('NSE - Other Index Options'!$J:$J,'NSE - Other Index Options'!$D:$D,$A23)=0,"",SUMIFS('NSE - NIFTY Index Options'!$J:$J,'NSE - NIFTY Index Options'!$D:$D,$A23)+SUMIFS('NSE - Other Index Options'!$J:$J,'NSE - Other Index Options'!$D:$D,$A23)) -> 2704917038 | C23: =IF(SUMIFS('NSE - NIFTY Index Options'!$K:$K,'NSE - NIFTY Index Options'!$D:$D,$A23)+SUMIFS('NSE - Other Index Options'!$K:$K,'NSE - Other Index Options'!$D:$D,$A23)=0,"",SUMIFS('NSE - NIFTY Index Options'!$K:$K,'NSE - NIFTY Index Options'!$D:$D,$A23)+SUMIFS('NSE - Other Index Options'!$K:$K,'NSE - Other Index Options'!$D:$D,$A23)) -> 4.2128809e+08 | D23: =IF(SUMIFS('NSE - NIFTY Index Options'!$L:$L,'NSE - NIFTY Index Options'!$D:$D,$A23)+SUMIFS('NSE - Other Index Options'!$L:$L,'NSE - Other Index Options'!$D:$D,$A23)=0,"",SUMIFS('NSE - NIFTY Index Options'!$L:$L,'NSE - NIFTY Index Options'!$D:$D,$A23)+SUMIFS('NSE - Other Index Options'!$L:$L,'NSE - Other Index Options'!$D:$D,$A23)) -> 1124391.5 | E23: =IF(SUMIFS('BSE - SENSEX Index Options'!$J:$J,'BSE - SENSEX Index Options'!$D:$D,$A23)+SUMIFS('BSE - Other Index Options'!$J:$J,'BSE - Other Index Options'!$D:$D,$A23)=0,"",SUMIFS('BSE - SENSEX Index Options'!$J:$J,'BSE - SENSEX Index Options'!$D:$D,$A23)+SUMIFS('BSE - Other Index Options'!$J:$J,'BSE - Other Index Options'!$D:$D,$A23)) -> 3511987765 | F23: =IF(SUMIFS('BSE - SENSEX Index Options'!$K:$K,'BSE - SENSEX Index Options'!$D:$D,$A23)+SUMIFS('BSE - Other Index Options'!$K:$K,'BSE - Other Index Options'!$D:$D,$A23)=0,"",SUMIFS('BSE - SENSEX Index Options'!$K:$K,'BSE - SENSEX Index Options'!$D:$D,$A23)+SUMIFS('BSE - Other Index Options'!$K:$K,'BSE - Other Index Options'!$D:$D,$A23)) -> 5.3776498e+08 | G23: =IF(SUMIFS('BSE - SENSEX Index Options'!$L:$L,'BSE - SENSEX Index Options'!$D:$D,$A23)+SUMIFS('BSE - Other Index Options'!$L:$L,'BSE - Other Index Options'!$D:$D,$A23)=0,"",SUMIFS('BSE - SENSEX Index Options'!$L:$L,'BSE - SENSEX Index Options'!$D:$D,$A23)+SUMIFS('BSE - Other Index Options'!$L:$L,'BSE - Other Index Options'!$D:$D,$A23)) -> 662899.61
A24: 46143 | B24: =IF(SUMIFS('NSE - NIFTY Index Options'!$J:$J,'NSE - NIFTY Index Options'!$D:$D,$A24)+SUMIFS('NSE - Other Index Options'!$J:$J,'NSE - Other Index Options'!$D:$D,$A24)=0,"",SUMIFS('NSE - NIFTY Index Options'!$J:$J,'NSE - NIFTY Index Options'!$D:$D,$A24)+SUMIFS('NSE - Other Index Options'!$J:$J,'NSE - Other Index Options'!$D:$D,$A24)) -> 3038254197 | C24: =IF(SUMIFS('NSE - NIFTY Index Options'!$K:$K,'NSE - NIFTY Index Options'!$D:$D,$A24)+SUMIFS('NSE - Other Index Options'!$K:$K,'NSE - Other Index Options'!$D:$D,$A24)=0,"",SUMIFS('NSE - NIFTY Index Options'!$K:$K,'NSE - NIFTY Index Options'!$D:$D,$A24)+SUMIFS('NSE - Other Index Options'!$K:$K,'NSE - Other Index Options'!$D:$D,$A24)) -> 4.7374534e+08 | D24: =IF(SUMIFS('NSE - NIFTY Index Options'!$L:$L,'NSE - NIFTY Index Options'!$D:$D,$A24)+SUMIFS('NSE - Other Index Options'!$L:$L,'NSE - Other Index Options'!$D:$D,$A24)=0,"",SUMIFS('NSE - NIFTY Index Options'!$L:$L,'NSE - NIFTY Index Options'!$D:$D,$A24)+SUMIFS('NSE - Other Index Options'!$L:$L,'NSE - Other Index Options'!$D:$D,$A24)) -> 1112871.6 | E24: =IF(SUMIFS('BSE - SENSEX Index Options'!$J:$J,'BSE - SENSEX Index Options'!$D:$D,$A24)+SUMIFS('BSE - Other Index Options'!$J:$J,'BSE - Other Index Options'!$D:$D,$A24)=0,"",SUMIFS('BSE - SENSEX Index Options'!$J:$J,'BSE - SENSEX Index Options'!$D:$D,$A24)+SUMIFS('BSE - Other Index Options'!$J:$J,'BSE - Other Index Options'!$D:$D,$A24)) -> 2859237260 | F24: =IF(SUMIFS('BSE - SENSEX Index Options'!$K:$K,'BSE - SENSEX Index Options'!$D:$D,$A24)+SUMIFS('BSE - Other Index Options'!$K:$K,'BSE - Other Index Options'!$D:$D,$A24)=0,"",SUMIFS('BSE - SENSEX Index Options'!$K:$K,'BSE - SENSEX Index Options'!$D:$D,$A24)+SUMIFS('BSE - Other Index Options'!$K:$K,'BSE - Other Index Options'!$D:$D,$A24)) -> 4.3603399e+08 | G24: =IF(SUMIFS('BSE - SENSEX Index Options'!$L:$L,'BSE - SENSEX Index Options'!$D:$D,$A24)+SUMIFS('BSE - Other Index Options'!$L:$L,'BSE - Other Index Options'!$D:$D,$A24)=0,"",SUMIFS('BSE - SENSEX Index Options'!$L:$L,'BSE - SENSEX Index Options'!$D:$D,$A24)+SUMIFS('BSE - Other Index Options'!$L:$L,'BSE - Other Index Options'!$D:$D,$A24)) -> 563688.26
A25: 46174 | B25: =IF(SUMIFS('NSE - NIFTY Index Options'!$J:$J,'NSE - NIFTY Index Options'!$D:$D,$A25)+SUMIFS('NSE - Other Index Options'!$J:$J,'NSE - Other Index Options'!$D:$D,$A25)=0,"",SUMIFS('NSE - NIFTY Index Options'!$J:$J,'NSE - NIFTY Index Options'!$D:$D,$A25)+SUMIFS('NSE - Other Index Options'!$J:$J,'NSE - Other Index Options'!$D:$D,$A25)) -> 3676370909 | C25: =IF(SUMIFS('NSE - NIFTY Index Options'!$K:$K,'NSE - NIFTY Index Options'!$D:$D,$A25)+SUMIFS('NSE - Other Index Options'!$K:$K,'NSE - Other Index Options'!$D:$D,$A25)=0,"",SUMIFS('NSE - NIFTY Index Options'!$K:$K,'NSE - NIFTY Index Options'!$D:$D,$A25)+SUMIFS('NSE - Other Index Options'!$K:$K,'NSE - Other Index Options'!$D:$D,$A25)) -> 5.7035593e+08 | D25: =IF(SUMIFS('NSE - NIFTY Index Options'!$L:$L,'NSE - NIFTY Index Options'!$D:$D,$A25)+SUMIFS('NSE - Other Index Options'!$L:$L,'NSE - Other Index Options'!$D:$D,$A25)=0,"",SUMIFS('NSE - NIFTY Index Options'!$L:$L,'NSE - NIFTY Index Options'!$D:$D,$A25)+SUMIFS('NSE - Other Index Options'!$L:$L,'NSE - Other Index Options'!$D:$D,$A25)) -> 1148733.7 | E25: =IF(SUMIFS('BSE - SENSEX Index Options'!$J:$J,'BSE - SENSEX Index Options'!$D:$D,$A25)+SUMIFS('BSE - Other Index Options'!$J:$J,'BSE - Other Index Options'!$D:$D,$A25)=0,"",SUMIFS('BSE - SENSEX Index Options'!$J:$J,'BSE - SENSEX Index Options'!$D:$D,$A25)+SUMIFS('BSE - Other Index Options'!$J:$J,'BSE - Other Index Options'!$D:$D,$A25)) -> 2968566958 | F25: =IF(SUMIFS('BSE - SENSEX Index Options'!$K:$K,'BSE - SENSEX Index Options'!$D:$D,$A25)+SUMIFS('BSE - Other Index Options'!$K:$K,'BSE - Other Index Options'!$D:$D,$A25)=0,"",SUMIFS('BSE - SENSEX Index Options'!$K:$K,'BSE - SENSEX Index Options'!$D:$D,$A25)+SUMIFS('BSE - Other Index Options'!$K:$K,'BSE - Other Index Options'!$D:$D,$A25)) -> 4.497161e+08 | G25: =IF(SUMIFS('BSE - SENSEX Index Options'!$L:$L,'BSE - SENSEX Index Options'!$D:$D,$A25)+SUMIFS('BSE - Other Index Options'!$L:$L,'BSE - Other Index Options'!$D:$D,$A25)=0,"",SUMIFS('BSE - SENSEX Index Options'!$L:$L,'BSE - SENSEX Index Options'!$D:$D,$A25)+SUMIFS('BSE - Other Index Options'!$L:$L,'BSE - Other Index Options'!$D:$D,$A25)) -> 550333.89
A26: 46204 | B26: =IF(SUMIFS('NSE - NIFTY Index Options'!$J:$J,'NSE - NIFTY Index Options'!$D:$D,$A26)+SUMIFS('NSE - Other Index Options'!$J:$J,'NSE - Other Index Options'!$D:$D,$A26)=0,"",SUMIFS('NSE - NIFTY Index Options'!$J:$J,'NSE - NIFTY Index Options'!$D:$D,$A26)+SUMIFS('NSE - Other Index Options'!$J:$J,'NSE - Other Index Options'!$D:$D,$A26)) -> 773569308 | C26: =IF(SUMIFS('NSE - NIFTY Index Options'!$K:$K,'NSE - NIFTY Index Options'!$D:$D,$A26)+SUMIFS('NSE - Other Index Options'!$K:$K,'NSE - Other Index Options'!$D:$D,$A26)=0,"",SUMIFS('NSE - NIFTY Index Options'!$K:$K,'NSE - NIFTY Index Options'!$D:$D,$A26)+SUMIFS('NSE - Other Index Options'!$K:$K,'NSE - Other Index Options'!$D:$D,$A26)) -> 1.2267554e+08 | D26: =IF(SUMIFS('NSE - NIFTY Index Options'!$L:$L,'NSE - NIFTY Index Options'!$D:$D,$A26)+SUMIFS('NSE - Other Index Options'!$L:$L,'NSE - Other Index Options'!$D:$D,$A26)=0,"",SUMIFS('NSE - NIFTY Index Options'!$L:$L,'NSE - NIFTY Index Options'!$D:$D,$A26)+SUMIFS('NSE - Other Index Options'!$L:$L,'NSE - Other Index Options'!$D:$D,$A26)) -> 242778.79 | E26: =IF(SUMIFS('BSE - SENSEX Index Options'!$J:$J,'BSE - SENSEX Index Options'!$D:$D,$A26)+SUMIFS('BSE - Other Index Options'!$J:$J,'BSE - Other Index Options'!$D:$D,$A26)=0,"",SUMIFS('BSE - SENSEX Index Options'!$J:$J,'BSE - SENSEX Index Options'!$D:$D,$A26)+SUMIFS('BSE - Other Index Options'!$J:$J,'BSE - Other Index Options'!$D:$D,$A26)) -> 845622618 | F26: =IF(SUMIFS('BSE - SENSEX Index Options'!$K:$K,'BSE - SENSEX Index Options'!$D:$D,$A26)+SUMIFS('BSE - Other Index Options'!$K:$K,'BSE - Other Index Options'!$D:$D,$A26)=0,"",SUMIFS('BSE - SENSEX Index Options'!$K:$K,'BSE - SENSEX Index Options'!$D:$D,$A26)+SUMIFS('BSE - Other Index Options'!$K:$K,'BSE - Other Index Options'!$D:$D,$A26)) -> 1.3085316e+08 | G26: =IF(SUMIFS('BSE - SENSEX Index Options'!$L:$L,'BSE - SENSEX Index Options'!$D:$D,$A26)+SUMIFS('BSE - Other Index Options'!$L:$L,'BSE - Other Index Options'!$D:$D,$A26)=0,"",SUMIFS('BSE - SENSEX Index Options'!$L:$L,'BSE - SENSEX Index Options'!$D:$D,$A26)+SUMIFS('BSE - Other Index Options'!$L:$L,'BSE - Other Index Options'!$D:$D,$A26)) -> 168229.27
A27: 46235 | B27: =IF(SUMIFS('NSE - NIFTY Index Options'!$J:$J,'NSE - NIFTY Index Options'!$D:$D,$A27)+SUMIFS('NSE - Other Index Options'!$J:$J,'NSE - Other Index Options'!$D:$D,$A27)=0,"",SUMIFS('NSE - NIFTY Index Options'!$J:$J,'NSE - NIFTY Index Options'!$D:$D,$A27)+SUMIFS('NSE - Other Index Options'!$J:$J,'NSE - Other Index Options'!$D:$D,$A27)) | C27: =IF(SUMIFS('NSE - NIFTY Index Options'!$K:$K,'NSE - NIFTY Index Options'!$D:$D,$A27)+SUMIFS('NSE - Other Index Options'!$K:$K,'NSE - Other Index Options'!$D:$D,$A27)=0,"",SUMIFS('NSE - NIFTY Index Options'!$K:$K,'NSE - NIFTY Index Options'!$D:$D,$A27)+SUMIFS('NSE - Other Index Options'!$K:$K,'NSE - Other Index Options'!$D:$D,$A27)) | D27: =IF(SUMIFS('NSE - NIFTY Index Options'!$L:$L,'NSE - NIFTY Index Options'!$D:$D,$A27)+SUMIFS('NSE - Other Index Options'!$L:$L,'NSE - Other Index Options'!$D:$D,$A27)=0,"",SUMIFS('NSE - NIFTY Index Options'!$L:$L,'NSE - NIFTY Index Options'!$D:$D,$A27)+SUMIFS('NSE - Other Index Options'!$L:$L,'NSE - Other Index Options'!$D:$D,$A27)) | E27: =IF(SUMIFS('BSE - SENSEX Index Options'!$J:$J,'BSE - SENSEX Index Options'!$D:$D,$A27)+SUMIFS('BSE - Other Index Options'!$J:$J,'BSE - Other Index Options'!$D:$D,$A27)=0,"",SUMIFS('BSE - SENSEX Index Options'!$J:$J,'BSE - SENSEX Index Options'!$D:$D,$A27)+SUMIFS('BSE - Other Index Options'!$J:$J,'BSE - Other Index Options'!$D:$D,$A27)) | F27: =IF(SUMIFS('BSE - SENSEX Index Options'!$K:$K,'BSE - SENSEX Index Options'!$D:$D,$A27)+SUMIFS('BSE - Other Index Options'!$K:$K,'BSE - Other Index Options'!$D:$D,$A27)=0,"",SUMIFS('BSE - SENSEX Index Options'!$K:$K,'BSE - SENSEX Index Options'!$D:$D,$A27)+SUMIFS('BSE - Other Index Options'!$K:$K,'BSE - Other Index Options'!$D:$D,$A27)) | G27: =IF(SUMIFS('BSE - SENSEX Index Options'!$L:$L,'BSE - SENSEX Index Options'!$D:$D,$A27)+SUMIFS('BSE - Other Index Options'!$L:$L,'BSE - Other Index Options'!$D:$D,$A27)=0,"",SUMIFS('BSE - SENSEX Index Options'!$L:$L,'BSE - SENSEX Index Options'!$D:$D,$A27)+SUMIFS('BSE - Other Index Options'!$L:$L,'BSE - Other Index Options'!$D:$D,$A27))
... A43: 46722 | B43: =IF(SUMIFS('NSE - NIFTY Index Options'!$J:$J,'NSE - NIFTY Index Options'!$D:$D,$A43)+SUMIFS('NSE - Other Index Options'!$J:$J,'NSE - Other Index Options'!$D:$D,$A43)=0,"",SUMIFS('NSE - NIFTY Index Options'!$J:$J,'NSE - NIFTY Index Options'!$D:$D,$A43)+SUMIFS('NSE - Other Index Options'!$J:$J,'NSE - Other Index Options'!$D:$D,$A43)) | C43: =IF(SUMIFS('NSE - NIFTY Index Options'!$K:$K,'NSE - NIFTY Index Options'!$D:$D,$A43)+SUMIFS('NSE - Other Index Options'!$K:$K,'NSE - Other Index Options'!$D:$D,$A43)=0,"",SUMIFS('NSE - NIFTY Index Options'!$K:$K,'NSE - NIFTY Index Options'!$D:$D,$A43)+SUMIFS('NSE - Other Index Options'!$K:$K,'NSE - Other Index Options'!$D:$D,$A43)) | D43: =IF(SUMIFS('NSE - NIFTY Index Options'!$L:$L,'NSE - NIFTY Index Options'!$D:$D,$A43)+SUMIFS('NSE - Other Index Options'!$L:$L,'NSE - Other Index Options'!$D:$D,$A43)=0,"",SUMIFS('NSE - NIFTY Index Options'!$L:$L,'NSE - NIFTY Index Options'!$D:$D,$A43)+SUMIFS('NSE - Other Index Options'!$L:$L,'NSE - Other Index Options'!$D:$D,$A43)) | E43: =IF(SUMIFS('BSE - SENSEX Index Options'!$J:$J,'BSE - SENSEX Index Options'!$D:$D,$A43)+SUMIFS('BSE - Other Index Options'!$J:$J,'BSE - Other Index Options'!$D:$D,$A43)=0,"",SUMIFS('BSE - SENSEX Index Options'!$J:$J,'BSE - SENSEX Index Options'!$D:$D,$A43)+SUMIFS('BSE - Other Index Options'!$J:$J,'BSE - Other Index Options'!$D:$D,$A43)) | F43: =IF(SUMIFS('BSE - SENSEX Index Options'!$K:$K,'BSE - SENSEX Index Options'!$D:$D,$A43)+SUMIFS('BSE - Other Index Options'!$K:$K,'BSE - Other Index Options'!$D:$D,$A43)=0,"",SUMIFS('BSE - SENSEX Index Options'!$K:$K,'BSE - SENSEX Index Options'!$D:$D,$A43)+SUMIFS('BSE - Other Index Options'!$K:$K,'BSE - Other Index Options'!$D:$D,$A43)) | G43: =IF(SUMIFS('BSE - SENSEX Index Options'!$L:$L,'BSE - SENSEX Index Options'!$D:$D,$A43)+SUMIFS('BSE - Other Index Options'!$L:$L,'BSE - Other Index Options'!$D:$D,$A43)=0,"",SUMIFS('BSE - SENSEX Index Options'!$L:$L,'BSE - SENSEX Index Options'!$D:$D,$A43)+SUMIFS('BSE - Other Index Options'!$L:$L,'BSE - Other Index Options'!$D:$D,$A43))
A44: Total | B44: =IF(SUM(B16:B43)=0,"",SUM(B16:B43)) -> 32543526141 | C44: =IF(SUM(C16:C43)=0,"",SUM(C16:C43)) -> 5.5742822e+09 | D44: =IF(SUM(D16:D43)=0,"",SUM(D16:D43)) -> 11525884 | E44: =IF(SUM(E16:E43)=0,"",SUM(E16:E43)) -> 29171164790 | F44: =IF(SUM(F16:F43)=0,"",SUM(F16:F43)) -> 4.6914776e+09 | G44: =IF(SUM(G16:G43)=0,"",SUM(G16:G43)) -> 5233083.2

Sheet Analysis1
A1: Premium Turnover Time Series by Trade Day — NSE vs BSE (Sep-2025 onwards, live — populates as master data is updated)
A3: Monday Trade Day
A4: Month | B4: NSE Premium Turnover (INR Crs) | C4: BSE Premium Turnover (INR Crs) | D4: NSE Market Share | E4: BSE Market Share
A5: 45901 | B5: =IF(SUMIFS('NSE - NIFTY Index Options'!$L:$L,'NSE - NIFTY Index Options'!$D:$D,$A5,'NSE - NIFTY Index Options'!$B:$B,"Monday")+SUMIFS('NSE - Other Index Options'!$L:$L,'NSE - Other Index Options'!$D:$D,$A5,'NSE - Other Index Options'!$B:$B,"Monday")=0,"",SUMIFS('NSE - NIFTY Index Options'!$L:$L,'NSE - NIFTY Index Options'!$D:$D,$A5,'NSE - NIFTY Index Options'!$B:$B,"Monday")+SUMIFS('NSE - Other Index Options'!$L:$L,'NSE - Other Index Options'!$D:$D,$A5,'NSE - Other Index Options'!$B:$B,"Monday")) -> 218242.89 | C5: =IF(SUMIFS('BSE - SENSEX Index Options'!$L:$L,'BSE - SENSEX Index Options'!$D:$D,$A5,'BSE - SENSEX Index Options'!$B:$B,"Monday")+SUMIFS('BSE - Other Index Options'!$L:$L,'BSE - Other Index Options'!$D:$D,$A5,'BSE - Other Index Options'!$B:$B,"Monday")=0,"",SUMIFS('BSE - SENSEX Index Options'!$L:$L,'BSE - SENSEX Index Options'!$D:$D,$A5,'BSE - SENSEX Index Options'!$B:$B,"Monday")+SUMIFS('BSE - Other Index Options'!$L:$L,'BSE - Other Index Options'!$D:$D,$A5,'BSE - Other Index Options'!$B:$B,"Monday")) -> 40591.17 | D5: =IF(SUM(B5:C5)=0,"",SUM(B5)/SUM(B5:C5)) -> 0.84317686 | E5: =IF(SUM(B5:C5)=0,"",SUM(C5)/SUM(B5:C5)) -> 0.15682314
A6: 45931 | B6: =IF(SUMIFS('NSE - NIFTY Index Options'!$L:$L,'NSE - NIFTY Index Options'!$D:$D,$A6,'NSE - NIFTY Index Options'!$B:$B,"Monday")+SUMIFS('NSE - Other Index Options'!$L:$L,'NSE - Other Index Options'!$D:$D,$A6,'NSE - Other Index Options'!$B:$B,"Monday")=0,"",SUMIFS('NSE - NIFTY Index Options'!$L:$L,'NSE - NIFTY Index Options'!$D:$D,$A6,'NSE - NIFTY Index Options'!$B:$B,"Monday")+SUMIFS('NSE - Other Index Options'!$L:$L,'NSE - Other Index Options'!$D:$D,$A6,'NSE - Other Index Options'!$B:$B,"Monday")) -> 224685.02 | C6: =IF(SUMIFS('BSE - SENSEX Index Options'!$L:$L,'BSE - SENSEX Index Options'!$D:$D,$A6,'BSE - SENSEX Index Options'!$B:$B,"Monday")+SUMIFS('BSE - Other Index Options'!$L:$L,'BSE - Other Index Options'!$D:$D,$A6,'BSE - Other Index Options'!$B:$B,"Monday")=0,"",SUMIFS('BSE - SENSEX Index Options'!$L:$L,'BSE - SENSEX Index Options'!$D:$D,$A6,'BSE - SENSEX Index Options'!$B:$B,"Monday")+SUMIFS('BSE - Other Index Options'!$L:$L,'BSE - Other Index Options'!$D:$D,$A6,'BSE - Other Index Options'!$B:$B,"Monday")) -> 39126.67 | D6: =IF(SUM(B6:C6)=0,"",SUM(B6)/SUM(B6:C6)) -> 0.85168713 | E6: =IF(SUM(B6:C6)=0,"",SUM(C6)/SUM(B6:C6)) -> 0.14831287
A7: 45962 | B7: =IF(SUMIFS('NSE - NIFTY Index Options'!$L:$L,'NSE - NIFTY Index Options'!$D:$D,$A7,'NSE - NIFTY Index Options'!$B:$B,"Monday")+SUMIFS('NSE - Other Index Options'!$L:$L,'NSE - Other Index Options'!$D:$D,$A7,'NSE - Other Index Options'!$B:$B,"Monday")=0,"",SUMIFS('NSE - NIFTY Index Options'!$L:$L,'NSE - NIFTY Index Options'!$D:$D,$A7,'NSE - NIFTY Index Options'!$B:$B,"Monday")+SUMIFS('NSE - Other Index Options'!$L:$L,'NSE - Other Index Options'!$D:$D,$A7,'NSE - Other Index Options'!$B:$B,"Monday")) -> 196832.15 | C7: =IF(SUMIFS('BSE - SENSEX Index Options'!$L:$L,'BSE - SENSEX Index Options'!$D:$D,$A7,'BSE - SENSEX Index Options'!$B:$B,"Monday")+SUMIFS('BSE - Other Index Options'!$L:$L,'BSE - Other Index Options'!$D:$D,$A7,'BSE - Other Index Options'!$B:$B,"Monday")=0,"",SUMIFS('BSE - SENSEX Index Options'!$L:$L,'BSE - SENSEX Index Options'!$D:$D,$A7,'BSE - SENSEX Index Options'!$B:$B,"Monday")+SUMIFS('BSE - Other Index Options'!$L:$L,'BSE - Other Index Options'!$D:$D,$A7,'BSE - Other Index Options'!$B:$B,"Monday")) -> 34746.32 | D7: =IF(SUM(B7:C7)=0,"",SUM(B7)/SUM(B7:C7)) -> 0.84995876 | E7: =IF(SUM(B7:C7)=0,"",SUM(C7)/SUM(B7:C7)) -> 0.15004124
A8: 45992 | B8: =IF(SUMIFS('NSE - NIFTY Index Options'!$L:$L,'NSE - NIFTY Index Options'!$D:$D,$A8,'NSE - NIFTY Index Options'!$B:$B,"Monday")+SUMIFS('NSE - Other Index Options'!$L:$L,'NSE - Other Index Options'!$D:$D,$A8,'NSE - Other Index Options'!$B:$B,"Monday")=0,"",SUMIFS('NSE - NIFTY Index Options'!$L:$L,'NSE - NIFTY Index Options'!$D:$D,$A8,'NSE - NIFTY Index Options'!$B:$B,"Monday")+SUMIFS('NSE - Other Index Options'!$L:$L,'NSE - Other Index Options'!$D:$D,$A8,'NSE - Other Index Options'!$B:$B,"Monday")) -> 224662.09 | C8: =IF(SUMIFS('BSE - SENSEX Index Options'!$L:$L,'BSE - SENSEX Index Options'!$D:$D,$A8,'BSE - SENSEX Index Options'!$B:$B,"Monday")+SUMIFS('BSE - Other Index Options'!$L:$L,'BSE - Other Index Options'!$D:$D,$A8,'BSE - Other Index Options'!$B:$B,"Monday")=0,"",SUMIFS('BSE - SENSEX Index Options'!$L:$L,'BSE - SENSEX Index Options'!$D:$D,$A8,'BSE - SENSEX Index Options'!$B:$B,"Monday")+SUMIFS('BSE - Other Index Options'!$L:$L,'BSE - Other Index Options'!$D:$D,$A8,'BSE - Other Index Options'!$B:$B,"Monday")) -> 44420.45 | D8: =IF(SUM(B8:C8)=0,"",SUM(B8)/SUM(B8:C8)) -> 0.83491887 | E8: =IF(SUM(B8:C8)=0,"",SUM(C8)/SUM(B8:C8)) -> 0.16508113
A9: 46023 | B9: =IF(SUMIFS('NSE - NIFTY Index Options'!$L:$L,'NSE - NIFTY Index Options'!$D:$D,$A9,'NSE - NIFTY Index Options'!$B:$B,"Monday")+SUMIFS('NSE - Other Index Options'!$L:$L,'NSE - Other Index Options'!$D:$D,$A9,'NSE - Other Index Options'!$B:$B,"Monday")=0,"",SUMIFS('NSE - NIFTY Index Options'!$L:$L,'NSE - NIFTY Index Options'!$D:$D,$A9,'NSE - NIFTY Index Options'!$B:$B,"Monday")+SUMIFS('NSE - Other Index Options'!$L:$L,'NSE - Other Index Options'!$D:$D,$A9,'NSE - Other Index Options'!$B:$B,"Monday")) -> 188703.59 | C9: =IF(SUMIFS('BSE - SENSEX Index Options'!$L:$L,'BSE - SENSEX Index Options'!$D:$D,$A9,'BSE - SENSEX Index Options'!$B:$B,"Monday")+SUMIFS('BSE - Other Index Options'!$L:$L,'BSE - Other Index Options'!$D:$D,$A9,'BSE - Other Index Options'!$B:$B,"Monday")=0,"",SUMIFS('BSE - SENSEX Index Options'!$L:$L,'BSE - SENSEX Index Options'!$D:$D,$A9,'BSE - SENSEX Index Options'!$B:$B,"Monday")+SUMIFS('BSE - Other Index Options'!$L:$L,'BSE - Other Index Options'!$D:$D,$A9,'BSE - Other Index Options'!$B:$B,"Monday")) -> 40606.1 | D9: =IF(SUM(B9:C9)=0,"",SUM(B9)/SUM(B9:C9)) -> 0.82292026 | E9: =IF(SUM(B9:C9)=0,"",SUM(C9)/SUM(B9:C9)) -> 0.17707974
A10: 46054 | B10: =IF(SUMIFS('NSE - NIFTY Index Options'!$L:$L,'NSE - NIFTY Index Options'!$D:$D,$A10,'NSE - NIFTY Index Options'!$B:$B,"Monday")+SUMIFS('NSE - Other Index Options'!$L:$L,'NSE - Other Index Options'!$D:$D,$A10,'NSE - Other Index Options'!$B:$B,"Monday")=0,"",SUMIFS('NSE - NIFTY Index Options'!$L:$L,'NSE - NIFTY Index Options'!$D:$D,$A10,'NSE - NIFTY Index Options'!$B:$B,"Monday")+SUMIFS('NSE - Other Index Options'!$L:$L,'NSE - Other Index Options'!$D:$D,$A10,'NSE - Other Index Options'!$B:$B,"Monday")) -> 273585.4 | C10: =IF(SUMIFS('BSE - SENSEX Index Options'!$L:$L,'BSE - SENSEX Index Options'!$D:$D,$A10,'BSE - SENSEX Index Options'!$B:$B,"Monday")+SUMIFS('BSE - Other Index Options'!$L:$L,'BSE - Other Index Options'!$D:$D,$A10,'BSE - Other Index Options'!$B:$B,"Monday")=0,"",SUMIFS('BSE - SENSEX Index Options'!$L:$L,'BSE - SENSEX Index Options'!$D:$D,$A10,'BSE - SENSEX Index Options'!$B:$B,"Monday")+SUMIFS('BSE - Other Index Options'!$L:$L,'BSE - Other Index Options'!$D:$D,$A10,'BSE - Other Index Options'!$B:$B,"Monday")) -> 49539.82 | D10: =IF(SUM(B10:C10)=0,"",SUM(B10)/SUM(B10:C10)) -> 0.84668538 | E10: =IF(SUM(B10:C10)=0,"",SUM(C10)/SUM(B10:C10)) -> 0.15331462
A11: 46082 | B11: =IF(SUMIFS('NSE - NIFTY Index Options'!$L:$L,'NSE - NIFTY Index Options'!$D:$D,$A11,'NSE - NIFTY Index Options'!$B:$B,"Monday")+SUMIFS('NSE - Other Index Options'!$L:$L,'NSE - Other Index Options'!$D:$D,$A11,'NSE - Other Index Options'!$B:$B,"Monday")=0,"",SUMIFS('NSE - NIFTY Index Options'!$L:$L,'NSE - NIFTY Index Options'!$D:$D,$A11,'NSE - NIFTY Index Options'!$B:$B,"Monday")+SUMIFS('NSE - Other Index Options'!$L:$L,'NSE - Other Index Options'!$D:$D,$A11,'NSE - Other Index Options'!$B:$B,"Monday")) -> 550323.86 | C11: =IF(SUMIFS('BSE - SENSEX Index Options'!$L:$L,'BSE - SENSEX Index Options'!$D:$D,$A11,'BSE - SENSEX Index Options'!$B:$B,"Monday")+SUMIFS('BSE - Other Index Options'!$L:$L,'BSE - Other Index Options'!$D:$D,$A11,'BSE - Other Index Options'!$B:$B,"Monday")=0,"",SUMIFS('BSE - SENSEX Index Options'!$L:$L,'BSE - SENSEX Index Options'!$D:$D,$A11,'BSE - SENSEX Index Options'!$B:$B,"Monday")+SUMIFS('BSE - Other Index Options'!$L:$L,'BSE - Other Index Options'!$D:$D,$A11,'BSE - Other Index Options'!$B:$B,"Monday")) -> 80746.14 | D11: =IF(SUM(B11:C11)=0,"",SUM(B11)/SUM(B11:C11)) -> 0.87204884 | E11: =IF(SUM(B11:C11)=0,"",SUM(C11)/SUM(B11:C11)) -> 0.12795116
A12: 46113 | B12: =IF(SUMIFS('NSE - NIFTY Index Options'!$L:$L,'NSE - NIFTY Index Options'!$D:$D,$A12,'NSE - NIFTY Index Options'!$B:$B,"Monday")+SUMIFS('NSE - Other Index Options'!$L:$L,'NSE - Other Index Options'!$D:$D,$A12,'NSE - Other Index Options'!$B:$B,"Monday")=0,"",SUMIFS('NSE - NIFTY Index Options'!$L:$L,'NSE - NIFTY Index Options'!$D:$D,$A12,'NSE - NIFTY Index Options'!$B:$B,"Monday")+SUMIFS('NSE - Other Index Options'!$L:$L,'NSE - Other Index Options'!$D:$D,$A12,'NSE - Other Index Options'!$B:$B,"Monday")) -> 300947.8 | C12: =IF(SUMIFS('BSE - SENSEX Index Options'!$L:$L,'BSE - SENSEX Index Options'!$D:$D,$A12,'BSE - SENSEX Index Options'!$B:$B,"Monday")+SUMIFS('BSE - Other Index Options'!$L:$L,'BSE - Other Index Options'!$D:$D,$A12,'BSE - Other Index Options'!$B:$B,"Monday")=0,"",SUMIFS('BSE - SENSEX Index Options'!$L:$L,'BSE - SENSEX Index Options'!$D:$D,$A12,'BSE - SENSEX Index Options'!$B:$B,"Monday")+SUMIFS('BSE - Other Index Options'!$L:$L,'BSE - Other Index Options'!$D:$D,$A12,'BSE - Other Index Options'!$B:$B,"Monday")) -> 49042.14 | D12: =IF(SUM(B12:C12)=0,"",SUM(B12)/SUM(B12:C12)) -> 0.85987557 | E12: =IF(SUM(B12:C12)=0,"",SUM(C12)/SUM(B12:C12)) -> 0.14012443
A13: 46143 | B13: =IF(SUMIFS('NSE - NIFTY Index Options'!$L:$L,'NSE - NIFTY Index Options'!$D:$D,$A13,'NSE - NIFTY Index Options'!$B:$B,"Monday")+SUMIFS('NSE - Other Index Options'!$L:$L,'NSE - Other Index Options'!$D:$D,$A13,'NSE - Other Index Options'!$B:$B,"Monday")=0,"",SUMIFS('NSE - NIFTY Index Options'!$L:$L,'NSE - NIFTY Index Options'!$D:$D,$A13,'NSE - NIFTY Index Options'!$B:$B,"Monday")+SUMIFS('NSE - Other Index Options'!$L:$L,'NSE - Other Index Options'!$D:$D,$A13,'NSE - Other Index Options'!$B:$B,"Monday")) -> 275956.83 | C13: =IF(SUMIFS('BSE - SENSEX Index Options'!$L:$L,'BSE - SENSEX Index Options'!$D:$D,$A13,'BSE - SENSEX Index Options'!$B:$B,"Monday")+SUMIFS('BSE - Other Index Options'!$L:$L,'BSE - Other Index Options'!$D:$D,$A13,'BSE - Other Index Options'!$B:$B,"Monday")=0,"",SUMIFS('BSE - SENSEX Index Options'!$L:$L,'BSE - SENSEX Index Options'!$D:$D,$A13,'BSE - SENSEX Index Options'!$B:$B,"Monday")+SUMIFS('BSE - Other Index Options'!$L:$L,'BSE - Other Index Options'!$D:$D,$A13,'BSE - Other Index Options'!$B:$B,"Monday")) -> 51821.24 | D13: =IF(SUM(B13:C13)=0,"",SUM(B13)/SUM(B13:C13)) -> 0.84190144 | E13: =IF(SUM(B13:C13)=0,"",SUM(C13)/SUM(B13:C13)) -> 0.15809856
A14: 46174 | B14: =IF(SUMIFS('NSE - NIFTY Index Options'!$L:$L,'NSE - NIFTY Index Options'!$D:$D,$A14,'NSE - NIFTY Index Options'!$B:$B,"Monday")+SUMIFS('NSE - Other Index Options'!$L:$L,'NSE - Other Index Options'!$D:$D,$A14,'NSE - Other Index Options'!$B:$B,"Monday")=0,"",SUMIFS('NSE - NIFTY Index Options'!$L:$L,'NSE - NIFTY Index Options'!$D:$D,$A14,'NSE - NIFTY Index Options'!$B:$B,"Monday")+SUMIFS('NSE - Other Index Options'!$L:$L,'NSE - Other Index Options'!$D:$D,$A14,'NSE - Other Index Options'!$B:$B,"Monday")) -> 292181.6 | C14: =IF(SUMIFS('BSE - SENSEX Index Options'!$L:$L,'BSE - SENSEX Index Options'!$D:$D,$A14,'BSE - SENSEX Index Options'!$B:$B,"Monday")+SUMIFS('BSE - Other Index Options'!$L:$L,'BSE - Other Index Options'!$D:$D,$A14,'BSE - Other Index Options'!$B:$B,"Monday")=0,"",SUMIFS('BSE - SENSEX Index Options'!$L:$L,'BSE - SENSEX Index Options'!$D:$D,$A14,'BSE - SENSEX Index Options'!$B:$B,"Monday")+SUMIFS('BSE - Other Index Options'!$L:$L,'BSE - Other Index Options'!$D:$D,$A14,'BSE - Other Index Options'!$B:$B,"Monday")) -> 52472.05 | D14: =IF(SUM(B14:C14)=0,"",SUM(B14)/SUM(B14:C14)) -> 0.84775426 | E14: =IF(SUM(B14:C14)=0,"",SUM(C14)/SUM(B14:C14)) -> 0.15224574
A15: 46204 | B15: =IF(SUMIFS('NSE - NIFTY Index Options'!$L:$L,'NSE - NIFTY Index Options'!$D:$D,$A15,'NSE - NIFTY Index Options'!$B:$B,"Monday")+SUMIFS('NSE - Other Index Options'!$L:$L,'NSE - Other Index Options'!$D:$D,$A15,'NSE - Other Index Options'!$B:$B,"Monday")=0,"",SUMIFS('NSE - NIFTY Index Options'!$L:$L,'NSE - NIFTY Index Options'!$D:$D,$A15,'NSE - NIFTY Index Options'!$B:$B,"Monday")+SUMIFS('NSE - Other Index Options'!$L:$L,'NSE - Other Index Options'!$D:$D,$A15,'NSE - Other Index Options'!$B:$B,"Monday")) -> 38844.05 | C15: =IF(SUMIFS('BSE - SENSEX Index Options'!$L:$L,'BSE - SENSEX Index Options'!$D:$D,$A15,'BSE - SENSEX Index Options'!$B:$B,"Monday")+SUMIFS('BSE - Other Index Options'!$L:$L,'BSE - Other Index Options'!$D:$D,$A15,'BSE - Other Index Options'!$B:$B,"Monday")=0,"",SUMIFS('BSE - SENSEX Index Options'!$L:$L,'BSE - SENSEX Index Options'!$D:$D,$A15,'BSE - SENSEX Index Options'!$B:$B,"Monday")+SUMIFS('BSE - Other Index Options'!$L:$L,'BSE - Other Index Options'!$D:$D,$A15,'BSE - Other Index Options'!$B:$B,"Monday")) -> 8708.01 | D15: =IF(SUM(B15:C15)=0,"",SUM(B15)/SUM(B15:C15)) -> 0.81687418 | E15: =IF(SUM(B15:C15)=0,"",SUM(C15)/SUM(B15:C15)) -> 0.18312582
A16: 46235 | B16: =IF(SUMIFS('NSE - NIFTY Index Options'!$L:$L,'NSE - NIFTY Index Options'!$D:$D,$A16,'NSE - NIFTY Index Options'!$B:$B,"Monday")+SUMIFS('NSE - Other Index Options'!$L:$L,'NSE - Other Index Options'!$D:$D,$A16,'NSE - Other Index Options'!$B:$B,"Monday")=0,"",SUMIFS('NSE - NIFTY Index Options'!$L:$L,'NSE - NIFTY Index Options'!$D:$D,$A16,'NSE - NIFTY Index Options'!$B:$B,"Monday")+SUMIFS('NSE - Other Index Options'!$L:$L,'NSE - Other Index Options'!$D:$D,$A16,'NSE - Other Index Options'!$B:$B,"Monday")) | C16: =IF(SUMIFS('BSE - SENSEX Index Options'!$L:$L,'BSE - SENSEX Index Options'!$D:$D,$A16,'BSE - SENSEX Index Options'!$B:$B,"Monday")+SUMIFS('BSE - Other Index Options'!$L:$L,'BSE - Other Index Options'!$D:$D,$A16,'BSE - Other Index Options'!$B:$B,"Monday")=0,"",SUMIFS('BSE - SENSEX Index Options'!$L:$L,'BSE - SENSEX Index Options'!$D:$D,$A16,'BSE - SENSEX Index Options'!$B:$B,"Monday")+SUMIFS('BSE - Other Index Options'!$L:$L,'BSE - Other Index Options'!$D:$D,$A16,'BSE - Other Index Options'!$B:$B,"Monday")) | D16: =IF(SUM(B16:C16)=0,"",SUM(B16)/SUM(B16:C16)) | E16: =IF(SUM(B16:C16)=0,"",SUM(C16)/SUM(B16:C16))
... A32: 46722 | B32: =IF(SUMIFS('NSE - NIFTY Index Options'!$L:$L,'NSE - NIFTY Index Options'!$D:$D,$A32,'NSE - NIFTY Index Options'!$B:$B,"Monday")+SUMIFS('NSE - Other Index Options'!$L:$L,'NSE - Other Index Options'!$D:$D,$A32,'NSE - Other Index Options'!$B:$B,"Monday")=0,"",SUMIFS('NSE - NIFTY Index Options'!$L:$L,'NSE - NIFTY Index Options'!$D:$D,$A32,'NSE - NIFTY Index Options'!$B:$B,"Monday")+SUMIFS('NSE - Other Index Options'!$L:$L,'NSE - Other Index Options'!$D:$D,$A32,'NSE - Other Index Options'!$B:$B,"Monday")) | C32: =IF(SUMIFS('BSE - SENSEX Index Options'!$L:$L,'BSE - SENSEX Index Options'!$D:$D,$A32,'BSE - SENSEX Index Options'!$B:$B,"Monday")+SUMIFS('BSE - Other Index Options'!$L:$L,'BSE - Other Index Options'!$D:$D,$A32,'BSE - Other Index Options'!$B:$B,"Monday")=0,"",SUMIFS('BSE - SENSEX Index Options'!$L:$L,'BSE - SENSEX Index Options'!$D:$D,$A32,'BSE - SENSEX Index Options'!$B:$B,"Monday")+SUMIFS('BSE - Other Index Options'!$L:$L,'BSE - Other Index Options'!$D:$D,$A32,'BSE - Other Index Options'!$B:$B,"Monday")) | D32: =IF(SUM(B32:C32)=0,"",SUM(B32)/SUM(B32:C32)) | E32: =IF(SUM(B32:C32)=0,"",SUM(C32)/SUM(B32:C32))
A33: Total | B33: =IF(SUM(B5:B32)=0,"",SUM(B5:B32)) -> 2784965.3 | C33: =IF(SUM(C5:C32)=0,"",SUM(C5:C32)) -> 491820.11 | D33: =IF(SUM(B33:C33)=0,"",SUM(B33)/SUM(B33:C33)) -> 0.84990774 | E33: =IF(SUM(B33:C33)=0,"",SUM(C33)/SUM(B33:C33)) -> 0.15009226
A35: Tuesday Trade Day
A36: Month | B36: NSE Premium Turnover (INR Crs) | C36: BSE Premium Turnover (INR Crs) | D36: NSE Market Share | E36: BSE Market Share
A37: 45901 | B37: =IF(SUMIFS('NSE - NIFTY Index Options'!$L:$L,'NSE - NIFTY Index Options'!$D:$D,$A37,'NSE - NIFTY Index Options'!$B:$B,"Tuesday")+SUMIFS('NSE - Other Index Options'!$L:$L,'NSE - Other Index Options'!$D:$D,$A37,'NSE - Other Index Options'!$B:$B,"Tuesday")=0,"",SUMIFS('NSE - NIFTY Index Options'!$L:$L,'NSE - NIFTY Index Options'!$D:$D,$A37,'NSE - NIFTY Index Options'!$B:$B,"Tuesday")+SUMIFS('NSE - Other Index Options'!$L:$L,'NSE - Other Index Options'!$D:$D,$A37,'NSE - Other Index Options'!$B:$B,"Tuesday")) -> 295244.49 | C37: =IF(SUMIFS('BSE - SENSEX Index Options'!$L:$L,'BSE - SENSEX Index Options'!$D:$D,$A37,'BSE - SENSEX Index Options'!$B:$B,"Tuesday")+SUMIFS('BSE - Other Index Options'!$L:$L,'BSE - Other Index Options'!$D:$D,$A37,'BSE - Other Index Options'!$B:$B,"Tuesday")=0,"",SUMIFS('BSE - SENSEX Index Options'!$L:$L,'BSE - SENSEX Index Options'!$D:$D,$A37,'BSE - SENSEX Index Options'!$B:$B,"Tuesday")+SUMIFS('BSE - Other Index Options'!$L:$L,'BSE - Other Index Options'!$D:$D,$A37,'BSE - Other Index Options'!$B:$B,"Tuesday")) -> 41472.37 | D37: =IF(SUM(B37:C37)=0,"",SUM(B37)/SUM(B37:C37)) -> 0.87683311 | E37: =IF(SUM(B37:C37)=0,"",SUM(C37)/SUM(B37:C37)) -> 0.12316689
A38: 45931 | B38: =IF(SUMIFS('NSE - NIFTY Index Options'!$L:$L,'NSE - NIFTY Index Options'!$D:$D,$A38,'NSE - NIFTY Index Options'!$B:$B,"Tuesday")+SUMIFS('NSE - Other Index Options'!$L:$L,'NSE - Other Index Options'!$D:$D,$A38,'NSE - Other Index Options'!$B:$B,"Tuesday")=0,"",SUMIFS('NSE - NIFTY Index Options'!$L:$L,'NSE - NIFTY Index Options'!$D:$D,$A38,'NSE - NIFTY Index Options'!$B:$B,"Tuesday")+SUMIFS('NSE - Other Index Options'!$L:$L,'NSE - Other Index Options'!$D:$D,$A38,'NSE - Other Index Options'!$B:$B,"Tuesday")) -> 235273.76 | C38: =IF(SUMIFS('BSE - SENSEX Index Options'!$L:$L,'BSE - SENSEX Index Options'!$D:$D,$A38,'BSE - SENSEX Index Options'!$B:$B,"Tuesday")+SUMIFS('BSE - Other Index Options'!$L:$L,'BSE - Other Index Options'!$D:$D,$A38,'BSE - Other Index Options'!$B:$B,"Tuesday")=0,"",SUMIFS('BSE - SENSEX Index Options'!$L:$L,'BSE - SENSEX Index Options'!$D:$D,$A38,'BSE - SENSEX Index Options'!$B:$B,"Tuesday")+SUMIFS('BSE - Other Index Options'!$L:$L,'BSE - Other Index Options'!$D:$D,$A38,'BSE - Other Index Options'!$B:$B,"Tuesday")) -> 36671.18 | D38: =IF(SUM(B38:C38)=0,"",SUM(B38)/SUM(B38:C38)) -> 0.86515219 | E38: =IF(SUM(B38:C38)=0,"",SUM(C38)/SUM(B38:C38)) -> 0.13484781
A39: 45962 | B39: =IF(SUMIFS('NSE - NIFTY Index Options'!$L:$L,'NSE - NIFTY Index Options'!$D:$D,$A39,'NSE - NIFTY Index Options'!$B:$B,"Tuesday")+SUMIFS('NSE - Other Index Options'!$L:$L,'NSE - Other Index Options'!$D:$D,$A39,'NSE - Other Index Options'!$B:$B,"Tuesday")=0,"",SUMIFS('NSE - NIFTY Index Options'!$L:$L,'NSE - NIFTY Index Options'!$D:$D,$A39,'NSE - NIFTY Index Options'!$B:$B,"Tuesday")+SUMIFS('NSE - Other Index Options'!$L:$L,'NSE - Other Index Options'!$D:$D,$A39,'NSE - Other Index Options'!$B:$B,"Tuesday")) -> 258753.37 | C39: =IF(SUMIFS('BSE - SENSEX Index Options'!$L:$L,'BSE - SENSEX Index Options'!$D:$D,$A39,'BSE - SENSEX Index Options'!$B:$B,"Tuesday")+SUMIFS('BSE - Other Index Options'!$L:$L,'BSE - Other Index Options'!$D:$D,$A39,'BSE - Other Index Options'!$B:$B,"Tuesday")=0,"",SUMIFS('BSE - SENSEX Index Options'!$L:$L,'BSE - SENSEX Index Options'!$D:$D,$A39,'BSE - SENSEX Index Options'!$B:$B,"Tuesday")+SUMIFS('BSE - Other Index Options'!$L:$L,'BSE - Other Index Options'!$D:$D,$A39,'BSE - Other Index Options'!$B:$B,"Tuesday")) -> 37451.27 | D39: =IF(SUM(B39:C39)=0,"",SUM(B39)/SUM(B39:C39)) -> 0.87356285 | E39: =IF(SUM(B39:C39)=0,"",SUM(C39)/SUM(B39:C39)) -> 0.12643715
A40: 45992 | B40: =IF(SUMIFS('NSE - NIFTY Index Options'!$L:$L,'NSE - NIFTY Index Options'!$D:$D,$A40,'NSE - NIFTY Index Options'!$B:$B,"Tuesday")+SUMIFS('NSE - Other Index Options'!$L:$L,'NSE - Other Index Options'!$D:$D,$A40,'NSE - Other Index Options'!$B:$B,"Tuesday")=0,"",SUMIFS('NSE - NIFTY Index Options'!$L:$L,'NSE - NIFTY Index Options'!$D:$D,$A40,'NSE - NIFTY Index Options'!$B:$B,"Tuesday")+SUMIFS('NSE - Other Index Options'!$L:$L,'NSE - Other Index Options'!$D:$D,$A40,'NSE - Other Index Options'!$B:$B,"Tuesday")) -> 294368.69 | C40: =IF(SUMIFS('BSE - SENSEX Index Options'!$L:$L,'BSE - SENSEX Index Options'!$D:$D,$A40,'BSE - SENSEX Index Options'!$B:$B,"Tuesday")+SUMIFS('BSE - Other Index Options'!$L:$L,'BSE - Other Index Options'!$D:$D,$A40,'BSE - Other Index Options'!$B:$B,"Tuesday")=0,"",SUMIFS('BSE - SENSEX Index Options'!$L:$L,'BSE - SENSEX Index Options'!$D:$D,$A40,'BSE - SENSEX Index Options'!$B:$B,"Tuesday")+SUMIFS('BSE - Other Index Options'!$L:$L,'BSE - Other Index Options'!$D:$D,$A40,'BSE - Other Index Options'!$B:$B,"Tuesday")) -> 44711.59 | D40: =IF(SUM(B40:C40)=0,"",SUM(B40)/SUM(B40:C40)) -> 0.86813863 | E40: =IF(SUM(B40:C40)=0,"",SUM(C40)/SUM(B40:C40)) -> 0.13186137
A41: 46023 | B41: =IF(SUMIFS('NSE - NIFTY Index Options'!$L:$L,'NSE - NIFTY Index Options'!$D:$D,$A41,'NSE - NIFTY Index Options'!$B:$B,"Tuesday")+SUMIFS('NSE - Other Index Options'!$L:$L,'NSE - Other Index Options'!$D:$D,$A41,'NSE - Other Index Options'!$B:$B,"Tuesday")=0,"",SUMIFS('NSE - NIFTY Index Options'!$L:$L,'NSE - NIFTY Index Options'!$D:$D,$A41,'NSE - NIFTY Index Options'!$B:$B,"Tuesday")+SUMIFS('NSE - Other Index Options'!$L:$L,'NSE - Other Index Options'!$D:$D,$A41,'NSE - Other Index Options'!$B:$B,"Tuesday")) -> 325809.67 | C41: =IF(SUMIFS('BSE - SENSEX Index Options'!$L:$L,'BSE - SENSEX Index Options'!$D:$D,$A41,'BSE - SENSEX Index Options'!$B:$B,"Tuesday")+SUMIFS('BSE - Other Index Options'!$L:$L,'BSE - Other Index Options'!$D:$D,$A41,'BSE - Other Index Options'!$B:$B,"Tuesday")=0,"",SUMIFS('BSE - SENSEX Index Options'!$L:$L,'BSE - SENSEX Index Options'!$D:$D,$A41,'BSE - SENSEX Index Options'!$B:$B,"Tuesday")+SUMIFS('BSE - Other Index Options'!$L:$L,'BSE - Other Index Options'!$D:$D,$A41,'BSE - Other Index Options'!$B:$B,"Tuesday")) -> 56750.32 | D41: =IF(SUM(B41:C41)=0,"",SUM(B41)/SUM(B41:C41)) -> 0.85165642 | E41: =IF(SUM(B41:C41)=0,"",SUM(C41)/SUM(B41:C41)) -> 0.14834358
A42: 46054 | B42: =IF(SUMIFS('NSE - NIFTY Index Options'!$L:$L,'NSE - NIFTY Index Options'!$D:$D,$A42,'NSE - NIFTY Index Options'!$B:$B,"Tuesday")+SUMIFS('NSE - Other Index Options'!$L:$L,'NSE - Other Index Options'!$D:$D,$A42,'NSE - Other Index Options'!$B:$B,"Tuesday")=0,"",SUMIFS('NSE - NIFTY Index Options'!$L:$L,'NSE - NIFTY Index Options'!$D:$D,$A42,'NSE - NIFTY Index Options'!$B:$B,"Tuesday")+SUMIFS('NSE - Other Index Options'!$L:$L,'NSE - Other Index Options'!$D:$D,$A42,'NSE - Other Index Options'!$B:$B,"Tuesday")) -> 344645.84 | C42: =IF(SUMIFS('BSE - SENSEX Index Options'!$L:$L,'BSE - SENSEX Index Options'!$D:$D,$A42,'BSE - SENSEX Index Options'!$B:$B,"Tuesday")+SUMIFS('BSE - Other Index Options'!$L:$L,'BSE - Other Index Options'!$D:$D,$A42,'BSE - Other Index Options'!$B:$B,"Tuesday")=0,"",SUMIFS('BSE - SENSEX Index Options'!$L:$L,'BSE - SENSEX Index Options'!$D:$D,$A42,'BSE - SENSEX Index Options'!$B:$B,"Tuesday")+SUMIFS('BSE - Other Index Options'!$L:$L,'BSE - Other Index Options'!$D:$D,$A42,'BSE - Other Index Options'!$B:$B,"Tuesday")) -> 52376.41 | D42: =IF(SUM(B42:C42)=0,"",SUM(B42)/SUM(B42:C42)) -> 0.86807689 | E42: =IF(SUM(B42:C42)=0,"",SUM(C42)/SUM(B42:C42)) -> 0.13192311
A43: 46082 | B43: =IF(SUMIFS('NSE - NIFTY Index Options'!$L:$L,'NSE - NIFTY Index Options'!$D:$D,$A43,'NSE - NIFTY Index Options'!$B:$B,"Tuesday")+SUMIFS('NSE - Other Index Options'!$L:$L,'NSE - Other Index Options'!$D:$D,$A43,'NSE - Other Index Options'!$B:$B,"Tuesday")=0,"",SUMIFS('NSE - NIFTY Index Options'!$L:$L,'NSE - NIFTY Index Options'!$D:$D,$A43,'NSE - NIFTY Index Options'!$B:$B,"Tuesday")+SUMIFS('NSE - Other Index Options'!$L:$L,'NSE - Other Index Options'!$D:$D,$A43,'NSE - Other Index Options'!$B:$B,"Tuesday")) -> 333055.23 | C43: =IF(SUMIFS('BSE - SENSEX Index Options'!$L:$L,'BSE - SENSEX Index Options'!$D:$D,$A43,'BSE - SENSEX Index Options'!$B:$B,"Tuesday")+SUMIFS('BSE - Other Index Options'!$L:$L,'BSE - Other Index Options'!$D:$D,$A43,'BSE - Other Index Options'!$B:$B,"Tuesday")=0,"",SUMIFS('BSE - SENSEX Index Options'!$L:$L,'BSE - SENSEX Index Options'!$D:$D,$A43,'BSE - SENSEX Index Options'!$B:$B,"Tuesday")+SUMIFS('BSE - Other Index Options'!$L:$L,'BSE - Other Index Options'!$D:$D,$A43,'BSE - Other Index Options'!$B:$B,"Tuesday")) -> 49767.1 | D43: =IF(SUM(B43:C43)=0,"",SUM(B43)/SUM(B43:C43)) -> 0.86999949 | E43: =IF(SUM(B43:C43)=0,"",SUM(C43)/SUM(B43:C43)) -> 0.13000051
A44: 46113 | B44: =IF(SUMIFS('NSE - NIFTY Index Options'!$L:$L,'NSE - NIFTY Index Options'!$D:$D,$A44,'NSE - NIFTY Index Options'!$B:$B,"Tuesday")+SUMIFS('NSE - Other Index Options'!$L:$L,'NSE - Other Index Options'!$D:$D,$A44,'NSE - Other Index Options'!$B:$B,"Tuesday")=0,"",SUMIFS('NSE - NIFTY Index Options'!$L:$L,'NSE - NIFTY Index Options'!$D:$D,$A44,'NSE - NIFTY Index Options'!$B:$B,"Tuesday")+SUMIFS('NSE - Other Index Options'!$L:$L,'NSE - Other Index Options'!$D:$D,$A44,'NSE - Other Index Options'!$B:$B,"Tuesday")) -> 245311.47 | C44: =IF(SUMIFS('BSE - SENSEX Index Options'!$L:$L,'BSE - SENSEX Index Options'!$D:$D,$A44,'BSE - SENSEX Index Options'!$B:$B,"Tuesday")+SUMIFS('BSE - Other Index Options'!$L:$L,'BSE - Other Index Options'!$D:$D,$A44,'BSE - Other Index Options'!$B:$B,"Tuesday")=0,"",SUMIFS('BSE - SENSEX Index Options'!$L:$L,'BSE - SENSEX Index Options'!$D:$D,$A44,'BSE - SENSEX Index Options'!$B:$B,"Tuesday")+SUMIFS('BSE - Other Index Options'!$L:$L,'BSE - Other Index Options'!$D:$D,$A44,'BSE - Other Index Options'!$B:$B,"Tuesday")) -> 32501.9 | D44: =IF(SUM(B44:C44)=0,"",SUM(B44)/SUM(B44:C44)) -> 0.88300815 | E44: =IF(SUM(B44:C44)=0,"",SUM(C44)/SUM(B44:C44)) -> 0.11699185
A45: 46143 | B45: =IF(SUMIFS('NSE - NIFTY Index Options'!$L:$L,'NSE - NIFTY Index Options'!$D:$D,$A45,'NSE - NIFTY Index Options'!$B:$B,"Tuesday")+SUMIFS('NSE - Other Index Options'!$L:$L,'NSE - Other Index Options'!$D:$D,$A45,'NSE - Other Index Options'!$B:$B,"Tuesday")=0,"",SUMIFS('NSE - NIFTY Index Options'!$L:$L,'NSE - NIFTY Index Options'!$D:$D,$A45,'NSE - NIFTY Index Options'!$B:$B,"Tuesday")+SUMIFS('NSE - Other Index Options'!$L:$L,'NSE - Other Index Options'!$D:$D,$A45,'NSE - Other Index Options'!$B:$B,"Tuesday")) -> 319647.91 | C45: =IF(SUMIFS('BSE - SENSEX Index Options'!$L:$L,'BSE - SENSEX Index Options'!$D:$D,$A45,'BSE - SENSEX Index Options'!$B:$B,"Tuesday")+SUMIFS('BSE - Other Index Options'!$L:$L,'BSE - Other Index Options'!$D:$D,$A45,'BSE - Other Index Options'!$B:$B,"Tuesday")=0,"",SUMIFS('BSE - SENSEX Index Options'!$L:$L,'BSE - SENSEX Index Options'!$D:$D,$A45,'BSE - SENSEX Index Options'!$B:$B,"Tuesday")+SUMIFS('BSE - Other Index Options'!$L:$L,'BSE - Other Index Options'!$D:$D,$A45,'BSE - Other Index Options'!$B:$B,"Tuesday")) -> 46010.85 | D45: =IF(SUM(B45:C45)=0,"",SUM(B45)/SUM(B45:C45)) -> 0.87416998 | E45: =IF(SUM(B45:C45)=0,"",SUM(C45)/SUM(B45:C45)) -> 0.12583002
A46: 46174 | B46: =IF(SUMIFS('NSE - NIFTY Index Options'!$L:$L,'NSE - NIFTY Index Options'!$D:$D,$A46,'NSE - NIFTY Index Options'!$B:$B,"Tuesday")+SUMIFS('NSE - Other Index Options'!$L:$L,'NSE - Other Index Options'!$D:$D,$A46,'NSE - Other Index Options'!$B:$B,"Tuesday")=0,"",SUMIFS('NSE - NIFTY Index Options'!$L:$L,'NSE - NIFTY Index Options'!$D:$D,$A46,'NSE - NIFTY Index Options'!$B:$B,"Tuesday")+SUMIFS('NSE - Other Index Options'!$L:$L,'NSE - Other Index Options'!$D:$D,$A46,'NSE - Other Index Options'!$B:$B,"Tuesday")) -> 385735.92 | C46: =IF(SUMIFS('BSE - SENSEX Index Options'!$L:$L,'BSE - SENSEX Index Options'!$D:$D,$A46,'BSE - SENSEX Index Options'!$B:$B,"Tuesday")+SUMIFS('BSE - Other Index Options'!$L:$L,'BSE - Other Index Options'!$D:$D,$A46,'BSE - Other Index Options'!$B:$B,"Tuesday")=0,"",SUMIFS('BSE - SENSEX Index Options'!$L:$L,'BSE - SENSEX Index Options'!$D:$D,$A46,'BSE - SENSEX Index Options'!$B:$B,"Tuesday")+SUMIFS('BSE - Other Index Options'!$L:$L,'BSE - Other Index Options'!$D:$D,$A46,'BSE - Other Index Options'!$B:$B,"Tuesday")) -> 56164.73 | D46: =IF(SUM(B46:C46)=0,"",SUM(B46)/SUM(B46:C46)) -> 0.87290191 | E46: =IF(SUM(B46:C46)=0,"",SUM(C46)/SUM(B46:C46)) -> 0.12709809
A47: 46204 | B47: =IF(SUMIFS('NSE - NIFTY Index Options'!$L:$L,'NSE - NIFTY Index Options'!$D:$D,$A47,'NSE - NIFTY Index Options'!$B:$B,"Tuesday")+SUMIFS('NSE - Other Index Options'!$L:$L,'NSE - Other Index Options'!$D:$D,$A47,'NSE - Other Index Options'!$B:$B,"Tuesday")=0,"",SUMIFS('NSE - NIFTY Index Options'!$L:$L,'NSE - NIFTY Index Options'!$D:$D,$A47,'NSE - NIFTY Index Options'!$B:$B,"Tuesday")+SUMIFS('NSE - Other Index Options'!$L:$L,'NSE - Other Index Options'!$D:$D,$A47,'NSE - Other Index Options'!$B:$B,"Tuesday")) -> 59870.49 | C47: =IF(SUMIFS('BSE - SENSEX Index Options'!$L:$L,'BSE - SENSEX Index Options'!$D:$D,$A47,'BSE - SENSEX Index Options'!$B:$B,"Tuesday")+SUMIFS('BSE - Other Index Options'!$L:$L,'BSE - Other Index Options'!$D:$D,$A47,'BSE - Other Index Options'!$B:$B,"Tuesday")=0,"",SUMIFS('BSE - SENSEX Index Options'!$L:$L,'BSE - SENSEX Index Options'!$D:$D,$A47,'BSE - SENSEX Index Options'!$B:$B,"Tuesday")+SUMIFS('BSE - Other Index Options'!$L:$L,'BSE - Other Index Options'!$D:$D,$A47,'BSE - Other Index Options'!$B:$B,"Tuesday")) -> 10159.3 | D47: =IF(SUM(B47:C47)=0,"",SUM(B47)/SUM(B47:C47)) -> 0.85492888 | E47: =IF(SUM(B47:C47)=0,"",SUM(C47)/SUM(B47:C47)) -> 0.14507112
