Workbook

Sheet Quality Check
A1: Quality Check — Exchanges Monthly Weekly Expiry (MASTER FILE)
A3: Exchange | B3: Sheet | C3: Data From | D3: Data To | E3: Data Rows | F3: Premium Turnover (INR Bn) | I3: Data Sources
A4: NSE | B4: NSE - NIFTY Index Options | C4: ='NSE - NIFTY Index Options'!A2 -> 01-Sep-2025 | D4: =LOOKUP(2,1/('NSE - NIFTY Index Options'!$A$2:$A$100000<>""),'NSE - NIFTY Index Options'!$A$2:$A$100000) -> 17-Jul-2026 | E4: =COUNTA('NSE - NIFTY Index Options'!A:A)-1 -> 3906 | F4: =SUM('NSE - NIFTY Index Options'!L:L) -> 106798.5 | I4: NSE: F&O contract-wise archives (Security-wise Price Volume data) - https://www.nseindia.com/report-detail/fo_eq_security (API: nseindia.com/api/historicalOR/foCPV, instrumentType=OPTIDX; NIFTY, BANKNIFTY, FINNIFTY, MIDCPNIFTY, NIFTYNXT50)
A5: NSE | B5: NSE - Other Index Options | C5: ='NSE - Other Index Options'!A2 -> 01-Sep-2025 | D5: =LOOKUP(2,1/('NSE - Other Index Options'!$A$2:$A$100000<>""),'NSE - Other Index Options'!$A$2:$A$100000) -> 17-Jul-2026 | E5: =COUNTA('NSE - Other Index Options'!A:A)-1 -> 1302 | F5: =SUM('NSE - Other Index Options'!L:L) -> 11552.228 | I5: BSE: Derivatives historical archives - https://www.bseindia.com/markets/derivatives/derireports/derihistorical (API: api.bseindia.com/BseIndiaAPI, Product_Type=IO; SENSEX + other index options)
A6: BSE | B6: BSE - SENSEX Index Options | C6: ='BSE - SENSEX Index Options'!A2 -> 01-Sep-2025 | D6: =LOOKUP(2,1/('BSE - SENSEX Index Options'!$A$2:$A$100000<>""),'BSE - SENSEX Index Options'!$A$2:$A$100000) -> 17-Jul-2026 | E6: =COUNTA('BSE - SENSEX Index Options'!A:A)-1 -> 1402 | F6: =SUM('BSE - SENSEX Index Options'!L:L) -> 54230.209 | I6: Units: raw API turnover in INR lakh, converted to INR Bn (divided by 10,000). Contracts: NSE = traded qty / market lot; BSE = as reported.
A7: BSE | B7: BSE - Other Index Options | C7: ='BSE - Other Index Options'!A2 -> 01-Sep-2025 | D7: =LOOKUP(2,1/('BSE - Other Index Options'!$A$2:$A$100000<>""),'BSE - Other Index Options'!$A$2:$A$100000) -> 17-Jul-2026 | E7: =COUNTA('BSE - Other Index Options'!A:A)-1 -> 396 | F7: =SUM('BSE - Other Index Options'!L:L) -> 133.5026 | I7: Validation: BSE daily aggregates reconciled against BSE consolidated product-wise report (0 mismatches, tolerance 0.5%); NSE verified internally (contracts x lot x underlying = notional).
I8: Extraction scripts: nse_options_expiry.py / bse_options_expiry.py in the project's Python Files folder.
A9: NSE data updated through: | B9: =IF(D4=D5,D4,"MISMATCH between NSE sheets") -> 17-Jul-2026
A10: BSE data updated through: | B10: =IF(D6=D7,D6,"MISMATCH between BSE sheets") -> 17-Jul-2026
A11: NSE & BSE end dates aligned? | B11: =IF(B9=B10,"YES","NO — update the lagging exchange") -> YES
A12: Master file created: | B12: 46210
A13: Last data refresh: | B13: 46223
A14: Monthly Totals (live — populates as data is updated)
A15: Month | B15: NSE - Number of Contracts | C15: NSE - Notional Turnover (INR Bn) | D15: NSE - Premium Turnover (INR Bn) | E15: BSE - Number of Contracts | F15: BSE - Notional Turnover (INR Bn) | G15: BSE - Premium Turnover (INR Bn)
A16: 45901 | B16: =IF(SUMIFS('NSE - NIFTY Index Options'!$J:$J,'NSE - NIFTY Index Options'!$D:$D,$A16)+SUMIFS('NSE - Other Index Options'!$J:$J,'NSE - Other Index Options'!$D:$D,$A16)=0,"",SUMIFS('NSE - NIFTY Index Options'!$J:$J,'NSE - NIFTY Index Options'!$D:$D,$A16)+SUMIFS('NSE - Other Index Options'!$J:$J,'NSE - Other Index Options'!$D:$D,$A16)) -> 3099946962 | C16: =IF(SUMIFS('NSE - NIFTY Index Options'!$K:$K,'NSE - NIFTY Index Options'!$D:$D,$A16)+SUMIFS('NSE - Other Index Options'!$K:$K,'NSE - Other Index Options'!$D:$D,$A16)=0,"",SUMIFS('NSE - NIFTY Index Options'!$K:$K,'NSE - NIFTY Index Options'!$D:$D,$A16)+SUMIFS('NSE - Other Index Options'!$K:$K,'NSE - Other Index Options'!$D:$D,$A16)) -> 5807256.4 | D16: =IF(SUMIFS('NSE - NIFTY Index Options'!$L:$L,'NSE - NIFTY Index Options'!$D:$D,$A16)+SUMIFS('NSE - Other Index Options'!$L:$L,'NSE - Other Index Options'!$D:$D,$A16)=0,"",SUMIFS('NSE - NIFTY Index Options'!$L:$L,'NSE - NIFTY Index Options'!$D:$D,$A16)+SUMIFS('NSE - Other Index Options'!$L:$L,'NSE - Other Index Options'!$D:$D,$A16)) -> 9332.5851 | E16: =IF(SUMIFS('BSE - SENSEX Index Options'!$J:$J,'BSE - SENSEX Index Options'!$D:$D,$A16)+SUMIFS('BSE - Other Index Options'!$J:$J,'BSE - Other Index Options'!$D:$D,$A16)=0,"",SUMIFS('BSE - SENSEX Index Options'!$J:$J,'BSE - SENSEX Index Options'!$D:$D,$A16)+SUMIFS('BSE - Other Index Options'!$J:$J,'BSE - Other Index Options'!$D:$D,$A16)) -> 2235360301 | F16: =IF(SUMIFS('BSE - SENSEX Index Options'!$K:$K,'BSE - SENSEX Index Options'!$D:$D,$A16)+SUMIFS('BSE - Other Index Options'!$K:$K,'BSE - Other Index Options'!$D:$D,$A16)=0,"",SUMIFS('BSE - SENSEX Index Options'!$K:$K,'BSE - SENSEX Index Options'!$D:$D,$A16)+SUMIFS('BSE - Other Index Options'!$K:$K,'BSE - Other Index Options'!$D:$D,$A16)) -> 3651815.5 | G16: =IF(SUMIFS('BSE - SENSEX Index Options'!$L:$L,'BSE - SENSEX Index Options'!$D:$D,$A16)+SUMIFS('BSE - Other Index Options'!$L:$L,'BSE - Other Index Options'!$D:$D,$A16)=0,"",SUMIFS('BSE - SENSEX Index Options'!$L:$L,'BSE - SENSEX Index Options'!$D:$D,$A16)+SUMIFS('BSE - Other Index Options'!$L:$L,'BSE - Other Index Options'!$D:$D,$A16)) -> 3462.2472
A17: 45931 | B17: =IF(SUMIFS('NSE - NIFTY Index Options'!$J:$J,'NSE - NIFTY Index Options'!$D:$D,$A17)+SUMIFS('NSE - Other Index Options'!$J:$J,'NSE - Other Index Options'!$D:$D,$A17)=0,"",SUMIFS('NSE - NIFTY Index Options'!$J:$J,'NSE - NIFTY Index Options'!$D:$D,$A17)+SUMIFS('NSE - Other Index Options'!$J:$J,'NSE - Other Index Options'!$D:$D,$A17)) -> 3053547719 | C17: =IF(SUMIFS('NSE - NIFTY Index Options'!$K:$K,'NSE - NIFTY Index Options'!$D:$D,$A17)+SUMIFS('NSE - Other Index Options'!$K:$K,'NSE - Other Index Options'!$D:$D,$A17)=0,"",SUMIFS('NSE - NIFTY Index Options'!$K:$K,'NSE - NIFTY Index Options'!$D:$D,$A17)+SUMIFS('NSE - Other Index Options'!$K:$K,'NSE - Other Index Options'!$D:$D,$A17)) -> 5859561 | D17: =IF(SUMIFS('NSE - NIFTY Index Options'!$L:$L,'NSE - NIFTY Index Options'!$D:$D,$A17)+SUMIFS('NSE - Other Index Options'!$L:$L,'NSE - Other Index Options'!$D:$D,$A17)=0,"",SUMIFS('NSE - NIFTY Index Options'!$L:$L,'NSE - NIFTY Index Options'!$D:$D,$A17)+SUMIFS('NSE - Other Index Options'!$L:$L,'NSE - Other Index Options'!$D:$D,$A17)) -> 10417.99 | E17: =IF(SUMIFS('BSE - SENSEX Index Options'!$J:$J,'BSE - SENSEX Index Options'!$D:$D,$A17)+SUMIFS('BSE - Other Index Options'!$J:$J,'BSE - Other Index Options'!$D:$D,$A17)=0,"",SUMIFS('BSE - SENSEX Index Options'!$J:$J,'BSE - SENSEX Index Options'!$D:$D,$A17)+SUMIFS('BSE - Other Index Options'!$J:$J,'BSE - Other Index Options'!$D:$D,$A17)) -> 2790051623 | F17: =IF(SUMIFS('BSE - SENSEX Index Options'!$K:$K,'BSE - SENSEX Index Options'!$D:$D,$A17)+SUMIFS('BSE - Other Index Options'!$K:$K,'BSE - Other Index Options'!$D:$D,$A17)=0,"",SUMIFS('BSE - SENSEX Index Options'!$K:$K,'BSE - SENSEX Index Options'!$D:$D,$A17)+SUMIFS('BSE - Other Index Options'!$K:$K,'BSE - Other Index Options'!$D:$D,$A17)) -> 4641252.5 | G17: =IF(SUMIFS('BSE - SENSEX Index Options'!$L:$L,'BSE - SENSEX Index Options'!$D:$D,$A17)+SUMIFS('BSE - Other Index Options'!$L:$L,'BSE - Other Index Options'!$D:$D,$A17)=0,"",SUMIFS('BSE - SENSEX Index Options'!$L:$L,'BSE - SENSEX Index Options'!$D:$D,$A17)+SUMIFS('BSE - Other Index Options'!$L:$L,'BSE - Other Index Options'!$D:$D,$A17)) -> 4304.274
A18: 45962 | B18: =IF(SUMIFS('NSE - NIFTY Index Options'!$J:$J,'NSE - NIFTY Index Options'!$D:$D,$A18)+SUMIFS('NSE - Other Index Options'!$J:$J,'NSE - Other Index Options'!$D:$D,$A18)=0,"",SUMIFS('NSE - NIFTY Index Options'!$J:$J,'NSE - NIFTY Index Options'!$D:$D,$A18)+SUMIFS('NSE - Other Index Options'!$J:$J,'NSE - Other Index Options'!$D:$D,$A18)) -> 2587888973 | C18: =IF(SUMIFS('NSE - NIFTY Index Options'!$K:$K,'NSE - NIFTY Index Options'!$D:$D,$A18)+SUMIFS('NSE - Other Index Options'!$K:$K,'NSE - Other Index Options'!$D:$D,$A18)=0,"",SUMIFS('NSE - NIFTY Index Options'!$K:$K,'NSE - NIFTY Index Options'!$D:$D,$A18)+SUMIFS('NSE - Other Index Options'!$K:$K,'NSE - Other Index Options'!$D:$D,$A18)) -> 5040587.9 | D18: =IF(SUMIFS('NSE - NIFTY Index Options'!$L:$L,'NSE - NIFTY Index Options'!$D:$D,$A18)+SUMIFS('NSE - Other Index Options'!$L:$L,'NSE - Other Index Options'!$D:$D,$A18)=0,"",SUMIFS('NSE - NIFTY Index Options'!$L:$L,'NSE - NIFTY Index Options'!$D:$D,$A18)+SUMIFS('NSE - Other Index Options'!$L:$L,'NSE - Other Index Options'!$D:$D,$A18)) -> 9132.7733 | E18: =IF(SUMIFS('BSE - SENSEX Index Options'!$J:$J,'BSE - SENSEX Index Options'!$D:$D,$A18)+SUMIFS('BSE - Other Index Options'!$J:$J,'BSE - Other Index Options'!$D:$D,$A18)=0,"",SUMIFS('BSE - SENSEX Index Options'!$J:$J,'BSE - SENSEX Index Options'!$D:$D,$A18)+SUMIFS('BSE - Other Index Options'!$J:$J,'BSE - Other Index Options'!$D:$D,$A18)) -> 2335516230 | F18: =IF(SUMIFS('BSE - SENSEX Index Options'!$K:$K,'BSE - SENSEX Index Options'!$D:$D,$A18)+SUMIFS('BSE - Other Index Options'!$K:$K,'BSE - Other Index Options'!$D:$D,$A18)=0,"",SUMIFS('BSE - SENSEX Index Options'!$K:$K,'BSE - SENSEX Index Options'!$D:$D,$A18)+SUMIFS('BSE - Other Index Options'!$K:$K,'BSE - Other Index Options'!$D:$D,$A18)) -> 3963897 | G18: =IF(SUMIFS('BSE - SENSEX Index Options'!$L:$L,'BSE - SENSEX Index Options'!$D:$D,$A18)+SUMIFS('BSE - Other Index Options'!$L:$L,'BSE - Other Index Options'!$D:$D,$A18)=0,"",SUMIFS('BSE - SENSEX Index Options'!$L:$L,'BSE - SENSEX Index Options'!$D:$D,$A18)+SUMIFS('BSE - Other Index Options'!$L:$L,'BSE - Other Index Options'!$D:$D,$A18)) -> 3631.3211
A19: 45992 | B19: =IF(SUMIFS('NSE - NIFTY Index Options'!$J:$J,'NSE - NIFTY Index Options'!$D:$D,$A19)+SUMIFS('NSE - Other Index Options'!$J:$J,'NSE - Other Index Options'!$D:$D,$A19)=0,"",SUMIFS('NSE - NIFTY Index Options'!$J:$J,'NSE - NIFTY Index Options'!$D:$D,$A19)+SUMIFS('NSE - Other Index Options'!$J:$J,'NSE - Other Index Options'!$D:$D,$A19)) -> 2990707367 | C19: =IF(SUMIFS('NSE - NIFTY Index Options'!$K:$K,'NSE - NIFTY Index Options'!$D:$D,$A19)+SUMIFS('NSE - Other Index Options'!$K:$K,'NSE - Other Index Options'!$D:$D,$A19)=0,"",SUMIFS('NSE - NIFTY Index Options'!$K:$K,'NSE - NIFTY Index Options'!$D:$D,$A19)+SUMIFS('NSE - Other Index Options'!$K:$K,'NSE - Other Index Options'!$D:$D,$A19)) -> 5834460.1 | D19: =IF(SUMIFS('NSE - NIFTY Index Options'!$L:$L,'NSE - NIFTY Index Options'!$D:$D,$A19)+SUMIFS('NSE - Other Index Options'!$L:$L,'NSE - Other Index Options'!$D:$D,$A19)=0,"",SUMIFS('NSE - NIFTY Index Options'!$L:$L,'NSE - NIFTY Index Options'!$D:$D,$A19)+SUMIFS('NSE - Other Index Options'!$L:$L,'NSE - Other Index Options'!$D:$D,$A19)) -> 9469.2296 | E19: =IF(SUMIFS('BSE - SENSEX Index Options'!$J:$J,'BSE - SENSEX Index Options'!$D:$D,$A19)+SUMIFS('BSE - Other Index Options'!$J:$J,'BSE - Other Index Options'!$D:$D,$A19)=0,"",SUMIFS('BSE - SENSEX Index Options'!$J:$J,'BSE - SENSEX Index Options'!$D:$D,$A19)+SUMIFS('BSE - Other Index Options'!$J:$J,'BSE - Other Index Options'!$D:$D,$A19)) -> 2594328292 | F19: =IF(SUMIFS('BSE - SENSEX Index Options'!$K:$K,'BSE - SENSEX Index Options'!$D:$D,$A19)+SUMIFS('BSE - Other Index Options'!$K:$K,'BSE - Other Index Options'!$D:$D,$A19)=0,"",SUMIFS('BSE - SENSEX Index Options'!$K:$K,'BSE - SENSEX Index Options'!$D:$D,$A19)+SUMIFS('BSE - Other Index Options'!$K:$K,'BSE - Other Index Options'!$D:$D,$A19)) -> 4414449.5 | G19: =IF(SUMIFS('BSE - SENSEX Index Options'!$L:$L,'BSE - SENSEX Index Options'!$D:$D,$A19)+SUMIFS('BSE - Other Index Options'!$L:$L,'BSE - Other Index Options'!$D:$D,$A19)=0,"",SUMIFS('BSE - SENSEX Index Options'!$L:$L,'BSE - SENSEX Index Options'!$D:$D,$A19)+SUMIFS('BSE - Other Index Options'!$L:$L,'BSE - Other Index Options'!$D:$D,$A19)) -> 4129.0249
A20: 46023 | B20: =IF(SUMIFS('NSE - NIFTY Index Options'!$J:$J,'NSE - NIFTY Index Options'!$D:$D,$A20)+SUMIFS('NSE - Other Index Options'!$J:$J,'NSE - Other Index Options'!$D:$D,$A20)=0,"",SUMIFS('NSE - NIFTY Index Options'!$J:$J,'NSE - NIFTY Index Options'!$D:$D,$A20)+SUMIFS('NSE - Other Index Options'!$J:$J,'NSE - Other Index Options'!$D:$D,$A20)) -> 3556776860 | C20: =IF(SUMIFS('NSE - NIFTY Index Options'!$K:$K,'NSE - NIFTY Index Options'!$D:$D,$A20)+SUMIFS('NSE - Other Index Options'!$K:$K,'NSE - Other Index Options'!$D:$D,$A20)=0,"",SUMIFS('NSE - NIFTY Index Options'!$K:$K,'NSE - NIFTY Index Options'!$D:$D,$A20)+SUMIFS('NSE - Other Index Options'!$K:$K,'NSE - Other Index Options'!$D:$D,$A20)) -> 5959791.8 | D20: =IF(SUMIFS('NSE - NIFTY Index Options'!$L:$L,'NSE - NIFTY Index Options'!$D:$D,$A20)+SUMIFS('NSE - Other Index Options'!$L:$L,'NSE - Other Index Options'!$D:$D,$A20)=0,"",SUMIFS('NSE - NIFTY Index Options'!$L:$L,'NSE - NIFTY Index Options'!$D:$D,$A20)+SUMIFS('NSE - Other Index Options'!$L:$L,'NSE - Other Index Options'!$D:$D,$A20)) -> 11531.54 | E20: =IF(SUMIFS('BSE - SENSEX Index Options'!$J:$J,'BSE - SENSEX Index Options'!$D:$D,$A20)+SUMIFS('BSE - Other Index Options'!$J:$J,'BSE - Other Index Options'!$D:$D,$A20)=0,"",SUMIFS('BSE - SENSEX Index Options'!$J:$J,'BSE - SENSEX Index Options'!$D:$D,$A20)+SUMIFS('BSE - Other Index Options'!$J:$J,'BSE - Other Index Options'!$D:$D,$A20)) -> 3431358943 | F20: =IF(SUMIFS('BSE - SENSEX Index Options'!$K:$K,'BSE - SENSEX Index Options'!$D:$D,$A20)+SUMIFS('BSE - Other Index Options'!$K:$K,'BSE - Other Index Options'!$D:$D,$A20)=0,"",SUMIFS('BSE - SENSEX Index Options'!$K:$K,'BSE - SENSEX Index Options'!$D:$D,$A20)+SUMIFS('BSE - Other Index Options'!$K:$K,'BSE - Other Index Options'!$D:$D,$A20)) -> 5731640.5 | G20: =IF(SUMIFS('BSE - SENSEX Index Options'!$L:$L,'BSE - SENSEX Index Options'!$D:$D,$A20)+SUMIFS('BSE - Other Index Options'!$L:$L,'BSE - Other Index Options'!$D:$D,$A20)=0,"",SUMIFS('BSE - SENSEX Index Options'!$L:$L,'BSE - SENSEX Index Options'!$D:$D,$A20)+SUMIFS('BSE - Other Index Options'!$L:$L,'BSE - Other Index Options'!$D:$D,$A20)) -> 5753.7784
A21: 46054 | B21: =IF(SUMIFS('NSE - NIFTY Index Options'!$J:$J,'NSE - NIFTY Index Options'!$D:$D,$A21)+SUMIFS('NSE - Other Index Options'!$J:$J,'NSE - Other Index Options'!$D:$D,$A21)=0,"",SUMIFS('NSE - NIFTY Index Options'!$J:$J,'NSE - NIFTY Index Options'!$D:$D,$A21)+SUMIFS('NSE - Other Index Options'!$J:$J,'NSE - Other Index Options'!$D:$D,$A21)) -> 3553974028 | C21: =IF(SUMIFS('NSE - NIFTY Index Options'!$K:$K,'NSE - NIFTY Index Options'!$D:$D,$A21)+SUMIFS('NSE - Other Index Options'!$K:$K,'NSE - Other Index Options'!$D:$D,$A21)=0,"",SUMIFS('NSE - NIFTY Index Options'!$K:$K,'NSE - NIFTY Index Options'!$D:$D,$A21)+SUMIFS('NSE - Other Index Options'!$K:$K,'NSE - Other Index Options'!$D:$D,$A21)) -> 5949997.9 | D21: =IF(SUMIFS('NSE - NIFTY Index Options'!$L:$L,'NSE - NIFTY Index Options'!$D:$D,$A21)+SUMIFS('NSE - Other Index Options'!$L:$L,'NSE - Other Index Options'!$D:$D,$A21)=0,"",SUMIFS('NSE - NIFTY Index Options'!$L:$L,'NSE - NIFTY Index Options'!$D:$D,$A21)+SUMIFS('NSE - Other Index Options'!$L:$L,'NSE - Other Index Options'!$D:$D,$A21)) -> 12839.693 | E21: =IF(SUMIFS('BSE - SENSEX Index Options'!$J:$J,'BSE - SENSEX Index Options'!$D:$D,$A21)+SUMIFS('BSE - Other Index Options'!$J:$J,'BSE - Other Index Options'!$D:$D,$A21)=0,"",SUMIFS('BSE - SENSEX Index Options'!$J:$J,'BSE - SENSEX Index Options'!$D:$D,$A21)+SUMIFS('BSE - Other Index Options'!$J:$J,'BSE - Other Index Options'!$D:$D,$A21)) -> 2818479299 | F21: =IF(SUMIFS('BSE - SENSEX Index Options'!$K:$K,'BSE - SENSEX Index Options'!$D:$D,$A21)+SUMIFS('BSE - Other Index Options'!$K:$K,'BSE - Other Index Options'!$D:$D,$A21)=0,"",SUMIFS('BSE - SENSEX Index Options'!$K:$K,'BSE - SENSEX Index Options'!$D:$D,$A21)+SUMIFS('BSE - Other Index Options'!$K:$K,'BSE - Other Index Options'!$D:$D,$A21)) -> 4693409.7 | G21: =IF(SUMIFS('BSE - SENSEX Index Options'!$L:$L,'BSE - SENSEX Index Options'!$D:$D,$A21)+SUMIFS('BSE - Other Index Options'!$L:$L,'BSE - Other Index Options'!$D:$D,$A21)=0,"",SUMIFS('BSE - SENSEX Index Options'!$L:$L,'BSE - SENSEX Index Options'!$D:$D,$A21)+SUMIFS('BSE - Other Index Options'!$L:$L,'BSE - Other Index Options'!$D:$D,$A21)) -> 5320.6359
A22: 46082 | B22: =IF(SUMIFS('NSE - NIFTY Index Options'!$J:$J,'NSE - NIFTY Index Options'!$D:$D,$A22)+SUMIFS('NSE - Other Index Options'!$J:$J,'NSE - Other Index Options'!$D:$D,$A22)=0,"",SUMIFS('NSE - NIFTY Index Options'!$J:$J,'NSE - NIFTY Index Options'!$D:$D,$A22)+SUMIFS('NSE - Other Index Options'!$J:$J,'NSE - Other Index Options'!$D:$D,$A22)) -> 3507526776 | C22: =IF(SUMIFS('NSE - NIFTY Index Options'!$K:$K,'NSE - NIFTY Index Options'!$D:$D,$A22)+SUMIFS('NSE - Other Index Options'!$K:$K,'NSE - Other Index Options'!$D:$D,$A22)=0,"",SUMIFS('NSE - NIFTY Index Options'!$K:$K,'NSE - NIFTY Index Options'!$D:$D,$A22)+SUMIFS('NSE - Other Index Options'!$K:$K,'NSE - Other Index Options'!$D:$D,$A22)) -> 5410440 | D22: =IF(SUMIFS('NSE - NIFTY Index Options'!$L:$L,'NSE - NIFTY Index Options'!$D:$D,$A22)+SUMIFS('NSE - Other Index Options'!$L:$L,'NSE - Other Index Options'!$D:$D,$A22)=0,"",SUMIFS('NSE - NIFTY Index Options'!$L:$L,'NSE - NIFTY Index Options'!$D:$D,$A22)+SUMIFS('NSE - Other Index Options'!$L:$L,'NSE - Other Index Options'!$D:$D,$A22)) -> 16246.679 | E22: =IF(SUMIFS('BSE - SENSEX Index Options'!$J:$J,'BSE - SENSEX Index Options'!$D:$D,$A22)+SUMIFS('BSE - Other Index Options'!$J:$J,'BSE - Other Index Options'!$D:$D,$A22)=0,"",SUMIFS('BSE - SENSEX Index Options'!$J:$J,'BSE - SENSEX Index Options'!$D:$D,$A22)+SUMIFS('BSE - Other Index Options'!$J:$J,'BSE - Other Index Options'!$D:$D,$A22)) -> 2780655501 | F22: =IF(SUMIFS('BSE - SENSEX Index Options'!$K:$K,'BSE - SENSEX Index Options'!$D:$D,$A22)+SUMIFS('BSE - Other Index Options'!$K:$K,'BSE - Other Index Options'!$D:$D,$A22)=0,"",SUMIFS('BSE - SENSEX Index Options'!$K:$K,'BSE - SENSEX Index Options'!$D:$D,$A22)+SUMIFS('BSE - Other Index Options'!$K:$K,'BSE - Other Index Options'!$D:$D,$A22)) -> 4274629.1 | G22: =IF(SUMIFS('BSE - SENSEX Index Options'!$L:$L,'BSE - SENSEX Index Options'!$D:$D,$A22)+SUMIFS('BSE - Other Index Options'!$L:$L,'BSE - Other Index Options'!$D:$D,$A22)=0,"",SUMIFS('BSE - SENSEX Index Options'!$L:$L,'BSE - SENSEX Index Options'!$D:$D,$A22)+SUMIFS('BSE - Other Index Options'!$L:$L,'BSE - Other Index Options'!$D:$D,$A22)) -> 6278.0398
A23: 46113 | B23: =IF(SUMIFS('NSE - NIFTY Index Options'!$J:$J,'NSE - NIFTY Index Options'!$D:$D,$A23)+SUMIFS('NSE - Other Index Options'!$J:$J,'NSE - Other Index Options'!$D:$D,$A23)=0,"",SUMIFS('NSE - NIFTY Index Options'!$J:$J,'NSE - NIFTY Index Options'!$D:$D,$A23)+SUMIFS('NSE - Other Index Options'!$J:$J,'NSE - Other Index Options'!$D:$D,$A23)) -> 2704917038 | C23: =IF(SUMIFS('NSE - NIFTY Index Options'!$K:$K,'NSE - NIFTY Index Options'!$D:$D,$A23)+SUMIFS('NSE - Other Index Options'!$K:$K,'NSE - Other Index Options'!$D:$D,$A23)=0,"",SUMIFS('NSE - NIFTY Index Options'!$K:$K,'NSE - NIFTY Index Options'!$D:$D,$A23)+SUMIFS('NSE - Other Index Options'!$K:$K,'NSE - Other Index Options'!$D:$D,$A23)) -> 4212880.9 | D23: =IF(SUMIFS('NSE - NIFTY Index Options'!$L:$L,'NSE - NIFTY Index Options'!$D:$D,$A23)+SUMIFS('NSE - Other Index Options'!$L:$L,'NSE - Other Index Options'!$D:$D,$A23)=0,"",SUMIFS('NSE - NIFTY Index Options'!$L:$L,'NSE - NIFTY Index Options'!$D:$D,$A23)+SUMIFS('NSE - Other Index Options'!$L:$L,'NSE - Other Index Options'!$D:$D,$A23)) -> 11243.915 | E23: =IF(SUMIFS('BSE - SENSEX Index Options'!$J:$J,'BSE - SENSEX Index Options'!$D:$D,$A23)+SUMIFS('BSE - Other Index Options'!$J:$J,'BSE - Other Index Options'!$D:$D,$A23)=0,"",SUMIFS('BSE - SENSEX Index Options'!$J:$J,'BSE - SENSEX Index Options'!$D:$D,$A23)+SUMIFS('BSE - Other Index Options'!$J:$J,'BSE - Other Index Options'!$D:$D,$A23)) -> 3511987765 | F23: =IF(SUMIFS('BSE - SENSEX Index Options'!$K:$K,'BSE - SENSEX Index Options'!$D:$D,$A23)+SUMIFS('BSE - Other Index Options'!$K:$K,'BSE - Other Index Options'!$D:$D,$A23)=0,"",SUMIFS('BSE - SENSEX Index Options'!$K:$K,'BSE - SENSEX Index Options'!$D:$D,$A23)+SUMIFS('BSE - Other Index Options'!$K:$K,'BSE - Other Index Options'!$D:$D,$A23)) -> 5377649.8 | G23: =IF(SUMIFS('BSE - SENSEX Index Options'!$L:$L,'BSE - SENSEX Index Options'!$D:$D,$A23)+SUMIFS('BSE - Other Index Options'!$L:$L,'BSE - Other Index Options'!$D:$D,$A23)=0,"",SUMIFS('BSE - SENSEX Index Options'!$L:$L,'BSE - SENSEX Index Options'!$D:$D,$A23)+SUMIFS('BSE - Other Index Options'!$L:$L,'BSE - Other Index Options'!$D:$D,$A23)) -> 6628.9961
A24: 46143 | B24: =IF(SUMIFS('NSE - NIFTY Index Options'!$J:$J,'NSE - NIFTY Index Options'!$D:$D,$A24)+SUMIFS('NSE - Other Index Options'!$J:$J,'NSE - Other Index Options'!$D:$D,$A24)=0,"",SUMIFS('NSE - NIFTY Index Options'!$J:$J,'NSE - NIFTY Index Options'!$D:$D,$A24)+SUMIFS('NSE - Other Index Options'!$J:$J,'NSE - Other Index Options'!$D:$D,$A24)) -> 3038254197 | C24: =IF(SUMIFS('NSE - NIFTY Index Options'!$K:$K,'NSE - NIFTY Index Options'!$D:$D,$A24)+SUMIFS('NSE - Other Index Options'!$K:$K,'NSE - Other Index Options'!$D:$D,$A24)=0,"",SUMIFS('NSE - NIFTY Index Options'!$K:$K,'NSE - NIFTY Index Options'!$D:$D,$A24)+SUMIFS('NSE - Other Index Options'!$K:$K,'NSE - Other Index Options'!$D:$D,$A24)) -> 4737453.4 | D24: =IF(SUMIFS('NSE - NIFTY Index Options'!$L:$L,'NSE - NIFTY Index Options'!$D:$D,$A24)+SUMIFS('NSE - Other Index Options'!$L:$L,'NSE - Other Index Options'!$D:$D,$A24)=0,"",SUMIFS('NSE - NIFTY Index Options'!$L:$L,'NSE - NIFTY Index Options'!$D:$D,$A24)+SUMIFS('NSE - Other Index Options'!$L:$L,'NSE - Other Index Options'!$D:$D,$A24)) -> 11128.716 | E24: =IF(SUMIFS('BSE - SENSEX Index Options'!$J:$J,'BSE - SENSEX Index Options'!$D:$D,$A24)+SUMIFS('BSE - Other Index Options'!$J:$J,'BSE - Other Index Options'!$D:$D,$A24)=0,"",SUMIFS('BSE - SENSEX Index Options'!$J:$J,'BSE - SENSEX Index Options'!$D:$D,$A24)+SUMIFS('BSE - Other Index Options'!$J:$J,'BSE - Other Index Options'!$D:$D,$A24)) -> 2859237260 | F24: =IF(SUMIFS('BSE - SENSEX Index Options'!$K:$K,'BSE - SENSEX Index Options'!$D:$D,$A24)+SUMIFS('BSE - Other Index Options'!$K:$K,'BSE - Other Index Options'!$D:$D,$A24)=0,"",SUMIFS('BSE - SENSEX Index Options'!$K:$K,'BSE - SENSEX Index Options'!$D:$D,$A24)+SUMIFS('BSE - Other Index Options'!$K:$K,'BSE - Other Index Options'!$D:$D,$A24)) -> 4360339.9 | G24: =IF(SUMIFS('BSE - SENSEX Index Options'!$L:$L,'BSE - SENSEX Index Options'!$D:$D,$A24)+SUMIFS('BSE - Other Index Options'!$L:$L,'BSE - Other Index Options'!$D:$D,$A24)=0,"",SUMIFS('BSE - SENSEX Index Options'!$L:$L,'BSE - SENSEX Index Options'!$D:$D,$A24)+SUMIFS('BSE - Other Index Options'!$L:$L,'BSE - Other Index Options'!$D:$D,$A24)) -> 5636.8826
A25: 46174 | B25: =IF(SUMIFS('NSE - NIFTY Index Options'!$J:$J,'NSE - NIFTY Index Options'!$D:$D,$A25)+SUMIFS('NSE - Other Index Options'!$J:$J,'NSE - Other Index Options'!$D:$D,$A25)=0,"",SUMIFS('NSE - NIFTY Index Options'!$J:$J,'NSE - NIFTY Index Options'!$D:$D,$A25)+SUMIFS('NSE - Other Index Options'!$J:$J,'NSE - Other Index Options'!$D:$D,$A25)) -> 3676370909 | C25: =IF(SUMIFS('NSE - NIFTY Index Options'!$K:$K,'NSE - NIFTY Index Options'!$D:$D,$A25)+SUMIFS('NSE - Other Index Options'!$K:$K,'NSE - Other Index Options'!$D:$D,$A25)=0,"",SUMIFS('NSE - NIFTY Index Options'!$K:$K,'NSE - NIFTY Index Options'!$D:$D,$A25)+SUMIFS('NSE - Other Index Options'!$K:$K,'NSE - Other Index Options'!$D:$D,$A25)) -> 5703559.3 | D25: =IF(SUMIFS('NSE - NIFTY Index Options'!$L:$L,'NSE - NIFTY Index Options'!$D:$D,$A25)+SUMIFS('NSE - Other Index Options'!$L:$L,'NSE - Other Index Options'!$D:$D,$A25)=0,"",SUMIFS('NSE - NIFTY Index Options'!$L:$L,'NSE - NIFTY Index Options'!$D:$D,$A25)+SUMIFS('NSE - Other Index Options'!$L:$L,'NSE - Other Index Options'!$D:$D,$A25)) -> 11487.337 | E25: =IF(SUMIFS('BSE - SENSEX Index Options'!$J:$J,'BSE - SENSEX Index Options'!$D:$D,$A25)+SUMIFS('BSE - Other Index Options'!$J:$J,'BSE - Other Index Options'!$D:$D,$A25)=0,"",SUMIFS('BSE - SENSEX Index Options'!$J:$J,'BSE - SENSEX Index Options'!$D:$D,$A25)+SUMIFS('BSE - Other Index Options'!$J:$J,'BSE - Other Index Options'!$D:$D,$A25)) -> 2968566958 | F25: =IF(SUMIFS('BSE - SENSEX Index Options'!$K:$K,'BSE - SENSEX Index Options'!$D:$D,$A25)+SUMIFS('BSE - Other Index Options'!$K:$K,'BSE - Other Index Options'!$D:$D,$A25)=0,"",SUMIFS('BSE - SENSEX Index Options'!$K:$K,'BSE - SENSEX Index Options'!$D:$D,$A25)+SUMIFS('BSE - Other Index Options'!$K:$K,'BSE - Other Index Options'!$D:$D,$A25)) -> 4497161 | G25: =IF(SUMIFS('BSE - SENSEX Index Options'!$L:$L,'BSE - SENSEX Index Options'!$D:$D,$A25)+SUMIFS('BSE - Other Index Options'!$L:$L,'BSE - Other Index Options'!$D:$D,$A25)=0,"",SUMIFS('BSE - SENSEX Index Options'!$L:$L,'BSE - SENSEX Index Options'!$D:$D,$A25)+SUMIFS('BSE - Other Index Options'!$L:$L,'BSE - Other Index Options'!$D:$D,$A25)) -> 5503.3389
A26: 46204 | B26: =IF(SUMIFS('NSE - NIFTY Index Options'!$J:$J,'NSE - NIFTY Index Options'!$D:$D,$A26)+SUMIFS('NSE - Other Index Options'!$J:$J,'NSE - Other Index Options'!$D:$D,$A26)=0,"",SUMIFS('NSE - NIFTY Index Options'!$J:$J,'NSE - NIFTY Index Options'!$D:$D,$A26)+SUMIFS('NSE - Other Index Options'!$J:$J,'NSE - Other Index Options'!$D:$D,$A26)) -> 1658865585 | C26: =IF(SUMIFS('NSE - NIFTY Index Options'!$K:$K,'NSE - NIFTY Index Options'!$D:$D,$A26)+SUMIFS('NSE - Other Index Options'!$K:$K,'NSE - Other Index Options'!$D:$D,$A26)=0,"",SUMIFS('NSE - NIFTY Index Options'!$K:$K,'NSE - NIFTY Index Options'!$D:$D,$A26)+SUMIFS('NSE - Other Index Options'!$K:$K,'NSE - Other Index Options'!$D:$D,$A26)) -> 2619549.9 | D26: =IF(SUMIFS('NSE - NIFTY Index Options'!$L:$L,'NSE - NIFTY Index Options'!$D:$D,$A26)+SUMIFS('NSE - Other Index Options'!$L:$L,'NSE - Other Index Options'!$D:$D,$A26)=0,"",SUMIFS('NSE - NIFTY Index Options'!$L:$L,'NSE - NIFTY Index Options'!$D:$D,$A26)+SUMIFS('NSE - Other Index Options'!$L:$L,'NSE - Other Index Options'!$D:$D,$A26)) -> 5520.267 | E26: =IF(SUMIFS('BSE - SENSEX Index Options'!$J:$J,'BSE - SENSEX Index Options'!$D:$D,$A26)+SUMIFS('BSE - Other Index Options'!$J:$J,'BSE - Other Index Options'!$D:$D,$A26)=0,"",SUMIFS('BSE - SENSEX Index Options'!$J:$J,'BSE - SENSEX Index Options'!$D:$D,$A26)+SUMIFS('BSE - Other Index Options'!$J:$J,'BSE - Other Index Options'!$D:$D,$A26)) -> 2135572172 | F26: =IF(SUMIFS('BSE - SENSEX Index Options'!$K:$K,'BSE - SENSEX Index Options'!$D:$D,$A26)+SUMIFS('BSE - Other Index Options'!$K:$K,'BSE - Other Index Options'!$D:$D,$A26)=0,"",SUMIFS('BSE - SENSEX Index Options'!$K:$K,'BSE - SENSEX Index Options'!$D:$D,$A26)+SUMIFS('BSE - Other Index Options'!$K:$K,'BSE - Other Index Options'!$D:$D,$A26)) -> 3299727.4 | G26: =IF(SUMIFS('BSE - SENSEX Index Options'!$L:$L,'BSE - SENSEX Index Options'!$D:$D,$A26)+SUMIFS('BSE - Other Index Options'!$L:$L,'BSE - Other Index Options'!$D:$D,$A26)=0,"",SUMIFS('BSE - SENSEX Index Options'!$L:$L,'BSE - SENSEX Index Options'!$D:$D,$A26)+SUMIFS('BSE - Other Index Options'!$L:$L,'BSE - Other Index Options'!$D:$D,$A26)) -> 3715.1728
A27: 46235 | B27: =IF(SUMIFS('NSE - NIFTY Index Options'!$J:$J,'NSE - NIFTY Index Options'!$D:$D,$A27)+SUMIFS('NSE - Other Index Options'!$J:$J,'NSE - Other Index Options'!$D:$D,$A27)=0,"",SUMIFS('NSE - NIFTY Index Options'!$J:$J,'NSE - NIFTY Index Options'!$D:$D,$A27)+SUMIFS('NSE - Other Index Options'!$J:$J,'NSE - Other Index Options'!$D:$D,$A27)) | C27: =IF(SUMIFS('NSE - NIFTY Index Options'!$K:$K,'NSE - NIFTY Index Options'!$D:$D,$A27)+SUMIFS('NSE - Other Index Options'!$K:$K,'NSE - Other Index Options'!$D:$D,$A27)=0,"",SUMIFS('NSE - NIFTY Index Options'!$K:$K,'NSE - NIFTY Index Options'!$D:$D,$A27)+SUMIFS('NSE - Other Index Options'!$K:$K,'NSE - Other Index Options'!$D:$D,$A27)) | D27: =IF(SUMIFS('NSE - NIFTY Index Options'!$L:$L,'NSE - NIFTY Index Options'!$D:$D,$A27)+SUMIFS('NSE - Other Index Options'!$L:$L,'NSE - Other Index Options'!$D:$D,$A27)=0,"",SUMIFS('NSE - NIFTY Index Options'!$L:$L,'NSE - NIFTY Index Options'!$D:$D,$A27)+SUMIFS('NSE - Other Index Options'!$L:$L,'NSE - Other Index Options'!$D:$D,$A27)) | E27: =IF(SUMIFS('BSE - SENSEX Index Options'!$J:$J,'BSE - SENSEX Index Options'!$D:$D,$A27)+SUMIFS('BSE - Other Index Options'!$J:$J,'BSE - Other Index Options'!$D:$D,$A27)=0,"",SUMIFS('BSE - SENSEX Index Options'!$J:$J,'BSE - SENSEX Index Options'!$D:$D,$A27)+SUMIFS('BSE - Other Index Options'!$J:$J,'BSE - Other Index Options'!$D:$D,$A27)) | F27: =IF(SUMIFS('BSE - SENSEX Index Options'!$K:$K,'BSE - SENSEX Index Options'!$D:$D,$A27)+SUMIFS('BSE - Other Index Options'!$K:$K,'BSE - Other Index Options'!$D:$D,$A27)=0,"",SUMIFS('BSE - SENSEX Index Options'!$K:$K,'BSE - SENSEX Index Options'!$D:$D,$A27)+SUMIFS('BSE - Other Index Options'!$K:$K,'BSE - Other Index Options'!$D:$D,$A27)) | G27: =IF(SUMIFS('BSE - SENSEX Index Options'!$L:$L,'BSE - SENSEX Index Options'!$D:$D,$A27)+SUMIFS('BSE - Other Index Options'!$L:$L,'BSE - Other Index Options'!$D:$D,$A27)=0,"",SUMIFS('BSE - SENSEX Index Options'!$L:$L,'BSE - SENSEX Index Options'!$D:$D,$A27)+SUMIFS('BSE - Other Index Options'!$L:$L,'BSE - Other Index Options'!$D:$D,$A27))
... A43: 46722 | B43: =IF(SUMIFS('NSE - NIFTY Index Options'!$J:$J,'NSE - NIFTY Index Options'!$D:$D,$A43)+SUMIFS('NSE - Other Index Options'!$J:$J,'NSE - Other Index Options'!$D:$D,$A43)=0,"",SUMIFS('NSE - NIFTY Index Options'!$J:$J,'NSE - NIFTY Index Options'!$D:$D,$A43)+SUMIFS('NSE - Other Index Options'!$J:$J,'NSE - Other Index Options'!$D:$D,$A43)) | C43: =IF(SUMIFS('NSE - NIFTY Index Options'!$K:$K,'NSE - NIFTY Index Options'!$D:$D,$A43)+SUMIFS('NSE - Other Index Options'!$K:$K,'NSE - Other Index Options'!$D:$D,$A43)=0,"",SUMIFS('NSE - NIFTY Index Options'!$K:$K,'NSE - NIFTY Index Options'!$D:$D,$A43)+SUMIFS('NSE - Other Index Options'!$K:$K,'NSE - Other Index Options'!$D:$D,$A43)) | D43: =IF(SUMIFS('NSE - NIFTY Index Options'!$L:$L,'NSE - NIFTY Index Options'!$D:$D,$A43)+SUMIFS('NSE - Other Index Options'!$L:$L,'NSE - Other Index Options'!$D:$D,$A43)=0,"",SUMIFS('NSE - NIFTY Index Options'!$L:$L,'NSE - NIFTY Index Options'!$D:$D,$A43)+SUMIFS('NSE - Other Index Options'!$L:$L,'NSE - Other Index Options'!$D:$D,$A43)) | E43: =IF(SUMIFS('BSE - SENSEX Index Options'!$J:$J,'BSE - SENSEX Index Options'!$D:$D,$A43)+SUMIFS('BSE - Other Index Options'!$J:$J,'BSE - Other Index Options'!$D:$D,$A43)=0,"",SUMIFS('BSE - SENSEX Index Options'!$J:$J,'BSE - SENSEX Index Options'!$D:$D,$A43)+SUMIFS('BSE - Other Index Options'!$J:$J,'BSE - Other Index Options'!$D:$D,$A43)) | F43: =IF(SUMIFS('BSE - SENSEX Index Options'!$K:$K,'BSE - SENSEX Index Options'!$D:$D,$A43)+SUMIFS('BSE - Other Index Options'!$K:$K,'BSE - Other Index Options'!$D:$D,$A43)=0,"",SUMIFS('BSE - SENSEX Index Options'!$K:$K,'BSE - SENSEX Index Options'!$D:$D,$A43)+SUMIFS('BSE - Other Index Options'!$K:$K,'BSE - Other Index Options'!$D:$D,$A43)) | G43: =IF(SUMIFS('BSE - SENSEX Index Options'!$L:$L,'BSE - SENSEX Index Options'!$D:$D,$A43)+SUMIFS('BSE - Other Index Options'!$L:$L,'BSE - Other Index Options'!$D:$D,$A43)=0,"",SUMIFS('BSE - SENSEX Index Options'!$L:$L,'BSE - SENSEX Index Options'!$D:$D,$A43)+SUMIFS('BSE - Other Index Options'!$L:$L,'BSE - Other Index Options'!$D:$D,$A43))
A44: Total | B44: =IF(SUM(B16:B43)=0,"",SUM(B16:B43)) -> 33428776414 | C44: =IF(SUM(C16:C43)=0,"",SUM(C16:C43)) -> 57135539 | D44: =IF(SUM(D16:D43)=0,"",SUM(D16:D43)) -> 118350.73 | E44: =IF(SUM(E16:E43)=0,"",SUM(E16:E43)) -> 30461114344 | F44: =IF(SUM(F16:F43)=0,"",SUM(F16:F43)) -> 48905972 | G44: =IF(SUM(G16:G43)=0,"",SUM(G16:G43)) -> 54363.712

Sheet Dataset Overview
A1: DATASET OVERVIEW — NSE & BSE Index Options, Expiry-wise Daily Premium Turnover
A2: Orientation page: what this dataset contains, how it is cut, and where to find each view. All figures below are live formulas.
A4: About the data
A5: Granularity: | B5: One row per Trade Date × Expiry Date per sheet; calls and puts combined. Columns: dates, day names, week/month labels, expiry classifications, Contracts, Notional & Premium Turnover.
A6: Coverage: | B6: INDEX OPTIONS ONLY (no stock options, no futures). NSE: NIFTY + other indices (BANKNIFTY, FINNIFTY, MIDCPNIFTY, NIFTYNXT50). BSE: SENSEX + other BSE indices.
A7: Period: | B7: 01-Sep-2025 onwards. NSE updated through: see Quality Check B9; BSE through: Quality Check B10. Includes special Sunday sessions and Muhurat trading.
A8: Units: | B8: Turnover in INR Bn (1 Bn = 100 crore). Raw exchange data arrives in INR lakh and is converted (÷10,000).
A9: Expiry calendar: | B9: NSE expiries fall on Tuesday (Monday when Tuesday is a holiday). BSE expiries fall on Thursday (Wednesday when shifted). NIFTY & SENSEX have weekly + monthly contracts; all other indices are monthly-only.
A10: Expiry Type: | B10: Monthly - <day> if the expiry date is in the last 7 days of its month (the month's final contract), else Weekly - <day>.
A11: Expiry Type 2: | B11: Same as Expiry Type, except a Monthly contract trading within 6 days of its own expiry becomes MDAW - <day> (Monthly acting As Weekly, i.e. the front contract of expiry week). MDAW applies only to NIFTY & SENSEX; other-index sheets keep Expiry Type as-is.
A13: Segment matrix — full period totals (live)
A14: Exchange | B14: Sheet | C14: Expiry Type 2 Cut | D14: Contracts | E14: Notional Turnover (INR Bn) | F14: Premium Turnover (INR Bn) | G14: % of Grand Premium
A15: NSE | B15: NIFTY Index Options | C15: Weekly | D15: =SUMIFS('NSE - NIFTY Index Options'!$J:$J,'NSE - NIFTY Index Options'!$H:$H,"Weekly*") -> 25123619614 | E15: =SUMIFS('NSE - NIFTY Index Options'!$K:$K,'NSE - NIFTY Index Options'!$H:$H,"Weekly*") -> 42707150 | F15: =SUMIFS('NSE - NIFTY Index Options'!$L:$L,'NSE - NIFTY Index Options'!$H:$H,"Weekly*") -> 80949.287 | G15: =IF($F$32=0,"",F15/$F$32) -> 0.4686886
A16: NSE | B16: NIFTY Index Options | C16: MDAW | D16: =SUMIFS('NSE - NIFTY Index Options'!$J:$J,'NSE - NIFTY Index Options'!$H:$H,"MDAW*") -> 5940511083 | E16: =SUMIFS('NSE - NIFTY Index Options'!$K:$K,'NSE - NIFTY Index Options'!$H:$H,"MDAW*") -> 10175975 | F16: =SUMIFS('NSE - NIFTY Index Options'!$L:$L,'NSE - NIFTY Index Options'!$H:$H,"MDAW*") -> 18875.127 | G16: =IF($F$32=0,"",F16/$F$32) -> 0.10928517
A17: NSE | B17: NIFTY Index Options | C17: Monthly | D17: =SUMIFS('NSE - NIFTY Index Options'!$J:$J,'NSE - NIFTY Index Options'!$H:$H,"Monthly*") -> 601353258 | E17: =SUMIFS('NSE - NIFTY Index Options'!$K:$K,'NSE - NIFTY Index Options'!$H:$H,"Monthly*") -> 1036899.6 | F17: =SUMIFS('NSE - NIFTY Index Options'!$L:$L,'NSE - NIFTY Index Options'!$H:$H,"Monthly*") -> 6974.0832 | G17: =IF($F$32=0,"",F17/$F$32) -> 0.040379272
A18: NSE | B18: NIFTY Index Options — Total | D18: =SUM(D15:D17) -> 31665483955 | E18: =SUM(E15:E17) -> 53920024 | F18: =SUM(F15:F17) -> 106798.5 | G18: =IF($F$32=0,"",F18/$F$32) -> 0.61835304
A19: NSE | B19: Other Index Options | C19: Weekly | D19: =SUMIFS('NSE - Other Index Options'!$J:$J,'NSE - Other Index Options'!$H:$H,"Weekly*") -> 0 | E19: =SUMIFS('NSE - Other Index Options'!$K:$K,'NSE - Other Index Options'!$H:$H,"Weekly*") -> 0 | F19: =SUMIFS('NSE - Other Index Options'!$L:$L,'NSE - Other Index Options'!$H:$H,"Weekly*") -> 0 | G19: =IF($F$32=0,"",F19/$F$32) -> 0
A20: NSE | B20: Other Index Options | C20: MDAW | D20: =SUMIFS('NSE - Other Index Options'!$J:$J,'NSE - Other Index Options'!$H:$H,"MDAW*") -> 0 | E20: =SUMIFS('NSE - Other Index Options'!$K:$K,'NSE - Other Index Options'!$H:$H,"MDAW*") -> 0 | F20: =SUMIFS('NSE - Other Index Options'!$L:$L,'NSE - Other Index Options'!$H:$H,"MDAW*") -> 0 | G20: =IF($F$32=0,"",F20/$F$32) -> 0
A21: NSE | B21: Other Index Options | C21: Monthly | D21: =SUMIFS('NSE - Other Index Options'!$J:$J,'NSE - Other Index Options'!$H:$H,"Monthly*") -> 1763292459 | E21: =SUMIFS('NSE - Other Index Options'!$K:$K,'NSE - Other Index Options'!$H:$H,"Monthly*") -> 3215514.4 | F21: =SUMIFS('NSE - Other Index Options'!$L:$L,'NSE - Other Index Options'!$H:$H,"Monthly*") -> 11552.228 | G21: =IF($F$32=0,"",F21/$F$32) -> 0.06688629
A22: NSE | B22: Other Index Options — Total | D22: =SUM(D19:D21) -> 1763292459 | E22: =SUM(E19:E21) -> 3215514.4 | F22: =SUM(F19:F21) -> 11552.228 | G22: =IF($F$32=0,"",F22/$F$32) -> 0.06688629
A23: BSE | B23: SENSEX Index Options | C23: Weekly | D23: =SUMIFS('BSE - SENSEX Index Options'!$J:$J,'BSE - SENSEX Index Options'!$H:$H,"Weekly*") -> 24566933353 | E23: =SUMIFS('BSE - SENSEX Index Options'!$K:$K,'BSE - SENSEX Index Options'!$H:$H,"Weekly*") -> 39416808 | F23: =SUMIFS('BSE - SENSEX Index Options'!$L:$L,'BSE - SENSEX Index Options'!$H:$H,"Weekly*") -> 43803.318 | G23: =IF($F$32=0,"",F23/$F$32) -> 0.253617
A24: BSE | B24: SENSEX Index Options | C24: MDAW | D24: =SUMIFS('BSE - SENSEX Index Options'!$J:$J,'BSE - SENSEX Index Options'!$H:$H,"MDAW*") -> 5793661425 | E24: =SUMIFS('BSE - SENSEX Index Options'!$K:$K,'BSE - SENSEX Index Options'!$H:$H,"MDAW*") -> 9303331.2 | F24: =SUMIFS('BSE - SENSEX Index Options'!$L:$L,'BSE - SENSEX Index Options'!$H:$H,"MDAW*") -> 10200.019 | G24: =IF($F$32=0,"",F24/$F$32) -> 0.059057128
A25: BSE | B25: SENSEX Index Options | C25: Monthly | D25: =SUMIFS('BSE - SENSEX Index Options'!$J:$J,'BSE - SENSEX Index Options'!$H:$H,"Monthly*") -> 30877741 | E25: =SUMIFS('BSE - SENSEX Index Options'!$K:$K,'BSE - SENSEX Index Options'!$H:$H,"Monthly*") -> 50540.097 | F25: =SUMIFS('BSE - SENSEX Index Options'!$L:$L,'BSE - SENSEX Index Options'!$H:$H,"Monthly*") -> 226.8724 | G25: =IF($F$32=0,"",F25/$F$32) -> 0.0013135694
A26: BSE | B26: SENSEX Index Options — Total | D26: =SUM(D23:D25) -> 30391472519 | E26: =SUM(E23:E25) -> 48770680 | F26: =SUM(F23:F25) -> 54230.209 | G26: =IF($F$32=0,"",F26/$F$32) -> 0.3139877
A27: BSE | B27: Other Index Options | C27: Weekly | D27: =SUMIFS('BSE - Other Index Options'!$J:$J,'BSE - Other Index Options'!$H:$H,"Weekly*") -> 0 | E27: =SUMIFS('BSE - Other Index Options'!$K:$K,'BSE - Other Index Options'!$H:$H,"Weekly*") -> 0 | F27: =SUMIFS('BSE - Other Index Options'!$L:$L,'BSE - Other Index Options'!$H:$H,"Weekly*") -> 0 | G27: =IF($F$32=0,"",F27/$F$32) -> 0
A28: BSE | B28: Other Index Options | C28: MDAW | D28: =SUMIFS('BSE - Other Index Options'!$J:$J,'BSE - Other Index Options'!$H:$H,"MDAW*") -> 0 | E28: =SUMIFS('BSE - Other Index Options'!$K:$K,'BSE - Other Index Options'!$H:$H,"MDAW*") -> 0 | F28: =SUMIFS('BSE - Other Index Options'!$L:$L,'BSE - Other Index Options'!$H:$H,"MDAW*") -> 0 | G28: =IF($F$32=0,"",F28/$F$32) -> 0
A29: BSE | B29: Other Index Options | C29: Monthly | D29: =SUMIFS('BSE - Other Index Options'!$J:$J,'BSE - Other Index Options'!$H:$H,"Monthly*") -> 69641825 | E29: =SUMIFS('BSE - Other Index Options'!$K:$K,'BSE - Other Index Options'!$H:$H,"Monthly*") -> 135291.91 | F29: =SUMIFS('BSE - Other Index Options'!$L:$L,'BSE - Other Index Options'!$H:$H,"Monthly*") -> 133.5026 | G29: =IF($F$32=0,"",F29/$F$32) -> 0.00077296723
A30: BSE | B30: Other Index Options — Total | D30: =SUM(D27:D29) -> 69641825 | E30: =SUM(E27:E29) -> 135291.91 | F30: =SUM(F27:F29) -> 133.5026 | G30: =IF($F$32=0,"",F30/$F$32) -> 0.00077296723
A32: GRAND TOTAL | D32: =D18+D22+D26+D30 -> 63889890758 | E32: =E18+E22+E26+E30 -> 1.0604151e+08 | F32: =F18+F22+F26+F30 -> 172714.44 | G32: =IF($F$32=0,"",F32/$F$32) -> 1
A35: Sheet guide
A36: Quality Check | B36: Data currency per sheet, NSE/BSE alignment flag, monthly totals, data sources.
A37: Analysis1 | B37: Monthly premium by trade day (6 tables, Mon-Fri + Sunday), NSE vs BSE + market share. All expiry types.
A38: Analysis2 | B38: Same as Analysis1 but weekly-expiry contracts only.
A39: Analysis3 | B39: Week-level premium by trade day: NSE / BSE premium & share matrices. All expiry types.
A40: Analysis4 | B40: Week-level matrices, Weekly + MDAW premium only.
A41: Analysis5 | B41: Week-level matrices, Monthly premium only.
A42: Analysis6 | B42: Overall monthly NSE vs BSE: three tables (All / Weekly+MDAW / Monthly).
A43: Analysis7 | B43: Overall monthly NSE vs BSE: four tables (All / Weekly / MDAW / Monthly) + composition of each cut as % of All (NSE, BSE, combined).
A44: Analysis8 | B44: Combined NSE+BSE week × day premium matrix + day-wise weekly composition + Mon+Tue / Wed+Thu / Fri grouping. All expiry types.
A45: Analysis9 | B45: Same as Analysis8 but Weekly + MDAW only.
...

Sheet Analysis1
A1: Premium Turnover Time Series by Trade Day — NSE vs BSE (Sep-2025 onwards, live — populates as master data is updated) | K1: Cuts / Scope
A2: Index options premium turnover (INR Bn) per month, one table per trade day (Mon-Fri + Sunday special sessions): NSE (NIFTY + other indices) vs BSE (SENSEX + other indices) with market share. ALL expiry types. Data: NSE & BSE contract-level archives, Sep-2025 onwards; live formulas — future months are blank and grouped (click + to expand). | K2: Index Options | L2: Yes
A3: Monday Trade Day | K3: Stock Options | L3: No
A4: Month | B4: NSE Premium Turnover (INR Bn) | C4: BSE Premium Turnover (INR Bn) | D4: NSE Market Share | E4: BSE Market Share | K4: Index Futures | L4: No
A5: 45901 | B5: =IF(SUMIFS('NSE - NIFTY Index Options'!$L:$L,'NSE - NIFTY Index Options'!$D:$D,$A5,'NSE - NIFTY Index Options'!$B:$B,"Monday")+SUMIFS('NSE - Other Index Options'!$L:$L,'NSE - Other Index Options'!$D:$D,$A5,'NSE - Other Index Options'!$B:$B,"Monday")=0,"",SUMIFS('NSE - NIFTY Index Options'!$L:$L,'NSE - NIFTY Index Options'!$D:$D,$A5,'NSE - NIFTY Index Options'!$B:$B,"Monday")+SUMIFS('NSE - Other Index Options'!$L:$L,'NSE - Other Index Options'!$D:$D,$A5,'NSE - Other Index Options'!$B:$B,"Monday")) -> 2182.4289 | C5: =IF(SUMIFS('BSE - SENSEX Index Options'!$L:$L,'BSE - SENSEX Index Options'!$D:$D,$A5,'BSE - SENSEX Index Options'!$B:$B,"Monday")+SUMIFS('BSE - Other Index Options'!$L:$L,'BSE - Other Index Options'!$D:$D,$A5,'BSE - Other Index Options'!$B:$B,"Monday")=0,"",SUMIFS('BSE - SENSEX Index Options'!$L:$L,'BSE - SENSEX Index Options'!$D:$D,$A5,'BSE - SENSEX Index Options'!$B:$B,"Monday")+SUMIFS('BSE - Other Index Options'!$L:$L,'BSE - Other Index Options'!$D:$D,$A5,'BSE - Other Index Options'!$B:$B,"Monday")) -> 405.9117 | D5: =IF(SUM(B5:C5)=0,"",SUM(B5)/SUM(B5:C5)) -> 0.84317686 | E5: =IF(SUM(B5:C5)=0,"",SUM(C5)/SUM(B5:C5)) -> 0.15682314 | K5: NSE | L5: Yes
A6: 45931 | B6: =IF(SUMIFS('NSE - NIFTY Index Options'!$L:$L,'NSE - NIFTY Index Options'!$D:$D,$A6,'NSE - NIFTY Index Options'!$B:$B,"Monday")+SUMIFS('NSE - Other Index Options'!$L:$L,'NSE - Other Index Options'!$D:$D,$A6,'NSE - Other Index Options'!$B:$B,"Monday")=0,"",SUMIFS('NSE - NIFTY Index Options'!$L:$L,'NSE - NIFTY Index Options'!$D:$D,$A6,'NSE - NIFTY Index Options'!$B:$B,"Monday")+SUMIFS('NSE - Other Index Options'!$L:$L,'NSE - Other Index Options'!$D:$D,$A6,'NSE - Other Index Options'!$B:$B,"Monday")) -> 2246.8502 | C6: =IF(SUMIFS('BSE - SENSEX Index Options'!$L:$L,'BSE - SENSEX Index Options'!$D:$D,$A6,'BSE - SENSEX Index Options'!$B:$B,"Monday")+SUMIFS('BSE - Other Index Options'!$L:$L,'BSE - Other Index Options'!$D:$D,$A6,'BSE - Other Index Options'!$B:$B,"Monday")=0,"",SUMIFS('BSE - SENSEX Index Options'!$L:$L,'BSE - SENSEX Index Options'!$D:$D,$A6,'BSE - SENSEX Index Options'!$B:$B,"Monday")+SUMIFS('BSE - Other Index Options'!$L:$L,'BSE - Other Index Options'!$D:$D,$A6,'BSE - Other Index Options'!$B:$B,"Monday")) -> 391.2667 | D6: =IF(SUM(B6:C6)=0,"",SUM(B6)/SUM(B6:C6)) -> 0.85168713 | E6: =IF(SUM(B6:C6)=0,"",SUM(C6)/SUM(B6:C6)) -> 0.14831287 | K6: BSE | L6: Yes
A7: 45962 | B7: =IF(SUMIFS('NSE - NIFTY Index Options'!$L:$L,'NSE - NIFTY Index Options'!$D:$D,$A7,'NSE - NIFTY Index Options'!$B:$B,"Monday")+SUMIFS('NSE - Other Index Options'!$L:$L,'NSE - Other Index Options'!$D:$D,$A7,'NSE - Other Index Options'!$B:$B,"Monday")=0,"",SUMIFS('NSE - NIFTY Index Options'!$L:$L,'NSE - NIFTY Index Options'!$D:$D,$A7,'NSE - NIFTY Index Options'!$B:$B,"Monday")+SUMIFS('NSE - Other Index Options'!$L:$L,'NSE - Other Index Options'!$D:$D,$A7,'NSE - Other Index Options'!$B:$B,"Monday")) -> 1968.3215 | C7: =IF(SUMIFS('BSE - SENSEX Index Options'!$L:$L,'BSE - SENSEX Index Options'!$D:$D,$A7,'BSE - SENSEX Index Options'!$B:$B,"Monday")+SUMIFS('BSE - Other Index Options'!$L:$L,'BSE - Other Index Options'!$D:$D,$A7,'BSE - Other Index Options'!$B:$B,"Monday")=0,"",SUMIFS('BSE - SENSEX Index Options'!$L:$L,'BSE - SENSEX Index Options'!$D:$D,$A7,'BSE - SENSEX Index Options'!$B:$B,"Monday")+SUMIFS('BSE - Other Index Options'!$L:$L,'BSE - Other Index Options'!$D:$D,$A7,'BSE - Other Index Options'!$B:$B,"Monday")) -> 347.4632 | D7: =IF(SUM(B7:C7)=0,"",SUM(B7)/SUM(B7:C7)) -> 0.84995876 | E7: =IF(SUM(B7:C7)=0,"",SUM(C7)/SUM(B7:C7)) -> 0.15004124 | K7: NIFTY Index | L7: Yes
A8: 45992 | B8: =IF(SUMIFS('NSE - NIFTY Index Options'!$L:$L,'NSE - NIFTY Index Options'!$D:$D,$A8,'NSE - NIFTY Index Options'!$B:$B,"Monday")+SUMIFS('NSE - Other Index Options'!$L:$L,'NSE - Other Index Options'!$D:$D,$A8,'NSE - Other Index Options'!$B:$B,"Monday")=0,"",SUMIFS('NSE - NIFTY Index Options'!$L:$L,'NSE - NIFTY Index Options'!$D:$D,$A8,'NSE - NIFTY Index Options'!$B:$B,"Monday")+SUMIFS('NSE - Other Index Options'!$L:$L,'NSE - Other Index Options'!$D:$D,$A8,'NSE - Other Index Options'!$B:$B,"Monday")) -> 2246.6209 | C8: =IF(SUMIFS('BSE - SENSEX Index Options'!$L:$L,'BSE - SENSEX Index Options'!$D:$D,$A8,'BSE - SENSEX Index Options'!$B:$B,"Monday")+SUMIFS('BSE - Other Index Options'!$L:$L,'BSE - Other Index Options'!$D:$D,$A8,'BSE - Other Index Options'!$B:$B,"Monday")=0,"",SUMIFS('BSE - SENSEX Index Options'!$L:$L,'BSE - SENSEX Index Options'!$D:$D,$A8,'BSE - SENSEX Index Options'!$B:$B,"Monday")+SUMIFS('BSE - Other Index Options'!$L:$L,'BSE - Other Index Options'!$D:$D,$A8,'BSE - Other Index Options'!$B:$B,"Monday")) -> 444.2045 | D8: =IF(SUM(B8:C8)=0,"",SUM(B8)/SUM(B8:C8)) -> 0.83491887 | E8: =IF(SUM(B8:C8)=0,"",SUM(C8)/SUM(B8:C8)) -> 0.16508113 | K8: Other NSE Indices | L8: Yes
A9: 46023 | B9: =IF(SUMIFS('NSE - NIFTY Index Options'!$L:$L,'NSE - NIFTY Index Options'!$D:$D,$A9,'NSE - NIFTY Index Options'!$B:$B,"Monday")+SUMIFS('NSE - Other Index Options'!$L:$L,'NSE - Other Index Options'!$D:$D,$A9,'NSE - Other Index Options'!$B:$B,"Monday")=0,"",SUMIFS('NSE - NIFTY Index Options'!$L:$L,'NSE - NIFTY Index Options'!$D:$D,$A9,'NSE - NIFTY Index Options'!$B:$B,"Monday")+SUMIFS('NSE - Other Index Options'!$L:$L,'NSE - Other Index Options'!$D:$D,$A9,'NSE - Other Index Options'!$B:$B,"Monday")) -> 1887.0359 | C9: =IF(SUMIFS('BSE - SENSEX Index Options'!$L:$L,'BSE - SENSEX Index Options'!$D:$D,$A9,'BSE - SENSEX Index Options'!$B:$B,"Monday")+SUMIFS('BSE - Other Index Options'!$L:$L,'BSE - Other Index Options'!$D:$D,$A9,'BSE - Other Index Options'!$B:$B,"Monday")=0,"",SUMIFS('BSE - SENSEX Index Options'!$L:$L,'BSE - SENSEX Index Options'!$D:$D,$A9,'BSE - SENSEX Index Options'!$B:$B,"Monday")+SUMIFS('BSE - Other Index Options'!$L:$L,'BSE - Other Index Options'!$D:$D,$A9,'BSE - Other Index Options'!$B:$B,"Monday")) -> 406.061 | D9: =IF(SUM(B9:C9)=0,"",SUM(B9)/SUM(B9:C9)) -> 0.82292026 | E9: =IF(SUM(B9:C9)=0,"",SUM(C9)/SUM(B9:C9)) -> 0.17707974 | K9: SENSEX Index | L9: Yes
A10: 46054 | B10: =IF(SUMIFS('NSE - NIFTY Index Options'!$L:$L,'NSE - NIFTY Index Options'!$D:$D,$A10,'NSE - NIFTY Index Options'!$B:$B,"Monday")+SUMIFS('NSE - Other Index Options'!$L:$L,'NSE - Other Index Options'!$D:$D,$A10,'NSE - Other Index Options'!$B:$B,"Monday")=0,"",SUMIFS('NSE - NIFTY Index Options'!$L:$L,'NSE - NIFTY Index Options'!$D:$D,$A10,'NSE - NIFTY Index Options'!$B:$B,"Monday")+SUMIFS('NSE - Other Index Options'!$L:$L,'NSE - Other Index Options'!$D:$D,$A10,'NSE - Other Index Options'!$B:$B,"Monday")) -> 2735.854 | C10: =IF(SUMIFS('BSE - SENSEX Index Options'!$L:$L,'BSE - SENSEX Index Options'!$D:$D,$A10,'BSE - SENSEX Index Options'!$B:$B,"Monday")+SUMIFS('BSE - Other Index Options'!$L:$L,'BSE - Other Index Options'!$D:$D,$A10,'BSE - Other Index Options'!$B:$B,"Monday")=0,"",SUMIFS('BSE - SENSEX Index Options'!$L:$L,'BSE - SENSEX Index Options'!$D:$D,$A10,'BSE - SENSEX Index Options'!$B:$B,"Monday")+SUMIFS('BSE - Other Index Options'!$L:$L,'BSE - Other Index Options'!$D:$D,$A10,'BSE - Other Index Options'!$B:$B,"Monday")) -> 495.3982 | D10: =IF(SUM(B10:C10)=0,"",SUM(B10)/SUM(B10:C10)) -> 0.84668538 | E10: =IF(SUM(B10:C10)=0,"",SUM(C10)/SUM(B10:C10)) -> 0.15331462 | K10: Other BSE Indices | L10: Yes
A11: 46082 | B11: =IF(SUMIFS('NSE - NIFTY Index Options'!$L:$L,'NSE - NIFTY Index Options'!$D:$D,$A11,'NSE - NIFTY Index Options'!$B:$B,"Monday")+SUMIFS('NSE - Other Index Options'!$L:$L,'NSE - Other Index Options'!$D:$D,$A11,'NSE - Other Index Options'!$B:$B,"Monday")=0,"",SUMIFS('NSE - NIFTY Index Options'!$L:$L,'NSE - NIFTY Index Options'!$D:$D,$A11,'NSE - NIFTY Index Options'!$B:$B,"Monday")+SUMIFS('NSE - Other Index Options'!$L:$L,'NSE - Other Index Options'!$D:$D,$A11,'NSE - Other Index Options'!$B:$B,"Monday")) -> 5503.2387 | C11: =IF(SUMIFS('BSE - SENSEX Index Options'!$L:$L,'BSE - SENSEX Index Options'!$D:$D,$A11,'BSE - SENSEX Index Options'!$B:$B,"Monday")+SUMIFS('BSE - Other Index Options'!$L:$L,'BSE - Other Index Options'!$D:$D,$A11,'BSE - Other Index Options'!$B:$B,"Monday")=0,"",SUMIFS('BSE - SENSEX Index Options'!$L:$L,'BSE - SENSEX Index Options'!$D:$D,$A11,'BSE - SENSEX Index Options'!$B:$B,"Monday")+SUMIFS('BSE - Other Index Options'!$L:$L,'BSE - Other Index Options'!$D:$D,$A11,'BSE - Other Index Options'!$B:$B,"Monday")) -> 807.4614 | D11: =IF(SUM(B11:C11)=0,"",SUM(B11)/SUM(B11:C11)) -> 0.87204884 | E11: =IF(SUM(B11:C11)=0,"",SUM(C11)/SUM(B11:C11)) -> 0.12795116 | K11: Expiry Type 2 - Weekly | L11: Yes
A12: 46113 | B12: =IF(SUMIFS('NSE - NIFTY Index Options'!$L:$L,'NSE - NIFTY Index Options'!$D:$D,$A12,'NSE - NIFTY Index Options'!$B:$B,"Monday")+SUMIFS('NSE - Other Index Options'!$L:$L,'NSE - Other Index Options'!$D:$D,$A12,'NSE - Other Index Options'!$B:$B,"Monday")=0,"",SUMIFS('NSE - NIFTY Index Options'!$L:$L,'NSE - NIFTY Index Options'!$D:$D,$A12,'NSE - NIFTY Index Options'!$B:$B,"Monday")+SUMIFS('NSE - Other Index Options'!$L:$L,'NSE - Other Index Options'!$D:$D,$A12,'NSE - Other Index Options'!$B:$B,"Monday")) -> 3009.4779 | C12: =IF(SUMIFS('BSE - SENSEX Index Options'!$L:$L,'BSE - SENSEX Index Options'!$D:$D,$A12,'BSE - SENSEX Index Options'!$B:$B,"Monday")+SUMIFS('BSE - Other Index Options'!$L:$L,'BSE - Other Index Options'!$D:$D,$A12,'BSE - Other Index Options'!$B:$B,"Monday")=0,"",SUMIFS('BSE - SENSEX Index Options'!$L:$L,'BSE - SENSEX Index Options'!$D:$D,$A12,'BSE - SENSEX Index Options'!$B:$B,"Monday")+SUMIFS('BSE - Other Index Options'!$L:$L,'BSE - Other Index Options'!$D:$D,$A12,'BSE - Other Index Options'!$B:$B,"Monday")) -> 490.4214 | D12: =IF(SUM(B12:C12)=0,"",SUM(B12)/SUM(B12:C12)) -> 0.85987557 | E12: =IF(SUM(B12:C12)=0,"",SUM(C12)/SUM(B12:C12)) -> 0.14012443 | K12: Expiry Type 2 - MDAW | L12: Yes
A13: 46143 | B13: =IF(SUMIFS('NSE - NIFTY Index Options'!$L:$L,'NSE - NIFTY Index Options'!$D:$D,$A13,'NSE - NIFTY Index Options'!$B:$B,"Monday")+SUMIFS('NSE - Other Index Options'!$L:$L,'NSE - Other Index Options'!$D:$D,$A13,'NSE - Other Index Options'!$B:$B,"Monday")=0,"",SUMIFS('NSE - NIFTY Index Options'!$L:$L,'NSE - NIFTY Index Options'!$D:$D,$A13,'NSE - NIFTY Index Options'!$B:$B,"Monday")+SUMIFS('NSE - Other Index Options'!$L:$L,'NSE - Other Index Options'!$D:$D,$A13,'NSE - Other Index Options'!$B:$B,"Monday")) -> 2759.5683 | C13: =IF(SUMIFS('BSE - SENSEX Index Options'!$L:$L,'BSE - SENSEX Index Options'!$D:$D,$A13,'BSE - SENSEX Index Options'!$B:$B,"Monday")+SUMIFS('BSE - Other Index Options'!$L:$L,'BSE - Other Index Options'!$D:$D,$A13,'BSE - Other Index Options'!$B:$B,"Monday")=0,"",SUMIFS('BSE - SENSEX Index Options'!$L:$L,'BSE - SENSEX Index Options'!$D:$D,$A13,'BSE - SENSEX Index Options'!$B:$B,"Monday")+SUMIFS('BSE - Other Index Options'!$L:$L,'BSE - Other Index Options'!$D:$D,$A13,'BSE - Other Index Options'!$B:$B,"Monday")) -> 518.2124 | D13: =IF(SUM(B13:C13)=0,"",SUM(B13)/SUM(B13:C13)) -> 0.84190144 | E13: =IF(SUM(B13:C13)=0,"",SUM(C13)/SUM(B13:C13)) -> 0.15809856 | K13: Expiry Type 2 - Monthly | L13: Yes
A14: 46174 | B14: =IF(SUMIFS('NSE - NIFTY Index Options'!$L:$L,'NSE - NIFTY Index Options'!$D:$D,$A14,'NSE - NIFTY Index Options'!$B:$B,"Monday")+SUMIFS('NSE - Other Index Options'!$L:$L,'NSE - Other Index Options'!$D:$D,$A14,'NSE - Other Index Options'!$B:$B,"Monday")=0,"",SUMIFS('NSE - NIFTY Index Options'!$L:$L,'NSE - NIFTY Index Options'!$D:$D,$A14,'NSE - NIFTY Index Options'!$B:$B,"Monday")+SUMIFS('NSE - Other Index Options'!$L:$L,'NSE - Other Index Options'!$D:$D,$A14,'NSE - Other Index Options'!$B:$B,"Monday")) -> 2921.816 | C14: =IF(SUMIFS('BSE - SENSEX Index Options'!$L:$L,'BSE - SENSEX Index Options'!$D:$D,$A14,'BSE - SENSEX Index Options'!$B:$B,"Monday")+SUMIFS('BSE - Other Index Options'!$L:$L,'BSE - Other Index Options'!$D:$D,$A14,'BSE - Other Index Options'!$B:$B,"Monday")=0,"",SUMIFS('BSE - SENSEX Index Options'!$L:$L,'BSE - SENSEX Index Options'!$D:$D,$A14,'BSE - SENSEX Index Options'!$B:$B,"Monday")+SUMIFS('BSE - Other Index Options'!$L:$L,'BSE - Other Index Options'!$D:$D,$A14,'BSE - Other Index Options'!$B:$B,"Monday")) -> 524.7205 | D14: =IF(SUM(B14:C14)=0,"",SUM(B14)/SUM(B14:C14)) -> 0.84775426 | E14: =IF(SUM(B14:C14)=0,"",SUM(C14)/SUM(B14:C14)) -> 0.15224574
A15: 46204 | B15: =IF(SUMIFS('NSE - NIFTY Index Options'!$L:$L,'NSE - NIFTY Index Options'!$D:$D,$A15,'NSE - NIFTY Index Options'!$B:$B,"Monday")+SUMIFS('NSE - Other Index Options'!$L:$L,'NSE - Other Index Options'!$D:$D,$A15,'NSE - Other Index Options'!$B:$B,"Monday")=0,"",SUMIFS('NSE - NIFTY Index Options'!$L:$L,'NSE - NIFTY Index Options'!$D:$D,$A15,'NSE - NIFTY Index Options'!$B:$B,"Monday")+SUMIFS('NSE - Other Index Options'!$L:$L,'NSE - Other Index Options'!$D:$D,$A15,'NSE - Other Index Options'!$B:$B,"Monday")) -> 985.6022 | C15: =IF(SUMIFS('BSE - SENSEX Index Options'!$L:$L,'BSE - SENSEX Index Options'!$D:$D,$A15,'BSE - SENSEX Index Options'!$B:$B,"Monday")+SUMIFS('BSE - Other Index Options'!$L:$L,'BSE - Other Index Options'!$D:$D,$A15,'BSE - Other Index Options'!$B:$B,"Monday")=0,"",SUMIFS('BSE - SENSEX Index Options'!$L:$L,'BSE - SENSEX Index Options'!$D:$D,$A15,'BSE - SENSEX Index Options'!$B:$B,"Monday")+SUMIFS('BSE - Other Index Options'!$L:$L,'BSE - Other Index Options'!$D:$D,$A15,'BSE - Other Index Options'!$B:$B,"Monday")) -> 223.3558 | D15: =IF(SUM(B15:C15)=0,"",SUM(B15)/SUM(B15:C15)) -> 0.81524933 | E15: =IF(SUM(B15:C15)=0,"",SUM(C15)/SUM(B15:C15)) -> 0.18475067
A16: 46235 | B16: =IF(SUMIFS('NSE - NIFTY Index Options'!$L:$L,'NSE - NIFTY Index Options'!$D:$D,$A16,'NSE - NIFTY Index Options'!$B:$B,"Monday")+SUMIFS('NSE - Other Index Options'!$L:$L,'NSE - Other Index Options'!$D:$D,$A16,'NSE - Other Index Options'!$B:$B,"Monday")=0,"",SUMIFS('NSE - NIFTY Index Options'!$L:$L,'NSE - NIFTY Index Options'!$D:$D,$A16,'NSE - NIFTY Index Options'!$B:$B,"Monday")+SUMIFS('NSE - Other Index Options'!$L:$L,'NSE - Other Index Options'!$D:$D,$A16,'NSE - Other Index Options'!$B:$B,"Monday")) | C16: =IF(SUMIFS('BSE - SENSEX Index Options'!$L:$L,'BSE - SENSEX Index Options'!$D:$D,$A16,'BSE - SENSEX Index Options'!$B:$B,"Monday")+SUMIFS('BSE - Other Index Options'!$L:$L,'BSE - Other Index Options'!$D:$D,$A16,'BSE - Other Index Options'!$B:$B,"Monday")=0,"",SUMIFS('BSE - SENSEX Index Options'!$L:$L,'BSE - SENSEX Index Options'!$D:$D,$A16,'BSE - SENSEX Index Options'!$B:$B,"Monday")+SUMIFS('BSE - Other Index Options'!$L:$L,'BSE - Other Index Options'!$D:$D,$A16,'BSE - Other Index Options'!$B:$B,"Monday")) | D16: =IF(SUM(B16:C16)=0,"",SUM(B16)/SUM(B16:C16)) | E16: =IF(SUM(B16:C16)=0,"",SUM(C16)/SUM(B16:C16))
A17: 46266 | B17: =IF(SUMIFS('NSE - NIFTY Index Options'!$L:$L,'NSE - NIFTY Index Options'!$D:$D,$A17,'NSE - NIFTY Index Options'!$B:$B,"Monday")+SUMIFS('NSE - Other Index Options'!$L:$L,'NSE - Other Index Options'!$D:$D,$A17,'NSE - Other Index Options'!$B:$B,"Monday")=0,"",SUMIFS('NSE - NIFTY Index Options'!$L:$L,'NSE - NIFTY Index Options'!$D:$D,$A17,'NSE - NIFTY Index Options'!$B:$B,"Monday")+SUMIFS('NSE - Other Index Options'!$L:$L,'NSE - Other Index Options'!$D:$D,$A17,'NSE - Other Index Options'!$B:$B,"Monday")) | C17: =IF(SUMIFS('BSE - SENSEX Index Options'!$L:$L,'BSE - SENSEX Index Options'!$D:$D,$A17,'BSE - SENSEX Index Options'!$B:$B,"Monday")+SUMIFS('BSE - Other Index Options'!$L:$L,'BSE - Other Index Options'!$D:$D,$A17,'BSE - Other Index Options'!$B:$B,"Monday")=0,"",SUMIFS('BSE - SENSEX Index Options'!$L:$L,'BSE - SENSEX Index Options'!$D:$D,$A17,'BSE - SENSEX Index Options'!$B:$B,"Monday")+SUMIFS('BSE - Other Index Options'!$L:$L,'BSE - Other Index Options'!$D:$D,$A17,'BSE - Other Index Options'!$B:$B,"Monday")) | D17: =IF(SUM(B17:C17)=0,"",SUM(B17)/SUM(B17:C17)) | E17: =IF(SUM(B17:C17)=0,"",SUM(C17)/SUM(B17:C17))
A18: 46296 | B18: =IF(SUMIFS('NSE - NIFTY Index Options'!$L:$L,'NSE - NIFTY Index Options'!$D:$D,$A18,'NSE - NIFTY Index Options'!$B:$B,"Monday")+SUMIFS('NSE - Other Index Options'!$L:$L,'NSE - Other Index Options'!$D:$D,$A18,'NSE - Other Index Options'!$B:$B,"Monday")=0,"",SUMIFS('NSE - NIFTY Index Options'!$L:$L,'NSE - NIFTY Index Options'!$D:$D,$A18,'NSE - NIFTY Index Options'!$B:$B,"Monday")+SUMIFS('NSE - Other Index Options'!$L:$L,'NSE - Other Index Options'!$D:$D,$A18,'NSE - Other Index Options'!$B:$B,"Monday")) | C18: =IF(SUMIFS('BSE - SENSEX Index Options'!$L:$L,'BSE - SENSEX Index Options'!$D:$D,$A18,'BSE - SENSEX Index Options'!$B:$B,"Monday")+SUMIFS('BSE - Other Index Options'!$L:$L,'BSE - Other Index Options'!$D:$D,$A18,'BSE - Other Index Options'!$B:$B,"Monday")=0,"",SUMIFS('BSE - SENSEX Index Options'!$L:$L,'BSE - SENSEX Index Options'!$D:$D,$A18,'BSE - SENSEX Index Options'!$B:$B,"Monday")+SUMIFS('BSE - Other Index Options'!$L:$L,'BSE - Other Index Options'!$D:$D,$A18,'BSE - Other Index Options'!$B:$B,"Monday")) | D18: =IF(SUM(B18:C18)=0,"",SUM(B18)/SUM(B18:C18)) | E18: =IF(SUM(B18:C18)=0,"",SUM(C18)/SUM(B18:C18))
A19: 46327 | B19: =IF(SUMIFS('NSE - NIFTY Index Options'!$L:$L,'NSE - NIFTY Index Options'!$D:$D,$A19,'NSE - NIFTY Index Options'!$B:$B,"Monday")+SUMIFS('NSE - Other Index Options'!$L:$L,'NSE - Other Index Options'!$D:$D,$A19,'NSE - Other Index Options'!$B:$B,"Monday")=0,"",SUMIFS('NSE - NIFTY Index Options'!$L:$L,'NSE - NIFTY Index Options'!$D:$D,$A19,'NSE - NIFTY Index Options'!$B:$B,"Monday")+SUMIFS('NSE - Other Index Options'!$L:$L,'NSE - Other Index Options'!$D:$D,$A19,'NSE - Other Index Options'!$B:$B,"Monday")) | C19: =IF(SUMIFS('BSE - SENSEX Index Options'!$L:$L,'BSE - SENSEX Index Options'!$D:$D,$A19,'BSE - SENSEX Index Options'!$B:$B,"Monday")+SUMIFS('BSE - Other Index Options'!$L:$L,'BSE - Other Index Options'!$D:$D,$A19,'BSE - Other Index Options'!$B:$B,"Monday")=0,"",SUMIFS('BSE - SENSEX Index Options'!$L:$L,'BSE - SENSEX Index Options'!$D:$D,$A19,'BSE - SENSEX Index Options'!$B:$B,"Monday")+SUMIFS('BSE - Other Index Options'!$L:$L,'BSE - Other Index Options'!$D:$D,$A19,'BSE - Other Index Options'!$B:$B,"Monday")) | D19: =IF(SUM(B19:C19)=0,"",SUM(B19)/SUM(B19:C19)) | E19: =IF(SUM(B19:C19)=0,"",SUM(C19)/SUM(B19:C19))
A20: 46357 | B20: =IF(SUMIFS('NSE - NIFTY Index Options'!$L:$L,'NSE - NIFTY Index Options'!$D:$D,$A20,'NSE - NIFTY Index Options'!$B:$B,"Monday")+SUMIFS('NSE - Other Index Options'!$L:$L,'NSE - Other Index Options'!$D:$D,$A20,'NSE - Other Index Options'!$B:$B,"Monday")=0,"",SUMIFS('NSE - NIFTY Index Options'!$L:$L,'NSE - NIFTY Index Options'!$D:$D,$A20,'NSE - NIFTY Index Options'!$B:$B,"Monday")+SUMIFS('NSE - Other Index Options'!$L:$L,'NSE - Other Index Options'!$D:$D,$A20,'NSE - Other Index Options'!$B:$B,"Monday")) | C20: =IF(SUMIFS('BSE - SENSEX Index Options'!$L:$L,'BSE - SENSEX Index Options'!$D:$D,$A20,'BSE - SENSEX Index Options'!$B:$B,"Monday")+SUMIFS('BSE - Other Index Options'!$L:$L,'BSE - Other Index Options'!$D:$D,$A20,'BSE - Other Index Options'!$B:$B,"Monday")=0,"",SUMIFS('BSE - SENSEX Index Options'!$L:$L,'BSE - SENSEX Index Options'!$D:$D,$A20,'BSE - SENSEX Index Options'!$B:$B,"Monday")+SUMIFS('BSE - Other Index Options'!$L:$L,'BSE - Other Index Options'!$D:$D,$A20,'BSE - Other Index Options'!$B:$B,"Monday")) | D20: =IF(SUM(B20:C20)=0,"",SUM(B20)/SUM(B20:C20)) | E20: =IF(SUM(B20:C20)=0,"",SUM(C20)/SUM(B20:C20))
