Workbook

Sheet Quality Check
A1: Quality Check - ICICI Pru Life monthly business update workbook
A3: Metric | B3: Data From | C3: Data To | D3: Months in Range | E3: Populated Months | F3: Coverage % | G3: Derived (March) | I3: Data Sources & Method
A4: RWRP (INR Bn) | B4: =IFERROR(INDEX(Monthly!$A$5:$A$100,MATCH(TRUE,INDEX(Monthly!C5:C100<>"",0),0)),"") | C4: =IFERROR(LOOKUP(2,1/(Monthly!C5:C100<>""),Monthly!$A$5:$A$100),"") | D4: =IF(B4="","",(YEAR(C4)-YEAR(B4))*12+MONTH(C4)-MONTH(B4)+1) | E4: =COUNT(Monthly!C5:C100) | F4: =IFERROR(E4/D4,"") | G4: 6 | I4: Source: BSE corporate announcements, scrip 540133 (ICICI Prudential Life -> renamed ICICI Life Insurance Ltd in 2026).
A5: APE (INR Bn) | B5: =IFERROR(INDEX(Monthly!$A$5:$A$100,MATCH(TRUE,INDEX(Monthly!F5:F100<>"",0),0)),"") | C5: =IFERROR(LOOKUP(2,1/(Monthly!F5:F100<>""),Monthly!$A$5:$A$100),"") | D5: =IF(B5="","",(YEAR(C5)-YEAR(B5))*12+MONTH(C5)-MONTH(B5)+1) | E5: =COUNT(Monthly!F5:F100) | F5: =IFERROR(E5/D5,"") | G5: 6 | I5: Monthly update = filing titled 'Investor Presentation' (to Aug-2025, Dec-2025 to Jul-2026) or 'Performance Update' / 'Monthly business performance update'.
A6: Retail APE (INR Bn) | B6: =IFERROR(INDEX(Monthly!$A$5:$A$100,MATCH(TRUE,INDEX(Monthly!I5:I100<>"",0),0)),"") | C6: =IFERROR(LOOKUP(2,1/(Monthly!I5:I100<>""),Monthly!$A$5:$A$100),"") | D6: =IF(B6="","",(YEAR(C6)-YEAR(B6))*12+MONTH(C6)-MONTH(B6)+1) | E6: =COUNT(Monthly!I5:I100) | F6: =IFERROR(E6/D6,"") | G6: 2 | I6: Figures are the 'Premium growth' table, INR billion as reported; sum assured also INR billion.
A7: NB Premium (INR Bn) | B7: =IFERROR(INDEX(Monthly!$A$5:$A$100,MATCH(TRUE,INDEX(Monthly!L5:L100<>"",0),0)),"") | C7: =IFERROR(LOOKUP(2,1/(Monthly!L5:L100<>""),Monthly!$A$5:$A$100),"") | D7: =IF(B7="","",(YEAR(C7)-YEAR(B7))*12+MONTH(C7)-MONTH(B7)+1) | E7: =COUNT(Monthly!L5:L100) | F7: =IFERROR(E7/D7,"") | G7: 5 | I7: Each release shows the quarter-to-date months; the LATEST release covering a month is used (restatements win).
A8: NB Sum Assured (INR Bn) | B8: =IFERROR(INDEX(Monthly!$A$5:$A$100,MATCH(TRUE,INDEX(Monthly!O5:O100<>"",0),0)),"") | C8: =IFERROR(LOOKUP(2,1/(Monthly!O5:O100<>""),Monthly!$A$5:$A$100),"") | D8: =IF(B8="","",(YEAR(C8)-YEAR(B8))*12+MONTH(C8)-MONTH(B8)+1) | E8: =COUNT(Monthly!O5:O100) | F8: =IFERROR(E8/D8,"") | G8: 5 | I8: March is never released monthly (it is in the Q4 results): March = reported FY total - reported 11M cumulative (purple, live formula).
I9: Where FY or 11M was not published for a metric, March stays blank (e.g. NB Premium / Sum Assured Mar-2020).
A10: Check | E10: Value | F10: Status | I10: Quarterly = live SUM of the 3 Monthly rows (fiscal quarters, Q1 = Apr-Jun); YoY / QoQ live; checked vs reported quarter totals.
A11: Excel errors in Monthly + FY Totals + Quarterly (must be 0) | E11: =SUMPRODUCT(--ISERROR(Monthly!A5:R100))+SUMPRODUCT(--ISERROR('FY Totals'!A4:P12))+SUMPRODUCT(--ISERROR(Quarterly!A5:R36)) | F11: =IF(E11=0,"OK","CHECK") | I11: Prior-Year Check: every release's value/(1+YoY) vs the prior-year figure published earlier, so a reclassification of last year is caught.
A12: FY2020 APE: sum of 12 months - reported FY (tol 0.16) | E12: =IF(COUNT(Monthly!F11:F22)<12,"n/a",SUM(Monthly!F11:F22)-'FY Totals'!E5) | F12: =IF(E12="n/a","n/a",IF(ABS(E12)<=0.1607,"OK","CHECK")) | I12: YoY / MoM are live formulas on the monthly levels; the first 12 months show the company-reported YoY (grey).
A13: FY2020 RWRP: sum of 12 months - reported FY (tol 0.15) | E13: =IF(COUNT(Monthly!C11:C22)<12,"n/a",SUM(Monthly!C11:C22)-'FY Totals'!B5) | F13: =IF(E13="n/a","n/a",IF(ABS(E13)<=0.1496,"OK","CHECK")) | I13: RWRP = retail weighted received premium; APE = annualised premium equivalent; NB = new business.
A14: FY2020 NB premium: sum of 12 months - reported FY (tol 0.24) | E14: =IF(COUNT(Monthly!L11:L22)<12,"n/a",SUM(Monthly!L11:L22)-'FY Totals'!K5) | F14: =IF(E14="n/a","n/a",IF(ABS(E14)<=0.2352,"OK","CHECK")) | I14: Retail APE disclosed from Jan-2025; NB premium from Apr-2020; NB sum assured from Oct-2020.
A15: FY2020 NB sum assured: sum of 12 months - reported FY (tol 8.62) | E15: =IF(COUNT(Monthly!O11:O22)<12,"n/a",SUM(Monthly!O11:O22)-'FY Totals'!N5) | F15: =IF(E15="n/a","n/a",IF(ABS(E15)<=8.6178,"OK","CHECK")) | I15: Refresh: python3 'ICICI Pru Life/Python Files/icici_pru_monthly_update.py' (updates land ~7th-13th of each month).
A16: FY2021 APE: sum of 12 months - reported FY (tol 0.15) | E16: =IF(COUNT(Monthly!F23:F34)<12,"n/a",SUM(Monthly!F23:F34)-'FY Totals'!E6) | F16: =IF(E16="n/a","n/a",IF(ABS(E16)<=0.1469,"OK","CHECK"))
A17: FY2021 RWRP: sum of 12 months - reported FY (tol 0.13) | E17: =IF(COUNT(Monthly!C23:C34)<12,"n/a",SUM(Monthly!C23:C34)-'FY Totals'!B6) | F17: =IF(E17="n/a","n/a",IF(ABS(E17)<=0.1318,"OK","CHECK"))
A18: FY2021 NB premium: sum of 12 months - reported FY (tol 0.25) | E18: =IF(COUNT(Monthly!L23:L34)<12,"n/a",SUM(Monthly!L23:L34)-'FY Totals'!K6) | F18: =IF(E18="n/a","n/a",IF(ABS(E18)<=0.2455,"OK","CHECK"))
A19: FY2021 NB sum assured: sum of 12 months - reported FY (tol 9.30) | E19: =IF(COUNT(Monthly!O23:O34)<12,"n/a",SUM(Monthly!O23:O34)-'FY Totals'!N6) | F19: =IF(E19="n/a","n/a",IF(ABS(E19)<=9.3003,"OK","CHECK"))
A20: FY2022 APE: sum of 12 months - reported FY (tol 0.17) | E20: =IF(COUNT(Monthly!F35:F46)<12,"n/a",SUM(Monthly!F35:F46)-'FY Totals'!E7) | F20: =IF(E20="n/a","n/a",IF(ABS(E20)<=0.1660,"OK","CHECK"))
A21: FY2022 RWRP: sum of 12 months - reported FY (tol 0.14) | E21: =IF(COUNT(Monthly!C35:C46)<12,"n/a",SUM(Monthly!C35:C46)-'FY Totals'!B7) | F21: =IF(E21="n/a","n/a",IF(ABS(E21)<=0.1445,"OK","CHECK"))
A22: FY2022 NB premium: sum of 12 months - reported FY (tol 0.28) | E22: =IF(COUNT(Monthly!L35:L46)<12,"n/a",SUM(Monthly!L35:L46)-'FY Totals'!K7) | F22: =IF(E22="n/a","n/a",IF(ABS(E22)<=0.2755,"OK","CHECK"))
A23: FY2022 NB sum assured: sum of 12 months - reported FY (tol 11.65) | E23: =IF(COUNT(Monthly!O35:O46)<12,"n/a",SUM(Monthly!O35:O46)-'FY Totals'!N7) | F23: =IF(E23="n/a","n/a",IF(ABS(E23)<=11.6472,"OK","CHECK"))
A24: FY2023 APE: sum of 12 months - reported FY (tol 0.18) | E24: =IF(COUNT(Monthly!F47:F58)<12,"n/a",SUM(Monthly!F47:F58)-'FY Totals'!E8) | F24: =IF(E24="n/a","n/a",IF(ABS(E24)<=0.1796,"OK","CHECK"))
A25: FY2023 RWRP: sum of 12 months - reported FY (tol 0.15) | E25: =IF(COUNT(Monthly!C47:C58)<12,"n/a",SUM(Monthly!C47:C58)-'FY Totals'!B8) | F25: =IF(E25="n/a","n/a",IF(ABS(E25)<=0.1511,"OK","CHECK"))
A26: FY2023 NB premium: sum of 12 months - reported FY (tol 0.30) | E26: =IF(COUNT(Monthly!L47:L58)<12,"n/a",SUM(Monthly!L47:L58)-'FY Totals'!K8) | F26: =IF(E26="n/a","n/a",IF(ABS(E26)<=0.3038,"OK","CHECK"))
A27: FY2023 NB sum assured: sum of 12 months - reported FY (tol 15.67) | E27: =IF(COUNT(Monthly!O47:O58)<12,"n/a",SUM(Monthly!O47:O58)-'FY Totals'!N8) | F27: =IF(E27="n/a","n/a",IF(ABS(E27)<=15.6709,"OK","CHECK"))
A28: FY2024 APE: sum of 12 months - reported FY (tol 0.19) | E28: =IF(COUNT(Monthly!F59:F70)<12,"n/a",SUM(Monthly!F59:F70)-'FY Totals'!E9) | F28: =IF(E28="n/a","n/a",IF(ABS(E28)<=0.1857,"OK","CHECK"))
A29: FY2024 RWRP: sum of 12 months - reported FY (tol 0.16) | E29: =IF(COUNT(Monthly!C59:C70)<12,"n/a",SUM(Monthly!C59:C70)-'FY Totals'!B9) | F29: =IF(E29="n/a","n/a",IF(ABS(E29)<=0.1582,"OK","CHECK"))
A30: FY2024 NB premium: sum of 12 months - reported FY (tol 0.32) | E30: =IF(COUNT(Monthly!L59:L70)<12,"n/a",SUM(Monthly!L59:L70)-'FY Totals'!K9) | F30: =IF(E30="n/a","n/a",IF(ABS(E30)<=0.3212,"OK","CHECK"))
A31: FY2024 NB sum assured: sum of 12 months - reported FY (tol 15.38) | E31: =IF(COUNT(Monthly!O59:O70)<12,"n/a",SUM(Monthly!O59:O70)-'FY Totals'!N9) | F31: =IF(E31="n/a","n/a",IF(ABS(E31)<=15.3817,"OK","CHECK"))
A32: FY2025 APE: sum of 12 months - reported FY (tol 0.21) | E32: =IF(COUNT(Monthly!F71:F82)<12,"n/a",SUM(Monthly!F71:F82)-'FY Totals'!E10) | F32: =IF(E32="n/a","n/a",IF(ABS(E32)<=0.2061,"OK","CHECK"))
A33: FY2025 RWRP: sum of 12 months - reported FY (tol 0.17) | E33: =IF(COUNT(Monthly!C71:C82)<12,"n/a",SUM(Monthly!C71:C82)-'FY Totals'!B10) | F33: =IF(E33="n/a","n/a",IF(ABS(E33)<=0.1746,"OK","CHECK"))
A34: FY2025 NB premium: sum of 12 months - reported FY (tol 0.39) | E34: =IF(COUNT(Monthly!L71:L82)<12,"n/a",SUM(Monthly!L71:L82)-'FY Totals'!K10) | F34: =IF(E34="n/a","n/a",IF(ABS(E34)<=0.3887,"OK","CHECK"))
A35: FY2025 NB sum assured: sum of 12 months - reported FY (tol 17.97) | E35: =IF(COUNT(Monthly!O71:O82)<12,"n/a",SUM(Monthly!O71:O82)-'FY Totals'!N10) | F35: =IF(E35="n/a","n/a",IF(ABS(E35)<=17.9660,"OK","CHECK"))
A36: FY2026 APE: sum of 12 months - reported FY (tol 0.21) | E36: =IF(COUNT(Monthly!F83:F94)<12,"n/a",SUM(Monthly!F83:F94)-'FY Totals'!E11) | F36: =IF(E36="n/a","n/a",IF(ABS(E36)<=0.2096,"OK","CHECK"))
A37: FY2026 RWRP: sum of 12 months - reported FY (tol 0.17) | E37: =IF(COUNT(Monthly!C83:C94)<12,"n/a",SUM(Monthly!C83:C94)-'FY Totals'!B11) | F37: =IF(E37="n/a","n/a",IF(ABS(E37)<=0.1731,"OK","CHECK"))
A38: FY2026 NB premium: sum of 12 months - reported FY (tol 0.42) | E38: =IF(COUNT(Monthly!L83:L94)<12,"n/a",SUM(Monthly!L83:L94)-'FY Totals'!K11) | F38: =IF(E38="n/a","n/a",IF(ABS(E38)<=0.4221,"OK","CHECK"))
A39: FY2026 NB sum assured: sum of 12 months - reported FY (tol 21.80) | E39: =IF(COUNT(Monthly!O83:O94)<12,"n/a",SUM(Monthly!O83:O94)-'FY Totals'!N11) | F39: =IF(E39="n/a","n/a",IF(ABS(E39)<=21.8034,"OK","CHECK"))
A40: FY2020 APE: Apr-Feb monthly sum - reported 11M (tol 0.10) | E40: =SUM(Monthly!F11:F21)-'FY Totals'!G5 | F40: =IF(ABS(E40)<=0.1,"OK","CHECK")
A41: FY2020 RWRP: Apr-Feb monthly sum - reported 11M (tol 0.10) | E41: =SUM(Monthly!C11:C21)-'FY Totals'!D5 | F41: =IF(ABS(E41)<=0.1,"OK","CHECK")
...

Sheet Charts
A1: ICICI Pru Life - monthly business update charts (data: Monthly / FY Totals sheets)

Sheet Monthly
A1: ICICI Pru Life - monthly business performance update (BSE 540133), INR Bn
A2: Black = company-reported | purple italic = March derived (FY total - 11M cumulative, live formula off FY Totals) | grey italic YoY = company-reported YoY for months with no prior-year row
A4: Month | B4: Fiscal Year | C4: RWRP (INR Bn) | D4: RWRP YoY | E4: RWRP MoM | F4: APE (INR Bn) | G4: APE YoY | H4: APE MoM | I4: Retail APE (INR Bn) | J4: Retail APE YoY | K4: Retail APE MoM | L4: NB Premium (INR Bn) | M4: NB Premium YoY | N4: NB Premium MoM | O4: NB Sum Assured (INR Bn) | P4: NB Sum Assured YoY | Q4: NB Sum Assured MoM | R4: Latest Release (BSE filing date)
A5: 43374 | B5: FY2019 | C5: 4.69 | D5: -0.172 | F5: 5.09 | G5: -0.118 | R5: 43472
A6: 43405 | B6: FY2019 | C6: 5.11 | D6: -0.239 | E6: =IFERROR(IF(OR(C6="",C5=""),"",C6/C5-1),"") | F6: 6.87 | G6: 0.003 | H6: =IFERROR(IF(OR(F6="",F5=""),"",F6/F5-1),"") | K6: =IFERROR(IF(OR(I6="",I5=""),"",I6/I5-1),"") | N6: =IFERROR(IF(OR(L6="",L5=""),"",L6/L5-1),"") | Q6: =IFERROR(IF(OR(O6="",O5=""),"",O6/O5-1),"") | R6: 43472
A7: 43435 | B7: FY2019 | C7: 6.88 | D7: -0.047 | E7: =IFERROR(IF(OR(C7="",C6=""),"",C7/C6-1),"") | F7: 7.66 | G7: 0.03 | H7: =IFERROR(IF(OR(F7="",F6=""),"",F7/F6-1),"") | K7: =IFERROR(IF(OR(I7="",I6=""),"",I7/I6-1),"") | N7: =IFERROR(IF(OR(L7="",L6=""),"",L7/L6-1),"") | Q7: =IFERROR(IF(OR(O7="",O6=""),"",O7/O6-1),"") | R7: 43472
A8: 43466 | B8: FY2019 | C8: 6.54 | D8: 0.089 | E8: =IFERROR(IF(OR(C8="",C7=""),"",C8/C7-1),"") | F8: 7.17 | G8: 0.16 | H8: =IFERROR(IF(OR(F8="",F7=""),"",F8/F7-1),"") | K8: =IFERROR(IF(OR(I8="",I7=""),"",I8/I7-1),"") | N8: =IFERROR(IF(OR(L8="",L7=""),"",L8/L7-1),"") | Q8: =IFERROR(IF(OR(O8="",O7=""),"",O8/O7-1),"") | R8: 43572
A9: 43497 | B9: FY2019 | C9: 6.88 | D9: 0.084 | E9: =IFERROR(IF(OR(C9="",C8=""),"",C9/C8-1),"") | F9: 7.48 | G9: 0.145 | H9: =IFERROR(IF(OR(F9="",F8=""),"",F9/F8-1),"") | K9: =IFERROR(IF(OR(I9="",I8=""),"",I9/I8-1),"") | N9: =IFERROR(IF(OR(L9="",L8=""),"",L9/L8-1),"") | Q9: =IFERROR(IF(OR(O9="",O8=""),"",O9/O8-1),"") | R9: 43572
A10: 43525 | B10: FY2019 | C10: 9.37 | D10: 0.137 | E10: =IFERROR(IF(OR(C10="",C9=""),"",C10/C9-1),"") | F10: 9.922 | H10: =IFERROR(IF(OR(F10="",F9=""),"",F10/F9-1),"") | K10: =IFERROR(IF(OR(I10="",I9=""),"",I10/I9-1),"") | N10: =IFERROR(IF(OR(L10="",L9=""),"",L10/L9-1),"") | Q10: =IFERROR(IF(OR(O10="",O9=""),"",O10/O9-1),"") | R10: 43572
A11: 43556 | B11: FY2020 | C11: 3.46 | D11: 0.02 | E11: =IFERROR(IF(OR(C11="",C10=""),"",C11/C10-1),"") | F11: 4.13 | G11: 0.09 | H11: =IFERROR(IF(OR(F11="",F10=""),"",F11/F10-1),"") | K11: =IFERROR(IF(OR(I11="",I10=""),"",I11/I10-1),"") | N11: =IFERROR(IF(OR(L11="",L10=""),"",L11/L10-1),"") | Q11: =IFERROR(IF(OR(O11="",O10=""),"",O11/O10-1),"") | R11: 43651
A12: 43586 | B12: FY2020 | C12: 4.03 | D12: 0.008 | E12: =IFERROR(IF(OR(C12="",C11=""),"",C12/C11-1),"") | F12: 4.57 | G12: 0.051 | H12: =IFERROR(IF(OR(F12="",F11=""),"",F12/F11-1),"") | K12: =IFERROR(IF(OR(I12="",I11=""),"",I12/I11-1),"") | N12: =IFERROR(IF(OR(L12="",L11=""),"",L12/L11-1),"") | Q12: =IFERROR(IF(OR(O12="",O11=""),"",O12/O11-1),"") | R12: 43651
A13: 43617 | B13: FY2020 | C13: 5.47 | D13: 0.006 | E13: =IFERROR(IF(OR(C13="",C12=""),"",C13/C12-1),"") | F13: 5.99 | G13: 0.029 | H13: =IFERROR(IF(OR(F13="",F12=""),"",F13/F12-1),"") | K13: =IFERROR(IF(OR(I13="",I12=""),"",I13/I12-1),"") | N13: =IFERROR(IF(OR(L13="",L12=""),"",L13/L12-1),"") | Q13: =IFERROR(IF(OR(O13="",O12=""),"",O13/O12-1),"") | R13: 43651
A14: 43647 | B14: FY2020 | C14: 5.99 | D14: -0.013 | E14: =IFERROR(IF(OR(C14="",C13=""),"",C14/C13-1),"") | F14: 6.46 | G14: 0.009 | H14: =IFERROR(IF(OR(F14="",F13=""),"",F14/F13-1),"") | K14: =IFERROR(IF(OR(I14="",I13=""),"",I14/I13-1),"") | N14: =IFERROR(IF(OR(L14="",L13=""),"",L14/L13-1),"") | Q14: =IFERROR(IF(OR(O14="",O13=""),"",O14/O13-1),"") | R14: 43749
A15: 43678 | B15: FY2020 | C15: 5.73 | D15: -0.101 | E15: =IFERROR(IF(OR(C15="",C14=""),"",C15/C14-1),"") | F15: 6.28 | G15: -0.078 | H15: =IFERROR(IF(OR(F15="",F14=""),"",F15/F14-1),"") | K15: =IFERROR(IF(OR(I15="",I14=""),"",I15/I14-1),"") | N15: =IFERROR(IF(OR(L15="",L14=""),"",L15/L14-1),"") | Q15: =IFERROR(IF(OR(O15="",O14=""),"",O15/O14-1),"") | R15: 43749
A16: 43709 | B16: FY2020 | C16: 5.81 | D16: -0.066 | E16: =IFERROR(IF(OR(C16="",C15=""),"",C16/C15-1),"") | F16: 6.25 | G16: -0.057 | H16: =IFERROR(IF(OR(F16="",F15=""),"",F16/F15-1),"") | K16: =IFERROR(IF(OR(I16="",I15=""),"",I16/I15-1),"") | N16: =IFERROR(IF(OR(L16="",L15=""),"",L16/L15-1),"") | Q16: =IFERROR(IF(OR(O16="",O15=""),"",O16/O15-1),"") | R16: 43749
A17: 43739 | B17: FY2020 | C17: 5.53 | D17: =IFERROR(IF(OR(C17="",C5=""),"",C17/C5-1),"") | E17: =IFERROR(IF(OR(C17="",C16=""),"",C17/C16-1),"") | F17: 5.9 | G17: =IFERROR(IF(OR(F17="",F5=""),"",F17/F5-1),"") | H17: =IFERROR(IF(OR(F17="",F16=""),"",F17/F16-1),"") | J17: =IFERROR(IF(OR(I17="",I5=""),"",I17/I5-1),"") | K17: =IFERROR(IF(OR(I17="",I16=""),"",I17/I16-1),"") | M17: =IFERROR(IF(OR(L17="",L5=""),"",L17/L5-1),"") | N17: =IFERROR(IF(OR(L17="",L16=""),"",L17/L16-1),"") | P17: =IFERROR(IF(OR(O17="",O5=""),"",O17/O5-1),"") | Q17: =IFERROR(IF(OR(O17="",O16=""),"",O17/O16-1),"") | R17: 43840
A18: 43770 | B18: FY2020 | C18: 6.11 | D18: =IFERROR(IF(OR(C18="",C6=""),"",C18/C6-1),"") | E18: =IFERROR(IF(OR(C18="",C17=""),"",C18/C17-1),"") | F18: 6.54 | G18: =IFERROR(IF(OR(F18="",F6=""),"",F18/F6-1),"") | H18: =IFERROR(IF(OR(F18="",F17=""),"",F18/F17-1),"") | J18: =IFERROR(IF(OR(I18="",I6=""),"",I18/I6-1),"") | K18: =IFERROR(IF(OR(I18="",I17=""),"",I18/I17-1),"") | M18: =IFERROR(IF(OR(L18="",L6=""),"",L18/L6-1),"") | N18: =IFERROR(IF(OR(L18="",L17=""),"",L18/L17-1),"") | P18: =IFERROR(IF(OR(O18="",O6=""),"",O18/O6-1),"") | Q18: =IFERROR(IF(OR(O18="",O17=""),"",O18/O17-1),"") | R18: 43840
A19: 43800 | B19: FY2020 | C19: 7.42 | D19: =IFERROR(IF(OR(C19="",C7=""),"",C19/C7-1),"") | E19: =IFERROR(IF(OR(C19="",C18=""),"",C19/C18-1),"") | F19: 7.94 | G19: =IFERROR(IF(OR(F19="",F7=""),"",F19/F7-1),"") | H19: =IFERROR(IF(OR(F19="",F18=""),"",F19/F18-1),"") | J19: =IFERROR(IF(OR(I19="",I7=""),"",I19/I7-1),"") | K19: =IFERROR(IF(OR(I19="",I18=""),"",I19/I18-1),"") | M19: =IFERROR(IF(OR(L19="",L7=""),"",L19/L7-1),"") | N19: =IFERROR(IF(OR(L19="",L18=""),"",L19/L18-1),"") | P19: =IFERROR(IF(OR(O19="",O7=""),"",O19/O7-1),"") | Q19: =IFERROR(IF(OR(O19="",O18=""),"",O19/O18-1),"") | R19: 43840
A20: 43831 | B20: FY2020 | C20: 6.22 | D20: =IFERROR(IF(OR(C20="",C8=""),"",C20/C8-1),"") | E20: =IFERROR(IF(OR(C20="",C19=""),"",C20/C19-1),"") | F20: 6.91 | G20: =IFERROR(IF(OR(F20="",F8=""),"",F20/F8-1),"") | H20: =IFERROR(IF(OR(F20="",F19=""),"",F20/F19-1),"") | J20: =IFERROR(IF(OR(I20="",I8=""),"",I20/I8-1),"") | K20: =IFERROR(IF(OR(I20="",I19=""),"",I20/I19-1),"") | M20: =IFERROR(IF(OR(L20="",L8=""),"",L20/L8-1),"") | N20: =IFERROR(IF(OR(L20="",L19=""),"",L20/L19-1),"") | P20: =IFERROR(IF(OR(O20="",O8=""),"",O20/O8-1),"") | Q20: =IFERROR(IF(OR(O20="",O19=""),"",O20/O19-1),"") | R20: 43899
A21: 43862 | B21: FY2020 | C21: 5.87 | D21: =IFERROR(IF(OR(C21="",C9=""),"",C21/C9-1),"") | E21: =IFERROR(IF(OR(C21="",C20=""),"",C21/C20-1),"") | F21: 7.54 | G21: =IFERROR(IF(OR(F21="",F9=""),"",F21/F9-1),"") | H21: =IFERROR(IF(OR(F21="",F20=""),"",F21/F20-1),"") | J21: =IFERROR(IF(OR(I21="",I9=""),"",I21/I9-1),"") | K21: =IFERROR(IF(OR(I21="",I20=""),"",I21/I20-1),"") | M21: =IFERROR(IF(OR(L21="",L9=""),"",L21/L9-1),"") | N21: =IFERROR(IF(OR(L21="",L20=""),"",L21/L20-1),"") | P21: =IFERROR(IF(OR(O21="",O9=""),"",O21/O9-1),"") | Q21: =IFERROR(IF(OR(O21="",O20=""),"",O21/O20-1),"") | R21: 43899
A22: 43891 | B22: FY2020 | C22: ='FY Totals'!B5-'FY Totals'!D5 | D22: =IFERROR(IF(OR(C22="",C10=""),"",C22/C10-1),"") | E22: =IFERROR(IF(OR(C22="",C21=""),"",C22/C21-1),"") | F22: ='FY Totals'!E5-'FY Totals'!G5 | G22: =IFERROR(IF(OR(F22="",F10=""),"",F22/F10-1),"") | H22: =IFERROR(IF(OR(F22="",F21=""),"",F22/F21-1),"") | J22: =IFERROR(IF(OR(I22="",I10=""),"",I22/I10-1),"") | K22: =IFERROR(IF(OR(I22="",I21=""),"",I22/I21-1),"") | M22: =IFERROR(IF(OR(L22="",L10=""),"",L22/L10-1),"") | N22: =IFERROR(IF(OR(L22="",L21=""),"",L22/L21-1),"") | P22: =IFERROR(IF(OR(O22="",O10=""),"",O22/O10-1),"") | Q22: =IFERROR(IF(OR(O22="",O21=""),"",O22/O21-1),"")
A23: 43922 | B23: FY2021 | C23: 1.55 | D23: =IFERROR(IF(OR(C23="",C11=""),"",C23/C11-1),"") | E23: =IFERROR(IF(OR(C23="",C22=""),"",C23/C22-1),"") | F23: 1.9 | G23: =IFERROR(IF(OR(F23="",F11=""),"",F23/F11-1),"") | H23: =IFERROR(IF(OR(F23="",F22=""),"",F23/F22-1),"") | J23: =IFERROR(IF(OR(I23="",I11=""),"",I23/I11-1),"") | K23: =IFERROR(IF(OR(I23="",I22=""),"",I23/I22-1),"") | L23: 2.56 | M23: =IFERROR(IF(OR(L23="",L11=""),"",L23/L11-1),"") | N23: =IFERROR(IF(OR(L23="",L22=""),"",L23/L22-1),"") | P23: =IFERROR(IF(OR(O23="",O11=""),"",O23/O11-1),"") | Q23: =IFERROR(IF(OR(O23="",O22=""),"",O23/O22-1),"") | R23: 44021
A24: 43952 | B24: FY2021 | C24: 1.92 | D24: =IFERROR(IF(OR(C24="",C12=""),"",C24/C12-1),"") | E24: =IFERROR(IF(OR(C24="",C23=""),"",C24/C23-1),"") | F24: 2.79 | G24: =IFERROR(IF(OR(F24="",F12=""),"",F24/F12-1),"") | H24: =IFERROR(IF(OR(F24="",F23=""),"",F24/F23-1),"") | J24: =IFERROR(IF(OR(I24="",I12=""),"",I24/I12-1),"") | K24: =IFERROR(IF(OR(I24="",I23=""),"",I24/I23-1),"") | L24: 6.79 | M24: =IFERROR(IF(OR(L24="",L12=""),"",L24/L12-1),"") | N24: =IFERROR(IF(OR(L24="",L23=""),"",L24/L23-1),"") | P24: =IFERROR(IF(OR(O24="",O12=""),"",O24/O12-1),"") | Q24: =IFERROR(IF(OR(O24="",O23=""),"",O24/O23-1),"") | R24: 44021
A25: 43983 | B25: FY2021 | C25: 3.09 | D25: =IFERROR(IF(OR(C25="",C13=""),"",C25/C13-1),"") | E25: =IFERROR(IF(OR(C25="",C24=""),"",C25/C24-1),"") | F25: 3.54 | G25: =IFERROR(IF(OR(F25="",F13=""),"",F25/F13-1),"") | H25: =IFERROR(IF(OR(F25="",F24=""),"",F25/F24-1),"") | J25: =IFERROR(IF(OR(I25="",I13=""),"",I25/I13-1),"") | K25: =IFERROR(IF(OR(I25="",I24=""),"",I25/I24-1),"") | L25: 5.65 | M25: =IFERROR(IF(OR(L25="",L13=""),"",L25/L13-1),"") | N25: =IFERROR(IF(OR(L25="",L24=""),"",L25/L24-1),"") | P25: =IFERROR(IF(OR(O25="",O13=""),"",O25/O13-1),"") | Q25: =IFERROR(IF(OR(O25="",O24=""),"",O25/O24-1),"") | R25: 44021
A26: 44013 | B26: FY2021 | C26: 3.81 | D26: =IFERROR(IF(OR(C26="",C14=""),"",C26/C14-1),"") | E26: =IFERROR(IF(OR(C26="",C25=""),"",C26/C25-1),"") | F26: 4.41 | G26: =IFERROR(IF(OR(F26="",F14=""),"",F26/F14-1),"") | H26: =IFERROR(IF(OR(F26="",F25=""),"",F26/F25-1),"") | J26: =IFERROR(IF(OR(I26="",I14=""),"",I26/I14-1),"") | K26: =IFERROR(IF(OR(I26="",I25=""),"",I26/I25-1),"") | L26: 8.49 | M26: =IFERROR(IF(OR(L26="",L14=""),"",L26/L14-1),"") | N26: =IFERROR(IF(OR(L26="",L25=""),"",L26/L25-1),"") | P26: =IFERROR(IF(OR(O26="",O14=""),"",O26/O14-1),"") | Q26: =IFERROR(IF(OR(O26="",O25=""),"",O26/O25-1),"") | R26: 44111
A27: 44044 | B27: FY2021 | C27: 4.06 | D27: =IFERROR(IF(OR(C27="",C15=""),"",C27/C15-1),"") | E27: =IFERROR(IF(OR(C27="",C26=""),"",C27/C26-1),"") | F27: 4.94 | G27: =IFERROR(IF(OR(F27="",F15=""),"",F27/F15-1),"") | H27: =IFERROR(IF(OR(F27="",F26=""),"",F27/F26-1),"") | J27: =IFERROR(IF(OR(I27="",I15=""),"",I27/I15-1),"") | K27: =IFERROR(IF(OR(I27="",I26=""),"",I27/I26-1),"") | L27: 8.92 | M27: =IFERROR(IF(OR(L27="",L15=""),"",L27/L15-1),"") | N27: =IFERROR(IF(OR(L27="",L26=""),"",L27/L26-1),"") | P27: =IFERROR(IF(OR(O27="",O15=""),"",O27/O15-1),"") | Q27: =IFERROR(IF(OR(O27="",O26=""),"",O27/O26-1),"") | R27: 44111
A28: 44075 | B28: FY2021 | C28: 4.42 | D28: =IFERROR(IF(OR(C28="",C16=""),"",C28/C16-1),"") | E28: =IFERROR(IF(OR(C28="",C27=""),"",C28/C27-1),"") | F28: 5.3 | G28: =IFERROR(IF(OR(F28="",F16=""),"",F28/F16-1),"") | H28: =IFERROR(IF(OR(F28="",F27=""),"",F28/F27-1),"") | J28: =IFERROR(IF(OR(I28="",I16=""),"",I28/I16-1),"") | K28: =IFERROR(IF(OR(I28="",I27=""),"",I28/I27-1),"") | L28: 12.16 | M28: =IFERROR(IF(OR(L28="",L16=""),"",L28/L16-1),"") | N28: =IFERROR(IF(OR(L28="",L27=""),"",L28/L27-1),"") | P28: =IFERROR(IF(OR(O28="",O16=""),"",O28/O16-1),"") | Q28: =IFERROR(IF(OR(O28="",O27=""),"",O28/O27-1),"") | R28: 44111
A29: 44105 | B29: FY2021 | C29: 4.33 | D29: =IFERROR(IF(OR(C29="",C17=""),"",C29/C17-1),"") | E29: =IFERROR(IF(OR(C29="",C28=""),"",C29/C28-1),"") | F29: 5.04 | G29: =IFERROR(IF(OR(F29="",F17=""),"",F29/F17-1),"") | H29: =IFERROR(IF(OR(F29="",F28=""),"",F29/F28-1),"") | J29: =IFERROR(IF(OR(I29="",I17=""),"",I29/I17-1),"") | K29: =IFERROR(IF(OR(I29="",I28=""),"",I29/I28-1),"") | L29: 9.9 | M29: =IFERROR(IF(OR(L29="",L17=""),"",L29/L17-1),"") | N29: =IFERROR(IF(OR(L29="",L28=""),"",L29/L28-1),"") | O29: 492.61 | P29: =IFERROR(IF(OR(O29="",O17=""),"",O29/O17-1),"") | Q29: =IFERROR(IF(OR(O29="",O28=""),"",O29/O28-1),"") | R29: 44204
A30: 44136 | B30: FY2021 | C30: 4.23 | D30: =IFERROR(IF(OR(C30="",C18=""),"",C30/C18-1),"") | E30: =IFERROR(IF(OR(C30="",C29=""),"",C30/C29-1),"") | F30: 4.88 | G30: =IFERROR(IF(OR(F30="",F18=""),"",F30/F18-1),"") | H30: =IFERROR(IF(OR(F30="",F29=""),"",F30/F29-1),"") | J30: =IFERROR(IF(OR(I30="",I18=""),"",I30/I18-1),"") | K30: =IFERROR(IF(OR(I30="",I29=""),"",I30/I29-1),"") | L30: 9.83 | M30: =IFERROR(IF(OR(L30="",L18=""),"",L30/L18-1),"") | N30: =IFERROR(IF(OR(L30="",L29=""),"",L30/L29-1),"") | O30: 465.09 | P30: =IFERROR(IF(OR(O30="",O18=""),"",O30/O18-1),"") | Q30: =IFERROR(IF(OR(O30="",O29=""),"",O30/O29-1),"") | R30: 44204
A31: 44166 | B31: FY2021 | C31: 5.65 | D31: =IFERROR(IF(OR(C31="",C19=""),"",C31/C19-1),"") | E31: =IFERROR(IF(OR(C31="",C30=""),"",C31/C30-1),"") | F31: 6.74 | G31: =IFERROR(IF(OR(F31="",F19=""),"",F31/F19-1),"") | H31: =IFERROR(IF(OR(F31="",F30=""),"",F31/F30-1),"") | J31: =IFERROR(IF(OR(I31="",I19=""),"",I31/I19-1),"") | K31: =IFERROR(IF(OR(I31="",I30=""),"",I31/I30-1),"") | L31: 14.69 | M31: =IFERROR(IF(OR(L31="",L19=""),"",L31/L19-1),"") | N31: =IFERROR(IF(OR(L31="",L30=""),"",L31/L30-1),"") | O31: 653.9 | P31: =IFERROR(IF(OR(O31="",O19=""),"",O31/O19-1),"") | Q31: =IFERROR(IF(OR(O31="",O30=""),"",O31/O30-1),"") | R31: 44204
A32: 44197 | B32: FY2021 | C32: 5.77 | D32: =IFERROR(IF(OR(C32="",C20=""),"",C32/C20-1),"") | E32: =IFERROR(IF(OR(C32="",C31=""),"",C32/C31-1),"") | F32: 6.7 | G32: =IFERROR(IF(OR(F32="",F20=""),"",F32/F20-1),"") | H32: =IFERROR(IF(OR(F32="",F31=""),"",F32/F31-1),"") | J32: =IFERROR(IF(OR(I32="",I20=""),"",I32/I20-1),"") | K32: =IFERROR(IF(OR(I32="",I31=""),"",I32/I31-1),"") | L32: 12.39 | M32: =IFERROR(IF(OR(L32="",L20=""),"",L32/L20-1),"") | N32: =IFERROR(IF(OR(L32="",L31=""),"",L32/L31-1),"") | O32: 612.65 | P32: =IFERROR(IF(OR(O32="",O20=""),"",O32/O20-1),"") | Q32: =IFERROR(IF(OR(O32="",O31=""),"",O32/O31-1),"") | R32: 44263
A33: 44228 | B33: FY2021 | C33: 6.25 | D33: =IFERROR(IF(OR(C33="",C21=""),"",C33/C21-1),"") | E33: =IFERROR(IF(OR(C33="",C32=""),"",C33/C32-1),"") | F33: 7.37 | G33: =IFERROR(IF(OR(F33="",F21=""),"",F33/F21-1),"") | H33: =IFERROR(IF(OR(F33="",F32=""),"",F33/F32-1),"") | J33: =IFERROR(IF(OR(I33="",I21=""),"",I33/I21-1),"") | K33: =IFERROR(IF(OR(I33="",I32=""),"",I33/I32-1),"") | L33: 17.37 | M33: =IFERROR(IF(OR(L33="",L21=""),"",L33/L21-1),"") | N33: =IFERROR(IF(OR(L33="",L32=""),"",L33/L32-1),"") | O33: 627.05 | P33: =IFERROR(IF(OR(O33="",O21=""),"",O33/O21-1),"") | Q33: =IFERROR(IF(OR(O33="",O32=""),"",O33/O32-1),"") | R33: 44263
A34: 44256 | B34: FY2021 | C34: ='FY Totals'!B6-'FY Totals'!D6 | D34: =IFERROR(IF(OR(C34="",C22=""),"",C34/C22-1),"") | E34: =IFERROR(IF(OR(C34="",C33=""),"",C34/C33-1),"") | F34: ='FY Totals'!E6-'FY Totals'!G6 | G34: =IFERROR(IF(OR(F34="",F22=""),"",F34/F22-1),"") | H34: =IFERROR(IF(OR(F34="",F33=""),"",F34/F33-1),"") | J34: =IFERROR(IF(OR(I34="",I22=""),"",I34/I22-1),"") | K34: =IFERROR(IF(OR(I34="",I33=""),"",I34/I33-1),"") | L34: ='FY Totals'!K6-'FY Totals'!M6 | M34: =IFERROR(IF(OR(L34="",L22=""),"",L34/L22-1),"") | N34: =IFERROR(IF(OR(L34="",L33=""),"",L34/L33-1),"") | O34: ='FY Totals'!N6-'FY Totals'!P6 | P34: =IFERROR(IF(OR(O34="",O22=""),"",O34/O22-1),"") | Q34: =IFERROR(IF(OR(O34="",O33=""),"",O34/O33-1),"")
A35: 44287 | B35: FY2022 | C35: 2.56 | D35: =IFERROR(IF(OR(C35="",C23=""),"",C35/C23-1),"") | E35: =IFERROR(IF(OR(C35="",C34=""),"",C35/C34-1),"") | F35: 3.57 | G35: =IFERROR(IF(OR(F35="",F23=""),"",F35/F23-1),"") | H35: =IFERROR(IF(OR(F35="",F34=""),"",F35/F34-1),"") | J35: =IFERROR(IF(OR(I35="",I23=""),"",I35/I23-1),"") | K35: =IFERROR(IF(OR(I35="",I34=""),"",I35/I34-1),"") | L35: 6.43 | M35: =IFERROR(IF(OR(L35="",L23=""),"",L35/L23-1),"") | N35: =IFERROR(IF(OR(L35="",L34=""),"",L35/L34-1),"") | O35: 707.59 | P35: =IFERROR(IF(OR(O35="",O23=""),"",O35/O23-1),"") | Q35: =IFERROR(IF(OR(O35="",O34=""),"",O35/O34-1),"") | R35: 44385
A36: 44317 | B36: FY2022 | C36: 2.45 | D36: =IFERROR(IF(OR(C36="",C24=""),"",C36/C24-1),"") | E36: =IFERROR(IF(OR(C36="",C35=""),"",C36/C35-1),"") | F36: 3.04 | G36: =IFERROR(IF(OR(F36="",F24=""),"",F36/F24-1),"") | H36: =IFERROR(IF(OR(F36="",F35=""),"",F36/F35-1),"") | J36: =IFERROR(IF(OR(I36="",I24=""),"",I36/I24-1),"") | K36: =IFERROR(IF(OR(I36="",I35=""),"",I36/I35-1),"") | L36: 6.52 | M36: =IFERROR(IF(OR(L36="",L24=""),"",L36/L24-1),"") | N36: =IFERROR(IF(OR(L36="",L35=""),"",L36/L35-1),"") | O36: 587.48 | P36: =IFERROR(IF(OR(O36="",O24=""),"",O36/O24-1),"") | Q36: =IFERROR(IF(OR(O36="",O35=""),"",O36/O35-1),"") | R36: 44385
A37: 44348 | B37: FY2022 | C37: 4.42 | D37: =IFERROR(IF(OR(C37="",C25=""),"",C37/C25-1),"") | E37: =IFERROR(IF(OR(C37="",C36=""),"",C37/C36-1),"") | F37: 5.58 | G37: =IFERROR(IF(OR(F37="",F25=""),"",F37/F25-1),"") | H37: =IFERROR(IF(OR(F37="",F36=""),"",F37/F36-1),"") | J37: =IFERROR(IF(OR(I37="",I25=""),"",I37/I25-1),"") | K37: =IFERROR(IF(OR(I37="",I36=""),"",I37/I36-1),"") | L37: 12.63 | M37: =IFERROR(IF(OR(L37="",L25=""),"",L37/L25-1),"") | N37: =IFERROR(IF(OR(L37="",L36=""),"",L37/L36-1),"") | O37: 473.55 | P37: =IFERROR(IF(OR(O37="",O25=""),"",O37/O25-1),"") | Q37: =IFERROR(IF(OR(O37="",O36=""),"",O37/O36-1),"") | R37: 44385
A38: 44378 | B38: FY2022 | C38: 4.77 | D38: =IFERROR(IF(OR(C38="",C26=""),"",C38/C26-1),"") | E38: =IFERROR(IF(OR(C38="",C37=""),"",C38/C37-1),"") | F38: 5.69 | G38: =IFERROR(IF(OR(F38="",F26=""),"",F38/F26-1),"") | H38: =IFERROR(IF(OR(F38="",F37=""),"",F38/F37-1),"") | J38: =IFERROR(IF(OR(I38="",I26=""),"",I38/I26-1),"") | K38: =IFERROR(IF(OR(I38="",I37=""),"",I38/I37-1),"") | L38: 11.57 | M38: =IFERROR(IF(OR(L38="",L26=""),"",L38/L26-1),"") | N38: =IFERROR(IF(OR(L38="",L37=""),"",L38/L37-1),"") | O38: 500.33 | P38: =IFERROR(IF(OR(O38="",O26=""),"",O38/O26-1),"") | Q38: =IFERROR(IF(OR(O38="",O37=""),"",O38/O37-1),"") | R38: 44476
A39: 44409 | B39: FY2022 | C39: 5.45 | D39: =IFERROR(IF(OR(C39="",C27=""),"",C39/C27-1),"") | E39: =IFERROR(IF(OR(C39="",C38=""),"",C39/C38-1),"") | F39: 6.4 | G39: =IFERROR(IF(OR(F39="",F27=""),"",F39/F27-1),"") | H39: =IFERROR(IF(OR(F39="",F38=""),"",F39/F38-1),"") | J39: =IFERROR(IF(OR(I39="",I27=""),"",I39/I27-1),"") | K39: =IFERROR(IF(OR(I39="",I38=""),"",I39/I38-1),"") | L39: 12.76 | M39: =IFERROR(IF(OR(L39="",L27=""),"",L39/L27-1),"") | N39: =IFERROR(IF(OR(L39="",L38=""),"",L39/L38-1),"") | O39: 509.69 | P39: =IFERROR(IF(OR(O39="",O27=""),"",O39/O27-1),"") | Q39: =IFERROR(IF(OR(O39="",O38=""),"",O39/O38-1),"") | R39: 44476
A40: 44440 | B40: FY2022 | C40: 6.23 | D40: =IFERROR(IF(OR(C40="",C28=""),"",C40/C28-1),"") | E40: =IFERROR(IF(OR(C40="",C39=""),"",C40/C39-1),"") | F40: 7.68 | G40: =IFERROR(IF(OR(F40="",F28=""),"",F40/F28-1),"") | H40: =IFERROR(IF(OR(F40="",F39=""),"",F40/F39-1),"") | J40: =IFERROR(IF(OR(I40="",I28=""),"",I40/I28-1),"") | K40: =IFERROR(IF(OR(I40="",I39=""),"",I40/I39-1),"") | L40: 14.69 | M40: =IFERROR(IF(OR(L40="",L28=""),"",L40/L28-1),"") | N40: =IFERROR(IF(OR(L40="",L39=""),"",L40/L39-1),"") | O40: 595.53 | P40: =IFERROR(IF(OR(O40="",O28=""),"",O40/O28-1),"") | Q40: =IFERROR(IF(OR(O40="",O39=""),"",O40/O39-1),"") | R40: 44476
A41: 44470 | B41: FY2022 | C41: 5.34 | D41: =IFERROR(IF(OR(C41="",C29=""),"",C41/C29-1),"") | E41: =IFERROR(IF(OR(C41="",C40=""),"",C41/C40-1),"") | F41: 6.2 | G41: =IFERROR(IF(OR(F41="",F29=""),"",F41/F29-1),"") | H41: =IFERROR(IF(OR(F41="",F40=""),"",F41/F40-1),"") | J41: =IFERROR(IF(OR(I41="",I29=""),"",I41/I29-1),"") | K41: =IFERROR(IF(OR(I41="",I40=""),"",I41/I40-1),"") | L41: 11.54 | M41: =IFERROR(IF(OR(L41="",L29=""),"",L41/L29-1),"") | N41: =IFERROR(IF(OR(L41="",L40=""),"",L41/L40-1),"") | O41: 566.02 | P41: =IFERROR(IF(OR(O41="",O29=""),"",O41/O29-1),"") | Q41: =IFERROR(IF(OR(O41="",O40=""),"",O41/O40-1),"") | R41: 44568
...

Sheet Quarterly
A1: ICICI Pru Life - quarterly (fiscal Apr-Mar), INR Bn = sum of the three Monthly rows
A2: Live SUM of Monthly; blank if any month of the quarter is missing. Q4 includes the derived March (FY - 11M). Quarter sums are checked against company-reported quarter totals on Quality Check.
A4: Quarter | B4: Fiscal Year | C4: Quarter End | D4: RWRP (INR Bn) | E4: RWRP YoY | F4: RWRP QoQ | G4: APE (INR Bn) | H4: APE YoY | I4: APE QoQ | J4: Retail APE (INR Bn) | K4: Retail APE YoY | L4: Retail APE QoQ | M4: NB Premium (INR Bn) | N4: NB Premium YoY | O4: NB Premium QoQ | P4: NB Sum Assured (INR Bn) | Q4: NB Sum Assured YoY | R4: NB Sum Assured QoQ
A5: Q3FY19 | B5: FY2019 | C5: 43435 | D5: =IF(COUNT(Monthly!C5:C7)<3,"",SUM(Monthly!C5:C7)) | G5: =IF(COUNT(Monthly!F5:F7)<3,"",SUM(Monthly!F5:F7)) | J5: =IF(COUNT(Monthly!I5:I7)<3,"",SUM(Monthly!I5:I7)) | M5: =IF(COUNT(Monthly!L5:L7)<3,"",SUM(Monthly!L5:L7)) | P5: =IF(COUNT(Monthly!O5:O7)<3,"",SUM(Monthly!O5:O7))
A6: Q4FY19 | B6: FY2019 | C6: 43525 | D6: =IF(COUNT(Monthly!C8:C10)<3,"",SUM(Monthly!C8:C10)) | F6: =IFERROR(IF(OR(D6="",D5=""),"",D6/D5-1),"") | G6: =IF(COUNT(Monthly!F8:F10)<3,"",SUM(Monthly!F8:F10)) | I6: =IFERROR(IF(OR(G6="",G5=""),"",G6/G5-1),"") | J6: =IF(COUNT(Monthly!I8:I10)<3,"",SUM(Monthly!I8:I10)) | L6: =IFERROR(IF(OR(J6="",J5=""),"",J6/J5-1),"") | M6: =IF(COUNT(Monthly!L8:L10)<3,"",SUM(Monthly!L8:L10)) | O6: =IFERROR(IF(OR(M6="",M5=""),"",M6/M5-1),"") | P6: =IF(COUNT(Monthly!O8:O10)<3,"",SUM(Monthly!O8:O10)) | R6: =IFERROR(IF(OR(P6="",P5=""),"",P6/P5-1),"")
A7: Q1FY20 | B7: FY2020 | C7: 43617 | D7: =IF(COUNT(Monthly!C11:C13)<3,"",SUM(Monthly!C11:C13)) | F7: =IFERROR(IF(OR(D7="",D6=""),"",D7/D6-1),"") | G7: =IF(COUNT(Monthly!F11:F13)<3,"",SUM(Monthly!F11:F13)) | I7: =IFERROR(IF(OR(G7="",G6=""),"",G7/G6-1),"") | J7: =IF(COUNT(Monthly!I11:I13)<3,"",SUM(Monthly!I11:I13)) | L7: =IFERROR(IF(OR(J7="",J6=""),"",J7/J6-1),"") | M7: =IF(COUNT(Monthly!L11:L13)<3,"",SUM(Monthly!L11:L13)) | O7: =IFERROR(IF(OR(M7="",M6=""),"",M7/M6-1),"") | P7: =IF(COUNT(Monthly!O11:O13)<3,"",SUM(Monthly!O11:O13)) | R7: =IFERROR(IF(OR(P7="",P6=""),"",P7/P6-1),"")
A8: Q2FY20 | B8: FY2020 | C8: 43709 | D8: =IF(COUNT(Monthly!C14:C16)<3,"",SUM(Monthly!C14:C16)) | F8: =IFERROR(IF(OR(D8="",D7=""),"",D8/D7-1),"") | G8: =IF(COUNT(Monthly!F14:F16)<3,"",SUM(Monthly!F14:F16)) | I8: =IFERROR(IF(OR(G8="",G7=""),"",G8/G7-1),"") | J8: =IF(COUNT(Monthly!I14:I16)<3,"",SUM(Monthly!I14:I16)) | L8: =IFERROR(IF(OR(J8="",J7=""),"",J8/J7-1),"") | M8: =IF(COUNT(Monthly!L14:L16)<3,"",SUM(Monthly!L14:L16)) | O8: =IFERROR(IF(OR(M8="",M7=""),"",M8/M7-1),"") | P8: =IF(COUNT(Monthly!O14:O16)<3,"",SUM(Monthly!O14:O16)) | R8: =IFERROR(IF(OR(P8="",P7=""),"",P8/P7-1),"")
A9: Q3FY20 | B9: FY2020 | C9: 43800 | D9: =IF(COUNT(Monthly!C17:C19)<3,"",SUM(Monthly!C17:C19)) | E9: =IFERROR(IF(OR(D9="",D5=""),"",D9/D5-1),"") | F9: =IFERROR(IF(OR(D9="",D8=""),"",D9/D8-1),"") | G9: =IF(COUNT(Monthly!F17:F19)<3,"",SUM(Monthly!F17:F19)) | H9: =IFERROR(IF(OR(G9="",G5=""),"",G9/G5-1),"") | I9: =IFERROR(IF(OR(G9="",G8=""),"",G9/G8-1),"") | J9: =IF(COUNT(Monthly!I17:I19)<3,"",SUM(Monthly!I17:I19)) | K9: =IFERROR(IF(OR(J9="",J5=""),"",J9/J5-1),"") | L9: =IFERROR(IF(OR(J9="",J8=""),"",J9/J8-1),"") | M9: =IF(COUNT(Monthly!L17:L19)<3,"",SUM(Monthly!L17:L19)) | N9: =IFERROR(IF(OR(M9="",M5=""),"",M9/M5-1),"") | O9: =IFERROR(IF(OR(M9="",M8=""),"",M9/M8-1),"") | P9: =IF(COUNT(Monthly!O17:O19)<3,"",SUM(Monthly!O17:O19)) | Q9: =IFERROR(IF(OR(P9="",P5=""),"",P9/P5-1),"") | R9: =IFERROR(IF(OR(P9="",P8=""),"",P9/P8-1),"")
A10: Q4FY20 | B10: FY2020 | C10: 43891 | D10: =IF(COUNT(Monthly!C20:C22)<3,"",SUM(Monthly!C20:C22)) | E10: =IFERROR(IF(OR(D10="",D6=""),"",D10/D6-1),"") | F10: =IFERROR(IF(OR(D10="",D9=""),"",D10/D9-1),"") | G10: =IF(COUNT(Monthly!F20:F22)<3,"",SUM(Monthly!F20:F22)) | H10: =IFERROR(IF(OR(G10="",G6=""),"",G10/G6-1),"") | I10: =IFERROR(IF(OR(G10="",G9=""),"",G10/G9-1),"") | J10: =IF(COUNT(Monthly!I20:I22)<3,"",SUM(Monthly!I20:I22)) | K10: =IFERROR(IF(OR(J10="",J6=""),"",J10/J6-1),"") | L10: =IFERROR(IF(OR(J10="",J9=""),"",J10/J9-1),"") | M10: =IF(COUNT(Monthly!L20:L22)<3,"",SUM(Monthly!L20:L22)) | N10: =IFERROR(IF(OR(M10="",M6=""),"",M10/M6-1),"") | O10: =IFERROR(IF(OR(M10="",M9=""),"",M10/M9-1),"") | P10: =IF(COUNT(Monthly!O20:O22)<3,"",SUM(Monthly!O20:O22)) | Q10: =IFERROR(IF(OR(P10="",P6=""),"",P10/P6-1),"") | R10: =IFERROR(IF(OR(P10="",P9=""),"",P10/P9-1),"")
A11: Q1FY21 | B11: FY2021 | C11: 43983 | D11: =IF(COUNT(Monthly!C23:C25)<3,"",SUM(Monthly!C23:C25)) | E11: =IFERROR(IF(OR(D11="",D7=""),"",D11/D7-1),"") | F11: =IFERROR(IF(OR(D11="",D10=""),"",D11/D10-1),"") | G11: =IF(COUNT(Monthly!F23:F25)<3,"",SUM(Monthly!F23:F25)) | H11: =IFERROR(IF(OR(G11="",G7=""),"",G11/G7-1),"") | I11: =IFERROR(IF(OR(G11="",G10=""),"",G11/G10-1),"") | J11: =IF(COUNT(Monthly!I23:I25)<3,"",SUM(Monthly!I23:I25)) | K11: =IFERROR(IF(OR(J11="",J7=""),"",J11/J7-1),"") | L11: =IFERROR(IF(OR(J11="",J10=""),"",J11/J10-1),"") | M11: =IF(COUNT(Monthly!L23:L25)<3,"",SUM(Monthly!L23:L25)) | N11: =IFERROR(IF(OR(M11="",M7=""),"",M11/M7-1),"") | O11: =IFERROR(IF(OR(M11="",M10=""),"",M11/M10-1),"") | P11: =IF(COUNT(Monthly!O23:O25)<3,"",SUM(Monthly!O23:O25)) | Q11: =IFERROR(IF(OR(P11="",P7=""),"",P11/P7-1),"") | R11: =IFERROR(IF(OR(P11="",P10=""),"",P11/P10-1),"")
A12: Q2FY21 | B12: FY2021 | C12: 44075 | D12: =IF(COUNT(Monthly!C26:C28)<3,"",SUM(Monthly!C26:C28)) | E12: =IFERROR(IF(OR(D12="",D8=""),"",D12/D8-1),"") | F12: =IFERROR(IF(OR(D12="",D11=""),"",D12/D11-1),"") | G12: =IF(COUNT(Monthly!F26:F28)<3,"",SUM(Monthly!F26:F28)) | H12: =IFERROR(IF(OR(G12="",G8=""),"",G12/G8-1),"") | I12: =IFERROR(IF(OR(G12="",G11=""),"",G12/G11-1),"") | J12: =IF(COUNT(Monthly!I26:I28)<3,"",SUM(Monthly!I26:I28)) | K12: =IFERROR(IF(OR(J12="",J8=""),"",J12/J8-1),"") | L12: =IFERROR(IF(OR(J12="",J11=""),"",J12/J11-1),"") | M12: =IF(COUNT(Monthly!L26:L28)<3,"",SUM(Monthly!L26:L28)) | N12: =IFERROR(IF(OR(M12="",M8=""),"",M12/M8-1),"") | O12: =IFERROR(IF(OR(M12="",M11=""),"",M12/M11-1),"") | P12: =IF(COUNT(Monthly!O26:O28)<3,"",SUM(Monthly!O26:O28)) | Q12: =IFERROR(IF(OR(P12="",P8=""),"",P12/P8-1),"") | R12: =IFERROR(IF(OR(P12="",P11=""),"",P12/P11-1),"")
A13: Q3FY21 | B13: FY2021 | C13: 44166 | D13: =IF(COUNT(Monthly!C29:C31)<3,"",SUM(Monthly!C29:C31)) | E13: =IFERROR(IF(OR(D13="",D9=""),"",D13/D9-1),"") | F13: =IFERROR(IF(OR(D13="",D12=""),"",D13/D12-1),"") | G13: =IF(COUNT(Monthly!F29:F31)<3,"",SUM(Monthly!F29:F31)) | H13: =IFERROR(IF(OR(G13="",G9=""),"",G13/G9-1),"") | I13: =IFERROR(IF(OR(G13="",G12=""),"",G13/G12-1),"") | J13: =IF(COUNT(Monthly!I29:I31)<3,"",SUM(Monthly!I29:I31)) | K13: =IFERROR(IF(OR(J13="",J9=""),"",J13/J9-1),"") | L13: =IFERROR(IF(OR(J13="",J12=""),"",J13/J12-1),"") | M13: =IF(COUNT(Monthly!L29:L31)<3,"",SUM(Monthly!L29:L31)) | N13: =IFERROR(IF(OR(M13="",M9=""),"",M13/M9-1),"") | O13: =IFERROR(IF(OR(M13="",M12=""),"",M13/M12-1),"") | P13: =IF(COUNT(Monthly!O29:O31)<3,"",SUM(Monthly!O29:O31)) | Q13: =IFERROR(IF(OR(P13="",P9=""),"",P13/P9-1),"") | R13: =IFERROR(IF(OR(P13="",P12=""),"",P13/P12-1),"")
A14: Q4FY21 | B14: FY2021 | C14: 44256 | D14: =IF(COUNT(Monthly!C32:C34)<3,"",SUM(Monthly!C32:C34)) | E14: =IFERROR(IF(OR(D14="",D10=""),"",D14/D10-1),"") | F14: =IFERROR(IF(OR(D14="",D13=""),"",D14/D13-1),"") | G14: =IF(COUNT(Monthly!F32:F34)<3,"",SUM(Monthly!F32:F34)) | H14: =IFERROR(IF(OR(G14="",G10=""),"",G14/G10-1),"") | I14: =IFERROR(IF(OR(G14="",G13=""),"",G14/G13-1),"") | J14: =IF(COUNT(Monthly!I32:I34)<3,"",SUM(Monthly!I32:I34)) | K14: =IFERROR(IF(OR(J14="",J10=""),"",J14/J10-1),"") | L14: =IFERROR(IF(OR(J14="",J13=""),"",J14/J13-1),"") | M14: =IF(COUNT(Monthly!L32:L34)<3,"",SUM(Monthly!L32:L34)) | N14: =IFERROR(IF(OR(M14="",M10=""),"",M14/M10-1),"") | O14: =IFERROR(IF(OR(M14="",M13=""),"",M14/M13-1),"") | P14: =IF(COUNT(Monthly!O32:O34)<3,"",SUM(Monthly!O32:O34)) | Q14: =IFERROR(IF(OR(P14="",P10=""),"",P14/P10-1),"") | R14: =IFERROR(IF(OR(P14="",P13=""),"",P14/P13-1),"")
A15: Q1FY22 | B15: FY2022 | C15: 44348 | D15: =IF(COUNT(Monthly!C35:C37)<3,"",SUM(Monthly!C35:C37)) | E15: =IFERROR(IF(OR(D15="",D11=""),"",D15/D11-1),"") | F15: =IFERROR(IF(OR(D15="",D14=""),"",D15/D14-1),"") | G15: =IF(COUNT(Monthly!F35:F37)<3,"",SUM(Monthly!F35:F37)) | H15: =IFERROR(IF(OR(G15="",G11=""),"",G15/G11-1),"") | I15: =IFERROR(IF(OR(G15="",G14=""),"",G15/G14-1),"") | J15: =IF(COUNT(Monthly!I35:I37)<3,"",SUM(Monthly!I35:I37)) | K15: =IFERROR(IF(OR(J15="",J11=""),"",J15/J11-1),"") | L15: =IFERROR(IF(OR(J15="",J14=""),"",J15/J14-1),"") | M15: =IF(COUNT(Monthly!L35:L37)<3,"",SUM(Monthly!L35:L37)) | N15: =IFERROR(IF(OR(M15="",M11=""),"",M15/M11-1),"") | O15: =IFERROR(IF(OR(M15="",M14=""),"",M15/M14-1),"") | P15: =IF(COUNT(Monthly!O35:O37)<3,"",SUM(Monthly!O35:O37)) | Q15: =IFERROR(IF(OR(P15="",P11=""),"",P15/P11-1),"") | R15: =IFERROR(IF(OR(P15="",P14=""),"",P15/P14-1),"")
A16: Q2FY22 | B16: FY2022 | C16: 44440 | D16: =IF(COUNT(Monthly!C38:C40)<3,"",SUM(Monthly!C38:C40)) | E16: =IFERROR(IF(OR(D16="",D12=""),"",D16/D12-1),"") | F16: =IFERROR(IF(OR(D16="",D15=""),"",D16/D15-1),"") | G16: =IF(COUNT(Monthly!F38:F40)<3,"",SUM(Monthly!F38:F40)) | H16: =IFERROR(IF(OR(G16="",G12=""),"",G16/G12-1),"") | I16: =IFERROR(IF(OR(G16="",G15=""),"",G16/G15-1),"") | J16: =IF(COUNT(Monthly!I38:I40)<3,"",SUM(Monthly!I38:I40)) | K16: =IFERROR(IF(OR(J16="",J12=""),"",J16/J12-1),"") | L16: =IFERROR(IF(OR(J16="",J15=""),"",J16/J15-1),"") | M16: =IF(COUNT(Monthly!L38:L40)<3,"",SUM(Monthly!L38:L40)) | N16: =IFERROR(IF(OR(M16="",M12=""),"",M16/M12-1),"") | O16: =IFERROR(IF(OR(M16="",M15=""),"",M16/M15-1),"") | P16: =IF(COUNT(Monthly!O38:O40)<3,"",SUM(Monthly!O38:O40)) | Q16: =IFERROR(IF(OR(P16="",P12=""),"",P16/P12-1),"") | R16: =IFERROR(IF(OR(P16="",P15=""),"",P16/P15-1),"")
A17: Q3FY22 | B17: FY2022 | C17: 44531 | D17: =IF(COUNT(Monthly!C41:C43)<3,"",SUM(Monthly!C41:C43)) | E17: =IFERROR(IF(OR(D17="",D13=""),"",D17/D13-1),"") | F17: =IFERROR(IF(OR(D17="",D16=""),"",D17/D16-1),"") | G17: =IF(COUNT(Monthly!F41:F43)<3,"",SUM(Monthly!F41:F43)) | H17: =IFERROR(IF(OR(G17="",G13=""),"",G17/G13-1),"") | I17: =IFERROR(IF(OR(G17="",G16=""),"",G17/G16-1),"") | J17: =IF(COUNT(Monthly!I41:I43)<3,"",SUM(Monthly!I41:I43)) | K17: =IFERROR(IF(OR(J17="",J13=""),"",J17/J13-1),"") | L17: =IFERROR(IF(OR(J17="",J16=""),"",J17/J16-1),"") | M17: =IF(COUNT(Monthly!L41:L43)<3,"",SUM(Monthly!L41:L43)) | N17: =IFERROR(IF(OR(M17="",M13=""),"",M17/M13-1),"") | O17: =IFERROR(IF(OR(M17="",M16=""),"",M17/M16-1),"") | P17: =IF(COUNT(Monthly!O41:O43)<3,"",SUM(Monthly!O41:O43)) | Q17: =IFERROR(IF(OR(P17="",P13=""),"",P17/P13-1),"") | R17: =IFERROR(IF(OR(P17="",P16=""),"",P17/P16-1),"")
A18: Q4FY22 | B18: FY2022 | C18: 44621 | D18: =IF(COUNT(Monthly!C44:C46)<3,"",SUM(Monthly!C44:C46)) | E18: =IFERROR(IF(OR(D18="",D14=""),"",D18/D14-1),"") | F18: =IFERROR(IF(OR(D18="",D17=""),"",D18/D17-1),"") | G18: =IF(COUNT(Monthly!F44:F46)<3,"",SUM(Monthly!F44:F46)) | H18: =IFERROR(IF(OR(G18="",G14=""),"",G18/G14-1),"") | I18: =IFERROR(IF(OR(G18="",G17=""),"",G18/G17-1),"") | J18: =IF(COUNT(Monthly!I44:I46)<3,"",SUM(Monthly!I44:I46)) | K18: =IFERROR(IF(OR(J18="",J14=""),"",J18/J14-1),"") | L18: =IFERROR(IF(OR(J18="",J17=""),"",J18/J17-1),"") | M18: =IF(COUNT(Monthly!L44:L46)<3,"",SUM(Monthly!L44:L46)) | N18: =IFERROR(IF(OR(M18="",M14=""),"",M18/M14-1),"") | O18: =IFERROR(IF(OR(M18="",M17=""),"",M18/M17-1),"") | P18: =IF(COUNT(Monthly!O44:O46)<3,"",SUM(Monthly!O44:O46)) | Q18: =IFERROR(IF(OR(P18="",P14=""),"",P18/P14-1),"") | R18: =IFERROR(IF(OR(P18="",P17=""),"",P18/P17-1),"")
A19: Q1FY23 | B19: FY2023 | C19: 44713 | D19: =IF(COUNT(Monthly!C47:C49)<3,"",SUM(Monthly!C47:C49)) | E19: =IFERROR(IF(OR(D19="",D15=""),"",D19/D15-1),"") | F19: =IFERROR(IF(OR(D19="",D18=""),"",D19/D18-1),"") | G19: =IF(COUNT(Monthly!F47:F49)<3,"",SUM(Monthly!F47:F49)) | H19: =IFERROR(IF(OR(G19="",G15=""),"",G19/G15-1),"") | I19: =IFERROR(IF(OR(G19="",G18=""),"",G19/G18-1),"") | J19: =IF(COUNT(Monthly!I47:I49)<3,"",SUM(Monthly!I47:I49)) | K19: =IFERROR(IF(OR(J19="",J15=""),"",J19/J15-1),"") | L19: =IFERROR(IF(OR(J19="",J18=""),"",J19/J18-1),"") | M19: =IF(COUNT(Monthly!L47:L49)<3,"",SUM(Monthly!L47:L49)) | N19: =IFERROR(IF(OR(M19="",M15=""),"",M19/M15-1),"") | O19: =IFERROR(IF(OR(M19="",M18=""),"",M19/M18-1),"") | P19: =IF(COUNT(Monthly!O47:O49)<3,"",SUM(Monthly!O47:O49)) | Q19: =IFERROR(IF(OR(P19="",P15=""),"",P19/P15-1),"") | R19: =IFERROR(IF(OR(P19="",P18=""),"",P19/P18-1),"")
A20: Q2FY23 | B20: FY2023 | C20: 44805 | D20: =IF(COUNT(Monthly!C50:C52)<3,"",SUM(Monthly!C50:C52)) | E20: =IFERROR(IF(OR(D20="",D16=""),"",D20/D16-1),"") | F20: =IFERROR(IF(OR(D20="",D19=""),"",D20/D19-1),"") | G20: =IF(COUNT(Monthly!F50:F52)<3,"",SUM(Monthly!F50:F52)) | H20: =IFERROR(IF(OR(G20="",G16=""),"",G20/G16-1),"") | I20: =IFERROR(IF(OR(G20="",G19=""),"",G20/G19-1),"") | J20: =IF(COUNT(Monthly!I50:I52)<3,"",SUM(Monthly!I50:I52)) | K20: =IFERROR(IF(OR(J20="",J16=""),"",J20/J16-1),"") | L20: =IFERROR(IF(OR(J20="",J19=""),"",J20/J19-1),"") | M20: =IF(COUNT(Monthly!L50:L52)<3,"",SUM(Monthly!L50:L52)) | N20: =IFERROR(IF(OR(M20="",M16=""),"",M20/M16-1),"") | O20: =IFERROR(IF(OR(M20="",M19=""),"",M20/M19-1),"") | P20: =IF(COUNT(Monthly!O50:O52)<3,"",SUM(Monthly!O50:O52)) | Q20: =IFERROR(IF(OR(P20="",P16=""),"",P20/P16-1),"") | R20: =IFERROR(IF(OR(P20="",P19=""),"",P20/P19-1),"")
A21: Q3FY23 | B21: FY2023 | C21: 44896 | D21: =IF(COUNT(Monthly!C53:C55)<3,"",SUM(Monthly!C53:C55)) | E21: =IFERROR(IF(OR(D21="",D17=""),"",D21/D17-1),"") | F21: =IFERROR(IF(OR(D21="",D20=""),"",D21/D20-1),"") | G21: =IF(COUNT(Monthly!F53:F55)<3,"",SUM(Monthly!F53:F55)) | H21: =IFERROR(IF(OR(G21="",G17=""),"",G21/G17-1),"") | I21: =IFERROR(IF(OR(G21="",G20=""),"",G21/G20-1),"") | J21: =IF(COUNT(Monthly!I53:I55)<3,"",SUM(Monthly!I53:I55)) | K21: =IFERROR(IF(OR(J21="",J17=""),"",J21/J17-1),"") | L21: =IFERROR(IF(OR(J21="",J20=""),"",J21/J20-1),"") | M21: =IF(COUNT(Monthly!L53:L55)<3,"",SUM(Monthly!L53:L55)) | N21: =IFERROR(IF(OR(M21="",M17=""),"",M21/M17-1),"") | O21: =IFERROR(IF(OR(M21="",M20=""),"",M21/M20-1),"") | P21: =IF(COUNT(Monthly!O53:O55)<3,"",SUM(Monthly!O53:O55)) | Q21: =IFERROR(IF(OR(P21="",P17=""),"",P21/P17-1),"") | R21: =IFERROR(IF(OR(P21="",P20=""),"",P21/P20-1),"")
A22: Q4FY23 | B22: FY2023 | C22: 44986 | D22: =IF(COUNT(Monthly!C56:C58)<3,"",SUM(Monthly!C56:C58)) | E22: =IFERROR(IF(OR(D22="",D18=""),"",D22/D18-1),"") | F22: =IFERROR(IF(OR(D22="",D21=""),"",D22/D21-1),"") | G22: =IF(COUNT(Monthly!F56:F58)<3,"",SUM(Monthly!F56:F58)) | H22: =IFERROR(IF(OR(G22="",G18=""),"",G22/G18-1),"") | I22: =IFERROR(IF(OR(G22="",G21=""),"",G22/G21-1),"") | J22: =IF(COUNT(Monthly!I56:I58)<3,"",SUM(Monthly!I56:I58)) | K22: =IFERROR(IF(OR(J22="",J18=""),"",J22/J18-1),"") | L22: =IFERROR(IF(OR(J22="",J21=""),"",J22/J21-1),"") | M22: =IF(COUNT(Monthly!L56:L58)<3,"",SUM(Monthly!L56:L58)) | N22: =IFERROR(IF(OR(M22="",M18=""),"",M22/M18-1),"") | O22: =IFERROR(IF(OR(M22="",M21=""),"",M22/M21-1),"") | P22: =IF(COUNT(Monthly!O56:O58)<3,"",SUM(Monthly!O56:O58)) | Q22: =IFERROR(IF(OR(P22="",P18=""),"",P22/P18-1),"") | R22: =IFERROR(IF(OR(P22="",P21=""),"",P22/P21-1),"")
A23: Q1FY24 | B23: FY2024 | C23: 45078 | D23: =IF(COUNT(Monthly!C59:C61)<3,"",SUM(Monthly!C59:C61)) | E23: =IFERROR(IF(OR(D23="",D19=""),"",D23/D19-1),"") | F23: =IFERROR(IF(OR(D23="",D22=""),"",D23/D22-1),"") | G23: =IF(COUNT(Monthly!F59:F61)<3,"",SUM(Monthly!F59:F61)) | H23: =IFERROR(IF(OR(G23="",G19=""),"",G23/G19-1),"") | I23: =IFERROR(IF(OR(G23="",G22=""),"",G23/G22-1),"") | J23: =IF(COUNT(Monthly!I59:I61)<3,"",SUM(Monthly!I59:I61)) | K23: =IFERROR(IF(OR(J23="",J19=""),"",J23/J19-1),"") | L23: =IFERROR(IF(OR(J23="",J22=""),"",J23/J22-1),"") | M23: =IF(COUNT(Monthly!L59:L61)<3,"",SUM(Monthly!L59:L61)) | N23: =IFERROR(IF(OR(M23="",M19=""),"",M23/M19-1),"") | O23: =IFERROR(IF(OR(M23="",M22=""),"",M23/M22-1),"") | P23: =IF(COUNT(Monthly!O59:O61)<3,"",SUM(Monthly!O59:O61)) | Q23: =IFERROR(IF(OR(P23="",P19=""),"",P23/P19-1),"") | R23: =IFERROR(IF(OR(P23="",P22=""),"",P23/P22-1),"")
A24: Q2FY24 | B24: FY2024 | C24: 45170 | D24: =IF(COUNT(Monthly!C62:C64)<3,"",SUM(Monthly!C62:C64)) | E24: =IFERROR(IF(OR(D24="",D20=""),"",D24/D20-1),"") | F24: =IFERROR(IF(OR(D24="",D23=""),"",D24/D23-1),"") | G24: =IF(COUNT(Monthly!F62:F64)<3,"",SUM(Monthly!F62:F64)) | H24: =IFERROR(IF(OR(G24="",G20=""),"",G24/G20-1),"") | I24: =IFERROR(IF(OR(G24="",G23=""),"",G24/G23-1),"") | J24: =IF(COUNT(Monthly!I62:I64)<3,"",SUM(Monthly!I62:I64)) | K24: =IFERROR(IF(OR(J24="",J20=""),"",J24/J20-1),"") | L24: =IFERROR(IF(OR(J24="",J23=""),"",J24/J23-1),"") | M24: =IF(COUNT(Monthly!L62:L64)<3,"",SUM(Monthly!L62:L64)) | N24: =IFERROR(IF(OR(M24="",M20=""),"",M24/M20-1),"") | O24: =IFERROR(IF(OR(M24="",M23=""),"",M24/M23-1),"") | P24: =IF(COUNT(Monthly!O62:O64)<3,"",SUM(Monthly!O62:O64)) | Q24: =IFERROR(IF(OR(P24="",P20=""),"",P24/P20-1),"") | R24: =IFERROR(IF(OR(P24="",P23=""),"",P24/P23-1),"")
A25: Q3FY24 | B25: FY2024 | C25: 45261 | D25: =IF(COUNT(Monthly!C65:C67)<3,"",SUM(Monthly!C65:C67)) | E25: =IFERROR(IF(OR(D25="",D21=""),"",D25/D21-1),"") | F25: =IFERROR(IF(OR(D25="",D24=""),"",D25/D24-1),"") | G25: =IF(COUNT(Monthly!F65:F67)<3,"",SUM(Monthly!F65:F67)) | H25: =IFERROR(IF(OR(G25="",G21=""),"",G25/G21-1),"") | I25: =IFERROR(IF(OR(G25="",G24=""),"",G25/G24-1),"") | J25: =IF(COUNT(Monthly!I65:I67)<3,"",SUM(Monthly!I65:I67)) | K25: =IFERROR(IF(OR(J25="",J21=""),"",J25/J21-1),"") | L25: =IFERROR(IF(OR(J25="",J24=""),"",J25/J24-1),"") | M25: =IF(COUNT(Monthly!L65:L67)<3,"",SUM(Monthly!L65:L67)) | N25: =IFERROR(IF(OR(M25="",M21=""),"",M25/M21-1),"") | O25: =IFERROR(IF(OR(M25="",M24=""),"",M25/M24-1),"") | P25: =IF(COUNT(Monthly!O65:O67)<3,"",SUM(Monthly!O65:O67)) | Q25: =IFERROR(IF(OR(P25="",P21=""),"",P25/P21-1),"") | R25: =IFERROR(IF(OR(P25="",P24=""),"",P25/P24-1),"")
A26: Q4FY24 | B26: FY2024 | C26: 45352 | D26: =IF(COUNT(Monthly!C68:C70)<3,"",SUM(Monthly!C68:C70)) | E26: =IFERROR(IF(OR(D26="",D22=""),"",D26/D22-1),"") | F26: =IFERROR(IF(OR(D26="",D25=""),"",D26/D25-1),"") | G26: =IF(COUNT(Monthly!F68:F70)<3,"",SUM(Monthly!F68:F70)) | H26: =IFERROR(IF(OR(G26="",G22=""),"",G26/G22-1),"") | I26: =IFERROR(IF(OR(G26="",G25=""),"",G26/G25-1),"") | J26: =IF(COUNT(Monthly!I68:I70)<3,"",SUM(Monthly!I68:I70)) | K26: =IFERROR(IF(OR(J26="",J22=""),"",J26/J22-1),"") | L26: =IFERROR(IF(OR(J26="",J25=""),"",J26/J25-1),"") | M26: =IF(COUNT(Monthly!L68:L70)<3,"",SUM(Monthly!L68:L70)) | N26: =IFERROR(IF(OR(M26="",M22=""),"",M26/M22-1),"") | O26: =IFERROR(IF(OR(M26="",M25=""),"",M26/M25-1),"") | P26: =IF(COUNT(Monthly!O68:O70)<3,"",SUM(Monthly!O68:O70)) | Q26: =IFERROR(IF(OR(P26="",P22=""),"",P26/P22-1),"") | R26: =IFERROR(IF(OR(P26="",P25=""),"",P26/P25-1),"")
A27: Q1FY25 | B27: FY2025 | C27: 45444 | D27: =IF(COUNT(Monthly!C71:C73)<3,"",SUM(Monthly!C71:C73)) | E27: =IFERROR(IF(OR(D27="",D23=""),"",D27/D23-1),"") | F27: =IFERROR(IF(OR(D27="",D26=""),"",D27/D26-1),"") | G27: =IF(COUNT(Monthly!F71:F73)<3,"",SUM(Monthly!F71:F73)) | H27: =IFERROR(IF(OR(G27="",G23=""),"",G27/G23-1),"") | I27: =IFERROR(IF(OR(G27="",G26=""),"",G27/G26-1),"") | J27: =IF(COUNT(Monthly!I71:I73)<3,"",SUM(Monthly!I71:I73)) | K27: =IFERROR(IF(OR(J27="",J23=""),"",J27/J23-1),"") | L27: =IFERROR(IF(OR(J27="",J26=""),"",J27/J26-1),"") | M27: =IF(COUNT(Monthly!L71:L73)<3,"",SUM(Monthly!L71:L73)) | N27: =IFERROR(IF(OR(M27="",M23=""),"",M27/M23-1),"") | O27: =IFERROR(IF(OR(M27="",M26=""),"",M27/M26-1),"") | P27: =IF(COUNT(Monthly!O71:O73)<3,"",SUM(Monthly!O71:O73)) | Q27: =IFERROR(IF(OR(P27="",P23=""),"",P27/P23-1),"") | R27: =IFERROR(IF(OR(P27="",P26=""),"",P27/P26-1),"")
A28: Q2FY25 | B28: FY2025 | C28: 45536 | D28: =IF(COUNT(Monthly!C74:C76)<3,"",SUM(Monthly!C74:C76)) | E28: =IFERROR(IF(OR(D28="",D24=""),"",D28/D24-1),"") | F28: =IFERROR(IF(OR(D28="",D27=""),"",D28/D27-1),"") | G28: =IF(COUNT(Monthly!F74:F76)<3,"",SUM(Monthly!F74:F76)) | H28: =IFERROR(IF(OR(G28="",G24=""),"",G28/G24-1),"") | I28: =IFERROR(IF(OR(G28="",G27=""),"",G28/G27-1),"") | J28: =IF(COUNT(Monthly!I74:I76)<3,"",SUM(Monthly!I74:I76)) | K28: =IFERROR(IF(OR(J28="",J24=""),"",J28/J24-1),"") | L28: =IFERROR(IF(OR(J28="",J27=""),"",J28/J27-1),"") | M28: =IF(COUNT(Monthly!L74:L76)<3,"",SUM(Monthly!L74:L76)) | N28: =IFERROR(IF(OR(M28="",M24=""),"",M28/M24-1),"") | O28: =IFERROR(IF(OR(M28="",M27=""),"",M28/M27-1),"") | P28: =IF(COUNT(Monthly!O74:O76)<3,"",SUM(Monthly!O74:O76)) | Q28: =IFERROR(IF(OR(P28="",P24=""),"",P28/P24-1),"") | R28: =IFERROR(IF(OR(P28="",P27=""),"",P28/P27-1),"")
A29: Q3FY25 | B29: FY2025 | C29: 45627 | D29: =IF(COUNT(Monthly!C77:C79)<3,"",SUM(Monthly!C77:C79)) | E29: =IFERROR(IF(OR(D29="",D25=""),"",D29/D25-1),"") | F29: =IFERROR(IF(OR(D29="",D28=""),"",D29/D28-1),"") | G29: =IF(COUNT(Monthly!F77:F79)<3,"",SUM(Monthly!F77:F79)) | H29: =IFERROR(IF(OR(G29="",G25=""),"",G29/G25-1),"") | I29: =IFERROR(IF(OR(G29="",G28=""),"",G29/G28-1),"") | J29: =IF(COUNT(Monthly!I77:I79)<3,"",SUM(Monthly!I77:I79)) | K29: =IFERROR(IF(OR(J29="",J25=""),"",J29/J25-1),"") | L29: =IFERROR(IF(OR(J29="",J28=""),"",J29/J28-1),"") | M29: =IF(COUNT(Monthly!L77:L79)<3,"",SUM(Monthly!L77:L79)) | N29: =IFERROR(IF(OR(M29="",M25=""),"",M29/M25-1),"") | O29: =IFERROR(IF(OR(M29="",M28=""),"",M29/M28-1),"") | P29: =IF(COUNT(Monthly!O77:O79)<3,"",SUM(Monthly!O77:O79)) | Q29: =IFERROR(IF(OR(P29="",P25=""),"",P29/P25-1),"") | R29: =IFERROR(IF(OR(P29="",P28=""),"",P29/P28-1),"")
A30: Q4FY25 | B30: FY2025 | C30: 45717 | D30: =IF(COUNT(Monthly!C80:C82)<3,"",SUM(Monthly!C80:C82)) | E30: =IFERROR(IF(OR(D30="",D26=""),"",D30/D26-1),"") | F30: =IFERROR(IF(OR(D30="",D29=""),"",D30/D29-1),"") | G30: =IF(COUNT(Monthly!F80:F82)<3,"",SUM(Monthly!F80:F82)) | H30: =IFERROR(IF(OR(G30="",G26=""),"",G30/G26-1),"") | I30: =IFERROR(IF(OR(G30="",G29=""),"",G30/G29-1),"") | J30: =IF(COUNT(Monthly!I80:I82)<3,"",SUM(Monthly!I80:I82)) | K30: =IFERROR(IF(OR(J30="",J26=""),"",J30/J26-1),"") | L30: =IFERROR(IF(OR(J30="",J29=""),"",J30/J29-1),"") | M30: =IF(COUNT(Monthly!L80:L82)<3,"",SUM(Monthly!L80:L82)) | N30: =IFERROR(IF(OR(M30="",M26=""),"",M30/M26-1),"") | O30: =IFERROR(IF(OR(M30="",M29=""),"",M30/M29-1),"") | P30: =IF(COUNT(Monthly!O80:O82)<3,"",SUM(Monthly!O80:O82)) | Q30: =IFERROR(IF(OR(P30="",P26=""),"",P30/P26-1),"") | R30: =IFERROR(IF(OR(P30="",P29=""),"",P30/P29-1),"")
A31: Q1FY26 | B31: FY2026 | C31: 45809 | D31: =IF(COUNT(Monthly!C83:C85)<3,"",SUM(Monthly!C83:C85)) | E31: =IFERROR(IF(OR(D31="",D27=""),"",D31/D27-1),"") | F31: =IFERROR(IF(OR(D31="",D30=""),"",D31/D30-1),"") | G31: =IF(COUNT(Monthly!F83:F85)<3,"",SUM(Monthly!F83:F85)) | H31: =IFERROR(IF(OR(G31="",G27=""),"",G31/G27-1),"") | I31: =IFERROR(IF(OR(G31="",G30=""),"",G31/G30-1),"") | J31: =IF(COUNT(Monthly!I83:I85)<3,"",SUM(Monthly!I83:I85)) | K31: =IFERROR(IF(OR(J31="",J27=""),"",J31/J27-1),"") | L31: =IFERROR(IF(OR(J31="",J30=""),"",J31/J30-1),"") | M31: =IF(COUNT(Monthly!L83:L85)<3,"",SUM(Monthly!L83:L85)) | N31: =IFERROR(IF(OR(M31="",M27=""),"",M31/M27-1),"") | O31: =IFERROR(IF(OR(M31="",M30=""),"",M31/M30-1),"") | P31: =IF(COUNT(Monthly!O83:O85)<3,"",SUM(Monthly!O83:O85)) | Q31: =IFERROR(IF(OR(P31="",P27=""),"",P31/P27-1),"") | R31: =IFERROR(IF(OR(P31="",P30=""),"",P31/P30-1),"")
A32: Q2FY26 | B32: FY2026 | C32: 45901 | D32: =IF(COUNT(Monthly!C86:C88)<3,"",SUM(Monthly!C86:C88)) | E32: =IFERROR(IF(OR(D32="",D28=""),"",D32/D28-1),"") | F32: =IFERROR(IF(OR(D32="",D31=""),"",D32/D31-1),"") | G32: =IF(COUNT(Monthly!F86:F88)<3,"",SUM(Monthly!F86:F88)) | H32: =IFERROR(IF(OR(G32="",G28=""),"",G32/G28-1),"") | I32: =IFERROR(IF(OR(G32="",G31=""),"",G32/G31-1),"") | J32: =IF(COUNT(Monthly!I86:I88)<3,"",SUM(Monthly!I86:I88)) | K32: =IFERROR(IF(OR(J32="",J28=""),"",J32/J28-1),"") | L32: =IFERROR(IF(OR(J32="",J31=""),"",J32/J31-1),"") | M32: =IF(COUNT(Monthly!L86:L88)<3,"",SUM(Monthly!L86:L88)) | N32: =IFERROR(IF(OR(M32="",M28=""),"",M32/M28-1),"") | O32: =IFERROR(IF(OR(M32="",M31=""),"",M32/M31-1),"") | P32: =IF(COUNT(Monthly!O86:O88)<3,"",SUM(Monthly!O86:O88)) | Q32: =IFERROR(IF(OR(P32="",P28=""),"",P32/P28-1),"") | R32: =IFERROR(IF(OR(P32="",P31=""),"",P32/P31-1),"")
A33: Q3FY26 | B33: FY2026 | C33: 45992 | D33: =IF(COUNT(Monthly!C89:C91)<3,"",SUM(Monthly!C89:C91)) | E33: =IFERROR(IF(OR(D33="",D29=""),"",D33/D29-1),"") | F33: =IFERROR(IF(OR(D33="",D32=""),"",D33/D32-1),"") | G33: =IF(COUNT(Monthly!F89:F91)<3,"",SUM(Monthly!F89:F91)) | H33: =IFERROR(IF(OR(G33="",G29=""),"",G33/G29-1),"") | I33: =IFERROR(IF(OR(G33="",G32=""),"",G33/G32-1),"") | J33: =IF(COUNT(Monthly!I89:I91)<3,"",SUM(Monthly!I89:I91)) | K33: =IFERROR(IF(OR(J33="",J29=""),"",J33/J29-1),"") | L33: =IFERROR(IF(OR(J33="",J32=""),"",J33/J32-1),"") | M33: =IF(COUNT(Monthly!L89:L91)<3,"",SUM(Monthly!L89:L91)) | N33: =IFERROR(IF(OR(M33="",M29=""),"",M33/M29-1),"") | O33: =IFERROR(IF(OR(M33="",M32=""),"",M33/M32-1),"") | P33: =IF(COUNT(Monthly!O89:O91)<3,"",SUM(Monthly!O89:O91)) | Q33: =IFERROR(IF(OR(P33="",P29=""),"",P33/P29-1),"") | R33: =IFERROR(IF(OR(P33="",P32=""),"",P33/P32-1),"")
A34: Q4FY26 | B34: FY2026 | C34: 46082 | D34: =IF(COUNT(Monthly!C92:C94)<3,"",SUM(Monthly!C92:C94)) | E34: =IFERROR(IF(OR(D34="",D30=""),"",D34/D30-1),"") | F34: =IFERROR(IF(OR(D34="",D33=""),"",D34/D33-1),"") | G34: =IF(COUNT(Monthly!F92:F94)<3,"",SUM(Monthly!F92:F94)) | H34: =IFERROR(IF(OR(G34="",G30=""),"",G34/G30-1),"") | I34: =IFERROR(IF(OR(G34="",G33=""),"",G34/G33-1),"") | J34: =IF(COUNT(Monthly!I92:I94)<3,"",SUM(Monthly!I92:I94)) | K34: =IFERROR(IF(OR(J34="",J30=""),"",J34/J30-1),"") | L34: =IFERROR(IF(OR(J34="",J33=""),"",J34/J33-1),"") | M34: =IF(COUNT(Monthly!L92:L94)<3,"",SUM(Monthly!L92:L94)) | N34: =IFERROR(IF(OR(M34="",M30=""),"",M34/M30-1),"") | O34: =IFERROR(IF(OR(M34="",M33=""),"",M34/M33-1),"") | P34: =IF(COUNT(Monthly!O92:O94)<3,"",SUM(Monthly!O92:O94)) | Q34: =IFERROR(IF(OR(P34="",P30=""),"",P34/P30-1),"") | R34: =IFERROR(IF(OR(P34="",P33=""),"",P34/P33-1),"")
A35: Q1FY27 | B35: FY2027 | C35: 46174 | D35: =IF(COUNT(Monthly!C95:C97)<3,"",SUM(Monthly!C95:C97)) | E35: =IFERROR(IF(OR(D35="",D31=""),"",D35/D31-1),"") | F35: =IFERROR(IF(OR(D35="",D34=""),"",D35/D34-1),"") | G35: =IF(COUNT(Monthly!F95:F97)<3,"",SUM(Monthly!F95:F97)) | H35: =IFERROR(IF(OR(G35="",G31=""),"",G35/G31-1),"") | I35: =IFERROR(IF(OR(G35="",G34=""),"",G35/G34-1),"") | J35: =IF(COUNT(Monthly!I95:I97)<3,"",SUM(Monthly!I95:I97)) | K35: =IFERROR(IF(OR(J35="",J31=""),"",J35/J31-1),"") | L35: =IFERROR(IF(OR(J35="",J34=""),"",J35/J34-1),"") | M35: =IF(COUNT(Monthly!L95:L97)<3,"",SUM(Monthly!L95:L97)) | N35: =IFERROR(IF(OR(M35="",M31=""),"",M35/M31-1),"") | O35: =IFERROR(IF(OR(M35="",M34=""),"",M35/M34-1),"") | P35: =IF(COUNT(Monthly!O95:O97)<3,"",SUM(Monthly!O95:O97)) | Q35: =IFERROR(IF(OR(P35="",P31=""),"",P35/P31-1),"") | R35: =IFERROR(IF(OR(P35="",P34=""),"",P35/P34-1),"")
A36: Q2FY27 | B36: FY2027 | C36: 46266 | D36: =IF(COUNT(Monthly!C98:C100)<3,"",SUM(Monthly!C98:C100)) | E36: =IFERROR(IF(OR(D36="",D32=""),"",D36/D32-1),"") | F36: =IFERROR(IF(OR(D36="",D35=""),"",D36/D35-1),"") | G36: =IF(COUNT(Monthly!F98:F100)<3,"",SUM(Monthly!F98:F100)) | H36: =IFERROR(IF(OR(G36="",G32=""),"",G36/G32-1),"") | I36: =IFERROR(IF(OR(G36="",G35=""),"",G36/G35-1),"") | J36: =IF(COUNT(Monthly!I98:I100)<3,"",SUM(Monthly!I98:I100)) | K36: =IFERROR(IF(OR(J36="",J32=""),"",J36/J32-1),"") | L36: =IFERROR(IF(OR(J36="",J35=""),"",J36/J35-1),"") | M36: =IF(COUNT(Monthly!L98:L100)<3,"",SUM(Monthly!L98:L100)) | N36: =IFERROR(IF(OR(M36="",M32=""),"",M36/M32-1),"") | O36: =IFERROR(IF(OR(M36="",M35=""),"",M36/M35-1),"") | P36: =IF(COUNT(Monthly!O98:O100)<3,"",SUM(Monthly!O98:O100)) | Q36: =IFERROR(IF(OR(P36="",P32=""),"",P36/P32-1),"") | R36: =IFERROR(IF(OR(P36="",P35=""),"",P36/P35-1),"")

Sheet FY Totals
A1: ICICI Pru Life - fiscal-year totals as reported (INR Bn); 11M = Apr-Feb cumulative, used to derive March
A3: Fiscal Year | B3: RWRP FY (INR Bn) | C3: RWRP FY YoY | D3: RWRP 11M (INR Bn) | E3: APE FY (INR Bn) | F3: APE FY YoY | G3: APE 11M (INR Bn) | H3: Retail APE FY (INR Bn) | I3: Retail APE FY YoY | J3: Retail APE 11M (INR Bn) | K3: NB Premium FY (INR Bn) | L3: NB Premium FY YoY | M3: NB Premium 11M (INR Bn) | N3: NB Sum Assured FY (INR Bn) | O3: NB Sum Assured FY YoY | P3: NB Sum Assured 11M (INR Bn)
A4: FY2019 | B4: 70.95 | D4: 61.58 | E4: 77.99 | G4: 68.07
A5: FY2020 | B5: 66.43 | C5: =IFERROR(IF(OR(B5="",B4=""),"",B5/B4-1),"") | D5: 61.65 | E5: 73.81 | F5: =IFERROR(IF(OR(E5="",E4=""),"",E5/E4-1),"") | G5: 68.52 | I5: =IFERROR(IF(OR(H5="",H4=""),"",H5/H4-1),"") | K5: 123.48 | L5: =IFERROR(IF(OR(K5="",K4=""),"",K5/K4-1),"") | N5: 5711.84 | O5: =IFERROR(IF(OR(N5="",N4=""),"",N5/N4-1),"")
A6: FY2021 | B6: 54.54 | C6: =IFERROR(IF(OR(B6="",B5=""),"",B6/B5-1),"") | D6: 45.06 | E6: 64.62 | F6: =IFERROR(IF(OR(E6="",E5=""),"",E6/E5-1),"") | G6: 53.61 | I6: =IFERROR(IF(OR(H6="",H5=""),"",H6/H5-1),"") | K6: 130.32 | L6: =IFERROR(IF(OR(K6="",K5=""),"",K6/K5-1),"") | M6: 108.75 | N6: 6166.84 | O6: =IFERROR(IF(OR(N6="",N5=""),"",N6/N5-1),"") | P6: 5354.69
A7: FY2022 | B7: 62.99 | C7: =IFERROR(IF(OR(B7="",B6=""),"",B7/B6-1),"") | D7: 53.41 | E7: 77.33 | F7: =IFERROR(IF(OR(E7="",E6=""),"",E7/E6-1),"") | G7: 65.52 | I7: =IFERROR(IF(OR(H7="",H6=""),"",H7/H6-1),"") | K7: 150.36 | L7: =IFERROR(IF(OR(K7="",K6=""),"",K7/K6-1),"") | M7: 128.45 | N7: 7731.46 | O7: =IFERROR(IF(OR(N7="",N6=""),"",N7/N6-1),"") | P7: 6790.52
A8: FY2023 | B8: 67.38 | C8: =IFERROR(IF(OR(B8="",B7=""),"",B8/B7-1),"") | D8: 52.15 | E8: 86.4 | F8: =IFERROR(IF(OR(E8="",E7=""),"",E8/E7-1),"") | G8: 68.35 | I8: =IFERROR(IF(OR(H8="",H7=""),"",H8/H7-1),"") | K8: 169.22 | L8: =IFERROR(IF(OR(K8="",K7=""),"",K8/K7-1),"") | M8: 140.57 | N8: 10413.92 | O8: =IFERROR(IF(OR(N8="",N7=""),"",N8/N7-1),"") | P8: 9313.38
