Workbook

Sheet NAV
A1: Scheme Name | B1: Fund Name | C1: Category | D1: 46111 | E1: 46112 | F1: 46113 | G1: 46114 | H1: 46118 | I1: 46119 | J1: 46120 | K1: 46121 | L1: 46122 | M1: 46125 | N1: 46127 | O1: 46128 | P1: 46129 | Q1: 46132 | R1: 46133 | S1: 46134 | T1: 46135 | U1: 46136 | V1: 46139 | W1: 46140 | X1: 46141 | Y1: 46142 | Z1: 46146 | AA1: 46147 | AB1: 46148 | AC1: 46149 | AD1: 46150 | AE1: 46153 | AF1: 46154 | AG1: 46155 | AH1: 46156 | AI1: 46157 | AJ1: 46160 | AK1: 46161 | AL1: 46162 | AM1: 46163 | AN1: 46164 | AO1: 46167 | AP1: 46168 | AQ1: 46169 | AR1: 46171
A2: 360 ONE Balanced Hybrid Fund | B2: 360 ONE | C2: BALANCED HYBRID | D2: 11.9842 | E2: 11.9849 | G2: 12.0828 | H2: 12.1517 | I2: 12.1905 | J2: 12.4602 | K2: 12.4323 | L2: 12.5287 | M2: 12.4834 | N2: 12.6104 | O2: 12.6252 | P2: 12.6903 | Q2: 12.6844 | R2: 12.7206 | S2: 12.6873 | T2: 12.6426 | U2: 12.5902 | V2: 12.6483 | W2: 12.6296 | X2: 12.6639 | Y2: 12.5998 | Z2: 12.6573 | AA2: 12.6693 | AB2: 12.7801 | AC2: 12.8329 | AD2: 12.811 | AE2: 12.7265 | AF2: 12.5757 | AG2: 12.5839 | AH2: 12.6374 | AI2: 12.6331 | AJ2: 12.606 | AK2: 12.6246 | AL2: 12.6512 | AM2: 12.6458 | AN2: 12.6797 | AO2: 12.7572 | AP2: 12.7528 | AQ2: 12.7882 | AR2: 12.7432
A3: 360 ONE Flexicap Fund | B3: 360 ONE | C3: FLEXI CAP | D3: 13.1454 | E3: 13.1447 | F3: 13.4198 | G3: 13.4138 | H3: 13.5864 | I3: 13.682 | J3: 14.2693 | K3: 14.204 | L3: 14.4501 | M3: 14.3498 | N3: 14.6117 | O3: 14.6519 | P3: 14.8019 | Q3: 14.7812 | R3: 14.8847 | S3: 14.8105 | T3: 14.7134 | U3: 14.605 | V3: 14.7159 | W3: 14.6841 | X3: 14.7764 | Y3: 14.6199 | Z3: 14.7281 | AA3: 14.7453 | AB3: 14.9851 | AC3: 15.1176 | AD3: 15.0644 | AE3: 14.8968 | AF3: 14.5438 | AG3: 14.5824 | AH3: 14.7124 | AI3: 14.7285 | AJ3: 14.6707 | AK3: 14.7208 | AL3: 14.7872 | AM3: 14.7891 | AN3: 14.8575 | AO3: 15.0317 | AP3: 15.0187 | AQ3: 15.1209 | AR3: 15.0069
A4: 360 ONE Focused Fund | B4: 360 ONE | C4: FOCUSED | D4: 41.3556 | E4: 41.3536 | F4: 42.1818 | G4: 42.1643 | H4: 42.675 | I4: 42.9814 | J4: 44.9583 | K4: 44.6187 | L4: 45.3147 | M4: 44.9372 | N4: 45.5416 | O4: 45.6178 | P4: 45.9123 | Q4: 45.8675 | R4: 46.3036 | S4: 46.0475 | T4: 45.7121 | U4: 45.4132 | V4: 45.5719 | W4: 45.4412 | X4: 45.6504 | Y4: 45.2021 | Z4: 45.4976 | AA4: 45.5098 | AB4: 46.2202 | AC4: 46.5182 | AD4: 46.4041 | AE4: 45.636 | AF4: 44.5 | AG4: 44.668 | AH4: 45.1999 | AI4: 45.2481 | AJ4: 45.2326 | AK4: 45.3216 | AL4: 45.5001 | AM4: 45.5496 | AN4: 45.8247 | AO4: 46.259 | AP4: 46.1592 | AQ4: 46.6008 | AR4: 46.0619
A5: 360 ONE Multi Asset Allocation Fund | B5: 360 ONE | C5: MULTI ASSET ALLOCATION | D5: 11.505 | E5: 11.5012 | G5: 11.5457 | H5: 11.6555 | I5: 11.6682 | J5: 11.8916 | K5: 11.822 | L5: 11.8976 | M5: 11.8631 | N5: 11.975 | O5: 11.9797 | P5: 11.9964 | Q5: 11.9765 | R5: 12.0196 | S5: 11.9813 | T5: 11.9229 | U5: 11.8964 | V5: 11.9339 | W5: 11.8682 | X5: 11.8606 | Y5: 11.8757 | Z5: 11.8704 | AA5: 11.852 | AB5: 11.9657 | AC5: 12.0118 | AD5: 11.9823 | AE5: 11.8807 | AF5: 11.8609 | AG5: 12.0144 | AH5: 12.0956 | AI5: 12.035 | AJ5: 12.0068 | AK5: 12.0493 | AL5: 12.0541 | AM5: 12.0566 | AN5: 12.0859 | AO5: 12.1216 | AP5: 12.0876 | AQ5: 12.0945 | AR5: 12.0594
A6: 360 ONE Quant Fund | B6: 360 ONE | C6: SECTORAL / THEMATIC | D6: 17.0029 | E6: 17.002 | F6: 17.2181 | G6: 17.1019 | H6: 17.3066 | I6: 17.3427 | J6: 18.18 | K6: 18.1291 | L6: 18.4814 | M6: 18.1988 | N6: 18.5528 | O6: 18.562 | P6: 18.7114 | Q6: 18.7349 | R6: 18.778 | S6: 18.7274 | T6: 18.5196 | U6: 18.3624 | V6: 18.5218 | W6: 18.402 | X6: 18.4783 | Y6: 18.2678 | Z6: 18.424 | AA6: 18.4857 | AB6: 18.8411 | AC6: 18.9782 | AD6: 18.9216 | AE6: 18.7264 | AF6: 18.3092 | AG6: 18.3736 | AH6: 18.5495 | AI6: 18.4641 | AJ6: 18.3441 | AK6: 18.3325 | AL6: 18.331 | AM6: 18.3705 | AN6: 18.4025 | AO6: 18.6237 | AP6: 18.5929 | AQ6: 18.7332 | AR6: 18.4041
A7: Abakkus Flexi Cap Fund | B7: Abakkus | C7: FLEXI CAP | D7: 9.08 | E7: 9.08 | F7: 9.267 | G7: 9.243 | H7: 9.33 | I7: 9.364 | J7: 9.691 | K7: 9.687 | L7: 9.879 | M7: 9.85 | N7: 10.024 | O7: 10.071 | P7: 10.163 | Q7: 10.16 | R7: 10.264 | S7: 10.285 | T7: 10.219 | U7: 10.115 | V7: 10.253 | W7: 10.226 | X7: 10.287 | Y7: 10.196 | Z7: 10.3 | AA7: 10.264 | AB7: 10.418 | AC7: 10.489 | AD7: 10.423 | AE7: 10.282 | AF7: 10.07 | AG7: 10.11 | AH7: 10.171 | AI7: 10.15 | AJ7: 10.094 | AK7: 10.155 | AL7: 10.201 | AM7: 10.223 | AN7: 10.262 | AO7: 10.405 | AP7: 10.397 | AQ7: 10.445 | AR7: 10.338
A8: Abakkus Small Cap Fund | B8: Abakkus | C8: SMALL CAP | D8: 9.854 | E8: 9.855 | F8: 10.007 | G8: 9.984 | H8: 10.04 | I8: 10.071 | J8: 10.343 | K8: 10.351 | L8: 10.508 | M8: 10.513 | N8: 10.74 | O8: 10.826 | P8: 10.911 | Q8: 10.871 | R8: 10.95 | S8: 11.037 | T8: 11.005 | U8: 10.906 | V8: 11.062 | W8: 11.035 | X8: 11.063 | Y8: 11.007 | Z8: 11.139 | AA8: 11.125 | AB8: 11.286 | AC8: 11.347 | AD8: 11.339 | AE8: 11.185 | AF8: 10.944 | AG8: 10.952 | AH8: 10.989 | AI8: 10.975 | AJ8: 10.856 | AK8: 10.958 | AL8: 10.969 | AM8: 11.048 | AN8: 11.044 | AO8: 11.158 | AP8: 11.181 | AQ8: 11.237 | AR8: 11.246
A9: Aditya Birla Sun Life Arbitrage Fund | B9: Aditya Birla Sun Life | C9: ARBITRAGE | D9: 27.7263 | E9: 27.7276 | F9: 27.7102 | G9: 27.7371 | H9: 27.7333 | I9: 27.751 | J9: 27.7549 | K9: 27.7578 | L9: 27.7795 | M9: 27.7987 | N9: 27.8138 | O9: 27.8186 | P9: 27.8157 | Q9: 27.8479 | R9: 27.8322 | S9: 27.8399 | T9: 27.8417 | U9: 27.8253 | V9: 27.8343 | W9: 27.8391 | X9: 27.8526 | Y9: 27.8377 | Z9: 27.8462 | AA9: 27.8535 | AB9: 27.8245 | AC9: 27.8621 | AD9: 27.8765 | AE9: 27.884 | AF9: 27.8844 | AG9: 27.8781 | AH9: 27.8886 | AI9: 27.919 | AJ9: 27.9172 | AK9: 27.923 | AL9: 27.9011 | AM9: 27.9046 | AN9: 27.8825 | AO9: 27.8981 | AP9: 27.9016 | AQ9: 27.8895 | AR9: 27.8437
A10: Aditya Birla Sun Life Balanced Advantage Fund | B10: Aditya Birla Sun Life | C10: DYNAMIC ASSET ALLOCATION OR BALANCED ADVANTAGE | D10: 102.25 | E10: 102.25 | F10: 103.41 | G10: 103.36 | H10: 104.18 | I10: 104.52 | J10: 107.02 | K10: 106.74 | L10: 107.86 | M10: 107.51 | N10: 108.82 | O10: 108.85 | P10: 109.57 | Q10: 109.63 | R10: 110.25 | S10: 110.11 | T10: 109.42 | U10: 108.41 | V10: 109.27 | W10: 108.98 | X10: 109.02 | Y10: 108.52 | Z10: 108.96 | AA10: 108.93 | AB10: 109.84 | AC10: 110.05 | AD10: 109.78 | AE10: 108.9 | AF10: 107.28 | AG10: 107.62 | AH10: 108.2 | AI10: 108.02 | AJ10: 107.87 | AK10: 108.23 | AL10: 108.19 | AM10: 107.99 | AN10: 108.31 | AO10: 109.14 | AP10: 109.18 | AQ10: 109.37 | AR10: 108.69
A11: Aditya Birla Sun Life Banking & Financial Services Fund | B11: Aditya Birla Sun Life | C11: SECTORAL / THEMATIC | D11: 54.66 | E11: 54.65 | F11: 55.87 | G11: 55.94 | H11: 57.17 | I11: 57.32 | J11: 60.61 | K11: 59.91 | L11: 61.15 | M11: 60.76 | N11: 61.58 | O11: 61.72 | P11: 62.2 | Q11: 62.29 | R11: 63.46 | S11: 63.18 | T11: 62.46 | U11: 62.24 | V11: 62.09 | W11: 61.48 | X11: 61.6 | Y11: 61.05 | Z11: 61.41 | AA11: 61.32 | AB11: 62.64 | AC11: 62.82 | AD11: 62.05 | AE11: 61.13 | AF11: 59.69 | AG11: 59.67 | AH11: 60.28 | AI11: 60.05 | AJ11: 59.74 | AK11: 59.77 | AL11: 59.78 | AM11: 59.68 | AN11: 60.15 | AO11: 61.34 | AP11: 61.11 | AQ11: 60.85 | AR11: 59.99
A12: Aditya Birla Sun Life Business Cycle Fund | B12: Aditya Birla Sun Life | C12: SECTORAL / THEMATIC | D12: 13.62 | E12: 13.62 | F12: 13.87 | G12: 13.86 | H12: 14.03 | I12: 14.08 | J12: 14.63 | K12: 14.55 | L12: 14.79 | M12: 14.74 | N12: 14.98 | O12: 15.02 | P12: 15.17 | Q12: 15.19 | R12: 15.34 | S12: 15.29 | T12: 15.14 | U12: 14.97 | V12: 15.13 | W12: 15.02 | X12: 15.01 | Y12: 14.91 | Z12: 15.04 | AA12: 15 | AB12: 15.17 | AC12: 15.27 | AD12: 15.19 | AE12: 14.99 | AF12: 14.65 | AG12: 14.66 | AH12: 14.78 | AI12: 14.69 | AJ12: 14.62 | AK12: 14.74 | AL12: 14.74 | AM12: 14.77 | AN12: 14.78 | AO12: 14.96 | AP12: 14.97 | AQ12: 15.03 | AR12: 14.93
A13: Aditya Birla Sun Life Conglomerate Fund | B13: Aditya Birla Sun Life | C13: SECTORAL / THEMATIC | D13: 9.2 | E13: 9.2 | F13: 9.44 | G13: 9.45 | H13: 9.52 | I13: 9.55 | J13: 9.96 | K13: 9.9 | L13: 10.06 | M13: 9.97 | N13: 10.2 | O13: 10.28 | P13: 10.35 | Q13: 10.35 | R13: 10.42 | S13: 10.44 | T13: 10.37 | U13: 10.24 | V13: 10.41 | W13: 10.46 | X13: 10.55 | Y13: 10.46 | Z13: 10.57 | AA13: 10.56 | AB13: 10.69 | AC13: 10.75 | AD13: 10.73 | AE13: 10.58 | AF13: 10.31 | AG13: 10.38 | AH13: 10.44 | AI13: 10.36 | AJ13: 10.32 | AK13: 10.37 | AL13: 10.43 | AM13: 10.45 | AN13: 10.47 | AO13: 10.63 | AP13: 10.67 | AQ13: 10.74 | AR13: 10.63
A14: Aditya Birla Sun Life Consumption Fund | B14: Aditya Birla Sun Life | C14: SECTORAL / THEMATIC | D14: 184.13 | E14: 184.12 | F14: 187.43 | G14: 187.3 | H14: 190.03 | I14: 190.29 | J14: 197.01 | K14: 196.08 | L14: 199.06 | M14: 197.18 | N14: 200.55 | O14: 200.62 | P14: 202.8 | Q14: 203.07 | R14: 205.54 | S14: 205.7 | T14: 203.67 | U14: 201.79 | V14: 203.28 | W14: 202.15 | X14: 203.37 | Y14: 201.42 | Z14: 202.3 | AA14: 201.81 | AB14: 204.34 | AC14: 204.54 | AD14: 204.32 | AE14: 201.44 | AF14: 197.14 | AG14: 197.39 | AH14: 199.5 | AI14: 199.33 | AJ14: 198.58 | AK14: 198.72 | AL14: 198.16 | AM14: 198.05 | AN14: 198.74 | AO14: 200.13 | AP14: 199.54 | AQ14: 199.97 | AR14: 196.92
A15: Aditya Birla Sun Life Digital India Fund | B15: Aditya Birla Sun Life | C15: SECTORAL / THEMATIC | D15: 135.22 | E15: 135.3 | F15: 138.44 | G15: 141.27 | H15: 142.03 | I15: 144.16 | J15: 146.64 | K15: 146.74 | L15: 145.76 | M15: 144.66 | N15: 148.46 | O15: 150.4 | P15: 150.87 | Q15: 149.91 | R15: 150.8 | S15: 148.04 | T15: 146.4 | U15: 141.07 | V15: 142.95 | W15: 142.41 | X15: 143.62 | Y15: 143.6 | Z15: 142.92 | AA15: 142.86 | AB15: 145.29 | AC15: 144.81 | AD15: 147 | AE15: 145.61 | AF15: 141.05 | AG15: 140.12 | AH15: 139.58 | AI15: 140.45 | AJ15: 142.73 | AK15: 146.32 | AL15: 145.52 | AM15: 144.65 | AN15: 144.63 | AO15: 145.93 | AP15: 146.17 | AQ15: 146.06 | AR15: 145.81
A16: Aditya Birla Sun Life Dividend Yield Fund | B16: Aditya Birla Sun Life | C16: DIVIDEND YIELD | D16: 413.1 | E16: 413.29 | F16: 422.19 | G16: 422.93 | H16: 429.69 | I16: 432.53 | J16: 443.64 | K16: 444.56 | L16: 447.52 | M16: 446.58 | N16: 453.9 | O16: 454.85 | P16: 460.1 | Q16: 460.22 | R16: 463.69 | S16: 461.35 | T16: 457.39 | U16: 452.1 | V16: 456.01 | W16: 454.34 | X16: 458.4 | Y16: 455.08 | Z16: 455.93 | AA16: 456.12 | AB16: 462.58 | AC16: 463.54 | AD16: 461.8 | AE16: 457.52 | AF16: 449.5 | AG16: 451.24 | AH16: 453.3 | AI16: 453.17 | AJ16: 450.94 | AK16: 455.46 | AL16: 455.46 | AM16: 453.58 | AN16: 452.82 | AO16: 457.65 | AP16: 457.03 | AQ16: 457.43 | AR16: 451.16
A17: Aditya Birla Sun Life ELSS Tax Saver Fund | B17: Aditya Birla Sun Life | C17: ELSS | D17: 54.36 | E17: 54.36 | F17: 55.58 | G17: 55.54 | H17: 56.26 | I17: 56.58 | J17: 58.65 | K17: 58.35 | L17: 59.16 | M17: 58.78 | N17: 59.78 | O17: 59.9 | P17: 60.48 | Q17: 60.47 | R17: 61.04 | S17: 60.95 | T17: 60.42 | U17: 59.72 | V17: 60.36 | W17: 60.06 | X17: 60.32 | Y17: 59.87 | Z17: 60.49 | AA17: 60.41 | AB17: 61.21 | AC17: 61.32 | AD17: 60.93 | AE17: 59.96 | AF17: 58.72 | AG17: 58.8 | AH17: 59.34 | AI17: 59.24 | AJ17: 59.1 | AK17: 59.27 | AL17: 59.41 | AM17: 59.32 | AN17: 59.52 | AO17: 60.27 | AP17: 60.16 | AQ17: 60.42 | AR17: 59.69
... A34: Aditya Birla Sun Life Quant Fund | B34: Aditya Birla Sun Life | C34: SECTORAL / THEMATIC | D34: 8.91 | E34: 8.91 | F34: 9.04 | G34: 9.01 | H34: 9.14 | I34: 9.2 | J34: 9.6 | K34: 9.58 | L34: 9.74 | M34: 9.64 | N34: 9.78 | O34: 9.78 | P34: 9.86 | Q34: 9.9 | R34: 9.91 | S34: 9.87 | T34: 9.78 | U34: 9.72 | V34: 9.84 | W34: 9.78 | X34: 9.81 | Y34: 9.7 | Z34: 9.77 | AA34: 9.79 | AB34: 9.97 | AC34: 10.06 | AD34: 10.02 | AE34: 9.93 | AF34: 9.76 | AG34: 9.8 | AH34: 9.91 | AI34: 9.85 | AJ34: 9.78 | AK34: 9.81 | AL34: 9.86 | AM34: 9.87 | AN34: 9.9 | AO34: 10.04 | AP34: 10.01 | AQ34: 10.07 | AR34: 9.92
A35: Aditya Birla Sun Life Regular Savings Fund | B35: Aditya Birla Sun Life | C35: CONSERVATIVE HYRBID | D35: 67.0697 | E35: 67.0895 | G35: 67.1641 | H35: 67.3988 | I35: 67.5138 | J35: 68.2278 | K35: 68.2235 | L35: 68.4753 | M35: 68.3599 | N35: 68.7058 | O35: 68.7124 | P35: 68.8416 | Q35: 68.8466 | R35: 68.9738 | S35: 68.9118 | T35: 68.7224 | U35: 68.5566 | V35: 68.7469 | W35: 68.695 | X35: 68.7055 | Y35: 68.5543 | Z35: 68.7193 | AA35: 68.6961 | AB35: 69.0035 | AC35: 69.0836 | AD35: 69.0182 | AE35: 68.8083 | AF35: 68.5395 | AG35: 68.5487 | AH35: 68.7144 | AI35: 68.609 | AJ35: 68.4192 | AK35: 68.43 | AL35: 68.4776 | AM35: 68.462 | AN35: 68.5233 | AO35: 68.7889 | AP35: 68.7847 | AQ35: 68.8661 | AR35: 68.7522
A36: Aditya Birla Sun Life Small cap Fund | B36: Aditya Birla Sun Life | C36: SMALL CAP | D36: 76.2251 | E36: 76.2218 | F36: 78.1433 | G36: 78.0308 | H36: 79.2089 | I36: 79.2352 | J36: 82.0232 | K36: 82.059 | L36: 83.2372 | M36: 82.9096 | N36: 84.3057 | O36: 84.8954 | P36: 86.0144 | Q36: 86.2474 | R36: 87.0972 | S36: 87.8899 | T36: 87.7067 | U36: 87.4017 | V36: 88.7495 | W36: 88.6403 | X36: 89.1451 | Y36: 88.8412 | Z36: 90.1122 | AA36: 89.7456 | AB36: 90.6651 | AC36: 92.1379 | AD36: 92.103 | AE36: 91.09 | AF36: 88.7621 | AG36: 88.961 | AH36: 89.6799 | AI36: 89.8147 | AJ36: 88.8786 | AK36: 90.0184 | AL36: 90.2036 | AM36: 90.5962 | AN36: 90.4121 | AO36: 91.6148 | AP36: 91.8316 | AQ36: 91.745 | AR36: 91.2669
A37: Aditya Birla Sun Life Special Opportunities Fund | B37: Aditya Birla Sun Life | C37: SECTORAL / THEMATIC | D37: 23.38 | E37: 23.37 | F37: 23.8 | G37: 23.79 | H37: 24.11 | I37: 24.23 | J37: 25.13 | K37: 25.09 | L37: 25.41 | M37: 25.31 | N37: 25.77 | O37: 25.85 | P37: 26.11 | Q37: 26.1 | R37: 26.41 | S37: 26.34 | T37: 26.14 | U37: 25.89 | V37: 26.15 | W37: 26.06 | X37: 26.24 | Y37: 26.03 | Z37: 26.23 | AA37: 26.24 | AB37: 26.59 | AC37: 26.71 | AD37: 26.65 | AE37: 26.34 | AF37: 25.83 | AG37: 25.92 | AH37: 26.16 | AI37: 26.1 | AJ37: 26 | AK37: 26.13 | AL37: 26.14 | AM37: 26.08 | AN37: 26.18 | AO37: 26.55 | AP37: 26.6 | AQ37: 26.63 | AR37: 26.55
A38: Aditya Birla Sun Life Transportation and Logistics Fund | B38: Aditya Birla Sun Life | C38: SECTORAL / THEMATIC | D38: 12.99 | E38: 12.99 | F38: 13.3 | G38: 13.21 | H38: 13.37 | I38: 13.36 | J38: 14.13 | K38: 14.04 | L38: 14.37 | M38: 14.09 | N38: 14.37 | O38: 14.41 | P38: 14.5 | Q38: 14.53 | R38: 14.62 | S38: 14.67 | T38: 14.41 | U38: 14.25 | V38: 14.5 | W38: 14.36 | X38: 14.41 | Y38: 14.32 | Z38: 14.43 | AA38: 14.45 | AB38: 14.76 | AC38: 14.99 | AD38: 15.02 | AE38: 14.73 | AF38: 14.33 | AG38: 14.29 | AH38: 14.35 | AI38: 14.34 | AJ38: 14.16 | AK38: 14.28 | AL38: 14.34 | AM38: 14.5 | AN38: 14.54 | AO38: 14.75 | AP38: 14.76 | AQ38: 14.99 | AR38: 14.75
A39: Aditya Birla Sun Life Value Fund | B39: Aditya Birla Sun Life | C39: VALUE | D39: 113.9322 | E39: 113.9268 | F39: 116.3411 | G39: 116.4956 | H39: 118.016 | I39: 118.7063 | J39: 123.1663 | K39: 123.0909 | L39: 124.5489 | M39: 124.2168 | N39: 126.7858 | O39: 127.4767 | P39: 129.0816 | Q39: 129.1341 | R39: 130.1124 | S39: 130.2569 | T39: 129.751 | U39: 128.061 | V39: 129.5452 | W39: 129.1364 | X39: 129.6306 | Y39: 128.7588 | Z39: 129.8865 | AA39: 129.746 | AB39: 131.6491 | AC39: 132.6191 | AD39: 132.6744 | AE39: 131.3783 | AF39: 128.3605 | AG39: 128.6369 | AH39: 129.5487 | AI39: 129.4134 | AJ39: 128.7731 | AK39: 129.8606 | AL39: 129.9578 | AM39: 130.3176 | AN39: 130.6344 | AO39: 132.3016 | AP39: 132.497 | AQ39: 133.0251 | AR39: 131.5397
A40: Axis Aggressive Hybrid Fund | B40: Axis | C40: AGGRESSIVE HYBRID | D40: 18.95 | E40: 18.95 | F40: 19.18 | G40: 19.19 | H40: 19.33 | I40: 19.4 | J40: 19.95 | K40: 19.82 | L40: 20.02 | M40: 19.91 | N40: 20.19 | O40: 20.2 | P40: 20.31 | Q40: 20.29 | R40: 20.43 | S40: 20.36 | T40: 20.22 | U40: 20.07 | V40: 20.25 | W40: 20.19 | X40: 20.25 | Y40: 20.14 | Z40: 20.21 | AA40: 20.2 | AB40: 20.4 | AC40: 20.42 | AD40: 20.36 | AE40: 20.15 | AF40: 19.81 | AG40: 19.82 | AH40: 19.93 | AI40: 19.89 | AJ40: 19.84 | AK40: 19.89 | AL40: 19.91 | AM40: 19.94 | AN40: 19.99 | AO40: 20.16 | AP40: 20.11 | AQ40: 20.14 | AR40: 19.94
A41: Axis Arbitrage Fund | B41: Axis | C41: ARBITRAGE | D41: 19.515 | E41: 19.5158 | F41: 19.5024 | G41: 19.5202 | H41: 19.513 | I41: 19.5306 | J41: 19.5303 | K41: 19.5387 | L41: 19.5509 | M41: 19.5661 | N41: 19.5757 | O41: 19.578 | P41: 19.579 | Q41: 19.6013 | R41: 19.5874 | S41: 19.5911 | T41: 19.5946 | U41: 19.5833 | V41: 19.5842 | W41: 19.5933 | X41: 19.6041 | Y41: 19.5899 | Z41: 19.5976 | AA41: 19.6025 | AB41: 19.5823 | AC41: 19.6091 | AD41: 19.621 | AE41: 19.6251 | AF41: 19.6225 | AG41: 19.6187 | AH41: 19.6265 | AI41: 19.6469 | AJ41: 19.6479 | AK41: 19.6509 | AL41: 19.6346 | AM41: 19.6404 | AN41: 19.6247 | AO41: 19.6336 | AP41: 19.6357 | AQ41: 19.6275 | AR41: 19.5935
A42: Axis Balanced Advantage Fund | B42: Axis | C42: DYNAMIC ASSET ALLOCATION OR BALANCED ADVANTAGE | D42: 20.03 | E42: 20.03 | F42: 20.21 | G42: 20.2 | H42: 20.33 | I42: 20.41 | J42: 20.91 | K42: 20.78 | L42: 20.95 | M42: 20.85 | N42: 21.1 | O42: 21.11 | P42: 21.21 | Q42: 21.21 | R42: 21.33 | S42: 21.26 | T42: 21.12 | U42: 20.98 | V42: 21.12 | W42: 21.05 | X42: 21.11 | Y42: 21.01 | Z42: 21.06 | AA42: 21.05 | AB42: 21.23 | AC42: 21.25 | AD42: 21.22 | AE42: 21.04 | AF42: 20.77 | AG42: 20.76 | AH42: 20.86 | AI42: 20.86 | AJ42: 20.83 | AK42: 20.85 | AL42: 20.86 | AM42: 20.85 | AN42: 20.89 | AO42: 21.05 | AP42: 21 | AQ42: 21.02 | AR42: 20.86
A43: Axis Business Cycles Fund | B43: Axis | C43: SECTORAL / THEMATIC | D43: 14.49 | E43: 14.49 | F43: 14.78 | G43: 14.77 | H43: 14.97 | I43: 15.04 | J43: 15.69 | K43: 15.58 | L43: 15.85 | M43: 15.72 | N43: 15.99 | O43: 16.05 | P43: 16.2 | Q43: 16.22 | R43: 16.38 | S43: 16.38 | T43: 16.26 | U43: 16.1 | V43: 16.29 | W43: 16.26 | X43: 16.28 | Y43: 16.17 | Z43: 16.28 | AA43: 16.3 | AB43: 16.51 | AC43: 16.63 | AD43: 16.56 | AE43: 16.41 | AF43: 16.04 | AG43: 16.08 | AH43: 16.23 | AI43: 16.14 | AJ43: 16.1 | AK43: 16.12 | AL43: 16.16 | AM43: 16.13 | AN43: 16.15 | AO43: 16.35 | AP43: 16.35 | AQ43: 16.42 | AR43: 16.19
A44: Axis Conservative Hybrid Fund | B44: Axis | C44: CONSERVATIVE HYRBID | D44: 29.5106 | E44: 29.5134 | G44: 29.5201 | H44: 29.6692 | I44: 29.7263 | J44: 30.0559 | K44: 29.9716 | L44: 30.0613 | M44: 30.0277 | N44: 30.1947 | O44: 30.1845 | P44: 30.2063 | Q44: 30.2226 | R44: 30.273 | S44: 30.1954 | T44: 30.123 | U44: 30.0226 | V44: 30.1062 | W44: 30.0511 | X44: 30.085 | Y44: 30.0314 | Z44: 30.0725 | AA44: 30.0682 | AB44: 30.2166 | AC44: 30.2166 | AD44: 30.1645 | AE44: 30.0157 | AF44: 29.8958 | AG44: 29.9158 | AH44: 29.9947 | AI44: 29.9468 | AJ44: 29.8911 | AK44: 29.9268 | AL44: 29.9119 | AM44: 29.8846 | AN44: 29.9311 | AO44: 30.0484 | AP44: 30.0204 | AQ44: 30.0186 | AR44: 29.9466
A45: Axis Consumption Fund | B45: Axis | C45: SECTORAL / THEMATIC | D45: 8.1 | E45: 8.1 | F45: 8.24 | G45: 8.24 | H45: 8.33 | I45: 8.36 | J45: 8.65 | K45: 8.61 | L45: 8.75 | M45: 8.65 | N45: 8.79 | O45: 8.78 | P45: 8.88 | Q45: 8.9 | R45: 9.02 | S45: 9 | T45: 8.91 | U45: 8.85 | V45: 8.93 | W45: 8.88 | X45: 8.96 | Y45: 8.87 | Z45: 8.88 | AA45: 8.88 | AB45: 9.01 | AC45: 9.02 | AD45: 9.06 | AE45: 8.89 | AF45: 8.72 | AG45: 8.73 | AH45: 8.84 | AI45: 8.85 | AJ45: 8.8 | AK45: 8.8 | AL45: 8.78 | AM45: 8.78 | AN45: 8.79 | AO45: 8.87 | AP45: 8.86 | AQ45: 8.91 | AR45: 8.76
A46: Axis ELSS Tax Saver Fund | B46: Axis | C46: ELSS | D46: 84.8179 | E46: 84.8148 | F46: 86.0844 | G46: 85.9079 | H46: 87.0296 | I46: 87.5442 | J46: 90.9738 | K46: 90.3255 | L46: 91.7201 | M46: 90.9178 | N46: 92.4074 | O46: 92.5739 | P46: 93.3343 | Q46: 93.5261 | R46: 94.4374 | S46: 94.0714 | T46: 93.4532 | U46: 92.538 | V46: 93.3775 | W46: 92.9957 | X46: 93.3887 | Y46: 92.6954 | Z46: 93.0932 | AA46: 93.1739 | AB46: 94.4895 | AC46: 94.7847 | AD46: 94.3225 | AE46: 92.9582 | AF46: 90.9598 | AG46: 91.0087 | AH46: 92.0254 | AI46: 91.7936 | AJ46: 91.6685 | AK46: 91.7733 | AL46: 92.0602 | AM46: 91.9588 | AN46: 92.2029 | AO46: 93.2104 | AP46: 92.8476 | AQ46: 93.2138 | AR46: 91.7876
A47: Axis ESG Integration Strategy Fund | B47: Axis | C47: SECTORAL / THEMATIC | D47: 18.92 | E47: 18.92 | F47: 19.15 | G47: 19.17 | H47: 19.36 | I47: 19.44 | J47: 20.12 | K47: 20 | L47: 20.25 | M47: 20.09 | N47: 20.37 | O47: 20.39 | P47: 20.58 | Q47: 20.62 | R47: 20.74 | S47: 20.66 | T47: 20.51 | U47: 20.34 | V47: 20.5 | W47: 20.38 | X47: 20.44 | Y47: 20.29 | Z47: 20.37 | AA47: 20.38 | AB47: 20.66 | AC47: 20.76 | AD47: 20.73 | AE47: 20.51 | AF47: 20.11 | AG47: 20.07 | AH47: 20.22 | AI47: 20.27 | AJ47: 20.21 | AK47: 20.25 | AL47: 20.29 | AM47: 20.33 | AN47: 20.39 | AO47: 20.62 | AP47: 20.56 | AQ47: 20.62 | AR47: 20.35
A48: Axis Equity Savings Fund | B48: Axis | C48: EQUITY SAVINGS | D48: 21.72 | E48: 21.72 | F48: 21.82 | G48: 21.81 | H48: 21.87 | I48: 21.94 | J48: 22.24 | K48: 22.18 | L48: 22.29 | M48: 22.25 | N48: 22.39 | O48: 22.39 | P48: 22.45 | Q48: 22.48 | R48: 22.52 | S48: 22.47 | T48: 22.4 | U48: 22.28 | V48: 22.39 | W48: 22.37 | X48: 22.42 | Y48: 22.38 | Z48: 22.45 | AA48: 22.45 | AB48: 22.55 | AC48: 22.58 | AD48: 22.53 | AE48: 22.44 | AF48: 22.28 | AG48: 22.28 | AH48: 22.38 | AI48: 22.35 | AJ48: 22.33 | AK48: 22.35 | AL48: 22.36 | AM48: 22.35 | AN48: 22.38 | AO48: 22.5 | AP48: 22.48 | AQ48: 22.48 | AR48: 22.37
A49: Axis Flexi Cap Fund | B49: Axis | C49: FLEXI CAP | D49: 23.44 | E49: 23.44 | F49: 23.85 | G49: 23.87 | H49: 24.22 | I49: 24.34 | J49: 25.3 | K49: 25.18 | L49: 25.62 | M49: 25.44 | N49: 25.78 | O49: 25.86 | P49: 26.06 | Q49: 26.15 | R49: 26.36 | S49: 26.37 | T49: 26.24 | U49: 26.01 | V49: 26.14 | W49: 25.93 | X49: 25.98 | Y49: 25.77 | Z49: 25.92 | AA49: 26 | AB49: 26.41 | AC49: 26.56 | AD49: 26.45 | AE49: 26.1 | AF49: 25.46 | AG49: 25.51 | AH49: 25.74 | AI49: 25.67 | AJ49: 25.55 | AK49: 25.62 | AL49: 25.78 | AM49: 25.88 | AN49: 25.95 | AO49: 26.21 | AP49: 26.15 | AQ49: 26.35 | AR49: 25.98
A50: Axis Focused Fund | B50: Axis | C50: FOCUSED | D50: 46.94 | E50: 46.94 | F50: 47.57 | G50: 47.51 | H50: 48.12 | I50: 48.36 | J50: 50.13 | K50: 49.81 | L50: 50.63 | M50: 50.06 | N50: 50.82 | O50: 51.04 | P50: 51.51 | Q50: 51.79 | R50: 52.26 | S50: 52.14 | T50: 51.98 | U50: 51.58 | V50: 51.85 | W50: 51.49 | X50: 51.64 | Y50: 51.28 | Z50: 51.61 | AA50: 51.67 | AB50: 52.39 | AC50: 52.52 | AD50: 52.36 | AE50: 51.5 | AF50: 50.48 | AG50: 50.4 | AH50: 51.01 | AI50: 50.82 | AJ50: 50.7 | AK50: 50.76 | AL50: 51.04 | AM50: 51.1 | AN50: 51.29 | AO50: 51.72 | AP50: 51.54 | AQ50: 51.95 | AR50: 51.09
A51: Axis India Manufacturing Fund | B51: Axis | C51: SECTORAL / THEMATIC | D51: 13.14 | E51: 13.14 | F51: 13.35 | G51: 13.3 | H51: 13.36 | I51: 13.42 | J51: 13.86 | K51: 13.91 | L51: 14.14 | M51: 14.03 | N51: 14.28 | O51: 14.36 | P51: 14.51 | Q51: 14.52 | R51: 14.55 | S51: 14.6 | T51: 14.53 | U51: 14.4 | V51: 14.64 | W51: 14.62 | X51: 14.71 | Y51: 14.6 | Z51: 14.73 | AA51: 14.78 | AB51: 14.94 | AC51: 15.12 | AD51: 15.1 | AE51: 14.94 | AF51: 14.62 | AG51: 14.71 | AH51: 14.81 | AI51: 14.71 | AJ51: 14.59 | AK51: 14.63 | AL51: 14.75 | AM51: 14.87 | AN51: 14.86 | AO51: 14.97 | AP51: 14.99 | AQ51: 15.22 | AR51: 15.04
A52: Axis Innovation Fund | B52: Axis | C52: SECTORAL / THEMATIC | D52: 16.63 | E52: 16.73 | F52: 17.09 | G52: 17.03 | H52: 17.18 | I52: 17.18 | J52: 17.83 | K52: 17.85 | L52: 18.19 | M52: 18.13 | N52: 18.53 | O52: 18.64 | P52: 18.78 | Q52: 18.77 | R52: 18.99 | S52: 19.15 | T52: 19.01 | U52: 18.92 | V52: 19.09 | W52: 19.03 | X52: 18.99 | Y52: 18.97 | Z52: 19.19 | AA52: 19.13 | AB52: 19.31 | AC52: 19.41 | AD52: 19.44 | AE52: 19.21 | AF52: 18.71 | AG52: 18.79 | AH52: 18.94 | AI52: 18.81 | AJ52: 18.67 | AK52: 18.65 | AL52: 18.79 | AM52: 18.8 | AN52: 18.79 | AO52: 18.87 | AP52: 19.01 | AQ52: 19.13 | AR52: 18.96
A53: Axis Large & Mid Cap Fund | B53: Axis | C53: LARGE & MID CAP | D53: 29.47 | E53: 29.53 | F53: 30.08 | G53: 30.04 | H53: 30.44 | I53: 30.56 | J53: 31.7 | K53: 31.59 | L53: 32.02 | M53: 31.87 | N53: 32.42 | O53: 32.44 | P53: 32.74 | Q53: 32.77 | R53: 33.01 | S53: 32.96 | T53: 32.81 | U53: 32.59 | V53: 32.96 | W53: 32.82 | X53: 32.94 | Y53: 32.74 | Z53: 32.85 | AA53: 32.88 | AB53: 33.42 | AC53: 33.55 | AD53: 33.49 | AE53: 33.12 | AF53: 32.4 | AG53: 32.45 | AH53: 32.87 | AI53: 32.75 | AJ53: 32.74 | AK53: 32.81 | AL53: 33.02 | AM53: 33.01 | AN53: 33.1 | AO53: 33.38 | AP53: 33.41 | AQ53: 33.57 | AR53: 33.15
A54: Axis Large Cap Fund | B54: Axis | C54: LARGE CAP | D54: 53.79 | E54: 53.78 | F54: 54.53 | G54: 54.54 | H54: 55.2 | I54: 55.47 | J54: 57.63 | K54: 57.02 | L54: 57.74 | M54: 57.3 | N54: 58.18 | O54: 58.14 | P54: 58.49 | Q54: 58.54 | R54: 59.05 | S54: 58.67 | T54: 58.1 | U54: 57.51 | V54: 57.92 | W54: 57.61 | X54: 57.92 | Y54: 57.49 | Z54: 57.7 | AA54: 57.64 | AB54: 58.43 | AC54: 58.53 | AD54: 58.24 | AE54: 57.36 | AF54: 56.29 | AG54: 56.29 | AH54: 56.95 | AI54: 56.86 | AJ54: 56.87 | AK54: 56.81 | AL54: 56.88 | AM54: 56.91 | AN54: 57.12 | AO54: 57.85 | AP54: 57.53 | AQ54: 57.67 | AR54: 56.91
A55: Axis Midcap Fund | B55: Axis | C55: MID CAP | D55: 102.63 | E55: 102.63 | F55: 104.28 | G55: 103.98 | H55: 105.35 | I55: 105.79 | J55: 109.5 | K55: 109.65 | L55: 111.43 | M55: 110.73 | N55: 112.63 | O55: 113.06 | P55: 114.2 | Q55: 114.54 | R55: 115.26 | S55: 115.44 | T55: 115.24 | U55: 114.26 | V55: 115.55 | W55: 115.34 | X55: 115.21 | Y55: 114.39 | Z55: 115.08 | AA55: 115.28 | AB55: 117.01 | AC55: 117.94 | AD55: 117.72 | AE55: 116.57 | AF55: 113.71 | AG55: 113.87 | AH55: 115.1 | AI55: 114.93 | AJ55: 114.82 | AK55: 115.54 | AL55: 116.29 | AM55: 116.29 | AN55: 116.24 | AO55: 117.06 | AP55: 117.3 | AQ55: 117.95 | AR55: 116.21
A56: Axis Momentum Fund | B56: Axis | C56: SECTORAL / THEMATIC | D56: 8.03 | E56: 8.03 | F56: 8.24 | G56: 8.22 | H56: 8.38 | I56: 8.38 | J56: 8.73 | K56: 8.74 | L56: 8.88 | M56: 8.8 | N56: 8.96 | O56: 9 | P56: 9.07 | Q56: 9.06 | R56: 9.07 | S56: 9.04 | T56: 8.98 | U56: 8.92 | V56: 8.97 | W56: 8.96 | X56: 8.98 | Y56: 8.9 | Z56: 8.92 | AA56: 8.89 | AB56: 8.98 | AC56: 8.99 | AD56: 8.93 | AE56: 8.83 | AF56: 8.68 | AG56: 8.73 | AH56: 8.8 | AI56: 8.76 | AJ56: 8.74 | AK56: 8.75 | AL56: 8.77 | AM56: 8.8 | AN56: 8.81 | AO56: 8.88 | AP56: 8.84 | AQ56: 8.88 | AR56: 8.7
...

Sheet Daily AUM
A1: Scheme Name | B1: Fund Name | C1: Category | D1: 46111 | E1: 46112 | F1: 46113 | G1: 46114 | H1: 46118 | I1: 46119 | J1: 46120 | K1: 46121 | L1: 46122 | M1: 46125 | N1: 46127 | O1: 46128 | P1: 46129 | Q1: 46132 | R1: 46133 | S1: 46134 | T1: 46135 | U1: 46136 | V1: 46139 | W1: 46140 | X1: 46141 | Y1: 46142 | Z1: 46146 | AA1: 46147 | AB1: 46148 | AC1: 46149 | AD1: 46150 | AE1: 46153 | AF1: 46154 | AG1: 46155 | AH1: 46156 | AI1: 46157 | AJ1: 46160 | AK1: 46161 | AL1: 46162 | AM1: 46163 | AN1: 46164 | AO1: 46167 | AP1: 46168 | AQ1: 46169 | AR1: 46171
A2: 360 ONE Balanced Hybrid Fund | B2: 360 ONE | C2: BALANCED HYBRID | D2: 714.69 | E2: 714.69 | G2: 720.06 | H2: 721.73 | I2: 722.91 | J2: 738.41 | K2: 736.71 | L2: 742.45 | M2: 732.63 | N2: 738.81 | O2: 738.23 | P2: 742.04 | Q2: 741.66 | R2: 743.69 | S2: 741.46 | T2: 738.09 | U2: 734.8 | V2: 738.25 | W2: 737.08 | X2: 739.26 | Y2: 734.47 | Z2: 737.88 | AA2: 738.75 | AB2: 745.19 | AC2: 748.32 | AD2: 746.37 | AE2: 741.47 | AF2: 732.36 | AG2: 732.81 | AH2: 735.95 | AI2: 734.75 | AJ2: 733.17 | AK2: 731.02 | AL2: 728.41 | AM2: 728.09 | AN2: 728.09 | AO2: 734.28 | AP2: 733.79 | AQ2: 734.62 | AR2: 732.07
A3: 360 ONE Flexicap Fund | B3: 360 ONE | C3: FLEXI CAP | D3: 1789.32 | E3: 1789.32 | F3: 1824.56 | G3: 1824.2 | H3: 1848.75 | I3: 1863.89 | J3: 1944.2 | K3: 1936.11 | L3: 1968.69 | M3: 1955.21 | N3: 1991.61 | O3: 1998.38 | P3: 2018.63 | Q3: 2014.95 | R3: 2029.47 | S3: 2021.08 | T3: 2006.88 | U3: 1992.26 | V3: 2006.8 | W3: 2002.69 | X3: 2015.75 | Y3: 1993.89 | Z3: 2008.11 | AA3: 2010.87 | AB3: 2043.85 | AC3: 2060.9 | AD3: 2054.14 | AE3: 2027.87 | AF3: 1980.54 | AG3: 1986.17 | AH3: 2004.1 | AI3: 2006.69 | AJ3: 2000.79 | AK3: 2008.43 | AL3: 2017.98 | AM3: 2014.49 | AN3: 2014.49 | AO3: 2046.94 | AP3: 2044.41 | AQ3: 2058.6 | AR3: 2042.92
A4: 360 ONE Focused Fund | B4: 360 ONE | C4: FOCUSED | D4: 6057.57 | E4: 6057.57 | F4: 6167.75 | G4: 6150.24 | H4: 6216.69 | I4: 6259.36 | J4: 6545.4 | K4: 6494.99 | L4: 6593.64 | M4: 6525.18 | N4: 6612.62 | O4: 6622.69 | P4: 6662.53 | Q4: 6656.14 | R4: 6717 | S4: 6673.4 | T4: 6624.59 | U4: 6577.17 | V4: 6598.66 | W4: 6577.37 | X4: 6607.18 | Y4: 6537.1 | Z4: 6579.4 | AA4: 6561.61 | AB4: 6662.93 | AC4: 6698.44 | AD4: 6684.43 | AE4: 6569.65 | AF4: 6400.81 | AG4: 6423.14 | AH4: 6497.26 | AI4: 6499.61 | AJ4: 6497.76 | AK4: 6507.99 | AL4: 6531.29 | AM4: 6535.6 | AN4: 6535.6 | AO4: 6621.1 | AP4: 6604.19 | AQ4: 6663.06 | AR4: 6584.77
A5: 360 ONE Multi Asset Allocation Fund | B5: 360 ONE | C5: MULTI ASSET ALLOCATION | D5: 387.47 | E5: 387.47 | G5: 389.26 | H5: 394.28 | I5: 396.93 | J5: 405.78 | K5: 404.07 | L5: 409.56 | M5: 409.28 | N5: 413.42 | O5: 414.68 | P5: 416.28 | Q5: 414.02 | R5: 416.81 | S5: 416.81 | T5: 415.91 | U5: 425.3 | V5: 428.87 | W5: 428.8 | X5: 429.53 | Y5: 430.57 | Z5: 432.26 | AA5: 432.72 | AB5: 438 | AC5: 439.58 | AD5: 438.74 | AE5: 436.03 | AF5: 436.51 | AG5: 443.49 | AH5: 446.8 | AI5: 444.84 | AJ5: 445.68 | AK5: 448.67 | AL5: 448.89 | AM5: 449.71 | AN5: 449.71 | AO5: 454.11 | AP5: 453.9 | AQ5: 455.05 | AR5: 454.17
A6: 360 ONE Quant Fund | B6: 360 ONE | C6: SECTORAL / THEMATIC | D6: 806.72 | E6: 806.72 | F6: 817.67 | G6: 812.33 | H6: 823.55 | I6: 829.12 | J6: 870.43 | K6: 868.74 | L6: 886.32 | M6: 874.05 | N6: 891.39 | O6: 892.91 | P6: 900.64 | Q6: 899.22 | R6: 901.79 | S6: 899.27 | T6: 889.32 | U6: 883.36 | V6: 891.47 | W6: 886.55 | X6: 890.59 | Y6: 879.56 | Z6: 887.27 | AA6: 890.69 | AB6: 908.82 | AC6: 915.88 | AD6: 913.58 | AE6: 884.08 | AF6: 864.86 | AG6: 868.35 | AH6: 877.39 | AI6: 873.57 | AJ6: 868.44 | AK6: 863.35 | AL6: 859.24 | AM6: 860.93 | AN6: 860.93 | AO6: 872.87 | AP6: 871.66 | AQ6: 878.29 | AR6: 862.77
A7: Abakkus Flexi Cap Fund | B7: Abakkus | C7: FLEXI CAP | D7: 3124.465 | E7: 3140.6846 | F7: 3205.6282 | G7: 3207.2637 | H7: 3264.424 | I7: 3308.8987 | J7: 3435.146 | K7: 3453.838 | L7: 3539.0803 | M7: 3540.355 | N7: 3618.4153 | O7: 3647.2776 | P7: 3700.2324 | Q7: 3743.2783 | R7: 3800.9927 | S7: 3828.7588 | T7: 3824.6118 | U7: 3808.3 | V7: 3880.358 | W7: 3894.4932 | X7: 3924.9512 | Y7: 3901.185 | Z7: 4179.3433 | AA7: 4178.858 | AB7: 4266.236 | AC7: 4314.709 | AD7: 4310.3765 | AE7: 4271.224 | AF7: 4198.735 | AG7: 4236.5464 | AH7: 4275.798 | AI7: 4314.742 | AJ7: 4311.1035 | AK7: 4350.541 | AL7: 4396.007 | AM7: 4426.394 | AN7: 4426.394 | AO7: 4566.509 | AP7: 4573.8657 | AQ7: 4608.777 | AR7: 4595.9463
A8: Abakkus Small Cap Fund | B8: Abakkus | C8: SMALL CAP | D8: 442.1605 | E8: 453.3766 | F8: 460.7434 | G8: 466.1826 | H8: 481.2368 | I8: 495.7582 | J8: 518.9619 | K8: 535.3229 | L8: 564.1524 | M8: 579.0963 | N8: 606.6468 | O8: 631.4845 | P8: 651.4239 | Q8: 667.4582 | R8: 698.0518 | S8: 716.7818 | T8: 724.6415 | U8: 734.55 | V8: 756.9808 | W8: 768.4932 | X8: 785.2932 | Y8: 816.7575 | Z8: 837.4553 | AA8: 857.3814 | AB8: 877.7815 | AC8: 899.0356 | AD8: 908.7972 | AE8: 910.3614 | AF8: 907.7453 | AG8: 919.9828 | AH8: 938.0538 | AI8: 951.5583 | AJ8: 956.3951 | AK8: 973.1456 | AL8: 988.0453 | AM8: 1005.9785 | AN8: 1005.9785 | AO8: 1039.1243 | AP8: 1051.8866 | AQ8: 1065.6925 | AR8: 1073.7545
A9: Aditya Birla Sun Life Arbitrage Fund | B9: Aditya Birla Sun Life | C9: ARBITRAGE | D9: 24864.025 | E9: 25064.553 | F9: 25049.188 | G9: 25019.309 | H9: 25149.37 | I9: 25144.477 | J9: 25140.443 | K9: 25306.627 | L9: 25507.2 | M9: 25315.344 | N9: 25154.703 | O9: 25195.072 | P9: 25264.504 | Q9: 25330.47 | R9: 25331.506 | S9: 25344.332 | T9: 25278.137 | U9: 25358.955 | V9: 25561.94 | W9: 25531.799 | X9: 25548.604 | Y9: 25678.504 | Z9: 25785.06 | AA9: 25766.172 | AB9: 25621.975 | AC9: 25698.887 | AD9: 25715.129 | AE9: 25727.838 | AF9: 25779.19 | AG9: 25784.854 | AH9: 25774.328 | AI9: 25848.246 | AJ9: 26083.916 | AK9: 26092.64 | AL9: 26175.094 | AM9: 26177.346 | AN9: 26137.12 | AO9: 26176.135 | AP9: 26027.951 | AQ9: 26011.266 | AR9: 26059.46
A10: Aditya Birla Sun Life Balanced Advantage Fund | B10: Aditya Birla Sun Life | C10: DYNAMIC ASSET ALLOCATION OR BALANCED ADVANTAGE | D10: 8532.136 | E10: 8539.877 | F10: 8636.936 | G10: 8627.432 | H10: 8701.606 | I10: 8729.112 | J10: 8948.255 | K10: 8931.775 | L10: 9050.222 | M10: 9024.955 | N10: 9134.521 | O10: 9137.024 | P10: 9227.855 | Q10: 9237.995 | R10: 9291.296 | S10: 9282.333 | T10: 9228.756 | U10: 9146.053 | V10: 9229.636 | W10: 9210.793 | X10: 9219.283 | Y10: 9182.391 | Z10: 9222.99 | AA10: 9219.533 | AB10: 9293.199 | AC10: 9318.613 | AD10: 9298.444 | AE10: 9230.484 | AF10: 9096.755 | AG10: 9128.904 | AH10: 9183.16 | AI10: 9171.015 | AJ10: 9161.602 | AK10: 9192.669 | AL10: 9192.735 | AM10: 9181.828 | AN10: 9209.405 | AO10: 9284.715 | AP10: 9291.7 | AQ10: 9304.154 | AR10: 9250.3125
A11: Aditya Birla Sun Life Banking & Financial Services Fund | B11: Aditya Birla Sun Life | C11: SECTORAL / THEMATIC | D11: 3155.414 | E11: 3154.8567 | F11: 3224.997 | G11: 3228.6257 | H11: 3303.5168 | I11: 3313.4067 | J11: 3504.21 | K11: 3464.643 | L11: 3534.3262 | M11: 3514.6343 | N11: 3562.5688 | O11: 3572.719 | P11: 3604.233 | Q11: 3610.4841 | R11: 3678.9583 | S11: 3664.0698 | T11: 3622.5095 | U11: 3610.0747 | V11: 3600.4421 | W11: 3565.2349 | X11: 3573.1716 | Y11: 3541.0872 | Z11: 3561.4253 | AA11: 3555.613 | AB11: 3631.6838 | AC11: 3641.0613 | AD11: 3597.4587 | AE11: 3544.1648 | AF11: 3460.3357 | AG11: 3454.5916 | AH11: 3489.2483 | AI11: 3475.7927 | AJ11: 3458.772 | AK11: 3458.3687 | AL11: 3457.5464 | AM11: 3448.5334 | AN11: 3475.8389 | AO11: 3544.2056 | AP11: 3532.4963 | AQ11: 3516.9424 | AR11: 3466.1643
A12: Aditya Birla Sun Life Business Cycle Fund | B12: Aditya Birla Sun Life | C12: SECTORAL / THEMATIC | D12: 1541.9215 | E12: 1540.4275 | F12: 1568.7871 | G12: 1567.0724 | H12: 1587.5558 | I12: 1594.287 | J12: 1655.9078 | K12: 1646.936 | L12: 1674.8918 | M12: 1669.3259 | N12: 1696.6942 | O12: 1700.7206 | P12: 1718.3027 | Q12: 1720.6064 | R12: 1736.8901 | S12: 1731.1495 | T12: 1713.8689 | U12: 1693.8441 | V12: 1711.313 | W12: 1699.9368 | X12: 1699.0259 | Y12: 1687.282 | Z12: 1701.9218 | AA12: 1697.0967 | AB12: 1717.0604 | AC12: 1727.6213 | AD12: 1717.2588 | AE12: 1694.997 | AF12: 1655.8811 | AG12: 1656.2449 | AH12: 1669.5868 | AI12: 1658.4622 | AJ12: 1651.3412 | AK12: 1663.7284 | AL12: 1663.502 | AM12: 1667.2407 | AN12: 1668.3589 | AO12: 1688.0278 | AP12: 1689.5236 | AQ12: 1694.9678 | AR12: 1684.1193
A13: Aditya Birla Sun Life Conglomerate Fund | B13: Aditya Birla Sun Life | C13: SECTORAL / THEMATIC | D13: 1438.5851 | E13: 1437.6033 | F13: 1474.5978 | G13: 1475.9995 | H13: 1488.6349 | I13: 1493.7084 | J13: 1556.449 | K13: 1547.7166 | L13: 1572.8307 | M13: 1560.2872 | N13: 1595.6292 | O13: 1608.8251 | P13: 1619.5615 | Q13: 1611.2615 | R13: 1621.7054 | S13: 1624.6483 | T13: 1613.2097 | U13: 1592.4159 | V13: 1618.273 | W13: 1623.577 | X13: 1637.5641 | Y13: 1622.5085 | Z13: 1640.5773 | AA13: 1639.0851 | AB13: 1658.9846 | AC13: 1659.0302 | AD13: 1655.2567 | AE13: 1631.5358 | AF13: 1590.5002 | AG13: 1600.6653 | AH13: 1609.4176 | AI13: 1596.6516 | AJ13: 1591.3606 | AK13: 1596.134 | AL13: 1603.9608 | AM13: 1604.7645 | AN13: 1607.0328 | AO13: 1629.0317 | AP13: 1633.1586 | AQ13: 1642.7664 | AR13: 1625.4442
A14: Aditya Birla Sun Life Consumption Fund | B14: Aditya Birla Sun Life | C14: SECTORAL / THEMATIC | D14: 5480.929 | E14: 5477.9106 | F14: 5576.2886 | G14: 5569.918 | H14: 5651.579 | I14: 5660.44 | J14: 5861.0474 | K14: 5833.31 | L14: 5922.6577 | M14: 5871.999 | N14: 5972.099 | O14: 5977.1416 | P14: 6043.236 | Q14: 6052.0703 | R14: 6125.7285 | S14: 6131.3335 | T14: 6068.989 | U14: 6012.4224 | V14: 6055.2383 | W14: 6019.2456 | X14: 6056.563 | Y14: 5996.2676 | Z14: 6021.1006 | AA14: 6003.3296 | AB14: 6078.642 | AC14: 6083.2886 | AD14: 6076.369 | AE14: 5990.027 | AF14: 5865.9214 | AG14: 5872.9688 | AH14: 5934.9053 | AI14: 5928.3037 | AJ14: 5910.378 | AK14: 5911.4043 | AL14: 5892.197 | AM14: 5890.1665 | AN14: 5910.182 | AO14: 5944.611 | AP14: 5926.4795 | AQ14: 5936.96 | AR14: 5844.728
A15: Aditya Birla Sun Life Digital India Fund | B15: Aditya Birla Sun Life | C15: SECTORAL / THEMATIC | D15: 3593.2747 | E15: 3589.8882 | F15: 3673.159 | G15: 3745.497 | H15: 3767.509 | I15: 3826.106 | J15: 3891.6035 | K15: 3893.9753 | L15: 3867.9963 | M15: 3841.7585 | N15: 3942.2522 | O15: 3990.199 | P15: 4001.7427 | Q15: 3975.2869 | R15: 3998.0608 | S15: 3923.0273 | T15: 3880.0706 | U15: 3737.4277 | V15: 3785.4385 | W15: 3769.6272 | X15: 3800.7056 | Y15: 3798.7854 | Z15: 3778.8892 | AA15: 3775.4983 | AB15: 3838.9475 | AC15: 3824.2126 | AD15: 3880.5464 | AE15: 3842.0874 | AF15: 3721.1267 | AG15: 3695.4111 | AH15: 3677.6106 | AI15: 3698.9722 | AJ15: 3758.0093 | AK15: 3848.6155 | AL15: 3825.1545 | AM15: 3802.3906 | AN15: 3800.001 | AO15: 3830.7874 | AP15: 3834.1313 | AQ15: 3827.9036 | AR15: 3819.5312
A16: Aditya Birla Sun Life Dividend Yield Fund | B16: Aditya Birla Sun Life | C16: DIVIDEND YIELD | D16: 1338.5585 | E16: 1338.9503 | F16: 1367.7981 | G16: 1369.8768 | H16: 1392.0577 | I16: 1401.6936 | J16: 1437.4338 | K16: 1440.6587 | L16: 1450.0544 | M16: 1447.5452 | N16: 1471.2201 | O16: 1474.571 | P16: 1491.4149 | Q16: 1492.0145 | R16: 1503.3973 | S16: 1495.7905 | T16: 1482.9647 | U16: 1465.1924 | V16: 1477.7389 | W16: 1472.0973 | X16: 1485.593 | Y16: 1475.1729 | Z16: 1477.9335 | AA16: 1477.8564 | AB16: 1498.8652 | AC16: 1501.8706 | AD16: 1496.0142 | AE16: 1481.7793 | AF16: 1456.2877 | AG16: 1461.6943 | AH16: 1468.7756 | AI16: 1468.244 | AJ16: 1461.2421 | AK16: 1475.537 | AL16: 1473.9586 | AM16: 1467.9651 | AN16: 1465.223 | AO16: 1480.6154 | AP16: 1478.5658 | AQ16: 1479.4829 | AR16: 1459.1869
A17: Aditya Birla Sun Life ELSS Tax Saver Fund | B17: Aditya Birla Sun Life | C17: ELSS | D17: 13126.825 | E17: 13117.288 | F17: 13411.292 | G17: 13398.838 | H17: 13570.04 | I17: 13641.816 | J17: 14141.59 | K17: 14064.438 | L17: 14256.553 | M17: 14167.586 | N17: 14403.001 | O17: 14428.905 | P17: 14564.289 | Q17: 14557.483 | R17: 14688.928 | S17: 14663.643 | T17: 14530.485 | U17: 14357.072 | V17: 14506.875 | W17: 14428.99 | X17: 14490.44 | Y17: 14378.229 | Z17: 14523.418 | AA17: 14498.031 | AB17: 14686.84 | AC17: 14707.705 | AD17: 14613.802 | AE17: 14376.779 | AF17: 14077.728 | AG17: 14094.105 | AH17: 14217.24 | AI17: 14189.281 | AJ17: 14156.932 | AK17: 14189.089 | AL17: 14219.024 | AM17: 14193.626 | AN17: 14236.966 | AO17: 14412.295 | AP17: 14377.255 | AQ17: 14433.757 | AR17: 14253.906
... A34: Aditya Birla Sun Life Quant Fund | B34: Aditya Birla Sun Life | C34: SECTORAL / THEMATIC | D34: 1868.6692 | E34: 1867.5317 | F34: 1894.1735 | G34: 1886.9379 | H34: 1916.5131 | I34: 1929.1764 | J34: 2013.5669 | K34: 2010.9996 | L34: 2043.9825 | M34: 2023.8503 | N34: 2052.767 | O34: 2053.6045 | P34: 2071.1323 | Q34: 2079.2349 | R34: 2080.451 | S34: 2071.996 | T34: 2051.312 | U34: 2036.7866 | V34: 2061.533 | W34: 2048.3792 | X34: 2050.1304 | Y34: 2027.0596 | Z34: 2039.5048 | AA34: 2044.5768 | AB34: 2072.5618 | AC34: 2090.291 | AD34: 2079.9502 | AE34: 2060.7104 | AF34: 2026.023 | AG34: 2031.7853 | AH34: 2054.2224 | AI34: 2041.341 | AJ34: 2026.0406 | AK34: 2031.7429 | AL34: 2040.8688 | AM34: 2043.3179 | AN34: 2046.5145 | AO34: 2075.4724 | AP34: 2069.543 | AQ34: 2078.939 | AR34: 2046.6152
A35: Aditya Birla Sun Life Regular Savings Fund | B35: Aditya Birla Sun Life | C35: CONSERVATIVE HYRBID | D35: 1457.4606 | E35: 1455.9271 | G35: 1457.5641 | H35: 1457.2861 | I35: 1459.2848 | J35: 1472.6641 | K35: 1472.3032 | L35: 1477.8148 | M35: 1476.5625 | N35: 1485.4645 | O35: 1484.9924 | P35: 1487.431 | Q35: 1488.3934 | R35: 1490.3629 | S35: 1487.5835 | T35: 1483.7313 | U35: 1480.5359 | V35: 1485.4629 | W35: 1483.3687 | X35: 1482.7213 | Y35: 1479.2755 | Z35: 1482.9631 | AA35: 1481.3405 | AB35: 1487.9635 | AC35: 1490.1614 | AD35: 1485.4065 | AE35: 1480.9194 | AF35: 1474.3639 | AG35: 1474.0963 | AH35: 1477.4717 | AI35: 1474.8047 | AJ35: 1470.52 | AK35: 1470.4421 | AL35: 1471.1711 | AM35: 1470.1178 | AN35: 1470.554 | AO35: 1476.3367 | AP35: 1477.0914 | AQ35: 1477.5615 | AR35: 1473.9827
A36: Aditya Birla Sun Life Small cap Fund | B36: Aditya Birla Sun Life | C36: SMALL CAP | D36: 4447.294 | E36: 4449.155 | F36: 4561.1445 | G36: 4553.9717 | H36: 4626.4824 | I36: 4630.805 | J36: 4795.472 | K36: 4809.903 | L36: 4879.7563 | M36: 4865.624 | N36: 4948.379 | O36: 5001.398 | P36: 5072.3687 | Q36: 5088.778 | R36: 5141.387 | S36: 5190.7607 | T36: 5181.736 | U36: 5164.0586 | V36: 5244.239 | W36: 5239.288 | X36: 5271.4644 | Y36: 5253.496 | Z36: 5339.01 | AA36: 5319.448 | AB36: 5391.172 | AC36: 5479.7915 | AD36: 5478.9634 | AE36: 5421.115 | AF36: 5287.3223 | AG36: 5299.349 | AH36: 5343.22 | AI36: 5351.095 | AJ36: 5298.9663 | AK36: 5364.915 | AL36: 5376.0156 | AM36: 5401.7876 | AN36: 5391.4233 | AO36: 5463.4233 | AP36: 5482.5356 | AQ36: 5477.251 | AR36: 5450.2446
A37: Aditya Birla Sun Life Special Opportunities Fund | B37: Aditya Birla Sun Life | C37: SECTORAL / THEMATIC | D37: 889.7754 | E37: 890.118 | F37: 906.2483 | G37: 906.1972 | H37: 920.4597 | I37: 931.8195 | J37: 966.1865 | K37: 966.3132 | L37: 981.0853 | M37: 979.6625 | N37: 998.6684 | O37: 1002.9356 | P37: 1014.2393 | Q37: 1016.6697 | R37: 1029.8871 | S37: 1029.6122 | T37: 1022.9605 | U37: 1021.3895 | V37: 1032.4897 | W37: 1029.7994 | X37: 1038.0173 | Y37: 1030.2155 | Z37: 1039.4563 | AA37: 1040.6731 | AB37: 1055.703 | AC37: 1060.8655 | AD37: 1060.3416 | AE37: 1048.8494 | AF37: 1030.9355 | AG37: 1036.2495 | AH37: 1046.9926 | AI37: 1046.1637 | AJ37: 1043.3342 | AK37: 1049.3854 | AL37: 1050.6312 | AM37: 1048.912 | AN37: 1053.2294 | AO37: 1068.9751 | AP37: 1071.8235 | AQ37: 1074.5415 | AR37: 1071.6044
A38: Aditya Birla Sun Life Transportation and Logistics Fund | B38: Aditya Birla Sun Life | C38: SECTORAL / THEMATIC | D38: 1320.1431 | E38: 1319.6266 | F38: 1351.8254 | G38: 1341.9265 | H38: 1358.2604 | I38: 1358.9147 | J38: 1436.591 | K38: 1427.2285 | L38: 1460.2935 | M38: 1433.2325 | N38: 1461.424 | O38: 1466.0767 | P38: 1475.6964 | Q38: 1478.33 | R38: 1487.4707 | S38: 1492.4689 | T38: 1464.7446 | U38: 1448.4761 | V38: 1473.4327 | W38: 1459.434 | X38: 1463.7406 | Y38: 1454.7826 | Z38: 1466.3802 | AA38: 1468.4465 | AB38: 1500.7216 | AC38: 1523.7228 | AD38: 1525.9578 | AE38: 1495.7405 | AF38: 1456.695 | AG38: 1451.5304 | AH38: 1457.8181 | AI38: 1455.9324 | AJ38: 1439.0728 | AK38: 1447.8071 | AL38: 1453.3717 | AM38: 1469.1559 | AN38: 1473.1099 | AO38: 1493.4436 | AP38: 1493.8411 | AQ38: 1516.6447 | AR38: 1492.327
A39: Aditya Birla Sun Life Value Fund | B39: Aditya Birla Sun Life | C39: VALUE | D39: 5637.185 | E39: 5638.6396 | F39: 5758.001 | G39: 5766.8887 | H39: 5843.3086 | I39: 5878.17 | J39: 6101.6597 | K39: 6097.414 | L39: 6169.4736 | M39: 6157.743 | N39: 6284.617 | O39: 6321.919 | P39: 6401.2104 | Q39: 6403.5737 | R39: 6454.105 | S39: 6460.789 | T39: 6435.444 | U39: 6351.11 | V39: 6424.3887 | W39: 6403.9517 | X39: 6430.9683 | Y39: 6387.7773 | Z39: 6443.055 | AA39: 6435.558 | AB39: 6530.2944 | AC39: 6577.264 | AD39: 6582.2007 | AE39: 6517.293 | AF39: 6371.9175 | AG39: 6385.382 | AH39: 6430.2617 | AI39: 6422.923 | AJ39: 6393.818 | AK39: 6446.8413 | AL39: 6450.479 | AM39: 6470.9844 | AN39: 6486.8403 | AO39: 6569.195 | AP39: 6577.854 | AQ39: 6603.403 | AR39: 6528.5845
A40: Axis Aggressive Hybrid Fund | B40: Axis | C40: AGGRESSIVE HYBRID | D40: 1398.6599 | E40: 1376.8906 | F40: 1376.8906 | G40: 1393.1064 | H40: 1394.0502 | I40: 1403.9083 | J40: 1409.0681 | K40: 1447.5709 | L40: 1437.9824 | M40: 1452.2106 | N40: 1439.115 | O40: 1458.8995 | P40: 1459.5027 | Q40: 1467.0125 | R40: 1464.8857 | S40: 1474.685 | T40: 1469.3351 | U40: 1458.9271 | V40: 1447.8384 | W40: 1460.0953 | X40: 1455.2123 | Y40: 1459.2877 | Z40: 1451.4524 | AA40: 1455.6553 | AB40: 1454.5194 | AC40: 1468.844 | AD40: 1470.2604 | AE40: 1465.8002 | AF40: 1449.6697 | AG40: 1424.7821 | AH40: 1425.473 | AI40: 1433.1179 | AJ40: 1430.0543 | AK40: 1426.3195 | AL40: 1429.6478 | AM40: 1430.9685 | AN40: 1433.1302 | AO40: 1435.5 | AP40: 1446.848 | AQ40: 1442.7242 | AR40: 1444.3026
A41: Axis Arbitrage Fund | B41: Axis | C41: ARBITRAGE | D41: 8993.552 | E41: 9022.162 | F41: 9022.69 | G41: 8997.845 | H41: 9045.597 | I41: 9010.49 | J41: 9089.549 | K41: 9106.703 | L41: 9184.397 | M41: 9194.557 | N41: 9195.073 | O41: 9329.495 | P41: 9343.958 | Q41: 9428.797 | R41: 9516.6045 | S41: 9522.236 | T41: 9556.995 | U41: 9570.576 | V41: 9645.193 | W41: 9666.059 | X41: 9657.055 | Y41: 9724.7 | Z41: 9813.865 | AA41: 9777.448 | AB41: 9575.249 | AC41: 9566.68 | AD41: 9675.275 | AE41: 9706.167 | AF41: 9756.704 | AG41: 9736.999 | AH41: 9726.302 | AI41: 9759.434 | AJ41: 9784.336 | AK41: 9795.27 | AL41: 9840.342 | AM41: 9826.266 | AN41: 9880.87 | AO41: 9883.555 | AP41: 9828.964 | AQ41: 9823.84 | AR41: 9832.639
A42: Axis Balanced Advantage Fund | B42: Axis | C42: DYNAMIC ASSET ALLOCATION OR BALANCED ADVANTAGE | D42: 3601.2666 | E42: 3557.3828 | F42: 3557.3828 | G42: 3588.3027 | H42: 3592.9165 | I42: 3616.6958 | J42: 3629.5205 | K42: 3719.9485 | L42: 3699.7073 | M42: 3730.7954 | N42: 3712.7073 | O42: 3757.267 | P42: 3782.084 | Q42: 3800.6536 | R42: 3801.3198 | S42: 3823.534 | T42: 3810.5615 | U42: 3781.5896 | V42: 3756.99 | W42: 3782.1687 | X42: 3770.8506 | Y42: 3781.2778 | Z42: 3764.9807 | AA42: 3775.7014 | AB42: 3776.1592 | AC42: 3814.2043 | AD42: 3818.444 | AE42: 3814.2573 | AF42: 3781.5464 | AG42: 3733.582 | AH42: 3732.4426 | AI42: 3750.0789 | AJ42: 3749.9653 | AK42: 3744.3616 | AL42: 3746.2375 | AM42: 3749.7507 | AN42: 3748.25 | AO42: 3755.144 | AP42: 3783.614 | AQ42: 3774.1643 | AR42: 3778.5586
A43: Axis Business Cycles Fund | B43: Axis | C43: SECTORAL / THEMATIC | D43: 1916.8031 | E43: 1866.7982 | F43: 1866.7947 | G43: 1903.2412 | H43: 1902.23 | I43: 1927.269 | J43: 1935.8317 | K43: 2019.0516 | L43: 2004.3228 | M43: 2038.8971 | N43: 2021.5325 | O43: 2056.1814 | P43: 2062.9124 | Q43: 2081.8616 | R43: 2082.9626 | S43: 2102.5305 | T43: 2100.761 | U43: 2085.322 | V43: 2064.422 | W43: 2087.6135 | X43: 2078.457 | Y43: 2079.4204 | Z43: 2064.754 | AA43: 2079.2725 | AB43: 2081.987 | AC43: 2107.4084 | AD43: 2122.242 | AE43: 2111.5146 | AF43: 2093.1023 | AG43: 2045.1349 | AH43: 2049.443 | AI43: 2073.4348 | AJ43: 2061.6926 | AK43: 2054.956 | AL43: 2056.865 | AM43: 2061.9185 | AN43: 2057.4763 | AO43: 2058.8203 | AP43: 2083.41 | AQ43: 2082.1787 | AR43: 2090.5432
A44: Axis Conservative Hybrid Fund | B44: Axis | C44: CONSERVATIVE HYRBID | D44: 216.5943 | E44: 214.7598 | G44: 214.7806 | H44: 214.5318 | I44: 215.4795 | J44: 215.8494 | K44: 218.0309 | L44: 217.0445 | M44: 217.7156 | N44: 217.7707 | O44: 218.7808 | P44: 218.6336 | Q44: 218.7971 | R44: 219.1506 | S44: 219.5504 | T44: 218.901 | U44: 218.7797 | V44: 218.0263 | W44: 218.2857 | X44: 218.0317 | Y44: 218.2027 | Z44: 217.8159 | AA44: 218.115 | AB44: 218.0756 | AC44: 218.9645 | AD44: 218.9407 | AE44: 218.5522 | AF44: 217.2512 | AG44: 216.3805 | AH44: 216.4981 | AI44: 217.9307 | AJ44: 217.9303 | AK44: 218.0922 | AL44: 218.4068 | AM44: 218.446 | AN44: 218.2345 | AO44: 218.5134 | AP44: 219.2458 | AQ44: 219.1428 | AR44: 218.6055
A45: Axis Consumption Fund | B45: Axis | C45: SECTORAL / THEMATIC | D45: 2698.2793 | E45: 2639.109 | F45: 2639.109 | G45: 2683.197 | H45: 2683.8357 | I45: 2713.6028 | J45: 2722.6846 | K45: 2816.963 | L45: 2803.575 | M45: 2849.622 | N45: 2816.4067 | O45: 2859.7083 | P45: 2855.7722 | Q45: 2886.272 | R45: 2898.1506 | S45: 2934.8936 | T45: 2924.2285 | U45: 2892.4329 | V45: 2870.1406 | W45: 2893.4226 | X45: 2875.5815 | Y45: 2899.6936 | Z45: 2867.571 | AA45: 2868.9248 | AB45: 2854.8782 | AC45: 2894.718 | AD45: 2895.6753 | AE45: 2906.0828 | AF45: 2846.9739 | AG45: 2789.927 | AH45: 2787.3003 | AI45: 2819.1707 | AJ45: 2808.981 | AK45: 2786.5295 | AL45: 2784.6294 | AM45: 2777.2053 | AN45: 2775.3032 | AO45: 2775.5205 | AP45: 2798.0115 | AQ45: 2791.7966 | AR45: 2804.8232
A46: Axis ELSS Tax Saver Fund | B46: Axis | C46: ELSS | D46: 29830.31 | E46: 29076.658 | F46: 29075.783 | G46: 29496.125 | H46: 29432.758 | I46: 29807.426 | J46: 29979.262 | K46: 31143.604 | L46: 30912.969 | M46: 31389.385 | N46: 31100.152 | O46: 31597.355 | P46: 31643.273 | Q46: 31891.2 | R46: 31939.586 | S46: 32233.56 | T46: 32095.707 | U46: 31872.25 | V46: 31549.674 | W46: 31821.525 | X46: 31680.207 | Y46: 31802.008 | Z46: 31554.889 | AA46: 31676.836 | AB46: 31699.883 | AC46: 32137.668 | AD46: 32227.172 | AE46: 32058.139 | AF46: 31583.258 | AG46: 30892.207 | AH46: 30894.54 | AI46: 31228.848 | AJ46: 31143.553 | AK46: 31083.473 | AL46: 31106.09 | AM46: 31195.125 | AN46: 31149.447 | AO46: 31221.902 | AP46: 31545.164 | AQ46: 31409.26 | AR46: 31522.766
A47: Axis ESG Integration Strategy Fund | B47: Axis | C47: SECTORAL / THEMATIC | D47: 1027.5824 | E47: 1006.5715 | F47: 1006.5715 | G47: 1018.0847 | H47: 1019.2322 | I47: 1029.1829 | J47: 1033.4579 | K47: 1069.0396 | L47: 1062.4944 | M47: 1075.6693 | N47: 1066.8676 | O47: 1081.3972 | P47: 1081.8582 | Q47: 1090.9268 | R47: 1092.7399 | S47: 1098.7853 | T47: 1094.0885 | U47: 1085.5181 | V47: 1076.1088 | W47: 1084.2034 | X47: 1077.4297 | Y47: 1079.9004 | Z47: 1071.4512 | AA47: 1075.4489 | AB47: 1076.3446 | AC47: 1090.4624 | AD47: 1095.4255 | AE47: 1093.6333 | AF47: 1082.1807 | AG47: 1060.3287 | AH47: 1057.5543 | AI47: 1064.453 | AJ47: 1066.9786 | AK47: 1063.49 | AL47: 1064.8212 | AM47: 1066.7673 | AN47: 1068.4841 | AO47: 1071.076 | AP47: 1077.7424 | AQ47: 1074.2113 | AR47: 1076.7456
A48: Axis Equity Savings Fund | B48: Axis | C48: EQUITY SAVINGS | D48: 860.7493 | E48: 849.6179 | F48: 849.6179 | G48: 852.833 | H48: 852.046 | I48: 853.6588 | J48: 856.3364 | K48: 868.1183 | L48: 865.8195 | M48: 869.9938 | N48: 869.1621 | O48: 873.5812 | P48: 872.9085 | Q48: 875.4983 | R48: 873.4326 | S48: 874.7238 | T48: 872.8213 | U48: 870.2063 | V48: 865.157 | W48: 868.7195 | X48: 865.5909 | Y48: 867.5102 | Z48: 866.0685 | AA48: 867.8104 | AB48: 868.0897 | AC48: 873.7491 | AD48: 874.1788 | AE48: 871.4419 | AF48: 868.1857 | AG48: 861.8961 | AH48: 861.9258 | AI48: 865.808 | AJ48: 864.5992 | AK48: 861.5236 | AL48: 861.2585 | AM48: 862.9597 | AN48: 862.6876 | AO48: 863.8119 | AP48: 868.5056 | AQ48: 867.0917 | AR48: 867.5176
A49: Axis Flexi Cap Fund | B49: Axis | C49: FLEXI CAP | D49: 11709.303 | E49: 11412.194 | F49: 11412.196 | G49: 11606.803 | H49: 11617.366 | I49: 11792.258 | J49: 11851.655 | K49: 12329.185 | L49: 12269.253 | M49: 12492.517 | N49: 12403.118 | O49: 12571.351 | P49: 12609.188 | Q49: 12703.914 | R49: 12748.273 | S49: 12847.572 | T49: 12849.45 | U49: 12783.084 | V49: 12668.807 | W49: 12731.802 | X49: 12627.965 | Y49: 12647.419 | Z49: 12542.739 | AA49: 12613.118 | AB49: 12656.926 | AC49: 12853.551 | AD49: 12925.511 | AE49: 12868.082 | AF49: 12704.236 | AG49: 12390.733 | AH49: 12412.672 | AI49: 12523.427 | AJ49: 12493.683 | AK49: 12433.071 | AL49: 12462.79 | AM49: 12542.063 | AN49: 12588.765 | AO49: 12620.529 | AP49: 12746.141 | AQ49: 12712.73 | AR49: 12806.75
A50: Axis Focused Fund | B50: Axis | C50: FOCUSED | D50: 10226.178 | E50: 9966.295 | F50: 9966.295 | G50: 10095.49 | H50: 10083.838 | I50: 10214.262 | J50: 10257.896 | K50: 10624.88 | L50: 10553.403 | M50: 10732.178 | N50: 10607.222 | O50: 10768.209 | P50: 10809.785 | Q50: 10904.527 | R50: 10958.261 | S50: 11051.765 | T50: 11020.444 | U50: 10981.56 | V50: 10893.281 | W50: 10945.174 | X50: 10865.102 | Y50: 10870.444 | Z50: 10789.463 | AA50: 10855.412 | AB50: 10868.865 | AC50: 11010.424 | AD50: 11033.858 | AE50: 10995.31 | AF50: 10817.08 | AG50: 10598.642 | AH50: 10577.131 | AI50: 10699.28 | AJ50: 10660.917 | AK50: 10628.207 | AL50: 10635.457 | AM50: 10689.804 | AN50: 10698.531 | AO50: 10731.573 | AP50: 10815.052 | AQ50: 10771.581 | AR50: 10852.226
A51: Axis India Manufacturing Fund | B51: Axis | C51: SECTORAL / THEMATIC | D51: 4754.8286 | E51: 4681.7876 | F51: 4681.7876 | G51: 4754.658 | H51: 4749.6436 | I51: 4773.4067 | J51: 4794.733 | K51: 4949.4604 | L51: 4967.5303 | M51: 5051.6885 | N51: 5011.643 | O51: 5112.122 | P51: 5140.287 | Q51: 5191.7256 | R51: 5194.2393 | S51: 5202.2485 | T51: 5218.482 | U51: 5191.318 | V51: 5143.293 | W51: 5227.2803 | X51: 5215.5005 | Y51: 5245.5347 | Z51: 5203.788 | AA51: 5251.709 | AB51: 5269.2017 | AC51: 5335.382 | AD51: 5398.551 | AE51: 5389.3013 | AF51: 5334.8394 | AG51: 5218.594 | AH51: 5248.9346 | AI51: 5282.017 | AJ51: 5244.7793 | AK51: 5200.123 | AL51: 5212.2993 | AM51: 5254.6543 | AN51: 5295.4956 | AO51: 5290.668 | AP51: 5327.0117 | AQ51: 5330.238 | AR51: 5410.2925
A52: Axis Innovation Fund | B52: Axis | C52: SECTORAL / THEMATIC | D52: 1062.7924 | E52: 1033.3287 | F52: 1039.5626 | G52: 1061.3087 | H52: 1056.7495 | I52: 1066.0767 | J52: 1066.138 | K52: 1106.3783 | L52: 1107.6852 | M52: 1129.153 | N52: 1125.0714 | O52: 1150.2913 | P52: 1156.9888 | Q52: 1165.6001 | R52: 1164.7318 | S52: 1178.255 | T52: 1187.8264 | U52: 1179.0566 | V52: 1173.3776 | W52: 1183.8342 | X52: 1180.0159 | Y52: 1177.5491 | Z52: 1176.5824 | AA52: 1190.0134 | AB52: 1186.4227 | AC52: 1197.6868 | AD52: 1203.9357 | AE52: 1206.0222 | AF52: 1192.1628 | AG52: 1160.8973 | AH52: 1165.7892 | AI52: 1175.0101 | AJ52: 1166.9607 | AK52: 1158.3202 | AL52: 1153.6016 | AM52: 1162.2762 | AN52: 1162.9061 | AO52: 1162.1107 | AP52: 1162.2109 | AQ52: 1170.1667 | AR52: 1177.6273
A53: Axis Large & Mid Cap Fund | B53: Axis | C53: LARGE & MID CAP | D53: 14266.582 | E53: 13945.196 | F53: 13973.884 | G53: 14231.882 | H53: 14221.679 | I53: 14426.284 | J53: 14488.854 | K53: 15030.305 | L53: 14982.67 | M53: 15202.14 | N53: 15135.217 | O53: 15404.27 | P53: 15415.557 | Q53: 15558.69 | R53: 15586.485 | S53: 15700.201 | T53: 15677.369 | U53: 15605.058 | V53: 15501.424 | W53: 15684.069 | X53: 15621.808 | Y53: 15677.494 | Z53: 15606.904 | AA53: 15664.618 | AB53: 15689.518 | AC53: 15947.855 | AD53: 16013.157 | AE53: 15986.736 | AF53: 15824.441 | AG53: 15483.824 | AH53: 15507.658 | AI53: 15726.041 | AJ53: 15677.462 | AK53: 15673.965 | AL53: 15706.463 | AM53: 15812.052 | AN53: 15804.795 | AO53: 15847.153 | AP53: 15986.618 | AQ53: 16001.371 | AR53: 16078.692
A54: Axis Large Cap Fund | B54: Axis | C54: LARGE CAP | D54: 29358.56 | E54: 28663.168 | F54: 28659.938 | G54: 29044.902 | H54: 29056.059 | I54: 29422.826 | J54: 29567.195 | K54: 30710.588 | L54: 30376.568 | M54: 30771.344 | N54: 30515.744 | O54: 30978.787 | P54: 30950.475 | Q54: 31123.62 | R54: 31138.959 | S54: 31396.643 | T54: 31176.637 | U54: 30860.844 | V54: 30534.635 | W54: 30744.543 | X54: 30574.613 | Y54: 30726.023 | Z54: 30488.629 | AA54: 30608.195 | AB54: 30575.54 | AC54: 30989.781 | AD54: 31036.504 | AE54: 30873.83 | AF54: 30408.373 | AG54: 29832.414 | AH54: 29817.508 | AI54: 30155.807 | AJ54: 30109.096 | AK54: 30099.54 | AL54: 30053.068 | AM54: 30082.475 | AN54: 30090.21 | AO54: 30183.299 | AP54: 30550.723 | AQ54: 30367.723 | AR54: 30430.56
A55: Axis Midcap Fund | B55: Axis | C55: MID CAP | D55: 29468.963 | E55: 28833.928 | F55: 28834.754 | G55: 29293.148 | H55: 29241.105 | I55: 29654.96 | J55: 29786.855 | K55: 30835.87 | L55: 30881.633 | M55: 31407.67 | N55: 31213.723 | O55: 31761.916 | P55: 31887.81 | Q55: 32208.082 | R55: 32312.156 | S55: 32513.285 | T55: 32562.244 | U55: 32506.059 | V55: 32228.162 | W55: 32603.285 | X55: 32547.365 | Y55: 32508.025 | Z55: 32278.658 | AA55: 32492.22 | AB55: 32565.406 | AC55: 33057.85 | AD55: 33319.98 | AE55: 33258.18 | AF55: 32955.793 | AG55: 32151.719 | AH55: 32196.207 | AI55: 32538.318 | AJ55: 32504.43 | AK55: 32470.459 | AL55: 32670.676 | AM55: 32890.355 | AN55: 32887.133 | AO55: 32864.746 | AP55: 33093.16 | AQ55: 33158.31 | AR55: 33344.027
A56: Axis Momentum Fund | B56: Axis | C56: SECTORAL / THEMATIC | D56: 945.8029 | E56: 924.0254 | F56: 924.0254 | G56: 947.9885 | H56: 945.8152 | I56: 964.8511 | J56: 964.7966 | K56: 1004.9257 | L56: 1006.8192 | M56: 1023.3619 | N56: 1013.5884 | O56: 1031.7246 | P56: 1035.2981 | Q56: 1042.6993 | R56: 1040.8418 | S56: 1042.3628 | T56: 1038.8263 | U56: 1031.0646 | V56: 1022.0594 | W56: 1027.3279 | X56: 1025.6742 | Y56: 1027.764 | Z56: 1018.3984 | AA56: 1020.1321 | AB56: 1016.4089 | AC56: 1025.1696 | AD56: 1025.9344 | AE56: 1017.7162 | AF56: 1005.6638 | AG56: 986.9648 | AH56: 991.7841 | AI56: 998.5322 | AJ56: 993.2488 | AK56: 987.9865 | AL56: 988.6104 | AM56: 990.1542 | AN56: 992.1461 | AO56: 992.1408 | AP56: 998.0851 | AQ56: 991.9159 | AR56: 995.8237
...

Sheet Detail1
A1: Details for Sum of Net flows_Apr26 - Fund Name: Nippon India, Category: AGGRESSIVE HYBRID (+)
A3: Scheme Name | B3: Fund Name | C3: Category | D3: 30-Mar-2026 | E3: 31-Mar-2026 | F3: 01-Apr-2026 | G3: 02-Apr-2026 | H3: 06-Apr-2026 | I3: 07-Apr-2026 | J3: 08-Apr-2026 | K3: 09-Apr-2026 | L3: 10-Apr-2026 | M3: 13-Apr-2026 | N3: 15-Apr-2026 | O3: 16-Apr-2026 | P3: 17-Apr-2026 | Q3: 20-Apr-2026 | R3: 21-Apr-2026 | S3: 22-Apr-2026 | T3: 23-Apr-2026 | U3: 24-Apr-2026 | V3: 27-Apr-2026 | W3: 28-Apr-2026 | X3: 29-Apr-2026 | Y3: 30-Apr-2026 | Z3: 04-May-2026 | AA3: 05-May-2026 | AB3: 06-May-2026 | AC3: 07-May-2026 | AD3: 08-May-2026 | AE3: 11-May-2026 | AF3: 12-May-2026 | AG3: 13-May-2026 | AH3: 14-May-2026 | AI3: 15-May-2026 | AJ3: 18-May-2026 | AK3: 19-May-2026 | AL3: 20-May-2026 | AM3: 21-May-2026 | AN3: 22-May-2026 | AO3: 25-May-2026 | AP3: 26-May-2026 | AQ3: 27-May-2026 | AR3: 29-May-2026 | AS3: Net flows_Apr26 | AT3: Net flows_maY26
A4: Nippon India Vision Large & Mid Cap Fund | B4: Nippon India | C4: LARGE & MID CAP | D4: 0 | E4: 11.566631 | F4: 0.011501751 | G4: 1.9579882 | H4: 13.69859 | I4: 14.3282 | J4: 7.8482896 | K4: 8.2683646 | L4: 11.785942 | M4: 11.132678 | N4: 5.5364291 | O4: 9.0776588 | P4: 5.3533921 | Q4: 7.4138738 | R4: 9.1112088 | S4: 3.1740726 | T4: 7.0133835 | U4: 2.9108903 | V4: 4.3881501 | W4: 7.9786046 | X4: 5.9513786 | Y4: 2.8673587 | Z4: -53.475838 | AA4: 65.028846 | AB4: 7.5837153 | AC4: 4.0743811 | AD4: 3.0123418 | AE4: 3.0643466 | AF4: 8.6364013 | AG4: 7.2155732 | AH4: 6.8710927 | AI4: 3.9985399 | AJ4: 6.6158385 | AK4: 5.682428 | AL4: 3.4724958 | AM4: 8.555569 | AN4: 2.4086919 | AO4: -57.01692 | AP4: 61.147234 | AQ4: 3.0010873 | AR4: 4.0001222 | AS4: 139.80796 | AT4: 93.875948
A5: Nippon India Value Fund | B5: Nippon India | C5: VALUE | D5: 0 | E5: -0.29158135 | F5: 0.016943193 | G5: -0.50686763 | H5: 3.7221237 | I5: 6.1055342 | J5: 2.4430446 | K5: 2.971952 | L5: 12.810244 | M5: 6.7316151 | N5: 1.610945 | O5: 3.3560788 | P5: 1.7681249 | Q5: -0.022986398 | R5: 2.9111841 | S5: 0.50390122 | T5: -1.558907 | U5: 1.7644355 | V5: 0.50258314 | W5: 2.0656661 | X5: 1.362712 | Y5: -0.16998538 | Z5: -61.726633 | AA5: 64.858879 | AB5: 2.8402497 | AC5: 0.29834723 | AD5: -1.7191444 | AE5: -0.61423965 | AF5: 6.3216273 | AG5: 2.3287621 | AH5: 1.0341541 | AI5: 1.7670554 | AJ5: 2.9845877 | AK5: 0.87864234 | AL5: -0.0030163291 | AM5: 1.9242895 | AN5: -0.4642405 | AO5: -107.9597 | AP5: 105.87528 | AQ5: -0.98251864 | AR5: -0.37871058 | AS5: 48.388341 | AT5: 17.263671
A6: Nippon India US Equity Opportunities Fund | B6: Nippon India | C6: SECTORAL / THEMATIC | D6: 0 | E6: -19.623957 | F6: 19.194832 | G6: -0.04179608 | H6: 0.14448117 | I6: 0.26247294 | J6: 0.01135525 | K6: -0.13048726 | L6: -0.062330895 | M6: 0.27690567 | N6: -0.042342855 | O6: -0.16071674 | P6: -0.097367015 | Q6: -0.067145838 | R6: 0.079533863 | S6: -0.064338509 | T6: -0.082041312 | U6: -0.018707226 | V6: 0.0017943241 | W6: 0.02873094 | X6: 0.053569012 | Y6: -0.048449422 | Z6: 1.4796363 | AA6: -9.0098721 | AB6: 7.5819797 | AC6: 0.017250683 | AD6: 0.0025035866 | AE6: -0.032594726 | AF6: 0.13905614 | AG6: 0.0038701192 | AH6: -0.14452202 | AI6: -0.02677751 | AJ6: 0.069007699 | AK6: -0.001097729 | AL6: -0.047510534 | AM6: -0.0066066744 | AN6: -0.062643685 | AO6: 0 | AP6: -0.031942003 | AQ6: -0.054006684 | AR6: -0.024632837 | AS6: 19.237952 | AT6: -0.14890221
