Workbook

Sheet Quality Check
A1: # | B1: Check | C1: Live Result | D1: Expected / Python | E1: Difference | F1: Tolerance | G1: Status
A2: 1 | B2: Strike ladder spans -2.00% to +2.00% in 0.25% steps (17 strikes) | C2: =COUNT('BS Engine'!$A$2:$A$18) | D2: 17 | E2: =C2-D2 | F2: 0 | G2: =IF(ABS(E2)<=F2,"OK","CHECK")
A3: 2 | B3: ATM strike equals spot exactly | C3: ='BS Engine'!$B$10 | D3: =Assumptions!$B$2 | E3: =C3-D3 | F3: 1e-09 | G3: =IF(ABS(E3)<=F3,"OK","CHECK")
A4: 3 | B4: +2.00% strike = spot x 1.0200 | C4: ='BS Engine'!$B$18 | D4: =Assumptions!$B$2*1.02 | E4: =C4-D4 | F4: 1e-09 | G4: =IF(ABS(E4)<=F4,"OK","CHECK")
A5: 4 | B5: Strike step is a constant 0.25% of spot across the ladder | C5: =SUMPRODUCT(--(ABS('BS Engine'!$B$3:$B$18-'BS Engine'!$B$2:$B$17-Assumptions!$B$2*0.0025)<=0.000001)) | D5: 16 | E5: =C5-D5 | F5: 0 | G5: =IF(ABS(E5)<=F5,"OK","CHECK")
A6: 5 | B6: ATM call per contract at base VIX (INR) vs Python | C6: ='BS Engine'!$G$10 | D6: 5876.3775 | E6: =C6-D6 | F6: 1e-08 | G6: =IF(ABS(E6)<=F6,"OK","CHECK")
A7: 6 | B7: +2.00% OTM call per contract at base VIX (INR) vs Python | C7: ='BS Engine'!$G$18 | D7: 70.475777 | E7: =C7-D7 | F7: 1e-08 | G7: =IF(ABS(E7)<=F7,"OK","CHECK")
A8: 7 | B8: -2.00% ITM call per contract at base VIX (INR) vs Python | C8: ='BS Engine'!$G$2 | D8: 32351.255 | E8: =C8-D8 | F8: 1e-08 | G8: =IF(ABS(E8)<=F8,"OK","CHECK")
A9: 8 | B9: ATM vega per contract per VIX point (INR) vs Python | C9: ='BS Engine'!$N$10 | D9: 469.92664 | E9: =C9-D9 | F9: 1e-08 | G9: =IF(ABS(E9)<=F9,"OK","CHECK")
A10: 9 | B10: Premium = intrinsic + time value, all 21 strikes | C10: =SUMPRODUCT(ABS('BS Engine'!$F$2:$F$18-'BS Engine'!$H$2:$H$18-'BS Engine'!$I$2:$I$18)) | D10: 0 | E10: =C10-D10 | F10: 1e-09 | G10: =IF(ABS(E10)<=F10,"OK","CHECK")
A11: 10 | B11: Deepest ITM (-2.00%) intrinsic = spot - strike | C11: ='BS Engine'!$H$2 | D11: =Assumptions!$B$2-'BS Engine'!$B$2 | E11: =C11-D11 | F11: 1e-09 | G11: =IF(ABS(E11)<=F11,"OK","CHECK")
A12: 11 | B12: Every OTM strike has zero intrinsic value | C12: =SUMPRODUCT(ABS('BS Engine'!$H$10:$H$18)) | D12: 0 | E12: =C12-D12 | F12: 1e-09 | G12: =IF(ABS(E12)<=F12,"OK","CHECK")
A13: 12 | B13: Call price never below its lower bound MAX(0, S.e^-qT - K.e^-rT) | C13: =SUMPRODUCT(--('BS Engine'!$F$2:$F$18>=MAX(0,Assumptions!$B$2*EXP(-Assumptions!$B$4*Assumptions!$B$9)-'BS Engine'!$B$2:$B$18*EXP(-Assumptions!$B$3*Assumptions!$B$9))-0.000001)) | D13: 17 | E13: =C13-D13 | F13: 0 | G13: =IF(ABS(E13)<=F13,"OK","CHECK")
A14: 13 | B14: Call price never above its upper bound S.e^-qT | C14: =SUMPRODUCT(--('BS Engine'!$F$2:$F$18<=Assumptions!$B$2*EXP(-Assumptions!$B$4*Assumptions!$B$9))) | D14: 17 | E14: =C14-D14 | F14: 0 | G14: =IF(ABS(E14)<=F14,"OK","CHECK")
A15: 14 | B15: Delta stays within 0 and 1 at all 21 strikes | C15: =SUMPRODUCT(--('BS Engine'!$L$2:$L$18>=0),--('BS Engine'!$L$2:$L$18<=1)) | D15: 17 | E15: =C15-D15 | F15: 0 | G15: =IF(ABS(E15)<=F15,"OK","CHECK")
A16: 15 | B16: Premium Grid base-VIX column = BS Engine call premium, all 21 rows | C16: =SUMPRODUCT(ABS('Premium Grid'!$L$4:$L$20-'BS Engine'!$G$2:$G$18)) | D16: 0 | E16: =C16-D16 | F16: 1e-08 | G16: =IF(ABS(E16)<=F16,"OK","CHECK")
A17: 16 | B17: Premium Grid at VIX 8.0, ATM (INR) vs Python | C17: ='Premium Grid'!$D$12 | D17: 3997.1676 | E17: =C17-D17 | F17: 1e-08 | G17: =IF(ABS(E17)<=F17,"OK","CHECK")
A18: 17 | B18: Premium Grid at VIX 30.0, ATM (INR) vs Python | C18: ='Premium Grid'!$AV$12 | D18: 14337.582 | E18: =C18-D18 | F18: 1e-08 | G18: =IF(ABS(E18)<=F18,"OK","CHECK")
A19: 18 | B19: Premium Grid at VIX 30.0, +2.00% call (INR) vs Python | C19: ='Premium Grid'!$AV$20 | D19: 3728.6485 | E19: =C19-D19 | F19: 1e-08 | G19: =IF(ABS(E19)<=F19,"OK","CHECK")
A20: 19 | B20: Premium Grid at VIX 8.0, -2.00% ITM call (INR) vs Python | C20: ='Premium Grid'!$D$4 | D20: 32301.678 | E20: =C20-D20 | F20: 1e-08 | G20: =IF(ABS(E20)<=F20,"OK","CHECK")
A21: 20 | B21: Change vs Base is zero down the base-VIX column | C21: =SUMPRODUCT(ABS('Change vs Base'!$L$4:$L$20)) | D21: 0 | E21: =C21-D21 | F21: 1e-09 | G21: =IF(ABS(E21)<=F21,"OK","CHECK")
A22: 21 | B22: VIX x DTE grid at base VIX / 2 DTE, ATM = BS Engine ATM premium | C22: ='VIX x DTE Grid'!$D$7 | D22: ='BS Engine'!$G$10 | E22: =C22-D22 | F22: 1e-08 | G22: =IF(ABS(E22)<=F22,"OK","CHECK")
A23: 22 | B23: Premium never falls as VIX rises (748 comparisons) | C23: =SUMPRODUCT(--('Premium Grid'!$E$4:$AV$20>='Premium Grid'!$D$4:$AU$20-1e-06)) | D23: 748 | E23: =C23-D23 | F23: 0 | G23: =IF(ABS(E23)<=F23,"OK","CHECK")
A24: 23 | B24: Premium never rises as strike rises (720 comparisons) | C24: =SUMPRODUCT(--('Premium Grid'!$D$5:$AV$20<='Premium Grid'!$D$4:$AV$19+1e-06)) | D24: 720 | E24: =C24-D24 | F24: 0 | G24: =IF(ABS(E24)<=F24,"OK","CHECK")
A25: 24 | B25: ATM elasticity to IV is close to 1.0 (Black-Scholes property) | C25: ='BS Engine'!$P$10 | D25: 1 | E25: =C25-D25 | F25: 0.05 | G25: =IF(ABS(E25)<=F25,"OK","CHECK")
A26: 25 | B26: Elasticity rises monotonically from deep ITM to deep OTM | C26: =SUMPRODUCT(--('BS Engine'!$P$3:$P$18>'BS Engine'!$P$2:$P$17)) | D26: 16 | E26: =C26-D26 | F26: 0 | G26: =IF(ABS(E26)<=F26,"OK","CHECK")
A27: 26 | B27: Time value share never falls as strike rises (ITM -> OTM) | C27: =SUMPRODUCT(--('BS Engine'!$K$3:$K$18>='BS Engine'!$K$2:$K$17-1e-06)) | D27: 16 | E27: =C27-D27 | F27: 0 | G27: =IF(ABS(E27)<=F27,"OK","CHECK")
A28: 27 | B28: Deepest ITM (-2.00%) has the lowest time-value share | C28: =IF('BS Engine'!$K$2=MIN('BS Engine'!$K$2:$K$18),1,0) | D28: 1 | E28: =C28-D28 | F28: 0 | G28: =IF(ABS(E28)<=F28,"OK","CHECK")
A29: 28 | B29: Every OTM strike is 100% time value (zero intrinsic) | C29: =SUMPRODUCT(--(ABS('BS Engine'!$K$10:$K$18-1)<=1e-06)) | D29: 9 | E29: =C29-D29 | F29: 0 | G29: =IF(ABS(E29)<=F29,"OK","CHECK")
A31: OVERALL | B31: =IF(COUNTIF($G$2:$G$29,"CHECK")=0,"ALL CHECKS OK",COUNTIF($G$2:$G$29,"CHECK")&" CHECK(S) FAILED")
A33: Column D holds either a second live formula (cross-sheet reconciliation) or a value recomputed independently in Python by premium_turnover_sensitivity.py.
A34: The 'vs Python' rows are pinned to the assumptions AS GENERATED - if you edit the Assumptions sheet they will show CHECK until the script is re-run. Every other row is live on both sides and stays valid whatever you change.
A35: The arbitrage-bound, monotonicity and intrinsic/time-value rows are real property tests of the pricing, not restatements of it: each would break if a formula were wrong, rather than cancelling out.
A36: Monotonicity is tested non-strictly because far-OTM strikes at low VIX are floored at zero and legitimately tie with their neighbours.

Sheet Key Findings
A1: Key Findings
A2: NIFTY calls, one contract of 65, 2 days to expiry, spot fixed at 24,500, dividend yield 1.20%. Every number below is a live formula off the grids - edit the Assumptions sheet and this text updates with it.
A4: THE SHORT VERSION
A5: ="Only the TIME VALUE of an option responds to volatility, so how much a call reacts to VIX is set almost entirely by WHERE ITS STRIKE SITS - not by how big the VIX move is. Across this ladder a -2.00% call is "&TEXT('BS Engine'!$K$2,"0.0%")&" time value and barely moves, while a +2.00% call is 100% time value and moves violently. Same VIX change, responses "&TEXT('BS Engine'!$P$18/'BS Engine'!$P$2,"#,##0")&" times apart."
A7: AT A GLANCE
A8: Strike | C8: Premium @ VIX 12 | D8: Premium @ VIX 30 | E8: Change (INR) | F8: Change (%) | G8: Time Value % | H8: Elasticity to IV | I8: % per +0.5 VIX
A9: -2.00% | B9: ='BS Engine'!$C$2 | C9: ='Premium Grid'!$L$4 | D9: ='Premium Grid'!$AV$4 | E9: =D9-C9 | F9: =IF(C9=0,"",D9/C9-1) | G9: ='BS Engine'!$K$2 | H9: ='BS Engine'!$P$2 | I9: ='BS Engine'!$O$2/'BS Engine'!$G$2
A10: -1.00% | B10: ='BS Engine'!$C$6 | C10: ='Premium Grid'!$L$8 | D10: ='Premium Grid'!$AV$8 | E10: =D10-C10 | F10: =IF(C10=0,"",D10/C10-1) | G10: ='BS Engine'!$K$6 | H10: ='BS Engine'!$P$6 | I10: ='BS Engine'!$O$6/'BS Engine'!$G$6
A11: ATM | B11: ='BS Engine'!$C$10 | C11: ='Premium Grid'!$L$12 | D11: ='Premium Grid'!$AV$12 | E11: =D11-C11 | F11: =IF(C11=0,"",D11/C11-1) | G11: ='BS Engine'!$K$10 | H11: ='BS Engine'!$P$10 | I11: ='BS Engine'!$O$10/'BS Engine'!$G$10
A12: +1.00% | B12: ='BS Engine'!$C$14 | C12: ='Premium Grid'!$L$16 | D12: ='Premium Grid'!$AV$16 | E12: =D12-C12 | F12: =IF(C12=0,"",D12/C12-1) | G12: ='BS Engine'!$K$14 | H12: ='BS Engine'!$P$14 | I12: ='BS Engine'!$O$14/'BS Engine'!$G$14
A13: +2.00% | B13: ='BS Engine'!$C$18 | C13: ='Premium Grid'!$L$20 | D13: ='Premium Grid'!$AV$20 | E13: =D13-C13 | F13: =IF(C13=0,"",D13/C13-1) | G13: ='BS Engine'!$K$18 | H13: ='BS Engine'!$P$18 | I13: ='BS Engine'!$O$18/'BS Engine'!$G$18
A15: WHAT THE ANALYSIS SHOWS
A16: 1. Only time value reacts to volatility.
A17: ="Premium splits into intrinsic value, fixed by spot and strike, and time value. Volatility touches ONLY the second part. At VIX 12 the -2.00% call is just "&TEXT('BS Engine'!$K$2,"0.0%")&" time value, so there is almost nothing for vol to act on; every strike at or above the money is 100% time value."
A19: 2. Elasticity rises monotonically from ITM to OTM, tracking that share.
A20: ="Elasticity to IV runs from "&TEXT('BS Engine'!$P$2,"#,##0.00")&" at -2.00% through "&TEXT('BS Engine'!$P$10,"#,##0.00")&" at the money to "&TEXT('BS Engine'!$P$18,"#,##0.00")&" at +2.00%. The at-the-money figure sitting near 1.0 is a known Black-Scholes property: an ATM option moves roughly one-for-one with vol in percentage terms."
A22: 3. Moneyness matters far more than the size of the VIX move.
A23: ="Taking VIX from 12 to 30 - a "&TEXT(0.3/0.12-1,"0%")&" move - lifts the -2.00% call "&TEXT('Premium Grid'!$AV$4/'Premium Grid'!$L$4-1,"0.0%")&" but the +2.00% call "&TEXT('Premium Grid'!$AV$20/'Premium Grid'!$L$20-1,"#,##0%")&". One input, one move, responses orders of magnitude apart across the ladder."
A25: 4. Rupees and percentages point in opposite directions.
A26: ="The at-the-money strike gains the most RUPEES ("&TEXT('Premium Grid'!$AV$12-'Premium Grid'!$L$12,"#,##0")&" per contract from VIX 12 to 30), while the +2.00% strike gains the most PERCENT off a far smaller base. Which one matters depends on whether you are sizing rupee exposure or percentage returns - do not read one and quote the other."
A28: 5. At low VIX the out-of-the-money strikes are nearly worthless.
A29: ="At VIX 8 the +2.00% call is worth "&TEXT('Premium Grid'!$D$20,"#,##0.00")&" per contract against "&TEXT('Premium Grid'!$D$12,"#,##0")&" for the ATM. Those strikes only start carrying real premium once vol lifts, which is why a rise in VIX widens the traded strike range as well as repricing it."
A31: 6. Dividend yield is a level effect, not a sensitivity effect.
A32: ="This workbook prices with q = "&TEXT(Assumptions!$B$4,"0.00%")&". The companion ZERO-DIVIDEND workbook is identical in every other respect and prices every call slightly HIGHER - a little in rupees at the ITM strikes, a little in percent at the OTM ones - while the elasticities are effectively unchanged. Dividend yield moves the LEVEL of premium, not its sensitivity to volatility."
A34: WHAT THIS DOES NOT SAY
A35: - Volatility is FLAT across strikes - no smile or skew. The real market charges more for OTM strikes than a flat vol implies, so the OTM premiums here are a LOWER BOUND and their true elasticities are somewhat lower than shown.
A36: - Contract volume is not modelled at all. This is one contract; it says nothing about how many contracts would trade at any VIX level, which is a behavioural question Black-Scholes cannot answer.
A37: - Spot is frozen. In practice VIX rises when spot falls, and that correlation would move call premiums the other way - so these are not forecasts, they are clean one-factor sensitivities.
A38: - Strikes are exact percentages of spot, not the tradeable 50-point NSE grid.
A39: - Everything is at 2 days to expiry. The VIX x DTE Grid sheet is the only place tenor is varied.

Sheet Terminology
A1: Terminology - what every term in this workbook means
A2: Grouped by role. The formula column ties each term to the actual arithmetic used on the BS Engine sheet.
A4: Term | B4: Formula / notation | C4: Technical definition | D4: In plain English (as if explaining to a 10-year-old) | E4: Where you see it here
A5: THE CONTRACT
A6: Call option | B6: C = S.e^(-qT).N(d1) - K.e^(-rT).N(d2) | C6: A contract giving the holder the right, but not the obligation, to BUY the underlying at a fixed strike price on or before expiry. This workbook prices calls only - there is no put leg anywhere. | D6: A ticket that lets you buy something later at a price you lock in today. If the thing gets more expensive, your ticket becomes more valuable. If it gets cheaper, you just don't use the ticket. | E6: Every sheet - the whole workbook is calls
A7: Underlying / Spot (S) | B7: S | C7: The current market level of the asset the option is written on. Here the NIFTY index at 24,500, held fixed across every scenario. | D7: What the thing costs in the shop right now. | E7: Assumptions B2
A8: Strike price (K) | B8: K | C8: The fixed price at which the holder may buy. Here strikes are set as exact percentages of spot, not rounded to NSE's tradeable 50-point grid. | D8: The price printed on your ticket - the price you're allowed to buy at. | E8: BS Engine column B
A9: Moneyness | B9: (K - S) / S | C9: The strike expressed relative to spot, (K - S) / S. Negative means the strike sits below spot, positive above. | D9: How far the price on your ticket is from today's shop price. | E9: BS Engine column A; row labels on every grid
A10: ITM / ATM / OTM | B10: K < S / K = S / K > S (calls) | C10: In / at / out of the money. For a CALL: strike below spot is ITM, equal is ATM, above is OTM. Note this reverses for puts. | D10: ITM: your ticket already beats the shop price. ATM: exactly the same. OTM: your ticket is worse than the shop price today, so it only pays off if prices jump. | E10: BS Engine column C
A11: WHAT YOU PAY
A12: Premium | B12: C in points; C x lot = INR/contract | C12: The price of the option. Quoted here in index points and, multiplied by the lot size, in rupees per contract. | D12: What you pay to get the ticket. | E12: BS Engine F and G; the whole Premium Grid
A13: Intrinsic value | B13: MAX(0, S - K) | C13: MAX(0, S - K) for a call: what the option would be worth if exercised right now. Fixed by spot and strike - completely independent of volatility. | D13: The part of the ticket's worth you'd get just by using it this second. | E13: BS Engine column H
A14: Time value | B14: C - MAX(0, S - K) | C14: Premium minus intrinsic value: the amount paid for the possibility that the option ends up further in the money before expiry. This is the ONLY part that responds to volatility. | D14: The extra you pay for the chance that things get better before the ticket runs out. It shrinks to nothing on the last day. | E14: BS Engine I, J and K
A15: THE CONTRACT
A16: Lot size | B16: 65 units per contract | C16: The number of index units in one contract. NIFTY trades in lots; here 65. | D16: Tickets are only sold in packs. One pack holds 65. | E16: Assumptions B5
A17: Contract | B17: 1 lot; this workbook prices exactly 1 | C17: One lot. This workbook prices exactly ONE contract - there is no volume, no open interest and no market-wide turnover anywhere in it. | D17: One pack of tickets. We're only ever looking at a single pack. | E17: Assumptions B8
A18: Days to expiry (DTE) | B18: T = DTE / 365 | C18: Calendar days remaining until the option expires, converted to years as T = DTE / 365 for the pricing formula. | D18: How many days before the ticket stops working. | E18: Assumptions B7; the VIX x DTE Grid
A19: MODEL INPUTS
A20: Implied volatility / VIX | B20: sigma (VIX 12 = sigma 12% p.a.) | C20: The annualised standard deviation of returns implied by option prices. VIX 12 means 12% per year. Modelled here as FLAT across strikes. | D20: How jumpy everyone expects prices to be. Jumpier means tickets cost more, because a big move is more likely. | E20: Assumptions B6; column headers on every grid
A21: Black-Scholes model | B21: see the Call option row above | C21: The standard closed-form option pricing formula. This workbook uses the generalised form with a continuous dividend yield q. | D21: A famous recipe for working out a fair price for the ticket, using today's price, the ticket price, how long is left, and how jumpy things are. | E21: BS Engine; every priced cell
A22: d1 and d2 | B22: d1 = [ln(S/K) + (r - q + sigma^2/2).T] / (sigma.sqrt(T)); d2 = d1 - sigma.sqrt(T) | C22: The two standardised distance terms inside Black-Scholes. Roughly, how many standard deviations the strike sits from the forward price. | D22: Bookkeeping numbers the recipe needs. They measure how far away the ticket price is, counted in 'typical wobbles'. | E22: BS Engine D and E
A23: SENSITIVITIES (THE GREEKS)
A24: Delta | B24: e^(-qT).N(d1) | C24: The rate of change of premium with respect to spot: e^(-qT) x N(d1) for a call. Bounded between 0 and 1. | D24: If the shop price goes up by 1 rupee, how much does your ticket go up? Near 1 for a ticket that's already winning, near 0 for one that isn't. | E24: BS Engine column L
A25: Vega | B25: S.e^(-qT).n(d1).sqrt(T) x 0.01 per VIX point | C25: The rate of change of premium with respect to volatility. Expressed here per 1.00 VIX point, and also in rupees per contract. | D25: How much the ticket price moves when people get more or less jumpy. | E25: BS Engine M, N and O
A26: Elasticity to IV | B26: vega x sigma / C | C26: vega x sigma / premium: the PERCENTAGE change in premium for a 1% RELATIVE change in implied vol. Dimensionless, so it compares strikes fairly. | D26: If jumpiness goes up by 1%, how many % does the ticket price go up? Above 1 means the ticket reacts harder than the jumpiness itself moved. | E26: BS Engine P; the VIX Sensitivity sheet
A27: Convexity | B27: d2C/dsigma2 > 0 away from the money | C27: The premium is a convex function of volatility away from the money, so percentage responses accelerate as strikes move out of the money. | D27: The ticket doesn't react in a straight line. The more useless the ticket looks today, the more dramatically its price jumps when things get jumpy. | E27: Visible as the rising elasticity down the VIX Sensitivity sheet
A28: MODEL INPUTS
A29: Risk-free rate (r) | B29: r | C29: The continuously compounded rate used to discount the strike to present value. | D29: What money earns just sitting safely in the bank. | E29: Assumptions B3
A30: Dividend yield (q) | B30: q | C30: The continuous payout rate of the index. It lowers the forward price and so slightly lowers call premiums. One workbook uses 1.2%, the other 0. | D30: Cash the shares pay out to their owners. Ticket holders don't get that cash, so it makes the ticket worth a tiny bit less. | E30: Assumptions B4
A31: Forward price | B31: F = S.e^((r - q).T) | C31: S x e^((r - q) x T): the price for delivery at expiry rather than today. What the option is really struck against. | D31: What the thing is expected to cost on the day the ticket runs out, rather than today. | E31: Implied inside d1 and d2
A32: WHAT YOU PAY
A33: Premium turnover | B33: contracts x lot x premium (here: 1 x 65 x C) | C33: Market-wide, the total rupee value of option premium traded. With ONE contract and no volume in this workbook, premium turnover collapses to simply the premium of that single contract. | D33: Normally: all the money everyone spends on tickets added up. Here we only have one pack of tickets, so it's just what that pack costs. | E33: Premium Grid (in rupees per contract)
A34: WHAT IS NOT MODELLED
A35: Volatility smile / skew | B35: NOT modelled - sigma is constant in K | C35: The real market charges different implied vols at different strikes. This workbook deliberately does NOT model that - vol is flat across the ladder. | D35: In real life, tickets that look useless are charged extra because people are scared of big drops. We've ignored that here to keep things simple. | E35: NOT modelled - see the caveat on Key Findings

Sheet Assumptions
A1: Parameter | B1: Value | C1: Unit | D1: Notes
A2: NIFTY Spot (S) | B2: 24500 | C2: index points | D2: Hypothetical, fixed per brief
A3: Risk-free rate (r) | B3: 0.065 | C3: % p.a. | D3: Continuously compounded
A4: Dividend yield (q) | B4: 0.012 | C4: % p.a. | D4: NIFTY index yield
A5: Lot size | B5: 65 | C5: units/contract | D5: Per brief
A6: Base VIX / implied volatility | B6: 0.12 | C6: % p.a. | D6: Flat across strikes - no smile is modelled
A7: Days to expiry | B7: 2 | C7: calendar days | D7: Per brief
A8: Number of contracts | B8: 1 | C8: contracts | D8: ONE contract throughout - no volume weighting anywhere in this workbook
A9: Time to expiry (T) | B9: =Assumptions!$B$7/365 | C9: years | D9: Derived
A10: SQRT(T) | B10: =SQRT(Assumptions!$B$9) | D10: Derived
A12: Option type | B12: CALL only | D12: Per brief. No put leg anywhere in this workbook.
A13: Strike ladder | B13: -2.00% to +2.00% | D13: 0.25% steps, ATM on the ladder - 17 strikes. Strike = Spot x (1 + moneyness), exact, not rounded to the 50-point tradeable grid. Strikes BELOW spot are ITM calls.
A14: VIX ladder | B14: 8.0% to 30.0% | D14: 0.5-point steps, base 12 on the ladder (-4 / +18) - 45 levels.
A17: Model
A18: Generalised Black-Scholes call with continuous dividend yield q.
A19: Volatility is FLAT across strikes: no smile or skew, so far-OTM premium here is understated relative to the market, most visibly at the +4% to +5% strikes.
A20: Premium per contract (INR) = lot size x call premium in index points. With one contract, premium turnover IS the premium of that contract.
A21: Only TIME VALUE responds to volatility. Intrinsic value is fixed by spot and strike, which is why the ITM strikes on the left are barely vol-sensitive.

Sheet BS Engine
A1: Moneyness | B1: Strike | C1: Call | D1: d1 | E1: d2 | F1: Call Premium (pts) | G1: Call Premium (INR/contract) | H1: Intrinsic (pts) | I1: Time Value (pts) | J1: Time Value (INR/contract) | K1: Time Value % of Premium | L1: Delta | M1: Vega (pts per 1 VIX pt) | N1: Vega (INR/contract per 1 VIX pt) | O1: INR change per +0.5 VIX pt | P1: Elasticity to IV
A2: -0.02 | B2: =Assumptions!$B$2*(1+A2) | C2: =IF(A2<0,"ITM",IF(A2>0,"OTM","ATM")) | D2: =((LN(Assumptions!$B$2/$B2)+(Assumptions!$B$3-Assumptions!$B$4+Assumptions!$B$6^2/2)*Assumptions!$B$9)/(Assumptions!$B$6*Assumptions!$B$10)) | E2: =D2-Assumptions!$B$6*Assumptions!$B$10 | F2: =MAX(0,Assumptions!$B$2*EXP(-Assumptions!$B$4*Assumptions!$B$9)*NORMSDIST(((LN(Assumptions!$B$2/$B2)+(Assumptions!$B$3-Assumptions!$B$4+Assumptions!$B$6^2/2)*Assumptions!$B$9)/(Assumptions!$B$6*Assumptions!$B$10)))-$B2*EXP(-Assumptions!$B$3*Assumptions!$B$9)*NORMSDIST((((LN(Assumptions!$B$2/$B2)+(Assumptions!$B$3-Assumptions!$B$4+Assumptions!$B$6^2/2)*Assumptions!$B$9)/(Assumptions!$B$6*Assumptions!$B$10))-Assumptions!$B$6*Assumptions!$B$10))) | G2: =F2*Assumptions!$B$5 | H2: =MAX(0,Assumptions!$B$2-B2) | I2: =F2-H2 | J2: =I2*Assumptions!$B$5 | K2: =IF(F2<=0,"",I2/F2) | L2: =EXP(-Assumptions!$B$4*Assumptions!$B$9)*NORMSDIST(D2) | M2: =Assumptions!$B$2*EXP(-Assumptions!$B$4*Assumptions!$B$9)*NORMDIST(((LN(Assumptions!$B$2/$B2)+(Assumptions!$B$3-Assumptions!$B$4+Assumptions!$B$6^2/2)*Assumptions!$B$9)/(Assumptions!$B$6*Assumptions!$B$10)),0,1,FALSE)*Assumptions!$B$10*0.01 | N2: =M2*Assumptions!$B$5 | O2: =N2*0.5 | P2: =IF(F2<=0,"",M2*(Assumptions!$B$6/0.01)/F2)
A3: -0.0175 | B3: =Assumptions!$B$2*(1+A3) | C3: =IF(A3<0,"ITM",IF(A3>0,"OTM","ATM")) | D3: =((LN(Assumptions!$B$2/$B3)+(Assumptions!$B$3-Assumptions!$B$4+Assumptions!$B$6^2/2)*Assumptions!$B$9)/(Assumptions!$B$6*Assumptions!$B$10)) | E3: =D3-Assumptions!$B$6*Assumptions!$B$10 | F3: =MAX(0,Assumptions!$B$2*EXP(-Assumptions!$B$4*Assumptions!$B$9)*NORMSDIST(((LN(Assumptions!$B$2/$B3)+(Assumptions!$B$3-Assumptions!$B$4+Assumptions!$B$6^2/2)*Assumptions!$B$9)/(Assumptions!$B$6*Assumptions!$B$10)))-$B3*EXP(-Assumptions!$B$3*Assumptions!$B$9)*NORMSDIST((((LN(Assumptions!$B$2/$B3)+(Assumptions!$B$3-Assumptions!$B$4+Assumptions!$B$6^2/2)*Assumptions!$B$9)/(Assumptions!$B$6*Assumptions!$B$10))-Assumptions!$B$6*Assumptions!$B$10))) | G3: =F3*Assumptions!$B$5 | H3: =MAX(0,Assumptions!$B$2-B3) | I3: =F3-H3 | J3: =I3*Assumptions!$B$5 | K3: =IF(F3<=0,"",I3/F3) | L3: =EXP(-Assumptions!$B$4*Assumptions!$B$9)*NORMSDIST(D3) | M3: =Assumptions!$B$2*EXP(-Assumptions!$B$4*Assumptions!$B$9)*NORMDIST(((LN(Assumptions!$B$2/$B3)+(Assumptions!$B$3-Assumptions!$B$4+Assumptions!$B$6^2/2)*Assumptions!$B$9)/(Assumptions!$B$6*Assumptions!$B$10)),0,1,FALSE)*Assumptions!$B$10*0.01 | N3: =M3*Assumptions!$B$5 | O3: =N3*0.5 | P3: =IF(F3<=0,"",M3*(Assumptions!$B$6/0.01)/F3)
A4: -0.015 | B4: =Assumptions!$B$2*(1+A4) | C4: =IF(A4<0,"ITM",IF(A4>0,"OTM","ATM")) | D4: =((LN(Assumptions!$B$2/$B4)+(Assumptions!$B$3-Assumptions!$B$4+Assumptions!$B$6^2/2)*Assumptions!$B$9)/(Assumptions!$B$6*Assumptions!$B$10)) | E4: =D4-Assumptions!$B$6*Assumptions!$B$10 | F4: =MAX(0,Assumptions!$B$2*EXP(-Assumptions!$B$4*Assumptions!$B$9)*NORMSDIST(((LN(Assumptions!$B$2/$B4)+(Assumptions!$B$3-Assumptions!$B$4+Assumptions!$B$6^2/2)*Assumptions!$B$9)/(Assumptions!$B$6*Assumptions!$B$10)))-$B4*EXP(-Assumptions!$B$3*Assumptions!$B$9)*NORMSDIST((((LN(Assumptions!$B$2/$B4)+(Assumptions!$B$3-Assumptions!$B$4+Assumptions!$B$6^2/2)*Assumptions!$B$9)/(Assumptions!$B$6*Assumptions!$B$10))-Assumptions!$B$6*Assumptions!$B$10))) | G4: =F4*Assumptions!$B$5 | H4: =MAX(0,Assumptions!$B$2-B4) | I4: =F4-H4 | J4: =I4*Assumptions!$B$5 | K4: =IF(F4<=0,"",I4/F4) | L4: =EXP(-Assumptions!$B$4*Assumptions!$B$9)*NORMSDIST(D4) | M4: =Assumptions!$B$2*EXP(-Assumptions!$B$4*Assumptions!$B$9)*NORMDIST(((LN(Assumptions!$B$2/$B4)+(Assumptions!$B$3-Assumptions!$B$4+Assumptions!$B$6^2/2)*Assumptions!$B$9)/(Assumptions!$B$6*Assumptions!$B$10)),0,1,FALSE)*Assumptions!$B$10*0.01 | N4: =M4*Assumptions!$B$5 | O4: =N4*0.5 | P4: =IF(F4<=0,"",M4*(Assumptions!$B$6/0.01)/F4)
A5: -0.0125 | B5: =Assumptions!$B$2*(1+A5) | C5: =IF(A5<0,"ITM",IF(A5>0,"OTM","ATM")) | D5: =((LN(Assumptions!$B$2/$B5)+(Assumptions!$B$3-Assumptions!$B$4+Assumptions!$B$6^2/2)*Assumptions!$B$9)/(Assumptions!$B$6*Assumptions!$B$10)) | E5: =D5-Assumptions!$B$6*Assumptions!$B$10 | F5: =MAX(0,Assumptions!$B$2*EXP(-Assumptions!$B$4*Assumptions!$B$9)*NORMSDIST(((LN(Assumptions!$B$2/$B5)+(Assumptions!$B$3-Assumptions!$B$4+Assumptions!$B$6^2/2)*Assumptions!$B$9)/(Assumptions!$B$6*Assumptions!$B$10)))-$B5*EXP(-Assumptions!$B$3*Assumptions!$B$9)*NORMSDIST((((LN(Assumptions!$B$2/$B5)+(Assumptions!$B$3-Assumptions!$B$4+Assumptions!$B$6^2/2)*Assumptions!$B$9)/(Assumptions!$B$6*Assumptions!$B$10))-Assumptions!$B$6*Assumptions!$B$10))) | G5: =F5*Assumptions!$B$5 | H5: =MAX(0,Assumptions!$B$2-B5) | I5: =F5-H5 | J5: =I5*Assumptions!$B$5 | K5: =IF(F5<=0,"",I5/F5) | L5: =EXP(-Assumptions!$B$4*Assumptions!$B$9)*NORMSDIST(D5) | M5: =Assumptions!$B$2*EXP(-Assumptions!$B$4*Assumptions!$B$9)*NORMDIST(((LN(Assumptions!$B$2/$B5)+(Assumptions!$B$3-Assumptions!$B$4+Assumptions!$B$6^2/2)*Assumptions!$B$9)/(Assumptions!$B$6*Assumptions!$B$10)),0,1,FALSE)*Assumptions!$B$10*0.01 | N5: =M5*Assumptions!$B$5 | O5: =N5*0.5 | P5: =IF(F5<=0,"",M5*(Assumptions!$B$6/0.01)/F5)
A6: -0.01 | B6: =Assumptions!$B$2*(1+A6) | C6: =IF(A6<0,"ITM",IF(A6>0,"OTM","ATM")) | D6: =((LN(Assumptions!$B$2/$B6)+(Assumptions!$B$3-Assumptions!$B$4+Assumptions!$B$6^2/2)*Assumptions!$B$9)/(Assumptions!$B$6*Assumptions!$B$10)) | E6: =D6-Assumptions!$B$6*Assumptions!$B$10 | F6: =MAX(0,Assumptions!$B$2*EXP(-Assumptions!$B$4*Assumptions!$B$9)*NORMSDIST(((LN(Assumptions!$B$2/$B6)+(Assumptions!$B$3-Assumptions!$B$4+Assumptions!$B$6^2/2)*Assumptions!$B$9)/(Assumptions!$B$6*Assumptions!$B$10)))-$B6*EXP(-Assumptions!$B$3*Assumptions!$B$9)*NORMSDIST((((LN(Assumptions!$B$2/$B6)+(Assumptions!$B$3-Assumptions!$B$4+Assumptions!$B$6^2/2)*Assumptions!$B$9)/(Assumptions!$B$6*Assumptions!$B$10))-Assumptions!$B$6*Assumptions!$B$10))) | G6: =F6*Assumptions!$B$5 | H6: =MAX(0,Assumptions!$B$2-B6) | I6: =F6-H6 | J6: =I6*Assumptions!$B$5 | K6: =IF(F6<=0,"",I6/F6) | L6: =EXP(-Assumptions!$B$4*Assumptions!$B$9)*NORMSDIST(D6) | M6: =Assumptions!$B$2*EXP(-Assumptions!$B$4*Assumptions!$B$9)*NORMDIST(((LN(Assumptions!$B$2/$B6)+(Assumptions!$B$3-Assumptions!$B$4+Assumptions!$B$6^2/2)*Assumptions!$B$9)/(Assumptions!$B$6*Assumptions!$B$10)),0,1,FALSE)*Assumptions!$B$10*0.01 | N6: =M6*Assumptions!$B$5 | O6: =N6*0.5 | P6: =IF(F6<=0,"",M6*(Assumptions!$B$6/0.01)/F6)
A7: -0.0075 | B7: =Assumptions!$B$2*(1+A7) | C7: =IF(A7<0,"ITM",IF(A7>0,"OTM","ATM")) | D7: =((LN(Assumptions!$B$2/$B7)+(Assumptions!$B$3-Assumptions!$B$4+Assumptions!$B$6^2/2)*Assumptions!$B$9)/(Assumptions!$B$6*Assumptions!$B$10)) | E7: =D7-Assumptions!$B$6*Assumptions!$B$10 | F7: =MAX(0,Assumptions!$B$2*EXP(-Assumptions!$B$4*Assumptions!$B$9)*NORMSDIST(((LN(Assumptions!$B$2/$B7)+(Assumptions!$B$3-Assumptions!$B$4+Assumptions!$B$6^2/2)*Assumptions!$B$9)/(Assumptions!$B$6*Assumptions!$B$10)))-$B7*EXP(-Assumptions!$B$3*Assumptions!$B$9)*NORMSDIST((((LN(Assumptions!$B$2/$B7)+(Assumptions!$B$3-Assumptions!$B$4+Assumptions!$B$6^2/2)*Assumptions!$B$9)/(Assumptions!$B$6*Assumptions!$B$10))-Assumptions!$B$6*Assumptions!$B$10))) | G7: =F7*Assumptions!$B$5 | H7: =MAX(0,Assumptions!$B$2-B7) | I7: =F7-H7 | J7: =I7*Assumptions!$B$5 | K7: =IF(F7<=0,"",I7/F7) | L7: =EXP(-Assumptions!$B$4*Assumptions!$B$9)*NORMSDIST(D7) | M7: =Assumptions!$B$2*EXP(-Assumptions!$B$4*Assumptions!$B$9)*NORMDIST(((LN(Assumptions!$B$2/$B7)+(Assumptions!$B$3-Assumptions!$B$4+Assumptions!$B$6^2/2)*Assumptions!$B$9)/(Assumptions!$B$6*Assumptions!$B$10)),0,1,FALSE)*Assumptions!$B$10*0.01 | N7: =M7*Assumptions!$B$5 | O7: =N7*0.5 | P7: =IF(F7<=0,"",M7*(Assumptions!$B$6/0.01)/F7)
A8: -0.005 | B8: =Assumptions!$B$2*(1+A8) | C8: =IF(A8<0,"ITM",IF(A8>0,"OTM","ATM")) | D8: =((LN(Assumptions!$B$2/$B8)+(Assumptions!$B$3-Assumptions!$B$4+Assumptions!$B$6^2/2)*Assumptions!$B$9)/(Assumptions!$B$6*Assumptions!$B$10)) | E8: =D8-Assumptions!$B$6*Assumptions!$B$10 | F8: =MAX(0,Assumptions!$B$2*EXP(-Assumptions!$B$4*Assumptions!$B$9)*NORMSDIST(((LN(Assumptions!$B$2/$B8)+(Assumptions!$B$3-Assumptions!$B$4+Assumptions!$B$6^2/2)*Assumptions!$B$9)/(Assumptions!$B$6*Assumptions!$B$10)))-$B8*EXP(-Assumptions!$B$3*Assumptions!$B$9)*NORMSDIST((((LN(Assumptions!$B$2/$B8)+(Assumptions!$B$3-Assumptions!$B$4+Assumptions!$B$6^2/2)*Assumptions!$B$9)/(Assumptions!$B$6*Assumptions!$B$10))-Assumptions!$B$6*Assumptions!$B$10))) | G8: =F8*Assumptions!$B$5 | H8: =MAX(0,Assumptions!$B$2-B8) | I8: =F8-H8 | J8: =I8*Assumptions!$B$5 | K8: =IF(F8<=0,"",I8/F8) | L8: =EXP(-Assumptions!$B$4*Assumptions!$B$9)*NORMSDIST(D8) | M8: =Assumptions!$B$2*EXP(-Assumptions!$B$4*Assumptions!$B$9)*NORMDIST(((LN(Assumptions!$B$2/$B8)+(Assumptions!$B$3-Assumptions!$B$4+Assumptions!$B$6^2/2)*Assumptions!$B$9)/(Assumptions!$B$6*Assumptions!$B$10)),0,1,FALSE)*Assumptions!$B$10*0.01 | N8: =M8*Assumptions!$B$5 | O8: =N8*0.5 | P8: =IF(F8<=0,"",M8*(Assumptions!$B$6/0.01)/F8)
A9: -0.0025 | B9: =Assumptions!$B$2*(1+A9) | C9: =IF(A9<0,"ITM",IF(A9>0,"OTM","ATM")) | D9: =((LN(Assumptions!$B$2/$B9)+(Assumptions!$B$3-Assumptions!$B$4+Assumptions!$B$6^2/2)*Assumptions!$B$9)/(Assumptions!$B$6*Assumptions!$B$10)) | E9: =D9-Assumptions!$B$6*Assumptions!$B$10 | F9: =MAX(0,Assumptions!$B$2*EXP(-Assumptions!$B$4*Assumptions!$B$9)*NORMSDIST(((LN(Assumptions!$B$2/$B9)+(Assumptions!$B$3-Assumptions!$B$4+Assumptions!$B$6^2/2)*Assumptions!$B$9)/(Assumptions!$B$6*Assumptions!$B$10)))-$B9*EXP(-Assumptions!$B$3*Assumptions!$B$9)*NORMSDIST((((LN(Assumptions!$B$2/$B9)+(Assumptions!$B$3-Assumptions!$B$4+Assumptions!$B$6^2/2)*Assumptions!$B$9)/(Assumptions!$B$6*Assumptions!$B$10))-Assumptions!$B$6*Assumptions!$B$10))) | G9: =F9*Assumptions!$B$5 | H9: =MAX(0,Assumptions!$B$2-B9) | I9: =F9-H9 | J9: =I9*Assumptions!$B$5 | K9: =IF(F9<=0,"",I9/F9) | L9: =EXP(-Assumptions!$B$4*Assumptions!$B$9)*NORMSDIST(D9) | M9: =Assumptions!$B$2*EXP(-Assumptions!$B$4*Assumptions!$B$9)*NORMDIST(((LN(Assumptions!$B$2/$B9)+(Assumptions!$B$3-Assumptions!$B$4+Assumptions!$B$6^2/2)*Assumptions!$B$9)/(Assumptions!$B$6*Assumptions!$B$10)),0,1,FALSE)*Assumptions!$B$10*0.01 | N9: =M9*Assumptions!$B$5 | O9: =N9*0.5 | P9: =IF(F9<=0,"",M9*(Assumptions!$B$6/0.01)/F9)
A10: 0 | B10: =Assumptions!$B$2*(1+A10) | C10: =IF(A10<0,"ITM",IF(A10>0,"OTM","ATM")) | D10: =((LN(Assumptions!$B$2/$B10)+(Assumptions!$B$3-Assumptions!$B$4+Assumptions!$B$6^2/2)*Assumptions!$B$9)/(Assumptions!$B$6*Assumptions!$B$10)) | E10: =D10-Assumptions!$B$6*Assumptions!$B$10 | F10: =MAX(0,Assumptions!$B$2*EXP(-Assumptions!$B$4*Assumptions!$B$9)*NORMSDIST(((LN(Assumptions!$B$2/$B10)+(Assumptions!$B$3-Assumptions!$B$4+Assumptions!$B$6^2/2)*Assumptions!$B$9)/(Assumptions!$B$6*Assumptions!$B$10)))-$B10*EXP(-Assumptions!$B$3*Assumptions!$B$9)*NORMSDIST((((LN(Assumptions!$B$2/$B10)+(Assumptions!$B$3-Assumptions!$B$4+Assumptions!$B$6^2/2)*Assumptions!$B$9)/(Assumptions!$B$6*Assumptions!$B$10))-Assumptions!$B$6*Assumptions!$B$10))) | G10: =F10*Assumptions!$B$5 | H10: =MAX(0,Assumptions!$B$2-B10) | I10: =F10-H10 | J10: =I10*Assumptions!$B$5 | K10: =IF(F10<=0,"",I10/F10) | L10: =EXP(-Assumptions!$B$4*Assumptions!$B$9)*NORMSDIST(D10) | M10: =Assumptions!$B$2*EXP(-Assumptions!$B$4*Assumptions!$B$9)*NORMDIST(((LN(Assumptions!$B$2/$B10)+(Assumptions!$B$3-Assumptions!$B$4+Assumptions!$B$6^2/2)*Assumptions!$B$9)/(Assumptions!$B$6*Assumptions!$B$10)),0,1,FALSE)*Assumptions!$B$10*0.01 | N10: =M10*Assumptions!$B$5 | O10: =N10*0.5 | P10: =IF(F10<=0,"",M10*(Assumptions!$B$6/0.01)/F10)
A11: 0.0025 | B11: =Assumptions!$B$2*(1+A11) | C11: =IF(A11<0,"ITM",IF(A11>0,"OTM","ATM")) | D11: =((LN(Assumptions!$B$2/$B11)+(Assumptions!$B$3-Assumptions!$B$4+Assumptions!$B$6^2/2)*Assumptions!$B$9)/(Assumptions!$B$6*Assumptions!$B$10)) | E11: =D11-Assumptions!$B$6*Assumptions!$B$10 | F11: =MAX(0,Assumptions!$B$2*EXP(-Assumptions!$B$4*Assumptions!$B$9)*NORMSDIST(((LN(Assumptions!$B$2/$B11)+(Assumptions!$B$3-Assumptions!$B$4+Assumptions!$B$6^2/2)*Assumptions!$B$9)/(Assumptions!$B$6*Assumptions!$B$10)))-$B11*EXP(-Assumptions!$B$3*Assumptions!$B$9)*NORMSDIST((((LN(Assumptions!$B$2/$B11)+(Assumptions!$B$3-Assumptions!$B$4+Assumptions!$B$6^2/2)*Assumptions!$B$9)/(Assumptions!$B$6*Assumptions!$B$10))-Assumptions!$B$6*Assumptions!$B$10))) | G11: =F11*Assumptions!$B$5 | H11: =MAX(0,Assumptions!$B$2-B11) | I11: =F11-H11 | J11: =I11*Assumptions!$B$5 | K11: =IF(F11<=0,"",I11/F11) | L11: =EXP(-Assumptions!$B$4*Assumptions!$B$9)*NORMSDIST(D11) | M11: =Assumptions!$B$2*EXP(-Assumptions!$B$4*Assumptions!$B$9)*NORMDIST(((LN(Assumptions!$B$2/$B11)+(Assumptions!$B$3-Assumptions!$B$4+Assumptions!$B$6^2/2)*Assumptions!$B$9)/(Assumptions!$B$6*Assumptions!$B$10)),0,1,FALSE)*Assumptions!$B$10*0.01 | N11: =M11*Assumptions!$B$5 | O11: =N11*0.5 | P11: =IF(F11<=0,"",M11*(Assumptions!$B$6/0.01)/F11)
A12: 0.005 | B12: =Assumptions!$B$2*(1+A12) | C12: =IF(A12<0,"ITM",IF(A12>0,"OTM","ATM")) | D12: =((LN(Assumptions!$B$2/$B12)+(Assumptions!$B$3-Assumptions!$B$4+Assumptions!$B$6^2/2)*Assumptions!$B$9)/(Assumptions!$B$6*Assumptions!$B$10)) | E12: =D12-Assumptions!$B$6*Assumptions!$B$10 | F12: =MAX(0,Assumptions!$B$2*EXP(-Assumptions!$B$4*Assumptions!$B$9)*NORMSDIST(((LN(Assumptions!$B$2/$B12)+(Assumptions!$B$3-Assumptions!$B$4+Assumptions!$B$6^2/2)*Assumptions!$B$9)/(Assumptions!$B$6*Assumptions!$B$10)))-$B12*EXP(-Assumptions!$B$3*Assumptions!$B$9)*NORMSDIST((((LN(Assumptions!$B$2/$B12)+(Assumptions!$B$3-Assumptions!$B$4+Assumptions!$B$6^2/2)*Assumptions!$B$9)/(Assumptions!$B$6*Assumptions!$B$10))-Assumptions!$B$6*Assumptions!$B$10))) | G12: =F12*Assumptions!$B$5 | H12: =MAX(0,Assumptions!$B$2-B12) | I12: =F12-H12 | J12: =I12*Assumptions!$B$5 | K12: =IF(F12<=0,"",I12/F12) | L12: =EXP(-Assumptions!$B$4*Assumptions!$B$9)*NORMSDIST(D12) | M12: =Assumptions!$B$2*EXP(-Assumptions!$B$4*Assumptions!$B$9)*NORMDIST(((LN(Assumptions!$B$2/$B12)+(Assumptions!$B$3-Assumptions!$B$4+Assumptions!$B$6^2/2)*Assumptions!$B$9)/(Assumptions!$B$6*Assumptions!$B$10)),0,1,FALSE)*Assumptions!$B$10*0.01 | N12: =M12*Assumptions!$B$5 | O12: =N12*0.5 | P12: =IF(F12<=0,"",M12*(Assumptions!$B$6/0.01)/F12)
A13: 0.0075 | B13: =Assumptions!$B$2*(1+A13) | C13: =IF(A13<0,"ITM",IF(A13>0,"OTM","ATM")) | D13: =((LN(Assumptions!$B$2/$B13)+(Assumptions!$B$3-Assumptions!$B$4+Assumptions!$B$6^2/2)*Assumptions!$B$9)/(Assumptions!$B$6*Assumptions!$B$10)) | E13: =D13-Assumptions!$B$6*Assumptions!$B$10 | F13: =MAX(0,Assumptions!$B$2*EXP(-Assumptions!$B$4*Assumptions!$B$9)*NORMSDIST(((LN(Assumptions!$B$2/$B13)+(Assumptions!$B$3-Assumptions!$B$4+Assumptions!$B$6^2/2)*Assumptions!$B$9)/(Assumptions!$B$6*Assumptions!$B$10)))-$B13*EXP(-Assumptions!$B$3*Assumptions!$B$9)*NORMSDIST((((LN(Assumptions!$B$2/$B13)+(Assumptions!$B$3-Assumptions!$B$4+Assumptions!$B$6^2/2)*Assumptions!$B$9)/(Assumptions!$B$6*Assumptions!$B$10))-Assumptions!$B$6*Assumptions!$B$10))) | G13: =F13*Assumptions!$B$5 | H13: =MAX(0,Assumptions!$B$2-B13) | I13: =F13-H13 | J13: =I13*Assumptions!$B$5 | K13: =IF(F13<=0,"",I13/F13) | L13: =EXP(-Assumptions!$B$4*Assumptions!$B$9)*NORMSDIST(D13) | M13: =Assumptions!$B$2*EXP(-Assumptions!$B$4*Assumptions!$B$9)*NORMDIST(((LN(Assumptions!$B$2/$B13)+(Assumptions!$B$3-Assumptions!$B$4+Assumptions!$B$6^2/2)*Assumptions!$B$9)/(Assumptions!$B$6*Assumptions!$B$10)),0,1,FALSE)*Assumptions!$B$10*0.01 | N13: =M13*Assumptions!$B$5 | O13: =N13*0.5 | P13: =IF(F13<=0,"",M13*(Assumptions!$B$6/0.01)/F13)
... A18: 0.02 | B18: =Assumptions!$B$2*(1+A18) | C18: =IF(A18<0,"ITM",IF(A18>0,"OTM","ATM")) | D18: =((LN(Assumptions!$B$2/$B18)+(Assumptions!$B$3-Assumptions!$B$4+Assumptions!$B$6^2/2)*Assumptions!$B$9)/(Assumptions!$B$6*Assumptions!$B$10)) | E18: =D18-Assumptions!$B$6*Assumptions!$B$10 | F18: =MAX(0,Assumptions!$B$2*EXP(-Assumptions!$B$4*Assumptions!$B$9)*NORMSDIST(((LN(Assumptions!$B$2/$B18)+(Assumptions!$B$3-Assumptions!$B$4+Assumptions!$B$6^2/2)*Assumptions!$B$9)/(Assumptions!$B$6*Assumptions!$B$10)))-$B18*EXP(-Assumptions!$B$3*Assumptions!$B$9)*NORMSDIST((((LN(Assumptions!$B$2/$B18)+(Assumptions!$B$3-Assumptions!$B$4+Assumptions!$B$6^2/2)*Assumptions!$B$9)/(Assumptions!$B$6*Assumptions!$B$10))-Assumptions!$B$6*Assumptions!$B$10))) | G18: =F18*Assumptions!$B$5 | H18: =MAX(0,Assumptions!$B$2-B18) | I18: =F18-H18 | J18: =I18*Assumptions!$B$5 | K18: =IF(F18<=0,"",I18/F18) | L18: =EXP(-Assumptions!$B$4*Assumptions!$B$9)*NORMSDIST(D18) | M18: =Assumptions!$B$2*EXP(-Assumptions!$B$4*Assumptions!$B$9)*NORMDIST(((LN(Assumptions!$B$2/$B18)+(Assumptions!$B$3-Assumptions!$B$4+Assumptions!$B$6^2/2)*Assumptions!$B$9)/(Assumptions!$B$6*Assumptions!$B$10)),0,1,FALSE)*Assumptions!$B$10*0.01 | N18: =M18*Assumptions!$B$5 | O18: =N18*0.5 | P18: =IF(F18<=0,"",M18*(Assumptions!$B$6/0.01)/F18)
A20: Elasticity to IV = vega x sigma / premium: the % change in premium for a 1% RELATIVE change in implied vol (e.g. VIX 12.00 -> 12.12).
A21: Read it against the Time Value % column - the two move together. An ITM call is mostly intrinsic, and intrinsic does not care about volatility at all.
A22: So elasticity climbs monotonically from its lowest value at -2.00% (deepest ITM) through about 1.0 at the money to its highest at +2.00% (deepest OTM).

Sheet Premium Grid
A1: CALL premium per contract (INR) - Moneyness x VIX
A2: One call contract, lot 65, 2 days to expiry. Column headers are VIX points. Strikes below spot are ITM.
A3: Moneyness | B3: Strike | C3: Call | D3: 8 | E3: 8.5 | F3: 9 | G3: 9.5 | H3: 10 | I3: 10.5 | J3: 11 | K3: 11.5 | L3: 12 | M3: 12.5 | N3: 13 | O3: 13.5 | P3: 14 | Q3: 14.5 | R3: 15 | S3: 15.5 | T3: 16 | U3: 16.5 | V3: 17 | W3: 17.5 | X3: 18 | Y3: 18.5 | Z3: 19 | AA3: 19.5 | AB3: 20 | AC3: 20.5 | AD3: 21 | AE3: 21.5 | AF3: 22 | AG3: 22.5 | AH3: 23 | AI3: 23.5 | AJ3: 24 | AK3: 24.5 | AL3: 25 | AM3: 25.5 | AN3: 26 | AO3: 26.5 | AP3: 27 | AQ3: 27.5 | AR3: 28 | AS3: 28.5 | AT3: 29 | AU3: 29.5 | AV3: 30
A4: -2.00% | B4: ='BS Engine'!$B$2 | C4: ='BS Engine'!$C$2 | D4: =Assumptions!$B$5*(MAX(0,Assumptions!$B$2*EXP(-Assumptions!$B$4*Assumptions!$B$9)*NORMSDIST(((LN(Assumptions!$B$2/$B4)+(Assumptions!$B$3-Assumptions!$B$4+(D$3/100)^2/2)*Assumptions!$B$9)/((D$3/100)*Assumptions!$B$10)))-$B4*EXP(-Assumptions!$B$3*Assumptions!$B$9)*NORMSDIST((((LN(Assumptions!$B$2/$B4)+(Assumptions!$B$3-Assumptions!$B$4+(D$3/100)^2/2)*Assumptions!$B$9)/((D$3/100)*Assumptions!$B$10))-(D$3/100)*Assumptions!$B$10)))) | E4: =Assumptions!$B$5*(MAX(0,Assumptions!$B$2*EXP(-Assumptions!$B$4*Assumptions!$B$9)*NORMSDIST(((LN(Assumptions!$B$2/$B4)+(Assumptions!$B$3-Assumptions!$B$4+(E$3/100)^2/2)*Assumptions!$B$9)/((E$3/100)*Assumptions!$B$10)))-$B4*EXP(-Assumptions!$B$3*Assumptions!$B$9)*NORMSDIST((((LN(Assumptions!$B$2/$B4)+(Assumptions!$B$3-Assumptions!$B$4+(E$3/100)^2/2)*Assumptions!$B$9)/((E$3/100)*Assumptions!$B$10))-(E$3/100)*Assumptions!$B$10)))) | F4: =Assumptions!$B$5*(MAX(0,Assumptions!$B$2*EXP(-Assumptions!$B$4*Assumptions!$B$9)*NORMSDIST(((LN(Assumptions!$B$2/$B4)+(Assumptions!$B$3-Assumptions!$B$4+(F$3/100)^2/2)*Assumptions!$B$9)/((F$3/100)*Assumptions!$B$10)))-$B4*EXP(-Assumptions!$B$3*Assumptions!$B$9)*NORMSDIST((((LN(Assumptions!$B$2/$B4)+(Assumptions!$B$3-Assumptions!$B$4+(F$3/100)^2/2)*Assumptions!$B$9)/((F$3/100)*Assumptions!$B$10))-(F$3/100)*Assumptions!$B$10)))) | G4: =Assumptions!$B$5*(MAX(0,Assumptions!$B$2*EXP(-Assumptions!$B$4*Assumptions!$B$9)*NORMSDIST(((LN(Assumptions!$B$2/$B4)+(Assumptions!$B$3-Assumptions!$B$4+(G$3/100)^2/2)*Assumptions!$B$9)/((G$3/100)*Assumptions!$B$10)))-$B4*EXP(-Assumptions!$B$3*Assumptions!$B$9)*NORMSDIST((((LN(Assumptions!$B$2/$B4)+(Assumptions!$B$3-Assumptions!$B$4+(G$3/100)^2/2)*Assumptions!$B$9)/((G$3/100)*Assumptions!$B$10))-(G$3/100)*Assumptions!$B$10)))) | H4: =Assumptions!$B$5*(MAX(0,Assumptions!$B$2*EXP(-Assumptions!$B$4*Assumptions!$B$9)*NORMSDIST(((LN(Assumptions!$B$2/$B4)+(Assumptions!$B$3-Assumptions!$B$4+(H$3/100)^2/2)*Assumptions!$B$9)/((H$3/100)*Assumptions!$B$10)))-$B4*EXP(-Assumptions!$B$3*Assumptions!$B$9)*NORMSDIST((((LN(Assumptions!$B$2/$B4)+(Assumptions!$B$3-Assumptions!$B$4+(H$3/100)^2/2)*Assumptions!$B$9)/((H$3/100)*Assumptions!$B$10))-(H$3/100)*Assumptions!$B$10)))) | I4: =Assumptions!$B$5*(MAX(0,Assumptions!$B$2*EXP(-Assumptions!$B$4*Assumptions!$B$9)*NORMSDIST(((LN(Assumptions!$B$2/$B4)+(Assumptions!$B$3-Assumptions!$B$4+(I$3/100)^2/2)*Assumptions!$B$9)/((I$3/100)*Assumptions!$B$10)))-$B4*EXP(-Assumptions!$B$3*Assumptions!$B$9)*NORMSDIST((((LN(Assumptions!$B$2/$B4)+(Assumptions!$B$3-Assumptions!$B$4+(I$3/100)^2/2)*Assumptions!$B$9)/((I$3/100)*Assumptions!$B$10))-(I$3/100)*Assumptions!$B$10)))) | J4: =Assumptions!$B$5*(MAX(0,Assumptions!$B$2*EXP(-Assumptions!$B$4*Assumptions!$B$9)*NORMSDIST(((LN(Assumptions!$B$2/$B4)+(Assumptions!$B$3-Assumptions!$B$4+(J$3/100)^2/2)*Assumptions!$B$9)/((J$3/100)*Assumptions!$B$10)))-$B4*EXP(-Assumptions!$B$3*Assumptions!$B$9)*NORMSDIST((((LN(Assumptions!$B$2/$B4)+(Assumptions!$B$3-Assumptions!$B$4+(J$3/100)^2/2)*Assumptions!$B$9)/((J$3/100)*Assumptions!$B$10))-(J$3/100)*Assumptions!$B$10)))) | K4: =Assumptions!$B$5*(MAX(0,Assumptions!$B$2*EXP(-Assumptions!$B$4*Assumptions!$B$9)*NORMSDIST(((LN(Assumptions!$B$2/$B4)+(Assumptions!$B$3-Assumptions!$B$4+(K$3/100)^2/2)*Assumptions!$B$9)/((K$3/100)*Assumptions!$B$10)))-$B4*EXP(-Assumptions!$B$3*Assumptions!$B$9)*NORMSDIST((((LN(Assumptions!$B$2/$B4)+(Assumptions!$B$3-Assumptions!$B$4+(K$3/100)^2/2)*Assumptions!$B$9)/((K$3/100)*Assumptions!$B$10))-(K$3/100)*Assumptions!$B$10)))) | ... AV4: =Assumptions!$B$5*(MAX(0,Assumptions!$B$2*EXP(-Assumptions!$B$4*Assumptions!$B$9)*NORMSDIST(((LN(Assumptions!$B$2/$B4)+(Assumptions!$B$3-Assumptions!$B$4+(AV$3/100)^2/2)*Assumptions!$B$9)/((AV$3/100)*Assumptions!$B$10)))-$B4*EXP(-Assumptions!$B$3*Assumptions!$B$9)*NORMSDIST((((LN(Assumptions!$B$2/$B4)+(Assumptions!$B$3-Assumptions!$B$4+(AV$3/100)^2/2)*Assumptions!$B$9)/((AV$3/100)*Assumptions!$B$10))-(AV$3/100)*Assumptions!$B$10))))
A5: -1.75% | B5: ='BS Engine'!$B$3 | C5: ='BS Engine'!$C$3 | D5: =Assumptions!$B$5*(MAX(0,Assumptions!$B$2*EXP(-Assumptions!$B$4*Assumptions!$B$9)*NORMSDIST(((LN(Assumptions!$B$2/$B5)+(Assumptions!$B$3-Assumptions!$B$4+(D$3/100)^2/2)*Assumptions!$B$9)/((D$3/100)*Assumptions!$B$10)))-$B5*EXP(-Assumptions!$B$3*Assumptions!$B$9)*NORMSDIST((((LN(Assumptions!$B$2/$B5)+(Assumptions!$B$3-Assumptions!$B$4+(D$3/100)^2/2)*Assumptions!$B$9)/((D$3/100)*Assumptions!$B$10))-(D$3/100)*Assumptions!$B$10)))) | E5: =Assumptions!$B$5*(MAX(0,Assumptions!$B$2*EXP(-Assumptions!$B$4*Assumptions!$B$9)*NORMSDIST(((LN(Assumptions!$B$2/$B5)+(Assumptions!$B$3-Assumptions!$B$4+(E$3/100)^2/2)*Assumptions!$B$9)/((E$3/100)*Assumptions!$B$10)))-$B5*EXP(-Assumptions!$B$3*Assumptions!$B$9)*NORMSDIST((((LN(Assumptions!$B$2/$B5)+(Assumptions!$B$3-Assumptions!$B$4+(E$3/100)^2/2)*Assumptions!$B$9)/((E$3/100)*Assumptions!$B$10))-(E$3/100)*Assumptions!$B$10)))) | F5: =Assumptions!$B$5*(MAX(0,Assumptions!$B$2*EXP(-Assumptions!$B$4*Assumptions!$B$9)*NORMSDIST(((LN(Assumptions!$B$2/$B5)+(Assumptions!$B$3-Assumptions!$B$4+(F$3/100)^2/2)*Assumptions!$B$9)/((F$3/100)*Assumptions!$B$10)))-$B5*EXP(-Assumptions!$B$3*Assumptions!$B$9)*NORMSDIST((((LN(Assumptions!$B$2/$B5)+(Assumptions!$B$3-Assumptions!$B$4+(F$3/100)^2/2)*Assumptions!$B$9)/((F$3/100)*Assumptions!$B$10))-(F$3/100)*Assumptions!$B$10)))) | G5: =Assumptions!$B$5*(MAX(0,Assumptions!$B$2*EXP(-Assumptions!$B$4*Assumptions!$B$9)*NORMSDIST(((LN(Assumptions!$B$2/$B5)+(Assumptions!$B$3-Assumptions!$B$4+(G$3/100)^2/2)*Assumptions!$B$9)/((G$3/100)*Assumptions!$B$10)))-$B5*EXP(-Assumptions!$B$3*Assumptions!$B$9)*NORMSDIST((((LN(Assumptions!$B$2/$B5)+(Assumptions!$B$3-Assumptions!$B$4+(G$3/100)^2/2)*Assumptions!$B$9)/((G$3/100)*Assumptions!$B$10))-(G$3/100)*Assumptions!$B$10)))) | H5: =Assumptions!$B$5*(MAX(0,Assumptions!$B$2*EXP(-Assumptions!$B$4*Assumptions!$B$9)*NORMSDIST(((LN(Assumptions!$B$2/$B5)+(Assumptions!$B$3-Assumptions!$B$4+(H$3/100)^2/2)*Assumptions!$B$9)/((H$3/100)*Assumptions!$B$10)))-$B5*EXP(-Assumptions!$B$3*Assumptions!$B$9)*NORMSDIST((((LN(Assumptions!$B$2/$B5)+(Assumptions!$B$3-Assumptions!$B$4+(H$3/100)^2/2)*Assumptions!$B$9)/((H$3/100)*Assumptions!$B$10))-(H$3/100)*Assumptions!$B$10)))) | I5: =Assumptions!$B$5*(MAX(0,Assumptions!$B$2*EXP(-Assumptions!$B$4*Assumptions!$B$9)*NORMSDIST(((LN(Assumptions!$B$2/$B5)+(Assumptions!$B$3-Assumptions!$B$4+(I$3/100)^2/2)*Assumptions!$B$9)/((I$3/100)*Assumptions!$B$10)))-$B5*EXP(-Assumptions!$B$3*Assumptions!$B$9)*NORMSDIST((((LN(Assumptions!$B$2/$B5)+(Assumptions!$B$3-Assumptions!$B$4+(I$3/100)^2/2)*Assumptions!$B$9)/((I$3/100)*Assumptions!$B$10))-(I$3/100)*Assumptions!$B$10)))) | J5: =Assumptions!$B$5*(MAX(0,Assumptions!$B$2*EXP(-Assumptions!$B$4*Assumptions!$B$9)*NORMSDIST(((LN(Assumptions!$B$2/$B5)+(Assumptions!$B$3-Assumptions!$B$4+(J$3/100)^2/2)*Assumptions!$B$9)/((J$3/100)*Assumptions!$B$10)))-$B5*EXP(-Assumptions!$B$3*Assumptions!$B$9)*NORMSDIST((((LN(Assumptions!$B$2/$B5)+(Assumptions!$B$3-Assumptions!$B$4+(J$3/100)^2/2)*Assumptions!$B$9)/((J$3/100)*Assumptions!$B$10))-(J$3/100)*Assumptions!$B$10)))) | K5: =Assumptions!$B$5*(MAX(0,Assumptions!$B$2*EXP(-Assumptions!$B$4*Assumptions!$B$9)*NORMSDIST(((LN(Assumptions!$B$2/$B5)+(Assumptions!$B$3-Assumptions!$B$4+(K$3/100)^2/2)*Assumptions!$B$9)/((K$3/100)*Assumptions!$B$10)))-$B5*EXP(-Assumptions!$B$3*Assumptions!$B$9)*NORMSDIST((((LN(Assumptions!$B$2/$B5)+(Assumptions!$B$3-Assumptions!$B$4+(K$3/100)^2/2)*Assumptions!$B$9)/((K$3/100)*Assumptions!$B$10))-(K$3/100)*Assumptions!$B$10)))) | ... AV5: =Assumptions!$B$5*(MAX(0,Assumptions!$B$2*EXP(-Assumptions!$B$4*Assumptions!$B$9)*NORMSDIST(((LN(Assumptions!$B$2/$B5)+(Assumptions!$B$3-Assumptions!$B$4+(AV$3/100)^2/2)*Assumptions!$B$9)/((AV$3/100)*Assumptions!$B$10)))-$B5*EXP(-Assumptions!$B$3*Assumptions!$B$9)*NORMSDIST((((LN(Assumptions!$B$2/$B5)+(Assumptions!$B$3-Assumptions!$B$4+(AV$3/100)^2/2)*Assumptions!$B$9)/((AV$3/100)*Assumptions!$B$10))-(AV$3/100)*Assumptions!$B$10))))
A6: -1.50% | B6: ='BS Engine'!$B$4 | C6: ='BS Engine'!$C$4 | D6: =Assumptions!$B$5*(MAX(0,Assumptions!$B$2*EXP(-Assumptions!$B$4*Assumptions!$B$9)*NORMSDIST(((LN(Assumptions!$B$2/$B6)+(Assumptions!$B$3-Assumptions!$B$4+(D$3/100)^2/2)*Assumptions!$B$9)/((D$3/100)*Assumptions!$B$10)))-$B6*EXP(-Assumptions!$B$3*Assumptions!$B$9)*NORMSDIST((((LN(Assumptions!$B$2/$B6)+(Assumptions!$B$3-Assumptions!$B$4+(D$3/100)^2/2)*Assumptions!$B$9)/((D$3/100)*Assumptions!$B$10))-(D$3/100)*Assumptions!$B$10)))) | E6: =Assumptions!$B$5*(MAX(0,Assumptions!$B$2*EXP(-Assumptions!$B$4*Assumptions!$B$9)*NORMSDIST(((LN(Assumptions!$B$2/$B6)+(Assumptions!$B$3-Assumptions!$B$4+(E$3/100)^2/2)*Assumptions!$B$9)/((E$3/100)*Assumptions!$B$10)))-$B6*EXP(-Assumptions!$B$3*Assumptions!$B$9)*NORMSDIST((((LN(Assumptions!$B$2/$B6)+(Assumptions!$B$3-Assumptions!$B$4+(E$3/100)^2/2)*Assumptions!$B$9)/((E$3/100)*Assumptions!$B$10))-(E$3/100)*Assumptions!$B$10)))) | F6: =Assumptions!$B$5*(MAX(0,Assumptions!$B$2*EXP(-Assumptions!$B$4*Assumptions!$B$9)*NORMSDIST(((LN(Assumptions!$B$2/$B6)+(Assumptions!$B$3-Assumptions!$B$4+(F$3/100)^2/2)*Assumptions!$B$9)/((F$3/100)*Assumptions!$B$10)))-$B6*EXP(-Assumptions!$B$3*Assumptions!$B$9)*NORMSDIST((((LN(Assumptions!$B$2/$B6)+(Assumptions!$B$3-Assumptions!$B$4+(F$3/100)^2/2)*Assumptions!$B$9)/((F$3/100)*Assumptions!$B$10))-(F$3/100)*Assumptions!$B$10)))) | G6: =Assumptions!$B$5*(MAX(0,Assumptions!$B$2*EXP(-Assumptions!$B$4*Assumptions!$B$9)*NORMSDIST(((LN(Assumptions!$B$2/$B6)+(Assumptions!$B$3-Assumptions!$B$4+(G$3/100)^2/2)*Assumptions!$B$9)/((G$3/100)*Assumptions!$B$10)))-$B6*EXP(-Assumptions!$B$3*Assumptions!$B$9)*NORMSDIST((((LN(Assumptions!$B$2/$B6)+(Assumptions!$B$3-Assumptions!$B$4+(G$3/100)^2/2)*Assumptions!$B$9)/((G$3/100)*Assumptions!$B$10))-(G$3/100)*Assumptions!$B$10)))) | H6: =Assumptions!$B$5*(MAX(0,Assumptions!$B$2*EXP(-Assumptions!$B$4*Assumptions!$B$9)*NORMSDIST(((LN(Assumptions!$B$2/$B6)+(Assumptions!$B$3-Assumptions!$B$4+(H$3/100)^2/2)*Assumptions!$B$9)/((H$3/100)*Assumptions!$B$10)))-$B6*EXP(-Assumptions!$B$3*Assumptions!$B$9)*NORMSDIST((((LN(Assumptions!$B$2/$B6)+(Assumptions!$B$3-Assumptions!$B$4+(H$3/100)^2/2)*Assumptions!$B$9)/((H$3/100)*Assumptions!$B$10))-(H$3/100)*Assumptions!$B$10)))) | I6: =Assumptions!$B$5*(MAX(0,Assumptions!$B$2*EXP(-Assumptions!$B$4*Assumptions!$B$9)*NORMSDIST(((LN(Assumptions!$B$2/$B6)+(Assumptions!$B$3-Assumptions!$B$4+(I$3/100)^2/2)*Assumptions!$B$9)/((I$3/100)*Assumptions!$B$10)))-$B6*EXP(-Assumptions!$B$3*Assumptions!$B$9)*NORMSDIST((((LN(Assumptions!$B$2/$B6)+(Assumptions!$B$3-Assumptions!$B$4+(I$3/100)^2/2)*Assumptions!$B$9)/((I$3/100)*Assumptions!$B$10))-(I$3/100)*Assumptions!$B$10)))) | J6: =Assumptions!$B$5*(MAX(0,Assumptions!$B$2*EXP(-Assumptions!$B$4*Assumptions!$B$9)*NORMSDIST(((LN(Assumptions!$B$2/$B6)+(Assumptions!$B$3-Assumptions!$B$4+(J$3/100)^2/2)*Assumptions!$B$9)/((J$3/100)*Assumptions!$B$10)))-$B6*EXP(-Assumptions!$B$3*Assumptions!$B$9)*NORMSDIST((((LN(Assumptions!$B$2/$B6)+(Assumptions!$B$3-Assumptions!$B$4+(J$3/100)^2/2)*Assumptions!$B$9)/((J$3/100)*Assumptions!$B$10))-(J$3/100)*Assumptions!$B$10)))) | K6: =Assumptions!$B$5*(MAX(0,Assumptions!$B$2*EXP(-Assumptions!$B$4*Assumptions!$B$9)*NORMSDIST(((LN(Assumptions!$B$2/$B6)+(Assumptions!$B$3-Assumptions!$B$4+(K$3/100)^2/2)*Assumptions!$B$9)/((K$3/100)*Assumptions!$B$10)))-$B6*EXP(-Assumptions!$B$3*Assumptions!$B$9)*NORMSDIST((((LN(Assumptions!$B$2/$B6)+(Assumptions!$B$3-Assumptions!$B$4+(K$3/100)^2/2)*Assumptions!$B$9)/((K$3/100)*Assumptions!$B$10))-(K$3/100)*Assumptions!$B$10)))) | ... AV6: =Assumptions!$B$5*(MAX(0,Assumptions!$B$2*EXP(-Assumptions!$B$4*Assumptions!$B$9)*NORMSDIST(((LN(Assumptions!$B$2/$B6)+(Assumptions!$B$3-Assumptions!$B$4+(AV$3/100)^2/2)*Assumptions!$B$9)/((AV$3/100)*Assumptions!$B$10)))-$B6*EXP(-Assumptions!$B$3*Assumptions!$B$9)*NORMSDIST((((LN(Assumptions!$B$2/$B6)+(Assumptions!$B$3-Assumptions!$B$4+(AV$3/100)^2/2)*Assumptions!$B$9)/((AV$3/100)*Assumptions!$B$10))-(AV$3/100)*Assumptions!$B$10))))
A7: -1.25% | B7: ='BS Engine'!$B$5 | C7: ='BS Engine'!$C$5 | D7: =Assumptions!$B$5*(MAX(0,Assumptions!$B$2*EXP(-Assumptions!$B$4*Assumptions!$B$9)*NORMSDIST(((LN(Assumptions!$B$2/$B7)+(Assumptions!$B$3-Assumptions!$B$4+(D$3/100)^2/2)*Assumptions!$B$9)/((D$3/100)*Assumptions!$B$10)))-$B7*EXP(-Assumptions!$B$3*Assumptions!$B$9)*NORMSDIST((((LN(Assumptions!$B$2/$B7)+(Assumptions!$B$3-Assumptions!$B$4+(D$3/100)^2/2)*Assumptions!$B$9)/((D$3/100)*Assumptions!$B$10))-(D$3/100)*Assumptions!$B$10)))) | E7: =Assumptions!$B$5*(MAX(0,Assumptions!$B$2*EXP(-Assumptions!$B$4*Assumptions!$B$9)*NORMSDIST(((LN(Assumptions!$B$2/$B7)+(Assumptions!$B$3-Assumptions!$B$4+(E$3/100)^2/2)*Assumptions!$B$9)/((E$3/100)*Assumptions!$B$10)))-$B7*EXP(-Assumptions!$B$3*Assumptions!$B$9)*NORMSDIST((((LN(Assumptions!$B$2/$B7)+(Assumptions!$B$3-Assumptions!$B$4+(E$3/100)^2/2)*Assumptions!$B$9)/((E$3/100)*Assumptions!$B$10))-(E$3/100)*Assumptions!$B$10)))) | F7: =Assumptions!$B$5*(MAX(0,Assumptions!$B$2*EXP(-Assumptions!$B$4*Assumptions!$B$9)*NORMSDIST(((LN(Assumptions!$B$2/$B7)+(Assumptions!$B$3-Assumptions!$B$4+(F$3/100)^2/2)*Assumptions!$B$9)/((F$3/100)*Assumptions!$B$10)))-$B7*EXP(-Assumptions!$B$3*Assumptions!$B$9)*NORMSDIST((((LN(Assumptions!$B$2/$B7)+(Assumptions!$B$3-Assumptions!$B$4+(F$3/100)^2/2)*Assumptions!$B$9)/((F$3/100)*Assumptions!$B$10))-(F$3/100)*Assumptions!$B$10)))) | G7: =Assumptions!$B$5*(MAX(0,Assumptions!$B$2*EXP(-Assumptions!$B$4*Assumptions!$B$9)*NORMSDIST(((LN(Assumptions!$B$2/$B7)+(Assumptions!$B$3-Assumptions!$B$4+(G$3/100)^2/2)*Assumptions!$B$9)/((G$3/100)*Assumptions!$B$10)))-$B7*EXP(-Assumptions!$B$3*Assumptions!$B$9)*NORMSDIST((((LN(Assumptions!$B$2/$B7)+(Assumptions!$B$3-Assumptions!$B$4+(G$3/100)^2/2)*Assumptions!$B$9)/((G$3/100)*Assumptions!$B$10))-(G$3/100)*Assumptions!$B$10)))) | H7: =Assumptions!$B$5*(MAX(0,Assumptions!$B$2*EXP(-Assumptions!$B$4*Assumptions!$B$9)*NORMSDIST(((LN(Assumptions!$B$2/$B7)+(Assumptions!$B$3-Assumptions!$B$4+(H$3/100)^2/2)*Assumptions!$B$9)/((H$3/100)*Assumptions!$B$10)))-$B7*EXP(-Assumptions!$B$3*Assumptions!$B$9)*NORMSDIST((((LN(Assumptions!$B$2/$B7)+(Assumptions!$B$3-Assumptions!$B$4+(H$3/100)^2/2)*Assumptions!$B$9)/((H$3/100)*Assumptions!$B$10))-(H$3/100)*Assumptions!$B$10)))) | I7: =Assumptions!$B$5*(MAX(0,Assumptions!$B$2*EXP(-Assumptions!$B$4*Assumptions!$B$9)*NORMSDIST(((LN(Assumptions!$B$2/$B7)+(Assumptions!$B$3-Assumptions!$B$4+(I$3/100)^2/2)*Assumptions!$B$9)/((I$3/100)*Assumptions!$B$10)))-$B7*EXP(-Assumptions!$B$3*Assumptions!$B$9)*NORMSDIST((((LN(Assumptions!$B$2/$B7)+(Assumptions!$B$3-Assumptions!$B$4+(I$3/100)^2/2)*Assumptions!$B$9)/((I$3/100)*Assumptions!$B$10))-(I$3/100)*Assumptions!$B$10)))) | J7: =Assumptions!$B$5*(MAX(0,Assumptions!$B$2*EXP(-Assumptions!$B$4*Assumptions!$B$9)*NORMSDIST(((LN(Assumptions!$B$2/$B7)+(Assumptions!$B$3-Assumptions!$B$4+(J$3/100)^2/2)*Assumptions!$B$9)/((J$3/100)*Assumptions!$B$10)))-$B7*EXP(-Assumptions!$B$3*Assumptions!$B$9)*NORMSDIST((((LN(Assumptions!$B$2/$B7)+(Assumptions!$B$3-Assumptions!$B$4+(J$3/100)^2/2)*Assumptions!$B$9)/((J$3/100)*Assumptions!$B$10))-(J$3/100)*Assumptions!$B$10)))) | K7: =Assumptions!$B$5*(MAX(0,Assumptions!$B$2*EXP(-Assumptions!$B$4*Assumptions!$B$9)*NORMSDIST(((LN(Assumptions!$B$2/$B7)+(Assumptions!$B$3-Assumptions!$B$4+(K$3/100)^2/2)*Assumptions!$B$9)/((K$3/100)*Assumptions!$B$10)))-$B7*EXP(-Assumptions!$B$3*Assumptions!$B$9)*NORMSDIST((((LN(Assumptions!$B$2/$B7)+(Assumptions!$B$3-Assumptions!$B$4+(K$3/100)^2/2)*Assumptions!$B$9)/((K$3/100)*Assumptions!$B$10))-(K$3/100)*Assumptions!$B$10)))) | ... AV7: =Assumptions!$B$5*(MAX(0,Assumptions!$B$2*EXP(-Assumptions!$B$4*Assumptions!$B$9)*NORMSDIST(((LN(Assumptions!$B$2/$B7)+(Assumptions!$B$3-Assumptions!$B$4+(AV$3/100)^2/2)*Assumptions!$B$9)/((AV$3/100)*Assumptions!$B$10)))-$B7*EXP(-Assumptions!$B$3*Assumptions!$B$9)*NORMSDIST((((LN(Assumptions!$B$2/$B7)+(Assumptions!$B$3-Assumptions!$B$4+(AV$3/100)^2/2)*Assumptions!$B$9)/((AV$3/100)*Assumptions!$B$10))-(AV$3/100)*Assumptions!$B$10))))
A8: -1.00% | B8: ='BS Engine'!$B$6 | C8: ='BS Engine'!$C$6 | D8: =Assumptions!$B$5*(MAX(0,Assumptions!$B$2*EXP(-Assumptions!$B$4*Assumptions!$B$9)*NORMSDIST(((LN(Assumptions!$B$2/$B8)+(Assumptions!$B$3-Assumptions!$B$4+(D$3/100)^2/2)*Assumptions!$B$9)/((D$3/100)*Assumptions!$B$10)))-$B8*EXP(-Assumptions!$B$3*Assumptions!$B$9)*NORMSDIST((((LN(Assumptions!$B$2/$B8)+(Assumptions!$B$3-Assumptions!$B$4+(D$3/100)^2/2)*Assumptions!$B$9)/((D$3/100)*Assumptions!$B$10))-(D$3/100)*Assumptions!$B$10)))) | E8: =Assumptions!$B$5*(MAX(0,Assumptions!$B$2*EXP(-Assumptions!$B$4*Assumptions!$B$9)*NORMSDIST(((LN(Assumptions!$B$2/$B8)+(Assumptions!$B$3-Assumptions!$B$4+(E$3/100)^2/2)*Assumptions!$B$9)/((E$3/100)*Assumptions!$B$10)))-$B8*EXP(-Assumptions!$B$3*Assumptions!$B$9)*NORMSDIST((((LN(Assumptions!$B$2/$B8)+(Assumptions!$B$3-Assumptions!$B$4+(E$3/100)^2/2)*Assumptions!$B$9)/((E$3/100)*Assumptions!$B$10))-(E$3/100)*Assumptions!$B$10)))) | F8: =Assumptions!$B$5*(MAX(0,Assumptions!$B$2*EXP(-Assumptions!$B$4*Assumptions!$B$9)*NORMSDIST(((LN(Assumptions!$B$2/$B8)+(Assumptions!$B$3-Assumptions!$B$4+(F$3/100)^2/2)*Assumptions!$B$9)/((F$3/100)*Assumptions!$B$10)))-$B8*EXP(-Assumptions!$B$3*Assumptions!$B$9)*NORMSDIST((((LN(Assumptions!$B$2/$B8)+(Assumptions!$B$3-Assumptions!$B$4+(F$3/100)^2/2)*Assumptions!$B$9)/((F$3/100)*Assumptions!$B$10))-(F$3/100)*Assumptions!$B$10)))) | G8: =Assumptions!$B$5*(MAX(0,Assumptions!$B$2*EXP(-Assumptions!$B$4*Assumptions!$B$9)*NORMSDIST(((LN(Assumptions!$B$2/$B8)+(Assumptions!$B$3-Assumptions!$B$4+(G$3/100)^2/2)*Assumptions!$B$9)/((G$3/100)*Assumptions!$B$10)))-$B8*EXP(-Assumptions!$B$3*Assumptions!$B$9)*NORMSDIST((((LN(Assumptions!$B$2/$B8)+(Assumptions!$B$3-Assumptions!$B$4+(G$3/100)^2/2)*Assumptions!$B$9)/((G$3/100)*Assumptions!$B$10))-(G$3/100)*Assumptions!$B$10)))) | H8: =Assumptions!$B$5*(MAX(0,Assumptions!$B$2*EXP(-Assumptions!$B$4*Assumptions!$B$9)*NORMSDIST(((LN(Assumptions!$B$2/$B8)+(Assumptions!$B$3-Assumptions!$B$4+(H$3/100)^2/2)*Assumptions!$B$9)/((H$3/100)*Assumptions!$B$10)))-$B8*EXP(-Assumptions!$B$3*Assumptions!$B$9)*NORMSDIST((((LN(Assumptions!$B$2/$B8)+(Assumptions!$B$3-Assumptions!$B$4+(H$3/100)^2/2)*Assumptions!$B$9)/((H$3/100)*Assumptions!$B$10))-(H$3/100)*Assumptions!$B$10)))) | I8: =Assumptions!$B$5*(MAX(0,Assumptions!$B$2*EXP(-Assumptions!$B$4*Assumptions!$B$9)*NORMSDIST(((LN(Assumptions!$B$2/$B8)+(Assumptions!$B$3-Assumptions!$B$4+(I$3/100)^2/2)*Assumptions!$B$9)/((I$3/100)*Assumptions!$B$10)))-$B8*EXP(-Assumptions!$B$3*Assumptions!$B$9)*NORMSDIST((((LN(Assumptions!$B$2/$B8)+(Assumptions!$B$3-Assumptions!$B$4+(I$3/100)^2/2)*Assumptions!$B$9)/((I$3/100)*Assumptions!$B$10))-(I$3/100)*Assumptions!$B$10)))) | J8: =Assumptions!$B$5*(MAX(0,Assumptions!$B$2*EXP(-Assumptions!$B$4*Assumptions!$B$9)*NORMSDIST(((LN(Assumptions!$B$2/$B8)+(Assumptions!$B$3-Assumptions!$B$4+(J$3/100)^2/2)*Assumptions!$B$9)/((J$3/100)*Assumptions!$B$10)))-$B8*EXP(-Assumptions!$B$3*Assumptions!$B$9)*NORMSDIST((((LN(Assumptions!$B$2/$B8)+(Assumptions!$B$3-Assumptions!$B$4+(J$3/100)^2/2)*Assumptions!$B$9)/((J$3/100)*Assumptions!$B$10))-(J$3/100)*Assumptions!$B$10)))) | K8: =Assumptions!$B$5*(MAX(0,Assumptions!$B$2*EXP(-Assumptions!$B$4*Assumptions!$B$9)*NORMSDIST(((LN(Assumptions!$B$2/$B8)+(Assumptions!$B$3-Assumptions!$B$4+(K$3/100)^2/2)*Assumptions!$B$9)/((K$3/100)*Assumptions!$B$10)))-$B8*EXP(-Assumptions!$B$3*Assumptions!$B$9)*NORMSDIST((((LN(Assumptions!$B$2/$B8)+(Assumptions!$B$3-Assumptions!$B$4+(K$3/100)^2/2)*Assumptions!$B$9)/((K$3/100)*Assumptions!$B$10))-(K$3/100)*Assumptions!$B$10)))) | ... AV8: =Assumptions!$B$5*(MAX(0,Assumptions!$B$2*EXP(-Assumptions!$B$4*Assumptions!$B$9)*NORMSDIST(((LN(Assumptions!$B$2/$B8)+(Assumptions!$B$3-Assumptions!$B$4+(AV$3/100)^2/2)*Assumptions!$B$9)/((AV$3/100)*Assumptions!$B$10)))-$B8*EXP(-Assumptions!$B$3*Assumptions!$B$9)*NORMSDIST((((LN(Assumptions!$B$2/$B8)+(Assumptions!$B$3-Assumptions!$B$4+(AV$3/100)^2/2)*Assumptions!$B$9)/((AV$3/100)*Assumptions!$B$10))-(AV$3/100)*Assumptions!$B$10))))
