Workbook

Sheet USD summary 2005-2025
A1: UBS wealth management – revenue mix in USD, 2005–2025
A2: All figures USD millions, CHF years converted at each year's average rate (FX tab). A year shows a number only when every unit in that year has it; otherwise the cell is blank – see Raw data for the unit-level figures.
A4: Year | B4: Perimeter | C4: Basis | D4: Total revenue (USD m) | E4: Net interest income | F4: Recurring net fees | G4: Transaction-based | H4: Other revenues | I4: Recurring (old: NII+fees) | J4: Non-recurring (old) | K4: Sum of income lines | L4: NII share | M4: Recurring fee share | N4: Transaction share | O4: Other revenues share | P4: Recurring share (NII+fees) – continuous series | Q4: Note
A5: 2005 | B5: WM Intl & Switzerland + WM US | C5: Old (recurring vs non-recurring) | D5: =IF(SUMPRODUCT(('Raw data (as reported)'!$A$5:$A$37=$A5)*ISNUMBER('Raw data (as reported)'!T$5:T$37))=COUNTIF('Raw data (as reported)'!$A$5:$A$37,$A5),SUMIFS('Raw data (as reported)'!T$5:T$37,'Raw data (as reported)'!$A$5:$A$37,$A5),"") -> 11370.897 | E5: =IF(SUMPRODUCT(('Raw data (as reported)'!$A$5:$A$37=$A5)*ISNUMBER('Raw data (as reported)'!N$5:N$37))=COUNTIF('Raw data (as reported)'!$A$5:$A$37,$A5),SUMIFS('Raw data (as reported)'!N$5:N$37,'Raw data (as reported)'!$A$5:$A$37,$A5),"") | F5: =IF(SUMPRODUCT(('Raw data (as reported)'!$A$5:$A$37=$A5)*ISNUMBER('Raw data (as reported)'!O$5:O$37))=COUNTIF('Raw data (as reported)'!$A$5:$A$37,$A5),SUMIFS('Raw data (as reported)'!O$5:O$37,'Raw data (as reported)'!$A$5:$A$37,$A5),"") | G5: =IF(SUMPRODUCT(('Raw data (as reported)'!$A$5:$A$37=$A5)*ISNUMBER('Raw data (as reported)'!P$5:P$37))=COUNTIF('Raw data (as reported)'!$A$5:$A$37,$A5),SUMIFS('Raw data (as reported)'!P$5:P$37,'Raw data (as reported)'!$A$5:$A$37,$A5),"") | H5: =IF(SUMPRODUCT(('Raw data (as reported)'!$A$5:$A$37=$A5)*ISNUMBER('Raw data (as reported)'!Q$5:Q$37))=COUNTIF('Raw data (as reported)'!$A$5:$A$37,$A5),SUMIFS('Raw data (as reported)'!Q$5:Q$37,'Raw data (as reported)'!$A$5:$A$37,$A5),"") | I5: =IF(SUMPRODUCT(('Raw data (as reported)'!$A$5:$A$37=$A5)*ISNUMBER('Raw data (as reported)'!R$5:R$37))=COUNTIF('Raw data (as reported)'!$A$5:$A$37,$A5),SUMIFS('Raw data (as reported)'!R$5:R$37,'Raw data (as reported)'!$A$5:$A$37,$A5),"") | J5: =IF(SUMPRODUCT(('Raw data (as reported)'!$A$5:$A$37=$A5)*ISNUMBER('Raw data (as reported)'!S$5:S$37))=COUNTIF('Raw data (as reported)'!$A$5:$A$37,$A5),SUMIFS('Raw data (as reported)'!S$5:S$37,'Raw data (as reported)'!$A$5:$A$37,$A5),"") | K5: =IF(AND(ISNUMBER(E5),ISNUMBER(F5),ISNUMBER(G5)),E5+F5+G5+IF(ISNUMBER(H5),H5,0),"") | L5: =IF(ISNUMBER(K5),E5/K5,"") | M5: =IF(ISNUMBER(K5),F5/K5,"") | N5: =IF(ISNUMBER(K5),G5/K5,"") | O5: =IF(AND(ISNUMBER(K5),ISNUMBER(H5)),H5/K5,"") | P5: =IF(ISNUMBER(K5),(E5+F5)/K5,IF(AND(ISNUMBER(I5),ISNUMBER(J5)),I5/(I5+J5),"")) | Q5: Recurring split only for WM US (55% recurring) – see Raw.
A6: 2006 | B6: WM Intl & Switzerland + WM US | C6: Old (recurring vs non-recurring) | D6: =IF(SUMPRODUCT(('Raw data (as reported)'!$A$5:$A$37=$A6)*ISNUMBER('Raw data (as reported)'!T$5:T$37))=COUNTIF('Raw data (as reported)'!$A$5:$A$37,$A6),SUMIFS('Raw data (as reported)'!T$5:T$37,'Raw data (as reported)'!$A$5:$A$37,$A6),"") -> 13294.765 | E6: =IF(SUMPRODUCT(('Raw data (as reported)'!$A$5:$A$37=$A6)*ISNUMBER('Raw data (as reported)'!N$5:N$37))=COUNTIF('Raw data (as reported)'!$A$5:$A$37,$A6),SUMIFS('Raw data (as reported)'!N$5:N$37,'Raw data (as reported)'!$A$5:$A$37,$A6),"") | F6: =IF(SUMPRODUCT(('Raw data (as reported)'!$A$5:$A$37=$A6)*ISNUMBER('Raw data (as reported)'!O$5:O$37))=COUNTIF('Raw data (as reported)'!$A$5:$A$37,$A6),SUMIFS('Raw data (as reported)'!O$5:O$37,'Raw data (as reported)'!$A$5:$A$37,$A6),"") | G6: =IF(SUMPRODUCT(('Raw data (as reported)'!$A$5:$A$37=$A6)*ISNUMBER('Raw data (as reported)'!P$5:P$37))=COUNTIF('Raw data (as reported)'!$A$5:$A$37,$A6),SUMIFS('Raw data (as reported)'!P$5:P$37,'Raw data (as reported)'!$A$5:$A$37,$A6),"") | H6: =IF(SUMPRODUCT(('Raw data (as reported)'!$A$5:$A$37=$A6)*ISNUMBER('Raw data (as reported)'!Q$5:Q$37))=COUNTIF('Raw data (as reported)'!$A$5:$A$37,$A6),SUMIFS('Raw data (as reported)'!Q$5:Q$37,'Raw data (as reported)'!$A$5:$A$37,$A6),"") | I6: =IF(SUMPRODUCT(('Raw data (as reported)'!$A$5:$A$37=$A6)*ISNUMBER('Raw data (as reported)'!R$5:R$37))=COUNTIF('Raw data (as reported)'!$A$5:$A$37,$A6),SUMIFS('Raw data (as reported)'!R$5:R$37,'Raw data (as reported)'!$A$5:$A$37,$A6),"") | J6: =IF(SUMPRODUCT(('Raw data (as reported)'!$A$5:$A$37=$A6)*ISNUMBER('Raw data (as reported)'!S$5:S$37))=COUNTIF('Raw data (as reported)'!$A$5:$A$37,$A6),SUMIFS('Raw data (as reported)'!S$5:S$37,'Raw data (as reported)'!$A$5:$A$37,$A6),"") | K6: =IF(AND(ISNUMBER(E6),ISNUMBER(F6),ISNUMBER(G6)),E6+F6+G6+IF(ISNUMBER(H6),H6,0),"") | L6: =IF(ISNUMBER(K6),E6/K6,"") | M6: =IF(ISNUMBER(K6),F6/K6,"") | N6: =IF(ISNUMBER(K6),G6/K6,"") | O6: =IF(AND(ISNUMBER(K6),ISNUMBER(H6)),H6/K6,"") | P6: =IF(ISNUMBER(K6),(E6+F6)/K6,IF(AND(ISNUMBER(I6),ISNUMBER(J6)),I6/(I6+J6),"")) | Q6: Recurring split only for WM US (59% recurring) – see Raw.
A7: 2007 | B7: WM Intl & Switzerland + WM US | C7: Old (recurring vs non-recurring) | D7: =IF(SUMPRODUCT(('Raw data (as reported)'!$A$5:$A$37=$A7)*ISNUMBER('Raw data (as reported)'!T$5:T$37))=COUNTIF('Raw data (as reported)'!$A$5:$A$37,$A7),SUMIFS('Raw data (as reported)'!T$5:T$37,'Raw data (as reported)'!$A$5:$A$37,$A7),"") | E7: =IF(SUMPRODUCT(('Raw data (as reported)'!$A$5:$A$37=$A7)*ISNUMBER('Raw data (as reported)'!N$5:N$37))=COUNTIF('Raw data (as reported)'!$A$5:$A$37,$A7),SUMIFS('Raw data (as reported)'!N$5:N$37,'Raw data (as reported)'!$A$5:$A$37,$A7),"") | F7: =IF(SUMPRODUCT(('Raw data (as reported)'!$A$5:$A$37=$A7)*ISNUMBER('Raw data (as reported)'!O$5:O$37))=COUNTIF('Raw data (as reported)'!$A$5:$A$37,$A7),SUMIFS('Raw data (as reported)'!O$5:O$37,'Raw data (as reported)'!$A$5:$A$37,$A7),"") | G7: =IF(SUMPRODUCT(('Raw data (as reported)'!$A$5:$A$37=$A7)*ISNUMBER('Raw data (as reported)'!P$5:P$37))=COUNTIF('Raw data (as reported)'!$A$5:$A$37,$A7),SUMIFS('Raw data (as reported)'!P$5:P$37,'Raw data (as reported)'!$A$5:$A$37,$A7),"") | H7: =IF(SUMPRODUCT(('Raw data (as reported)'!$A$5:$A$37=$A7)*ISNUMBER('Raw data (as reported)'!Q$5:Q$37))=COUNTIF('Raw data (as reported)'!$A$5:$A$37,$A7),SUMIFS('Raw data (as reported)'!Q$5:Q$37,'Raw data (as reported)'!$A$5:$A$37,$A7),"") | I7: =IF(SUMPRODUCT(('Raw data (as reported)'!$A$5:$A$37=$A7)*ISNUMBER('Raw data (as reported)'!R$5:R$37))=COUNTIF('Raw data (as reported)'!$A$5:$A$37,$A7),SUMIFS('Raw data (as reported)'!R$5:R$37,'Raw data (as reported)'!$A$5:$A$37,$A7),"") | J7: =IF(SUMPRODUCT(('Raw data (as reported)'!$A$5:$A$37=$A7)*ISNUMBER('Raw data (as reported)'!S$5:S$37))=COUNTIF('Raw data (as reported)'!$A$5:$A$37,$A7),SUMIFS('Raw data (as reported)'!S$5:S$37,'Raw data (as reported)'!$A$5:$A$37,$A7),"") | K7: =IF(AND(ISNUMBER(E7),ISNUMBER(F7),ISNUMBER(G7)),E7+F7+G7+IF(ISNUMBER(H7),H7,0),"") | L7: =IF(ISNUMBER(K7),E7/K7,"") | M7: =IF(ISNUMBER(K7),F7/K7,"") | N7: =IF(ISNUMBER(K7),G7/K7,"") | O7: =IF(AND(ISNUMBER(K7),ISNUMBER(H7)),H7/K7,"") | P7: =IF(ISNUMBER(K7),(E7+F7)/K7,IF(AND(ISNUMBER(I7),ISNUMBER(J7)),I7/(I7+J7),"")) | Q7: Annual totals not found; WM US recurring USD 3.5bn. 3Q07 Intl & Swiss unit: 75% recurring.
A8: 2008 | B8: WM + WM Americas | C8: Old (recurring vs non-recurring) | D8: =IF(SUMPRODUCT(('Raw data (as reported)'!$A$5:$A$37=$A8)*ISNUMBER('Raw data (as reported)'!T$5:T$37))=COUNTIF('Raw data (as reported)'!$A$5:$A$37,$A8),SUMIFS('Raw data (as reported)'!T$5:T$37,'Raw data (as reported)'!$A$5:$A$37,$A8),"") | E8: =IF(SUMPRODUCT(('Raw data (as reported)'!$A$5:$A$37=$A8)*ISNUMBER('Raw data (as reported)'!N$5:N$37))=COUNTIF('Raw data (as reported)'!$A$5:$A$37,$A8),SUMIFS('Raw data (as reported)'!N$5:N$37,'Raw data (as reported)'!$A$5:$A$37,$A8),"") | F8: =IF(SUMPRODUCT(('Raw data (as reported)'!$A$5:$A$37=$A8)*ISNUMBER('Raw data (as reported)'!O$5:O$37))=COUNTIF('Raw data (as reported)'!$A$5:$A$37,$A8),SUMIFS('Raw data (as reported)'!O$5:O$37,'Raw data (as reported)'!$A$5:$A$37,$A8),"") | G8: =IF(SUMPRODUCT(('Raw data (as reported)'!$A$5:$A$37=$A8)*ISNUMBER('Raw data (as reported)'!P$5:P$37))=COUNTIF('Raw data (as reported)'!$A$5:$A$37,$A8),SUMIFS('Raw data (as reported)'!P$5:P$37,'Raw data (as reported)'!$A$5:$A$37,$A8),"") | H8: =IF(SUMPRODUCT(('Raw data (as reported)'!$A$5:$A$37=$A8)*ISNUMBER('Raw data (as reported)'!Q$5:Q$37))=COUNTIF('Raw data (as reported)'!$A$5:$A$37,$A8),SUMIFS('Raw data (as reported)'!Q$5:Q$37,'Raw data (as reported)'!$A$5:$A$37,$A8),"") | I8: =IF(SUMPRODUCT(('Raw data (as reported)'!$A$5:$A$37=$A8)*ISNUMBER('Raw data (as reported)'!R$5:R$37))=COUNTIF('Raw data (as reported)'!$A$5:$A$37,$A8),SUMIFS('Raw data (as reported)'!R$5:R$37,'Raw data (as reported)'!$A$5:$A$37,$A8),"") | J8: =IF(SUMPRODUCT(('Raw data (as reported)'!$A$5:$A$37=$A8)*ISNUMBER('Raw data (as reported)'!S$5:S$37))=COUNTIF('Raw data (as reported)'!$A$5:$A$37,$A8),SUMIFS('Raw data (as reported)'!S$5:S$37,'Raw data (as reported)'!$A$5:$A$37,$A8),"") | K8: =IF(AND(ISNUMBER(E8),ISNUMBER(F8),ISNUMBER(G8)),E8+F8+G8+IF(ISNUMBER(H8),H8,0),"") | L8: =IF(ISNUMBER(K8),E8/K8,"") | M8: =IF(ISNUMBER(K8),F8/K8,"") | N8: =IF(ISNUMBER(K8),G8/K8,"") | O8: =IF(AND(ISNUMBER(K8),ISNUMBER(H8)),H8/K8,"") | P8: =IF(ISNUMBER(K8),(E8+F8)/K8,IF(AND(ISNUMBER(I8),ISNUMBER(J8)),I8/(I8+J8),"")) | Q8: Only WM Americas found (65% recurring) – see Raw.
A9: 2009 | B9: WM + WM Americas | C9: Old (recurring vs non-recurring) | D9: =IF(SUMPRODUCT(('Raw data (as reported)'!$A$5:$A$37=$A9)*ISNUMBER('Raw data (as reported)'!T$5:T$37))=COUNTIF('Raw data (as reported)'!$A$5:$A$37,$A9),SUMIFS('Raw data (as reported)'!T$5:T$37,'Raw data (as reported)'!$A$5:$A$37,$A9),"") -> 11945.672 | E9: =IF(SUMPRODUCT(('Raw data (as reported)'!$A$5:$A$37=$A9)*ISNUMBER('Raw data (as reported)'!N$5:N$37))=COUNTIF('Raw data (as reported)'!$A$5:$A$37,$A9),SUMIFS('Raw data (as reported)'!N$5:N$37,'Raw data (as reported)'!$A$5:$A$37,$A9),"") | F9: =IF(SUMPRODUCT(('Raw data (as reported)'!$A$5:$A$37=$A9)*ISNUMBER('Raw data (as reported)'!O$5:O$37))=COUNTIF('Raw data (as reported)'!$A$5:$A$37,$A9),SUMIFS('Raw data (as reported)'!O$5:O$37,'Raw data (as reported)'!$A$5:$A$37,$A9),"") | G9: =IF(SUMPRODUCT(('Raw data (as reported)'!$A$5:$A$37=$A9)*ISNUMBER('Raw data (as reported)'!P$5:P$37))=COUNTIF('Raw data (as reported)'!$A$5:$A$37,$A9),SUMIFS('Raw data (as reported)'!P$5:P$37,'Raw data (as reported)'!$A$5:$A$37,$A9),"") | H9: =IF(SUMPRODUCT(('Raw data (as reported)'!$A$5:$A$37=$A9)*ISNUMBER('Raw data (as reported)'!Q$5:Q$37))=COUNTIF('Raw data (as reported)'!$A$5:$A$37,$A9),SUMIFS('Raw data (as reported)'!Q$5:Q$37,'Raw data (as reported)'!$A$5:$A$37,$A9),"") | I9: =IF(SUMPRODUCT(('Raw data (as reported)'!$A$5:$A$37=$A9)*ISNUMBER('Raw data (as reported)'!R$5:R$37))=COUNTIF('Raw data (as reported)'!$A$5:$A$37,$A9),SUMIFS('Raw data (as reported)'!R$5:R$37,'Raw data (as reported)'!$A$5:$A$37,$A9),"") -> 8243.0939 | J9: =IF(SUMPRODUCT(('Raw data (as reported)'!$A$5:$A$37=$A9)*ISNUMBER('Raw data (as reported)'!S$5:S$37))=COUNTIF('Raw data (as reported)'!$A$5:$A$37,$A9),SUMIFS('Raw data (as reported)'!S$5:S$37,'Raw data (as reported)'!$A$5:$A$37,$A9),"") -> 3702.5783 | K9: =IF(AND(ISNUMBER(E9),ISNUMBER(F9),ISNUMBER(G9)),E9+F9+G9+IF(ISNUMBER(H9),H9,0),"") | L9: =IF(ISNUMBER(K9),E9/K9,"") | M9: =IF(ISNUMBER(K9),F9/K9,"") | N9: =IF(ISNUMBER(K9),G9/K9,"") | O9: =IF(AND(ISNUMBER(K9),ISNUMBER(H9)),H9/K9,"") | P9: =IF(ISNUMBER(K9),(E9+F9)/K9,IF(AND(ISNUMBER(I9),ISNUMBER(J9)),I9/(I9+J9),"")) -> 0.69004856
A10: 2010 | B10: WM + WM Americas | C10: Old (recurring vs non-recurring) | D10: =IF(SUMPRODUCT(('Raw data (as reported)'!$A$5:$A$37=$A10)*ISNUMBER('Raw data (as reported)'!T$5:T$37))=COUNTIF('Raw data (as reported)'!$A$5:$A$37,$A10),SUMIFS('Raw data (as reported)'!T$5:T$37,'Raw data (as reported)'!$A$5:$A$37,$A10),"") -> 12375.383 | E10: =IF(SUMPRODUCT(('Raw data (as reported)'!$A$5:$A$37=$A10)*ISNUMBER('Raw data (as reported)'!N$5:N$37))=COUNTIF('Raw data (as reported)'!$A$5:$A$37,$A10),SUMIFS('Raw data (as reported)'!N$5:N$37,'Raw data (as reported)'!$A$5:$A$37,$A10),"") | F10: =IF(SUMPRODUCT(('Raw data (as reported)'!$A$5:$A$37=$A10)*ISNUMBER('Raw data (as reported)'!O$5:O$37))=COUNTIF('Raw data (as reported)'!$A$5:$A$37,$A10),SUMIFS('Raw data (as reported)'!O$5:O$37,'Raw data (as reported)'!$A$5:$A$37,$A10),"") | G10: =IF(SUMPRODUCT(('Raw data (as reported)'!$A$5:$A$37=$A10)*ISNUMBER('Raw data (as reported)'!P$5:P$37))=COUNTIF('Raw data (as reported)'!$A$5:$A$37,$A10),SUMIFS('Raw data (as reported)'!P$5:P$37,'Raw data (as reported)'!$A$5:$A$37,$A10),"") | H10: =IF(SUMPRODUCT(('Raw data (as reported)'!$A$5:$A$37=$A10)*ISNUMBER('Raw data (as reported)'!Q$5:Q$37))=COUNTIF('Raw data (as reported)'!$A$5:$A$37,$A10),SUMIFS('Raw data (as reported)'!Q$5:Q$37,'Raw data (as reported)'!$A$5:$A$37,$A10),"") | I10: =IF(SUMPRODUCT(('Raw data (as reported)'!$A$5:$A$37=$A10)*ISNUMBER('Raw data (as reported)'!R$5:R$37))=COUNTIF('Raw data (as reported)'!$A$5:$A$37,$A10),SUMIFS('Raw data (as reported)'!R$5:R$37,'Raw data (as reported)'!$A$5:$A$37,$A10),"") -> 8515.1457 | J10: =IF(SUMPRODUCT(('Raw data (as reported)'!$A$5:$A$37=$A10)*ISNUMBER('Raw data (as reported)'!S$5:S$37))=COUNTIF('Raw data (as reported)'!$A$5:$A$37,$A10),SUMIFS('Raw data (as reported)'!S$5:S$37,'Raw data (as reported)'!$A$5:$A$37,$A10),"") -> 3860.2377 | K10: =IF(AND(ISNUMBER(E10),ISNUMBER(F10),ISNUMBER(G10)),E10+F10+G10+IF(ISNUMBER(H10),H10,0),"") | L10: =IF(ISNUMBER(K10),E10/K10,"") | M10: =IF(ISNUMBER(K10),F10/K10,"") | N10: =IF(ISNUMBER(K10),G10/K10,"") | O10: =IF(AND(ISNUMBER(K10),ISNUMBER(H10)),H10/K10,"") | P10: =IF(ISNUMBER(K10),(E10+F10)/K10,IF(AND(ISNUMBER(I10),ISNUMBER(J10)),I10/(I10+J10),"")) -> 0.68807126
A11: 2011 | B11: WM + WM Americas | C11: Accounting lines | D11: =IF(SUMPRODUCT(('Raw data (as reported)'!$A$5:$A$37=$A11)*ISNUMBER('Raw data (as reported)'!T$5:T$37))=COUNTIF('Raw data (as reported)'!$A$5:$A$37,$A11),SUMIFS('Raw data (as reported)'!T$5:T$37,'Raw data (as reported)'!$A$5:$A$37,$A11),"") -> 14631.308 | E11: =IF(SUMPRODUCT(('Raw data (as reported)'!$A$5:$A$37=$A11)*ISNUMBER('Raw data (as reported)'!N$5:N$37))=COUNTIF('Raw data (as reported)'!$A$5:$A$37,$A11),SUMIFS('Raw data (as reported)'!N$5:N$37,'Raw data (as reported)'!$A$5:$A$37,$A11),"") -> 3048.7177 | F11: =IF(SUMPRODUCT(('Raw data (as reported)'!$A$5:$A$37=$A11)*ISNUMBER('Raw data (as reported)'!O$5:O$37))=COUNTIF('Raw data (as reported)'!$A$5:$A$37,$A11),SUMIFS('Raw data (as reported)'!O$5:O$37,'Raw data (as reported)'!$A$5:$A$37,$A11),"") | G11: =IF(SUMPRODUCT(('Raw data (as reported)'!$A$5:$A$37=$A11)*ISNUMBER('Raw data (as reported)'!P$5:P$37))=COUNTIF('Raw data (as reported)'!$A$5:$A$37,$A11),SUMIFS('Raw data (as reported)'!P$5:P$37,'Raw data (as reported)'!$A$5:$A$37,$A11),"") | H11: =IF(SUMPRODUCT(('Raw data (as reported)'!$A$5:$A$37=$A11)*ISNUMBER('Raw data (as reported)'!Q$5:Q$37))=COUNTIF('Raw data (as reported)'!$A$5:$A$37,$A11),SUMIFS('Raw data (as reported)'!Q$5:Q$37,'Raw data (as reported)'!$A$5:$A$37,$A11),"") -> 600.57572 | I11: =IF(SUMPRODUCT(('Raw data (as reported)'!$A$5:$A$37=$A11)*ISNUMBER('Raw data (as reported)'!R$5:R$37))=COUNTIF('Raw data (as reported)'!$A$5:$A$37,$A11),SUMIFS('Raw data (as reported)'!R$5:R$37,'Raw data (as reported)'!$A$5:$A$37,$A11),"") | J11: =IF(SUMPRODUCT(('Raw data (as reported)'!$A$5:$A$37=$A11)*ISNUMBER('Raw data (as reported)'!S$5:S$37))=COUNTIF('Raw data (as reported)'!$A$5:$A$37,$A11),SUMIFS('Raw data (as reported)'!S$5:S$37,'Raw data (as reported)'!$A$5:$A$37,$A11),"") | K11: =IF(AND(ISNUMBER(E11),ISNUMBER(F11),ISNUMBER(G11)),E11+F11+G11+IF(ISNUMBER(H11),H11,0),"") | L11: =IF(ISNUMBER(K11),E11/K11,"") | M11: =IF(ISNUMBER(K11),F11/K11,"") | N11: =IF(ISNUMBER(K11),G11/K11,"") | O11: =IF(AND(ISNUMBER(K11),ISNUMBER(H11)),H11/K11,"") | P11: =IF(ISNUMBER(K11),(E11+F11)/K11,IF(AND(ISNUMBER(I11),ISNUMBER(J11)),I11/(I11+J11),"")) | Q11: Only NII, other income and totals disclosed on a comparable basis.
A12: 2012 | B12: WM + WM Americas | C12: Accounting lines | D12: =IF(SUMPRODUCT(('Raw data (as reported)'!$A$5:$A$37=$A12)*ISNUMBER('Raw data (as reported)'!T$5:T$37))=COUNTIF('Raw data (as reported)'!$A$5:$A$37,$A12),SUMIFS('Raw data (as reported)'!T$5:T$37,'Raw data (as reported)'!$A$5:$A$37,$A12),"") -> 14054.732 | E12: =IF(SUMPRODUCT(('Raw data (as reported)'!$A$5:$A$37=$A12)*ISNUMBER('Raw data (as reported)'!N$5:N$37))=COUNTIF('Raw data (as reported)'!$A$5:$A$37,$A12),SUMIFS('Raw data (as reported)'!N$5:N$37,'Raw data (as reported)'!$A$5:$A$37,$A12),"") -> 2929.6228 | F12: =IF(SUMPRODUCT(('Raw data (as reported)'!$A$5:$A$37=$A12)*ISNUMBER('Raw data (as reported)'!O$5:O$37))=COUNTIF('Raw data (as reported)'!$A$5:$A$37,$A12),SUMIFS('Raw data (as reported)'!O$5:O$37,'Raw data (as reported)'!$A$5:$A$37,$A12),"") | G12: =IF(SUMPRODUCT(('Raw data (as reported)'!$A$5:$A$37=$A12)*ISNUMBER('Raw data (as reported)'!P$5:P$37))=COUNTIF('Raw data (as reported)'!$A$5:$A$37,$A12),SUMIFS('Raw data (as reported)'!P$5:P$37,'Raw data (as reported)'!$A$5:$A$37,$A12),"") | H12: =IF(SUMPRODUCT(('Raw data (as reported)'!$A$5:$A$37=$A12)*ISNUMBER('Raw data (as reported)'!Q$5:Q$37))=COUNTIF('Raw data (as reported)'!$A$5:$A$37,$A12),SUMIFS('Raw data (as reported)'!Q$5:Q$37,'Raw data (as reported)'!$A$5:$A$37,$A12),"") -> 305.45825 | I12: =IF(SUMPRODUCT(('Raw data (as reported)'!$A$5:$A$37=$A12)*ISNUMBER('Raw data (as reported)'!R$5:R$37))=COUNTIF('Raw data (as reported)'!$A$5:$A$37,$A12),SUMIFS('Raw data (as reported)'!R$5:R$37,'Raw data (as reported)'!$A$5:$A$37,$A12),"") | J12: =IF(SUMPRODUCT(('Raw data (as reported)'!$A$5:$A$37=$A12)*ISNUMBER('Raw data (as reported)'!S$5:S$37))=COUNTIF('Raw data (as reported)'!$A$5:$A$37,$A12),SUMIFS('Raw data (as reported)'!S$5:S$37,'Raw data (as reported)'!$A$5:$A$37,$A12),"") | K12: =IF(AND(ISNUMBER(E12),ISNUMBER(F12),ISNUMBER(G12)),E12+F12+G12+IF(ISNUMBER(H12),H12,0),"") | L12: =IF(ISNUMBER(K12),E12/K12,"") | M12: =IF(ISNUMBER(K12),F12/K12,"") | N12: =IF(ISNUMBER(K12),G12/K12,"") | O12: =IF(AND(ISNUMBER(K12),ISNUMBER(H12)),H12/K12,"") | P12: =IF(ISNUMBER(K12),(E12+F12)/K12,IF(AND(ISNUMBER(I12),ISNUMBER(J12)),I12/(I12+J12),"")) | Q12: Only NII, other income and totals disclosed on a comparable basis.
A13: 2013 | B13: WM + WM Americas | C13: New (NII / fees / transaction / other) | D13: =IF(SUMPRODUCT(('Raw data (as reported)'!$A$5:$A$37=$A13)*ISNUMBER('Raw data (as reported)'!T$5:T$37))=COUNTIF('Raw data (as reported)'!$A$5:$A$37,$A13),SUMIFS('Raw data (as reported)'!T$5:T$37,'Raw data (as reported)'!$A$5:$A$37,$A13),"") -> 15213.076 | E13: =IF(SUMPRODUCT(('Raw data (as reported)'!$A$5:$A$37=$A13)*ISNUMBER('Raw data (as reported)'!N$5:N$37))=COUNTIF('Raw data (as reported)'!$A$5:$A$37,$A13),SUMIFS('Raw data (as reported)'!N$5:N$37,'Raw data (as reported)'!$A$5:$A$37,$A13),"") -> 3233.3585 | F13: =IF(SUMPRODUCT(('Raw data (as reported)'!$A$5:$A$37=$A13)*ISNUMBER('Raw data (as reported)'!O$5:O$37))=COUNTIF('Raw data (as reported)'!$A$5:$A$37,$A13),SUMIFS('Raw data (as reported)'!O$5:O$37,'Raw data (as reported)'!$A$5:$A$37,$A13),"") -> 8000.8631 | G13: =IF(SUMPRODUCT(('Raw data (as reported)'!$A$5:$A$37=$A13)*ISNUMBER('Raw data (as reported)'!P$5:P$37))=COUNTIF('Raw data (as reported)'!$A$5:$A$37,$A13),SUMIFS('Raw data (as reported)'!P$5:P$37,'Raw data (as reported)'!$A$5:$A$37,$A13),"") -> 3978.8542 | H13: =IF(SUMPRODUCT(('Raw data (as reported)'!$A$5:$A$37=$A13)*ISNUMBER('Raw data (as reported)'!Q$5:Q$37))=COUNTIF('Raw data (as reported)'!$A$5:$A$37,$A13),SUMIFS('Raw data (as reported)'!Q$5:Q$37,'Raw data (as reported)'!$A$5:$A$37,$A13),"") | I13: =IF(SUMPRODUCT(('Raw data (as reported)'!$A$5:$A$37=$A13)*ISNUMBER('Raw data (as reported)'!R$5:R$37))=COUNTIF('Raw data (as reported)'!$A$5:$A$37,$A13),SUMIFS('Raw data (as reported)'!R$5:R$37,'Raw data (as reported)'!$A$5:$A$37,$A13),"") | J13: =IF(SUMPRODUCT(('Raw data (as reported)'!$A$5:$A$37=$A13)*ISNUMBER('Raw data (as reported)'!S$5:S$37))=COUNTIF('Raw data (as reported)'!$A$5:$A$37,$A13),SUMIFS('Raw data (as reported)'!S$5:S$37,'Raw data (as reported)'!$A$5:$A$37,$A13),"") | K13: =IF(AND(ISNUMBER(E13),ISNUMBER(F13),ISNUMBER(G13)),E13+F13+G13+IF(ISNUMBER(H13),H13,0),"") -> 15213.076 | L13: =IF(ISNUMBER(K13),E13/K13,"") -> 0.21253812 | M13: =IF(ISNUMBER(K13),F13/K13,"") -> 0.52592015 | N13: =IF(ISNUMBER(K13),G13/K13,"") -> 0.26154173 | O13: =IF(AND(ISNUMBER(K13),ISNUMBER(H13)),H13/K13,"") | P13: =IF(ISNUMBER(K13),(E13+F13)/K13,IF(AND(ISNUMBER(I13),ISNUMBER(J13)),I13/(I13+J13),"")) -> 0.73845827 | Q13: Other income not disclosed separately; it sits inside recurring fees (derived).
A14: 2014 | B14: WM + WM Americas | C14: New (NII / fees / transaction / other) | D14: =IF(SUMPRODUCT(('Raw data (as reported)'!$A$5:$A$37=$A14)*ISNUMBER('Raw data (as reported)'!T$5:T$37))=COUNTIF('Raw data (as reported)'!$A$5:$A$37,$A14),SUMIFS('Raw data (as reported)'!T$5:T$37,'Raw data (as reported)'!$A$5:$A$37,$A14),"") -> 16228.898 | E14: =IF(SUMPRODUCT(('Raw data (as reported)'!$A$5:$A$37=$A14)*ISNUMBER('Raw data (as reported)'!N$5:N$37))=COUNTIF('Raw data (as reported)'!$A$5:$A$37,$A14),SUMIFS('Raw data (as reported)'!N$5:N$37,'Raw data (as reported)'!$A$5:$A$37,$A14),"") -> 3433.8963 | F14: =IF(SUMPRODUCT(('Raw data (as reported)'!$A$5:$A$37=$A14)*ISNUMBER('Raw data (as reported)'!O$5:O$37))=COUNTIF('Raw data (as reported)'!$A$5:$A$37,$A14),SUMIFS('Raw data (as reported)'!O$5:O$37,'Raw data (as reported)'!$A$5:$A$37,$A14),"") -> 8801.7822 | G14: =IF(SUMPRODUCT(('Raw data (as reported)'!$A$5:$A$37=$A14)*ISNUMBER('Raw data (as reported)'!P$5:P$37))=COUNTIF('Raw data (as reported)'!$A$5:$A$37,$A14),SUMIFS('Raw data (as reported)'!P$5:P$37,'Raw data (as reported)'!$A$5:$A$37,$A14),"") -> 3932.7949 | H14: =IF(SUMPRODUCT(('Raw data (as reported)'!$A$5:$A$37=$A14)*ISNUMBER('Raw data (as reported)'!Q$5:Q$37))=COUNTIF('Raw data (as reported)'!$A$5:$A$37,$A14),SUMIFS('Raw data (as reported)'!Q$5:Q$37,'Raw data (as reported)'!$A$5:$A$37,$A14),"") -> 60.331365 | I14: =IF(SUMPRODUCT(('Raw data (as reported)'!$A$5:$A$37=$A14)*ISNUMBER('Raw data (as reported)'!R$5:R$37))=COUNTIF('Raw data (as reported)'!$A$5:$A$37,$A14),SUMIFS('Raw data (as reported)'!R$5:R$37,'Raw data (as reported)'!$A$5:$A$37,$A14),"") | J14: =IF(SUMPRODUCT(('Raw data (as reported)'!$A$5:$A$37=$A14)*ISNUMBER('Raw data (as reported)'!S$5:S$37))=COUNTIF('Raw data (as reported)'!$A$5:$A$37,$A14),SUMIFS('Raw data (as reported)'!S$5:S$37,'Raw data (as reported)'!$A$5:$A$37,$A14),"") | K14: =IF(AND(ISNUMBER(E14),ISNUMBER(F14),ISNUMBER(G14)),E14+F14+G14+IF(ISNUMBER(H14),H14,0),"") -> 16228.805 | L14: =IF(ISNUMBER(K14),E14/K14,"") -> 0.21159268 | M14: =IF(ISNUMBER(K14),F14/K14,"") -> 0.54235554 | N14: =IF(ISNUMBER(K14),G14/K14,"") -> 0.24233423 | O14: =IF(AND(ISNUMBER(K14),ISNUMBER(H14)),H14/K14,"") -> 0.0037175483 | P14: =IF(ISNUMBER(K14),(E14+F14)/K14,IF(AND(ISNUMBER(I14),ISNUMBER(J14)),I14/(I14+J14),"")) -> 0.75394822
A15: 2015 | B15: WM + WM Americas | C15: New (NII / fees / transaction / other) | D15: =IF(SUMPRODUCT(('Raw data (as reported)'!$A$5:$A$37=$A15)*ISNUMBER('Raw data (as reported)'!T$5:T$37))=COUNTIF('Raw data (as reported)'!$A$5:$A$37,$A15),SUMIFS('Raw data (as reported)'!T$5:T$37,'Raw data (as reported)'!$A$5:$A$37,$A15),"") -> 16127.087 | E15: =IF(SUMPRODUCT(('Raw data (as reported)'!$A$5:$A$37=$A15)*ISNUMBER('Raw data (as reported)'!N$5:N$37))=COUNTIF('Raw data (as reported)'!$A$5:$A$37,$A15),SUMIFS('Raw data (as reported)'!N$5:N$37,'Raw data (as reported)'!$A$5:$A$37,$A15),"") -> 3630.8704 | F15: =IF(SUMPRODUCT(('Raw data (as reported)'!$A$5:$A$37=$A15)*ISNUMBER('Raw data (as reported)'!O$5:O$37))=COUNTIF('Raw data (as reported)'!$A$5:$A$37,$A15),SUMIFS('Raw data (as reported)'!O$5:O$37,'Raw data (as reported)'!$A$5:$A$37,$A15),"") -> 8762.5945 | G15: =IF(SUMPRODUCT(('Raw data (as reported)'!$A$5:$A$37=$A15)*ISNUMBER('Raw data (as reported)'!P$5:P$37))=COUNTIF('Raw data (as reported)'!$A$5:$A$37,$A15),SUMIFS('Raw data (as reported)'!P$5:P$37,'Raw data (as reported)'!$A$5:$A$37,$A15),"") -> 3460.6971 | H15: =IF(SUMPRODUCT(('Raw data (as reported)'!$A$5:$A$37=$A15)*ISNUMBER('Raw data (as reported)'!Q$5:Q$37))=COUNTIF('Raw data (as reported)'!$A$5:$A$37,$A15),SUMIFS('Raw data (as reported)'!Q$5:Q$37,'Raw data (as reported)'!$A$5:$A$37,$A15),"") -> 271.92522 | I15: =IF(SUMPRODUCT(('Raw data (as reported)'!$A$5:$A$37=$A15)*ISNUMBER('Raw data (as reported)'!R$5:R$37))=COUNTIF('Raw data (as reported)'!$A$5:$A$37,$A15),SUMIFS('Raw data (as reported)'!R$5:R$37,'Raw data (as reported)'!$A$5:$A$37,$A15),"") | J15: =IF(SUMPRODUCT(('Raw data (as reported)'!$A$5:$A$37=$A15)*ISNUMBER('Raw data (as reported)'!S$5:S$37))=COUNTIF('Raw data (as reported)'!$A$5:$A$37,$A15),SUMIFS('Raw data (as reported)'!S$5:S$37,'Raw data (as reported)'!$A$5:$A$37,$A15),"") | K15: =IF(AND(ISNUMBER(E15),ISNUMBER(F15),ISNUMBER(G15)),E15+F15+G15+IF(ISNUMBER(H15),H15,0),"") -> 16126.087 | L15: =IF(ISNUMBER(K15),E15/K15,"") -> 0.22515507 | M15: =IF(ISNUMBER(K15),F15/K15,"") -> 0.54338008 | N15: =IF(ISNUMBER(K15),G15/K15,"") -> 0.21460241 | O15: =IF(AND(ISNUMBER(K15),ISNUMBER(H15)),H15/K15,"") -> 0.016862442 | P15: =IF(ISNUMBER(K15),(E15+F15)/K15,IF(AND(ISNUMBER(I15),ISNUMBER(J15)),I15/(I15+J15),"")) -> 0.76853515
A16: 2016 | B16: WM + WM Americas | C16: New (NII / fees / transaction / other) | D16: =IF(SUMPRODUCT(('Raw data (as reported)'!$A$5:$A$37=$A16)*ISNUMBER('Raw data (as reported)'!T$5:T$37))=COUNTIF('Raw data (as reported)'!$A$5:$A$37,$A16),SUMIFS('Raw data (as reported)'!T$5:T$37,'Raw data (as reported)'!$A$5:$A$37,$A16),"") -> 15281.611 | E16: =IF(SUMPRODUCT(('Raw data (as reported)'!$A$5:$A$37=$A16)*ISNUMBER('Raw data (as reported)'!N$5:N$37))=COUNTIF('Raw data (as reported)'!$A$5:$A$37,$A16),SUMIFS('Raw data (as reported)'!N$5:N$37,'Raw data (as reported)'!$A$5:$A$37,$A16),"") -> 3850.9781 | F16: =IF(SUMPRODUCT(('Raw data (as reported)'!$A$5:$A$37=$A16)*ISNUMBER('Raw data (as reported)'!O$5:O$37))=COUNTIF('Raw data (as reported)'!$A$5:$A$37,$A16),SUMIFS('Raw data (as reported)'!O$5:O$37,'Raw data (as reported)'!$A$5:$A$37,$A16),"") -> 8482.762 | G16: =IF(SUMPRODUCT(('Raw data (as reported)'!$A$5:$A$37=$A16)*ISNUMBER('Raw data (as reported)'!P$5:P$37))=COUNTIF('Raw data (as reported)'!$A$5:$A$37,$A16),SUMIFS('Raw data (as reported)'!P$5:P$37,'Raw data (as reported)'!$A$5:$A$37,$A16),"") -> 2892.5621 | H16: =IF(SUMPRODUCT(('Raw data (as reported)'!$A$5:$A$37=$A16)*ISNUMBER('Raw data (as reported)'!Q$5:Q$37))=COUNTIF('Raw data (as reported)'!$A$5:$A$37,$A16),SUMIFS('Raw data (as reported)'!Q$5:Q$37,'Raw data (as reported)'!$A$5:$A$37,$A16),"") -> 55.308692 | I16: =IF(SUMPRODUCT(('Raw data (as reported)'!$A$5:$A$37=$A16)*ISNUMBER('Raw data (as reported)'!R$5:R$37))=COUNTIF('Raw data (as reported)'!$A$5:$A$37,$A16),SUMIFS('Raw data (as reported)'!R$5:R$37,'Raw data (as reported)'!$A$5:$A$37,$A16),"") | J16: =IF(SUMPRODUCT(('Raw data (as reported)'!$A$5:$A$37=$A16)*ISNUMBER('Raw data (as reported)'!S$5:S$37))=COUNTIF('Raw data (as reported)'!$A$5:$A$37,$A16),SUMIFS('Raw data (as reported)'!S$5:S$37,'Raw data (as reported)'!$A$5:$A$37,$A16),"") | K16: =IF(AND(ISNUMBER(E16),ISNUMBER(F16),ISNUMBER(G16)),E16+F16+G16+IF(ISNUMBER(H16),H16,0),"") -> 15281.611 | L16: =IF(ISNUMBER(K16),E16/K16,"") -> 0.25200079 | M16: =IF(ISNUMBER(K16),F16/K16,"") -> 0.55509606 | N16: =IF(ISNUMBER(K16),G16/K16,"") -> 0.18928385 | O16: =IF(AND(ISNUMBER(K16),ISNUMBER(H16)),H16/K16,"") -> 0.0036192972 | P16: =IF(ISNUMBER(K16),(E16+F16)/K16,IF(AND(ISNUMBER(I16),ISNUMBER(J16)),I16/(I16+J16),"")) -> 0.80709685
A17: 2017 | B17: Global Wealth Management | C17: New (NII / fees / transaction / other) | D17: =IF(SUMPRODUCT(('Raw data (as reported)'!$A$5:$A$37=$A17)*ISNUMBER('Raw data (as reported)'!T$5:T$37))=COUNTIF('Raw data (as reported)'!$A$5:$A$37,$A17),SUMIFS('Raw data (as reported)'!T$5:T$37,'Raw data (as reported)'!$A$5:$A$37,$A17),"") -> 16295 | E17: =IF(SUMPRODUCT(('Raw data (as reported)'!$A$5:$A$37=$A17)*ISNUMBER('Raw data (as reported)'!N$5:N$37))=COUNTIF('Raw data (as reported)'!$A$5:$A$37,$A17),SUMIFS('Raw data (as reported)'!N$5:N$37,'Raw data (as reported)'!$A$5:$A$37,$A17),"") -> 4103 | F17: =IF(SUMPRODUCT(('Raw data (as reported)'!$A$5:$A$37=$A17)*ISNUMBER('Raw data (as reported)'!O$5:O$37))=COUNTIF('Raw data (as reported)'!$A$5:$A$37,$A17),SUMIFS('Raw data (as reported)'!O$5:O$37,'Raw data (as reported)'!$A$5:$A$37,$A17),"") -> 8968 | G17: =IF(SUMPRODUCT(('Raw data (as reported)'!$A$5:$A$37=$A17)*ISNUMBER('Raw data (as reported)'!P$5:P$37))=COUNTIF('Raw data (as reported)'!$A$5:$A$37,$A17),SUMIFS('Raw data (as reported)'!P$5:P$37,'Raw data (as reported)'!$A$5:$A$37,$A17),"") -> 3159 | H17: =IF(SUMPRODUCT(('Raw data (as reported)'!$A$5:$A$37=$A17)*ISNUMBER('Raw data (as reported)'!Q$5:Q$37))=COUNTIF('Raw data (as reported)'!$A$5:$A$37,$A17),SUMIFS('Raw data (as reported)'!Q$5:Q$37,'Raw data (as reported)'!$A$5:$A$37,$A17),"") -> 65 | I17: =IF(SUMPRODUCT(('Raw data (as reported)'!$A$5:$A$37=$A17)*ISNUMBER('Raw data (as reported)'!R$5:R$37))=COUNTIF('Raw data (as reported)'!$A$5:$A$37,$A17),SUMIFS('Raw data (as reported)'!R$5:R$37,'Raw data (as reported)'!$A$5:$A$37,$A17),"") | J17: =IF(SUMPRODUCT(('Raw data (as reported)'!$A$5:$A$37=$A17)*ISNUMBER('Raw data (as reported)'!S$5:S$37))=COUNTIF('Raw data (as reported)'!$A$5:$A$37,$A17),SUMIFS('Raw data (as reported)'!S$5:S$37,'Raw data (as reported)'!$A$5:$A$37,$A17),"") | K17: =IF(AND(ISNUMBER(E17),ISNUMBER(F17),ISNUMBER(G17)),E17+F17+G17+IF(ISNUMBER(H17),H17,0),"") -> 16295 | L17: =IF(ISNUMBER(K17),E17/K17,"") -> 0.25179503 | M17: =IF(ISNUMBER(K17),F17/K17,"") -> 0.55035287 | N17: =IF(ISNUMBER(K17),G17/K17,"") -> 0.19386315 | O17: =IF(AND(ISNUMBER(K17),ISNUMBER(H17)),H17/K17,"") -> 0.0039889537 | P17: =IF(ISNUMBER(K17),(E17+F17)/K17,IF(AND(ISNUMBER(I17),ISNUMBER(J17)),I17/(I17+J17),"")) -> 0.8021479
A18: 2018 | B18: Global Wealth Management | C18: New (NII / fees / transaction / other) | D18: =IF(SUMPRODUCT(('Raw data (as reported)'!$A$5:$A$37=$A18)*ISNUMBER('Raw data (as reported)'!T$5:T$37))=COUNTIF('Raw data (as reported)'!$A$5:$A$37,$A18),SUMIFS('Raw data (as reported)'!T$5:T$37,'Raw data (as reported)'!$A$5:$A$37,$A18),"") -> 16956 | E18: =IF(SUMPRODUCT(('Raw data (as reported)'!$A$5:$A$37=$A18)*ISNUMBER('Raw data (as reported)'!N$5:N$37))=COUNTIF('Raw data (as reported)'!$A$5:$A$37,$A18),SUMIFS('Raw data (as reported)'!N$5:N$37,'Raw data (as reported)'!$A$5:$A$37,$A18),"") -> 4310 | F18: =IF(SUMPRODUCT(('Raw data (as reported)'!$A$5:$A$37=$A18)*ISNUMBER('Raw data (as reported)'!O$5:O$37))=COUNTIF('Raw data (as reported)'!$A$5:$A$37,$A18),SUMIFS('Raw data (as reported)'!O$5:O$37,'Raw data (as reported)'!$A$5:$A$37,$A18),"") -> 9585 | G18: =IF(SUMPRODUCT(('Raw data (as reported)'!$A$5:$A$37=$A18)*ISNUMBER('Raw data (as reported)'!P$5:P$37))=COUNTIF('Raw data (as reported)'!$A$5:$A$37,$A18),SUMIFS('Raw data (as reported)'!P$5:P$37,'Raw data (as reported)'!$A$5:$A$37,$A18),"") -> 2911 | H18: =IF(SUMPRODUCT(('Raw data (as reported)'!$A$5:$A$37=$A18)*ISNUMBER('Raw data (as reported)'!Q$5:Q$37))=COUNTIF('Raw data (as reported)'!$A$5:$A$37,$A18),SUMIFS('Raw data (as reported)'!Q$5:Q$37,'Raw data (as reported)'!$A$5:$A$37,$A18),"") -> 151 | I18: =IF(SUMPRODUCT(('Raw data (as reported)'!$A$5:$A$37=$A18)*ISNUMBER('Raw data (as reported)'!R$5:R$37))=COUNTIF('Raw data (as reported)'!$A$5:$A$37,$A18),SUMIFS('Raw data (as reported)'!R$5:R$37,'Raw data (as reported)'!$A$5:$A$37,$A18),"") | J18: =IF(SUMPRODUCT(('Raw data (as reported)'!$A$5:$A$37=$A18)*ISNUMBER('Raw data (as reported)'!S$5:S$37))=COUNTIF('Raw data (as reported)'!$A$5:$A$37,$A18),SUMIFS('Raw data (as reported)'!S$5:S$37,'Raw data (as reported)'!$A$5:$A$37,$A18),"") | K18: =IF(AND(ISNUMBER(E18),ISNUMBER(F18),ISNUMBER(G18)),E18+F18+G18+IF(ISNUMBER(H18),H18,0),"") -> 16957 | L18: =IF(ISNUMBER(K18),E18/K18,"") -> 0.25417232 | M18: =IF(ISNUMBER(K18),F18/K18,"") -> 0.56525329 | N18: =IF(ISNUMBER(K18),G18/K18,"") -> 0.17166952 | O18: =IF(AND(ISNUMBER(K18),ISNUMBER(H18)),H18/K18,"") -> 0.008904877 | P18: =IF(ISNUMBER(K18),(E18+F18)/K18,IF(AND(ISNUMBER(I18),ISNUMBER(J18)),I18/(I18+J18),"")) -> 0.81942561
A19: 2019 | B19: Global Wealth Management | C19: New (NII / fees / transaction / other) | D19: =IF(SUMPRODUCT(('Raw data (as reported)'!$A$5:$A$37=$A19)*ISNUMBER('Raw data (as reported)'!T$5:T$37))=COUNTIF('Raw data (as reported)'!$A$5:$A$37,$A19),SUMIFS('Raw data (as reported)'!T$5:T$37,'Raw data (as reported)'!$A$5:$A$37,$A19),"") -> 16373 | E19: =IF(SUMPRODUCT(('Raw data (as reported)'!$A$5:$A$37=$A19)*ISNUMBER('Raw data (as reported)'!N$5:N$37))=COUNTIF('Raw data (as reported)'!$A$5:$A$37,$A19),SUMIFS('Raw data (as reported)'!N$5:N$37,'Raw data (as reported)'!$A$5:$A$37,$A19),"") -> 3947 | F19: =IF(SUMPRODUCT(('Raw data (as reported)'!$A$5:$A$37=$A19)*ISNUMBER('Raw data (as reported)'!O$5:O$37))=COUNTIF('Raw data (as reported)'!$A$5:$A$37,$A19),SUMIFS('Raw data (as reported)'!O$5:O$37,'Raw data (as reported)'!$A$5:$A$37,$A19),"") -> 9258 | G19: =IF(SUMPRODUCT(('Raw data (as reported)'!$A$5:$A$37=$A19)*ISNUMBER('Raw data (as reported)'!P$5:P$37))=COUNTIF('Raw data (as reported)'!$A$5:$A$37,$A19),SUMIFS('Raw data (as reported)'!P$5:P$37,'Raw data (as reported)'!$A$5:$A$37,$A19),"") -> 3059 | H19: =IF(SUMPRODUCT(('Raw data (as reported)'!$A$5:$A$37=$A19)*ISNUMBER('Raw data (as reported)'!Q$5:Q$37))=COUNTIF('Raw data (as reported)'!$A$5:$A$37,$A19),SUMIFS('Raw data (as reported)'!Q$5:Q$37,'Raw data (as reported)'!$A$5:$A$37,$A19),"") -> 110 | I19: =IF(SUMPRODUCT(('Raw data (as reported)'!$A$5:$A$37=$A19)*ISNUMBER('Raw data (as reported)'!R$5:R$37))=COUNTIF('Raw data (as reported)'!$A$5:$A$37,$A19),SUMIFS('Raw data (as reported)'!R$5:R$37,'Raw data (as reported)'!$A$5:$A$37,$A19),"") | J19: =IF(SUMPRODUCT(('Raw data (as reported)'!$A$5:$A$37=$A19)*ISNUMBER('Raw data (as reported)'!S$5:S$37))=COUNTIF('Raw data (as reported)'!$A$5:$A$37,$A19),SUMIFS('Raw data (as reported)'!S$5:S$37,'Raw data (as reported)'!$A$5:$A$37,$A19),"") | K19: =IF(AND(ISNUMBER(E19),ISNUMBER(F19),ISNUMBER(G19)),E19+F19+G19+IF(ISNUMBER(H19),H19,0),"") -> 16374 | L19: =IF(ISNUMBER(K19),E19/K19,"") -> 0.24105289 | M19: =IF(ISNUMBER(K19),F19/K19,"") -> 0.56540857 | N19: =IF(ISNUMBER(K19),G19/K19,"") -> 0.18682057 | O19: =IF(AND(ISNUMBER(K19),ISNUMBER(H19)),H19/K19,"") -> 0.0067179675 | P19: =IF(ISNUMBER(K19),(E19+F19)/K19,IF(AND(ISNUMBER(I19),ISNUMBER(J19)),I19/(I19+J19),"")) -> 0.80646146
A20: 2020 | B20: Global Wealth Management | C20: New (NII / fees / transaction / other) | D20: =IF(SUMPRODUCT(('Raw data (as reported)'!$A$5:$A$37=$A20)*ISNUMBER('Raw data (as reported)'!T$5:T$37))=COUNTIF('Raw data (as reported)'!$A$5:$A$37,$A20),SUMIFS('Raw data (as reported)'!T$5:T$37,'Raw data (as reported)'!$A$5:$A$37,$A20),"") -> 17134 | E20: =IF(SUMPRODUCT(('Raw data (as reported)'!$A$5:$A$37=$A20)*ISNUMBER('Raw data (as reported)'!N$5:N$37))=COUNTIF('Raw data (as reported)'!$A$5:$A$37,$A20),SUMIFS('Raw data (as reported)'!N$5:N$37,'Raw data (as reported)'!$A$5:$A$37,$A20),"") -> 4027 | F20: =IF(SUMPRODUCT(('Raw data (as reported)'!$A$5:$A$37=$A20)*ISNUMBER('Raw data (as reported)'!O$5:O$37))=COUNTIF('Raw data (as reported)'!$A$5:$A$37,$A20),SUMIFS('Raw data (as reported)'!O$5:O$37,'Raw data (as reported)'!$A$5:$A$37,$A20),"") -> 9372 | G20: =IF(SUMPRODUCT(('Raw data (as reported)'!$A$5:$A$37=$A20)*ISNUMBER('Raw data (as reported)'!P$5:P$37))=COUNTIF('Raw data (as reported)'!$A$5:$A$37,$A20),SUMIFS('Raw data (as reported)'!P$5:P$37,'Raw data (as reported)'!$A$5:$A$37,$A20),"") -> 3576 | H20: =IF(SUMPRODUCT(('Raw data (as reported)'!$A$5:$A$37=$A20)*ISNUMBER('Raw data (as reported)'!Q$5:Q$37))=COUNTIF('Raw data (as reported)'!$A$5:$A$37,$A20),SUMIFS('Raw data (as reported)'!Q$5:Q$37,'Raw data (as reported)'!$A$5:$A$37,$A20),"") -> 159 | I20: =IF(SUMPRODUCT(('Raw data (as reported)'!$A$5:$A$37=$A20)*ISNUMBER('Raw data (as reported)'!R$5:R$37))=COUNTIF('Raw data (as reported)'!$A$5:$A$37,$A20),SUMIFS('Raw data (as reported)'!R$5:R$37,'Raw data (as reported)'!$A$5:$A$37,$A20),"") | J20: =IF(SUMPRODUCT(('Raw data (as reported)'!$A$5:$A$37=$A20)*ISNUMBER('Raw data (as reported)'!S$5:S$37))=COUNTIF('Raw data (as reported)'!$A$5:$A$37,$A20),SUMIFS('Raw data (as reported)'!S$5:S$37,'Raw data (as reported)'!$A$5:$A$37,$A20),"") | K20: =IF(AND(ISNUMBER(E20),ISNUMBER(F20),ISNUMBER(G20)),E20+F20+G20+IF(ISNUMBER(H20),H20,0),"") -> 17134 | L20: =IF(ISNUMBER(K20),E20/K20,"") -> 0.23502977 | M20: =IF(ISNUMBER(K20),F20/K20,"") -> 0.54698261 | N20: =IF(ISNUMBER(K20),G20/K20,"") -> 0.20870783 | O20: =IF(AND(ISNUMBER(K20),ISNUMBER(H20)),H20/K20,"") -> 0.0092797946 | P20: =IF(ISNUMBER(K20),(E20+F20)/K20,IF(AND(ISNUMBER(I20),ISNUMBER(J20)),I20/(I20+J20),"")) -> 0.78201237
A21: 2021 | B21: Global Wealth Management | C21: New (NII / fees / transaction / other) | D21: =IF(SUMPRODUCT(('Raw data (as reported)'!$A$5:$A$37=$A21)*ISNUMBER('Raw data (as reported)'!T$5:T$37))=COUNTIF('Raw data (as reported)'!$A$5:$A$37,$A21),SUMIFS('Raw data (as reported)'!T$5:T$37,'Raw data (as reported)'!$A$5:$A$37,$A21),"") -> 19419 | E21: =IF(SUMPRODUCT(('Raw data (as reported)'!$A$5:$A$37=$A21)*ISNUMBER('Raw data (as reported)'!N$5:N$37))=COUNTIF('Raw data (as reported)'!$A$5:$A$37,$A21),SUMIFS('Raw data (as reported)'!N$5:N$37,'Raw data (as reported)'!$A$5:$A$37,$A21),"") -> 4244 | F21: =IF(SUMPRODUCT(('Raw data (as reported)'!$A$5:$A$37=$A21)*ISNUMBER('Raw data (as reported)'!O$5:O$37))=COUNTIF('Raw data (as reported)'!$A$5:$A$37,$A21),SUMIFS('Raw data (as reported)'!O$5:O$37,'Raw data (as reported)'!$A$5:$A$37,$A21),"") -> 11170 | G21: =IF(SUMPRODUCT(('Raw data (as reported)'!$A$5:$A$37=$A21)*ISNUMBER('Raw data (as reported)'!P$5:P$37))=COUNTIF('Raw data (as reported)'!$A$5:$A$37,$A21),SUMIFS('Raw data (as reported)'!P$5:P$37,'Raw data (as reported)'!$A$5:$A$37,$A21),"") -> 3836 | H21: =IF(SUMPRODUCT(('Raw data (as reported)'!$A$5:$A$37=$A21)*ISNUMBER('Raw data (as reported)'!Q$5:Q$37))=COUNTIF('Raw data (as reported)'!$A$5:$A$37,$A21),SUMIFS('Raw data (as reported)'!Q$5:Q$37,'Raw data (as reported)'!$A$5:$A$37,$A21),"") -> 168 | I21: =IF(SUMPRODUCT(('Raw data (as reported)'!$A$5:$A$37=$A21)*ISNUMBER('Raw data (as reported)'!R$5:R$37))=COUNTIF('Raw data (as reported)'!$A$5:$A$37,$A21),SUMIFS('Raw data (as reported)'!R$5:R$37,'Raw data (as reported)'!$A$5:$A$37,$A21),"") | J21: =IF(SUMPRODUCT(('Raw data (as reported)'!$A$5:$A$37=$A21)*ISNUMBER('Raw data (as reported)'!S$5:S$37))=COUNTIF('Raw data (as reported)'!$A$5:$A$37,$A21),SUMIFS('Raw data (as reported)'!S$5:S$37,'Raw data (as reported)'!$A$5:$A$37,$A21),"") | K21: =IF(AND(ISNUMBER(E21),ISNUMBER(F21),ISNUMBER(G21)),E21+F21+G21+IF(ISNUMBER(H21),H21,0),"") -> 19418 | L21: =IF(ISNUMBER(K21),E21/K21,"") -> 0.2185601 | M21: =IF(ISNUMBER(K21),F21/K21,"") -> 0.57523947 | N21: =IF(ISNUMBER(K21),G21/K21,"") -> 0.19754867 | O21: =IF(AND(ISNUMBER(K21),ISNUMBER(H21)),H21/K21,"") -> 0.0086517664 | P21: =IF(ISNUMBER(K21),(E21+F21)/K21,IF(AND(ISNUMBER(I21),ISNUMBER(J21)),I21/(I21+J21),"")) -> 0.79379957
A22: 2022 | B22: Global Wealth Management | C22: New (NII / fees / transaction / other) | D22: =IF(SUMPRODUCT(('Raw data (as reported)'!$A$5:$A$37=$A22)*ISNUMBER('Raw data (as reported)'!T$5:T$37))=COUNTIF('Raw data (as reported)'!$A$5:$A$37,$A22),SUMIFS('Raw data (as reported)'!T$5:T$37,'Raw data (as reported)'!$A$5:$A$37,$A22),"") -> 18967 | E22: =IF(SUMPRODUCT(('Raw data (as reported)'!$A$5:$A$37=$A22)*ISNUMBER('Raw data (as reported)'!N$5:N$37))=COUNTIF('Raw data (as reported)'!$A$5:$A$37,$A22),SUMIFS('Raw data (as reported)'!N$5:N$37,'Raw data (as reported)'!$A$5:$A$37,$A22),"") -> 5273 | F22: =IF(SUMPRODUCT(('Raw data (as reported)'!$A$5:$A$37=$A22)*ISNUMBER('Raw data (as reported)'!O$5:O$37))=COUNTIF('Raw data (as reported)'!$A$5:$A$37,$A22),SUMIFS('Raw data (as reported)'!O$5:O$37,'Raw data (as reported)'!$A$5:$A$37,$A22),"") -> 10282 | G22: =IF(SUMPRODUCT(('Raw data (as reported)'!$A$5:$A$37=$A22)*ISNUMBER('Raw data (as reported)'!P$5:P$37))=COUNTIF('Raw data (as reported)'!$A$5:$A$37,$A22),SUMIFS('Raw data (as reported)'!P$5:P$37,'Raw data (as reported)'!$A$5:$A$37,$A22),"") -> 3137 | H22: =IF(SUMPRODUCT(('Raw data (as reported)'!$A$5:$A$37=$A22)*ISNUMBER('Raw data (as reported)'!Q$5:Q$37))=COUNTIF('Raw data (as reported)'!$A$5:$A$37,$A22),SUMIFS('Raw data (as reported)'!Q$5:Q$37,'Raw data (as reported)'!$A$5:$A$37,$A22),"") -> 275 | I22: =IF(SUMPRODUCT(('Raw data (as reported)'!$A$5:$A$37=$A22)*ISNUMBER('Raw data (as reported)'!R$5:R$37))=COUNTIF('Raw data (as reported)'!$A$5:$A$37,$A22),SUMIFS('Raw data (as reported)'!R$5:R$37,'Raw data (as reported)'!$A$5:$A$37,$A22),"") | J22: =IF(SUMPRODUCT(('Raw data (as reported)'!$A$5:$A$37=$A22)*ISNUMBER('Raw data (as reported)'!S$5:S$37))=COUNTIF('Raw data (as reported)'!$A$5:$A$37,$A22),SUMIFS('Raw data (as reported)'!S$5:S$37,'Raw data (as reported)'!$A$5:$A$37,$A22),"") | K22: =IF(AND(ISNUMBER(E22),ISNUMBER(F22),ISNUMBER(G22)),E22+F22+G22+IF(ISNUMBER(H22),H22,0),"") -> 18967 | L22: =IF(ISNUMBER(K22),E22/K22,"") -> 0.27800917 | M22: =IF(ISNUMBER(K22),F22/K22,"") -> 0.54209944 | N22: =IF(ISNUMBER(K22),G22/K22,"") -> 0.16539252 | O22: =IF(AND(ISNUMBER(K22),ISNUMBER(H22)),H22/K22,"") -> 0.014498866 | P22: =IF(ISNUMBER(K22),(E22+F22)/K22,IF(AND(ISNUMBER(I22),ISNUMBER(J22)),I22/(I22+J22),"")) -> 0.82010861
A23: 2023 | B23: GWM + Credit Suisse (7 months) | C23: New (NII / fees / transaction / other) | D23: =IF(SUMPRODUCT(('Raw data (as reported)'!$A$5:$A$37=$A23)*ISNUMBER('Raw data (as reported)'!T$5:T$37))=COUNTIF('Raw data (as reported)'!$A$5:$A$37,$A23),SUMIFS('Raw data (as reported)'!T$5:T$37,'Raw data (as reported)'!$A$5:$A$37,$A23),"") -> 21556 | E23: =IF(SUMPRODUCT(('Raw data (as reported)'!$A$5:$A$37=$A23)*ISNUMBER('Raw data (as reported)'!N$5:N$37))=COUNTIF('Raw data (as reported)'!$A$5:$A$37,$A23),SUMIFS('Raw data (as reported)'!N$5:N$37,'Raw data (as reported)'!$A$5:$A$37,$A23),"") -> 7082 | F23: =IF(SUMPRODUCT(('Raw data (as reported)'!$A$5:$A$37=$A23)*ISNUMBER('Raw data (as reported)'!O$5:O$37))=COUNTIF('Raw data (as reported)'!$A$5:$A$37,$A23),SUMIFS('Raw data (as reported)'!O$5:O$37,'Raw data (as reported)'!$A$5:$A$37,$A23),"") -> 10988 | G23: =IF(SUMPRODUCT(('Raw data (as reported)'!$A$5:$A$37=$A23)*ISNUMBER('Raw data (as reported)'!P$5:P$37))=COUNTIF('Raw data (as reported)'!$A$5:$A$37,$A23),SUMIFS('Raw data (as reported)'!P$5:P$37,'Raw data (as reported)'!$A$5:$A$37,$A23),"") -> 3623 | H23: =IF(SUMPRODUCT(('Raw data (as reported)'!$A$5:$A$37=$A23)*ISNUMBER('Raw data (as reported)'!Q$5:Q$37))=COUNTIF('Raw data (as reported)'!$A$5:$A$37,$A23),SUMIFS('Raw data (as reported)'!Q$5:Q$37,'Raw data (as reported)'!$A$5:$A$37,$A23),"") -> -137 | I23: =IF(SUMPRODUCT(('Raw data (as reported)'!$A$5:$A$37=$A23)*ISNUMBER('Raw data (as reported)'!R$5:R$37))=COUNTIF('Raw data (as reported)'!$A$5:$A$37,$A23),SUMIFS('Raw data (as reported)'!R$5:R$37,'Raw data (as reported)'!$A$5:$A$37,$A23),"") | J23: =IF(SUMPRODUCT(('Raw data (as reported)'!$A$5:$A$37=$A23)*ISNUMBER('Raw data (as reported)'!S$5:S$37))=COUNTIF('Raw data (as reported)'!$A$5:$A$37,$A23),SUMIFS('Raw data (as reported)'!S$5:S$37,'Raw data (as reported)'!$A$5:$A$37,$A23),"") | K23: =IF(AND(ISNUMBER(E23),ISNUMBER(F23),ISNUMBER(G23)),E23+F23+G23+IF(ISNUMBER(H23),H23,0),"") -> 21556 | L23: =IF(ISNUMBER(K23),E23/K23,"") -> 0.32853962 | M23: =IF(ISNUMBER(K23),F23/K23,"") -> 0.50974207 | N23: =IF(ISNUMBER(K23),G23/K23,"") -> 0.16807385 | O23: =IF(AND(ISNUMBER(K23),ISNUMBER(H23)),H23/K23,"") -> -0.0063555391 | P23: =IF(ISNUMBER(K23),(E23+F23)/K23,IF(AND(ISNUMBER(I23),ISNUMBER(J23)),I23/(I23+J23),"")) -> 0.83828168 | Q23: Includes Credit Suisse from June 2023; other revenues negative.
A24: 2024 | B24: GWM + Credit Suisse | C24: New (NII / fees / transaction / other) | D24: =IF(SUMPRODUCT(('Raw data (as reported)'!$A$5:$A$37=$A24)*ISNUMBER('Raw data (as reported)'!T$5:T$37))=COUNTIF('Raw data (as reported)'!$A$5:$A$37,$A24),SUMIFS('Raw data (as reported)'!T$5:T$37,'Raw data (as reported)'!$A$5:$A$37,$A24),"") -> 24516 | E24: =IF(SUMPRODUCT(('Raw data (as reported)'!$A$5:$A$37=$A24)*ISNUMBER('Raw data (as reported)'!N$5:N$37))=COUNTIF('Raw data (as reported)'!$A$5:$A$37,$A24),SUMIFS('Raw data (as reported)'!N$5:N$37,'Raw data (as reported)'!$A$5:$A$37,$A24),"") -> 7358 | F24: =IF(SUMPRODUCT(('Raw data (as reported)'!$A$5:$A$37=$A24)*ISNUMBER('Raw data (as reported)'!O$5:O$37))=COUNTIF('Raw data (as reported)'!$A$5:$A$37,$A24),SUMIFS('Raw data (as reported)'!O$5:O$37,'Raw data (as reported)'!$A$5:$A$37,$A24),"") -> 12625 | G24: =IF(SUMPRODUCT(('Raw data (as reported)'!$A$5:$A$37=$A24)*ISNUMBER('Raw data (as reported)'!P$5:P$37))=COUNTIF('Raw data (as reported)'!$A$5:$A$37,$A24),SUMIFS('Raw data (as reported)'!P$5:P$37,'Raw data (as reported)'!$A$5:$A$37,$A24),"") -> 4503 | H24: =IF(SUMPRODUCT(('Raw data (as reported)'!$A$5:$A$37=$A24)*ISNUMBER('Raw data (as reported)'!Q$5:Q$37))=COUNTIF('Raw data (as reported)'!$A$5:$A$37,$A24),SUMIFS('Raw data (as reported)'!Q$5:Q$37,'Raw data (as reported)'!$A$5:$A$37,$A24),"") -> 31 | I24: =IF(SUMPRODUCT(('Raw data (as reported)'!$A$5:$A$37=$A24)*ISNUMBER('Raw data (as reported)'!R$5:R$37))=COUNTIF('Raw data (as reported)'!$A$5:$A$37,$A24),SUMIFS('Raw data (as reported)'!R$5:R$37,'Raw data (as reported)'!$A$5:$A$37,$A24),"") | J24: =IF(SUMPRODUCT(('Raw data (as reported)'!$A$5:$A$37=$A24)*ISNUMBER('Raw data (as reported)'!S$5:S$37))=COUNTIF('Raw data (as reported)'!$A$5:$A$37,$A24),SUMIFS('Raw data (as reported)'!S$5:S$37,'Raw data (as reported)'!$A$5:$A$37,$A24),"") | K24: =IF(AND(ISNUMBER(E24),ISNUMBER(F24),ISNUMBER(G24)),E24+F24+G24+IF(ISNUMBER(H24),H24,0),"") -> 24517 | L24: =IF(ISNUMBER(K24),E24/K24,"") -> 0.30011829 | M24: =IF(ISNUMBER(K24),F24/K24,"") -> 0.51494881 | N24: =IF(ISNUMBER(K24),G24/K24,"") -> 0.18366847 | O24: =IF(AND(ISNUMBER(K24),ISNUMBER(H24)),H24/K24,"") -> 0.0012644288 | P24: =IF(ISNUMBER(K24),(E24+F24)/K24,IF(AND(ISNUMBER(I24),ISNUMBER(J24)),I24/(I24+J24),"")) -> 0.8150671
A25: 2025 | B25: GWM + Credit Suisse | C25: New (NII / fees / transaction / other) | D25: =IF(SUMPRODUCT(('Raw data (as reported)'!$A$5:$A$37=$A25)*ISNUMBER('Raw data (as reported)'!T$5:T$37))=COUNTIF('Raw data (as reported)'!$A$5:$A$37,$A25),SUMIFS('Raw data (as reported)'!T$5:T$37,'Raw data (as reported)'!$A$5:$A$37,$A25),"") -> 25960 | E25: =IF(SUMPRODUCT(('Raw data (as reported)'!$A$5:$A$37=$A25)*ISNUMBER('Raw data (as reported)'!N$5:N$37))=COUNTIF('Raw data (as reported)'!$A$5:$A$37,$A25),SUMIFS('Raw data (as reported)'!N$5:N$37,'Raw data (as reported)'!$A$5:$A$37,$A25),"") -> 7018 | F25: =IF(SUMPRODUCT(('Raw data (as reported)'!$A$5:$A$37=$A25)*ISNUMBER('Raw data (as reported)'!O$5:O$37))=COUNTIF('Raw data (as reported)'!$A$5:$A$37,$A25),SUMIFS('Raw data (as reported)'!O$5:O$37,'Raw data (as reported)'!$A$5:$A$37,$A25),"") -> 13671 | G25: =IF(SUMPRODUCT(('Raw data (as reported)'!$A$5:$A$37=$A25)*ISNUMBER('Raw data (as reported)'!P$5:P$37))=COUNTIF('Raw data (as reported)'!$A$5:$A$37,$A25),SUMIFS('Raw data (as reported)'!P$5:P$37,'Raw data (as reported)'!$A$5:$A$37,$A25),"") -> 5208 | H25: =IF(SUMPRODUCT(('Raw data (as reported)'!$A$5:$A$37=$A25)*ISNUMBER('Raw data (as reported)'!Q$5:Q$37))=COUNTIF('Raw data (as reported)'!$A$5:$A$37,$A25),SUMIFS('Raw data (as reported)'!Q$5:Q$37,'Raw data (as reported)'!$A$5:$A$37,$A25),"") -> 62 | I25: =IF(SUMPRODUCT(('Raw data (as reported)'!$A$5:$A$37=$A25)*ISNUMBER('Raw data (as reported)'!R$5:R$37))=COUNTIF('Raw data (as reported)'!$A$5:$A$37,$A25),SUMIFS('Raw data (as reported)'!R$5:R$37,'Raw data (as reported)'!$A$5:$A$37,$A25),"") | J25: =IF(SUMPRODUCT(('Raw data (as reported)'!$A$5:$A$37=$A25)*ISNUMBER('Raw data (as reported)'!S$5:S$37))=COUNTIF('Raw data (as reported)'!$A$5:$A$37,$A25),SUMIFS('Raw data (as reported)'!S$5:S$37,'Raw data (as reported)'!$A$5:$A$37,$A25),"") | K25: =IF(AND(ISNUMBER(E25),ISNUMBER(F25),ISNUMBER(G25)),E25+F25+G25+IF(ISNUMBER(H25),H25,0),"") -> 25959 | L25: =IF(ISNUMBER(K25),E25/K25,"") -> 0.2703494 | M25: =IF(ISNUMBER(K25),F25/K25,"") -> 0.52663816 | N25: =IF(ISNUMBER(K25),G25/K25,"") -> 0.20062406 | O25: =IF(AND(ISNUMBER(K25),ISNUMBER(H25)),H25/K25,"") -> 0.0023883817 | P25: =IF(ISNUMBER(K25),(E25+F25)/K25,IF(AND(ISNUMBER(I25),ISNUMBER(J25)),I25/(I25+J25),"")) -> 0.79698756 | Q25: UBS renamed 'Other income' to 'Other revenues' from 4Q25.
A28: NII share in 2011–2012 (WM + WMA): see Raw data – NII was about 21% of revenue in both years.
A29: Shares use the sum of all four income lines (NII + recurring fees + transaction + other revenues) as the denominator; recurring share (NII+fees) links both reporting bases.

Sheet Verification
A1: Verification log – how each input was checked
A2: Status key: VERBATIM = row read word-for-word from the filing table · TWO SOURCES = two separate filings show the same number · TIES = the lines add exactly to the reported total · QUARTERLY CHECK = consistent with quarterly figures · DERIVED = calculated by me · NOT VERIFIED = left blank.
A4: Year | B4: Unit | C4: Figures | D4: Status | E4: How it was checked
A5: 2005 | B5: WM Intl & Switzerland | C5: Total CHF 9,011m | D5: VERBATIM + TIES | E5: 4Q05 6-K table row 'Total operating income … 9,011 | 7,693'; Handbook: 9,011 + 5,156 + 5,071 (Business Banking) = 19,238 business-group total.
A6: 2005–06 | B6: WM US | C6: Totals 5,156 / 5,863 | D6: TIES | E6: UBS Handbook table; unit totals add exactly to the business-group totals 19,238 (2005) and 21,931 (2006).
A7: 2006 | B7: WM Intl & Switzerland | C7: Total 10,798 | D7: TIES | E7: As above: 10,798 + 5,863 + 5,270 = 21,931.
A8: 2005–07 | B8: WM US | C8: Recurring 2,834 / 3,488 / 4,173 | D8: QUARTERLY CHECK | E8: Text from 20-F 2007. Unit confirmed by quarterly reports: WM US recurring was CHF 1,040m (2Q07) and 1,092m (3Q07), consistent with ~4.2bn a year; the Intl & Swiss unit ran ~2.5bn a quarter, so it cannot be that unit.
A9: 2008 | B9: WM Americas | C9: Income 6,278; recurring 4,076 | D9: VERBATIM | E9: 4Q09 6-K table, 'Year ended 31.12.08' column.
A10: 2009–10 | B10: WM and WM Americas | C10: Recurring / non-recurring / income | D10: VERBATIM + TIES | E10: 4Q10 6-K tables, 'Year ended' columns; recurring + non-recurring = income exactly (e.g. 5,411 + 1,934 = 7,345).
A11: 2011–12 | B11: WM | C11: NII 1,968 / 1,951; income 7,634 / 7,040 | D11: VERBATIM | E11: 4Q12 6-K table, 'Year ended' columns.
A12: 2011–12 | B12: WM Americas | C12: NII 828 / 849; income 6,017 / 6,547 | D12: VERBATIM | E12: 4Q12 6-K US-dollar table.
A13: 2011–12 | B13: WM Americas | C13: Recurring income | D13: NOT VERIFIED – REMOVED | E13: An earlier extraction said 65.2% / 65.3%; the filing text shows 2012 recurring as '4,26…' (cut off), i.e. ~65.1%, so the earlier figure could not be confirmed. Left blank.
A14: 2013 | B14: WM and WM Americas | C14: NII, transaction, total | D14: VERBATIM | E14: 4Q14 6-K comparison table (13 vs 14) as indexed from the SEC filing.
A15: 2013 | B15: WM and WM Americas | C15: Recurring fees | D15: DERIVED | E15: Total less NII and transaction (includes small other income).
... A24: All CHF years | B24: FX | C24: Annual average CHF per USD | D24: PRIMARY SOURCE | E24: FRED series AEXSZUS (Federal Reserve).

Sheet Reconciliation
A1: Reconciliation: do the four income lines add up to the total UBS reported?
A2: UBS files Form 20-F (annual) and Form 6-K (quarterly reports) with the SEC – it is a foreign private issuer, so there are no 10-K/10-Q filings. Every line links to the Raw data tab.
A4: Year | B4: Unit | C4: Ccy | D4: SEC form | E4: NII + recurring fees + transaction + other | F4: Reported total | G4: Difference | H4: What explains the difference
A5: ='Raw data (as reported)'!A5 -> 2005 | B5: ='Raw data (as reported)'!B5 -> WM International & Switzerland | C5: ='Raw data (as reported)'!C5 -> CHF | D5: 20-F 2007 / Handbook | E5: =IF(AND(ISNUMBER('Raw data (as reported)'!E5),ISNUMBER('Raw data (as reported)'!F5),ISNUMBER('Raw data (as reported)'!G5),ISNUMBER('Raw data (as reported)'!H5)),'Raw data (as reported)'!E5+'Raw data (as reported)'!F5+'Raw data (as reported)'!G5+'Raw data (as reported)'!H5,IF(AND(ISNUMBER('Raw data (as reported)'!I5),ISNUMBER('Raw data (as reported)'!J5)),'Raw data (as reported)'!I5+'Raw data (as reported)'!J5,"")) | F5: =IF(ISNUMBER('Raw data (as reported)'!K5),'Raw data (as reported)'!K5,"") -> 9011 | G5: =IF(AND(ISNUMBER(E5),ISNUMBER(F5)),F5-E5,"") | H5: Only a total (or nothing) found – nothing to reconcile.
A6: ='Raw data (as reported)'!A6 -> 2005 | B6: ='Raw data (as reported)'!B6 -> Wealth Management US | C6: ='Raw data (as reported)'!C6 -> CHF | D6: 20-F 2007 / Handbook | E6: =IF(AND(ISNUMBER('Raw data (as reported)'!E6),ISNUMBER('Raw data (as reported)'!F6),ISNUMBER('Raw data (as reported)'!G6),ISNUMBER('Raw data (as reported)'!H6)),'Raw data (as reported)'!E6+'Raw data (as reported)'!F6+'Raw data (as reported)'!G6+'Raw data (as reported)'!H6,IF(AND(ISNUMBER('Raw data (as reported)'!I6),ISNUMBER('Raw data (as reported)'!J6)),'Raw data (as reported)'!I6+'Raw data (as reported)'!J6,"")) -> 5156 | F6: =IF(ISNUMBER('Raw data (as reported)'!K6),'Raw data (as reported)'!K6,"") -> 5156 | G6: =IF(AND(ISNUMBER(E6),ISNUMBER(F6)),F6-E6,"") -> 0 | H6: Non-recurring derived as total less recurring, so ties by construction.
A7: ='Raw data (as reported)'!A7 -> 2006 | B7: ='Raw data (as reported)'!B7 -> WM International & Switzerland | C7: ='Raw data (as reported)'!C7 -> CHF | D7: 20-F 2007 / Handbook | E7: =IF(AND(ISNUMBER('Raw data (as reported)'!E7),ISNUMBER('Raw data (as reported)'!F7),ISNUMBER('Raw data (as reported)'!G7),ISNUMBER('Raw data (as reported)'!H7)),'Raw data (as reported)'!E7+'Raw data (as reported)'!F7+'Raw data (as reported)'!G7+'Raw data (as reported)'!H7,IF(AND(ISNUMBER('Raw data (as reported)'!I7),ISNUMBER('Raw data (as reported)'!J7)),'Raw data (as reported)'!I7+'Raw data (as reported)'!J7,"")) | F7: =IF(ISNUMBER('Raw data (as reported)'!K7),'Raw data (as reported)'!K7,"") -> 10798 | G7: =IF(AND(ISNUMBER(E7),ISNUMBER(F7)),F7-E7,"") | H7: Only a total (or nothing) found – nothing to reconcile.
A8: ='Raw data (as reported)'!A8 -> 2006 | B8: ='Raw data (as reported)'!B8 -> Wealth Management US | C8: ='Raw data (as reported)'!C8 -> CHF | D8: 20-F 2007 / Handbook | E8: =IF(AND(ISNUMBER('Raw data (as reported)'!E8),ISNUMBER('Raw data (as reported)'!F8),ISNUMBER('Raw data (as reported)'!G8),ISNUMBER('Raw data (as reported)'!H8)),'Raw data (as reported)'!E8+'Raw data (as reported)'!F8+'Raw data (as reported)'!G8+'Raw data (as reported)'!H8,IF(AND(ISNUMBER('Raw data (as reported)'!I8),ISNUMBER('Raw data (as reported)'!J8)),'Raw data (as reported)'!I8+'Raw data (as reported)'!J8,"")) -> 5863 | F8: =IF(ISNUMBER('Raw data (as reported)'!K8),'Raw data (as reported)'!K8,"") -> 5863 | G8: =IF(AND(ISNUMBER(E8),ISNUMBER(F8)),F8-E8,"") -> 0 | H8: Non-recurring derived as total less recurring, so ties by construction.
A9: ='Raw data (as reported)'!A9 -> 2007 | B9: ='Raw data (as reported)'!B9 -> WM International & Switzerland | C9: ='Raw data (as reported)'!C9 -> CHF | D9: 20-F 2007 | E9: =IF(AND(ISNUMBER('Raw data (as reported)'!E9),ISNUMBER('Raw data (as reported)'!F9),ISNUMBER('Raw data (as reported)'!G9),ISNUMBER('Raw data (as reported)'!H9)),'Raw data (as reported)'!E9+'Raw data (as reported)'!F9+'Raw data (as reported)'!G9+'Raw data (as reported)'!H9,IF(AND(ISNUMBER('Raw data (as reported)'!I9),ISNUMBER('Raw data (as reported)'!J9)),'Raw data (as reported)'!I9+'Raw data (as reported)'!J9,"")) | F9: =IF(ISNUMBER('Raw data (as reported)'!K9),'Raw data (as reported)'!K9,"") | G9: =IF(AND(ISNUMBER(E9),ISNUMBER(F9)),F9-E9,"") | H9: Only a total (or nothing) found – nothing to reconcile.
A10: ='Raw data (as reported)'!A10 -> 2007 | B10: ='Raw data (as reported)'!B10 -> Wealth Management US | C10: ='Raw data (as reported)'!C10 -> CHF | D10: 20-F 2007 | E10: =IF(AND(ISNUMBER('Raw data (as reported)'!E10),ISNUMBER('Raw data (as reported)'!F10),ISNUMBER('Raw data (as reported)'!G10),ISNUMBER('Raw data (as reported)'!H10)),'Raw data (as reported)'!E10+'Raw data (as reported)'!F10+'Raw data (as reported)'!G10+'Raw data (as reported)'!H10,IF(AND(ISNUMBER('Raw data (as reported)'!I10),ISNUMBER('Raw data (as reported)'!J10)),'Raw data (as reported)'!I10+'Raw data (as reported)'!J10,"")) | F10: =IF(ISNUMBER('Raw data (as reported)'!K10),'Raw data (as reported)'!K10,"") | G10: =IF(AND(ISNUMBER(E10),ISNUMBER(F10)),F10-E10,"") | H10: Non-recurring derived as total less recurring, so ties by construction.
A11: ='Raw data (as reported)'!A11 -> 2008 | B11: ='Raw data (as reported)'!B11 -> Wealth Management (excl. Swiss retail) | C11: ='Raw data (as reported)'!C11 -> CHF | D11: 6-K (4Q09 report) | E11: =IF(AND(ISNUMBER('Raw data (as reported)'!E11),ISNUMBER('Raw data (as reported)'!F11),ISNUMBER('Raw data (as reported)'!G11),ISNUMBER('Raw data (as reported)'!H11)),'Raw data (as reported)'!E11+'Raw data (as reported)'!F11+'Raw data (as reported)'!G11+'Raw data (as reported)'!H11,IF(AND(ISNUMBER('Raw data (as reported)'!I11),ISNUMBER('Raw data (as reported)'!J11)),'Raw data (as reported)'!I11+'Raw data (as reported)'!J11,"")) | F11: =IF(ISNUMBER('Raw data (as reported)'!K11),'Raw data (as reported)'!K11,"") | G11: =IF(AND(ISNUMBER(E11),ISNUMBER(F11)),F11-E11,"") | H11: Only a total (or nothing) found – nothing to reconcile.
A12: ='Raw data (as reported)'!A12 -> 2008 | B12: ='Raw data (as reported)'!B12 -> Wealth Management Americas | C12: ='Raw data (as reported)'!C12 -> CHF | D12: 6-K (4Q09 report) | E12: =IF(AND(ISNUMBER('Raw data (as reported)'!E12),ISNUMBER('Raw data (as reported)'!F12),ISNUMBER('Raw data (as reported)'!G12),ISNUMBER('Raw data (as reported)'!H12)),'Raw data (as reported)'!E12+'Raw data (as reported)'!F12+'Raw data (as reported)'!G12+'Raw data (as reported)'!H12,IF(AND(ISNUMBER('Raw data (as reported)'!I12),ISNUMBER('Raw data (as reported)'!J12)),'Raw data (as reported)'!I12+'Raw data (as reported)'!J12,"")) -> 6278 | F12: =IF(ISNUMBER('Raw data (as reported)'!K12),'Raw data (as reported)'!K12,"") -> 6278 | G12: =IF(AND(ISNUMBER(E12),ISNUMBER(F12)),F12-E12,"") -> 0 | H12: Non-recurring derived as total less recurring, so ties by construction.
A13: ='Raw data (as reported)'!A13 -> 2009 | B13: ='Raw data (as reported)'!B13 -> Wealth Management | C13: ='Raw data (as reported)'!C13 -> CHF | D13: 6-K (4Q10 report) | E13: =IF(AND(ISNUMBER('Raw data (as reported)'!E13),ISNUMBER('Raw data (as reported)'!F13),ISNUMBER('Raw data (as reported)'!G13),ISNUMBER('Raw data (as reported)'!H13)),'Raw data (as reported)'!E13+'Raw data (as reported)'!F13+'Raw data (as reported)'!G13+'Raw data (as reported)'!H13,IF(AND(ISNUMBER('Raw data (as reported)'!I13),ISNUMBER('Raw data (as reported)'!J13)),'Raw data (as reported)'!I13+'Raw data (as reported)'!J13,"")) -> 7427 | F13: =IF(ISNUMBER('Raw data (as reported)'!K13),'Raw data (as reported)'!K13,"") -> 7427 | G13: =IF(AND(ISNUMBER(E13),ISNUMBER(F13)),F13-E13,"") -> 0 | H13: Recurring + non-recurring = income before credit loss (by construction).
